Workbook

Sheet cal_new
D2: WEEKEND | K2: WEEKEND | R2: WEEKEND | Y2: WEEKEND | AF2: WEEKEND
B3: Wednesday | C3: Thursday | D3: Friday | E3: Saturday | F3: Sunday | G3: Monday | H3: Tuesday | I3: Wednesday | J3: Thursday | K3: Friday | L3: Saturday | M3: Sunday | N3: Monday | O3: Tuesday | P3: Wednesday | Q3: Thursday | R3: Friday | S3: Saturday | T3: Sunday | U3: Monday | V3: Tuesday | W3: Wednesday | X3: Thursday | Y3: Friday | Z3: Saturday | AA3: Sunday | AB3: Monday | AC3: Tuesday | AD3: Wednesday | AE3: Jueves | AF3: Friday | AG3: Saturday | AH3: Sunday
B4: 1 | C4: 2 | D4: 3 | E4: 4 | F4: 5 | G4: 6 | H4: 7 | I4: 8 | J4: 9 | K4: 10 | L4: 11 | M4: 12 | N4: 13 | O4: 14 | P4: 15 | Q4: 16 | R4: 17 | S4: 18 | T4: 19 | U4: 20 | V4: 21 | W4: 22 | X4: 23 | Y4: 24 | Z4: 25 | AA4: 26 | AB4: 27 | AC4: 28 | AD4: 29 | AE4: 30 | AF4: 1 | AG4: 2 | AH4: 3
B5: Season Pass | AF5: Season Pass
D6: Team Race | K6: Team Race | R6: Team Race | Y6: Team Race | AF6: Team Race
B7: Team Event | G7: Team Event | N7: Team Event | U7: Team Event | AB7: Team Event
B8: Top Teams Leaderboard | G8: Top Teams Leaderboard | N8: Top Teams Leaderboard | U8: Top Teams Leaderboard | AB8: Top Teams Leaderboard
D9: Chuck's Flash Race | E9: Chuck's Flash Race | F9: Chuck's Flash Race | K9: Chuck's Flash Race | L9: Chuck's Flash Race | M9: Chuck's Flash Race | R9: Chuck's Flash Race | S9: Chuck's Flash Race | T9: Chuck's Flash Race | Y9: Chuck's Flash Race | Z9: Chuck's Flash Race | AA9: Chuck's Flash Race | AF9: Chuck's Flash Race | AG9: Chuck's Flash Race | AH9: Chuck's Flash Race
G10: Chuck's Challenge | I10: Chuck's Challenge
N11: Bomb's Challenge | P11: Bomb's Challenge
B12: Flock Flurry | C12: Flock Flurry | G12: Flock Flurry | H12: Flock Flurry | I12: Flock Flurry | J12: Flock Flurry | N12: Flock Flurry | O12: Flock Flurry | P12: Flock Flurry | Q12: Flock Flurry | U12: Flock Flurry | V12: Flock Flurry | W12: Flock Flurry | X12: Flock Flurry | AB12: Flock Flurry | AC12: Flock Flurry | AD12: Flock Flurry | AE12: Flock Flurry
U13: Level Race | W13: Level Race
B14: Red's Challenge | AB14: Red's Challenge | AD14: Red's Challenge
D15: Kite Festival | K15: Kite Festival | R15: Kite Festival | Y15: Kite Festival | AF15: Kite Festival
B16: Top Players Leaderboard | G16: Top Players Leaderboard | N16: Top Players Leaderboard | U16: Top Players Leaderboard | AB16: Top Players Leaderboard
D17: Mystery Puzzle | K17: Bomb's Ballet Show | R17: Jigsaw Puzzle | Y17: Photoshoot | AF17: Mystery Puzzle
B18: Rainbow Maker | G18: Rainbow Maker | N18: Rainbow Maker | U18: Rainbow Maker | AB18: Rainbow Maker
D19: Target Day | E19: Target Day | F19: Target Day | K19: Target Day | L19: Target Day | M19: Target Day | R19: Target Day | S19: Target Day | T19: Target Day | Y19: Target Day | Z19: Target Day | AA19: Target Day | AF19: Target Day | AG19: Target Day | AH19: Target Day
B20: Hatchling Hideaway | G20: Hatchling Hideaway | N20: Hatchling Hideaway | U20: Hatchling Hideaway | AB20: Hatchling Hideaway
B21: Night Sky | C21: Night Sky | D21: Night Sky | E21: Night Sky | F21: Night Sky | G21: Night Sky | H21: Night Sky | I21: Night Sky | J21: Night Sky | K21: Night Sky | L21: Night Sky | M21: Night Sky | N21: Night Sky | O21: Night Sky | P21: Night Sky | Q21: Night Sky | R21: Night Sky | S21: Night Sky | T21: Night Sky | U21: Night Sky | V21: Night Sky | W21: Night Sky | X21: Night Sky | Y21: Night Sky | Z21: Night Sky | AA21: Night Sky | AB21: Night Sky | AC21: Night Sky | AD21: Night Sky | AE21: Night Sky | AF21: Night Sky | AG21: Night Sky | AH21: Night Sky
B23: Season Offers | G23: Season Offers | N23: Season Offers | U23: Season Offers | AB23: Season Offers
D24: Progress Pack | K24: Progress Pack | R24: Progress Pack | Y24: Progress Pack | AF24: Progress Pack
E25: Special Offer | L25: Special Offer | S25: Special Offer | Z25: Special Offer | AG25: Special Offer
B28: Summary Section
B30: Instances Count
A31: old | B31: =COUNT_COLORED_MERGED(cal_curr!B5:B25) | C31: =COUNT_COLORED_MERGED(cal_curr!C5:C25) | D31: =COUNT_COLORED_MERGED(cal_curr!D5:D25) | E31: =COUNT_COLORED_MERGED(cal_curr!E5:E25) | F31: =COUNT_COLORED_MERGED(cal_curr!F5:F25) | G31: =COUNT_COLORED_MERGED(cal_curr!G5:G25) | H31: =COUNT_COLORED_MERGED(cal_curr!H5:H25) | I31: =COUNT_COLORED_MERGED(cal_curr!I5:I25) | ... AH31: =COUNT_COLORED_MERGED(cal_curr!AH5:AH25)
A32: new | B32: =COUNT_COLORED_MERGED(B5:B25) | C32: =COUNT_COLORED_MERGED(C5:C25) | D32: =COUNT_COLORED_MERGED(D5:D25) | E32: =COUNT_COLORED_MERGED(E5:E25) | F32: =COUNT_COLORED_MERGED(F5:F25) | G32: =COUNT_COLORED_MERGED(G5:G25) | H32: =COUNT_COLORED_MERGED(H5:H25) | I32: =COUNT_COLORED_MERGED(I5:I25) | ... AH32: =COUNT_COLORED_MERGED(AH5:AH25)
A33: diff | B33: =(B32-B31)/B31 | C33: =(C32-C31)/C31 | D33: =(D32-D31)/D31 | E33: =(E32-E31)/E31 | F33: =(F32-F31)/F31 | G33: =(G32-G31)/G31 | H33: =(H32-H31)/H31 | I33: =(I32-I31)/I31 | ... AH33: =(AH32-AH31)/AH31
B35: Summary of old vs new
E36: old | H36: new | K36: diff
C37: source | E37: instances | F37: event-days | H37: instances | I37: event-days | K37: instances | L37: event-days
C38: Ads | E38: =ECOGAINS_CAL_COUNTS(sim_refresh!$A$1) | L38: =iferror((F38-I38)/F38, "")
C39: Bomb Challenge | L39: =iferror((F39-I39)/F39, "")
C40: Bomb's Ballet | L40: =iferror((F40-I40)/F40, "")
C41: Chuck Challenge | L41: =iferror((F41-I41)/F41, "")
C42: Core | L42: =iferror((F42-I42)/F42, "")
C43: Daily Gift | L43: =iferror((F43-I43)/F43, "")
C44: Daily Night Sky Prize | L44: =iferror((F44-I44)/F44, "")
C45: Flock Flurry | L45: =iferror((F45-I45)/F45, "")
C46: Hatchling Hideaway | L46: =iferror((F46-I46)/F46, "")
...
