Workbook

Sheet EcoGainsSim_Daily
B1: DAILY RESOURCE GAINS + NET — 33-day calendar, per earner (day 1 = Wednesday) | EN1: source dropdown list
EN2: ALL
B3: Payer | C3: NONPAYER | D3: ◀ filters (dropdowns) — the whole table re-simulates on change | EN3: Ads
B4: Segment | C4: 0-9 | EN4: Bomb Challenge
B5: Source | C5: ALL | EN5: Bomb's Ballet
EN6: Chuck Challenge
D7: ◄ CURRENT (cal_curr, measured) ► | X7: ◄ NEW (cal_new, simulated) ► | AR7: Δ NEW − CURRENT (same day) | BL7: ◄ ACTUAL SPEND / earner (data_econ_daily) ► | CF7: ◄ CURRENT NET / earner (gain − spend) ► | CZ7: ◄ NEW NET / earner (gain + sim Δ − spend) ► | DT7: Δ NET (new − cur; == sim Δ) | EN7: Core
B8: Day | C8: DoW | D8: HC | E8: Slingshot | F8: Shuffle | G8: Comet | H8: Red | I8: Chuck | J8: Bomb | K8: UL Bomb | L8: UL Chuck | M8: UL Red | N8: Unlimited Lives | O8: SPT | P8: SPTx2 | Q8: 1-star Pack | R8: 2-star Pack | S8: 3-star Pack | T8: 4-star Pack | U8: 5-star Pack | V8: 6-star Pack | X8: HC | Y8: Slingshot | Z8: Shuffle | AA8: Comet | AB8: Red | AC8: Chuck | AD8: Bomb | AE8: UL Bomb | AF8: UL Chuck | AG8: UL Red | AH8: Unlimited Lives | AI8: SPT | AJ8: SPTx2 | AK8: 1-star Pack | AL8: 2-star Pack | AM8: 3-star Pack | AN8: 4-star Pack | AO8: 5-star Pack | AP8: 6-star Pack | AR8: HC | AS8: Slingshot | AT8: Shuffle | AU8: Comet | AV8: Red | AW8: Chuck | AX8: Bomb | AY8: UL Bomb | AZ8: UL Chuck | BA8: UL Red | BB8: Unlimited Lives | BC8: SPT | BD8: SPTx2 | BE8: 1-star Pack | BF8: 2-star Pack | BG8: 3-star Pack | BH8: 4-star Pack | BI8: 5-star Pack | BJ8: 6-star Pack | BL8: HC | BM8: Slingshot | BN8: Shuffle | BO8: Comet | BP8: Red | BQ8: Chuck | BR8: Bomb | BS8: UL Bomb | BT8: UL Chuck | BU8: UL Red | BV8: Unlimited Lives | BW8: SPT | BX8: SPTx2 | BY8: 1-star Pack | BZ8: 2-star Pack | CA8: 3-star Pack | CB8: 4-star Pack | CC8: 5-star Pack | CD8: 6-star Pack | CF8: HC | CG8: Slingshot | CH8: Shuffle | CI8: Comet | CJ8: Red | CK8: Chuck | CL8: Bomb | CM8: UL Bomb | CN8: UL Chuck | CO8: UL Red | CP8: Unlimited Lives | CQ8: SPT | CR8: SPTx2 | CS8: 1-star Pack | CT8: 2-star Pack | CU8: 3-star Pack | CV8: 4-star Pack | CW8: 5-star Pack | CX8: 6-star Pack | CZ8: HC | DA8: Slingshot | DB8: Shuffle | DC8: Comet | DD8: Red | DE8: Chuck | DF8: Bomb | DG8: UL Bomb | DH8: UL Chuck | DI8: UL Red | DJ8: Unlimited Lives | DK8: SPT | DL8: SPTx2 | DM8: 1-star Pack | DN8: 2-star Pack | DO8: 3-star Pack | DP8: 4-star Pack | DQ8: 5-star Pack | DR8: 6-star Pack | DT8: HC | DU8: Slingshot | DV8: Shuffle | DW8: Comet | DX8: Red | DY8: Chuck | DZ8: Bomb | EA8: UL Bomb | EB8: UL Chuck | EC8: UL Red | ED8: Unlimited Lives | EE8: SPT | EF8: SPTx2 | EG8: 1-star Pack | EH8: 2-star Pack | EI8: 3-star Pack | EJ8: 4-star Pack | EK8: 5-star Pack | EL8: 6-star Pack | EN8: Daily Gift
B9: 1 | C9: Wed | D9: =LET(payer,$C$3, segment,$C$4, source,$C$5, ECOGAINS_DAILY(payer, segment, source, "CURRENT", sim_refresh!$A$1)) | X9: =LET(payer,$C$3, segment,$C$4, source,$C$5, ECOGAINS_DAILY(payer, segment, source, "NEW", sim_refresh!$A$1)) | AR9: =LET(payer,$C$3, segment,$C$4, source,$C$5, ECOGAINS_DAILY(payer, segment, source, "DIFF", sim_refresh!$A$1)) | BL9: =LET(payer,$C$3, segment,$C$4, source,$C$5, ECOGAINS_DAILY(payer, segment, source, "SPEND", sim_refresh!$A$1)) | CF9: =LET(payer,$C$3, segment,$C$4, source,$C$5, ECOGAINS_DAILY(payer, segment, source, "CURNET", sim_refresh!$A$1)) | CZ9: =LET(payer,$C$3, segment,$C$4, source,$C$5, ECOGAINS_DAILY(payer, segment, source, "NEWNET", sim_refresh!$A$1)) | DT9: =IFERROR(CZ9-CF9,"") | DU9: =IFERROR(DA9-CG9,"") | DV9: =IFERROR(DB9-CH9,"") | DW9: =IFERROR(DC9-CI9,"") | DX9: =IFERROR(DD9-CJ9,"") | DY9: =IFERROR(DE9-CK9,"") | DZ9: =IFERROR(DF9-CL9,"") | EA9: =IFERROR(DG9-CM9,"") | ... EL9: =IFERROR(DR9-CX9,"") | EN9: Daily Night Sky Prize
B10: 2 | C10: Thu | DT10: =IFERROR(CZ10-CF10,"") | DU10: =IFERROR(DA10-CG10,"") | DV10: =IFERROR(DB10-CH10,"") | DW10: =IFERROR(DC10-CI10,"") | DX10: =IFERROR(DD10-CJ10,"") | DY10: =IFERROR(DE10-CK10,"") | DZ10: =IFERROR(DF10-CL10,"") | EA10: =IFERROR(DG10-CM10,"") | ... EL10: =IFERROR(DR10-CX10,"") | EN10: Flock Flurry
B11: 3 | C11: Fri | DT11: =IFERROR(CZ11-CF11,"") | DU11: =IFERROR(DA11-CG11,"") | DV11: =IFERROR(DB11-CH11,"") | DW11: =IFERROR(DC11-CI11,"") | DX11: =IFERROR(DD11-CJ11,"") | DY11: =IFERROR(DE11-CK11,"") | DZ11: =IFERROR(DF11-CL11,"") | EA11: =IFERROR(DG11-CM11,"") | ... EL11: =IFERROR(DR11-CX11,"") | EN11: Hatchling Hideaway
B12: 4 | C12: Sat | DT12: =IFERROR(CZ12-CF12,"") | DU12: =IFERROR(DA12-CG12,"") | DV12: =IFERROR(DB12-CH12,"") | DW12: =IFERROR(DC12-CI12,"") | DX12: =IFERROR(DD12-CJ12,"") | DY12: =IFERROR(DE12-CK12,"") | DZ12: =IFERROR(DF12-CL12,"") | EA12: =IFERROR(DG12-CM12,"") | ... EL12: =IFERROR(DR12-CX12,"") | EN12: Jigsaw
B13: 5 | C13: Sun | DT13: =IFERROR(CZ13-CF13,"") | DU13: =IFERROR(DA13-CG13,"") | DV13: =IFERROR(DB13-CH13,"") | DW13: =IFERROR(DC13-CI13,"") | DX13: =IFERROR(DD13-CJ13,"") | DY13: =IFERROR(DE13-CK13,"") | DZ13: =IFERROR(DF13-CL13,"") | EA13: =IFERROR(DG13-CM13,"") | ... EL13: =IFERROR(DR13-CX13,"") | EN13: Kite Festival
B14: 6 | C14: Mon | DT14: =IFERROR(CZ14-CF14,"") | DU14: =IFERROR(DA14-CG14,"") | DV14: =IFERROR(DB14-CH14,"") | DW14: =IFERROR(DC14-CI14,"") | DX14: =IFERROR(DD14-CJ14,"") | DY14: =IFERROR(DE14-CK14,"") | DZ14: =IFERROR(DF14-CL14,"") | EA14: =IFERROR(DG14-CM14,"") | ... EL14: =IFERROR(DR14-CX14,"") | EN14: Level Race
B15: 7 | C15: Tue | DT15: =IFERROR(CZ15-CF15,"") | DU15: =IFERROR(DA15-CG15,"") | DV15: =IFERROR(DB15-CH15,"") | DW15: =IFERROR(DC15-CI15,"") | DX15: =IFERROR(DD15-CJ15,"") | DY15: =IFERROR(DE15-CK15,"") | DZ15: =IFERROR(DF15-CL15,"") | EA15: =IFERROR(DG15-CM15,"") | ... EL15: =IFERROR(DR15-CX15,"") | EN15: Other
B16: 8 | C16: Wed | DT16: =IFERROR(CZ16-CF16,"") | DU16: =IFERROR(DA16-CG16,"") | DV16: =IFERROR(DB16-CH16,"") | DW16: =IFERROR(DC16-CI16,"") | DX16: =IFERROR(DD16-CJ16,"") | DY16: =IFERROR(DE16-CK16,"") | DZ16: =IFERROR(DF16-CL16,"") | EA16: =IFERROR(DG16-CM16,"") | ... EL16: =IFERROR(DR16-CX16,"") | EN16: Photoshoot
B17: 9 | C17: Thu | DT17: =IFERROR(CZ17-CF17,"") | DU17: =IFERROR(DA17-CG17,"") | DV17: =IFERROR(DB17-CH17,"") | DW17: =IFERROR(DC17-CI17,"") | DX17: =IFERROR(DD17-CJ17,"") | DY17: =IFERROR(DE17-CK17,"") | DZ17: =IFERROR(DF17-CL17,"") | EA17: =IFERROR(DG17-CM17,"") | ... EL17: =IFERROR(DR17-CX17,"") | EN17: Red Challenge
B18: 10 | C18: Fri | DT18: =IFERROR(CZ18-CF18,"") | DU18: =IFERROR(DA18-CG18,"") | DV18: =IFERROR(DB18-CH18,"") | DW18: =IFERROR(DC18-CI18,"") | DX18: =IFERROR(DD18-CJ18,"") | DY18: =IFERROR(DE18-CK18,"") | DZ18: =IFERROR(DF18-CL18,"") | EA18: =IFERROR(DG18-CM18,"") | ... EL18: =IFERROR(DR18-CX18,"") | EN18: River Rush
B19: 11 | C19: Sat | DT19: =IFERROR(CZ19-CF19,"") | DU19: =IFERROR(DA19-CG19,"") | DV19: =IFERROR(DB19-CH19,"") | DW19: =IFERROR(DC19-CI19,"") | DX19: =IFERROR(DD19-CJ19,"") | DY19: =IFERROR(DE19-CK19,"") | DZ19: =IFERROR(DF19-CL19,"") | EA19: =IFERROR(DG19-CM19,"") | ... EL19: =IFERROR(DR19-CX19,"") | EN19: Saga
B20: 12 | C20: Sun | DT20: =IFERROR(CZ20-CF20,"") | DU20: =IFERROR(DA20-CG20,"") | DV20: =IFERROR(DB20-CH20,"") | DW20: =IFERROR(DC20-CI20,"") | DX20: =IFERROR(DD20-CJ20,"") | DY20: =IFERROR(DE20-CK20,"") | DZ20: =IFERROR(DF20-CL20,"") | EA20: =IFERROR(DG20-CM20,"") | ... EL20: =IFERROR(DR20-CX20,"") | EN20: Season Pass (Free)
B21: 13 | C21: Mon | DT21: =IFERROR(CZ21-CF21,"") | DU21: =IFERROR(DA21-CG21,"") | DV21: =IFERROR(DB21-CH21,"") | DW21: =IFERROR(DC21-CI21,"") | DX21: =IFERROR(DD21-CJ21,"") | DY21: =IFERROR(DE21-CK21,"") | DZ21: =IFERROR(DF21-CL21,"") | EA21: =IFERROR(DG21-CM21,"") | ... EL21: =IFERROR(DR21-CX21,"") | EN21: Target Day
... B27: 19 | C27: Sun | DT27: =IFERROR(CZ27-CF27,"") | DU27: =IFERROR(DA27-CG27,"") | DV27: =IFERROR(DB27-CH27,"") | DW27: =IFERROR(DC27-CI27,"") | DX27: =IFERROR(DD27-CJ27,"") | DY27: =IFERROR(DE27-CK27,"") | DZ27: =IFERROR(DF27-CL27,"") | EA27: =IFERROR(DG27-CM27,"") | ... EL27: =IFERROR(DR27-CX27,"") | EN27: IAPs
B28: 20 | C28: Mon | DT28: =IFERROR(CZ28-CF28,"") | DU28: =IFERROR(DA28-CG28,"") | DV28: =IFERROR(DB28-CH28,"") | DW28: =IFERROR(DC28-CI28,"") | DX28: =IFERROR(DD28-CJ28,"") | DY28: =IFERROR(DE28-CK28,"") | DZ28: =IFERROR(DF28-CL28,"") | EA28: =IFERROR(DG28-CM28,"") | ... EL28: =IFERROR(DR28-CX28,"")
B29: 21 | C29: Tue | DT29: =IFERROR(CZ29-CF29,"") | DU29: =IFERROR(DA29-CG29,"") | DV29: =IFERROR(DB29-CH29,"") | DW29: =IFERROR(DC29-CI29,"") | DX29: =IFERROR(DD29-CJ29,"") | DY29: =IFERROR(DE29-CK29,"") | DZ29: =IFERROR(DF29-CL29,"") | EA29: =IFERROR(DG29-CM29,"") | ... EL29: =IFERROR(DR29-CX29,"")
B30: 22 | C30: Wed | DT30: =IFERROR(CZ30-CF30,"") | DU30: =IFERROR(DA30-CG30,"") | DV30: =IFERROR(DB30-CH30,"") | DW30: =IFERROR(DC30-CI30,"") | DX30: =IFERROR(DD30-CJ30,"") | DY30: =IFERROR(DE30-CK30,"") | DZ30: =IFERROR(DF30-CL30,"") | EA30: =IFERROR(DG30-CM30,"") | ... EL30: =IFERROR(DR30-CX30,"")
B31: 23 | C31: Thu | DT31: =IFERROR(CZ31-CF31,"") | DU31: =IFERROR(DA31-CG31,"") | DV31: =IFERROR(DB31-CH31,"") | DW31: =IFERROR(DC31-CI31,"") | DX31: =IFERROR(DD31-CJ31,"") | DY31: =IFERROR(DE31-CK31,"") | DZ31: =IFERROR(DF31-CL31,"") | EA31: =IFERROR(DG31-CM31,"") | ... EL31: =IFERROR(DR31-CX31,"")
B32: 24 | C32: Fri | DT32: =IFERROR(CZ32-CF32,"") | DU32: =IFERROR(DA32-CG32,"") | DV32: =IFERROR(DB32-CH32,"") | DW32: =IFERROR(DC32-CI32,"") | DX32: =IFERROR(DD32-CJ32,"") | DY32: =IFERROR(DE32-CK32,"") | DZ32: =IFERROR(DF32-CL32,"") | EA32: =IFERROR(DG32-CM32,"") | ... EL32: =IFERROR(DR32-CX32,"")
B33: 25 | C33: Sat | DT33: =IFERROR(CZ33-CF33,"") | DU33: =IFERROR(DA33-CG33,"") | DV33: =IFERROR(DB33-CH33,"") | DW33: =IFERROR(DC33-CI33,"") | DX33: =IFERROR(DD33-CJ33,"") | DY33: =IFERROR(DE33-CK33,"") | DZ33: =IFERROR(DF33-CL33,"") | EA33: =IFERROR(DG33-CM33,"") | ... EL33: =IFERROR(DR33-CX33,"")
B34: 26 | C34: Sun | DT34: =IFERROR(CZ34-CF34,"") | DU34: =IFERROR(DA34-CG34,"") | DV34: =IFERROR(DB34-CH34,"") | DW34: =IFERROR(DC34-CI34,"") | DX34: =IFERROR(DD34-CJ34,"") | DY34: =IFERROR(DE34-CK34,"") | DZ34: =IFERROR(DF34-CL34,"") | EA34: =IFERROR(DG34-CM34,"") | ... EL34: =IFERROR(DR34-CX34,"")
B35: 27 | C35: Mon | DT35: =IFERROR(CZ35-CF35,"") | DU35: =IFERROR(DA35-CG35,"") | DV35: =IFERROR(DB35-CH35,"") | DW35: =IFERROR(DC35-CI35,"") | DX35: =IFERROR(DD35-CJ35,"") | DY35: =IFERROR(DE35-CK35,"") | DZ35: =IFERROR(DF35-CL35,"") | EA35: =IFERROR(DG35-CM35,"") | ... EL35: =IFERROR(DR35-CX35,"")
B36: 28 | C36: Tue | DT36: =IFERROR(CZ36-CF36,"") | DU36: =IFERROR(DA36-CG36,"") | DV36: =IFERROR(DB36-CH36,"") | DW36: =IFERROR(DC36-CI36,"") | DX36: =IFERROR(DD36-CJ36,"") | DY36: =IFERROR(DE36-CK36,"") | DZ36: =IFERROR(DF36-CL36,"") | EA36: =IFERROR(DG36-CM36,"") | ... EL36: =IFERROR(DR36-CX36,"")
B37: 29 | C37: Wed | DT37: =IFERROR(CZ37-CF37,"") | DU37: =IFERROR(DA37-CG37,"") | DV37: =IFERROR(DB37-CH37,"") | DW37: =IFERROR(DC37-CI37,"") | DX37: =IFERROR(DD37-CJ37,"") | DY37: =IFERROR(DE37-CK37,"") | DZ37: =IFERROR(DF37-CL37,"") | EA37: =IFERROR(DG37-CM37,"") | ... EL37: =IFERROR(DR37-CX37,"")
B38: 30 | C38: Thu | DT38: =IFERROR(CZ38-CF38,"") | DU38: =IFERROR(DA38-CG38,"") | DV38: =IFERROR(DB38-CH38,"") | DW38: =IFERROR(DC38-CI38,"") | DX38: =IFERROR(DD38-CJ38,"") | DY38: =IFERROR(DE38-CK38,"") | DZ38: =IFERROR(DF38-CL38,"") | EA38: =IFERROR(DG38-CM38,"") | ... EL38: =IFERROR(DR38-CX38,"")
B39: 31 | C39: Fri | DT39: =IFERROR(CZ39-CF39,"") | DU39: =IFERROR(DA39-CG39,"") | DV39: =IFERROR(DB39-CH39,"") | DW39: =IFERROR(DC39-CI39,"") | DX39: =IFERROR(DD39-CJ39,"") | DY39: =IFERROR(DE39-CK39,"") | DZ39: =IFERROR(DF39-CL39,"") | EA39: =IFERROR(DG39-CM39,"") | ... EL39: =IFERROR(DR39-CX39,"")
... B41: 33 | C41: Sun | DT41: =IFERROR(CZ41-CF41,"") | DU41: =IFERROR(DA41-CG41,"") | DV41: =IFERROR(DB41-CH41,"") | DW41: =IFERROR(DC41-CI41,"") | DX41: =IFERROR(DD41-CJ41,"") | DY41: =IFERROR(DE41-CK41,"") | DZ41: =IFERROR(DF41-CL41,"") | EA41: =IFERROR(DG41-CM41,"") | ... EL41: =IFERROR(DR41-CX41,"")
B42: TOTAL | D42: =SUM(D9:D41) | E42: =SUM(E9:E41) | F42: =SUM(F9:F41) | G42: =SUM(G9:G41) | H42: =SUM(H9:H41) | I42: =SUM(I9:I41) | J42: =SUM(J9:J41) | K42: =SUM(K9:K41) | ... V42: =SUM(V9:V41) | X42: =SUM(X9:X41) | Y42: =SUM(Y9:Y41) | Z42: =SUM(Z9:Z41) | AA42: =SUM(AA9:AA41) | AB42: =SUM(AB9:AB41) | AC42: =SUM(AC9:AC41) | AD42: =SUM(AD9:AD41) | AE42: =SUM(AE9:AE41) | ... AP42: =SUM(AP9:AP41) | AR42: =SUM(AR9:AR41) | AS42: =SUM(AS9:AS41) | AT42: =SUM(AT9:AT41) | AU42: =SUM(AU9:AU41) | AV42: =SUM(AV9:AV41) | AW42: =SUM(AW9:AW41) | AX42: =SUM(AX9:AX41) | AY42: =SUM(AY9:AY41) | ... BJ42: =SUM(BJ9:BJ41) | BL42: =IF(COUNT(BL9:BL41)=0,"",SUM(BL9:BL41)) | BM42: =IF(COUNT(BM9:BM41)=0,"",SUM(BM9:BM41)) | BN42: =IF(COUNT(BN9:BN41)=0,"",SUM(BN9:BN41)) | BO42: =IF(COUNT(BO9:BO41)=0,"",SUM(BO9:BO41)) | BP42: =IF(COUNT(BP9:BP41)=0,"",SUM(BP9:BP41)) | BQ42: =IF(COUNT(BQ9:BQ41)=0,"",SUM(BQ9:BQ41)) | BR42: =IF(COUNT(BR9:BR41)=0,"",SUM(BR9:BR41)) | BS42: =IF(COUNT(BS9:BS41)=0,"",SUM(BS9:BS41)) | ... CD42: =IF(COUNT(CD9:CD41)=0,"",SUM(CD9:CD41)) | CF42: =IF(COUNT(CF9:CF41)=0,"",SUM(CF9:CF41)) | CG42: =IF(COUNT(CG9:CG41)=0,"",SUM(CG9:CG41)) | CH42: =IF(COUNT(CH9:CH41)=0,"",SUM(CH9:CH41)) | CI42: =IF(COUNT(CI9:CI41)=0,"",SUM(CI9:CI41)) | CJ42: =IF(COUNT(CJ9:CJ41)=0,"",SUM(CJ9:CJ41)) | CK42: =IF(COUNT(CK9:CK41)=0,"",SUM(CK9:CK41)) | CL42: =IF(COUNT(CL9:CL41)=0,"",SUM(CL9:CL41)) | CM42: =IF(COUNT(CM9:CM41)=0,"",SUM(CM9:CM41)) | ... CX42: =IF(COUNT(CX9:CX41)=0,"",SUM(CX9:CX41)) | CZ42: =IF(COUNT(CZ9:CZ41)=0,"",SUM(CZ9:CZ41)) | DA42: =IF(COUNT(DA9:DA41)=0,"",SUM(DA9:DA41)) | DB42: =IF(COUNT(DB9:DB41)=0,"",SUM(DB9:DB41)) | DC42: =IF(COUNT(DC9:DC41)=0,"",SUM(DC9:DC41)) | DD42: =IF(COUNT(DD9:DD41)=0,"",SUM(DD9:DD41)) | DE42: =IF(COUNT(DE9:DE41)=0,"",SUM(DE9:DE41)) | DF42: =IF(COUNT(DF9:DF41)=0,"",SUM(DF9:DF41)) | DG42: =IF(COUNT(DG9:DG41)=0,"",SUM(DG9:DG41)) | ... DR42: =IF(COUNT(DR9:DR41)=0,"",SUM(DR9:DR41)) | DT42: =IF(COUNT(DT9:DT41)=0,"",SUM(DT9:DT41)) | DU42: =IF(COUNT(DU9:DU41)=0,"",SUM(DU9:DU41)) | DV42: =IF(COUNT(DV9:DV41)=0,"",SUM(DV9:DV41)) | DW42: =IF(COUNT(DW9:DW41)=0,"",SUM(DW9:DW41)) | DX42: =IF(COUNT(DX9:DX41)=0,"",SUM(DX9:DX41)) | DY42: =IF(COUNT(DY9:DY41)=0,"",SUM(DY9:DY41)) | DZ42: =IF(COUNT(DZ9:DZ41)=0,"",SUM(DZ9:DZ41)) | EA42: =IF(COUNT(EA9:EA41)=0,"",SUM(EA9:EA41)) | ... EL42: =IF(COUNT(EL9:EL41)=0,"",SUM(EL9:EL41))
B44: LEGEND / ALLOCATION RULES (claim-day realistic — EcoGainsSim_Daily.gs)
B45: Window totals are exactly the main sim’s numbers (CURRENT = measured on cal_curr, NEW = simulated on cal_new); this view only places them on days — column TOTALs reconcile with EcoGainsSim_HC.
B46: Leaderboard events (Bomb/Chuck/Red Challenge, Level Race, Flash Race, Target Day, Kite) pay on each instance’s LAST day → expect end-day spikes. Instance slices are split by reach.
B47: Collections (Hatchling Hideaway, Bomb’s Ballet, Jigsaw, Photoshoot) spread across instance days by the accrual curve’s marginal share; Rainbow Maker spreads ∝ active rate within its instances (no curve — flagged).
...
