Workbook

Sheet EcoGainsSim_Daily
B1: DAILY RESOURCE GAINS + NET — data vs sim, 28-day window, per earner (days and weekdays from the calendar sheets: day 1 = the first 1 on row 4) | FP1: source dropdown list
FP2: ALL
B3: Payer | C3: NONPAYER | D3: ◀ filters (dropdowns) — the whole table re-simulates on change | FP3: Ads
B4: Segment | C4: 0-9 | FP4: Bomb Challenge
B5: Source | C5: ALL | FP5: Bomb's Ballet
FP6: Chuck Challenge
D7: ◄ CURRENT GAINS (data: data_econ_daily, per earner) ► | Y7: ◄ NEW GAINS (sim, cal_new) ► | AT7: Δ GAINS data − sim | BO7: ◄ CURRENT SPEND (data, per earner) ► | CJ7: ◄ CURRENT NET (data: gain − spend) ► | DE7: ◄ NEW NET (sim: data gain + sim Δ − spend) ► | DZ7: Δ NET data − sim | EU7: ◄ SIM of cal_curr — validation lane (data − this = model error) ► | FP7: Core
B8: Day | C8: DoW | D8: HC | E8: Slingshot | F8: Shuffle | G8: Comet | H8: Red | I8: Chuck | J8: Bomb | K8: UL Bomb | L8: UL Chuck | M8: UL Red | N8: Unlimited Lives | O8: SPT | P8: SPTx2 | Q8: 1-star Pack | R8: 2-star Pack | S8: 3-star Pack | T8: 4-star Pack | U8: 5-star Pack | V8: 6-star Pack | W8: ToF_Ticket | Y8: HC | Z8: Slingshot | AA8: Shuffle | AB8: Comet | AC8: Red | AD8: Chuck | AE8: Bomb | AF8: UL Bomb | AG8: UL Chuck | AH8: UL Red | AI8: Unlimited Lives | AJ8: SPT | AK8: SPTx2 | AL8: 1-star Pack | AM8: 2-star Pack | AN8: 3-star Pack | AO8: 4-star Pack | AP8: 5-star Pack | AQ8: 6-star Pack | AR8: ToF_Ticket | AT8: HC | AU8: Slingshot | AV8: Shuffle | AW8: Comet | AX8: Red | AY8: Chuck | AZ8: Bomb | BA8: UL Bomb | BB8: UL Chuck | BC8: UL Red | BD8: Unlimited Lives | BE8: SPT | BF8: SPTx2 | BG8: 1-star Pack | BH8: 2-star Pack | BI8: 3-star Pack | BJ8: 4-star Pack | BK8: 5-star Pack | BL8: 6-star Pack | BM8: ToF_Ticket | BO8: HC | BP8: Slingshot | BQ8: Shuffle | BR8: Comet | BS8: Red | BT8: Chuck | BU8: Bomb | BV8: UL Bomb | BW8: UL Chuck | BX8: UL Red | BY8: Unlimited Lives | BZ8: SPT | CA8: SPTx2 | CB8: 1-star Pack | CC8: 2-star Pack | CD8: 3-star Pack | CE8: 4-star Pack | CF8: 5-star Pack | CG8: 6-star Pack | CH8: ToF_Ticket | CJ8: HC | CK8: Slingshot | CL8: Shuffle | CM8: Comet | CN8: Red | CO8: Chuck | CP8: Bomb | CQ8: UL Bomb | CR8: UL Chuck | CS8: UL Red | CT8: Unlimited Lives | CU8: SPT | CV8: SPTx2 | CW8: 1-star Pack | CX8: 2-star Pack | CY8: 3-star Pack | CZ8: 4-star Pack | DA8: 5-star Pack | DB8: 6-star Pack | DC8: ToF_Ticket | DE8: HC | DF8: Slingshot | DG8: Shuffle | DH8: Comet | DI8: Red | DJ8: Chuck | DK8: Bomb | DL8: UL Bomb | DM8: UL Chuck | DN8: UL Red | DO8: Unlimited Lives | DP8: SPT | DQ8: SPTx2 | DR8: 1-star Pack | DS8: 2-star Pack | DT8: 3-star Pack | DU8: 4-star Pack | DV8: 5-star Pack | DW8: 6-star Pack | DX8: ToF_Ticket | DZ8: HC | EA8: Slingshot | EB8: Shuffle | EC8: Comet | ED8: Red | EE8: Chuck | EF8: Bomb | EG8: UL Bomb | EH8: UL Chuck | EI8: UL Red | EJ8: Unlimited Lives | EK8: SPT | EL8: SPTx2 | EM8: 1-star Pack | EN8: 2-star Pack | EO8: 3-star Pack | EP8: 4-star Pack | EQ8: 5-star Pack | ER8: 6-star Pack | ES8: ToF_Ticket | EU8: HC | EV8: Slingshot | EW8: Shuffle | EX8: Comet | EY8: Red | EZ8: Chuck | FA8: Bomb | FB8: UL Bomb | FC8: UL Chuck | FD8: UL Red | FE8: Unlimited Lives | FF8: SPT | FG8: SPTx2 | FH8: 1-star Pack | FI8: 2-star Pack | FJ8: 3-star Pack | FK8: 4-star Pack | FL8: 5-star Pack | FM8: 6-star Pack | FN8: ToF_Ticket | FP8: Daily Gift
B9: 1 | C9: =IFERROR(LEFT(INDEX(cal_new!$A$3:$AH$3,1,MATCH(1,cal_new!$A$4:$AH$4,0)+B9-1),3),"") | D9: =LET(payer,$C$3, segment,$C$4, source,$C$5, ECOGAINS_DAILY(payer, segment, source, "DATA", sim_refresh!$A$1)) | Y9: =LET(payer,$C$3, segment,$C$4, source,$C$5, ECOGAINS_DAILY(payer, segment, source, "NEW", sim_refresh!$A$1)) | AT9: =LET(payer,$C$3, segment,$C$4, source,$C$5, ECOGAINS_DAILY(payer, segment, source, "DATADIFF", sim_refresh!$A$1)) | BO9: =LET(payer,$C$3, segment,$C$4, source,$C$5, ECOGAINS_DAILY(payer, segment, source, "SPEND", sim_refresh!$A$1)) | CJ9: =LET(payer,$C$3, segment,$C$4, source,$C$5, ECOGAINS_DAILY(payer, segment, source, "CURNET", sim_refresh!$A$1)) | DE9: =LET(payer,$C$3, segment,$C$4, source,$C$5, ECOGAINS_DAILY(payer, segment, source, "NEWNET", sim_refresh!$A$1)) | DZ9: =IF(OR(CJ9="",DE9=""),"",IFERROR(CJ9-DE9,"")) | EA9: =IF(OR(CK9="",DF9=""),"",IFERROR(CK9-DF9,"")) | EB9: =IF(OR(CL9="",DG9=""),"",IFERROR(CL9-DG9,"")) | EC9: =IF(OR(CM9="",DH9=""),"",IFERROR(CM9-DH9,"")) | ED9: =IF(OR(CN9="",DI9=""),"",IFERROR(CN9-DI9,"")) | EE9: =IF(OR(CO9="",DJ9=""),"",IFERROR(CO9-DJ9,"")) | EF9: =IF(OR(CP9="",DK9=""),"",IFERROR(CP9-DK9,"")) | EG9: =IF(OR(CQ9="",DL9=""),"",IFERROR(CQ9-DL9,"")) | ... ES9: =IF(OR(DC9="",DX9=""),"",IFERROR(DC9-DX9,"")) | EU9: =LET(payer,$C$3, segment,$C$4, source,$C$5, ECOGAINS_DAILY(payer, segment, source, "CURRENT", sim_refresh!$A$1)) | FP9: Daily Night Sky Prize
B10: 2 | C10: =IFERROR(LEFT(INDEX(cal_new!$A$3:$AH$3,1,MATCH(1,cal_new!$A$4:$AH$4,0)+B10-1),3),"") | DZ10: =IF(OR(CJ10="",DE10=""),"",IFERROR(CJ10-DE10,"")) | EA10: =IF(OR(CK10="",DF10=""),"",IFERROR(CK10-DF10,"")) | EB10: =IF(OR(CL10="",DG10=""),"",IFERROR(CL10-DG10,"")) | EC10: =IF(OR(CM10="",DH10=""),"",IFERROR(CM10-DH10,"")) | ED10: =IF(OR(CN10="",DI10=""),"",IFERROR(CN10-DI10,"")) | EE10: =IF(OR(CO10="",DJ10=""),"",IFERROR(CO10-DJ10,"")) | EF10: =IF(OR(CP10="",DK10=""),"",IFERROR(CP10-DK10,"")) | EG10: =IF(OR(CQ10="",DL10=""),"",IFERROR(CQ10-DL10,"")) | ... ES10: =IF(OR(DC10="",DX10=""),"",IFERROR(DC10-DX10,"")) | FP10: Flock Flurry
B11: 3 | C11: =IFERROR(LEFT(INDEX(cal_new!$A$3:$AH$3,1,MATCH(1,cal_new!$A$4:$AH$4,0)+B11-1),3),"") | DZ11: =IF(OR(CJ11="",DE11=""),"",IFERROR(CJ11-DE11,"")) | EA11: =IF(OR(CK11="",DF11=""),"",IFERROR(CK11-DF11,"")) | EB11: =IF(OR(CL11="",DG11=""),"",IFERROR(CL11-DG11,"")) | EC11: =IF(OR(CM11="",DH11=""),"",IFERROR(CM11-DH11,"")) | ED11: =IF(OR(CN11="",DI11=""),"",IFERROR(CN11-DI11,"")) | EE11: =IF(OR(CO11="",DJ11=""),"",IFERROR(CO11-DJ11,"")) | EF11: =IF(OR(CP11="",DK11=""),"",IFERROR(CP11-DK11,"")) | EG11: =IF(OR(CQ11="",DL11=""),"",IFERROR(CQ11-DL11,"")) | ... ES11: =IF(OR(DC11="",DX11=""),"",IFERROR(DC11-DX11,"")) | FP11: Hatchling Hideaway
B12: 4 | C12: =IFERROR(LEFT(INDEX(cal_new!$A$3:$AH$3,1,MATCH(1,cal_new!$A$4:$AH$4,0)+B12-1),3),"") | DZ12: =IF(OR(CJ12="",DE12=""),"",IFERROR(CJ12-DE12,"")) | EA12: =IF(OR(CK12="",DF12=""),"",IFERROR(CK12-DF12,"")) | EB12: =IF(OR(CL12="",DG12=""),"",IFERROR(CL12-DG12,"")) | EC12: =IF(OR(CM12="",DH12=""),"",IFERROR(CM12-DH12,"")) | ED12: =IF(OR(CN12="",DI12=""),"",IFERROR(CN12-DI12,"")) | EE12: =IF(OR(CO12="",DJ12=""),"",IFERROR(CO12-DJ12,"")) | EF12: =IF(OR(CP12="",DK12=""),"",IFERROR(CP12-DK12,"")) | EG12: =IF(OR(CQ12="",DL12=""),"",IFERROR(CQ12-DL12,"")) | ... ES12: =IF(OR(DC12="",DX12=""),"",IFERROR(DC12-DX12,"")) | FP12: Jigsaw
B13: 5 | C13: =IFERROR(LEFT(INDEX(cal_new!$A$3:$AH$3,1,MATCH(1,cal_new!$A$4:$AH$4,0)+B13-1),3),"") | DZ13: =IF(OR(CJ13="",DE13=""),"",IFERROR(CJ13-DE13,"")) | EA13: =IF(OR(CK13="",DF13=""),"",IFERROR(CK13-DF13,"")) | EB13: =IF(OR(CL13="",DG13=""),"",IFERROR(CL13-DG13,"")) | EC13: =IF(OR(CM13="",DH13=""),"",IFERROR(CM13-DH13,"")) | ED13: =IF(OR(CN13="",DI13=""),"",IFERROR(CN13-DI13,"")) | EE13: =IF(OR(CO13="",DJ13=""),"",IFERROR(CO13-DJ13,"")) | EF13: =IF(OR(CP13="",DK13=""),"",IFERROR(CP13-DK13,"")) | EG13: =IF(OR(CQ13="",DL13=""),"",IFERROR(CQ13-DL13,"")) | ... ES13: =IF(OR(DC13="",DX13=""),"",IFERROR(DC13-DX13,"")) | FP13: Kite Festival
B14: 6 | C14: =IFERROR(LEFT(INDEX(cal_new!$A$3:$AH$3,1,MATCH(1,cal_new!$A$4:$AH$4,0)+B14-1),3),"") | DZ14: =IF(OR(CJ14="",DE14=""),"",IFERROR(CJ14-DE14,"")) | EA14: =IF(OR(CK14="",DF14=""),"",IFERROR(CK14-DF14,"")) | EB14: =IF(OR(CL14="",DG14=""),"",IFERROR(CL14-DG14,"")) | EC14: =IF(OR(CM14="",DH14=""),"",IFERROR(CM14-DH14,"")) | ED14: =IF(OR(CN14="",DI14=""),"",IFERROR(CN14-DI14,"")) | EE14: =IF(OR(CO14="",DJ14=""),"",IFERROR(CO14-DJ14,"")) | EF14: =IF(OR(CP14="",DK14=""),"",IFERROR(CP14-DK14,"")) | EG14: =IF(OR(CQ14="",DL14=""),"",IFERROR(CQ14-DL14,"")) | ... ES14: =IF(OR(DC14="",DX14=""),"",IFERROR(DC14-DX14,"")) | FP14: Level Race
B15: 7 | C15: =IFERROR(LEFT(INDEX(cal_new!$A$3:$AH$3,1,MATCH(1,cal_new!$A$4:$AH$4,0)+B15-1),3),"") | DZ15: =IF(OR(CJ15="",DE15=""),"",IFERROR(CJ15-DE15,"")) | EA15: =IF(OR(CK15="",DF15=""),"",IFERROR(CK15-DF15,"")) | EB15: =IF(OR(CL15="",DG15=""),"",IFERROR(CL15-DG15,"")) | EC15: =IF(OR(CM15="",DH15=""),"",IFERROR(CM15-DH15,"")) | ED15: =IF(OR(CN15="",DI15=""),"",IFERROR(CN15-DI15,"")) | EE15: =IF(OR(CO15="",DJ15=""),"",IFERROR(CO15-DJ15,"")) | EF15: =IF(OR(CP15="",DK15=""),"",IFERROR(CP15-DK15,"")) | EG15: =IF(OR(CQ15="",DL15=""),"",IFERROR(CQ15-DL15,"")) | ... ES15: =IF(OR(DC15="",DX15=""),"",IFERROR(DC15-DX15,"")) | FP15: Other
B16: 8 | C16: =IFERROR(LEFT(INDEX(cal_new!$A$3:$AH$3,1,MATCH(1,cal_new!$A$4:$AH$4,0)+B16-1),3),"") | DZ16: =IF(OR(CJ16="",DE16=""),"",IFERROR(CJ16-DE16,"")) | EA16: =IF(OR(CK16="",DF16=""),"",IFERROR(CK16-DF16,"")) | EB16: =IF(OR(CL16="",DG16=""),"",IFERROR(CL16-DG16,"")) | EC16: =IF(OR(CM16="",DH16=""),"",IFERROR(CM16-DH16,"")) | ED16: =IF(OR(CN16="",DI16=""),"",IFERROR(CN16-DI16,"")) | EE16: =IF(OR(CO16="",DJ16=""),"",IFERROR(CO16-DJ16,"")) | EF16: =IF(OR(CP16="",DK16=""),"",IFERROR(CP16-DK16,"")) | EG16: =IF(OR(CQ16="",DL16=""),"",IFERROR(CQ16-DL16,"")) | ... ES16: =IF(OR(DC16="",DX16=""),"",IFERROR(DC16-DX16,"")) | FP16: Photoshoot
B17: 9 | C17: =IFERROR(LEFT(INDEX(cal_new!$A$3:$AH$3,1,MATCH(1,cal_new!$A$4:$AH$4,0)+B17-1),3),"") | DZ17: =IF(OR(CJ17="",DE17=""),"",IFERROR(CJ17-DE17,"")) | EA17: =IF(OR(CK17="",DF17=""),"",IFERROR(CK17-DF17,"")) | EB17: =IF(OR(CL17="",DG17=""),"",IFERROR(CL17-DG17,"")) | EC17: =IF(OR(CM17="",DH17=""),"",IFERROR(CM17-DH17,"")) | ED17: =IF(OR(CN17="",DI17=""),"",IFERROR(CN17-DI17,"")) | EE17: =IF(OR(CO17="",DJ17=""),"",IFERROR(CO17-DJ17,"")) | EF17: =IF(OR(CP17="",DK17=""),"",IFERROR(CP17-DK17,"")) | EG17: =IF(OR(CQ17="",DL17=""),"",IFERROR(CQ17-DL17,"")) | ... ES17: =IF(OR(DC17="",DX17=""),"",IFERROR(DC17-DX17,"")) | FP17: Red Challenge
B18: 10 | C18: =IFERROR(LEFT(INDEX(cal_new!$A$3:$AH$3,1,MATCH(1,cal_new!$A$4:$AH$4,0)+B18-1),3),"") | DZ18: =IF(OR(CJ18="",DE18=""),"",IFERROR(CJ18-DE18,"")) | EA18: =IF(OR(CK18="",DF18=""),"",IFERROR(CK18-DF18,"")) | EB18: =IF(OR(CL18="",DG18=""),"",IFERROR(CL18-DG18,"")) | EC18: =IF(OR(CM18="",DH18=""),"",IFERROR(CM18-DH18,"")) | ED18: =IF(OR(CN18="",DI18=""),"",IFERROR(CN18-DI18,"")) | EE18: =IF(OR(CO18="",DJ18=""),"",IFERROR(CO18-DJ18,"")) | EF18: =IF(OR(CP18="",DK18=""),"",IFERROR(CP18-DK18,"")) | EG18: =IF(OR(CQ18="",DL18=""),"",IFERROR(CQ18-DL18,"")) | ... ES18: =IF(OR(DC18="",DX18=""),"",IFERROR(DC18-DX18,"")) | FP18: River Rush
B19: 11 | C19: =IFERROR(LEFT(INDEX(cal_new!$A$3:$AH$3,1,MATCH(1,cal_new!$A$4:$AH$4,0)+B19-1),3),"") | DZ19: =IF(OR(CJ19="",DE19=""),"",IFERROR(CJ19-DE19,"")) | EA19: =IF(OR(CK19="",DF19=""),"",IFERROR(CK19-DF19,"")) | EB19: =IF(OR(CL19="",DG19=""),"",IFERROR(CL19-DG19,"")) | EC19: =IF(OR(CM19="",DH19=""),"",IFERROR(CM19-DH19,"")) | ED19: =IF(OR(CN19="",DI19=""),"",IFERROR(CN19-DI19,"")) | EE19: =IF(OR(CO19="",DJ19=""),"",IFERROR(CO19-DJ19,"")) | EF19: =IF(OR(CP19="",DK19=""),"",IFERROR(CP19-DK19,"")) | EG19: =IF(OR(CQ19="",DL19=""),"",IFERROR(CQ19-DL19,"")) | ... ES19: =IF(OR(DC19="",DX19=""),"",IFERROR(DC19-DX19,"")) | FP19: Saga
B20: 12 | C20: =IFERROR(LEFT(INDEX(cal_new!$A$3:$AH$3,1,MATCH(1,cal_new!$A$4:$AH$4,0)+B20-1),3),"") | DZ20: =IF(OR(CJ20="",DE20=""),"",IFERROR(CJ20-DE20,"")) | EA20: =IF(OR(CK20="",DF20=""),"",IFERROR(CK20-DF20,"")) | EB20: =IF(OR(CL20="",DG20=""),"",IFERROR(CL20-DG20,"")) | EC20: =IF(OR(CM20="",DH20=""),"",IFERROR(CM20-DH20,"")) | ED20: =IF(OR(CN20="",DI20=""),"",IFERROR(CN20-DI20,"")) | EE20: =IF(OR(CO20="",DJ20=""),"",IFERROR(CO20-DJ20,"")) | EF20: =IF(OR(CP20="",DK20=""),"",IFERROR(CP20-DK20,"")) | EG20: =IF(OR(CQ20="",DL20=""),"",IFERROR(CQ20-DL20,"")) | ... ES20: =IF(OR(DC20="",DX20=""),"",IFERROR(DC20-DX20,"")) | FP20: Season Pass (Free)
B21: 13 | C21: =IFERROR(LEFT(INDEX(cal_new!$A$3:$AH$3,1,MATCH(1,cal_new!$A$4:$AH$4,0)+B21-1),3),"") | DZ21: =IF(OR(CJ21="",DE21=""),"",IFERROR(CJ21-DE21,"")) | EA21: =IF(OR(CK21="",DF21=""),"",IFERROR(CK21-DF21,"")) | EB21: =IF(OR(CL21="",DG21=""),"",IFERROR(CL21-DG21,"")) | EC21: =IF(OR(CM21="",DH21=""),"",IFERROR(CM21-DH21,"")) | ED21: =IF(OR(CN21="",DI21=""),"",IFERROR(CN21-DI21,"")) | EE21: =IF(OR(CO21="",DJ21=""),"",IFERROR(CO21-DJ21,"")) | EF21: =IF(OR(CP21="",DK21=""),"",IFERROR(CP21-DK21,"")) | EG21: =IF(OR(CQ21="",DL21=""),"",IFERROR(CQ21-DL21,"")) | ... ES21: =IF(OR(DC21="",DX21=""),"",IFERROR(DC21-DX21,"")) | FP21: Target Day
... B27: 19 | C27: =IFERROR(LEFT(INDEX(cal_new!$A$3:$AH$3,1,MATCH(1,cal_new!$A$4:$AH$4,0)+B27-1),3),"") | DZ27: =IF(OR(CJ27="",DE27=""),"",IFERROR(CJ27-DE27,"")) | EA27: =IF(OR(CK27="",DF27=""),"",IFERROR(CK27-DF27,"")) | EB27: =IF(OR(CL27="",DG27=""),"",IFERROR(CL27-DG27,"")) | EC27: =IF(OR(CM27="",DH27=""),"",IFERROR(CM27-DH27,"")) | ED27: =IF(OR(CN27="",DI27=""),"",IFERROR(CN27-DI27,"")) | EE27: =IF(OR(CO27="",DJ27=""),"",IFERROR(CO27-DJ27,"")) | EF27: =IF(OR(CP27="",DK27=""),"",IFERROR(CP27-DK27,"")) | EG27: =IF(OR(CQ27="",DL27=""),"",IFERROR(CQ27-DL27,"")) | ... ES27: =IF(OR(DC27="",DX27=""),"",IFERROR(DC27-DX27,"")) | FP27: IAPs
B28: 20 | C28: =IFERROR(LEFT(INDEX(cal_new!$A$3:$AH$3,1,MATCH(1,cal_new!$A$4:$AH$4,0)+B28-1),3),"") | DZ28: =IF(OR(CJ28="",DE28=""),"",IFERROR(CJ28-DE28,"")) | EA28: =IF(OR(CK28="",DF28=""),"",IFERROR(CK28-DF28,"")) | EB28: =IF(OR(CL28="",DG28=""),"",IFERROR(CL28-DG28,"")) | EC28: =IF(OR(CM28="",DH28=""),"",IFERROR(CM28-DH28,"")) | ED28: =IF(OR(CN28="",DI28=""),"",IFERROR(CN28-DI28,"")) | EE28: =IF(OR(CO28="",DJ28=""),"",IFERROR(CO28-DJ28,"")) | EF28: =IF(OR(CP28="",DK28=""),"",IFERROR(CP28-DK28,"")) | EG28: =IF(OR(CQ28="",DL28=""),"",IFERROR(CQ28-DL28,"")) | ... ES28: =IF(OR(DC28="",DX28=""),"",IFERROR(DC28-DX28,""))
B29: 21 | C29: =IFERROR(LEFT(INDEX(cal_new!$A$3:$AH$3,1,MATCH(1,cal_new!$A$4:$AH$4,0)+B29-1),3),"") | DZ29: =IF(OR(CJ29="",DE29=""),"",IFERROR(CJ29-DE29,"")) | EA29: =IF(OR(CK29="",DF29=""),"",IFERROR(CK29-DF29,"")) | EB29: =IF(OR(CL29="",DG29=""),"",IFERROR(CL29-DG29,"")) | EC29: =IF(OR(CM29="",DH29=""),"",IFERROR(CM29-DH29,"")) | ED29: =IF(OR(CN29="",DI29=""),"",IFERROR(CN29-DI29,"")) | EE29: =IF(OR(CO29="",DJ29=""),"",IFERROR(CO29-DJ29,"")) | EF29: =IF(OR(CP29="",DK29=""),"",IFERROR(CP29-DK29,"")) | EG29: =IF(OR(CQ29="",DL29=""),"",IFERROR(CQ29-DL29,"")) | ... ES29: =IF(OR(DC29="",DX29=""),"",IFERROR(DC29-DX29,""))
B30: 22 | C30: =IFERROR(LEFT(INDEX(cal_new!$A$3:$AH$3,1,MATCH(1,cal_new!$A$4:$AH$4,0)+B30-1),3),"") | DZ30: =IF(OR(CJ30="",DE30=""),"",IFERROR(CJ30-DE30,"")) | EA30: =IF(OR(CK30="",DF30=""),"",IFERROR(CK30-DF30,"")) | EB30: =IF(OR(CL30="",DG30=""),"",IFERROR(CL30-DG30,"")) | EC30: =IF(OR(CM30="",DH30=""),"",IFERROR(CM30-DH30,"")) | ED30: =IF(OR(CN30="",DI30=""),"",IFERROR(CN30-DI30,"")) | EE30: =IF(OR(CO30="",DJ30=""),"",IFERROR(CO30-DJ30,"")) | EF30: =IF(OR(CP30="",DK30=""),"",IFERROR(CP30-DK30,"")) | EG30: =IF(OR(CQ30="",DL30=""),"",IFERROR(CQ30-DL30,"")) | ... ES30: =IF(OR(DC30="",DX30=""),"",IFERROR(DC30-DX30,""))
B31: 23 | C31: =IFERROR(LEFT(INDEX(cal_new!$A$3:$AH$3,1,MATCH(1,cal_new!$A$4:$AH$4,0)+B31-1),3),"") | DZ31: =IF(OR(CJ31="",DE31=""),"",IFERROR(CJ31-DE31,"")) | EA31: =IF(OR(CK31="",DF31=""),"",IFERROR(CK31-DF31,"")) | EB31: =IF(OR(CL31="",DG31=""),"",IFERROR(CL31-DG31,"")) | EC31: =IF(OR(CM31="",DH31=""),"",IFERROR(CM31-DH31,"")) | ED31: =IF(OR(CN31="",DI31=""),"",IFERROR(CN31-DI31,"")) | EE31: =IF(OR(CO31="",DJ31=""),"",IFERROR(CO31-DJ31,"")) | EF31: =IF(OR(CP31="",DK31=""),"",IFERROR(CP31-DK31,"")) | EG31: =IF(OR(CQ31="",DL31=""),"",IFERROR(CQ31-DL31,"")) | ... ES31: =IF(OR(DC31="",DX31=""),"",IFERROR(DC31-DX31,""))
B32: 24 | C32: =IFERROR(LEFT(INDEX(cal_new!$A$3:$AH$3,1,MATCH(1,cal_new!$A$4:$AH$4,0)+B32-1),3),"") | DZ32: =IF(OR(CJ32="",DE32=""),"",IFERROR(CJ32-DE32,"")) | EA32: =IF(OR(CK32="",DF32=""),"",IFERROR(CK32-DF32,"")) | EB32: =IF(OR(CL32="",DG32=""),"",IFERROR(CL32-DG32,"")) | EC32: =IF(OR(CM32="",DH32=""),"",IFERROR(CM32-DH32,"")) | ED32: =IF(OR(CN32="",DI32=""),"",IFERROR(CN32-DI32,"")) | EE32: =IF(OR(CO32="",DJ32=""),"",IFERROR(CO32-DJ32,"")) | EF32: =IF(OR(CP32="",DK32=""),"",IFERROR(CP32-DK32,"")) | EG32: =IF(OR(CQ32="",DL32=""),"",IFERROR(CQ32-DL32,"")) | ... ES32: =IF(OR(DC32="",DX32=""),"",IFERROR(DC32-DX32,""))
B33: 25 | C33: =IFERROR(LEFT(INDEX(cal_new!$A$3:$AH$3,1,MATCH(1,cal_new!$A$4:$AH$4,0)+B33-1),3),"") | DZ33: =IF(OR(CJ33="",DE33=""),"",IFERROR(CJ33-DE33,"")) | EA33: =IF(OR(CK33="",DF33=""),"",IFERROR(CK33-DF33,"")) | EB33: =IF(OR(CL33="",DG33=""),"",IFERROR(CL33-DG33,"")) | EC33: =IF(OR(CM33="",DH33=""),"",IFERROR(CM33-DH33,"")) | ED33: =IF(OR(CN33="",DI33=""),"",IFERROR(CN33-DI33,"")) | EE33: =IF(OR(CO33="",DJ33=""),"",IFERROR(CO33-DJ33,"")) | EF33: =IF(OR(CP33="",DK33=""),"",IFERROR(CP33-DK33,"")) | EG33: =IF(OR(CQ33="",DL33=""),"",IFERROR(CQ33-DL33,"")) | ... ES33: =IF(OR(DC33="",DX33=""),"",IFERROR(DC33-DX33,""))
B34: 26 | C34: =IFERROR(LEFT(INDEX(cal_new!$A$3:$AH$3,1,MATCH(1,cal_new!$A$4:$AH$4,0)+B34-1),3),"") | DZ34: =IF(OR(CJ34="",DE34=""),"",IFERROR(CJ34-DE34,"")) | EA34: =IF(OR(CK34="",DF34=""),"",IFERROR(CK34-DF34,"")) | EB34: =IF(OR(CL34="",DG34=""),"",IFERROR(CL34-DG34,"")) | EC34: =IF(OR(CM34="",DH34=""),"",IFERROR(CM34-DH34,"")) | ED34: =IF(OR(CN34="",DI34=""),"",IFERROR(CN34-DI34,"")) | EE34: =IF(OR(CO34="",DJ34=""),"",IFERROR(CO34-DJ34,"")) | EF34: =IF(OR(CP34="",DK34=""),"",IFERROR(CP34-DK34,"")) | EG34: =IF(OR(CQ34="",DL34=""),"",IFERROR(CQ34-DL34,"")) | ... ES34: =IF(OR(DC34="",DX34=""),"",IFERROR(DC34-DX34,""))
B35: 27 | C35: =IFERROR(LEFT(INDEX(cal_new!$A$3:$AH$3,1,MATCH(1,cal_new!$A$4:$AH$4,0)+B35-1),3),"") | DZ35: =IF(OR(CJ35="",DE35=""),"",IFERROR(CJ35-DE35,"")) | EA35: =IF(OR(CK35="",DF35=""),"",IFERROR(CK35-DF35,"")) | EB35: =IF(OR(CL35="",DG35=""),"",IFERROR(CL35-DG35,"")) | EC35: =IF(OR(CM35="",DH35=""),"",IFERROR(CM35-DH35,"")) | ED35: =IF(OR(CN35="",DI35=""),"",IFERROR(CN35-DI35,"")) | EE35: =IF(OR(CO35="",DJ35=""),"",IFERROR(CO35-DJ35,"")) | EF35: =IF(OR(CP35="",DK35=""),"",IFERROR(CP35-DK35,"")) | EG35: =IF(OR(CQ35="",DL35=""),"",IFERROR(CQ35-DL35,"")) | ... ES35: =IF(OR(DC35="",DX35=""),"",IFERROR(DC35-DX35,""))
B36: 28 | C36: =IFERROR(LEFT(INDEX(cal_new!$A$3:$AH$3,1,MATCH(1,cal_new!$A$4:$AH$4,0)+B36-1),3),"") | DZ36: =IF(OR(CJ36="",DE36=""),"",IFERROR(CJ36-DE36,"")) | EA36: =IF(OR(CK36="",DF36=""),"",IFERROR(CK36-DF36,"")) | EB36: =IF(OR(CL36="",DG36=""),"",IFERROR(CL36-DG36,"")) | EC36: =IF(OR(CM36="",DH36=""),"",IFERROR(CM36-DH36,"")) | ED36: =IF(OR(CN36="",DI36=""),"",IFERROR(CN36-DI36,"")) | EE36: =IF(OR(CO36="",DJ36=""),"",IFERROR(CO36-DJ36,"")) | EF36: =IF(OR(CP36="",DK36=""),"",IFERROR(CP36-DK36,"")) | EG36: =IF(OR(CQ36="",DL36=""),"",IFERROR(CQ36-DL36,"")) | ... ES36: =IF(OR(DC36="",DX36=""),"",IFERROR(DC36-DX36,""))
B37: TOTAL | D37: =IF(COUNT(D9:D36)=0,"",SUM(D9:D36)) | E37: =IF(COUNT(E9:E36)=0,"",SUM(E9:E36)) | F37: =IF(COUNT(F9:F36)=0,"",SUM(F9:F36)) | G37: =IF(COUNT(G9:G36)=0,"",SUM(G9:G36)) | H37: =IF(COUNT(H9:H36)=0,"",SUM(H9:H36)) | I37: =IF(COUNT(I9:I36)=0,"",SUM(I9:I36)) | J37: =IF(COUNT(J9:J36)=0,"",SUM(J9:J36)) | K37: =IF(COUNT(K9:K36)=0,"",SUM(K9:K36)) | ... W37: =IF(COUNT(W9:W36)=0,"",SUM(W9:W36)) | Y37: =SUM(Y9:Y36) | Z37: =SUM(Z9:Z36) | AA37: =SUM(AA9:AA36) | AB37: =SUM(AB9:AB36) | AC37: =SUM(AC9:AC36) | AD37: =SUM(AD9:AD36) | AE37: =SUM(AE9:AE36) | AF37: =SUM(AF9:AF36) | ... AR37: =SUM(AR9:AR36) | AT37: =IF(COUNT(AT9:AT36)=0,"",SUM(AT9:AT36)) | AU37: =IF(COUNT(AU9:AU36)=0,"",SUM(AU9:AU36)) | AV37: =IF(COUNT(AV9:AV36)=0,"",SUM(AV9:AV36)) | AW37: =IF(COUNT(AW9:AW36)=0,"",SUM(AW9:AW36)) | AX37: =IF(COUNT(AX9:AX36)=0,"",SUM(AX9:AX36)) | AY37: =IF(COUNT(AY9:AY36)=0,"",SUM(AY9:AY36)) | AZ37: =IF(COUNT(AZ9:AZ36)=0,"",SUM(AZ9:AZ36)) | BA37: =IF(COUNT(BA9:BA36)=0,"",SUM(BA9:BA36)) | ... BM37: =IF(COUNT(BM9:BM36)=0,"",SUM(BM9:BM36)) | BO37: =IF(COUNT(BO9:BO36)=0,"",SUM(BO9:BO36)) | BP37: =IF(COUNT(BP9:BP36)=0,"",SUM(BP9:BP36)) | BQ37: =IF(COUNT(BQ9:BQ36)=0,"",SUM(BQ9:BQ36)) | BR37: =IF(COUNT(BR9:BR36)=0,"",SUM(BR9:BR36)) | BS37: =IF(COUNT(BS9:BS36)=0,"",SUM(BS9:BS36)) | BT37: =IF(COUNT(BT9:BT36)=0,"",SUM(BT9:BT36)) | BU37: =IF(COUNT(BU9:BU36)=0,"",SUM(BU9:BU36)) | BV37: =IF(COUNT(BV9:BV36)=0,"",SUM(BV9:BV36)) | ... CH37: =IF(COUNT(CH9:CH36)=0,"",SUM(CH9:CH36)) | CJ37: =IF(COUNT(CJ9:CJ36)=0,"",SUM(CJ9:CJ36)) | CK37: =IF(COUNT(CK9:CK36)=0,"",SUM(CK9:CK36)) | CL37: =IF(COUNT(CL9:CL36)=0,"",SUM(CL9:CL36)) | CM37: =IF(COUNT(CM9:CM36)=0,"",SUM(CM9:CM36)) | CN37: =IF(COUNT(CN9:CN36)=0,"",SUM(CN9:CN36)) | CO37: =IF(COUNT(CO9:CO36)=0,"",SUM(CO9:CO36)) | CP37: =IF(COUNT(CP9:CP36)=0,"",SUM(CP9:CP36)) | CQ37: =IF(COUNT(CQ9:CQ36)=0,"",SUM(CQ9:CQ36)) | ... DC37: =IF(COUNT(DC9:DC36)=0,"",SUM(DC9:DC36)) | DE37: =IF(COUNT(DE9:DE36)=0,"",SUM(DE9:DE36)) | DF37: =IF(COUNT(DF9:DF36)=0,"",SUM(DF9:DF36)) | DG37: =IF(COUNT(DG9:DG36)=0,"",SUM(DG9:DG36)) | DH37: =IF(COUNT(DH9:DH36)=0,"",SUM(DH9:DH36)) | DI37: =IF(COUNT(DI9:DI36)=0,"",SUM(DI9:DI36)) | DJ37: =IF(COUNT(DJ9:DJ36)=0,"",SUM(DJ9:DJ36)) | DK37: =IF(COUNT(DK9:DK36)=0,"",SUM(DK9:DK36)) | DL37: =IF(COUNT(DL9:DL36)=0,"",SUM(DL9:DL36)) | ... DX37: =IF(COUNT(DX9:DX36)=0,"",SUM(DX9:DX36)) | DZ37: =IF(COUNT(DZ9:DZ36)=0,"",SUM(DZ9:DZ36)) | EA37: =IF(COUNT(EA9:EA36)=0,"",SUM(EA9:EA36)) | EB37: =IF(COUNT(EB9:EB36)=0,"",SUM(EB9:EB36)) | EC37: =IF(COUNT(EC9:EC36)=0,"",SUM(EC9:EC36)) | ED37: =IF(COUNT(ED9:ED36)=0,"",SUM(ED9:ED36)) | EE37: =IF(COUNT(EE9:EE36)=0,"",SUM(EE9:EE36)) | EF37: =IF(COUNT(EF9:EF36)=0,"",SUM(EF9:EF36)) | EG37: =IF(COUNT(EG9:EG36)=0,"",SUM(EG9:EG36)) | ... ES37: =IF(COUNT(ES9:ES36)=0,"",SUM(ES9:ES36)) | EU37: =SUM(EU9:EU36) | EV37: =SUM(EV9:EV36) | EW37: =SUM(EW9:EW36) | EX37: =SUM(EX9:EX36) | EY37: =SUM(EY9:EY36) | EZ37: =SUM(EZ9:EZ36) | FA37: =SUM(FA9:FA36) | FB37: =SUM(FB9:FB36) | ... FN37: =SUM(FN9:FN36)
B39: LEGEND / ALLOCATION RULES (D60, 2026-10-14 — EcoGainsSim_Daily.gs, DAILY_ALLOC_MODEL = settle)
B40: CURRENT GAINS, CURRENT SPEND, CURRENT NET are DATA: data_econ_daily, per earner per day (window-earner denominator, so the days of the pull sum to the data_econ window total). They are BLANK past the last day the pull carries — a day with no row is "not pulled yet", never 0 — and blank unless Source = ALL (the data is game-wide).
B41: NEW GAINS is the SIM of cal_new. Δ GAINS = data − sim: positive means the data sits above the sim. While cal_curr is the live calendar this Δ mixes the redesign with model error; the validation lane on the far right (SIM of cal_curr) separates them: data − sim_new = (data − sim_curr) + (sim_curr − sim_new).
B42: NEW NET = data gain + the sim’s day shift (sim NEW − sim cal_curr) − data spend: anchored to the data, so when the redesign changes nothing it equals CURRENT NET exactly. Δ NET = CURRENT NET − NEW NET (data − sim).
B43: PLACEMENT (measured against the data before it was built, harness/_probe_daily_alloc*.js): rank-family lumps (Bomb/Chuck/Red Challenge, Level Race, Flash Race, Target Day, Kite, Team Event, Team Race, Flock Flurry) land the DATE AFTER the grid cell — a 1-day cell is a 2-date event, the board settles and pays on the next date. Authored per source on the optional sim_settle sheet (settle_days; lag_0..2 to spread a payout over +0/+1/+2 once the lag data exists). The 7-day view sums the EARN day instead.
B44: Collections (Hatchling Hideaway, Bomb’s Ballet, Jigsaw, Photoshoot) spread by the MEAN accrual curve’s marginal; Season Pass (Free/Paid) spreads ∝ active rate over every day its lane is open (no reach split — the 3-day stub artefact is gone); Core / Saga / Daily Gift pay daily ∝ weekday/weekend active rate; Night Sky over its daily instances; Rainbow Maker ∝ active rate within its instances. Non-calendar sources (Ads, Other, IAPs, FlowerCoop) are flat over the window. River Rush must be DRAWN on cal_curr — off-grid it is flat and SPTx2 is placed on the wrong days.
B45: Reading the comparison: a single day’s % is NOT a verdict — the data’s own day-to-day CV is 17–29% for the smooth resources. Read cumulative-through-day-N (N ≥ 7) against the resource’s week-over-week CV (HC 2–12%, boosters 3–22%, UL 10–30%), and timing on 3-day centred sums (±1 day). SPT is dominated by the synthetic Core anchor and SPTx2 by River Rush’s schedule until those are fixed.
B46: WINDOW: 28 days, day 1 = the column holding the first 1 on the calendars' day-number row (row 4); the blacked-out columns before it are not counted, but cal_curr's events there still scale the measured side to the window (D71). The data blocks read the pull by calendar day, so re-pull data_econ_daily_live with window_start_date = the date of day 1.
...
