Workbook

Sheet TaD_v2
A1: Target Day | AH1: Player Rank Simulation (measured rank percentile → ladder reward) — SIMULATED
A2: Config Panel | AH2: Percentile | AI2: p50
A3: winStreakMultipliers | B3: 1, 5, 10, 20, 100 | AH3: Payer | AI3: NONPAYER
A4: levelDifficultyMultiplier | B4: "normal": 1, "hard": 1, "extreme": 1
A5: desiredBotCounts | B5: "easy": 9, "medium": 6, "hard": 3, "extreme": 1 | AH5: Event | AI5: 0-9_pos | AJ5: 0-9_reward | AK5: 10-19_pos | AL5: 10-19_reward | AM5: 20-39_pos | AN5: 20-39_reward | AO5: 40-99_pos | AP5: 40-99_reward | AQ5: 100_pos | AR5: 100_reward
A6: requiredSagaLevel | B6: 25 | AH6: Target Day (LB) | AI6: =LET(pos,CHOOSE(MATCH($AI$2,{"p25","p50","p75"},0),SUMIFS(data_event_inst!$K:$K,data_event_inst!$A:$A,"Target Day",data_event_inst!$B:$B,$AI$3,data_event_inst!$C:$C,"0-9"),SUMIFS(data_event_inst!$L:$L,data_event_inst!$A:$A,"Target Day",data_event_inst!$B:$B,$AI$3,data_event_inst!$C:$C,"0-9"),SUMIFS(data_event_inst!$M:$M,data_event_inst!$A:$A,"Target Day",data_event_inst!$B:$B,$AI$3,data_event_inst!$C:$C,"0-9")),IF(pos=0,"n/a",pos)) | AJ6: =LET(p,AI6,IF(p="n/a","n/a",IF(p>20,"— (below ladder)",LET(s,INDEX($C$36:$W$55,p,0),b,TEXTJOIN(", ",TRUE,ARRAYFORMULA(IF(s>0,$C$35:$W$35&": "&ROUND(s,2),""))),IF(b="","{} (rank pays nothing)","{"&b&"}"))))) | AK6: =LET(pos,CHOOSE(MATCH($AI$2,{"p25","p50","p75"},0),SUMIFS(data_event_inst!$K:$K,data_event_inst!$A:$A,"Target Day",data_event_inst!$B:$B,$AI$3,data_event_inst!$C:$C,"10-19"),SUMIFS(data_event_inst!$L:$L,data_event_inst!$A:$A,"Target Day",data_event_inst!$B:$B,$AI$3,data_event_inst!$C:$C,"10-19"),SUMIFS(data_event_inst!$M:$M,data_event_inst!$A:$A,"Target Day",data_event_inst!$B:$B,$AI$3,data_event_inst!$C:$C,"10-19")),IF(pos=0,"n/a",pos)) | AL6: =LET(p,AK6,IF(p="n/a","n/a",IF(p>20,"— (below ladder)",LET(s,INDEX($C$36:$W$55,p,0),b,TEXTJOIN(", ",TRUE,ARRAYFORMULA(IF(s>0,$C$35:$W$35&": "&ROUND(s,2),""))),IF(b="","{} (rank pays nothing)","{"&b&"}"))))) | AM6: =LET(pos,CHOOSE(MATCH($AI$2,{"p25","p50","p75"},0),SUMIFS(data_event_inst!$K:$K,data_event_inst!$A:$A,"Target Day",data_event_inst!$B:$B,$AI$3,data_event_inst!$C:$C,"20-39"),SUMIFS(data_event_inst!$L:$L,data_event_inst!$A:$A,"Target Day",data_event_inst!$B:$B,$AI$3,data_event_inst!$C:$C,"20-39"),SUMIFS(data_event_inst!$M:$M,data_event_inst!$A:$A,"Target Day",data_event_inst!$B:$B,$AI$3,data_event_inst!$C:$C,"20-39")),IF(pos=0,"n/a",pos)) | AN6: =LET(p,AM6,IF(p="n/a","n/a",IF(p>20,"— (below ladder)",LET(s,INDEX($C$36:$W$55,p,0),b,TEXTJOIN(", ",TRUE,ARRAYFORMULA(IF(s>0,$C$35:$W$35&": "&ROUND(s,2),""))),IF(b="","{} (rank pays nothing)","{"&b&"}"))))) | AO6: =LET(pos,CHOOSE(MATCH($AI$2,{"p25","p50","p75"},0),SUMIFS(data_event_inst!$K:$K,data_event_inst!$A:$A,"Target Day",data_event_inst!$B:$B,$AI$3,data_event_inst!$C:$C,"40-99"),SUMIFS(data_event_inst!$L:$L,data_event_inst!$A:$A,"Target Day",data_event_inst!$B:$B,$AI$3,data_event_inst!$C:$C,"40-99"),SUMIFS(data_event_inst!$M:$M,data_event_inst!$A:$A,"Target Day",data_event_inst!$B:$B,$AI$3,data_event_inst!$C:$C,"40-99")),IF(pos=0,"n/a",pos)) | AP6: =LET(p,AO6,IF(p="n/a","n/a",IF(p>20,"— (below ladder)",LET(s,INDEX($C$36:$W$55,p,0),b,TEXTJOIN(", ",TRUE,ARRAYFORMULA(IF(s>0,$C$35:$W$35&": "&ROUND(s,2),""))),IF(b="","{} (rank pays nothing)","{"&b&"}"))))) | AQ6: =LET(pos,CHOOSE(MATCH($AI$2,{"p25","p50","p75"},0),SUMIFS(data_event_inst!$K:$K,data_event_inst!$A:$A,"Target Day",data_event_inst!$B:$B,$AI$3,data_event_inst!$C:$C,"100+"),SUMIFS(data_event_inst!$L:$L,data_event_inst!$A:$A,"Target Day",data_event_inst!$B:$B,$AI$3,data_event_inst!$C:$C,"100+"),SUMIFS(data_event_inst!$M:$M,data_event_inst!$A:$A,"Target Day",data_event_inst!$B:$B,$AI$3,data_event_inst!$C:$C,"100+")),IF(pos=0,"n/a",pos)) | AR6: =LET(p,AQ6,IF(p="n/a","n/a",IF(p>20,"— (below ladder)",LET(s,INDEX($C$36:$W$55,p,0),b,TEXTJOIN(", ",TRUE,ARRAYFORMULA(IF(s>0,$C$35:$W$35&": "&ROUND(s,2),""))),IF(b="","{} (rank pays nothing)","{"&b&"}")))))
A7: EventDuration | B7: 1
AH8: p25 = top-quartile finisher (lower position = better); source: data_event_inst position percentiles, measured on the CURRENT calendar
A9: Milestone Goals and Rewards | AH9: ⚠ leaderboard track only — milestone ladder NOT simulated (all milestone reward cells are 0 in TaD/TaD_v2 config; deliberate scope cut)
A10: Milestone | B10: Total score requirement | C10: Coins | D10: SPT | E10: SPT x2 | F10: Red | G10: Chuck | H10: Bomb | I10: Slingshot | J10: Shuffle | K10: Comet | L10: Unlimited Lives | M10: Unlimited Red | N10: Unlimited Chuck | O10: Unlimited Bomb | P10: COOP Token | Q10: Avatar | R10: 1-star Dly | S10: 2-star Dly | T10: 3-star Dly | U10: 4-star Dly | V10: 5-star Dly | W10: 6-star Dly | AH10: ⚠ LB size 50 per config; measured avg_bots ≈ 0–1; positions 11–20 configured but pay nothing
A11: 1 | B11: 100 | C11: 0 | D11: 0 | E11: 0 | F11: 0 | G11: 0 | H11: 0 | I11: 0 | J11: 0 | K11: 0 | L11: 0 | M11: 0 | N11: 0 | O11: 0 | P11: 0 | Q11: 0 | R11: 0 | S11: 0 | T11: 0 | U11: 0 | V11: 0 | W11: 0
A12: 2 | B12: 300 | C12: 0 | D12: 0 | E12: 0 | F12: 0 | G12: 0 | H12: 0 | I12: 0 | J12: 0 | K12: 0 | L12: 0 | M12: 0 | N12: 0 | O12: 0 | P12: 0 | Q12: 0 | R12: 0 | S12: 0 | T12: 0 | U12: 0 | V12: 0 | W12: 0
A13: 3 | B13: 500 | C13: 0 | D13: 0 | E13: 0 | F13: 0 | G13: 0 | H13: 0 | I13: 0 | J13: 0 | K13: 0 | L13: 0 | M13: 0 | N13: 0 | O13: 0 | P13: 0 | Q13: 0 | R13: 0 | S13: 0 | T13: 0 | U13: 0 | V13: 0 | W13: 0
A14: 4 | B14: 700 | C14: 0 | D14: 0 | E14: 0 | F14: 0 | G14: 0 | H14: 0 | I14: 0 | J14: 0 | K14: 0 | L14: 0 | M14: 0 | N14: 0 | O14: 0 | P14: 0 | Q14: 0 | R14: 0 | S14: 0 | T14: 0 | U14: 0 | V14: 0 | W14: 0
A15: 5 | B15: 2000 | C15: 0 | D15: 0 | E15: 0 | F15: 0 | G15: 0 | H15: 0 | I15: 0 | J15: 0 | K15: 0 | L15: 0 | M15: 0 | N15: 0 | O15: 0 | P15: 0 | Q15: 0 | R15: 0 | S15: 0 | T15: 0 | U15: 0 | V15: 0 | W15: 0
A16: 6 | B16: 3000 | C16: 0 | D16: 0 | E16: 0 | F16: 0 | G16: 0 | H16: 0 | I16: 0 | J16: 0 | K16: 0 | L16: 0 | M16: 0 | N16: 0 | O16: 0 | P16: 0 | Q16: 0 | R16: 0 | S16: 0 | T16: 0 | U16: 0 | V16: 0 | W16: 0
A17: 7 | B17: 4000 | C17: 0 | D17: 0 | E17: 0 | F17: 0 | G17: 0 | H17: 0 | I17: 0 | J17: 0 | K17: 0 | L17: 0 | M17: 0 | N17: 0 | O17: 0 | P17: 0 | Q17: 0 | R17: 0 | S17: 0 | T17: 0 | U17: 0 | V17: 0 | W17: 0
A18: 8 | B18: 5500 | C18: 0 | D18: 0 | E18: 0 | F18: 0 | G18: 0 | H18: 0 | I18: 0 | J18: 0 | K18: 0 | L18: 0 | M18: 0 | N18: 0 | O18: 0 | P18: 0 | Q18: 0 | R18: 0 | S18: 0 | T18: 0 | U18: 0 | V18: 0 | W18: 0
A19: 9 | B19: 7000 | C19: 0 | D19: 0 | E19: 0 | F19: 0 | G19: 0 | H19: 0 | I19: 0 | J19: 0 | K19: 0 | L19: 0 | M19: 0 | N19: 0 | O19: 0 | P19: 0 | Q19: 0 | R19: 0 | S19: 0 | T19: 0 | U19: 0 | V19: 0 | W19: 0
A20: 10 | B20: 8500 | C20: 0 | D20: 0 | E20: 0 | F20: 0 | G20: 0 | H20: 0 | I20: 0 | J20: 0 | K20: 0 | L20: 0 | M20: 0 | N20: 0 | O20: 0 | P20: 0 | Q20: 0 | R20: 0 | S20: 0 | T20: 0 | U20: 0 | V20: 0 | W20: 0
A21: 11 | B21: 10000 | C21: 0 | D21: 0 | E21: 0 | F21: 0 | G21: 0 | H21: 0 | I21: 0 | J21: 0 | K21: 0 | L21: 0 | M21: 0 | N21: 0 | O21: 0 | P21: 0 | Q21: 0 | R21: 0 | S21: 0 | T21: 0 | U21: 0 | V21: 0 | W21: 0
A22: 12 | B22: 11500 | C22: 0 | D22: 0 | E22: 0 | F22: 0 | G22: 0 | H22: 0 | I22: 0 | J22: 0 | K22: 0 | L22: 0 | M22: 0 | N22: 0 | O22: 0 | P22: 0 | Q22: 0 | R22: 0 | S22: 0 | T22: 0 | U22: 0 | V22: 0 | W22: 0
... A30: 20 | B30: 23500 | C30: 0 | D30: 0 | E30: 0 | F30: 0 | G30: 0 | H30: 0 | I30: 0 | J30: 0 | K30: 0 | L30: 0 | M30: 0 | N30: 0 | O30: 0 | P30: 0 | Q30: 0 | R30: 0 | S30: 0 | T30: 0 | U30: 0 | V30: 0 | W30: 0
A34: Leaderboard Goals and Rewards
A35: LB# | C35: Coins | D35: SPT | E35: SPT x2 | F35: Red | G35: Chuck | H35: Bomb | I35: Slingshot | J35: Shuffle | K35: Comet | L35: Unlimited Lives | M35: Unlimited Red | N35: Unlimited Chuck | O35: Unlimited Bomb | P35: COOP Token | Q35: Avatar | R35: 1-star Dly | S35: 2-star Dly | T35: 3-star Dly | U35: 4-star Dly | V35: 5-star Dly | W35: 6-star Dly
A36: 1 | C36: 200 | D36: 0 | E36: 0 | F36: 0 | G36: 0 | H36: 0 | I36: 0 | J36: 0 | K36: 1 | L36: 0 | M36: 0 | N36: 0 | O36: 0 | P36: 0 | Q36: 0 | R36: 0 | S36: 0 | T36: 0 | U36: 0 | V36: 0 | W36: 0
A37: 2 | C37: 100 | D37: 0 | E37: 0 | F37: 0 | G37: 0 | H37: 0 | I37: 0 | J37: 1 | K37: 0 | L37: 0 | M37: 0 | N37: 0 | O37: 0 | P37: 0 | Q37: 0 | R37: 0 | S37: 0 | T37: 0 | U37: 0 | V37: 0 | W37: 0
A38: 3 | C38: 50 | D38: 0 | E38: 0 | F38: 0 | G38: 0 | H38: 0 | I38: 1 | J38: 0 | K38: 0 | L38: 0 | M38: 0 | N38: 0 | O38: 0 | P38: 0 | Q38: 0 | R38: 0 | S38: 0 | T38: 0 | U38: 0 | V38: 0 | W38: 0
A39: 4 | C39: 0 | D39: 0 | E39: 0 | F39: 0 | G39: 0 | H39: 0 | I39: 0 | J39: 1 | K39: 0 | L39: 0 | M39: 0 | N39: 0 | O39: 0 | P39: 0 | Q39: 0 | R39: 0 | S39: 0 | T39: 0 | U39: 0 | V39: 0 | W39: 0
A40: 5 | C40: 0 | D40: 0 | E40: 0 | F40: 0 | G40: 0 | H40: 0 | I40: 0 | J40: 1 | K40: 0 | L40: 0 | M40: 0 | N40: 0 | O40: 0 | P40: 0 | Q40: 0 | R40: 0 | S40: 0 | T40: 0 | U40: 0 | V40: 0 | W40: 0
A41: 6 | C41: 0 | D41: 0 | E41: 0 | F41: 0 | G41: 0 | H41: 0 | I41: 1 | J41: 0 | K41: 0 | L41: 0 | M41: 0 | N41: 0 | O41: 0 | P41: 0 | Q41: 0 | R41: 0 | S41: 0 | T41: 0 | U41: 0 | V41: 0 | W41: 0
A42: 7 | C42: 0 | D42: 0 | E42: 0 | F42: 0 | G42: 0 | H42: 0 | I42: 1 | J42: 0 | K42: 0 | L42: 0 | M42: 0 | N42: 0 | O42: 0 | P42: 0 | Q42: 0 | R42: 0 | S42: 0 | T42: 0 | U42: 0 | V42: 0 | W42: 0
A43: 8 | C43: 0 | D43: 0 | E43: 0 | F43: 0 | G43: 0 | H43: 0 | I43: 1 | J43: 0 | K43: 0 | L43: 0 | M43: 0 | N43: 0 | O43: 0 | P43: 0 | Q43: 0 | R43: 0 | S43: 0 | T43: 0 | U43: 0 | V43: 0 | W43: 0
A44: 9 | C44: 0 | D44: 0 | E44: 0 | F44: 0 | G44: 0 | H44: 0 | I44: 1 | J44: 0 | K44: 0 | L44: 0 | M44: 0 | N44: 0 | O44: 0 | P44: 0 | Q44: 0 | R44: 0 | S44: 0 | T44: 0 | U44: 0 | V44: 0 | W44: 0
A45: 10 | C45: 0 | D45: 0 | E45: 0 | F45: 0 | G45: 0 | H45: 0 | I45: 1 | J45: 0 | K45: 0 | L45: 0 | M45: 0 | N45: 0 | O45: 0 | P45: 0 | Q45: 0 | R45: 0 | S45: 0 | T45: 0 | U45: 0 | V45: 0 | W45: 0
A46: 11 | C46: 0 | D46: 0 | E46: 0 | F46: 0 | G46: 0 | H46: 0 | I46: 0 | J46: 0 | K46: 0 | L46: 0 | M46: 0 | N46: 0 | O46: 0 | P46: 0 | Q46: 0 | R46: 0 | S46: 0 | T46: 0 | U46: 0 | V46: 0 | W46: 0
A47: 12 | C47: 0 | D47: 0 | E47: 0 | F47: 0 | G47: 0 | H47: 0 | I47: 0 | J47: 0 | K47: 0 | L47: 0 | M47: 0 | N47: 0 | O47: 0 | P47: 0 | Q47: 0 | R47: 0 | S47: 0 | T47: 0 | U47: 0 | V47: 0 | W47: 0
... A55: 20 | C55: 0 | D55: 0 | E55: 0 | F55: 0 | G55: 0 | H55: 0 | I55: 0 | J55: 0 | K55: 0 | L55: 0 | M55: 0 | N55: 0 | O55: 0 | P55: 0 | Q55: 0 | R55: 0 | S55: 0 | T55: 0 | U55: 0 | V55: 0 | W55: 0

Sheet F_v2
A1: Flock Flurry | AH1: Player Rank Simulation (measured rank percentile → ladder reward) — SIMULATED
A2: Config Panel | AH2: Percentile | AI2: p50
A3: Total Players | B3: 5 | AH3: Payer | AI3: NONPAYER
A4: Days | B4: 1
A5: Player level | B5: 1 | AH5: Event | AI5: 0-9_pos | AJ5: 0-9_reward | AK5: 10-19_pos | AL5: 10-19_reward | AM5: 20-39_pos | AN5: 20-39_reward | AO5: 40-99_pos | AP5: 40-99_reward | AQ5: 100_pos | AR5: 100_reward
A6: Level unlock | B6: 27 | AH6: Flock Flurry | AI6: =LET(pos,CHOOSE(MATCH($AI$2,{"p25","p50","p75"},0),SUMIFS(data_event_inst!$K:$K,data_event_inst!$A:$A,"Flock Flurry",data_event_inst!$B:$B,$AI$3,data_event_inst!$C:$C,"0-9"),SUMIFS(data_event_inst!$L:$L,data_event_inst!$A:$A,"Flock Flurry",data_event_inst!$B:$B,$AI$3,data_event_inst!$C:$C,"0-9"),SUMIFS(data_event_inst!$M:$M,data_event_inst!$A:$A,"Flock Flurry",data_event_inst!$B:$B,$AI$3,data_event_inst!$C:$C,"0-9")),IF(pos=0,"n/a",pos)) | AJ6: =LET(p,AI6,IF(p="n/a","n/a",IF(p>5,"— (below ladder)",LET(s,INDEX($B$11:$V$15,p,0),b,TEXTJOIN(", ",TRUE,ARRAYFORMULA(IF(s>0,$B$10:$V$10&": "&ROUND(s,2),""))),IF(b="","{} (rank pays nothing)","{"&b&"}"))))) | AK6: =LET(pos,CHOOSE(MATCH($AI$2,{"p25","p50","p75"},0),SUMIFS(data_event_inst!$K:$K,data_event_inst!$A:$A,"Flock Flurry",data_event_inst!$B:$B,$AI$3,data_event_inst!$C:$C,"10-19"),SUMIFS(data_event_inst!$L:$L,data_event_inst!$A:$A,"Flock Flurry",data_event_inst!$B:$B,$AI$3,data_event_inst!$C:$C,"10-19"),SUMIFS(data_event_inst!$M:$M,data_event_inst!$A:$A,"Flock Flurry",data_event_inst!$B:$B,$AI$3,data_event_inst!$C:$C,"10-19")),IF(pos=0,"n/a",pos)) | AL6: =LET(p,AK6,IF(p="n/a","n/a",IF(p>5,"— (below ladder)",LET(s,INDEX($B$11:$V$15,p,0),b,TEXTJOIN(", ",TRUE,ARRAYFORMULA(IF(s>0,$B$10:$V$10&": "&ROUND(s,2),""))),IF(b="","{} (rank pays nothing)","{"&b&"}"))))) | AM6: =LET(pos,CHOOSE(MATCH($AI$2,{"p25","p50","p75"},0),SUMIFS(data_event_inst!$K:$K,data_event_inst!$A:$A,"Flock Flurry",data_event_inst!$B:$B,$AI$3,data_event_inst!$C:$C,"20-39"),SUMIFS(data_event_inst!$L:$L,data_event_inst!$A:$A,"Flock Flurry",data_event_inst!$B:$B,$AI$3,data_event_inst!$C:$C,"20-39"),SUMIFS(data_event_inst!$M:$M,data_event_inst!$A:$A,"Flock Flurry",data_event_inst!$B:$B,$AI$3,data_event_inst!$C:$C,"20-39")),IF(pos=0,"n/a",pos)) | AN6: =LET(p,AM6,IF(p="n/a","n/a",IF(p>5,"— (below ladder)",LET(s,INDEX($B$11:$V$15,p,0),b,TEXTJOIN(", ",TRUE,ARRAYFORMULA(IF(s>0,$B$10:$V$10&": "&ROUND(s,2),""))),IF(b="","{} (rank pays nothing)","{"&b&"}"))))) | AO6: =LET(pos,CHOOSE(MATCH($AI$2,{"p25","p50","p75"},0),SUMIFS(data_event_inst!$K:$K,data_event_inst!$A:$A,"Flock Flurry",data_event_inst!$B:$B,$AI$3,data_event_inst!$C:$C,"40-99"),SUMIFS(data_event_inst!$L:$L,data_event_inst!$A:$A,"Flock Flurry",data_event_inst!$B:$B,$AI$3,data_event_inst!$C:$C,"40-99"),SUMIFS(data_event_inst!$M:$M,data_event_inst!$A:$A,"Flock Flurry",data_event_inst!$B:$B,$AI$3,data_event_inst!$C:$C,"40-99")),IF(pos=0,"n/a",pos)) | AP6: =LET(p,AO6,IF(p="n/a","n/a",IF(p>5,"— (below ladder)",LET(s,INDEX($B$11:$V$15,p,0),b,TEXTJOIN(", ",TRUE,ARRAYFORMULA(IF(s>0,$B$10:$V$10&": "&ROUND(s,2),""))),IF(b="","{} (rank pays nothing)","{"&b&"}"))))) | AQ6: =LET(pos,CHOOSE(MATCH($AI$2,{"p25","p50","p75"},0),SUMIFS(data_event_inst!$K:$K,data_event_inst!$A:$A,"Flock Flurry",data_event_inst!$B:$B,$AI$3,data_event_inst!$C:$C,"100+"),SUMIFS(data_event_inst!$L:$L,data_event_inst!$A:$A,"Flock Flurry",data_event_inst!$B:$B,$AI$3,data_event_inst!$C:$C,"100+"),SUMIFS(data_event_inst!$M:$M,data_event_inst!$A:$A,"Flock Flurry",data_event_inst!$B:$B,$AI$3,data_event_inst!$C:$C,"100+")),IF(pos=0,"n/a",pos)) | AR6: =LET(p,AQ6,IF(p="n/a","n/a",IF(p>5,"— (below ladder)",LET(s,INDEX($B$11:$V$15,p,0),b,TEXTJOIN(", ",TRUE,ARRAYFORMULA(IF(s>0,$B$10:$V$10&": "&ROUND(s,2),""))),IF(b="","{} (rank pays nothing)","{"&b&"}")))))
A7: EventDuration (days) | B7: 1
AH8: p25 = top-quartile finisher (lower position = better); source: data_event_inst position percentiles, measured on the CURRENT calendar
A9: Goals and Rewards | AH9: ⚠ winner-take-all: only position 1 pays (20 SPT + 4 boosters); SPT is outside the 11-resource universe
A10: Position | B10: Coins | C10: SPT | D10: SPT x2 | E10: Red | F10: Chuck | G10: Bomb | H10: Slingshot | I10: Shuffle | J10: Comet | K10: Unlimited Lives | L10: Unlimited Red | M10: Unlimited Chuck | N10: Unlimited Bomb | O10: COOP Token | P10: Avatar | Q10: 1-star Dly | R10: 2-star Dly | S10: 3-star Dly | T10: 4-star Dly | U10: 5-star Dly | V10: 6-star Dly | AH10: ⚠ the 1h Unlimited Lives on opt-in is a JOIN grant, not a rank reward — not shown here (see flock-flurry.md)
A11: 1 | B11: 0 | C11: 20 | D11: 0 | E11: 1 | F11: 1 | G11: 1 | H11: 1 | I11: 0 | J11: 0 | K11: 0 | L11: 0 | M11: 0 | N11: 0 | O11: 0 | P11: 0 | Q11: 0 | R11: 0 | S11: 0 | T11: 0 | U11: 0 | V11: 0
A12: 2 | B12: 0 | C12: 0 | D12: 0 | E12: 0 | F12: 0 | G12: 0 | H12: 0 | I12: 0 | J12: 0 | K12: 0 | L12: 0 | M12: 0 | N12: 0 | O12: 0 | P12: 0 | Q12: 0 | R12: 0 | S12: 0 | T12: 0 | U12: 0 | V12: 0
A13: 3 | B13: 0 | C13: 0 | D13: 0 | E13: 0 | F13: 0 | G13: 0 | H13: 0 | I13: 0 | J13: 0 | K13: 0 | L13: 0 | M13: 0 | N13: 0 | O13: 0 | P13: 0 | Q13: 0 | R13: 0 | S13: 0 | T13: 0 | U13: 0 | V13: 0
A14: 4 | B14: 0 | C14: 0 | D14: 0 | E14: 0 | F14: 0 | G14: 0 | H14: 0 | I14: 0 | J14: 0 | K14: 0 | L14: 0 | M14: 0 | N14: 0 | O14: 0 | P14: 0 | Q14: 0 | R14: 0 | S14: 0 | T14: 0 | U14: 0 | V14: 0
A15: 5 | B15: 0 | C15: 0 | D15: 0 | E15: 0 | F15: 0 | G15: 0 | H15: 0 | I15: 0 | J15: 0 | K15: 0 | L15: 0 | M15: 0 | N15: 0 | O15: 0 | P15: 0 | Q15: 0 | R15: 0 | S15: 0 | T15: 0 | U15: 0 | V15: 0

Sheet Race_v2
A1: All LB Challenges | AH1: Player Rank Simulation (measured rank percentile → ladder reward) — SIMULATED
AH2: Percentile | AI2: p50
A3: Red's Challenge - Config Panel | AH3: Payer | AI3: NONPAYER
A4: numberOfPositions | B4: 10
A5: LBSize | B5: 10 | AH5: Event | AI5: 0-9_pos | AJ5: 0-9_reward | AK5: 10-19_pos | AL5: 10-19_reward | AM5: 20-39_pos | AN5: 20-39_reward | AO5: 40-99_pos | AP5: 40-99_reward | AQ5: 100_pos | AR5: 100_reward
A6: EventDuration | B6: 2 | AH6: Red Challenge | AI6: =LET(pos,CHOOSE(MATCH($AI$2,{"p25","p50","p75"},0),SUMIFS(data_event_inst!$K:$K,data_event_inst!$A:$A,"Red",data_event_inst!$B:$B,$AI$3,data_event_inst!$C:$C,"0-9"),SUMIFS(data_event_inst!$L:$L,data_event_inst!$A:$A,"Red",data_event_inst!$B:$B,$AI$3,data_event_inst!$C:$C,"0-9"),SUMIFS(data_event_inst!$M:$M,data_event_inst!$A:$A,"Red",data_event_inst!$B:$B,$AI$3,data_event_inst!$C:$C,"0-9")),IF(pos=0,"n/a",pos)) | AJ6: =LET(p,AI6,IF(p="n/a","n/a",IF(p>10,"— (below ladder)",LET(s,INDEX($B$10:$V$19,p,0),b,TEXTJOIN(", ",TRUE,ARRAYFORMULA(IF(s>0,$B$9:$V$9&": "&ROUND(s,2),""))),IF(b="","{} (rank pays nothing)","{"&b&"}"))))) | AK6: =LET(pos,CHOOSE(MATCH($AI$2,{"p25","p50","p75"},0),SUMIFS(data_event_inst!$K:$K,data_event_inst!$A:$A,"Red",data_event_inst!$B:$B,$AI$3,data_event_inst!$C:$C,"10-19"),SUMIFS(data_event_inst!$L:$L,data_event_inst!$A:$A,"Red",data_event_inst!$B:$B,$AI$3,data_event_inst!$C:$C,"10-19"),SUMIFS(data_event_inst!$M:$M,data_event_inst!$A:$A,"Red",data_event_inst!$B:$B,$AI$3,data_event_inst!$C:$C,"10-19")),IF(pos=0,"n/a",pos)) | AL6: =LET(p,AK6,IF(p="n/a","n/a",IF(p>10,"— (below ladder)",LET(s,INDEX($B$10:$V$19,p,0),b,TEXTJOIN(", ",TRUE,ARRAYFORMULA(IF(s>0,$B$9:$V$9&": "&ROUND(s,2),""))),IF(b="","{} (rank pays nothing)","{"&b&"}"))))) | AM6: =LET(pos,CHOOSE(MATCH($AI$2,{"p25","p50","p75"},0),SUMIFS(data_event_inst!$K:$K,data_event_inst!$A:$A,"Red",data_event_inst!$B:$B,$AI$3,data_event_inst!$C:$C,"20-39"),SUMIFS(data_event_inst!$L:$L,data_event_inst!$A:$A,"Red",data_event_inst!$B:$B,$AI$3,data_event_inst!$C:$C,"20-39"),SUMIFS(data_event_inst!$M:$M,data_event_inst!$A:$A,"Red",data_event_inst!$B:$B,$AI$3,data_event_inst!$C:$C,"20-39")),IF(pos=0,"n/a",pos)) | AN6: =LET(p,AM6,IF(p="n/a","n/a",IF(p>10,"— (below ladder)",LET(s,INDEX($B$10:$V$19,p,0),b,TEXTJOIN(", ",TRUE,ARRAYFORMULA(IF(s>0,$B$9:$V$9&": "&ROUND(s,2),""))),IF(b="","{} (rank pays nothing)","{"&b&"}"))))) | AO6: =LET(pos,CHOOSE(MATCH($AI$2,{"p25","p50","p75"},0),SUMIFS(data_event_inst!$K:$K,data_event_inst!$A:$A,"Red",data_event_inst!$B:$B,$AI$3,data_event_inst!$C:$C,"40-99"),SUMIFS(data_event_inst!$L:$L,data_event_inst!$A:$A,"Red",data_event_inst!$B:$B,$AI$3,data_event_inst!$C:$C,"40-99"),SUMIFS(data_event_inst!$M:$M,data_event_inst!$A:$A,"Red",data_event_inst!$B:$B,$AI$3,data_event_inst!$C:$C,"40-99")),IF(pos=0,"n/a",pos)) | AP6: =LET(p,AO6,IF(p="n/a","n/a",IF(p>10,"— (below ladder)",LET(s,INDEX($B$10:$V$19,p,0),b,TEXTJOIN(", ",TRUE,ARRAYFORMULA(IF(s>0,$B$9:$V$9&": "&ROUND(s,2),""))),IF(b="","{} (rank pays nothing)","{"&b&"}"))))) | AQ6: =LET(pos,CHOOSE(MATCH($AI$2,{"p25","p50","p75"},0),SUMIFS(data_event_inst!$K:$K,data_event_inst!$A:$A,"Red",data_event_inst!$B:$B,$AI$3,data_event_inst!$C:$C,"100+"),SUMIFS(data_event_inst!$L:$L,data_event_inst!$A:$A,"Red",data_event_inst!$B:$B,$AI$3,data_event_inst!$C:$C,"100+"),SUMIFS(data_event_inst!$M:$M,data_event_inst!$A:$A,"Red",data_event_inst!$B:$B,$AI$3,data_event_inst!$C:$C,"100+")),IF(pos=0,"n/a",pos)) | AR6: =LET(p,AQ6,IF(p="n/a","n/a",IF(p>10,"— (below ladder)",LET(s,INDEX($B$10:$V$19,p,0),b,TEXTJOIN(", ",TRUE,ARRAYFORMULA(IF(s>0,$B$9:$V$9&": "&ROUND(s,2),""))),IF(b="","{} (rank pays nothing)","{"&b&"}")))))
AH7: Chuck Challenge | AI7: =LET(pos,CHOOSE(MATCH($AI$2,{"p25","p50","p75"},0),SUMIFS(data_event_inst!$K:$K,data_event_inst!$A:$A,"Chuck",data_event_inst!$B:$B,$AI$3,data_event_inst!$C:$C,"0-9"),SUMIFS(data_event_inst!$L:$L,data_event_inst!$A:$A,"Chuck",data_event_inst!$B:$B,$AI$3,data_event_inst!$C:$C,"0-9"),SUMIFS(data_event_inst!$M:$M,data_event_inst!$A:$A,"Chuck",data_event_inst!$B:$B,$AI$3,data_event_inst!$C:$C,"0-9")),IF(pos=0,"n/a",pos)) | AJ7: =LET(p,AI7,IF(p="n/a","n/a",IF(p>10,"— (below ladder)",LET(s,INDEX($B$28:$V$37,p,0),b,TEXTJOIN(", ",TRUE,ARRAYFORMULA(IF(s>0,$B$27:$V$27&": "&ROUND(s,2),""))),IF(b="","{} (rank pays nothing)","{"&b&"}"))))) | AK7: =LET(pos,CHOOSE(MATCH($AI$2,{"p25","p50","p75"},0),SUMIFS(data_event_inst!$K:$K,data_event_inst!$A:$A,"Chuck",data_event_inst!$B:$B,$AI$3,data_event_inst!$C:$C,"10-19"),SUMIFS(data_event_inst!$L:$L,data_event_inst!$A:$A,"Chuck",data_event_inst!$B:$B,$AI$3,data_event_inst!$C:$C,"10-19"),SUMIFS(data_event_inst!$M:$M,data_event_inst!$A:$A,"Chuck",data_event_inst!$B:$B,$AI$3,data_event_inst!$C:$C,"10-19")),IF(pos=0,"n/a",pos)) | AL7: =LET(p,AK7,IF(p="n/a","n/a",IF(p>10,"— (below ladder)",LET(s,INDEX($B$28:$V$37,p,0),b,TEXTJOIN(", ",TRUE,ARRAYFORMULA(IF(s>0,$B$27:$V$27&": "&ROUND(s,2),""))),IF(b="","{} (rank pays nothing)","{"&b&"}"))))) | AM7: =LET(pos,CHOOSE(MATCH($AI$2,{"p25","p50","p75"},0),SUMIFS(data_event_inst!$K:$K,data_event_inst!$A:$A,"Chuck",data_event_inst!$B:$B,$AI$3,data_event_inst!$C:$C,"20-39"),SUMIFS(data_event_inst!$L:$L,data_event_inst!$A:$A,"Chuck",data_event_inst!$B:$B,$AI$3,data_event_inst!$C:$C,"20-39"),SUMIFS(data_event_inst!$M:$M,data_event_inst!$A:$A,"Chuck",data_event_inst!$B:$B,$AI$3,data_event_inst!$C:$C,"20-39")),IF(pos=0,"n/a",pos)) | AN7: =LET(p,AM7,IF(p="n/a","n/a",IF(p>10,"— (below ladder)",LET(s,INDEX($B$28:$V$37,p,0),b,TEXTJOIN(", ",TRUE,ARRAYFORMULA(IF(s>0,$B$27:$V$27&": "&ROUND(s,2),""))),IF(b="","{} (rank pays nothing)","{"&b&"}"))))) | AO7: =LET(pos,CHOOSE(MATCH($AI$2,{"p25","p50","p75"},0),SUMIFS(data_event_inst!$K:$K,data_event_inst!$A:$A,"Chuck",data_event_inst!$B:$B,$AI$3,data_event_inst!$C:$C,"40-99"),SUMIFS(data_event_inst!$L:$L,data_event_inst!$A:$A,"Chuck",data_event_inst!$B:$B,$AI$3,data_event_inst!$C:$C,"40-99"),SUMIFS(data_event_inst!$M:$M,data_event_inst!$A:$A,"Chuck",data_event_inst!$B:$B,$AI$3,data_event_inst!$C:$C,"40-99")),IF(pos=0,"n/a",pos)) | AP7: =LET(p,AO7,IF(p="n/a","n/a",IF(p>10,"— (below ladder)",LET(s,INDEX($B$28:$V$37,p,0),b,TEXTJOIN(", ",TRUE,ARRAYFORMULA(IF(s>0,$B$27:$V$27&": "&ROUND(s,2),""))),IF(b="","{} (rank pays nothing)","{"&b&"}"))))) | AQ7: =LET(pos,CHOOSE(MATCH($AI$2,{"p25","p50","p75"},0),SUMIFS(data_event_inst!$K:$K,data_event_inst!$A:$A,"Chuck",data_event_inst!$B:$B,$AI$3,data_event_inst!$C:$C,"100+"),SUMIFS(data_event_inst!$L:$L,data_event_inst!$A:$A,"Chuck",data_event_inst!$B:$B,$AI$3,data_event_inst!$C:$C,"100+"),SUMIFS(data_event_inst!$M:$M,data_event_inst!$A:$A,"Chuck",data_event_inst!$B:$B,$AI$3,data_event_inst!$C:$C,"100+")),IF(pos=0,"n/a",pos)) | AR7: =LET(p,AQ7,IF(p="n/a","n/a",IF(p>10,"— (below ladder)",LET(s,INDEX($B$28:$V$37,p,0),b,TEXTJOIN(", ",TRUE,ARRAYFORMULA(IF(s>0,$B$27:$V$27&": "&ROUND(s,2),""))),IF(b="","{} (rank pays nothing)","{"&b&"}")))))
A8: Red's Challenge - Goals and Rewards | AH8: Bomb Challenge | AI8: =LET(pos,CHOOSE(MATCH($AI$2,{"p25","p50","p75"},0),SUMIFS(data_event_inst!$K:$K,data_event_inst!$A:$A,"Bomb",data_event_inst!$B:$B,$AI$3,data_event_inst!$C:$C,"0-9"),SUMIFS(data_event_inst!$L:$L,data_event_inst!$A:$A,"Bomb",data_event_inst!$B:$B,$AI$3,data_event_inst!$C:$C,"0-9"),SUMIFS(data_event_inst!$M:$M,data_event_inst!$A:$A,"Bomb",data_event_inst!$B:$B,$AI$3,data_event_inst!$C:$C,"0-9")),IF(pos=0,"n/a",pos)) | AJ8: =LET(p,AI8,IF(p="n/a","n/a",IF(p>10,"— (below ladder)",LET(s,INDEX($B$46:$V$55,p,0),b,TEXTJOIN(", ",TRUE,ARRAYFORMULA(IF(s>0,$B$45:$V$45&": "&ROUND(s,2),""))),IF(b="","{} (rank pays nothing)","{"&b&"}"))))) | AK8: =LET(pos,CHOOSE(MATCH($AI$2,{"p25","p50","p75"},0),SUMIFS(data_event_inst!$K:$K,data_event_inst!$A:$A,"Bomb",data_event_inst!$B:$B,$AI$3,data_event_inst!$C:$C,"10-19"),SUMIFS(data_event_inst!$L:$L,data_event_inst!$A:$A,"Bomb",data_event_inst!$B:$B,$AI$3,data_event_inst!$C:$C,"10-19"),SUMIFS(data_event_inst!$M:$M,data_event_inst!$A:$A,"Bomb",data_event_inst!$B:$B,$AI$3,data_event_inst!$C:$C,"10-19")),IF(pos=0,"n/a",pos)) | AL8: =LET(p,AK8,IF(p="n/a","n/a",IF(p>10,"— (below ladder)",LET(s,INDEX($B$46:$V$55,p,0),b,TEXTJOIN(", ",TRUE,ARRAYFORMULA(IF(s>0,$B$45:$V$45&": "&ROUND(s,2),""))),IF(b="","{} (rank pays nothing)","{"&b&"}"))))) | AM8: =LET(pos,CHOOSE(MATCH($AI$2,{"p25","p50","p75"},0),SUMIFS(data_event_inst!$K:$K,data_event_inst!$A:$A,"Bomb",data_event_inst!$B:$B,$AI$3,data_event_inst!$C:$C,"20-39"),SUMIFS(data_event_inst!$L:$L,data_event_inst!$A:$A,"Bomb",data_event_inst!$B:$B,$AI$3,data_event_inst!$C:$C,"20-39"),SUMIFS(data_event_inst!$M:$M,data_event_inst!$A:$A,"Bomb",data_event_inst!$B:$B,$AI$3,data_event_inst!$C:$C,"20-39")),IF(pos=0,"n/a",pos)) | AN8: =LET(p,AM8,IF(p="n/a","n/a",IF(p>10,"— (below ladder)",LET(s,INDEX($B$46:$V$55,p,0),b,TEXTJOIN(", ",TRUE,ARRAYFORMULA(IF(s>0,$B$45:$V$45&": "&ROUND(s,2),""))),IF(b="","{} (rank pays nothing)","{"&b&"}"))))) | AO8: =LET(pos,CHOOSE(MATCH($AI$2,{"p25","p50","p75"},0),SUMIFS(data_event_inst!$K:$K,data_event_inst!$A:$A,"Bomb",data_event_inst!$B:$B,$AI$3,data_event_inst!$C:$C,"40-99"),SUMIFS(data_event_inst!$L:$L,data_event_inst!$A:$A,"Bomb",data_event_inst!$B:$B,$AI$3,data_event_inst!$C:$C,"40-99"),SUMIFS(data_event_inst!$M:$M,data_event_inst!$A:$A,"Bomb",data_event_inst!$B:$B,$AI$3,data_event_inst!$C:$C,"40-99")),IF(pos=0,"n/a",pos)) | AP8: =LET(p,AO8,IF(p="n/a","n/a",IF(p>10,"— (below ladder)",LET(s,INDEX($B$46:$V$55,p,0),b,TEXTJOIN(", ",TRUE,ARRAYFORMULA(IF(s>0,$B$45:$V$45&": "&ROUND(s,2),""))),IF(b="","{} (rank pays nothing)","{"&b&"}"))))) | AQ8: =LET(pos,CHOOSE(MATCH($AI$2,{"p25","p50","p75"},0),SUMIFS(data_event_inst!$K:$K,data_event_inst!$A:$A,"Bomb",data_event_inst!$B:$B,$AI$3,data_event_inst!$C:$C,"100+"),SUMIFS(data_event_inst!$L:$L,data_event_inst!$A:$A,"Bomb",data_event_inst!$B:$B,$AI$3,data_event_inst!$C:$C,"100+"),SUMIFS(data_event_inst!$M:$M,data_event_inst!$A:$A,"Bomb",data_event_inst!$B:$B,$AI$3,data_event_inst!$C:$C,"100+")),IF(pos=0,"n/a",pos)) | AR8: =LET(p,AQ8,IF(p="n/a","n/a",IF(p>10,"— (below ladder)",LET(s,INDEX($B$46:$V$55,p,0),b,TEXTJOIN(", ",TRUE,ARRAYFORMULA(IF(s>0,$B$45:$V$45&": "&ROUND(s,2),""))),IF(b="","{} (rank pays nothing)","{"&b&"}")))))
A9: Position | B9: Coins | C9: SPT | D9: SPT x2 | E9: Red | F9: Chuck | G9: Bomb | H9: Slingshot | I9: Shuffle | J9: Comet | K9: Unlimited Lives | L9: Unlimited Red | M9: Unlimited Chuck | N9: Unlimited Bomb | O9: COOP Token | P9: Avatar | Q9: 1-star Dly | R9: 2-star Dly | S9: 3-star Dly | T9: 4-star Dly | U9: 5-star Dly | V9: 6-star Dly | AH9: Level Race | AI9: =LET(pos,CHOOSE(MATCH($AI$2,{"p25","p50","p75"},0),SUMIFS(data_event_inst!$K:$K,data_event_inst!$A:$A,"Level Race",data_event_inst!$B:$B,$AI$3,data_event_inst!$C:$C,"0-9"),SUMIFS(data_event_inst!$L:$L,data_event_inst!$A:$A,"Level Race",data_event_inst!$B:$B,$AI$3,data_event_inst!$C:$C,"0-9"),SUMIFS(data_event_inst!$M:$M,data_event_inst!$A:$A,"Level Race",data_event_inst!$B:$B,$AI$3,data_event_inst!$C:$C,"0-9")),IF(pos=0,"n/a",pos)) | AJ9: =LET(p,AI9,IF(p="n/a","n/a",IF(p>10,"— (below ladder)",LET(s,INDEX($B$64:$V$73,p,0),b,TEXTJOIN(", ",TRUE,ARRAYFORMULA(IF(s>0,$B$63:$V$63&": "&ROUND(s,2),""))),IF(b="","{} (rank pays nothing)","{"&b&"}"))))) | AK9: =LET(pos,CHOOSE(MATCH($AI$2,{"p25","p50","p75"},0),SUMIFS(data_event_inst!$K:$K,data_event_inst!$A:$A,"Level Race",data_event_inst!$B:$B,$AI$3,data_event_inst!$C:$C,"10-19"),SUMIFS(data_event_inst!$L:$L,data_event_inst!$A:$A,"Level Race",data_event_inst!$B:$B,$AI$3,data_event_inst!$C:$C,"10-19"),SUMIFS(data_event_inst!$M:$M,data_event_inst!$A:$A,"Level Race",data_event_inst!$B:$B,$AI$3,data_event_inst!$C:$C,"10-19")),IF(pos=0,"n/a",pos)) | AL9: =LET(p,AK9,IF(p="n/a","n/a",IF(p>10,"— (below ladder)",LET(s,INDEX($B$64:$V$73,p,0),b,TEXTJOIN(", ",TRUE,ARRAYFORMULA(IF(s>0,$B$63:$V$63&": "&ROUND(s,2),""))),IF(b="","{} (rank pays nothing)","{"&b&"}"))))) | AM9: =LET(pos,CHOOSE(MATCH($AI$2,{"p25","p50","p75"},0),SUMIFS(data_event_inst!$K:$K,data_event_inst!$A:$A,"Level Race",data_event_inst!$B:$B,$AI$3,data_event_inst!$C:$C,"20-39"),SUMIFS(data_event_inst!$L:$L,data_event_inst!$A:$A,"Level Race",data_event_inst!$B:$B,$AI$3,data_event_inst!$C:$C,"20-39"),SUMIFS(data_event_inst!$M:$M,data_event_inst!$A:$A,"Level Race",data_event_inst!$B:$B,$AI$3,data_event_inst!$C:$C,"20-39")),IF(pos=0,"n/a",pos)) | AN9: =LET(p,AM9,IF(p="n/a","n/a",IF(p>10,"— (below ladder)",LET(s,INDEX($B$64:$V$73,p,0),b,TEXTJOIN(", ",TRUE,ARRAYFORMULA(IF(s>0,$B$63:$V$63&": "&ROUND(s,2),""))),IF(b="","{} (rank pays nothing)","{"&b&"}"))))) | AO9: =LET(pos,CHOOSE(MATCH($AI$2,{"p25","p50","p75"},0),SUMIFS(data_event_inst!$K:$K,data_event_inst!$A:$A,"Level Race",data_event_inst!$B:$B,$AI$3,data_event_inst!$C:$C,"40-99"),SUMIFS(data_event_inst!$L:$L,data_event_inst!$A:$A,"Level Race",data_event_inst!$B:$B,$AI$3,data_event_inst!$C:$C,"40-99"),SUMIFS(data_event_inst!$M:$M,data_event_inst!$A:$A,"Level Race",data_event_inst!$B:$B,$AI$3,data_event_inst!$C:$C,"40-99")),IF(pos=0,"n/a",pos)) | AP9: =LET(p,AO9,IF(p="n/a","n/a",IF(p>10,"— (below ladder)",LET(s,INDEX($B$64:$V$73,p,0),b,TEXTJOIN(", ",TRUE,ARRAYFORMULA(IF(s>0,$B$63:$V$63&": "&ROUND(s,2),""))),IF(b="","{} (rank pays nothing)","{"&b&"}"))))) | AQ9: =LET(pos,CHOOSE(MATCH($AI$2,{"p25","p50","p75"},0),SUMIFS(data_event_inst!$K:$K,data_event_inst!$A:$A,"Level Race",data_event_inst!$B:$B,$AI$3,data_event_inst!$C:$C,"100+"),SUMIFS(data_event_inst!$L:$L,data_event_inst!$A:$A,"Level Race",data_event_inst!$B:$B,$AI$3,data_event_inst!$C:$C,"100+"),SUMIFS(data_event_inst!$M:$M,data_event_inst!$A:$A,"Level Race",data_event_inst!$B:$B,$AI$3,data_event_inst!$C:$C,"100+")),IF(pos=0,"n/a",pos)) | AR9: =LET(p,AQ9,IF(p="n/a","n/a",IF(p>10,"— (below ladder)",LET(s,INDEX($B$64:$V$73,p,0),b,TEXTJOIN(", ",TRUE,ARRAYFORMULA(IF(s>0,$B$63:$V$63&": "&ROUND(s,2),""))),IF(b="","{} (rank pays nothing)","{"&b&"}")))))
A10: 1 | B10: 200 | C10: 0 | D10: 0 | E10: 0 | F10: 0 | G10: 0 | H10: 0 | I10: 0 | J10: 1 | K10: 0 | L10: 0 | M10: 0 | N10: 0 | O10: 0 | P10: 0 | Q10: 0 | R10: 0 | S10: 0 | T10: 0 | U10: 0 | V10: 0 | AH10: Flash Race | AI10: =LET(pos,CHOOSE(MATCH($AI$2,{"p25","p50","p75"},0),SUMIFS(data_event_inst!$K:$K,data_event_inst!$A:$A,"Flash Race",data_event_inst!$B:$B,$AI$3,data_event_inst!$C:$C,"0-9"),SUMIFS(data_event_inst!$L:$L,data_event_inst!$A:$A,"Flash Race",data_event_inst!$B:$B,$AI$3,data_event_inst!$C:$C,"0-9"),SUMIFS(data_event_inst!$M:$M,data_event_inst!$A:$A,"Flash Race",data_event_inst!$B:$B,$AI$3,data_event_inst!$C:$C,"0-9")),IF(pos=0,"n/a",pos)) | AJ10: =LET(p,AI10,IF(p="n/a","n/a",IF(p>10,"— (below ladder)",LET(s,INDEX($B$82:$V$91,p,0),b,TEXTJOIN(", ",TRUE,ARRAYFORMULA(IF(s>0,$B$81:$V$81&": "&ROUND(s,2),""))),IF(b="","{} (rank pays nothing)","{"&b&"}"))))) | AK10: =LET(pos,CHOOSE(MATCH($AI$2,{"p25","p50","p75"},0),SUMIFS(data_event_inst!$K:$K,data_event_inst!$A:$A,"Flash Race",data_event_inst!$B:$B,$AI$3,data_event_inst!$C:$C,"10-19"),SUMIFS(data_event_inst!$L:$L,data_event_inst!$A:$A,"Flash Race",data_event_inst!$B:$B,$AI$3,data_event_inst!$C:$C,"10-19"),SUMIFS(data_event_inst!$M:$M,data_event_inst!$A:$A,"Flash Race",data_event_inst!$B:$B,$AI$3,data_event_inst!$C:$C,"10-19")),IF(pos=0,"n/a",pos)) | AL10: =LET(p,AK10,IF(p="n/a","n/a",IF(p>10,"— (below ladder)",LET(s,INDEX($B$82:$V$91,p,0),b,TEXTJOIN(", ",TRUE,ARRAYFORMULA(IF(s>0,$B$81:$V$81&": "&ROUND(s,2),""))),IF(b="","{} (rank pays nothing)","{"&b&"}"))))) | AM10: =LET(pos,CHOOSE(MATCH($AI$2,{"p25","p50","p75"},0),SUMIFS(data_event_inst!$K:$K,data_event_inst!$A:$A,"Flash Race",data_event_inst!$B:$B,$AI$3,data_event_inst!$C:$C,"20-39"),SUMIFS(data_event_inst!$L:$L,data_event_inst!$A:$A,"Flash Race",data_event_inst!$B:$B,$AI$3,data_event_inst!$C:$C,"20-39"),SUMIFS(data_event_inst!$M:$M,data_event_inst!$A:$A,"Flash Race",data_event_inst!$B:$B,$AI$3,data_event_inst!$C:$C,"20-39")),IF(pos=0,"n/a",pos)) | AN10: =LET(p,AM10,IF(p="n/a","n/a",IF(p>10,"— (below ladder)",LET(s,INDEX($B$82:$V$91,p,0),b,TEXTJOIN(", ",TRUE,ARRAYFORMULA(IF(s>0,$B$81:$V$81&": "&ROUND(s,2),""))),IF(b="","{} (rank pays nothing)","{"&b&"}"))))) | AO10: =LET(pos,CHOOSE(MATCH($AI$2,{"p25","p50","p75"},0),SUMIFS(data_event_inst!$K:$K,data_event_inst!$A:$A,"Flash Race",data_event_inst!$B:$B,$AI$3,data_event_inst!$C:$C,"40-99"),SUMIFS(data_event_inst!$L:$L,data_event_inst!$A:$A,"Flash Race",data_event_inst!$B:$B,$AI$3,data_event_inst!$C:$C,"40-99"),SUMIFS(data_event_inst!$M:$M,data_event_inst!$A:$A,"Flash Race",data_event_inst!$B:$B,$AI$3,data_event_inst!$C:$C,"40-99")),IF(pos=0,"n/a",pos)) | AP10: =LET(p,AO10,IF(p="n/a","n/a",IF(p>10,"— (below ladder)",LET(s,INDEX($B$82:$V$91,p,0),b,TEXTJOIN(", ",TRUE,ARRAYFORMULA(IF(s>0,$B$81:$V$81&": "&ROUND(s,2),""))),IF(b="","{} (rank pays nothing)","{"&b&"}"))))) | AQ10: =LET(pos,CHOOSE(MATCH($AI$2,{"p25","p50","p75"},0),SUMIFS(data_event_inst!$K:$K,data_event_inst!$A:$A,"Flash Race",data_event_inst!$B:$B,$AI$3,data_event_inst!$C:$C,"100+"),SUMIFS(data_event_inst!$L:$L,data_event_inst!$A:$A,"Flash Race",data_event_inst!$B:$B,$AI$3,data_event_inst!$C:$C,"100+"),SUMIFS(data_event_inst!$M:$M,data_event_inst!$A:$A,"Flash Race",data_event_inst!$B:$B,$AI$3,data_event_inst!$C:$C,"100+")),IF(pos=0,"n/a",pos)) | AR10: =LET(p,AQ10,IF(p="n/a","n/a",IF(p>10,"— (below ladder)",LET(s,INDEX($B$82:$V$91,p,0),b,TEXTJOIN(", ",TRUE,ARRAYFORMULA(IF(s>0,$B$81:$V$81&": "&ROUND(s,2),""))),IF(b="","{} (rank pays nothing)","{"&b&"}")))))
A11: 2 | B11: 100 | C11: 0 | D11: 0 | E11: 0 | F11: 0 | G11: 0 | H11: 0 | I11: 1 | J11: 0 | K11: 0 | L11: 0 | M11: 0 | N11: 0 | O11: 0 | P11: 0 | Q11: 0 | R11: 0 | S11: 0 | T11: 0 | U11: 0 | V11: 0
A12: 3 | B12: 50 | C12: 0 | D12: 0 | E12: 0 | F12: 0 | G12: 0 | H12: 0 | I12: 1 | J12: 0 | K12: 0 | L12: 0 | M12: 0 | N12: 0 | O12: 0 | P12: 0 | Q12: 0 | R12: 0 | S12: 0 | T12: 0 | U12: 0 | V12: 0 | AH12: p25 = top-quartile finisher (lower position = better); source: data_event_inst position percentiles, measured on the CURRENT calendar
A13: 4 | B13: 0 | C13: 0 | D13: 0 | E13: 0 | F13: 0 | G13: 0 | H13: 0 | I13: 1 | J13: 0 | K13: 0 | L13: 0 | M13: 0 | N13: 0 | O13: 0 | P13: 0 | Q13: 0 | R13: 0 | S13: 0 | T13: 0 | U13: 0 | V13: 0 | AH13: ⚠ Level Race: observed positions exceed configured LBSize=10 (p75 up to 15) — live board size understated; ranks 11+ shown as below ladder
A14: 5 | B14: 0 | C14: 0 | D14: 0 | E14: 0 | F14: 0 | G14: 0 | H14: 0 | I14: 1 | J14: 0 | K14: 0 | L14: 0 | M14: 0 | N14: 0 | O14: 0 | P14: 0 | Q14: 0 | R14: 0 | S14: 0 | T14: 0 | U14: 0 | V14: 0 | AH14: ⚠ Flash Race: telemetry shows ≈0 of the 11 tracked resources (event pays SPT) — ladder HC here is config-nominal, uncorroborated
A15: 6 | B15: 0 | C15: 0 | D15: 0 | E15: 0 | F15: 0 | G15: 0 | H15: 1 | I15: 0 | J15: 0 | K15: 0 | L15: 0 | M15: 0 | N15: 0 | O15: 0 | P15: 0 | Q15: 0 | R15: 0 | S15: 0 | T15: 0 | U15: 0 | V15: 0 | AH15: ⚠ all five ladders are identical (family template) — authenticity vs live config unverified
A16: 7 | B16: 0 | C16: 0 | D16: 0 | E16: 0 | F16: 0 | G16: 0 | H16: 1 | I16: 0 | J16: 0 | K16: 0 | L16: 0 | M16: 0 | N16: 0 | O16: 0 | P16: 0 | Q16: 0 | R16: 0 | S16: 0 | T16: 0 | U16: 0 | V16: 0
A17: 8 | B17: 0 | C17: 0 | D17: 0 | E17: 0 | F17: 0 | G17: 0 | H17: 1 | I17: 0 | J17: 0 | K17: 0 | L17: 0 | M17: 0 | N17: 0 | O17: 0 | P17: 0 | Q17: 0 | R17: 0 | S17: 0 | T17: 0 | U17: 0 | V17: 0
A18: 9 | B18: 0 | C18: 0 | D18: 0 | E18: 0 | F18: 0 | G18: 0 | H18: 1 | I18: 0 | J18: 0 | K18: 0 | L18: 0 | M18: 0 | N18: 0 | O18: 0 | P18: 0 | Q18: 0 | R18: 0 | S18: 0 | T18: 0 | U18: 0 | V18: 0
A19: 10 | B19: 0 | C19: 0 | D19: 0 | E19: 0 | F19: 0 | G19: 0 | H19: 1 | I19: 0 | J19: 0 | K19: 0 | L19: 0 | M19: 0 | N19: 0 | O19: 0 | P19: 0 | Q19: 0 | R19: 0 | S19: 0 | T19: 0 | U19: 0 | V19: 0
A21: Chunk's Challenge - Config Panel
A22: numberOfPositions | B22: 10
A23: LBSize | B23: 10
A24: EventDuration | B24: 2
A26: Chunk's Challenge - Goals and Rewards
A27: Position | B27: Coins | C27: SPT | D27: SPT x2 | E27: Red | F27: Chuck | G27: Bomb | H27: Slingshot | I27: Shuffle | J27: Comet | K27: Unlimited Lives | L27: Unlimited Red | M27: Unlimited Chuck | N27: Unlimited Bomb | O27: COOP Token | P27: Avatar | Q27: 1-star Dly | R27: 2-star Dly | S27: 3-star Dly | T27: 4-star Dly | U27: 5-star Dly | V27: 6-star Dly
A28: 1 | B28: 200 | C28: 0 | D28: 0 | E28: 0 | F28: 0 | G28: 0 | H28: 0 | I28: 0 | J28: 1 | K28: 0 | L28: 0 | M28: 0 | N28: 0 | O28: 0 | P28: 0 | Q28: 0 | R28: 0 | S28: 0 | T28: 0 | U28: 0 | V28: 0
A29: 2 | B29: 100 | C29: 0 | D29: 0 | E29: 0 | F29: 0 | G29: 0 | H29: 0 | I29: 1 | J29: 0 | K29: 0 | L29: 0 | M29: 0 | N29: 0 | O29: 0 | P29: 0 | Q29: 0 | R29: 0 | S29: 0 | T29: 0 | U29: 0 | V29: 0
A30: 3 | B30: 50 | C30: 0 | D30: 0 | E30: 0 | F30: 0 | G30: 0 | H30: 0 | I30: 1 | J30: 0 | K30: 0 | L30: 0 | M30: 0 | N30: 0 | O30: 0 | P30: 0 | Q30: 0 | R30: 0 | S30: 0 | T30: 0 | U30: 0 | V30: 0
A31: 4 | B31: 0 | C31: 0 | D31: 0 | E31: 0 | F31: 0 | G31: 0 | H31: 0 | I31: 1 | J31: 0 | K31: 0 | L31: 0 | M31: 0 | N31: 0 | O31: 0 | P31: 0 | Q31: 0 | R31: 0 | S31: 0 | T31: 0 | U31: 0 | V31: 0
A32: 5 | B32: 0 | C32: 0 | D32: 0 | E32: 0 | F32: 0 | G32: 0 | H32: 0 | I32: 1 | J32: 0 | K32: 0 | L32: 0 | M32: 0 | N32: 0 | O32: 0 | P32: 0 | Q32: 0 | R32: 0 | S32: 0 | T32: 0 | U32: 0 | V32: 0
A33: 6 | B33: 0 | C33: 0 | D33: 0 | E33: 0 | F33: 0 | G33: 0 | H33: 1 | I33: 0 | J33: 0 | K33: 0 | L33: 0 | M33: 0 | N33: 0 | O33: 0 | P33: 0 | Q33: 0 | R33: 0 | S33: 0 | T33: 0 | U33: 0 | V33: 0
A34: 7 | B34: 0 | C34: 0 | D34: 0 | E34: 0 | F34: 0 | G34: 0 | H34: 1 | I34: 0 | J34: 0 | K34: 0 | L34: 0 | M34: 0 | N34: 0 | O34: 0 | P34: 0 | Q34: 0 | R34: 0 | S34: 0 | T34: 0 | U34: 0 | V34: 0
A35: 8 | B35: 0 | C35: 0 | D35: 0 | E35: 0 | F35: 0 | G35: 0 | H35: 1 | I35: 0 | J35: 0 | K35: 0 | L35: 0 | M35: 0 | N35: 0 | O35: 0 | P35: 0 | Q35: 0 | R35: 0 | S35: 0 | T35: 0 | U35: 0 | V35: 0
A36: 9 | B36: 0 | C36: 0 | D36: 0 | E36: 0 | F36: 0 | G36: 0 | H36: 1 | I36: 0 | J36: 0 | K36: 0 | L36: 0 | M36: 0 | N36: 0 | O36: 0 | P36: 0 | Q36: 0 | R36: 0 | S36: 0 | T36: 0 | U36: 0 | V36: 0
A37: 10 | B37: 0 | C37: 0 | D37: 0 | E37: 0 | F37: 0 | G37: 0 | H37: 1 | I37: 0 | J37: 0 | K37: 0 | L37: 0 | M37: 0 | N37: 0 | O37: 0 | P37: 0 | Q37: 0 | R37: 0 | S37: 0 | T37: 0 | U37: 0 | V37: 0
A39: Bomb's Challenge - Config Panel
A40: numberOfPositions | B40: 10
A41: LBSize | B41: 10
A42: EventDuration | B42: 2
A44: Bomb's Challenge - Goals and Rewards
...
