Workbook

Sheet J_v2
A1: Jigsaw Puzzle | AH1: Player Reach Simulation (per event day) — SIMULATED
A2: Config Panel | AH2: Percentile | AI2: Avg
A3: EventDuration | B3: 3 | AH3: Payer | AI3: NONPAYER
A4: requiredPlayerLevel | B4: 1
A5: requiredSagaLevel | B5: 15 | AH5: Day_of_event | AI5: 0-9_ms | AJ5: 0-9_reward | AK5: 10-19_ms | AL5: 10-19_reward | AM5: 20-39_ms | AN5: 20-39_reward | AO5: 40-99_ms | AP5: 40-99_reward | AQ5: 100_ms | AR5: 100_reward
A6: tokenMultiplier | B6: 2 | AH6: =IF(1<=$B$3,1,"") | AI6: =IF($AH6="","",LET(bal,SUMIFS(data_event_inst!$N:$N,data_event_inst!$A:$A,"Jigsaw",data_event_inst!$B:$B,$AI$3,data_event_inst!$C:$C,"0-9"),shr,MIN(1,IFERROR(CHOOSE(MATCH($AI$2,{"Avg","p25","p50","p75"},0),AVERAGEIFS(data_event_accrual!$I:$I,data_event_accrual!$A:$A,"Jigsaw",data_event_accrual!$B:$B,$AI$3,data_event_accrual!$C:$C,"0-9",data_event_accrual!$E:$E,$AH6),AVERAGEIFS(data_event_accrual!$K:$K,data_event_accrual!$A:$A,"Jigsaw",data_event_accrual!$B:$B,$AI$3,data_event_accrual!$C:$C,"0-9",data_event_accrual!$E:$E,$AH6),AVERAGEIFS(data_event_accrual!$J:$J,data_event_accrual!$A:$A,"Jigsaw",data_event_accrual!$B:$B,$AI$3,data_event_accrual!$C:$C,"0-9",data_event_accrual!$E:$E,$AH6),AVERAGEIFS(data_event_accrual!$L:$L,data_event_accrual!$A:$A,"Jigsaw",data_event_accrual!$B:$B,$AI$3,data_event_accrual!$C:$C,"0-9",data_event_accrual!$E:$E,$AH6)),1)),COUNTIF($B$11:$B$22,"<="&bal*shr))) | AJ6: =IF($AH6="","",IF(AI6=0,"{}",LET(m,AI6,s,MMULT(SEQUENCE(1,m,1,0),ARRAY_CONSTRAIN($C$11:$W$22,m,21)),"{"&TEXTJOIN(", ",TRUE,ARRAYFORMULA(IF(s>0,$C$10:$W$10&": "&ROUND(s,2),"")))&"}"))) | AK6: =IF($AH6="","",LET(bal,SUMIFS(data_event_inst!$N:$N,data_event_inst!$A:$A,"Jigsaw",data_event_inst!$B:$B,$AI$3,data_event_inst!$C:$C,"10-19"),shr,MIN(1,IFERROR(CHOOSE(MATCH($AI$2,{"Avg","p25","p50","p75"},0),AVERAGEIFS(data_event_accrual!$I:$I,data_event_accrual!$A:$A,"Jigsaw",data_event_accrual!$B:$B,$AI$3,data_event_accrual!$C:$C,"10-19",data_event_accrual!$E:$E,$AH6),AVERAGEIFS(data_event_accrual!$K:$K,data_event_accrual!$A:$A,"Jigsaw",data_event_accrual!$B:$B,$AI$3,data_event_accrual!$C:$C,"10-19",data_event_accrual!$E:$E,$AH6),AVERAGEIFS(data_event_accrual!$J:$J,data_event_accrual!$A:$A,"Jigsaw",data_event_accrual!$B:$B,$AI$3,data_event_accrual!$C:$C,"10-19",data_event_accrual!$E:$E,$AH6),AVERAGEIFS(data_event_accrual!$L:$L,data_event_accrual!$A:$A,"Jigsaw",data_event_accrual!$B:$B,$AI$3,data_event_accrual!$C:$C,"10-19",data_event_accrual!$E:$E,$AH6)),1)),COUNTIF($B$11:$B$22,"<="&bal*shr))) | AL6: =IF($AH6="","",IF(AK6=0,"{}",LET(m,AK6,s,MMULT(SEQUENCE(1,m,1,0),ARRAY_CONSTRAIN($C$11:$W$22,m,21)),"{"&TEXTJOIN(", ",TRUE,ARRAYFORMULA(IF(s>0,$C$10:$W$10&": "&ROUND(s,2),"")))&"}"))) | AM6: =IF($AH6="","",LET(bal,SUMIFS(data_event_inst!$N:$N,data_event_inst!$A:$A,"Jigsaw",data_event_inst!$B:$B,$AI$3,data_event_inst!$C:$C,"20-39"),shr,MIN(1,IFERROR(CHOOSE(MATCH($AI$2,{"Avg","p25","p50","p75"},0),AVERAGEIFS(data_event_accrual!$I:$I,data_event_accrual!$A:$A,"Jigsaw",data_event_accrual!$B:$B,$AI$3,data_event_accrual!$C:$C,"20-39",data_event_accrual!$E:$E,$AH6),AVERAGEIFS(data_event_accrual!$K:$K,data_event_accrual!$A:$A,"Jigsaw",data_event_accrual!$B:$B,$AI$3,data_event_accrual!$C:$C,"20-39",data_event_accrual!$E:$E,$AH6),AVERAGEIFS(data_event_accrual!$J:$J,data_event_accrual!$A:$A,"Jigsaw",data_event_accrual!$B:$B,$AI$3,data_event_accrual!$C:$C,"20-39",data_event_accrual!$E:$E,$AH6),AVERAGEIFS(data_event_accrual!$L:$L,data_event_accrual!$A:$A,"Jigsaw",data_event_accrual!$B:$B,$AI$3,data_event_accrual!$C:$C,"20-39",data_event_accrual!$E:$E,$AH6)),1)),COUNTIF($B$11:$B$22,"<="&bal*shr))) | AN6: =IF($AH6="","",IF(AM6=0,"{}",LET(m,AM6,s,MMULT(SEQUENCE(1,m,1,0),ARRAY_CONSTRAIN($C$11:$W$22,m,21)),"{"&TEXTJOIN(", ",TRUE,ARRAYFORMULA(IF(s>0,$C$10:$W$10&": "&ROUND(s,2),"")))&"}"))) | AO6: =IF($AH6="","",LET(bal,SUMIFS(data_event_inst!$N:$N,data_event_inst!$A:$A,"Jigsaw",data_event_inst!$B:$B,$AI$3,data_event_inst!$C:$C,"40-99"),shr,MIN(1,IFERROR(CHOOSE(MATCH($AI$2,{"Avg","p25","p50","p75"},0),AVERAGEIFS(data_event_accrual!$I:$I,data_event_accrual!$A:$A,"Jigsaw",data_event_accrual!$B:$B,$AI$3,data_event_accrual!$C:$C,"40-99",data_event_accrual!$E:$E,$AH6),AVERAGEIFS(data_event_accrual!$K:$K,data_event_accrual!$A:$A,"Jigsaw",data_event_accrual!$B:$B,$AI$3,data_event_accrual!$C:$C,"40-99",data_event_accrual!$E:$E,$AH6),AVERAGEIFS(data_event_accrual!$J:$J,data_event_accrual!$A:$A,"Jigsaw",data_event_accrual!$B:$B,$AI$3,data_event_accrual!$C:$C,"40-99",data_event_accrual!$E:$E,$AH6),AVERAGEIFS(data_event_accrual!$L:$L,data_event_accrual!$A:$A,"Jigsaw",data_event_accrual!$B:$B,$AI$3,data_event_accrual!$C:$C,"40-99",data_event_accrual!$E:$E,$AH6)),1)),COUNTIF($B$11:$B$22,"<="&bal*shr))) | AP6: =IF($AH6="","",IF(AO6=0,"{}",LET(m,AO6,s,MMULT(SEQUENCE(1,m,1,0),ARRAY_CONSTRAIN($C$11:$W$22,m,21)),"{"&TEXTJOIN(", ",TRUE,ARRAYFORMULA(IF(s>0,$C$10:$W$10&": "&ROUND(s,2),"")))&"}"))) | AQ6: =IF($AH6="","",LET(bal,SUMIFS(data_event_inst!$N:$N,data_event_inst!$A:$A,"Jigsaw",data_event_inst!$B:$B,$AI$3,data_event_inst!$C:$C,"100+"),shr,MIN(1,IFERROR(CHOOSE(MATCH($AI$2,{"Avg","p25","p50","p75"},0),AVERAGEIFS(data_event_accrual!$I:$I,data_event_accrual!$A:$A,"Jigsaw",data_event_accrual!$B:$B,$AI$3,data_event_accrual!$C:$C,"100+",data_event_accrual!$E:$E,$AH6),AVERAGEIFS(data_event_accrual!$K:$K,data_event_accrual!$A:$A,"Jigsaw",data_event_accrual!$B:$B,$AI$3,data_event_accrual!$C:$C,"100+",data_event_accrual!$E:$E,$AH6),AVERAGEIFS(data_event_accrual!$J:$J,data_event_accrual!$A:$A,"Jigsaw",data_event_accrual!$B:$B,$AI$3,data_event_accrual!$C:$C,"100+",data_event_accrual!$E:$E,$AH6),AVERAGEIFS(data_event_accrual!$L:$L,data_event_accrual!$A:$A,"Jigsaw",data_event_accrual!$B:$B,$AI$3,data_event_accrual!$C:$C,"100+",data_event_accrual!$E:$E,$AH6)),1)),COUNTIF($B$11:$B$22,"<="&bal*shr))) | AR6: =IF($AH6="","",IF(AQ6=0,"{}",LET(m,AQ6,s,MMULT(SEQUENCE(1,m,1,0),ARRAY_CONSTRAIN($C$11:$W$22,m,21)),"{"&TEXTJOIN(", ",TRUE,ARRAYFORMULA(IF(s>0,$C$10:$W$10&": "&ROUND(s,2),"")))&"}")))
A7: scoreDoubler | B7: =TRUE() | AH7: =IF(2<=$B$3,2,"") | AI7: =IF($AH7="","",LET(bal,SUMIFS(data_event_inst!$N:$N,data_event_inst!$A:$A,"Jigsaw",data_event_inst!$B:$B,$AI$3,data_event_inst!$C:$C,"0-9"),shr,MIN(1,IFERROR(CHOOSE(MATCH($AI$2,{"Avg","p25","p50","p75"},0),AVERAGEIFS(data_event_accrual!$I:$I,data_event_accrual!$A:$A,"Jigsaw",data_event_accrual!$B:$B,$AI$3,data_event_accrual!$C:$C,"0-9",data_event_accrual!$E:$E,$AH7),AVERAGEIFS(data_event_accrual!$K:$K,data_event_accrual!$A:$A,"Jigsaw",data_event_accrual!$B:$B,$AI$3,data_event_accrual!$C:$C,"0-9",data_event_accrual!$E:$E,$AH7),AVERAGEIFS(data_event_accrual!$J:$J,data_event_accrual!$A:$A,"Jigsaw",data_event_accrual!$B:$B,$AI$3,data_event_accrual!$C:$C,"0-9",data_event_accrual!$E:$E,$AH7),AVERAGEIFS(data_event_accrual!$L:$L,data_event_accrual!$A:$A,"Jigsaw",data_event_accrual!$B:$B,$AI$3,data_event_accrual!$C:$C,"0-9",data_event_accrual!$E:$E,$AH7)),1)),COUNTIF($B$11:$B$22,"<="&bal*shr))) | AJ7: =IF($AH7="","",IF(AI7=0,"{}",LET(m,AI7,s,MMULT(SEQUENCE(1,m,1,0),ARRAY_CONSTRAIN($C$11:$W$22,m,21)),"{"&TEXTJOIN(", ",TRUE,ARRAYFORMULA(IF(s>0,$C$10:$W$10&": "&ROUND(s,2),"")))&"}"))) | AK7: =IF($AH7="","",LET(bal,SUMIFS(data_event_inst!$N:$N,data_event_inst!$A:$A,"Jigsaw",data_event_inst!$B:$B,$AI$3,data_event_inst!$C:$C,"10-19"),shr,MIN(1,IFERROR(CHOOSE(MATCH($AI$2,{"Avg","p25","p50","p75"},0),AVERAGEIFS(data_event_accrual!$I:$I,data_event_accrual!$A:$A,"Jigsaw",data_event_accrual!$B:$B,$AI$3,data_event_accrual!$C:$C,"10-19",data_event_accrual!$E:$E,$AH7),AVERAGEIFS(data_event_accrual!$K:$K,data_event_accrual!$A:$A,"Jigsaw",data_event_accrual!$B:$B,$AI$3,data_event_accrual!$C:$C,"10-19",data_event_accrual!$E:$E,$AH7),AVERAGEIFS(data_event_accrual!$J:$J,data_event_accrual!$A:$A,"Jigsaw",data_event_accrual!$B:$B,$AI$3,data_event_accrual!$C:$C,"10-19",data_event_accrual!$E:$E,$AH7),AVERAGEIFS(data_event_accrual!$L:$L,data_event_accrual!$A:$A,"Jigsaw",data_event_accrual!$B:$B,$AI$3,data_event_accrual!$C:$C,"10-19",data_event_accrual!$E:$E,$AH7)),1)),COUNTIF($B$11:$B$22,"<="&bal*shr))) | AL7: =IF($AH7="","",IF(AK7=0,"{}",LET(m,AK7,s,MMULT(SEQUENCE(1,m,1,0),ARRAY_CONSTRAIN($C$11:$W$22,m,21)),"{"&TEXTJOIN(", ",TRUE,ARRAYFORMULA(IF(s>0,$C$10:$W$10&": "&ROUND(s,2),"")))&"}"))) | AM7: =IF($AH7="","",LET(bal,SUMIFS(data_event_inst!$N:$N,data_event_inst!$A:$A,"Jigsaw",data_event_inst!$B:$B,$AI$3,data_event_inst!$C:$C,"20-39"),shr,MIN(1,IFERROR(CHOOSE(MATCH($AI$2,{"Avg","p25","p50","p75"},0),AVERAGEIFS(data_event_accrual!$I:$I,data_event_accrual!$A:$A,"Jigsaw",data_event_accrual!$B:$B,$AI$3,data_event_accrual!$C:$C,"20-39",data_event_accrual!$E:$E,$AH7),AVERAGEIFS(data_event_accrual!$K:$K,data_event_accrual!$A:$A,"Jigsaw",data_event_accrual!$B:$B,$AI$3,data_event_accrual!$C:$C,"20-39",data_event_accrual!$E:$E,$AH7),AVERAGEIFS(data_event_accrual!$J:$J,data_event_accrual!$A:$A,"Jigsaw",data_event_accrual!$B:$B,$AI$3,data_event_accrual!$C:$C,"20-39",data_event_accrual!$E:$E,$AH7),AVERAGEIFS(data_event_accrual!$L:$L,data_event_accrual!$A:$A,"Jigsaw",data_event_accrual!$B:$B,$AI$3,data_event_accrual!$C:$C,"20-39",data_event_accrual!$E:$E,$AH7)),1)),COUNTIF($B$11:$B$22,"<="&bal*shr))) | AN7: =IF($AH7="","",IF(AM7=0,"{}",LET(m,AM7,s,MMULT(SEQUENCE(1,m,1,0),ARRAY_CONSTRAIN($C$11:$W$22,m,21)),"{"&TEXTJOIN(", ",TRUE,ARRAYFORMULA(IF(s>0,$C$10:$W$10&": "&ROUND(s,2),"")))&"}"))) | AO7: =IF($AH7="","",LET(bal,SUMIFS(data_event_inst!$N:$N,data_event_inst!$A:$A,"Jigsaw",data_event_inst!$B:$B,$AI$3,data_event_inst!$C:$C,"40-99"),shr,MIN(1,IFERROR(CHOOSE(MATCH($AI$2,{"Avg","p25","p50","p75"},0),AVERAGEIFS(data_event_accrual!$I:$I,data_event_accrual!$A:$A,"Jigsaw",data_event_accrual!$B:$B,$AI$3,data_event_accrual!$C:$C,"40-99",data_event_accrual!$E:$E,$AH7),AVERAGEIFS(data_event_accrual!$K:$K,data_event_accrual!$A:$A,"Jigsaw",data_event_accrual!$B:$B,$AI$3,data_event_accrual!$C:$C,"40-99",data_event_accrual!$E:$E,$AH7),AVERAGEIFS(data_event_accrual!$J:$J,data_event_accrual!$A:$A,"Jigsaw",data_event_accrual!$B:$B,$AI$3,data_event_accrual!$C:$C,"40-99",data_event_accrual!$E:$E,$AH7),AVERAGEIFS(data_event_accrual!$L:$L,data_event_accrual!$A:$A,"Jigsaw",data_event_accrual!$B:$B,$AI$3,data_event_accrual!$C:$C,"40-99",data_event_accrual!$E:$E,$AH7)),1)),COUNTIF($B$11:$B$22,"<="&bal*shr))) | AP7: =IF($AH7="","",IF(AO7=0,"{}",LET(m,AO7,s,MMULT(SEQUENCE(1,m,1,0),ARRAY_CONSTRAIN($C$11:$W$22,m,21)),"{"&TEXTJOIN(", ",TRUE,ARRAYFORMULA(IF(s>0,$C$10:$W$10&": "&ROUND(s,2),"")))&"}"))) | AQ7: =IF($AH7="","",LET(bal,SUMIFS(data_event_inst!$N:$N,data_event_inst!$A:$A,"Jigsaw",data_event_inst!$B:$B,$AI$3,data_event_inst!$C:$C,"100+"),shr,MIN(1,IFERROR(CHOOSE(MATCH($AI$2,{"Avg","p25","p50","p75"},0),AVERAGEIFS(data_event_accrual!$I:$I,data_event_accrual!$A:$A,"Jigsaw",data_event_accrual!$B:$B,$AI$3,data_event_accrual!$C:$C,"100+",data_event_accrual!$E:$E,$AH7),AVERAGEIFS(data_event_accrual!$K:$K,data_event_accrual!$A:$A,"Jigsaw",data_event_accrual!$B:$B,$AI$3,data_event_accrual!$C:$C,"100+",data_event_accrual!$E:$E,$AH7),AVERAGEIFS(data_event_accrual!$J:$J,data_event_accrual!$A:$A,"Jigsaw",data_event_accrual!$B:$B,$AI$3,data_event_accrual!$C:$C,"100+",data_event_accrual!$E:$E,$AH7),AVERAGEIFS(data_event_accrual!$L:$L,data_event_accrual!$A:$A,"Jigsaw",data_event_accrual!$B:$B,$AI$3,data_event_accrual!$C:$C,"100+",data_event_accrual!$E:$E,$AH7)),1)),COUNTIF($B$11:$B$22,"<="&bal*shr))) | AR7: =IF($AH7="","",IF(AQ7=0,"{}",LET(m,AQ7,s,MMULT(SEQUENCE(1,m,1,0),ARRAY_CONSTRAIN($C$11:$W$22,m,21)),"{"&TEXTJOIN(", ",TRUE,ARRAYFORMULA(IF(s>0,$C$10:$W$10&": "&ROUND(s,2),"")))&"}")))
AH8: =IF(3<=$B$3,3,"") | AI8: =IF($AH8="","",LET(bal,SUMIFS(data_event_inst!$N:$N,data_event_inst!$A:$A,"Jigsaw",data_event_inst!$B:$B,$AI$3,data_event_inst!$C:$C,"0-9"),shr,MIN(1,IFERROR(CHOOSE(MATCH($AI$2,{"Avg","p25","p50","p75"},0),AVERAGEIFS(data_event_accrual!$I:$I,data_event_accrual!$A:$A,"Jigsaw",data_event_accrual!$B:$B,$AI$3,data_event_accrual!$C:$C,"0-9",data_event_accrual!$E:$E,$AH8),AVERAGEIFS(data_event_accrual!$K:$K,data_event_accrual!$A:$A,"Jigsaw",data_event_accrual!$B:$B,$AI$3,data_event_accrual!$C:$C,"0-9",data_event_accrual!$E:$E,$AH8),AVERAGEIFS(data_event_accrual!$J:$J,data_event_accrual!$A:$A,"Jigsaw",data_event_accrual!$B:$B,$AI$3,data_event_accrual!$C:$C,"0-9",data_event_accrual!$E:$E,$AH8),AVERAGEIFS(data_event_accrual!$L:$L,data_event_accrual!$A:$A,"Jigsaw",data_event_accrual!$B:$B,$AI$3,data_event_accrual!$C:$C,"0-9",data_event_accrual!$E:$E,$AH8)),1)),COUNTIF($B$11:$B$22,"<="&bal*shr))) | AJ8: =IF($AH8="","",IF(AI8=0,"{}",LET(m,AI8,s,MMULT(SEQUENCE(1,m,1,0),ARRAY_CONSTRAIN($C$11:$W$22,m,21)),"{"&TEXTJOIN(", ",TRUE,ARRAYFORMULA(IF(s>0,$C$10:$W$10&": "&ROUND(s,2),"")))&"}"))) | AK8: =IF($AH8="","",LET(bal,SUMIFS(data_event_inst!$N:$N,data_event_inst!$A:$A,"Jigsaw",data_event_inst!$B:$B,$AI$3,data_event_inst!$C:$C,"10-19"),shr,MIN(1,IFERROR(CHOOSE(MATCH($AI$2,{"Avg","p25","p50","p75"},0),AVERAGEIFS(data_event_accrual!$I:$I,data_event_accrual!$A:$A,"Jigsaw",data_event_accrual!$B:$B,$AI$3,data_event_accrual!$C:$C,"10-19",data_event_accrual!$E:$E,$AH8),AVERAGEIFS(data_event_accrual!$K:$K,data_event_accrual!$A:$A,"Jigsaw",data_event_accrual!$B:$B,$AI$3,data_event_accrual!$C:$C,"10-19",data_event_accrual!$E:$E,$AH8),AVERAGEIFS(data_event_accrual!$J:$J,data_event_accrual!$A:$A,"Jigsaw",data_event_accrual!$B:$B,$AI$3,data_event_accrual!$C:$C,"10-19",data_event_accrual!$E:$E,$AH8),AVERAGEIFS(data_event_accrual!$L:$L,data_event_accrual!$A:$A,"Jigsaw",data_event_accrual!$B:$B,$AI$3,data_event_accrual!$C:$C,"10-19",data_event_accrual!$E:$E,$AH8)),1)),COUNTIF($B$11:$B$22,"<="&bal*shr))) | AL8: =IF($AH8="","",IF(AK8=0,"{}",LET(m,AK8,s,MMULT(SEQUENCE(1,m,1,0),ARRAY_CONSTRAIN($C$11:$W$22,m,21)),"{"&TEXTJOIN(", ",TRUE,ARRAYFORMULA(IF(s>0,$C$10:$W$10&": "&ROUND(s,2),"")))&"}"))) | AM8: =IF($AH8="","",LET(bal,SUMIFS(data_event_inst!$N:$N,data_event_inst!$A:$A,"Jigsaw",data_event_inst!$B:$B,$AI$3,data_event_inst!$C:$C,"20-39"),shr,MIN(1,IFERROR(CHOOSE(MATCH($AI$2,{"Avg","p25","p50","p75"},0),AVERAGEIFS(data_event_accrual!$I:$I,data_event_accrual!$A:$A,"Jigsaw",data_event_accrual!$B:$B,$AI$3,data_event_accrual!$C:$C,"20-39",data_event_accrual!$E:$E,$AH8),AVERAGEIFS(data_event_accrual!$K:$K,data_event_accrual!$A:$A,"Jigsaw",data_event_accrual!$B:$B,$AI$3,data_event_accrual!$C:$C,"20-39",data_event_accrual!$E:$E,$AH8),AVERAGEIFS(data_event_accrual!$J:$J,data_event_accrual!$A:$A,"Jigsaw",data_event_accrual!$B:$B,$AI$3,data_event_accrual!$C:$C,"20-39",data_event_accrual!$E:$E,$AH8),AVERAGEIFS(data_event_accrual!$L:$L,data_event_accrual!$A:$A,"Jigsaw",data_event_accrual!$B:$B,$AI$3,data_event_accrual!$C:$C,"20-39",data_event_accrual!$E:$E,$AH8)),1)),COUNTIF($B$11:$B$22,"<="&bal*shr))) | AN8: =IF($AH8="","",IF(AM8=0,"{}",LET(m,AM8,s,MMULT(SEQUENCE(1,m,1,0),ARRAY_CONSTRAIN($C$11:$W$22,m,21)),"{"&TEXTJOIN(", ",TRUE,ARRAYFORMULA(IF(s>0,$C$10:$W$10&": "&ROUND(s,2),"")))&"}"))) | AO8: =IF($AH8="","",LET(bal,SUMIFS(data_event_inst!$N:$N,data_event_inst!$A:$A,"Jigsaw",data_event_inst!$B:$B,$AI$3,data_event_inst!$C:$C,"40-99"),shr,MIN(1,IFERROR(CHOOSE(MATCH($AI$2,{"Avg","p25","p50","p75"},0),AVERAGEIFS(data_event_accrual!$I:$I,data_event_accrual!$A:$A,"Jigsaw",data_event_accrual!$B:$B,$AI$3,data_event_accrual!$C:$C,"40-99",data_event_accrual!$E:$E,$AH8),AVERAGEIFS(data_event_accrual!$K:$K,data_event_accrual!$A:$A,"Jigsaw",data_event_accrual!$B:$B,$AI$3,data_event_accrual!$C:$C,"40-99",data_event_accrual!$E:$E,$AH8),AVERAGEIFS(data_event_accrual!$J:$J,data_event_accrual!$A:$A,"Jigsaw",data_event_accrual!$B:$B,$AI$3,data_event_accrual!$C:$C,"40-99",data_event_accrual!$E:$E,$AH8),AVERAGEIFS(data_event_accrual!$L:$L,data_event_accrual!$A:$A,"Jigsaw",data_event_accrual!$B:$B,$AI$3,data_event_accrual!$C:$C,"40-99",data_event_accrual!$E:$E,$AH8)),1)),COUNTIF($B$11:$B$22,"<="&bal*shr))) | AP8: =IF($AH8="","",IF(AO8=0,"{}",LET(m,AO8,s,MMULT(SEQUENCE(1,m,1,0),ARRAY_CONSTRAIN($C$11:$W$22,m,21)),"{"&TEXTJOIN(", ",TRUE,ARRAYFORMULA(IF(s>0,$C$10:$W$10&": "&ROUND(s,2),"")))&"}"))) | AQ8: =IF($AH8="","",LET(bal,SUMIFS(data_event_inst!$N:$N,data_event_inst!$A:$A,"Jigsaw",data_event_inst!$B:$B,$AI$3,data_event_inst!$C:$C,"100+"),shr,MIN(1,IFERROR(CHOOSE(MATCH($AI$2,{"Avg","p25","p50","p75"},0),AVERAGEIFS(data_event_accrual!$I:$I,data_event_accrual!$A:$A,"Jigsaw",data_event_accrual!$B:$B,$AI$3,data_event_accrual!$C:$C,"100+",data_event_accrual!$E:$E,$AH8),AVERAGEIFS(data_event_accrual!$K:$K,data_event_accrual!$A:$A,"Jigsaw",data_event_accrual!$B:$B,$AI$3,data_event_accrual!$C:$C,"100+",data_event_accrual!$E:$E,$AH8),AVERAGEIFS(data_event_accrual!$J:$J,data_event_accrual!$A:$A,"Jigsaw",data_event_accrual!$B:$B,$AI$3,data_event_accrual!$C:$C,"100+",data_event_accrual!$E:$E,$AH8),AVERAGEIFS(data_event_accrual!$L:$L,data_event_accrual!$A:$A,"Jigsaw",data_event_accrual!$B:$B,$AI$3,data_event_accrual!$C:$C,"100+",data_event_accrual!$E:$E,$AH8)),1)),COUNTIF($B$11:$B$22,"<="&bal*shr))) | AR8: =IF($AH8="","",IF(AQ8=0,"{}",LET(m,AQ8,s,MMULT(SEQUENCE(1,m,1,0),ARRAY_CONSTRAIN($C$11:$W$22,m,21)),"{"&TEXTJOIN(", ",TRUE,ARRAYFORMULA(IF(s>0,$C$10:$W$10&": "&ROUND(s,2),"")))&"}")))
A9: Goals and Rewards | AH9: =IF(4<=$B$3,4,"") | AI9: =IF($AH9="","",LET(bal,SUMIFS(data_event_inst!$N:$N,data_event_inst!$A:$A,"Jigsaw",data_event_inst!$B:$B,$AI$3,data_event_inst!$C:$C,"0-9"),shr,MIN(1,IFERROR(CHOOSE(MATCH($AI$2,{"Avg","p25","p50","p75"},0),AVERAGEIFS(data_event_accrual!$I:$I,data_event_accrual!$A:$A,"Jigsaw",data_event_accrual!$B:$B,$AI$3,data_event_accrual!$C:$C,"0-9",data_event_accrual!$E:$E,$AH9),AVERAGEIFS(data_event_accrual!$K:$K,data_event_accrual!$A:$A,"Jigsaw",data_event_accrual!$B:$B,$AI$3,data_event_accrual!$C:$C,"0-9",data_event_accrual!$E:$E,$AH9),AVERAGEIFS(data_event_accrual!$J:$J,data_event_accrual!$A:$A,"Jigsaw",data_event_accrual!$B:$B,$AI$3,data_event_accrual!$C:$C,"0-9",data_event_accrual!$E:$E,$AH9),AVERAGEIFS(data_event_accrual!$L:$L,data_event_accrual!$A:$A,"Jigsaw",data_event_accrual!$B:$B,$AI$3,data_event_accrual!$C:$C,"0-9",data_event_accrual!$E:$E,$AH9)),1)),COUNTIF($B$11:$B$22,"<="&bal*shr))) | AJ9: =IF($AH9="","",IF(AI9=0,"{}",LET(m,AI9,s,MMULT(SEQUENCE(1,m,1,0),ARRAY_CONSTRAIN($C$11:$W$22,m,21)),"{"&TEXTJOIN(", ",TRUE,ARRAYFORMULA(IF(s>0,$C$10:$W$10&": "&ROUND(s,2),"")))&"}"))) | AK9: =IF($AH9="","",LET(bal,SUMIFS(data_event_inst!$N:$N,data_event_inst!$A:$A,"Jigsaw",data_event_inst!$B:$B,$AI$3,data_event_inst!$C:$C,"10-19"),shr,MIN(1,IFERROR(CHOOSE(MATCH($AI$2,{"Avg","p25","p50","p75"},0),AVERAGEIFS(data_event_accrual!$I:$I,data_event_accrual!$A:$A,"Jigsaw",data_event_accrual!$B:$B,$AI$3,data_event_accrual!$C:$C,"10-19",data_event_accrual!$E:$E,$AH9),AVERAGEIFS(data_event_accrual!$K:$K,data_event_accrual!$A:$A,"Jigsaw",data_event_accrual!$B:$B,$AI$3,data_event_accrual!$C:$C,"10-19",data_event_accrual!$E:$E,$AH9),AVERAGEIFS(data_event_accrual!$J:$J,data_event_accrual!$A:$A,"Jigsaw",data_event_accrual!$B:$B,$AI$3,data_event_accrual!$C:$C,"10-19",data_event_accrual!$E:$E,$AH9),AVERAGEIFS(data_event_accrual!$L:$L,data_event_accrual!$A:$A,"Jigsaw",data_event_accrual!$B:$B,$AI$3,data_event_accrual!$C:$C,"10-19",data_event_accrual!$E:$E,$AH9)),1)),COUNTIF($B$11:$B$22,"<="&bal*shr))) | AL9: =IF($AH9="","",IF(AK9=0,"{}",LET(m,AK9,s,MMULT(SEQUENCE(1,m,1,0),ARRAY_CONSTRAIN($C$11:$W$22,m,21)),"{"&TEXTJOIN(", ",TRUE,ARRAYFORMULA(IF(s>0,$C$10:$W$10&": "&ROUND(s,2),"")))&"}"))) | AM9: =IF($AH9="","",LET(bal,SUMIFS(data_event_inst!$N:$N,data_event_inst!$A:$A,"Jigsaw",data_event_inst!$B:$B,$AI$3,data_event_inst!$C:$C,"20-39"),shr,MIN(1,IFERROR(CHOOSE(MATCH($AI$2,{"Avg","p25","p50","p75"},0),AVERAGEIFS(data_event_accrual!$I:$I,data_event_accrual!$A:$A,"Jigsaw",data_event_accrual!$B:$B,$AI$3,data_event_accrual!$C:$C,"20-39",data_event_accrual!$E:$E,$AH9),AVERAGEIFS(data_event_accrual!$K:$K,data_event_accrual!$A:$A,"Jigsaw",data_event_accrual!$B:$B,$AI$3,data_event_accrual!$C:$C,"20-39",data_event_accrual!$E:$E,$AH9),AVERAGEIFS(data_event_accrual!$J:$J,data_event_accrual!$A:$A,"Jigsaw",data_event_accrual!$B:$B,$AI$3,data_event_accrual!$C:$C,"20-39",data_event_accrual!$E:$E,$AH9),AVERAGEIFS(data_event_accrual!$L:$L,data_event_accrual!$A:$A,"Jigsaw",data_event_accrual!$B:$B,$AI$3,data_event_accrual!$C:$C,"20-39",data_event_accrual!$E:$E,$AH9)),1)),COUNTIF($B$11:$B$22,"<="&bal*shr))) | AN9: =IF($AH9="","",IF(AM9=0,"{}",LET(m,AM9,s,MMULT(SEQUENCE(1,m,1,0),ARRAY_CONSTRAIN($C$11:$W$22,m,21)),"{"&TEXTJOIN(", ",TRUE,ARRAYFORMULA(IF(s>0,$C$10:$W$10&": "&ROUND(s,2),"")))&"}"))) | AO9: =IF($AH9="","",LET(bal,SUMIFS(data_event_inst!$N:$N,data_event_inst!$A:$A,"Jigsaw",data_event_inst!$B:$B,$AI$3,data_event_inst!$C:$C,"40-99"),shr,MIN(1,IFERROR(CHOOSE(MATCH($AI$2,{"Avg","p25","p50","p75"},0),AVERAGEIFS(data_event_accrual!$I:$I,data_event_accrual!$A:$A,"Jigsaw",data_event_accrual!$B:$B,$AI$3,data_event_accrual!$C:$C,"40-99",data_event_accrual!$E:$E,$AH9),AVERAGEIFS(data_event_accrual!$K:$K,data_event_accrual!$A:$A,"Jigsaw",data_event_accrual!$B:$B,$AI$3,data_event_accrual!$C:$C,"40-99",data_event_accrual!$E:$E,$AH9),AVERAGEIFS(data_event_accrual!$J:$J,data_event_accrual!$A:$A,"Jigsaw",data_event_accrual!$B:$B,$AI$3,data_event_accrual!$C:$C,"40-99",data_event_accrual!$E:$E,$AH9),AVERAGEIFS(data_event_accrual!$L:$L,data_event_accrual!$A:$A,"Jigsaw",data_event_accrual!$B:$B,$AI$3,data_event_accrual!$C:$C,"40-99",data_event_accrual!$E:$E,$AH9)),1)),COUNTIF($B$11:$B$22,"<="&bal*shr))) | AP9: =IF($AH9="","",IF(AO9=0,"{}",LET(m,AO9,s,MMULT(SEQUENCE(1,m,1,0),ARRAY_CONSTRAIN($C$11:$W$22,m,21)),"{"&TEXTJOIN(", ",TRUE,ARRAYFORMULA(IF(s>0,$C$10:$W$10&": "&ROUND(s,2),"")))&"}"))) | AQ9: =IF($AH9="","",LET(bal,SUMIFS(data_event_inst!$N:$N,data_event_inst!$A:$A,"Jigsaw",data_event_inst!$B:$B,$AI$3,data_event_inst!$C:$C,"100+"),shr,MIN(1,IFERROR(CHOOSE(MATCH($AI$2,{"Avg","p25","p50","p75"},0),AVERAGEIFS(data_event_accrual!$I:$I,data_event_accrual!$A:$A,"Jigsaw",data_event_accrual!$B:$B,$AI$3,data_event_accrual!$C:$C,"100+",data_event_accrual!$E:$E,$AH9),AVERAGEIFS(data_event_accrual!$K:$K,data_event_accrual!$A:$A,"Jigsaw",data_event_accrual!$B:$B,$AI$3,data_event_accrual!$C:$C,"100+",data_event_accrual!$E:$E,$AH9),AVERAGEIFS(data_event_accrual!$J:$J,data_event_accrual!$A:$A,"Jigsaw",data_event_accrual!$B:$B,$AI$3,data_event_accrual!$C:$C,"100+",data_event_accrual!$E:$E,$AH9),AVERAGEIFS(data_event_accrual!$L:$L,data_event_accrual!$A:$A,"Jigsaw",data_event_accrual!$B:$B,$AI$3,data_event_accrual!$C:$C,"100+",data_event_accrual!$E:$E,$AH9)),1)),COUNTIF($B$11:$B$22,"<="&bal*shr))) | AR9: =IF($AH9="","",IF(AQ9=0,"{}",LET(m,AQ9,s,MMULT(SEQUENCE(1,m,1,0),ARRAY_CONSTRAIN($C$11:$W$22,m,21)),"{"&TEXTJOIN(", ",TRUE,ARRAYFORMULA(IF(s>0,$C$10:$W$10&": "&ROUND(s,2),"")))&"}")))
A10: Milestone | B10: Cumul token req | C10: Coins | D10: SPT | E10: SPT x2 | F10: Red | G10: Chuck | H10: Bomb | I10: Slingshot | J10: Shuffle | K10: Comet | L10: Unlimited Lives | M10: Unlimited Red | N10: Unlimited Chuck | O10: Unlimited Bomb | P10: COOP Token | Q10: Avatar | R10: 1-star Dly | S10: 2-star Dly | T10: 3-star Dly | U10: 4-star Dly | V10: 5-star Dly | W10: 6-star Dly | AH10: =IF(5<=$B$3,5,"") | AI10: =IF($AH10="","",LET(bal,SUMIFS(data_event_inst!$N:$N,data_event_inst!$A:$A,"Jigsaw",data_event_inst!$B:$B,$AI$3,data_event_inst!$C:$C,"0-9"),shr,MIN(1,IFERROR(CHOOSE(MATCH($AI$2,{"Avg","p25","p50","p75"},0),AVERAGEIFS(data_event_accrual!$I:$I,data_event_accrual!$A:$A,"Jigsaw",data_event_accrual!$B:$B,$AI$3,data_event_accrual!$C:$C,"0-9",data_event_accrual!$E:$E,$AH10),AVERAGEIFS(data_event_accrual!$K:$K,data_event_accrual!$A:$A,"Jigsaw",data_event_accrual!$B:$B,$AI$3,data_event_accrual!$C:$C,"0-9",data_event_accrual!$E:$E,$AH10),AVERAGEIFS(data_event_accrual!$J:$J,data_event_accrual!$A:$A,"Jigsaw",data_event_accrual!$B:$B,$AI$3,data_event_accrual!$C:$C,"0-9",data_event_accrual!$E:$E,$AH10),AVERAGEIFS(data_event_accrual!$L:$L,data_event_accrual!$A:$A,"Jigsaw",data_event_accrual!$B:$B,$AI$3,data_event_accrual!$C:$C,"0-9",data_event_accrual!$E:$E,$AH10)),1)),COUNTIF($B$11:$B$22,"<="&bal*shr))) | AJ10: =IF($AH10="","",IF(AI10=0,"{}",LET(m,AI10,s,MMULT(SEQUENCE(1,m,1,0),ARRAY_CONSTRAIN($C$11:$W$22,m,21)),"{"&TEXTJOIN(", ",TRUE,ARRAYFORMULA(IF(s>0,$C$10:$W$10&": "&ROUND(s,2),"")))&"}"))) | AK10: =IF($AH10="","",LET(bal,SUMIFS(data_event_inst!$N:$N,data_event_inst!$A:$A,"Jigsaw",data_event_inst!$B:$B,$AI$3,data_event_inst!$C:$C,"10-19"),shr,MIN(1,IFERROR(CHOOSE(MATCH($AI$2,{"Avg","p25","p50","p75"},0),AVERAGEIFS(data_event_accrual!$I:$I,data_event_accrual!$A:$A,"Jigsaw",data_event_accrual!$B:$B,$AI$3,data_event_accrual!$C:$C,"10-19",data_event_accrual!$E:$E,$AH10),AVERAGEIFS(data_event_accrual!$K:$K,data_event_accrual!$A:$A,"Jigsaw",data_event_accrual!$B:$B,$AI$3,data_event_accrual!$C:$C,"10-19",data_event_accrual!$E:$E,$AH10),AVERAGEIFS(data_event_accrual!$J:$J,data_event_accrual!$A:$A,"Jigsaw",data_event_accrual!$B:$B,$AI$3,data_event_accrual!$C:$C,"10-19",data_event_accrual!$E:$E,$AH10),AVERAGEIFS(data_event_accrual!$L:$L,data_event_accrual!$A:$A,"Jigsaw",data_event_accrual!$B:$B,$AI$3,data_event_accrual!$C:$C,"10-19",data_event_accrual!$E:$E,$AH10)),1)),COUNTIF($B$11:$B$22,"<="&bal*shr))) | AL10: =IF($AH10="","",IF(AK10=0,"{}",LET(m,AK10,s,MMULT(SEQUENCE(1,m,1,0),ARRAY_CONSTRAIN($C$11:$W$22,m,21)),"{"&TEXTJOIN(", ",TRUE,ARRAYFORMULA(IF(s>0,$C$10:$W$10&": "&ROUND(s,2),"")))&"}"))) | AM10: =IF($AH10="","",LET(bal,SUMIFS(data_event_inst!$N:$N,data_event_inst!$A:$A,"Jigsaw",data_event_inst!$B:$B,$AI$3,data_event_inst!$C:$C,"20-39"),shr,MIN(1,IFERROR(CHOOSE(MATCH($AI$2,{"Avg","p25","p50","p75"},0),AVERAGEIFS(data_event_accrual!$I:$I,data_event_accrual!$A:$A,"Jigsaw",data_event_accrual!$B:$B,$AI$3,data_event_accrual!$C:$C,"20-39",data_event_accrual!$E:$E,$AH10),AVERAGEIFS(data_event_accrual!$K:$K,data_event_accrual!$A:$A,"Jigsaw",data_event_accrual!$B:$B,$AI$3,data_event_accrual!$C:$C,"20-39",data_event_accrual!$E:$E,$AH10),AVERAGEIFS(data_event_accrual!$J:$J,data_event_accrual!$A:$A,"Jigsaw",data_event_accrual!$B:$B,$AI$3,data_event_accrual!$C:$C,"20-39",data_event_accrual!$E:$E,$AH10),AVERAGEIFS(data_event_accrual!$L:$L,data_event_accrual!$A:$A,"Jigsaw",data_event_accrual!$B:$B,$AI$3,data_event_accrual!$C:$C,"20-39",data_event_accrual!$E:$E,$AH10)),1)),COUNTIF($B$11:$B$22,"<="&bal*shr))) | AN10: =IF($AH10="","",IF(AM10=0,"{}",LET(m,AM10,s,MMULT(SEQUENCE(1,m,1,0),ARRAY_CONSTRAIN($C$11:$W$22,m,21)),"{"&TEXTJOIN(", ",TRUE,ARRAYFORMULA(IF(s>0,$C$10:$W$10&": "&ROUND(s,2),"")))&"}"))) | AO10: =IF($AH10="","",LET(bal,SUMIFS(data_event_inst!$N:$N,data_event_inst!$A:$A,"Jigsaw",data_event_inst!$B:$B,$AI$3,data_event_inst!$C:$C,"40-99"),shr,MIN(1,IFERROR(CHOOSE(MATCH($AI$2,{"Avg","p25","p50","p75"},0),AVERAGEIFS(data_event_accrual!$I:$I,data_event_accrual!$A:$A,"Jigsaw",data_event_accrual!$B:$B,$AI$3,data_event_accrual!$C:$C,"40-99",data_event_accrual!$E:$E,$AH10),AVERAGEIFS(data_event_accrual!$K:$K,data_event_accrual!$A:$A,"Jigsaw",data_event_accrual!$B:$B,$AI$3,data_event_accrual!$C:$C,"40-99",data_event_accrual!$E:$E,$AH10),AVERAGEIFS(data_event_accrual!$J:$J,data_event_accrual!$A:$A,"Jigsaw",data_event_accrual!$B:$B,$AI$3,data_event_accrual!$C:$C,"40-99",data_event_accrual!$E:$E,$AH10),AVERAGEIFS(data_event_accrual!$L:$L,data_event_accrual!$A:$A,"Jigsaw",data_event_accrual!$B:$B,$AI$3,data_event_accrual!$C:$C,"40-99",data_event_accrual!$E:$E,$AH10)),1)),COUNTIF($B$11:$B$22,"<="&bal*shr))) | AP10: =IF($AH10="","",IF(AO10=0,"{}",LET(m,AO10,s,MMULT(SEQUENCE(1,m,1,0),ARRAY_CONSTRAIN($C$11:$W$22,m,21)),"{"&TEXTJOIN(", ",TRUE,ARRAYFORMULA(IF(s>0,$C$10:$W$10&": "&ROUND(s,2),"")))&"}"))) | AQ10: =IF($AH10="","",LET(bal,SUMIFS(data_event_inst!$N:$N,data_event_inst!$A:$A,"Jigsaw",data_event_inst!$B:$B,$AI$3,data_event_inst!$C:$C,"100+"),shr,MIN(1,IFERROR(CHOOSE(MATCH($AI$2,{"Avg","p25","p50","p75"},0),AVERAGEIFS(data_event_accrual!$I:$I,data_event_accrual!$A:$A,"Jigsaw",data_event_accrual!$B:$B,$AI$3,data_event_accrual!$C:$C,"100+",data_event_accrual!$E:$E,$AH10),AVERAGEIFS(data_event_accrual!$K:$K,data_event_accrual!$A:$A,"Jigsaw",data_event_accrual!$B:$B,$AI$3,data_event_accrual!$C:$C,"100+",data_event_accrual!$E:$E,$AH10),AVERAGEIFS(data_event_accrual!$J:$J,data_event_accrual!$A:$A,"Jigsaw",data_event_accrual!$B:$B,$AI$3,data_event_accrual!$C:$C,"100+",data_event_accrual!$E:$E,$AH10),AVERAGEIFS(data_event_accrual!$L:$L,data_event_accrual!$A:$A,"Jigsaw",data_event_accrual!$B:$B,$AI$3,data_event_accrual!$C:$C,"100+",data_event_accrual!$E:$E,$AH10)),1)),COUNTIF($B$11:$B$22,"<="&bal*shr))) | AR10: =IF($AH10="","",IF(AQ10=0,"{}",LET(m,AQ10,s,MMULT(SEQUENCE(1,m,1,0),ARRAY_CONSTRAIN($C$11:$W$22,m,21)),"{"&TEXTJOIN(", ",TRUE,ARRAYFORMULA(IF(s>0,$C$10:$W$10&": "&ROUND(s,2),"")))&"}")))
A11: 1 | B11: 30 | C11: 0 | D11: 0 | E11: 0 | F11: 0 | G11: 1 | H11: 0 | I11: 0 | J11: 0 | K11: 0 | L11: 0 | M11: 0 | N11: 0 | O11: 0 | P11: 0 | Q11: 0 | R11: 0 | S11: 0 | T11: 0 | U11: 0 | V11: 0 | W11: 0 | AH11: =IF(6<=$B$3,6,"") | AI11: =IF($AH11="","",LET(bal,SUMIFS(data_event_inst!$N:$N,data_event_inst!$A:$A,"Jigsaw",data_event_inst!$B:$B,$AI$3,data_event_inst!$C:$C,"0-9"),shr,MIN(1,IFERROR(CHOOSE(MATCH($AI$2,{"Avg","p25","p50","p75"},0),AVERAGEIFS(data_event_accrual!$I:$I,data_event_accrual!$A:$A,"Jigsaw",data_event_accrual!$B:$B,$AI$3,data_event_accrual!$C:$C,"0-9",data_event_accrual!$E:$E,$AH11),AVERAGEIFS(data_event_accrual!$K:$K,data_event_accrual!$A:$A,"Jigsaw",data_event_accrual!$B:$B,$AI$3,data_event_accrual!$C:$C,"0-9",data_event_accrual!$E:$E,$AH11),AVERAGEIFS(data_event_accrual!$J:$J,data_event_accrual!$A:$A,"Jigsaw",data_event_accrual!$B:$B,$AI$3,data_event_accrual!$C:$C,"0-9",data_event_accrual!$E:$E,$AH11),AVERAGEIFS(data_event_accrual!$L:$L,data_event_accrual!$A:$A,"Jigsaw",data_event_accrual!$B:$B,$AI$3,data_event_accrual!$C:$C,"0-9",data_event_accrual!$E:$E,$AH11)),1)),COUNTIF($B$11:$B$22,"<="&bal*shr))) | AJ11: =IF($AH11="","",IF(AI11=0,"{}",LET(m,AI11,s,MMULT(SEQUENCE(1,m,1,0),ARRAY_CONSTRAIN($C$11:$W$22,m,21)),"{"&TEXTJOIN(", ",TRUE,ARRAYFORMULA(IF(s>0,$C$10:$W$10&": "&ROUND(s,2),"")))&"}"))) | AK11: =IF($AH11="","",LET(bal,SUMIFS(data_event_inst!$N:$N,data_event_inst!$A:$A,"Jigsaw",data_event_inst!$B:$B,$AI$3,data_event_inst!$C:$C,"10-19"),shr,MIN(1,IFERROR(CHOOSE(MATCH($AI$2,{"Avg","p25","p50","p75"},0),AVERAGEIFS(data_event_accrual!$I:$I,data_event_accrual!$A:$A,"Jigsaw",data_event_accrual!$B:$B,$AI$3,data_event_accrual!$C:$C,"10-19",data_event_accrual!$E:$E,$AH11),AVERAGEIFS(data_event_accrual!$K:$K,data_event_accrual!$A:$A,"Jigsaw",data_event_accrual!$B:$B,$AI$3,data_event_accrual!$C:$C,"10-19",data_event_accrual!$E:$E,$AH11),AVERAGEIFS(data_event_accrual!$J:$J,data_event_accrual!$A:$A,"Jigsaw",data_event_accrual!$B:$B,$AI$3,data_event_accrual!$C:$C,"10-19",data_event_accrual!$E:$E,$AH11),AVERAGEIFS(data_event_accrual!$L:$L,data_event_accrual!$A:$A,"Jigsaw",data_event_accrual!$B:$B,$AI$3,data_event_accrual!$C:$C,"10-19",data_event_accrual!$E:$E,$AH11)),1)),COUNTIF($B$11:$B$22,"<="&bal*shr))) | AL11: =IF($AH11="","",IF(AK11=0,"{}",LET(m,AK11,s,MMULT(SEQUENCE(1,m,1,0),ARRAY_CONSTRAIN($C$11:$W$22,m,21)),"{"&TEXTJOIN(", ",TRUE,ARRAYFORMULA(IF(s>0,$C$10:$W$10&": "&ROUND(s,2),"")))&"}"))) | AM11: =IF($AH11="","",LET(bal,SUMIFS(data_event_inst!$N:$N,data_event_inst!$A:$A,"Jigsaw",data_event_inst!$B:$B,$AI$3,data_event_inst!$C:$C,"20-39"),shr,MIN(1,IFERROR(CHOOSE(MATCH($AI$2,{"Avg","p25","p50","p75"},0),AVERAGEIFS(data_event_accrual!$I:$I,data_event_accrual!$A:$A,"Jigsaw",data_event_accrual!$B:$B,$AI$3,data_event_accrual!$C:$C,"20-39",data_event_accrual!$E:$E,$AH11),AVERAGEIFS(data_event_accrual!$K:$K,data_event_accrual!$A:$A,"Jigsaw",data_event_accrual!$B:$B,$AI$3,data_event_accrual!$C:$C,"20-39",data_event_accrual!$E:$E,$AH11),AVERAGEIFS(data_event_accrual!$J:$J,data_event_accrual!$A:$A,"Jigsaw",data_event_accrual!$B:$B,$AI$3,data_event_accrual!$C:$C,"20-39",data_event_accrual!$E:$E,$AH11),AVERAGEIFS(data_event_accrual!$L:$L,data_event_accrual!$A:$A,"Jigsaw",data_event_accrual!$B:$B,$AI$3,data_event_accrual!$C:$C,"20-39",data_event_accrual!$E:$E,$AH11)),1)),COUNTIF($B$11:$B$22,"<="&bal*shr))) | AN11: =IF($AH11="","",IF(AM11=0,"{}",LET(m,AM11,s,MMULT(SEQUENCE(1,m,1,0),ARRAY_CONSTRAIN($C$11:$W$22,m,21)),"{"&TEXTJOIN(", ",TRUE,ARRAYFORMULA(IF(s>0,$C$10:$W$10&": "&ROUND(s,2),"")))&"}"))) | AO11: =IF($AH11="","",LET(bal,SUMIFS(data_event_inst!$N:$N,data_event_inst!$A:$A,"Jigsaw",data_event_inst!$B:$B,$AI$3,data_event_inst!$C:$C,"40-99"),shr,MIN(1,IFERROR(CHOOSE(MATCH($AI$2,{"Avg","p25","p50","p75"},0),AVERAGEIFS(data_event_accrual!$I:$I,data_event_accrual!$A:$A,"Jigsaw",data_event_accrual!$B:$B,$AI$3,data_event_accrual!$C:$C,"40-99",data_event_accrual!$E:$E,$AH11),AVERAGEIFS(data_event_accrual!$K:$K,data_event_accrual!$A:$A,"Jigsaw",data_event_accrual!$B:$B,$AI$3,data_event_accrual!$C:$C,"40-99",data_event_accrual!$E:$E,$AH11),AVERAGEIFS(data_event_accrual!$J:$J,data_event_accrual!$A:$A,"Jigsaw",data_event_accrual!$B:$B,$AI$3,data_event_accrual!$C:$C,"40-99",data_event_accrual!$E:$E,$AH11),AVERAGEIFS(data_event_accrual!$L:$L,data_event_accrual!$A:$A,"Jigsaw",data_event_accrual!$B:$B,$AI$3,data_event_accrual!$C:$C,"40-99",data_event_accrual!$E:$E,$AH11)),1)),COUNTIF($B$11:$B$22,"<="&bal*shr))) | AP11: =IF($AH11="","",IF(AO11=0,"{}",LET(m,AO11,s,MMULT(SEQUENCE(1,m,1,0),ARRAY_CONSTRAIN($C$11:$W$22,m,21)),"{"&TEXTJOIN(", ",TRUE,ARRAYFORMULA(IF(s>0,$C$10:$W$10&": "&ROUND(s,2),"")))&"}"))) | AQ11: =IF($AH11="","",LET(bal,SUMIFS(data_event_inst!$N:$N,data_event_inst!$A:$A,"Jigsaw",data_event_inst!$B:$B,$AI$3,data_event_inst!$C:$C,"100+"),shr,MIN(1,IFERROR(CHOOSE(MATCH($AI$2,{"Avg","p25","p50","p75"},0),AVERAGEIFS(data_event_accrual!$I:$I,data_event_accrual!$A:$A,"Jigsaw",data_event_accrual!$B:$B,$AI$3,data_event_accrual!$C:$C,"100+",data_event_accrual!$E:$E,$AH11),AVERAGEIFS(data_event_accrual!$K:$K,data_event_accrual!$A:$A,"Jigsaw",data_event_accrual!$B:$B,$AI$3,data_event_accrual!$C:$C,"100+",data_event_accrual!$E:$E,$AH11),AVERAGEIFS(data_event_accrual!$J:$J,data_event_accrual!$A:$A,"Jigsaw",data_event_accrual!$B:$B,$AI$3,data_event_accrual!$C:$C,"100+",data_event_accrual!$E:$E,$AH11),AVERAGEIFS(data_event_accrual!$L:$L,data_event_accrual!$A:$A,"Jigsaw",data_event_accrual!$B:$B,$AI$3,data_event_accrual!$C:$C,"100+",data_event_accrual!$E:$E,$AH11)),1)),COUNTIF($B$11:$B$22,"<="&bal*shr))) | AR11: =IF($AH11="","",IF(AQ11=0,"{}",LET(m,AQ11,s,MMULT(SEQUENCE(1,m,1,0),ARRAY_CONSTRAIN($C$11:$W$22,m,21)),"{"&TEXTJOIN(", ",TRUE,ARRAYFORMULA(IF(s>0,$C$10:$W$10&": "&ROUND(s,2),"")))&"}")))
A12: 2 | B12: 80 | C12: 0 | D12: 0 | E12: 0 | F12: 0 | G12: 0 | H12: 0 | I12: 0 | J12: 0 | K12: 0 | L12: 0 | M12: 10 | N12: 0 | O12: 0 | P12: 0 | Q12: 0 | R12: 0 | S12: 0 | T12: 0 | U12: 0 | V12: 0 | W12: 0 | AH12: =IF(7<=$B$3,7,"") | AI12: =IF($AH12="","",LET(bal,SUMIFS(data_event_inst!$N:$N,data_event_inst!$A:$A,"Jigsaw",data_event_inst!$B:$B,$AI$3,data_event_inst!$C:$C,"0-9"),shr,MIN(1,IFERROR(CHOOSE(MATCH($AI$2,{"Avg","p25","p50","p75"},0),AVERAGEIFS(data_event_accrual!$I:$I,data_event_accrual!$A:$A,"Jigsaw",data_event_accrual!$B:$B,$AI$3,data_event_accrual!$C:$C,"0-9",data_event_accrual!$E:$E,$AH12),AVERAGEIFS(data_event_accrual!$K:$K,data_event_accrual!$A:$A,"Jigsaw",data_event_accrual!$B:$B,$AI$3,data_event_accrual!$C:$C,"0-9",data_event_accrual!$E:$E,$AH12),AVERAGEIFS(data_event_accrual!$J:$J,data_event_accrual!$A:$A,"Jigsaw",data_event_accrual!$B:$B,$AI$3,data_event_accrual!$C:$C,"0-9",data_event_accrual!$E:$E,$AH12),AVERAGEIFS(data_event_accrual!$L:$L,data_event_accrual!$A:$A,"Jigsaw",data_event_accrual!$B:$B,$AI$3,data_event_accrual!$C:$C,"0-9",data_event_accrual!$E:$E,$AH12)),1)),COUNTIF($B$11:$B$22,"<="&bal*shr))) | AJ12: =IF($AH12="","",IF(AI12=0,"{}",LET(m,AI12,s,MMULT(SEQUENCE(1,m,1,0),ARRAY_CONSTRAIN($C$11:$W$22,m,21)),"{"&TEXTJOIN(", ",TRUE,ARRAYFORMULA(IF(s>0,$C$10:$W$10&": "&ROUND(s,2),"")))&"}"))) | AK12: =IF($AH12="","",LET(bal,SUMIFS(data_event_inst!$N:$N,data_event_inst!$A:$A,"Jigsaw",data_event_inst!$B:$B,$AI$3,data_event_inst!$C:$C,"10-19"),shr,MIN(1,IFERROR(CHOOSE(MATCH($AI$2,{"Avg","p25","p50","p75"},0),AVERAGEIFS(data_event_accrual!$I:$I,data_event_accrual!$A:$A,"Jigsaw",data_event_accrual!$B:$B,$AI$3,data_event_accrual!$C:$C,"10-19",data_event_accrual!$E:$E,$AH12),AVERAGEIFS(data_event_accrual!$K:$K,data_event_accrual!$A:$A,"Jigsaw",data_event_accrual!$B:$B,$AI$3,data_event_accrual!$C:$C,"10-19",data_event_accrual!$E:$E,$AH12),AVERAGEIFS(data_event_accrual!$J:$J,data_event_accrual!$A:$A,"Jigsaw",data_event_accrual!$B:$B,$AI$3,data_event_accrual!$C:$C,"10-19",data_event_accrual!$E:$E,$AH12),AVERAGEIFS(data_event_accrual!$L:$L,data_event_accrual!$A:$A,"Jigsaw",data_event_accrual!$B:$B,$AI$3,data_event_accrual!$C:$C,"10-19",data_event_accrual!$E:$E,$AH12)),1)),COUNTIF($B$11:$B$22,"<="&bal*shr))) | AL12: =IF($AH12="","",IF(AK12=0,"{}",LET(m,AK12,s,MMULT(SEQUENCE(1,m,1,0),ARRAY_CONSTRAIN($C$11:$W$22,m,21)),"{"&TEXTJOIN(", ",TRUE,ARRAYFORMULA(IF(s>0,$C$10:$W$10&": "&ROUND(s,2),"")))&"}"))) | AM12: =IF($AH12="","",LET(bal,SUMIFS(data_event_inst!$N:$N,data_event_inst!$A:$A,"Jigsaw",data_event_inst!$B:$B,$AI$3,data_event_inst!$C:$C,"20-39"),shr,MIN(1,IFERROR(CHOOSE(MATCH($AI$2,{"Avg","p25","p50","p75"},0),AVERAGEIFS(data_event_accrual!$I:$I,data_event_accrual!$A:$A,"Jigsaw",data_event_accrual!$B:$B,$AI$3,data_event_accrual!$C:$C,"20-39",data_event_accrual!$E:$E,$AH12),AVERAGEIFS(data_event_accrual!$K:$K,data_event_accrual!$A:$A,"Jigsaw",data_event_accrual!$B:$B,$AI$3,data_event_accrual!$C:$C,"20-39",data_event_accrual!$E:$E,$AH12),AVERAGEIFS(data_event_accrual!$J:$J,data_event_accrual!$A:$A,"Jigsaw",data_event_accrual!$B:$B,$AI$3,data_event_accrual!$C:$C,"20-39",data_event_accrual!$E:$E,$AH12),AVERAGEIFS(data_event_accrual!$L:$L,data_event_accrual!$A:$A,"Jigsaw",data_event_accrual!$B:$B,$AI$3,data_event_accrual!$C:$C,"20-39",data_event_accrual!$E:$E,$AH12)),1)),COUNTIF($B$11:$B$22,"<="&bal*shr))) | AN12: =IF($AH12="","",IF(AM12=0,"{}",LET(m,AM12,s,MMULT(SEQUENCE(1,m,1,0),ARRAY_CONSTRAIN($C$11:$W$22,m,21)),"{"&TEXTJOIN(", ",TRUE,ARRAYFORMULA(IF(s>0,$C$10:$W$10&": "&ROUND(s,2),"")))&"}"))) | AO12: =IF($AH12="","",LET(bal,SUMIFS(data_event_inst!$N:$N,data_event_inst!$A:$A,"Jigsaw",data_event_inst!$B:$B,$AI$3,data_event_inst!$C:$C,"40-99"),shr,MIN(1,IFERROR(CHOOSE(MATCH($AI$2,{"Avg","p25","p50","p75"},0),AVERAGEIFS(data_event_accrual!$I:$I,data_event_accrual!$A:$A,"Jigsaw",data_event_accrual!$B:$B,$AI$3,data_event_accrual!$C:$C,"40-99",data_event_accrual!$E:$E,$AH12),AVERAGEIFS(data_event_accrual!$K:$K,data_event_accrual!$A:$A,"Jigsaw",data_event_accrual!$B:$B,$AI$3,data_event_accrual!$C:$C,"40-99",data_event_accrual!$E:$E,$AH12),AVERAGEIFS(data_event_accrual!$J:$J,data_event_accrual!$A:$A,"Jigsaw",data_event_accrual!$B:$B,$AI$3,data_event_accrual!$C:$C,"40-99",data_event_accrual!$E:$E,$AH12),AVERAGEIFS(data_event_accrual!$L:$L,data_event_accrual!$A:$A,"Jigsaw",data_event_accrual!$B:$B,$AI$3,data_event_accrual!$C:$C,"40-99",data_event_accrual!$E:$E,$AH12)),1)),COUNTIF($B$11:$B$22,"<="&bal*shr))) | AP12: =IF($AH12="","",IF(AO12=0,"{}",LET(m,AO12,s,MMULT(SEQUENCE(1,m,1,0),ARRAY_CONSTRAIN($C$11:$W$22,m,21)),"{"&TEXTJOIN(", ",TRUE,ARRAYFORMULA(IF(s>0,$C$10:$W$10&": "&ROUND(s,2),"")))&"}"))) | AQ12: =IF($AH12="","",LET(bal,SUMIFS(data_event_inst!$N:$N,data_event_inst!$A:$A,"Jigsaw",data_event_inst!$B:$B,$AI$3,data_event_inst!$C:$C,"100+"),shr,MIN(1,IFERROR(CHOOSE(MATCH($AI$2,{"Avg","p25","p50","p75"},0),AVERAGEIFS(data_event_accrual!$I:$I,data_event_accrual!$A:$A,"Jigsaw",data_event_accrual!$B:$B,$AI$3,data_event_accrual!$C:$C,"100+",data_event_accrual!$E:$E,$AH12),AVERAGEIFS(data_event_accrual!$K:$K,data_event_accrual!$A:$A,"Jigsaw",data_event_accrual!$B:$B,$AI$3,data_event_accrual!$C:$C,"100+",data_event_accrual!$E:$E,$AH12),AVERAGEIFS(data_event_accrual!$J:$J,data_event_accrual!$A:$A,"Jigsaw",data_event_accrual!$B:$B,$AI$3,data_event_accrual!$C:$C,"100+",data_event_accrual!$E:$E,$AH12),AVERAGEIFS(data_event_accrual!$L:$L,data_event_accrual!$A:$A,"Jigsaw",data_event_accrual!$B:$B,$AI$3,data_event_accrual!$C:$C,"100+",data_event_accrual!$E:$E,$AH12)),1)),COUNTIF($B$11:$B$22,"<="&bal*shr))) | AR12: =IF($AH12="","",IF(AQ12=0,"{}",LET(m,AQ12,s,MMULT(SEQUENCE(1,m,1,0),ARRAY_CONSTRAIN($C$11:$W$22,m,21)),"{"&TEXTJOIN(", ",TRUE,ARRAYFORMULA(IF(s>0,$C$10:$W$10&": "&ROUND(s,2),"")))&"}")))
A13: 3 | B13: 150 | C13: 0 | D13: 0 | E13: 0 | F13: 0 | G13: 0 | H13: 0 | I13: 0 | J13: 0 | K13: 0 | L13: 0 | M13: 0 | N13: 10 | O13: 0 | P13: 0 | Q13: 0 | R13: 0 | S13: 0 | T13: 0 | U13: 0 | V13: 0 | W13: 0
A14: 4 | B14: 250 | C14: 0 | D14: 0 | E14: 0 | F14: 0 | G14: 0 | H14: 0 | I14: 0 | J14: 0 | K14: 0 | L14: 30 | M14: 0 | N14: 0 | O14: 0 | P14: 0 | Q14: 0 | R14: 0 | S14: 0 | T14: 0 | U14: 0 | V14: 0 | W14: 0
A15: 5 | B15: 370 | C15: 25 | D15: 0 | E15: 0 | F15: 0 | G15: 0 | H15: 0 | I15: 0 | J15: 0 | K15: 0 | L15: 0 | M15: 0 | N15: 0 | O15: 0 | P15: 0 | Q15: 0 | R15: 0 | S15: 0 | T15: 0 | U15: 0 | V15: 0 | W15: 0
A16: 6 | B16: 520 | C16: 0 | D16: 0 | E16: 0 | F16: 1 | G16: 0 | H16: 0 | I16: 0 | J16: 0 | K16: 0 | L16: 0 | M16: 0 | N16: 0 | O16: 10 | P16: 0 | Q16: 0 | R16: 0 | S16: 0 | T16: 0 | U16: 0 | V16: 0 | W16: 0
A17: 7 | B17: 690 | C17: 0 | D17: 0 | E17: 0 | F17: 0 | G17: 0 | H17: 0 | I17: 0 | J17: 0 | K17: 0 | L17: 60 | M17: 0 | N17: 0 | O17: 0 | P17: 0 | Q17: 0 | R17: 0 | S17: 0 | T17: 0 | U17: 0 | V17: 0 | W17: 0
A18: 8 | B18: 890 | C18: 0 | D18: 0 | E18: 0 | F18: 0 | G18: 0 | H18: 0 | I18: 0 | J18: 0 | K18: 0 | L18: 0 | M18: 15 | N18: 0 | O18: 0 | P18: 0 | Q18: 0 | R18: 0 | S18: 0 | T18: 0 | U18: 0 | V18: 0 | W18: 0
A19: 9 | B19: 1110 | C19: 25 | D19: 0 | E19: 0 | F19: 0 | G19: 0 | H19: 0 | I19: 0 | J19: 0 | K19: 0 | L19: 0 | M19: 0 | N19: 0 | O19: 0 | P19: 0 | Q19: 0 | R19: 0 | S19: 0 | T19: 0 | U19: 0 | V19: 0 | W19: 0
A20: 10 | B20: 1360 | C20: 0 | D20: 0 | E20: 0 | F20: 0 | G20: 0 | H20: 0 | I20: 0 | J20: 0 | K20: 0 | L20: 0 | M20: 0 | N20: 15 | O20: 0 | P20: 0 | Q20: 0 | R20: 0 | S20: 0 | T20: 0 | U20: 0 | V20: 0 | W20: 0
A21: 11 | B21: 1630 | C21: 0 | D21: 0 | E21: 0 | F21: 0 | G21: 0 | H21: 0 | I21: 1 | J21: 0 | K21: 0 | L21: 0 | M21: 0 | N21: 0 | O21: 0 | P21: 0 | Q21: 0 | R21: 0 | S21: 0 | T21: 0 | U21: 0 | V21: 0 | W21: 0
A22: 12 | B22: 1930 | C22: 0 | D22: 0 | E22: 0 | F22: 0 | G22: 0 | H22: 0 | I22: 0 | J22: 0 | K22: 0 | L22: 60 | M22: 0 | N22: 0 | O22: 15 | P22: 0 | Q22: 0 | R22: 0 | S22: 0 | T22: 0 | U22: 0 | V22: 0 | W22: 0

Sheet HH_v2
A1: Hatchling Hideaway | AH1: Player Reach Simulation (per event day) — SIMULATED
A2: Config Panel | AH2: Percentile | AI2: Avg | AT2: accuracy | AU2: 0.8
A3: EventDuration | B3: 4 | AH3: Payer | AI3: NONPAYER
A4: requiredPlayerLevel | B4: 1 | AT4: Gate | AU4: Tiles | AV4: Cum tokens req
A5: requiredSagaLevel | B5: 15 | AH5: Day_of_event | AI5: 0-9_ms | AJ5: 0-9_reward | AK5: 10-19_ms | AL5: 10-19_reward | AM5: 20-39_ms | AN5: 20-39_reward | AO5: 40-99_ms | AP5: 40-99_reward | AQ5: 100_ms | AR5: 100_reward | AT5: 1 | AU5: 16 | AV5: =SUM($AU$5:$AU5)/$AU$2
A6: NormalLevelTokenReward | B6: 1 | AH6: =IF(1<=$B$3,1,"") | AI6: =IF($AH6="","",LET(bal,SUMIFS(data_event_inst!$N:$N,data_event_inst!$A:$A,"Hatchling Hideaway",data_event_inst!$B:$B,$AI$3,data_event_inst!$C:$C,"0-9"),shr,MIN(1,IFERROR(CHOOSE(MATCH($AI$2,{"Avg","p25","p50","p75"},0),AVERAGEIFS(data_event_accrual!$I:$I,data_event_accrual!$A:$A,"Hatchling Hideaway",data_event_accrual!$B:$B,$AI$3,data_event_accrual!$C:$C,"0-9",data_event_accrual!$E:$E,$AH6),AVERAGEIFS(data_event_accrual!$K:$K,data_event_accrual!$A:$A,"Hatchling Hideaway",data_event_accrual!$B:$B,$AI$3,data_event_accrual!$C:$C,"0-9",data_event_accrual!$E:$E,$AH6),AVERAGEIFS(data_event_accrual!$J:$J,data_event_accrual!$A:$A,"Hatchling Hideaway",data_event_accrual!$B:$B,$AI$3,data_event_accrual!$C:$C,"0-9",data_event_accrual!$E:$E,$AH6),AVERAGEIFS(data_event_accrual!$L:$L,data_event_accrual!$A:$A,"Hatchling Hideaway",data_event_accrual!$B:$B,$AI$3,data_event_accrual!$C:$C,"0-9",data_event_accrual!$E:$E,$AH6)),1)),COUNTIF($AV$5:$AV$9,"<="&bal*shr))) | AJ6: =IF($AH6="","",IF(AI6=0,"{}",LET(m,AI6,s,MMULT(SEQUENCE(1,m,1,0),ARRAY_CONSTRAIN($B$12:$V$16,m,21)),"{"&TEXTJOIN(", ",TRUE,ARRAYFORMULA(IF(s>0,$B$11:$V$11&": "&ROUND(s,2),"")))&"}"))) | AK6: =IF($AH6="","",LET(bal,SUMIFS(data_event_inst!$N:$N,data_event_inst!$A:$A,"Hatchling Hideaway",data_event_inst!$B:$B,$AI$3,data_event_inst!$C:$C,"10-19"),shr,MIN(1,IFERROR(CHOOSE(MATCH($AI$2,{"Avg","p25","p50","p75"},0),AVERAGEIFS(data_event_accrual!$I:$I,data_event_accrual!$A:$A,"Hatchling Hideaway",data_event_accrual!$B:$B,$AI$3,data_event_accrual!$C:$C,"10-19",data_event_accrual!$E:$E,$AH6),AVERAGEIFS(data_event_accrual!$K:$K,data_event_accrual!$A:$A,"Hatchling Hideaway",data_event_accrual!$B:$B,$AI$3,data_event_accrual!$C:$C,"10-19",data_event_accrual!$E:$E,$AH6),AVERAGEIFS(data_event_accrual!$J:$J,data_event_accrual!$A:$A,"Hatchling Hideaway",data_event_accrual!$B:$B,$AI$3,data_event_accrual!$C:$C,"10-19",data_event_accrual!$E:$E,$AH6),AVERAGEIFS(data_event_accrual!$L:$L,data_event_accrual!$A:$A,"Hatchling Hideaway",data_event_accrual!$B:$B,$AI$3,data_event_accrual!$C:$C,"10-19",data_event_accrual!$E:$E,$AH6)),1)),COUNTIF($AV$5:$AV$9,"<="&bal*shr))) | AL6: =IF($AH6="","",IF(AK6=0,"{}",LET(m,AK6,s,MMULT(SEQUENCE(1,m,1,0),ARRAY_CONSTRAIN($B$12:$V$16,m,21)),"{"&TEXTJOIN(", ",TRUE,ARRAYFORMULA(IF(s>0,$B$11:$V$11&": "&ROUND(s,2),"")))&"}"))) | AM6: =IF($AH6="","",LET(bal,SUMIFS(data_event_inst!$N:$N,data_event_inst!$A:$A,"Hatchling Hideaway",data_event_inst!$B:$B,$AI$3,data_event_inst!$C:$C,"20-39"),shr,MIN(1,IFERROR(CHOOSE(MATCH($AI$2,{"Avg","p25","p50","p75"},0),AVERAGEIFS(data_event_accrual!$I:$I,data_event_accrual!$A:$A,"Hatchling Hideaway",data_event_accrual!$B:$B,$AI$3,data_event_accrual!$C:$C,"20-39",data_event_accrual!$E:$E,$AH6),AVERAGEIFS(data_event_accrual!$K:$K,data_event_accrual!$A:$A,"Hatchling Hideaway",data_event_accrual!$B:$B,$AI$3,data_event_accrual!$C:$C,"20-39",data_event_accrual!$E:$E,$AH6),AVERAGEIFS(data_event_accrual!$J:$J,data_event_accrual!$A:$A,"Hatchling Hideaway",data_event_accrual!$B:$B,$AI$3,data_event_accrual!$C:$C,"20-39",data_event_accrual!$E:$E,$AH6),AVERAGEIFS(data_event_accrual!$L:$L,data_event_accrual!$A:$A,"Hatchling Hideaway",data_event_accrual!$B:$B,$AI$3,data_event_accrual!$C:$C,"20-39",data_event_accrual!$E:$E,$AH6)),1)),COUNTIF($AV$5:$AV$9,"<="&bal*shr))) | AN6: =IF($AH6="","",IF(AM6=0,"{}",LET(m,AM6,s,MMULT(SEQUENCE(1,m,1,0),ARRAY_CONSTRAIN($B$12:$V$16,m,21)),"{"&TEXTJOIN(", ",TRUE,ARRAYFORMULA(IF(s>0,$B$11:$V$11&": "&ROUND(s,2),"")))&"}"))) | AO6: =IF($AH6="","",LET(bal,SUMIFS(data_event_inst!$N:$N,data_event_inst!$A:$A,"Hatchling Hideaway",data_event_inst!$B:$B,$AI$3,data_event_inst!$C:$C,"40-99"),shr,MIN(1,IFERROR(CHOOSE(MATCH($AI$2,{"Avg","p25","p50","p75"},0),AVERAGEIFS(data_event_accrual!$I:$I,data_event_accrual!$A:$A,"Hatchling Hideaway",data_event_accrual!$B:$B,$AI$3,data_event_accrual!$C:$C,"40-99",data_event_accrual!$E:$E,$AH6),AVERAGEIFS(data_event_accrual!$K:$K,data_event_accrual!$A:$A,"Hatchling Hideaway",data_event_accrual!$B:$B,$AI$3,data_event_accrual!$C:$C,"40-99",data_event_accrual!$E:$E,$AH6),AVERAGEIFS(data_event_accrual!$J:$J,data_event_accrual!$A:$A,"Hatchling Hideaway",data_event_accrual!$B:$B,$AI$3,data_event_accrual!$C:$C,"40-99",data_event_accrual!$E:$E,$AH6),AVERAGEIFS(data_event_accrual!$L:$L,data_event_accrual!$A:$A,"Hatchling Hideaway",data_event_accrual!$B:$B,$AI$3,data_event_accrual!$C:$C,"40-99",data_event_accrual!$E:$E,$AH6)),1)),COUNTIF($AV$5:$AV$9,"<="&bal*shr))) | AP6: =IF($AH6="","",IF(AO6=0,"{}",LET(m,AO6,s,MMULT(SEQUENCE(1,m,1,0),ARRAY_CONSTRAIN($B$12:$V$16,m,21)),"{"&TEXTJOIN(", ",TRUE,ARRAYFORMULA(IF(s>0,$B$11:$V$11&": "&ROUND(s,2),"")))&"}"))) | AQ6: =IF($AH6="","",LET(bal,SUMIFS(data_event_inst!$N:$N,data_event_inst!$A:$A,"Hatchling Hideaway",data_event_inst!$B:$B,$AI$3,data_event_inst!$C:$C,"100+"),shr,MIN(1,IFERROR(CHOOSE(MATCH($AI$2,{"Avg","p25","p50","p75"},0),AVERAGEIFS(data_event_accrual!$I:$I,data_event_accrual!$A:$A,"Hatchling Hideaway",data_event_accrual!$B:$B,$AI$3,data_event_accrual!$C:$C,"100+",data_event_accrual!$E:$E,$AH6),AVERAGEIFS(data_event_accrual!$K:$K,data_event_accrual!$A:$A,"Hatchling Hideaway",data_event_accrual!$B:$B,$AI$3,data_event_accrual!$C:$C,"100+",data_event_accrual!$E:$E,$AH6),AVERAGEIFS(data_event_accrual!$J:$J,data_event_accrual!$A:$A,"Hatchling Hideaway",data_event_accrual!$B:$B,$AI$3,data_event_accrual!$C:$C,"100+",data_event_accrual!$E:$E,$AH6),AVERAGEIFS(data_event_accrual!$L:$L,data_event_accrual!$A:$A,"Hatchling Hideaway",data_event_accrual!$B:$B,$AI$3,data_event_accrual!$C:$C,"100+",data_event_accrual!$E:$E,$AH6)),1)),COUNTIF($AV$5:$AV$9,"<="&bal*shr))) | AR6: =IF($AH6="","",IF(AQ6=0,"{}",LET(m,AQ6,s,MMULT(SEQUENCE(1,m,1,0),ARRAY_CONSTRAIN($B$12:$V$16,m,21)),"{"&TEXTJOIN(", ",TRUE,ARRAYFORMULA(IF(s>0,$B$11:$V$11&": "&ROUND(s,2),"")))&"}"))) | AT6: 2 | AU6: 25 | AV6: =SUM($AU$5:$AU6)/$AU$2
A7: HardLevelTokenReward | B7: 2 | AH7: =IF(2<=$B$3,2,"") | AI7: =IF($AH7="","",LET(bal,SUMIFS(data_event_inst!$N:$N,data_event_inst!$A:$A,"Hatchling Hideaway",data_event_inst!$B:$B,$AI$3,data_event_inst!$C:$C,"0-9"),shr,MIN(1,IFERROR(CHOOSE(MATCH($AI$2,{"Avg","p25","p50","p75"},0),AVERAGEIFS(data_event_accrual!$I:$I,data_event_accrual!$A:$A,"Hatchling Hideaway",data_event_accrual!$B:$B,$AI$3,data_event_accrual!$C:$C,"0-9",data_event_accrual!$E:$E,$AH7),AVERAGEIFS(data_event_accrual!$K:$K,data_event_accrual!$A:$A,"Hatchling Hideaway",data_event_accrual!$B:$B,$AI$3,data_event_accrual!$C:$C,"0-9",data_event_accrual!$E:$E,$AH7),AVERAGEIFS(data_event_accrual!$J:$J,data_event_accrual!$A:$A,"Hatchling Hideaway",data_event_accrual!$B:$B,$AI$3,data_event_accrual!$C:$C,"0-9",data_event_accrual!$E:$E,$AH7),AVERAGEIFS(data_event_accrual!$L:$L,data_event_accrual!$A:$A,"Hatchling Hideaway",data_event_accrual!$B:$B,$AI$3,data_event_accrual!$C:$C,"0-9",data_event_accrual!$E:$E,$AH7)),1)),COUNTIF($AV$5:$AV$9,"<="&bal*shr))) | AJ7: =IF($AH7="","",IF(AI7=0,"{}",LET(m,AI7,s,MMULT(SEQUENCE(1,m,1,0),ARRAY_CONSTRAIN($B$12:$V$16,m,21)),"{"&TEXTJOIN(", ",TRUE,ARRAYFORMULA(IF(s>0,$B$11:$V$11&": "&ROUND(s,2),"")))&"}"))) | AK7: =IF($AH7="","",LET(bal,SUMIFS(data_event_inst!$N:$N,data_event_inst!$A:$A,"Hatchling Hideaway",data_event_inst!$B:$B,$AI$3,data_event_inst!$C:$C,"10-19"),shr,MIN(1,IFERROR(CHOOSE(MATCH($AI$2,{"Avg","p25","p50","p75"},0),AVERAGEIFS(data_event_accrual!$I:$I,data_event_accrual!$A:$A,"Hatchling Hideaway",data_event_accrual!$B:$B,$AI$3,data_event_accrual!$C:$C,"10-19",data_event_accrual!$E:$E,$AH7),AVERAGEIFS(data_event_accrual!$K:$K,data_event_accrual!$A:$A,"Hatchling Hideaway",data_event_accrual!$B:$B,$AI$3,data_event_accrual!$C:$C,"10-19",data_event_accrual!$E:$E,$AH7),AVERAGEIFS(data_event_accrual!$J:$J,data_event_accrual!$A:$A,"Hatchling Hideaway",data_event_accrual!$B:$B,$AI$3,data_event_accrual!$C:$C,"10-19",data_event_accrual!$E:$E,$AH7),AVERAGEIFS(data_event_accrual!$L:$L,data_event_accrual!$A:$A,"Hatchling Hideaway",data_event_accrual!$B:$B,$AI$3,data_event_accrual!$C:$C,"10-19",data_event_accrual!$E:$E,$AH7)),1)),COUNTIF($AV$5:$AV$9,"<="&bal*shr))) | AL7: =IF($AH7="","",IF(AK7=0,"{}",LET(m,AK7,s,MMULT(SEQUENCE(1,m,1,0),ARRAY_CONSTRAIN($B$12:$V$16,m,21)),"{"&TEXTJOIN(", ",TRUE,ARRAYFORMULA(IF(s>0,$B$11:$V$11&": "&ROUND(s,2),"")))&"}"))) | AM7: =IF($AH7="","",LET(bal,SUMIFS(data_event_inst!$N:$N,data_event_inst!$A:$A,"Hatchling Hideaway",data_event_inst!$B:$B,$AI$3,data_event_inst!$C:$C,"20-39"),shr,MIN(1,IFERROR(CHOOSE(MATCH($AI$2,{"Avg","p25","p50","p75"},0),AVERAGEIFS(data_event_accrual!$I:$I,data_event_accrual!$A:$A,"Hatchling Hideaway",data_event_accrual!$B:$B,$AI$3,data_event_accrual!$C:$C,"20-39",data_event_accrual!$E:$E,$AH7),AVERAGEIFS(data_event_accrual!$K:$K,data_event_accrual!$A:$A,"Hatchling Hideaway",data_event_accrual!$B:$B,$AI$3,data_event_accrual!$C:$C,"20-39",data_event_accrual!$E:$E,$AH7),AVERAGEIFS(data_event_accrual!$J:$J,data_event_accrual!$A:$A,"Hatchling Hideaway",data_event_accrual!$B:$B,$AI$3,data_event_accrual!$C:$C,"20-39",data_event_accrual!$E:$E,$AH7),AVERAGEIFS(data_event_accrual!$L:$L,data_event_accrual!$A:$A,"Hatchling Hideaway",data_event_accrual!$B:$B,$AI$3,data_event_accrual!$C:$C,"20-39",data_event_accrual!$E:$E,$AH7)),1)),COUNTIF($AV$5:$AV$9,"<="&bal*shr))) | AN7: =IF($AH7="","",IF(AM7=0,"{}",LET(m,AM7,s,MMULT(SEQUENCE(1,m,1,0),ARRAY_CONSTRAIN($B$12:$V$16,m,21)),"{"&TEXTJOIN(", ",TRUE,ARRAYFORMULA(IF(s>0,$B$11:$V$11&": "&ROUND(s,2),"")))&"}"))) | AO7: =IF($AH7="","",LET(bal,SUMIFS(data_event_inst!$N:$N,data_event_inst!$A:$A,"Hatchling Hideaway",data_event_inst!$B:$B,$AI$3,data_event_inst!$C:$C,"40-99"),shr,MIN(1,IFERROR(CHOOSE(MATCH($AI$2,{"Avg","p25","p50","p75"},0),AVERAGEIFS(data_event_accrual!$I:$I,data_event_accrual!$A:$A,"Hatchling Hideaway",data_event_accrual!$B:$B,$AI$3,data_event_accrual!$C:$C,"40-99",data_event_accrual!$E:$E,$AH7),AVERAGEIFS(data_event_accrual!$K:$K,data_event_accrual!$A:$A,"Hatchling Hideaway",data_event_accrual!$B:$B,$AI$3,data_event_accrual!$C:$C,"40-99",data_event_accrual!$E:$E,$AH7),AVERAGEIFS(data_event_accrual!$J:$J,data_event_accrual!$A:$A,"Hatchling Hideaway",data_event_accrual!$B:$B,$AI$3,data_event_accrual!$C:$C,"40-99",data_event_accrual!$E:$E,$AH7),AVERAGEIFS(data_event_accrual!$L:$L,data_event_accrual!$A:$A,"Hatchling Hideaway",data_event_accrual!$B:$B,$AI$3,data_event_accrual!$C:$C,"40-99",data_event_accrual!$E:$E,$AH7)),1)),COUNTIF($AV$5:$AV$9,"<="&bal*shr))) | AP7: =IF($AH7="","",IF(AO7=0,"{}",LET(m,AO7,s,MMULT(SEQUENCE(1,m,1,0),ARRAY_CONSTRAIN($B$12:$V$16,m,21)),"{"&TEXTJOIN(", ",TRUE,ARRAYFORMULA(IF(s>0,$B$11:$V$11&": "&ROUND(s,2),"")))&"}"))) | AQ7: =IF($AH7="","",LET(bal,SUMIFS(data_event_inst!$N:$N,data_event_inst!$A:$A,"Hatchling Hideaway",data_event_inst!$B:$B,$AI$3,data_event_inst!$C:$C,"100+"),shr,MIN(1,IFERROR(CHOOSE(MATCH($AI$2,{"Avg","p25","p50","p75"},0),AVERAGEIFS(data_event_accrual!$I:$I,data_event_accrual!$A:$A,"Hatchling Hideaway",data_event_accrual!$B:$B,$AI$3,data_event_accrual!$C:$C,"100+",data_event_accrual!$E:$E,$AH7),AVERAGEIFS(data_event_accrual!$K:$K,data_event_accrual!$A:$A,"Hatchling Hideaway",data_event_accrual!$B:$B,$AI$3,data_event_accrual!$C:$C,"100+",data_event_accrual!$E:$E,$AH7),AVERAGEIFS(data_event_accrual!$J:$J,data_event_accrual!$A:$A,"Hatchling Hideaway",data_event_accrual!$B:$B,$AI$3,data_event_accrual!$C:$C,"100+",data_event_accrual!$E:$E,$AH7),AVERAGEIFS(data_event_accrual!$L:$L,data_event_accrual!$A:$A,"Hatchling Hideaway",data_event_accrual!$B:$B,$AI$3,data_event_accrual!$C:$C,"100+",data_event_accrual!$E:$E,$AH7)),1)),COUNTIF($AV$5:$AV$9,"<="&bal*shr))) | AR7: =IF($AH7="","",IF(AQ7=0,"{}",LET(m,AQ7,s,MMULT(SEQUENCE(1,m,1,0),ARRAY_CONSTRAIN($B$12:$V$16,m,21)),"{"&TEXTJOIN(", ",TRUE,ARRAYFORMULA(IF(s>0,$B$11:$V$11&": "&ROUND(s,2),"")))&"}"))) | AT7: 3 | AU7: 36 | AV7: =SUM($AU$5:$AU7)/$AU$2
