Workbook

Sheet NS Proposal
A1: Night Sky coin uplift - proposal and HC impact
A2: Sizes a Night Sky COIN increase that pulls HC gain back into the -4%..0% band and re-steepens the streak ladder. Observed values are live formulas over 'Raw Data' (copy this tab INTO LiveOps_v2_AB_Summary.xlsx - they cannot resolve standalone). Yellow cells are inputs: retype a reward and everything below re-prices. Requirements are unchanged; coins only.
A4: Block | B4: Metric | C4: 1-9 | D4: 10-19 | E4: 20-39 | F4: 40-99 | G4: 100+
B5: 'Raw Data' bucket key | C5: B. 1-9 | D5: C. 10-19 | E5: D. 20-39 | F5: E. 40-99 | G5: F. 100+
A6: NS CONFIG
B7: Cum streak req - R1 | C7: 2 | D7: 6 | E7: 11 | F7: 28 | G7: 80 | I7: unchanged by this proposal
B8: Cum streak req - R2 | C8: 5 | D8: 13 | E8: 26 | F8: 60 | G8: 175
B9: Cum streak req - R3 | C9: 10 | D9: 26 | E9: 42 | F9: 100 | G9: 280
B10: Current HC reward - R1 | C10: 0 | D10: 10 | E10: 15 | F10: 50 | G10: 100 | I10: live NS ladder; identical in NS_v2, so NS was NOT changed by the A/B
B11: Current HC reward - R2 | C11: 10 | D11: 30 | E11: 50 | F11: 120 | G11: 300
B12: Current HC reward - R3 | C12: 15 | D12: 60 | E12: 100 | F12: 250 | G12: 400
B13: PROPOSED HC reward - R1 | C13: 0 | D13: 10 | E13: 15 | F13: 60 | G13: 120
B14: PROPOSED HC reward - R2 | C14: 15 | D14: 45 | E14: 70 | F14: 160 | G14: 450
B15: PROPOSED HC reward - R3 | C15: 30 | D15: 100 | E15: 160 | F15: 300 | G15: 700
B16: Delta HC - R1 | C16: =C13-C10 | D16: =D13-D10 | E16: =E13-E10 | F16: =F13-F10 | G16: =G13-G10
B17: Delta HC - R2 | C17: =C14-C11 | D17: =D14-D11 | E17: =E14-E11 | F17: =F14-F11 | G17: =G14-G11
B18: Delta HC - R3 | C18: =C15-C12 | D18: =D15-D12 | E18: =E15-E12 | F18: =F15-F12 | G18: =G15-G12
A19: OBSERVED (variant arm)
B20: Claim rate / player-day - R1 (%) | C20: =IFERROR(SUMPRODUCT(('Raw Data'!$B$2:$B$9999="Variant")*('Raw Data'!$C$2:$C$9999=C$5)*'Raw Data'!$D$2:$D$9999*'Raw Data'!$AI$2:$AI$9999)/SUMIFS('Raw Data'!$D:$D, 'Raw Data'!$B:$B, "Variant", 'Raw Data'!$C:$C, C$5),"") | D20: =IFERROR(SUMPRODUCT(('Raw Data'!$B$2:$B$9999="Variant")*('Raw Data'!$C$2:$C$9999=D$5)*'Raw Data'!$D$2:$D$9999*'Raw Data'!$AI$2:$AI$9999)/SUMIFS('Raw Data'!$D:$D, 'Raw Data'!$B:$B, "Variant", 'Raw Data'!$C:$C, D$5),"") | E20: =IFERROR(SUMPRODUCT(('Raw Data'!$B$2:$B$9999="Variant")*('Raw Data'!$C$2:$C$9999=E$5)*'Raw Data'!$D$2:$D$9999*'Raw Data'!$AI$2:$AI$9999)/SUMIFS('Raw Data'!$D:$D, 'Raw Data'!$B:$B, "Variant", 'Raw Data'!$C:$C, E$5),"") | F20: =IFERROR(SUMPRODUCT(('Raw Data'!$B$2:$B$9999="Variant")*('Raw Data'!$C$2:$C$9999=F$5)*'Raw Data'!$D$2:$D$9999*'Raw Data'!$AI$2:$AI$9999)/SUMIFS('Raw Data'!$D:$D, 'Raw Data'!$B:$B, "Variant", 'Raw Data'!$C:$C, F$5),"") | G20: =IFERROR(SUMPRODUCT(('Raw Data'!$B$2:$B$9999="Variant")*('Raw Data'!$C$2:$C$9999=G$5)*'Raw Data'!$D$2:$D$9999*'Raw Data'!$AI$2:$AI$9999)/SUMIFS('Raw Data'!$D:$D, 'Raw Data'!$B:$B, "Variant", 'Raw Data'!$C:$C, G$5),"") | I20: pct_player_days_passed_R1/2/3 - the per-day claim probability
B21: Claim rate / player-day - R2 (%) | C21: =IFERROR(SUMPRODUCT(('Raw Data'!$B$2:$B$9999="Variant")*('Raw Data'!$C$2:$C$9999=C$5)*'Raw Data'!$D$2:$D$9999*'Raw Data'!$AJ$2:$AJ$9999)/SUMIFS('Raw Data'!$D:$D, 'Raw Data'!$B:$B, "Variant", 'Raw Data'!$C:$C, C$5),"") | D21: =IFERROR(SUMPRODUCT(('Raw Data'!$B$2:$B$9999="Variant")*('Raw Data'!$C$2:$C$9999=D$5)*'Raw Data'!$D$2:$D$9999*'Raw Data'!$AJ$2:$AJ$9999)/SUMIFS('Raw Data'!$D:$D, 'Raw Data'!$B:$B, "Variant", 'Raw Data'!$C:$C, D$5),"") | E21: =IFERROR(SUMPRODUCT(('Raw Data'!$B$2:$B$9999="Variant")*('Raw Data'!$C$2:$C$9999=E$5)*'Raw Data'!$D$2:$D$9999*'Raw Data'!$AJ$2:$AJ$9999)/SUMIFS('Raw Data'!$D:$D, 'Raw Data'!$B:$B, "Variant", 'Raw Data'!$C:$C, E$5),"") | F21: =IFERROR(SUMPRODUCT(('Raw Data'!$B$2:$B$9999="Variant")*('Raw Data'!$C$2:$C$9999=F$5)*'Raw Data'!$D$2:$D$9999*'Raw Data'!$AJ$2:$AJ$9999)/SUMIFS('Raw Data'!$D:$D, 'Raw Data'!$B:$B, "Variant", 'Raw Data'!$C:$C, F$5),"") | G21: =IFERROR(SUMPRODUCT(('Raw Data'!$B$2:$B$9999="Variant")*('Raw Data'!$C$2:$C$9999=G$5)*'Raw Data'!$D$2:$D$9999*'Raw Data'!$AJ$2:$AJ$9999)/SUMIFS('Raw Data'!$D:$D, 'Raw Data'!$B:$B, "Variant", 'Raw Data'!$C:$C, G$5),"")
B22: Claim rate / player-day - R3 (%) | C22: =IFERROR(SUMPRODUCT(('Raw Data'!$B$2:$B$9999="Variant")*('Raw Data'!$C$2:$C$9999=C$5)*'Raw Data'!$D$2:$D$9999*'Raw Data'!$AK$2:$AK$9999)/SUMIFS('Raw Data'!$D:$D, 'Raw Data'!$B:$B, "Variant", 'Raw Data'!$C:$C, C$5),"") | D22: =IFERROR(SUMPRODUCT(('Raw Data'!$B$2:$B$9999="Variant")*('Raw Data'!$C$2:$C$9999=D$5)*'Raw Data'!$D$2:$D$9999*'Raw Data'!$AK$2:$AK$9999)/SUMIFS('Raw Data'!$D:$D, 'Raw Data'!$B:$B, "Variant", 'Raw Data'!$C:$C, D$5),"") | E22: =IFERROR(SUMPRODUCT(('Raw Data'!$B$2:$B$9999="Variant")*('Raw Data'!$C$2:$C$9999=E$5)*'Raw Data'!$D$2:$D$9999*'Raw Data'!$AK$2:$AK$9999)/SUMIFS('Raw Data'!$D:$D, 'Raw Data'!$B:$B, "Variant", 'Raw Data'!$C:$C, E$5),"") | F22: =IFERROR(SUMPRODUCT(('Raw Data'!$B$2:$B$9999="Variant")*('Raw Data'!$C$2:$C$9999=F$5)*'Raw Data'!$D$2:$D$9999*'Raw Data'!$AK$2:$AK$9999)/SUMIFS('Raw Data'!$D:$D, 'Raw Data'!$B:$B, "Variant", 'Raw Data'!$C:$C, F$5),"") | G22: =IFERROR(SUMPRODUCT(('Raw Data'!$B$2:$B$9999="Variant")*('Raw Data'!$C$2:$C$9999=G$5)*'Raw Data'!$D$2:$D$9999*'Raw Data'!$AK$2:$AK$9999)/SUMIFS('Raw Data'!$D:$D, 'Raw Data'!$B:$B, "Variant", 'Raw Data'!$C:$C, G$5),"")
B23: Daily streak p50 | C23: =IFERROR(SUMPRODUCT(('Raw Data'!$B$2:$B$9999="Variant")*('Raw Data'!$C$2:$C$9999=C$5)*'Raw Data'!$D$2:$D$9999*'Raw Data'!$AF$2:$AF$9999)/SUMIFS('Raw Data'!$D:$D, 'Raw Data'!$B:$B, "Variant", 'Raw Data'!$C:$C, C$5),"") | D23: =IFERROR(SUMPRODUCT(('Raw Data'!$B$2:$B$9999="Variant")*('Raw Data'!$C$2:$C$9999=D$5)*'Raw Data'!$D$2:$D$9999*'Raw Data'!$AF$2:$AF$9999)/SUMIFS('Raw Data'!$D:$D, 'Raw Data'!$B:$B, "Variant", 'Raw Data'!$C:$C, D$5),"") | E23: =IFERROR(SUMPRODUCT(('Raw Data'!$B$2:$B$9999="Variant")*('Raw Data'!$C$2:$C$9999=E$5)*'Raw Data'!$D$2:$D$9999*'Raw Data'!$AF$2:$AF$9999)/SUMIFS('Raw Data'!$D:$D, 'Raw Data'!$B:$B, "Variant", 'Raw Data'!$C:$C, E$5),"") | F23: =IFERROR(SUMPRODUCT(('Raw Data'!$B$2:$B$9999="Variant")*('Raw Data'!$C$2:$C$9999=F$5)*'Raw Data'!$D$2:$D$9999*'Raw Data'!$AF$2:$AF$9999)/SUMIFS('Raw Data'!$D:$D, 'Raw Data'!$B:$B, "Variant", 'Raw Data'!$C:$C, F$5),"") | G23: =IFERROR(SUMPRODUCT(('Raw Data'!$B$2:$B$9999="Variant")*('Raw Data'!$C$2:$C$9999=G$5)*'Raw Data'!$D$2:$D$9999*'Raw Data'!$AF$2:$AF$9999)/SUMIFS('Raw Data'!$D:$D, 'Raw Data'!$B:$B, "Variant", 'Raw Data'!$C:$C, G$5),"")
B24: Daily streak p75 | C24: =IFERROR(SUMPRODUCT(('Raw Data'!$B$2:$B$9999="Variant")*('Raw Data'!$C$2:$C$9999=C$5)*'Raw Data'!$D$2:$D$9999*'Raw Data'!$AG$2:$AG$9999)/SUMIFS('Raw Data'!$D:$D, 'Raw Data'!$B:$B, "Variant", 'Raw Data'!$C:$C, C$5),"") | D24: =IFERROR(SUMPRODUCT(('Raw Data'!$B$2:$B$9999="Variant")*('Raw Data'!$C$2:$C$9999=D$5)*'Raw Data'!$D$2:$D$9999*'Raw Data'!$AG$2:$AG$9999)/SUMIFS('Raw Data'!$D:$D, 'Raw Data'!$B:$B, "Variant", 'Raw Data'!$C:$C, D$5),"") | E24: =IFERROR(SUMPRODUCT(('Raw Data'!$B$2:$B$9999="Variant")*('Raw Data'!$C$2:$C$9999=E$5)*'Raw Data'!$D$2:$D$9999*'Raw Data'!$AG$2:$AG$9999)/SUMIFS('Raw Data'!$D:$D, 'Raw Data'!$B:$B, "Variant", 'Raw Data'!$C:$C, E$5),"") | F24: =IFERROR(SUMPRODUCT(('Raw Data'!$B$2:$B$9999="Variant")*('Raw Data'!$C$2:$C$9999=F$5)*'Raw Data'!$D$2:$D$9999*'Raw Data'!$AG$2:$AG$9999)/SUMIFS('Raw Data'!$D:$D, 'Raw Data'!$B:$B, "Variant", 'Raw Data'!$C:$C, F$5),"") | G24: =IFERROR(SUMPRODUCT(('Raw Data'!$B$2:$B$9999="Variant")*('Raw Data'!$C$2:$C$9999=G$5)*'Raw Data'!$D$2:$D$9999*'Raw Data'!$AG$2:$AG$9999)/SUMIFS('Raw Data'!$D:$D, 'Raw Data'!$B:$B, "Variant", 'Raw Data'!$C:$C, G$5),"")
B25: Daily streak p90 | C25: =IFERROR(SUMPRODUCT(('Raw Data'!$B$2:$B$9999="Variant")*('Raw Data'!$C$2:$C$9999=C$5)*'Raw Data'!$D$2:$D$9999*'Raw Data'!$AH$2:$AH$9999)/SUMIFS('Raw Data'!$D:$D, 'Raw Data'!$B:$B, "Variant", 'Raw Data'!$C:$C, C$5),"") | D25: =IFERROR(SUMPRODUCT(('Raw Data'!$B$2:$B$9999="Variant")*('Raw Data'!$C$2:$C$9999=D$5)*'Raw Data'!$D$2:$D$9999*'Raw Data'!$AH$2:$AH$9999)/SUMIFS('Raw Data'!$D:$D, 'Raw Data'!$B:$B, "Variant", 'Raw Data'!$C:$C, D$5),"") | E25: =IFERROR(SUMPRODUCT(('Raw Data'!$B$2:$B$9999="Variant")*('Raw Data'!$C$2:$C$9999=E$5)*'Raw Data'!$D$2:$D$9999*'Raw Data'!$AH$2:$AH$9999)/SUMIFS('Raw Data'!$D:$D, 'Raw Data'!$B:$B, "Variant", 'Raw Data'!$C:$C, E$5),"") | F25: =IFERROR(SUMPRODUCT(('Raw Data'!$B$2:$B$9999="Variant")*('Raw Data'!$C$2:$C$9999=F$5)*'Raw Data'!$D$2:$D$9999*'Raw Data'!$AH$2:$AH$9999)/SUMIFS('Raw Data'!$D:$D, 'Raw Data'!$B:$B, "Variant", 'Raw Data'!$C:$C, F$5),"") | G25: =IFERROR(SUMPRODUCT(('Raw Data'!$B$2:$B$9999="Variant")*('Raw Data'!$C$2:$C$9999=G$5)*'Raw Data'!$D$2:$D$9999*'Raw Data'!$AH$2:$AH$9999)/SUMIFS('Raw Data'!$D:$D, 'Raw Data'!$B:$B, "Variant", 'Raw Data'!$C:$C, G$5),"")
B26: NS active rate (%) | C26: =IFERROR(SUMPRODUCT(('Raw Data'!$B$2:$B$9999="Variant")*('Raw Data'!$C$2:$C$9999=C$5)*'Raw Data'!$D$2:$D$9999*'Raw Data'!$AM$2:$AM$9999)/SUMIFS('Raw Data'!$D:$D, 'Raw Data'!$B:$B, "Variant", 'Raw Data'!$C:$C, C$5),"") | D26: =IFERROR(SUMPRODUCT(('Raw Data'!$B$2:$B$9999="Variant")*('Raw Data'!$C$2:$C$9999=D$5)*'Raw Data'!$D$2:$D$9999*'Raw Data'!$AM$2:$AM$9999)/SUMIFS('Raw Data'!$D:$D, 'Raw Data'!$B:$B, "Variant", 'Raw Data'!$C:$C, D$5),"") | E26: =IFERROR(SUMPRODUCT(('Raw Data'!$B$2:$B$9999="Variant")*('Raw Data'!$C$2:$C$9999=E$5)*'Raw Data'!$D$2:$D$9999*'Raw Data'!$AM$2:$AM$9999)/SUMIFS('Raw Data'!$D:$D, 'Raw Data'!$B:$B, "Variant", 'Raw Data'!$C:$C, E$5),"") | F26: =IFERROR(SUMPRODUCT(('Raw Data'!$B$2:$B$9999="Variant")*('Raw Data'!$C$2:$C$9999=F$5)*'Raw Data'!$D$2:$D$9999*'Raw Data'!$AM$2:$AM$9999)/SUMIFS('Raw Data'!$D:$D, 'Raw Data'!$B:$B, "Variant", 'Raw Data'!$C:$C, F$5),"") | G26: =IFERROR(SUMPRODUCT(('Raw Data'!$B$2:$B$9999="Variant")*('Raw Data'!$C$2:$C$9999=G$5)*'Raw Data'!$D$2:$D$9999*'Raw Data'!$AM$2:$AM$9999)/SUMIFS('Raw Data'!$D:$D, 'Raw Data'!$B:$B, "Variant", 'Raw Data'!$C:$C, G$5),"")
B27: R1 finished (%) [actual] | C27: =IFERROR(SUMPRODUCT(('Raw Data'!$B$2:$B$9999="Variant")*('Raw Data'!$C$2:$C$9999=C$5)*'Raw Data'!$D$2:$D$9999*'Raw Data'!$AN$2:$AN$9999)/SUMIFS('Raw Data'!$D:$D, 'Raw Data'!$B:$B, "Variant", 'Raw Data'!$C:$C, C$5),"") | D27: =IFERROR(SUMPRODUCT(('Raw Data'!$B$2:$B$9999="Variant")*('Raw Data'!$C$2:$C$9999=D$5)*'Raw Data'!$D$2:$D$9999*'Raw Data'!$AN$2:$AN$9999)/SUMIFS('Raw Data'!$D:$D, 'Raw Data'!$B:$B, "Variant", 'Raw Data'!$C:$C, D$5),"") | E27: =IFERROR(SUMPRODUCT(('Raw Data'!$B$2:$B$9999="Variant")*('Raw Data'!$C$2:$C$9999=E$5)*'Raw Data'!$D$2:$D$9999*'Raw Data'!$AN$2:$AN$9999)/SUMIFS('Raw Data'!$D:$D, 'Raw Data'!$B:$B, "Variant", 'Raw Data'!$C:$C, E$5),"") | F27: =IFERROR(SUMPRODUCT(('Raw Data'!$B$2:$B$9999="Variant")*('Raw Data'!$C$2:$C$9999=F$5)*'Raw Data'!$D$2:$D$9999*'Raw Data'!$AN$2:$AN$9999)/SUMIFS('Raw Data'!$D:$D, 'Raw Data'!$B:$B, "Variant", 'Raw Data'!$C:$C, F$5),"") | G27: =IFERROR(SUMPRODUCT(('Raw Data'!$B$2:$B$9999="Variant")*('Raw Data'!$C$2:$C$9999=G$5)*'Raw Data'!$D$2:$D$9999*'Raw Data'!$AN$2:$AN$9999)/SUMIFS('Raw Data'!$D:$D, 'Raw Data'!$B:$B, "Variant", 'Raw Data'!$C:$C, G$5),"")
B28: R2 finished (%) [actual] | C28: =IFERROR(SUMPRODUCT(('Raw Data'!$B$2:$B$9999="Variant")*('Raw Data'!$C$2:$C$9999=C$5)*'Raw Data'!$D$2:$D$9999*'Raw Data'!$AO$2:$AO$9999)/SUMIFS('Raw Data'!$D:$D, 'Raw Data'!$B:$B, "Variant", 'Raw Data'!$C:$C, C$5),"") | D28: =IFERROR(SUMPRODUCT(('Raw Data'!$B$2:$B$9999="Variant")*('Raw Data'!$C$2:$C$9999=D$5)*'Raw Data'!$D$2:$D$9999*'Raw Data'!$AO$2:$AO$9999)/SUMIFS('Raw Data'!$D:$D, 'Raw Data'!$B:$B, "Variant", 'Raw Data'!$C:$C, D$5),"") | E28: =IFERROR(SUMPRODUCT(('Raw Data'!$B$2:$B$9999="Variant")*('Raw Data'!$C$2:$C$9999=E$5)*'Raw Data'!$D$2:$D$9999*'Raw Data'!$AO$2:$AO$9999)/SUMIFS('Raw Data'!$D:$D, 'Raw Data'!$B:$B, "Variant", 'Raw Data'!$C:$C, E$5),"") | F28: =IFERROR(SUMPRODUCT(('Raw Data'!$B$2:$B$9999="Variant")*('Raw Data'!$C$2:$C$9999=F$5)*'Raw Data'!$D$2:$D$9999*'Raw Data'!$AO$2:$AO$9999)/SUMIFS('Raw Data'!$D:$D, 'Raw Data'!$B:$B, "Variant", 'Raw Data'!$C:$C, F$5),"") | G28: =IFERROR(SUMPRODUCT(('Raw Data'!$B$2:$B$9999="Variant")*('Raw Data'!$C$2:$C$9999=G$5)*'Raw Data'!$D$2:$D$9999*'Raw Data'!$AO$2:$AO$9999)/SUMIFS('Raw Data'!$D:$D, 'Raw Data'!$B:$B, "Variant", 'Raw Data'!$C:$C, G$5),"")
B29: R3 finished (%) [actual] | C29: =IFERROR(SUMPRODUCT(('Raw Data'!$B$2:$B$9999="Variant")*('Raw Data'!$C$2:$C$9999=C$5)*'Raw Data'!$D$2:$D$9999*'Raw Data'!$AP$2:$AP$9999)/SUMIFS('Raw Data'!$D:$D, 'Raw Data'!$B:$B, "Variant", 'Raw Data'!$C:$C, C$5),"") | D29: =IFERROR(SUMPRODUCT(('Raw Data'!$B$2:$B$9999="Variant")*('Raw Data'!$C$2:$C$9999=D$5)*'Raw Data'!$D$2:$D$9999*'Raw Data'!$AP$2:$AP$9999)/SUMIFS('Raw Data'!$D:$D, 'Raw Data'!$B:$B, "Variant", 'Raw Data'!$C:$C, D$5),"") | E29: =IFERROR(SUMPRODUCT(('Raw Data'!$B$2:$B$9999="Variant")*('Raw Data'!$C$2:$C$9999=E$5)*'Raw Data'!$D$2:$D$9999*'Raw Data'!$AP$2:$AP$9999)/SUMIFS('Raw Data'!$D:$D, 'Raw Data'!$B:$B, "Variant", 'Raw Data'!$C:$C, E$5),"") | F29: =IFERROR(SUMPRODUCT(('Raw Data'!$B$2:$B$9999="Variant")*('Raw Data'!$C$2:$C$9999=F$5)*'Raw Data'!$D$2:$D$9999*'Raw Data'!$AP$2:$AP$9999)/SUMIFS('Raw Data'!$D:$D, 'Raw Data'!$B:$B, "Variant", 'Raw Data'!$C:$C, F$5),"") | G29: =IFERROR(SUMPRODUCT(('Raw Data'!$B$2:$B$9999="Variant")*('Raw Data'!$C$2:$C$9999=G$5)*'Raw Data'!$D$2:$D$9999*'Raw Data'!$AP$2:$AP$9999)/SUMIFS('Raw Data'!$D:$D, 'Raw Data'!$B:$B, "Variant", 'Raw Data'!$C:$C, G$5),"")
A30: WHERE EACH ROUND SITS
B31: R1 req vs streak distribution | C31: =IF(C7<C23,"below p50 - no streak pull",IF(C7<C24,"p50-p75 - reachable stretch",IF(C7<C25,"p75-p90 - stretch",">p90 - aspiration"))) | D31: =IF(D7<D23,"below p50 - no streak pull",IF(D7<D24,"p50-p75 - reachable stretch",IF(D7<D25,"p75-p90 - stretch",">p90 - aspiration"))) | E31: =IF(E7<E23,"below p50 - no streak pull",IF(E7<E24,"p50-p75 - reachable stretch",IF(E7<E25,"p75-p90 - stretch",">p90 - aspiration"))) | F31: =IF(F7<F23,"below p50 - no streak pull",IF(F7<F24,"p50-p75 - reachable stretch",IF(F7<F25,"p75-p90 - stretch",">p90 - aspiration"))) | G31: =IF(G7<G23,"below p50 - no streak pull",IF(G7<G24,"p50-p75 - reachable stretch",IF(G7<G25,"p75-p90 - stretch",">p90 - aspiration"))) | I31: raising a below-p50 rung is pure HC inflation
B32: R2 req vs streak distribution | C32: =IF(C8<C23,"below p50 - no streak pull",IF(C8<C24,"p50-p75 - reachable stretch",IF(C8<C25,"p75-p90 - stretch",">p90 - aspiration"))) | D32: =IF(D8<D23,"below p50 - no streak pull",IF(D8<D24,"p50-p75 - reachable stretch",IF(D8<D25,"p75-p90 - stretch",">p90 - aspiration"))) | E32: =IF(E8<E23,"below p50 - no streak pull",IF(E8<E24,"p50-p75 - reachable stretch",IF(E8<E25,"p75-p90 - stretch",">p90 - aspiration"))) | F32: =IF(F8<F23,"below p50 - no streak pull",IF(F8<F24,"p50-p75 - reachable stretch",IF(F8<F25,"p75-p90 - stretch",">p90 - aspiration"))) | G32: =IF(G8<G23,"below p50 - no streak pull",IF(G8<G24,"p50-p75 - reachable stretch",IF(G8<G25,"p75-p90 - stretch",">p90 - aspiration")))
B33: R3 req vs streak distribution | C33: =IF(C9<C23,"below p50 - no streak pull",IF(C9<C24,"p50-p75 - reachable stretch",IF(C9<C25,"p75-p90 - stretch",">p90 - aspiration"))) | D33: =IF(D9<D23,"below p50 - no streak pull",IF(D9<D24,"p50-p75 - reachable stretch",IF(D9<D25,"p75-p90 - stretch",">p90 - aspiration"))) | E33: =IF(E9<E23,"below p50 - no streak pull",IF(E9<E24,"p50-p75 - reachable stretch",IF(E9<E25,"p75-p90 - stretch",">p90 - aspiration"))) | F33: =IF(F9<F23,"below p50 - no streak pull",IF(F9<F24,"p50-p75 - reachable stretch",IF(F9<F25,"p75-p90 - stretch",">p90 - aspiration"))) | G33: =IF(G9<G23,"below p50 - no streak pull",IF(G9<G24,"p50-p75 - reachable stretch",IF(G9<G25,"p75-p90 - stretch",">p90 - aspiration")))
A34: NS HC PER PLAYER-DAY
B35: NS HC now (sum of claim rate x reward) | C35: =SUMPRODUCT(C20:C22/100,C10:C12) | D35: =SUMPRODUCT(D20:D22/100,D10:D12) | E35: =SUMPRODUCT(E20:E22/100,E10:E12) | F35: =SUMPRODUCT(F20:F22/100,F10:F12) | G35: =SUMPRODUCT(G20:G22/100,G10:G12)
B36: NS HC with proposal | C36: =SUMPRODUCT(C20:C22/100,C13:C15) | D36: =SUMPRODUCT(D20:D22/100,D13:D15) | E36: =SUMPRODUCT(E20:E22/100,E13:E15) | F36: =SUMPRODUCT(F20:F22/100,F13:F15) | G36: =SUMPRODUCT(G20:G22/100,G13:G15)
B37: Delta NS HC / player-day | C37: =C36-C35 | D37: =D36-D35 | E37: =E36-E35 | F37: =F36-F35 | G37: =G36-G35
B38: NS uplift % | C38: =IFERROR(C36/C35-1,"") | D38: =IFERROR(D36/D35-1,"") | E38: =IFERROR(E36/E35-1,"") | F38: =IFERROR(F36/F35-1,"") | G38: =IFERROR(G36/G35-1,"")
A39: TOTAL HC GAIN / PLAYER
B40: Control | C40: =IFERROR(SUMPRODUCT(('Raw Data'!$B$2:$B$9999="Control")*('Raw Data'!$C$2:$C$9999=C$5)*'Raw Data'!$D$2:$D$9999*'Raw Data'!$Q$2:$Q$9999)/SUMIFS('Raw Data'!$D:$D, 'Raw Data'!$B:$B, "Control", 'Raw Data'!$C:$C, C$5),"") | D40: =IFERROR(SUMPRODUCT(('Raw Data'!$B$2:$B$9999="Control")*('Raw Data'!$C$2:$C$9999=D$5)*'Raw Data'!$D$2:$D$9999*'Raw Data'!$Q$2:$Q$9999)/SUMIFS('Raw Data'!$D:$D, 'Raw Data'!$B:$B, "Control", 'Raw Data'!$C:$C, D$5),"") | E40: =IFERROR(SUMPRODUCT(('Raw Data'!$B$2:$B$9999="Control")*('Raw Data'!$C$2:$C$9999=E$5)*'Raw Data'!$D$2:$D$9999*'Raw Data'!$Q$2:$Q$9999)/SUMIFS('Raw Data'!$D:$D, 'Raw Data'!$B:$B, "Control", 'Raw Data'!$C:$C, E$5),"") | F40: =IFERROR(SUMPRODUCT(('Raw Data'!$B$2:$B$9999="Control")*('Raw Data'!$C$2:$C$9999=F$5)*'Raw Data'!$D$2:$D$9999*'Raw Data'!$Q$2:$Q$9999)/SUMIFS('Raw Data'!$D:$D, 'Raw Data'!$B:$B, "Control", 'Raw Data'!$C:$C, F$5),"") | G40: =IFERROR(SUMPRODUCT(('Raw Data'!$B$2:$B$9999="Control")*('Raw Data'!$C$2:$C$9999=G$5)*'Raw Data'!$D$2:$D$9999*'Raw Data'!$Q$2:$Q$9999)/SUMIFS('Raw Data'!$D:$D, 'Raw Data'!$B:$B, "Control", 'Raw Data'!$C:$C, G$5),"")
B41: Variant (as tested) | C41: =IFERROR(SUMPRODUCT(('Raw Data'!$B$2:$B$9999="Variant")*('Raw Data'!$C$2:$C$9999=C$5)*'Raw Data'!$D$2:$D$9999*'Raw Data'!$Q$2:$Q$9999)/SUMIFS('Raw Data'!$D:$D, 'Raw Data'!$B:$B, "Variant", 'Raw Data'!$C:$C, C$5),"") | D41: =IFERROR(SUMPRODUCT(('Raw Data'!$B$2:$B$9999="Variant")*('Raw Data'!$C$2:$C$9999=D$5)*'Raw Data'!$D$2:$D$9999*'Raw Data'!$Q$2:$Q$9999)/SUMIFS('Raw Data'!$D:$D, 'Raw Data'!$B:$B, "Variant", 'Raw Data'!$C:$C, D$5),"") | E41: =IFERROR(SUMPRODUCT(('Raw Data'!$B$2:$B$9999="Variant")*('Raw Data'!$C$2:$C$9999=E$5)*'Raw Data'!$D$2:$D$9999*'Raw Data'!$Q$2:$Q$9999)/SUMIFS('Raw Data'!$D:$D, 'Raw Data'!$B:$B, "Variant", 'Raw Data'!$C:$C, E$5),"") | F41: =IFERROR(SUMPRODUCT(('Raw Data'!$B$2:$B$9999="Variant")*('Raw Data'!$C$2:$C$9999=F$5)*'Raw Data'!$D$2:$D$9999*'Raw Data'!$Q$2:$Q$9999)/SUMIFS('Raw Data'!$D:$D, 'Raw Data'!$B:$B, "Variant", 'Raw Data'!$C:$C, F$5),"") | G41: =IFERROR(SUMPRODUCT(('Raw Data'!$B$2:$B$9999="Variant")*('Raw Data'!$C$2:$C$9999=G$5)*'Raw Data'!$D$2:$D$9999*'Raw Data'!$Q$2:$Q$9999)/SUMIFS('Raw Data'!$D:$D, 'Raw Data'!$B:$B, "Variant", 'Raw Data'!$C:$C, G$5),"")
...
