Workbook

Sheet Ph_v2
A1: Photoshoot | AH1: Player Reach Simulation (per event day) - SIMULATED - GREEDY (reward-item-first)
A2: Config Panel | AH2: Percentile | AI2: Avg
A3: EventDuration (days) | B3: 3 | AH3: Payer | AI3: NONPAYER
A4: requiredPlayerLevel | B4: 1 | AU4: Cum item price | AW4: Set # | AX4: Greedy cum. cost
A5: requiredSagaLevel | B5: 17 | AH5: Day_of_event | AI5: 0-9_ms | AJ5: 0-9_reward | AK5: 10-19_ms | AL5: 10-19_reward | AM5: 20-39_ms | AN5: 20-39_reward | AO5: 40-99_ms | AP5: 40-99_reward | AQ5: 100_ms | AR5: 100_reward | AT5: 1 | AU5: =SUM($F$25:$F25) | AW5: 1 | AX5: 155
A6: lastTierUnlockRequirement | B6: =TRUE() | AH6: =IF(1<=$B$3,1,"") | AI6: {=IF($AH6="","",LET(bal,SUMIFS(data_event_inst!$N:$N,data_event_inst!$A:$A,"Photoshoot",data_event_inst!$B:$B,$AI$3,data_event_inst!$C:$C,"0-9"),shr,MIN(1,IFERROR(CHOOSE(MATCH($AI$2,{"Avg","p25","p50","p75"},0),AVERAGEIFS(data_event_accrual!$I:$I,data_event_accrual!$A:$A,"Photoshoot",data_event_accrual!$B:$B,$AI$3,data_event_accrual!$C:$C,"0-9",data_event_accrual!$E:$E,$AH6),AVERAGEIFS(data_event_accrual!$K:$K,data_event_accrual!$A:$A,"Photoshoot",data_event_accrual!$B:$B,$AI$3,data_event_accrual!$C:$C,"0-9",data_event_accrual!$E:$E,$AH6),AVERAGEIFS(data_event_accrual!$J:$J,data_event_accrual!$A:$A,"Photoshoot",data_event_accrual!$B:$B,$AI$3,data_event_accrual!$C:$C,"0-9",data_event_accrual!$E:$E,$AH6),AVERAGEIFS(data_event_accrual!$L:$L,data_event_accrual!$A:$A,"Photoshoot",data_event_accrual!$B:$B,$AI$3,data_event_accrual!$C:$C,"0-9",data_event_accrual!$E:$E,$AH6)),1)),COUNTIF($AX$5:$AX$14,"<="&bal*shr)))} | AJ6: {=IF($AH6="","",IF(AI6=0,"{}",LET(m,AI6,s,MMULT(TRANSPOSE((SEQUENCE(10,1,1,1)<=m)*1),VSTACK($H$27:$AB$27,$H$30:$AB$30,$H$33:$AB$33,$H$36:$AB$36,$H$39:$AB$39,$H$42:$AB$42,$H$45:$AB$45,$H$48:$AB$48,$H$51:$AB$51,$H$54:$AB$54)),"{"&TEXTJOIN(", ",TRUE,IF(s>0,$H$24:$AB$24&": "&ROUND(s,2),""))&"}")))} | AK6: {=IF($AH6="","",LET(bal,SUMIFS(data_event_inst!$N:$N,data_event_inst!$A:$A,"Photoshoot",data_event_inst!$B:$B,$AI$3,data_event_inst!$C:$C,"10-19"),shr,MIN(1,IFERROR(CHOOSE(MATCH($AI$2,{"Avg","p25","p50","p75"},0),AVERAGEIFS(data_event_accrual!$I:$I,data_event_accrual!$A:$A,"Photoshoot",data_event_accrual!$B:$B,$AI$3,data_event_accrual!$C:$C,"10-19",data_event_accrual!$E:$E,$AH6),AVERAGEIFS(data_event_accrual!$K:$K,data_event_accrual!$A:$A,"Photoshoot",data_event_accrual!$B:$B,$AI$3,data_event_accrual!$C:$C,"10-19",data_event_accrual!$E:$E,$AH6),AVERAGEIFS(data_event_accrual!$J:$J,data_event_accrual!$A:$A,"Photoshoot",data_event_accrual!$B:$B,$AI$3,data_event_accrual!$C:$C,"10-19",data_event_accrual!$E:$E,$AH6),AVERAGEIFS(data_event_accrual!$L:$L,data_event_accrual!$A:$A,"Photoshoot",data_event_accrual!$B:$B,$AI$3,data_event_accrual!$C:$C,"10-19",data_event_accrual!$E:$E,$AH6)),1)),COUNTIF($AX$5:$AX$14,"<="&bal*shr)))} | AL6: {=IF($AH6="","",IF(AK6=0,"{}",LET(m,AK6,s,MMULT(TRANSPOSE((SEQUENCE(10,1,1,1)<=m)*1),VSTACK($H$27:$AB$27,$H$30:$AB$30,$H$33:$AB$33,$H$36:$AB$36,$H$39:$AB$39,$H$42:$AB$42,$H$45:$AB$45,$H$48:$AB$48,$H$51:$AB$51,$H$54:$AB$54)),"{"&TEXTJOIN(", ",TRUE,IF(s>0,$H$24:$AB$24&": "&ROUND(s,2),""))&"}")))} | AM6: {=IF($AH6="","",LET(bal,SUMIFS(data_event_inst!$N:$N,data_event_inst!$A:$A,"Photoshoot",data_event_inst!$B:$B,$AI$3,data_event_inst!$C:$C,"20-39"),shr,MIN(1,IFERROR(CHOOSE(MATCH($AI$2,{"Avg","p25","p50","p75"},0),AVERAGEIFS(data_event_accrual!$I:$I,data_event_accrual!$A:$A,"Photoshoot",data_event_accrual!$B:$B,$AI$3,data_event_accrual!$C:$C,"20-39",data_event_accrual!$E:$E,$AH6),AVERAGEIFS(data_event_accrual!$K:$K,data_event_accrual!$A:$A,"Photoshoot",data_event_accrual!$B:$B,$AI$3,data_event_accrual!$C:$C,"20-39",data_event_accrual!$E:$E,$AH6),AVERAGEIFS(data_event_accrual!$J:$J,data_event_accrual!$A:$A,"Photoshoot",data_event_accrual!$B:$B,$AI$3,data_event_accrual!$C:$C,"20-39",data_event_accrual!$E:$E,$AH6),AVERAGEIFS(data_event_accrual!$L:$L,data_event_accrual!$A:$A,"Photoshoot",data_event_accrual!$B:$B,$AI$3,data_event_accrual!$C:$C,"20-39",data_event_accrual!$E:$E,$AH6)),1)),COUNTIF($AX$5:$AX$14,"<="&bal*shr)))} | AN6: {=IF($AH6="","",IF(AM6=0,"{}",LET(m,AM6,s,MMULT(TRANSPOSE((SEQUENCE(10,1,1,1)<=m)*1),VSTACK($H$27:$AB$27,$H$30:$AB$30,$H$33:$AB$33,$H$36:$AB$36,$H$39:$AB$39,$H$42:$AB$42,$H$45:$AB$45,$H$48:$AB$48,$H$51:$AB$51,$H$54:$AB$54)),"{"&TEXTJOIN(", ",TRUE,IF(s>0,$H$24:$AB$24&": "&ROUND(s,2),""))&"}")))} | AO6: {=IF($AH6="","",LET(bal,SUMIFS(data_event_inst!$N:$N,data_event_inst!$A:$A,"Photoshoot",data_event_inst!$B:$B,$AI$3,data_event_inst!$C:$C,"40-99"),shr,MIN(1,IFERROR(CHOOSE(MATCH($AI$2,{"Avg","p25","p50","p75"},0),AVERAGEIFS(data_event_accrual!$I:$I,data_event_accrual!$A:$A,"Photoshoot",data_event_accrual!$B:$B,$AI$3,data_event_accrual!$C:$C,"40-99",data_event_accrual!$E:$E,$AH6),AVERAGEIFS(data_event_accrual!$K:$K,data_event_accrual!$A:$A,"Photoshoot",data_event_accrual!$B:$B,$AI$3,data_event_accrual!$C:$C,"40-99",data_event_accrual!$E:$E,$AH6),AVERAGEIFS(data_event_accrual!$J:$J,data_event_accrual!$A:$A,"Photoshoot",data_event_accrual!$B:$B,$AI$3,data_event_accrual!$C:$C,"40-99",data_event_accrual!$E:$E,$AH6),AVERAGEIFS(data_event_accrual!$L:$L,data_event_accrual!$A:$A,"Photoshoot",data_event_accrual!$B:$B,$AI$3,data_event_accrual!$C:$C,"40-99",data_event_accrual!$E:$E,$AH6)),1)),COUNTIF($AX$5:$AX$14,"<="&bal*shr)))} | AP6: {=IF($AH6="","",IF(AO6=0,"{}",LET(m,AO6,s,MMULT(TRANSPOSE((SEQUENCE(10,1,1,1)<=m)*1),VSTACK($H$27:$AB$27,$H$30:$AB$30,$H$33:$AB$33,$H$36:$AB$36,$H$39:$AB$39,$H$42:$AB$42,$H$45:$AB$45,$H$48:$AB$48,$H$51:$AB$51,$H$54:$AB$54)),"{"&TEXTJOIN(", ",TRUE,IF(s>0,$H$24:$AB$24&": "&ROUND(s,2),""))&"}")))} | AQ6: {=IF($AH6="","",LET(bal,SUMIFS(data_event_inst!$N:$N,data_event_inst!$A:$A,"Photoshoot",data_event_inst!$B:$B,$AI$3,data_event_inst!$C:$C,"100+"),shr,MIN(1,IFERROR(CHOOSE(MATCH($AI$2,{"Avg","p25","p50","p75"},0),AVERAGEIFS(data_event_accrual!$I:$I,data_event_accrual!$A:$A,"Photoshoot",data_event_accrual!$B:$B,$AI$3,data_event_accrual!$C:$C,"100+",data_event_accrual!$E:$E,$AH6),AVERAGEIFS(data_event_accrual!$K:$K,data_event_accrual!$A:$A,"Photoshoot",data_event_accrual!$B:$B,$AI$3,data_event_accrual!$C:$C,"100+",data_event_accrual!$E:$E,$AH6),AVERAGEIFS(data_event_accrual!$J:$J,data_event_accrual!$A:$A,"Photoshoot",data_event_accrual!$B:$B,$AI$3,data_event_accrual!$C:$C,"100+",data_event_accrual!$E:$E,$AH6),AVERAGEIFS(data_event_accrual!$L:$L,data_event_accrual!$A:$A,"Photoshoot",data_event_accrual!$B:$B,$AI$3,data_event_accrual!$C:$C,"100+",data_event_accrual!$E:$E,$AH6)),1)),COUNTIF($AX$5:$AX$14,"<="&bal*shr)))} | AR6: {=IF($AH6="","",IF(AQ6=0,"{}",LET(m,AQ6,s,MMULT(TRANSPOSE((SEQUENCE(10,1,1,1)<=m)*1),VSTACK($H$27:$AB$27,$H$30:$AB$30,$H$33:$AB$33,$H$36:$AB$36,$H$39:$AB$39,$H$42:$AB$42,$H$45:$AB$45,$H$48:$AB$48,$H$51:$AB$51,$H$54:$AB$54)),"{"&TEXTJOIN(", ",TRUE,IF(s>0,$H$24:$AB$24&": "&ROUND(s,2),""))&"}")))} | AT6: 2 | AU6: =SUM($F$25:$F26) | AW6: 2 | AX6: 395
A7: manualRewardClaiming | B7: =FALSE() | AH7: =IF(2<=$B$3,2,"") | AI7: {=IF($AH7="","",LET(bal,SUMIFS(data_event_inst!$N:$N,data_event_inst!$A:$A,"Photoshoot",data_event_inst!$B:$B,$AI$3,data_event_inst!$C:$C,"0-9"),shr,MIN(1,IFERROR(CHOOSE(MATCH($AI$2,{"Avg","p25","p50","p75"},0),AVERAGEIFS(data_event_accrual!$I:$I,data_event_accrual!$A:$A,"Photoshoot",data_event_accrual!$B:$B,$AI$3,data_event_accrual!$C:$C,"0-9",data_event_accrual!$E:$E,$AH7),AVERAGEIFS(data_event_accrual!$K:$K,data_event_accrual!$A:$A,"Photoshoot",data_event_accrual!$B:$B,$AI$3,data_event_accrual!$C:$C,"0-9",data_event_accrual!$E:$E,$AH7),AVERAGEIFS(data_event_accrual!$J:$J,data_event_accrual!$A:$A,"Photoshoot",data_event_accrual!$B:$B,$AI$3,data_event_accrual!$C:$C,"0-9",data_event_accrual!$E:$E,$AH7),AVERAGEIFS(data_event_accrual!$L:$L,data_event_accrual!$A:$A,"Photoshoot",data_event_accrual!$B:$B,$AI$3,data_event_accrual!$C:$C,"0-9",data_event_accrual!$E:$E,$AH7)),1)),COUNTIF($AX$5:$AX$14,"<="&bal*shr)))} | AJ7: {=IF($AH7="","",IF(AI7=0,"{}",LET(m,AI7,s,MMULT(TRANSPOSE((SEQUENCE(10,1,1,1)<=m)*1),VSTACK($H$27:$AB$27,$H$30:$AB$30,$H$33:$AB$33,$H$36:$AB$36,$H$39:$AB$39,$H$42:$AB$42,$H$45:$AB$45,$H$48:$AB$48,$H$51:$AB$51,$H$54:$AB$54)),"{"&TEXTJOIN(", ",TRUE,IF(s>0,$H$24:$AB$24&": "&ROUND(s,2),""))&"}")))} | AK7: {=IF($AH7="","",LET(bal,SUMIFS(data_event_inst!$N:$N,data_event_inst!$A:$A,"Photoshoot",data_event_inst!$B:$B,$AI$3,data_event_inst!$C:$C,"10-19"),shr,MIN(1,IFERROR(CHOOSE(MATCH($AI$2,{"Avg","p25","p50","p75"},0),AVERAGEIFS(data_event_accrual!$I:$I,data_event_accrual!$A:$A,"Photoshoot",data_event_accrual!$B:$B,$AI$3,data_event_accrual!$C:$C,"10-19",data_event_accrual!$E:$E,$AH7),AVERAGEIFS(data_event_accrual!$K:$K,data_event_accrual!$A:$A,"Photoshoot",data_event_accrual!$B:$B,$AI$3,data_event_accrual!$C:$C,"10-19",data_event_accrual!$E:$E,$AH7),AVERAGEIFS(data_event_accrual!$J:$J,data_event_accrual!$A:$A,"Photoshoot",data_event_accrual!$B:$B,$AI$3,data_event_accrual!$C:$C,"10-19",data_event_accrual!$E:$E,$AH7),AVERAGEIFS(data_event_accrual!$L:$L,data_event_accrual!$A:$A,"Photoshoot",data_event_accrual!$B:$B,$AI$3,data_event_accrual!$C:$C,"10-19",data_event_accrual!$E:$E,$AH7)),1)),COUNTIF($AX$5:$AX$14,"<="&bal*shr)))} | AL7: {=IF($AH7="","",IF(AK7=0,"{}",LET(m,AK7,s,MMULT(TRANSPOSE((SEQUENCE(10,1,1,1)<=m)*1),VSTACK($H$27:$AB$27,$H$30:$AB$30,$H$33:$AB$33,$H$36:$AB$36,$H$39:$AB$39,$H$42:$AB$42,$H$45:$AB$45,$H$48:$AB$48,$H$51:$AB$51,$H$54:$AB$54)),"{"&TEXTJOIN(", ",TRUE,IF(s>0,$H$24:$AB$24&": "&ROUND(s,2),""))&"}")))} | AM7: {=IF($AH7="","",LET(bal,SUMIFS(data_event_inst!$N:$N,data_event_inst!$A:$A,"Photoshoot",data_event_inst!$B:$B,$AI$3,data_event_inst!$C:$C,"20-39"),shr,MIN(1,IFERROR(CHOOSE(MATCH($AI$2,{"Avg","p25","p50","p75"},0),AVERAGEIFS(data_event_accrual!$I:$I,data_event_accrual!$A:$A,"Photoshoot",data_event_accrual!$B:$B,$AI$3,data_event_accrual!$C:$C,"20-39",data_event_accrual!$E:$E,$AH7),AVERAGEIFS(data_event_accrual!$K:$K,data_event_accrual!$A:$A,"Photoshoot",data_event_accrual!$B:$B,$AI$3,data_event_accrual!$C:$C,"20-39",data_event_accrual!$E:$E,$AH7),AVERAGEIFS(data_event_accrual!$J:$J,data_event_accrual!$A:$A,"Photoshoot",data_event_accrual!$B:$B,$AI$3,data_event_accrual!$C:$C,"20-39",data_event_accrual!$E:$E,$AH7),AVERAGEIFS(data_event_accrual!$L:$L,data_event_accrual!$A:$A,"Photoshoot",data_event_accrual!$B:$B,$AI$3,data_event_accrual!$C:$C,"20-39",data_event_accrual!$E:$E,$AH7)),1)),COUNTIF($AX$5:$AX$14,"<="&bal*shr)))} | AN7: {=IF($AH7="","",IF(AM7=0,"{}",LET(m,AM7,s,MMULT(TRANSPOSE((SEQUENCE(10,1,1,1)<=m)*1),VSTACK($H$27:$AB$27,$H$30:$AB$30,$H$33:$AB$33,$H$36:$AB$36,$H$39:$AB$39,$H$42:$AB$42,$H$45:$AB$45,$H$48:$AB$48,$H$51:$AB$51,$H$54:$AB$54)),"{"&TEXTJOIN(", ",TRUE,IF(s>0,$H$24:$AB$24&": "&ROUND(s,2),""))&"}")))} | AO7: {=IF($AH7="","",LET(bal,SUMIFS(data_event_inst!$N:$N,data_event_inst!$A:$A,"Photoshoot",data_event_inst!$B:$B,$AI$3,data_event_inst!$C:$C,"40-99"),shr,MIN(1,IFERROR(CHOOSE(MATCH($AI$2,{"Avg","p25","p50","p75"},0),AVERAGEIFS(data_event_accrual!$I:$I,data_event_accrual!$A:$A,"Photoshoot",data_event_accrual!$B:$B,$AI$3,data_event_accrual!$C:$C,"40-99",data_event_accrual!$E:$E,$AH7),AVERAGEIFS(data_event_accrual!$K:$K,data_event_accrual!$A:$A,"Photoshoot",data_event_accrual!$B:$B,$AI$3,data_event_accrual!$C:$C,"40-99",data_event_accrual!$E:$E,$AH7),AVERAGEIFS(data_event_accrual!$J:$J,data_event_accrual!$A:$A,"Photoshoot",data_event_accrual!$B:$B,$AI$3,data_event_accrual!$C:$C,"40-99",data_event_accrual!$E:$E,$AH7),AVERAGEIFS(data_event_accrual!$L:$L,data_event_accrual!$A:$A,"Photoshoot",data_event_accrual!$B:$B,$AI$3,data_event_accrual!$C:$C,"40-99",data_event_accrual!$E:$E,$AH7)),1)),COUNTIF($AX$5:$AX$14,"<="&bal*shr)))} | AP7: {=IF($AH7="","",IF(AO7=0,"{}",LET(m,AO7,s,MMULT(TRANSPOSE((SEQUENCE(10,1,1,1)<=m)*1),VSTACK($H$27:$AB$27,$H$30:$AB$30,$H$33:$AB$33,$H$36:$AB$36,$H$39:$AB$39,$H$42:$AB$42,$H$45:$AB$45,$H$48:$AB$48,$H$51:$AB$51,$H$54:$AB$54)),"{"&TEXTJOIN(", ",TRUE,IF(s>0,$H$24:$AB$24&": "&ROUND(s,2),""))&"}")))} | AQ7: {=IF($AH7="","",LET(bal,SUMIFS(data_event_inst!$N:$N,data_event_inst!$A:$A,"Photoshoot",data_event_inst!$B:$B,$AI$3,data_event_inst!$C:$C,"100+"),shr,MIN(1,IFERROR(CHOOSE(MATCH($AI$2,{"Avg","p25","p50","p75"},0),AVERAGEIFS(data_event_accrual!$I:$I,data_event_accrual!$A:$A,"Photoshoot",data_event_accrual!$B:$B,$AI$3,data_event_accrual!$C:$C,"100+",data_event_accrual!$E:$E,$AH7),AVERAGEIFS(data_event_accrual!$K:$K,data_event_accrual!$A:$A,"Photoshoot",data_event_accrual!$B:$B,$AI$3,data_event_accrual!$C:$C,"100+",data_event_accrual!$E:$E,$AH7),AVERAGEIFS(data_event_accrual!$J:$J,data_event_accrual!$A:$A,"Photoshoot",data_event_accrual!$B:$B,$AI$3,data_event_accrual!$C:$C,"100+",data_event_accrual!$E:$E,$AH7),AVERAGEIFS(data_event_accrual!$L:$L,data_event_accrual!$A:$A,"Photoshoot",data_event_accrual!$B:$B,$AI$3,data_event_accrual!$C:$C,"100+",data_event_accrual!$E:$E,$AH7)),1)),COUNTIF($AX$5:$AX$14,"<="&bal*shr)))} | AR7: {=IF($AH7="","",IF(AQ7=0,"{}",LET(m,AQ7,s,MMULT(TRANSPOSE((SEQUENCE(10,1,1,1)<=m)*1),VSTACK($H$27:$AB$27,$H$30:$AB$30,$H$33:$AB$33,$H$36:$AB$36,$H$39:$AB$39,$H$42:$AB$42,$H$45:$AB$45,$H$48:$AB$48,$H$51:$AB$51,$H$54:$AB$54)),"{"&TEXTJOIN(", ",TRUE,IF(s>0,$H$24:$AB$24&": "&ROUND(s,2),""))&"}")))} | AT7: 3 | AU7: =SUM($F$25:$F27) | AW7: 3 | AX7: 640
A8: assetBundle | B8: event-photoshoot-generic | AH8: =IF(3<=$B$3,3,"") | AI8: {=IF($AH8="","",LET(bal,SUMIFS(data_event_inst!$N:$N,data_event_inst!$A:$A,"Photoshoot",data_event_inst!$B:$B,$AI$3,data_event_inst!$C:$C,"0-9"),shr,MIN(1,IFERROR(CHOOSE(MATCH($AI$2,{"Avg","p25","p50","p75"},0),AVERAGEIFS(data_event_accrual!$I:$I,data_event_accrual!$A:$A,"Photoshoot",data_event_accrual!$B:$B,$AI$3,data_event_accrual!$C:$C,"0-9",data_event_accrual!$E:$E,$AH8),AVERAGEIFS(data_event_accrual!$K:$K,data_event_accrual!$A:$A,"Photoshoot",data_event_accrual!$B:$B,$AI$3,data_event_accrual!$C:$C,"0-9",data_event_accrual!$E:$E,$AH8),AVERAGEIFS(data_event_accrual!$J:$J,data_event_accrual!$A:$A,"Photoshoot",data_event_accrual!$B:$B,$AI$3,data_event_accrual!$C:$C,"0-9",data_event_accrual!$E:$E,$AH8),AVERAGEIFS(data_event_accrual!$L:$L,data_event_accrual!$A:$A,"Photoshoot",data_event_accrual!$B:$B,$AI$3,data_event_accrual!$C:$C,"0-9",data_event_accrual!$E:$E,$AH8)),1)),COUNTIF($AX$5:$AX$14,"<="&bal*shr)))} | AJ8: {=IF($AH8="","",IF(AI8=0,"{}",LET(m,AI8,s,MMULT(TRANSPOSE((SEQUENCE(10,1,1,1)<=m)*1),VSTACK($H$27:$AB$27,$H$30:$AB$30,$H$33:$AB$33,$H$36:$AB$36,$H$39:$AB$39,$H$42:$AB$42,$H$45:$AB$45,$H$48:$AB$48,$H$51:$AB$51,$H$54:$AB$54)),"{"&TEXTJOIN(", ",TRUE,IF(s>0,$H$24:$AB$24&": "&ROUND(s,2),""))&"}")))} | AK8: {=IF($AH8="","",LET(bal,SUMIFS(data_event_inst!$N:$N,data_event_inst!$A:$A,"Photoshoot",data_event_inst!$B:$B,$AI$3,data_event_inst!$C:$C,"10-19"),shr,MIN(1,IFERROR(CHOOSE(MATCH($AI$2,{"Avg","p25","p50","p75"},0),AVERAGEIFS(data_event_accrual!$I:$I,data_event_accrual!$A:$A,"Photoshoot",data_event_accrual!$B:$B,$AI$3,data_event_accrual!$C:$C,"10-19",data_event_accrual!$E:$E,$AH8),AVERAGEIFS(data_event_accrual!$K:$K,data_event_accrual!$A:$A,"Photoshoot",data_event_accrual!$B:$B,$AI$3,data_event_accrual!$C:$C,"10-19",data_event_accrual!$E:$E,$AH8),AVERAGEIFS(data_event_accrual!$J:$J,data_event_accrual!$A:$A,"Photoshoot",data_event_accrual!$B:$B,$AI$3,data_event_accrual!$C:$C,"10-19",data_event_accrual!$E:$E,$AH8),AVERAGEIFS(data_event_accrual!$L:$L,data_event_accrual!$A:$A,"Photoshoot",data_event_accrual!$B:$B,$AI$3,data_event_accrual!$C:$C,"10-19",data_event_accrual!$E:$E,$AH8)),1)),COUNTIF($AX$5:$AX$14,"<="&bal*shr)))} | AL8: {=IF($AH8="","",IF(AK8=0,"{}",LET(m,AK8,s,MMULT(TRANSPOSE((SEQUENCE(10,1,1,1)<=m)*1),VSTACK($H$27:$AB$27,$H$30:$AB$30,$H$33:$AB$33,$H$36:$AB$36,$H$39:$AB$39,$H$42:$AB$42,$H$45:$AB$45,$H$48:$AB$48,$H$51:$AB$51,$H$54:$AB$54)),"{"&TEXTJOIN(", ",TRUE,IF(s>0,$H$24:$AB$24&": "&ROUND(s,2),""))&"}")))} | AM8: {=IF($AH8="","",LET(bal,SUMIFS(data_event_inst!$N:$N,data_event_inst!$A:$A,"Photoshoot",data_event_inst!$B:$B,$AI$3,data_event_inst!$C:$C,"20-39"),shr,MIN(1,IFERROR(CHOOSE(MATCH($AI$2,{"Avg","p25","p50","p75"},0),AVERAGEIFS(data_event_accrual!$I:$I,data_event_accrual!$A:$A,"Photoshoot",data_event_accrual!$B:$B,$AI$3,data_event_accrual!$C:$C,"20-39",data_event_accrual!$E:$E,$AH8),AVERAGEIFS(data_event_accrual!$K:$K,data_event_accrual!$A:$A,"Photoshoot",data_event_accrual!$B:$B,$AI$3,data_event_accrual!$C:$C,"20-39",data_event_accrual!$E:$E,$AH8),AVERAGEIFS(data_event_accrual!$J:$J,data_event_accrual!$A:$A,"Photoshoot",data_event_accrual!$B:$B,$AI$3,data_event_accrual!$C:$C,"20-39",data_event_accrual!$E:$E,$AH8),AVERAGEIFS(data_event_accrual!$L:$L,data_event_accrual!$A:$A,"Photoshoot",data_event_accrual!$B:$B,$AI$3,data_event_accrual!$C:$C,"20-39",data_event_accrual!$E:$E,$AH8)),1)),COUNTIF($AX$5:$AX$14,"<="&bal*shr)))} | AN8: {=IF($AH8="","",IF(AM8=0,"{}",LET(m,AM8,s,MMULT(TRANSPOSE((SEQUENCE(10,1,1,1)<=m)*1),VSTACK($H$27:$AB$27,$H$30:$AB$30,$H$33:$AB$33,$H$36:$AB$36,$H$39:$AB$39,$H$42:$AB$42,$H$45:$AB$45,$H$48:$AB$48,$H$51:$AB$51,$H$54:$AB$54)),"{"&TEXTJOIN(", ",TRUE,IF(s>0,$H$24:$AB$24&": "&ROUND(s,2),""))&"}")))} | AO8: {=IF($AH8="","",LET(bal,SUMIFS(data_event_inst!$N:$N,data_event_inst!$A:$A,"Photoshoot",data_event_inst!$B:$B,$AI$3,data_event_inst!$C:$C,"40-99"),shr,MIN(1,IFERROR(CHOOSE(MATCH($AI$2,{"Avg","p25","p50","p75"},0),AVERAGEIFS(data_event_accrual!$I:$I,data_event_accrual!$A:$A,"Photoshoot",data_event_accrual!$B:$B,$AI$3,data_event_accrual!$C:$C,"40-99",data_event_accrual!$E:$E,$AH8),AVERAGEIFS(data_event_accrual!$K:$K,data_event_accrual!$A:$A,"Photoshoot",data_event_accrual!$B:$B,$AI$3,data_event_accrual!$C:$C,"40-99",data_event_accrual!$E:$E,$AH8),AVERAGEIFS(data_event_accrual!$J:$J,data_event_accrual!$A:$A,"Photoshoot",data_event_accrual!$B:$B,$AI$3,data_event_accrual!$C:$C,"40-99",data_event_accrual!$E:$E,$AH8),AVERAGEIFS(data_event_accrual!$L:$L,data_event_accrual!$A:$A,"Photoshoot",data_event_accrual!$B:$B,$AI$3,data_event_accrual!$C:$C,"40-99",data_event_accrual!$E:$E,$AH8)),1)),COUNTIF($AX$5:$AX$14,"<="&bal*shr)))} | AP8: {=IF($AH8="","",IF(AO8=0,"{}",LET(m,AO8,s,MMULT(TRANSPOSE((SEQUENCE(10,1,1,1)<=m)*1),VSTACK($H$27:$AB$27,$H$30:$AB$30,$H$33:$AB$33,$H$36:$AB$36,$H$39:$AB$39,$H$42:$AB$42,$H$45:$AB$45,$H$48:$AB$48,$H$51:$AB$51,$H$54:$AB$54)),"{"&TEXTJOIN(", ",TRUE,IF(s>0,$H$24:$AB$24&": "&ROUND(s,2),""))&"}")))} | AQ8: {=IF($AH8="","",LET(bal,SUMIFS(data_event_inst!$N:$N,data_event_inst!$A:$A,"Photoshoot",data_event_inst!$B:$B,$AI$3,data_event_inst!$C:$C,"100+"),shr,MIN(1,IFERROR(CHOOSE(MATCH($AI$2,{"Avg","p25","p50","p75"},0),AVERAGEIFS(data_event_accrual!$I:$I,data_event_accrual!$A:$A,"Photoshoot",data_event_accrual!$B:$B,$AI$3,data_event_accrual!$C:$C,"100+",data_event_accrual!$E:$E,$AH8),AVERAGEIFS(data_event_accrual!$K:$K,data_event_accrual!$A:$A,"Photoshoot",data_event_accrual!$B:$B,$AI$3,data_event_accrual!$C:$C,"100+",data_event_accrual!$E:$E,$AH8),AVERAGEIFS(data_event_accrual!$J:$J,data_event_accrual!$A:$A,"Photoshoot",data_event_accrual!$B:$B,$AI$3,data_event_accrual!$C:$C,"100+",data_event_accrual!$E:$E,$AH8),AVERAGEIFS(data_event_accrual!$L:$L,data_event_accrual!$A:$A,"Photoshoot",data_event_accrual!$B:$B,$AI$3,data_event_accrual!$C:$C,"100+",data_event_accrual!$E:$E,$AH8)),1)),COUNTIF($AX$5:$AX$14,"<="&bal*shr)))} | AR8: {=IF($AH8="","",IF(AQ8=0,"{}",LET(m,AQ8,s,MMULT(TRANSPOSE((SEQUENCE(10,1,1,1)<=m)*1),VSTACK($H$27:$AB$27,$H$30:$AB$30,$H$33:$AB$33,$H$36:$AB$36,$H$39:$AB$39,$H$42:$AB$42,$H$45:$AB$45,$H$48:$AB$48,$H$51:$AB$51,$H$54:$AB$54)),"{"&TEXTJOIN(", ",TRUE,IF(s>0,$H$24:$AB$24&": "&ROUND(s,2),""))&"}")))} | AT8: 4 | AU8: =SUM($F$25:$F28) | AW8: 4 | AX8: 985
A9: numberOfItems | B9: 30 | AH9: =IF(4<=$B$3,4,"") | AI9: {=IF($AH9="","",LET(bal,SUMIFS(data_event_inst!$N:$N,data_event_inst!$A:$A,"Photoshoot",data_event_inst!$B:$B,$AI$3,data_event_inst!$C:$C,"0-9"),shr,MIN(1,IFERROR(CHOOSE(MATCH($AI$2,{"Avg","p25","p50","p75"},0),AVERAGEIFS(data_event_accrual!$I:$I,data_event_accrual!$A:$A,"Photoshoot",data_event_accrual!$B:$B,$AI$3,data_event_accrual!$C:$C,"0-9",data_event_accrual!$E:$E,$AH9),AVERAGEIFS(data_event_accrual!$K:$K,data_event_accrual!$A:$A,"Photoshoot",data_event_accrual!$B:$B,$AI$3,data_event_accrual!$C:$C,"0-9",data_event_accrual!$E:$E,$AH9),AVERAGEIFS(data_event_accrual!$J:$J,data_event_accrual!$A:$A,"Photoshoot",data_event_accrual!$B:$B,$AI$3,data_event_accrual!$C:$C,"0-9",data_event_accrual!$E:$E,$AH9),AVERAGEIFS(data_event_accrual!$L:$L,data_event_accrual!$A:$A,"Photoshoot",data_event_accrual!$B:$B,$AI$3,data_event_accrual!$C:$C,"0-9",data_event_accrual!$E:$E,$AH9)),1)),COUNTIF($AX$5:$AX$14,"<="&bal*shr)))} | AJ9: {=IF($AH9="","",IF(AI9=0,"{}",LET(m,AI9,s,MMULT(TRANSPOSE((SEQUENCE(10,1,1,1)<=m)*1),VSTACK($H$27:$AB$27,$H$30:$AB$30,$H$33:$AB$33,$H$36:$AB$36,$H$39:$AB$39,$H$42:$AB$42,$H$45:$AB$45,$H$48:$AB$48,$H$51:$AB$51,$H$54:$AB$54)),"{"&TEXTJOIN(", ",TRUE,IF(s>0,$H$24:$AB$24&": "&ROUND(s,2),""))&"}")))} | AK9: {=IF($AH9="","",LET(bal,SUMIFS(data_event_inst!$N:$N,data_event_inst!$A:$A,"Photoshoot",data_event_inst!$B:$B,$AI$3,data_event_inst!$C:$C,"10-19"),shr,MIN(1,IFERROR(CHOOSE(MATCH($AI$2,{"Avg","p25","p50","p75"},0),AVERAGEIFS(data_event_accrual!$I:$I,data_event_accrual!$A:$A,"Photoshoot",data_event_accrual!$B:$B,$AI$3,data_event_accrual!$C:$C,"10-19",data_event_accrual!$E:$E,$AH9),AVERAGEIFS(data_event_accrual!$K:$K,data_event_accrual!$A:$A,"Photoshoot",data_event_accrual!$B:$B,$AI$3,data_event_accrual!$C:$C,"10-19",data_event_accrual!$E:$E,$AH9),AVERAGEIFS(data_event_accrual!$J:$J,data_event_accrual!$A:$A,"Photoshoot",data_event_accrual!$B:$B,$AI$3,data_event_accrual!$C:$C,"10-19",data_event_accrual!$E:$E,$AH9),AVERAGEIFS(data_event_accrual!$L:$L,data_event_accrual!$A:$A,"Photoshoot",data_event_accrual!$B:$B,$AI$3,data_event_accrual!$C:$C,"10-19",data_event_accrual!$E:$E,$AH9)),1)),COUNTIF($AX$5:$AX$14,"<="&bal*shr)))} | AL9: {=IF($AH9="","",IF(AK9=0,"{}",LET(m,AK9,s,MMULT(TRANSPOSE((SEQUENCE(10,1,1,1)<=m)*1),VSTACK($H$27:$AB$27,$H$30:$AB$30,$H$33:$AB$33,$H$36:$AB$36,$H$39:$AB$39,$H$42:$AB$42,$H$45:$AB$45,$H$48:$AB$48,$H$51:$AB$51,$H$54:$AB$54)),"{"&TEXTJOIN(", ",TRUE,IF(s>0,$H$24:$AB$24&": "&ROUND(s,2),""))&"}")))} | AM9: {=IF($AH9="","",LET(bal,SUMIFS(data_event_inst!$N:$N,data_event_inst!$A:$A,"Photoshoot",data_event_inst!$B:$B,$AI$3,data_event_inst!$C:$C,"20-39"),shr,MIN(1,IFERROR(CHOOSE(MATCH($AI$2,{"Avg","p25","p50","p75"},0),AVERAGEIFS(data_event_accrual!$I:$I,data_event_accrual!$A:$A,"Photoshoot",data_event_accrual!$B:$B,$AI$3,data_event_accrual!$C:$C,"20-39",data_event_accrual!$E:$E,$AH9),AVERAGEIFS(data_event_accrual!$K:$K,data_event_accrual!$A:$A,"Photoshoot",data_event_accrual!$B:$B,$AI$3,data_event_accrual!$C:$C,"20-39",data_event_accrual!$E:$E,$AH9),AVERAGEIFS(data_event_accrual!$J:$J,data_event_accrual!$A:$A,"Photoshoot",data_event_accrual!$B:$B,$AI$3,data_event_accrual!$C:$C,"20-39",data_event_accrual!$E:$E,$AH9),AVERAGEIFS(data_event_accrual!$L:$L,data_event_accrual!$A:$A,"Photoshoot",data_event_accrual!$B:$B,$AI$3,data_event_accrual!$C:$C,"20-39",data_event_accrual!$E:$E,$AH9)),1)),COUNTIF($AX$5:$AX$14,"<="&bal*shr)))} | AN9: {=IF($AH9="","",IF(AM9=0,"{}",LET(m,AM9,s,MMULT(TRANSPOSE((SEQUENCE(10,1,1,1)<=m)*1),VSTACK($H$27:$AB$27,$H$30:$AB$30,$H$33:$AB$33,$H$36:$AB$36,$H$39:$AB$39,$H$42:$AB$42,$H$45:$AB$45,$H$48:$AB$48,$H$51:$AB$51,$H$54:$AB$54)),"{"&TEXTJOIN(", ",TRUE,IF(s>0,$H$24:$AB$24&": "&ROUND(s,2),""))&"}")))} | AO9: {=IF($AH9="","",LET(bal,SUMIFS(data_event_inst!$N:$N,data_event_inst!$A:$A,"Photoshoot",data_event_inst!$B:$B,$AI$3,data_event_inst!$C:$C,"40-99"),shr,MIN(1,IFERROR(CHOOSE(MATCH($AI$2,{"Avg","p25","p50","p75"},0),AVERAGEIFS(data_event_accrual!$I:$I,data_event_accrual!$A:$A,"Photoshoot",data_event_accrual!$B:$B,$AI$3,data_event_accrual!$C:$C,"40-99",data_event_accrual!$E:$E,$AH9),AVERAGEIFS(data_event_accrual!$K:$K,data_event_accrual!$A:$A,"Photoshoot",data_event_accrual!$B:$B,$AI$3,data_event_accrual!$C:$C,"40-99",data_event_accrual!$E:$E,$AH9),AVERAGEIFS(data_event_accrual!$J:$J,data_event_accrual!$A:$A,"Photoshoot",data_event_accrual!$B:$B,$AI$3,data_event_accrual!$C:$C,"40-99",data_event_accrual!$E:$E,$AH9),AVERAGEIFS(data_event_accrual!$L:$L,data_event_accrual!$A:$A,"Photoshoot",data_event_accrual!$B:$B,$AI$3,data_event_accrual!$C:$C,"40-99",data_event_accrual!$E:$E,$AH9)),1)),COUNTIF($AX$5:$AX$14,"<="&bal*shr)))} | AP9: {=IF($AH9="","",IF(AO9=0,"{}",LET(m,AO9,s,MMULT(TRANSPOSE((SEQUENCE(10,1,1,1)<=m)*1),VSTACK($H$27:$AB$27,$H$30:$AB$30,$H$33:$AB$33,$H$36:$AB$36,$H$39:$AB$39,$H$42:$AB$42,$H$45:$AB$45,$H$48:$AB$48,$H$51:$AB$51,$H$54:$AB$54)),"{"&TEXTJOIN(", ",TRUE,IF(s>0,$H$24:$AB$24&": "&ROUND(s,2),""))&"}")))} | AQ9: {=IF($AH9="","",LET(bal,SUMIFS(data_event_inst!$N:$N,data_event_inst!$A:$A,"Photoshoot",data_event_inst!$B:$B,$AI$3,data_event_inst!$C:$C,"100+"),shr,MIN(1,IFERROR(CHOOSE(MATCH($AI$2,{"Avg","p25","p50","p75"},0),AVERAGEIFS(data_event_accrual!$I:$I,data_event_accrual!$A:$A,"Photoshoot",data_event_accrual!$B:$B,$AI$3,data_event_accrual!$C:$C,"100+",data_event_accrual!$E:$E,$AH9),AVERAGEIFS(data_event_accrual!$K:$K,data_event_accrual!$A:$A,"Photoshoot",data_event_accrual!$B:$B,$AI$3,data_event_accrual!$C:$C,"100+",data_event_accrual!$E:$E,$AH9),AVERAGEIFS(data_event_accrual!$J:$J,data_event_accrual!$A:$A,"Photoshoot",data_event_accrual!$B:$B,$AI$3,data_event_accrual!$C:$C,"100+",data_event_accrual!$E:$E,$AH9),AVERAGEIFS(data_event_accrual!$L:$L,data_event_accrual!$A:$A,"Photoshoot",data_event_accrual!$B:$B,$AI$3,data_event_accrual!$C:$C,"100+",data_event_accrual!$E:$E,$AH9)),1)),COUNTIF($AX$5:$AX$14,"<="&bal*shr)))} | AR9: {=IF($AH9="","",IF(AQ9=0,"{}",LET(m,AQ9,s,MMULT(TRANSPOSE((SEQUENCE(10,1,1,1)<=m)*1),VSTACK($H$27:$AB$27,$H$30:$AB$30,$H$33:$AB$33,$H$36:$AB$36,$H$39:$AB$39,$H$42:$AB$42,$H$45:$AB$45,$H$48:$AB$48,$H$51:$AB$51,$H$54:$AB$54)),"{"&TEXTJOIN(", ",TRUE,IF(s>0,$H$24:$AB$24&": "&ROUND(s,2),""))&"}")))} | AT9: 5 | AU9: =SUM($F$25:$F29) | AW9: 5 | AX9: 1415
A10: numberOfMilestoneTiers | B10: 10 | AH10: =IF(5<=$B$3,5,"") | AI10: {=IF($AH10="","",LET(bal,SUMIFS(data_event_inst!$N:$N,data_event_inst!$A:$A,"Photoshoot",data_event_inst!$B:$B,$AI$3,data_event_inst!$C:$C,"0-9"),shr,MIN(1,IFERROR(CHOOSE(MATCH($AI$2,{"Avg","p25","p50","p75"},0),AVERAGEIFS(data_event_accrual!$I:$I,data_event_accrual!$A:$A,"Photoshoot",data_event_accrual!$B:$B,$AI$3,data_event_accrual!$C:$C,"0-9",data_event_accrual!$E:$E,$AH10),AVERAGEIFS(data_event_accrual!$K:$K,data_event_accrual!$A:$A,"Photoshoot",data_event_accrual!$B:$B,$AI$3,data_event_accrual!$C:$C,"0-9",data_event_accrual!$E:$E,$AH10),AVERAGEIFS(data_event_accrual!$J:$J,data_event_accrual!$A:$A,"Photoshoot",data_event_accrual!$B:$B,$AI$3,data_event_accrual!$C:$C,"0-9",data_event_accrual!$E:$E,$AH10),AVERAGEIFS(data_event_accrual!$L:$L,data_event_accrual!$A:$A,"Photoshoot",data_event_accrual!$B:$B,$AI$3,data_event_accrual!$C:$C,"0-9",data_event_accrual!$E:$E,$AH10)),1)),COUNTIF($AX$5:$AX$14,"<="&bal*shr)))} | AJ10: {=IF($AH10="","",IF(AI10=0,"{}",LET(m,AI10,s,MMULT(TRANSPOSE((SEQUENCE(10,1,1,1)<=m)*1),VSTACK($H$27:$AB$27,$H$30:$AB$30,$H$33:$AB$33,$H$36:$AB$36,$H$39:$AB$39,$H$42:$AB$42,$H$45:$AB$45,$H$48:$AB$48,$H$51:$AB$51,$H$54:$AB$54)),"{"&TEXTJOIN(", ",TRUE,IF(s>0,$H$24:$AB$24&": "&ROUND(s,2),""))&"}")))} | AK10: {=IF($AH10="","",LET(bal,SUMIFS(data_event_inst!$N:$N,data_event_inst!$A:$A,"Photoshoot",data_event_inst!$B:$B,$AI$3,data_event_inst!$C:$C,"10-19"),shr,MIN(1,IFERROR(CHOOSE(MATCH($AI$2,{"Avg","p25","p50","p75"},0),AVERAGEIFS(data_event_accrual!$I:$I,data_event_accrual!$A:$A,"Photoshoot",data_event_accrual!$B:$B,$AI$3,data_event_accrual!$C:$C,"10-19",data_event_accrual!$E:$E,$AH10),AVERAGEIFS(data_event_accrual!$K:$K,data_event_accrual!$A:$A,"Photoshoot",data_event_accrual!$B:$B,$AI$3,data_event_accrual!$C:$C,"10-19",data_event_accrual!$E:$E,$AH10),AVERAGEIFS(data_event_accrual!$J:$J,data_event_accrual!$A:$A,"Photoshoot",data_event_accrual!$B:$B,$AI$3,data_event_accrual!$C:$C,"10-19",data_event_accrual!$E:$E,$AH10),AVERAGEIFS(data_event_accrual!$L:$L,data_event_accrual!$A:$A,"Photoshoot",data_event_accrual!$B:$B,$AI$3,data_event_accrual!$C:$C,"10-19",data_event_accrual!$E:$E,$AH10)),1)),COUNTIF($AX$5:$AX$14,"<="&bal*shr)))} | AL10: {=IF($AH10="","",IF(AK10=0,"{}",LET(m,AK10,s,MMULT(TRANSPOSE((SEQUENCE(10,1,1,1)<=m)*1),VSTACK($H$27:$AB$27,$H$30:$AB$30,$H$33:$AB$33,$H$36:$AB$36,$H$39:$AB$39,$H$42:$AB$42,$H$45:$AB$45,$H$48:$AB$48,$H$51:$AB$51,$H$54:$AB$54)),"{"&TEXTJOIN(", ",TRUE,IF(s>0,$H$24:$AB$24&": "&ROUND(s,2),""))&"}")))} | AM10: {=IF($AH10="","",LET(bal,SUMIFS(data_event_inst!$N:$N,data_event_inst!$A:$A,"Photoshoot",data_event_inst!$B:$B,$AI$3,data_event_inst!$C:$C,"20-39"),shr,MIN(1,IFERROR(CHOOSE(MATCH($AI$2,{"Avg","p25","p50","p75"},0),AVERAGEIFS(data_event_accrual!$I:$I,data_event_accrual!$A:$A,"Photoshoot",data_event_accrual!$B:$B,$AI$3,data_event_accrual!$C:$C,"20-39",data_event_accrual!$E:$E,$AH10),AVERAGEIFS(data_event_accrual!$K:$K,data_event_accrual!$A:$A,"Photoshoot",data_event_accrual!$B:$B,$AI$3,data_event_accrual!$C:$C,"20-39",data_event_accrual!$E:$E,$AH10),AVERAGEIFS(data_event_accrual!$J:$J,data_event_accrual!$A:$A,"Photoshoot",data_event_accrual!$B:$B,$AI$3,data_event_accrual!$C:$C,"20-39",data_event_accrual!$E:$E,$AH10),AVERAGEIFS(data_event_accrual!$L:$L,data_event_accrual!$A:$A,"Photoshoot",data_event_accrual!$B:$B,$AI$3,data_event_accrual!$C:$C,"20-39",data_event_accrual!$E:$E,$AH10)),1)),COUNTIF($AX$5:$AX$14,"<="&bal*shr)))} | AN10: {=IF($AH10="","",IF(AM10=0,"{}",LET(m,AM10,s,MMULT(TRANSPOSE((SEQUENCE(10,1,1,1)<=m)*1),VSTACK($H$27:$AB$27,$H$30:$AB$30,$H$33:$AB$33,$H$36:$AB$36,$H$39:$AB$39,$H$42:$AB$42,$H$45:$AB$45,$H$48:$AB$48,$H$51:$AB$51,$H$54:$AB$54)),"{"&TEXTJOIN(", ",TRUE,IF(s>0,$H$24:$AB$24&": "&ROUND(s,2),""))&"}")))} | AO10: {=IF($AH10="","",LET(bal,SUMIFS(data_event_inst!$N:$N,data_event_inst!$A:$A,"Photoshoot",data_event_inst!$B:$B,$AI$3,data_event_inst!$C:$C,"40-99"),shr,MIN(1,IFERROR(CHOOSE(MATCH($AI$2,{"Avg","p25","p50","p75"},0),AVERAGEIFS(data_event_accrual!$I:$I,data_event_accrual!$A:$A,"Photoshoot",data_event_accrual!$B:$B,$AI$3,data_event_accrual!$C:$C,"40-99",data_event_accrual!$E:$E,$AH10),AVERAGEIFS(data_event_accrual!$K:$K,data_event_accrual!$A:$A,"Photoshoot",data_event_accrual!$B:$B,$AI$3,data_event_accrual!$C:$C,"40-99",data_event_accrual!$E:$E,$AH10),AVERAGEIFS(data_event_accrual!$J:$J,data_event_accrual!$A:$A,"Photoshoot",data_event_accrual!$B:$B,$AI$3,data_event_accrual!$C:$C,"40-99",data_event_accrual!$E:$E,$AH10),AVERAGEIFS(data_event_accrual!$L:$L,data_event_accrual!$A:$A,"Photoshoot",data_event_accrual!$B:$B,$AI$3,data_event_accrual!$C:$C,"40-99",data_event_accrual!$E:$E,$AH10)),1)),COUNTIF($AX$5:$AX$14,"<="&bal*shr)))} | AP10: {=IF($AH10="","",IF(AO10=0,"{}",LET(m,AO10,s,MMULT(TRANSPOSE((SEQUENCE(10,1,1,1)<=m)*1),VSTACK($H$27:$AB$27,$H$30:$AB$30,$H$33:$AB$33,$H$36:$AB$36,$H$39:$AB$39,$H$42:$AB$42,$H$45:$AB$45,$H$48:$AB$48,$H$51:$AB$51,$H$54:$AB$54)),"{"&TEXTJOIN(", ",TRUE,IF(s>0,$H$24:$AB$24&": "&ROUND(s,2),""))&"}")))} | AQ10: {=IF($AH10="","",LET(bal,SUMIFS(data_event_inst!$N:$N,data_event_inst!$A:$A,"Photoshoot",data_event_inst!$B:$B,$AI$3,data_event_inst!$C:$C,"100+"),shr,MIN(1,IFERROR(CHOOSE(MATCH($AI$2,{"Avg","p25","p50","p75"},0),AVERAGEIFS(data_event_accrual!$I:$I,data_event_accrual!$A:$A,"Photoshoot",data_event_accrual!$B:$B,$AI$3,data_event_accrual!$C:$C,"100+",data_event_accrual!$E:$E,$AH10),AVERAGEIFS(data_event_accrual!$K:$K,data_event_accrual!$A:$A,"Photoshoot",data_event_accrual!$B:$B,$AI$3,data_event_accrual!$C:$C,"100+",data_event_accrual!$E:$E,$AH10),AVERAGEIFS(data_event_accrual!$J:$J,data_event_accrual!$A:$A,"Photoshoot",data_event_accrual!$B:$B,$AI$3,data_event_accrual!$C:$C,"100+",data_event_accrual!$E:$E,$AH10),AVERAGEIFS(data_event_accrual!$L:$L,data_event_accrual!$A:$A,"Photoshoot",data_event_accrual!$B:$B,$AI$3,data_event_accrual!$C:$C,"100+",data_event_accrual!$E:$E,$AH10)),1)),COUNTIF($AX$5:$AX$14,"<="&bal*shr)))} | AR10: {=IF($AH10="","",IF(AQ10=0,"{}",LET(m,AQ10,s,MMULT(TRANSPOSE((SEQUENCE(10,1,1,1)<=m)*1),VSTACK($H$27:$AB$27,$H$30:$AB$30,$H$33:$AB$33,$H$36:$AB$36,$H$39:$AB$39,$H$42:$AB$42,$H$45:$AB$45,$H$48:$AB$48,$H$51:$AB$51,$H$54:$AB$54)),"{"&TEXTJOIN(", ",TRUE,IF(s>0,$H$24:$AB$24&": "&ROUND(s,2),""))&"}")))} | AT10: 6 | AU10: =SUM($F$25:$F30) | AW10: 6 | AX10: 1845
A11: numberOfEndlessLanes | B11: 3 | AH11: =IF(6<=$B$3,6,"") | AI11: {=IF($AH11="","",LET(bal,SUMIFS(data_event_inst!$N:$N,data_event_inst!$A:$A,"Photoshoot",data_event_inst!$B:$B,$AI$3,data_event_inst!$C:$C,"0-9"),shr,MIN(1,IFERROR(CHOOSE(MATCH($AI$2,{"Avg","p25","p50","p75"},0),AVERAGEIFS(data_event_accrual!$I:$I,data_event_accrual!$A:$A,"Photoshoot",data_event_accrual!$B:$B,$AI$3,data_event_accrual!$C:$C,"0-9",data_event_accrual!$E:$E,$AH11),AVERAGEIFS(data_event_accrual!$K:$K,data_event_accrual!$A:$A,"Photoshoot",data_event_accrual!$B:$B,$AI$3,data_event_accrual!$C:$C,"0-9",data_event_accrual!$E:$E,$AH11),AVERAGEIFS(data_event_accrual!$J:$J,data_event_accrual!$A:$A,"Photoshoot",data_event_accrual!$B:$B,$AI$3,data_event_accrual!$C:$C,"0-9",data_event_accrual!$E:$E,$AH11),AVERAGEIFS(data_event_accrual!$L:$L,data_event_accrual!$A:$A,"Photoshoot",data_event_accrual!$B:$B,$AI$3,data_event_accrual!$C:$C,"0-9",data_event_accrual!$E:$E,$AH11)),1)),COUNTIF($AX$5:$AX$14,"<="&bal*shr)))} | AJ11: {=IF($AH11="","",IF(AI11=0,"{}",LET(m,AI11,s,MMULT(TRANSPOSE((SEQUENCE(10,1,1,1)<=m)*1),VSTACK($H$27:$AB$27,$H$30:$AB$30,$H$33:$AB$33,$H$36:$AB$36,$H$39:$AB$39,$H$42:$AB$42,$H$45:$AB$45,$H$48:$AB$48,$H$51:$AB$51,$H$54:$AB$54)),"{"&TEXTJOIN(", ",TRUE,IF(s>0,$H$24:$AB$24&": "&ROUND(s,2),""))&"}")))} | AK11: {=IF($AH11="","",LET(bal,SUMIFS(data_event_inst!$N:$N,data_event_inst!$A:$A,"Photoshoot",data_event_inst!$B:$B,$AI$3,data_event_inst!$C:$C,"10-19"),shr,MIN(1,IFERROR(CHOOSE(MATCH($AI$2,{"Avg","p25","p50","p75"},0),AVERAGEIFS(data_event_accrual!$I:$I,data_event_accrual!$A:$A,"Photoshoot",data_event_accrual!$B:$B,$AI$3,data_event_accrual!$C:$C,"10-19",data_event_accrual!$E:$E,$AH11),AVERAGEIFS(data_event_accrual!$K:$K,data_event_accrual!$A:$A,"Photoshoot",data_event_accrual!$B:$B,$AI$3,data_event_accrual!$C:$C,"10-19",data_event_accrual!$E:$E,$AH11),AVERAGEIFS(data_event_accrual!$J:$J,data_event_accrual!$A:$A,"Photoshoot",data_event_accrual!$B:$B,$AI$3,data_event_accrual!$C:$C,"10-19",data_event_accrual!$E:$E,$AH11),AVERAGEIFS(data_event_accrual!$L:$L,data_event_accrual!$A:$A,"Photoshoot",data_event_accrual!$B:$B,$AI$3,data_event_accrual!$C:$C,"10-19",data_event_accrual!$E:$E,$AH11)),1)),COUNTIF($AX$5:$AX$14,"<="&bal*shr)))} | AL11: {=IF($AH11="","",IF(AK11=0,"{}",LET(m,AK11,s,MMULT(TRANSPOSE((SEQUENCE(10,1,1,1)<=m)*1),VSTACK($H$27:$AB$27,$H$30:$AB$30,$H$33:$AB$33,$H$36:$AB$36,$H$39:$AB$39,$H$42:$AB$42,$H$45:$AB$45,$H$48:$AB$48,$H$51:$AB$51,$H$54:$AB$54)),"{"&TEXTJOIN(", ",TRUE,IF(s>0,$H$24:$AB$24&": "&ROUND(s,2),""))&"}")))} | AM11: {=IF($AH11="","",LET(bal,SUMIFS(data_event_inst!$N:$N,data_event_inst!$A:$A,"Photoshoot",data_event_inst!$B:$B,$AI$3,data_event_inst!$C:$C,"20-39"),shr,MIN(1,IFERROR(CHOOSE(MATCH($AI$2,{"Avg","p25","p50","p75"},0),AVERAGEIFS(data_event_accrual!$I:$I,data_event_accrual!$A:$A,"Photoshoot",data_event_accrual!$B:$B,$AI$3,data_event_accrual!$C:$C,"20-39",data_event_accrual!$E:$E,$AH11),AVERAGEIFS(data_event_accrual!$K:$K,data_event_accrual!$A:$A,"Photoshoot",data_event_accrual!$B:$B,$AI$3,data_event_accrual!$C:$C,"20-39",data_event_accrual!$E:$E,$AH11),AVERAGEIFS(data_event_accrual!$J:$J,data_event_accrual!$A:$A,"Photoshoot",data_event_accrual!$B:$B,$AI$3,data_event_accrual!$C:$C,"20-39",data_event_accrual!$E:$E,$AH11),AVERAGEIFS(data_event_accrual!$L:$L,data_event_accrual!$A:$A,"Photoshoot",data_event_accrual!$B:$B,$AI$3,data_event_accrual!$C:$C,"20-39",data_event_accrual!$E:$E,$AH11)),1)),COUNTIF($AX$5:$AX$14,"<="&bal*shr)))} | AN11: {=IF($AH11="","",IF(AM11=0,"{}",LET(m,AM11,s,MMULT(TRANSPOSE((SEQUENCE(10,1,1,1)<=m)*1),VSTACK($H$27:$AB$27,$H$30:$AB$30,$H$33:$AB$33,$H$36:$AB$36,$H$39:$AB$39,$H$42:$AB$42,$H$45:$AB$45,$H$48:$AB$48,$H$51:$AB$51,$H$54:$AB$54)),"{"&TEXTJOIN(", ",TRUE,IF(s>0,$H$24:$AB$24&": "&ROUND(s,2),""))&"}")))} | AO11: {=IF($AH11="","",LET(bal,SUMIFS(data_event_inst!$N:$N,data_event_inst!$A:$A,"Photoshoot",data_event_inst!$B:$B,$AI$3,data_event_inst!$C:$C,"40-99"),shr,MIN(1,IFERROR(CHOOSE(MATCH($AI$2,{"Avg","p25","p50","p75"},0),AVERAGEIFS(data_event_accrual!$I:$I,data_event_accrual!$A:$A,"Photoshoot",data_event_accrual!$B:$B,$AI$3,data_event_accrual!$C:$C,"40-99",data_event_accrual!$E:$E,$AH11),AVERAGEIFS(data_event_accrual!$K:$K,data_event_accrual!$A:$A,"Photoshoot",data_event_accrual!$B:$B,$AI$3,data_event_accrual!$C:$C,"40-99",data_event_accrual!$E:$E,$AH11),AVERAGEIFS(data_event_accrual!$J:$J,data_event_accrual!$A:$A,"Photoshoot",data_event_accrual!$B:$B,$AI$3,data_event_accrual!$C:$C,"40-99",data_event_accrual!$E:$E,$AH11),AVERAGEIFS(data_event_accrual!$L:$L,data_event_accrual!$A:$A,"Photoshoot",data_event_accrual!$B:$B,$AI$3,data_event_accrual!$C:$C,"40-99",data_event_accrual!$E:$E,$AH11)),1)),COUNTIF($AX$5:$AX$14,"<="&bal*shr)))} | AP11: {=IF($AH11="","",IF(AO11=0,"{}",LET(m,AO11,s,MMULT(TRANSPOSE((SEQUENCE(10,1,1,1)<=m)*1),VSTACK($H$27:$AB$27,$H$30:$AB$30,$H$33:$AB$33,$H$36:$AB$36,$H$39:$AB$39,$H$42:$AB$42,$H$45:$AB$45,$H$48:$AB$48,$H$51:$AB$51,$H$54:$AB$54)),"{"&TEXTJOIN(", ",TRUE,IF(s>0,$H$24:$AB$24&": "&ROUND(s,2),""))&"}")))} | AQ11: {=IF($AH11="","",LET(bal,SUMIFS(data_event_inst!$N:$N,data_event_inst!$A:$A,"Photoshoot",data_event_inst!$B:$B,$AI$3,data_event_inst!$C:$C,"100+"),shr,MIN(1,IFERROR(CHOOSE(MATCH($AI$2,{"Avg","p25","p50","p75"},0),AVERAGEIFS(data_event_accrual!$I:$I,data_event_accrual!$A:$A,"Photoshoot",data_event_accrual!$B:$B,$AI$3,data_event_accrual!$C:$C,"100+",data_event_accrual!$E:$E,$AH11),AVERAGEIFS(data_event_accrual!$K:$K,data_event_accrual!$A:$A,"Photoshoot",data_event_accrual!$B:$B,$AI$3,data_event_accrual!$C:$C,"100+",data_event_accrual!$E:$E,$AH11),AVERAGEIFS(data_event_accrual!$J:$J,data_event_accrual!$A:$A,"Photoshoot",data_event_accrual!$B:$B,$AI$3,data_event_accrual!$C:$C,"100+",data_event_accrual!$E:$E,$AH11),AVERAGEIFS(data_event_accrual!$L:$L,data_event_accrual!$A:$A,"Photoshoot",data_event_accrual!$B:$B,$AI$3,data_event_accrual!$C:$C,"100+",data_event_accrual!$E:$E,$AH11)),1)),COUNTIF($AX$5:$AX$14,"<="&bal*shr)))} | AR11: {=IF($AH11="","",IF(AQ11=0,"{}",LET(m,AQ11,s,MMULT(TRANSPOSE((SEQUENCE(10,1,1,1)<=m)*1),VSTACK($H$27:$AB$27,$H$30:$AB$30,$H$33:$AB$33,$H$36:$AB$36,$H$39:$AB$39,$H$42:$AB$42,$H$45:$AB$45,$H$48:$AB$48,$H$51:$AB$51,$H$54:$AB$54)),"{"&TEXTJOIN(", ",TRUE,IF(s>0,$H$24:$AB$24&": "&ROUND(s,2),""))&"}")))} | AT11: 7 | AU11: =SUM($F$25:$F31) | AW11: 7 | AX11: 2555
A12: endlessRewardsPerLane | B12: 15 | AH12: =IF(7<=$B$3,7,"") | AI12: {=IF($AH12="","",LET(bal,SUMIFS(data_event_inst!$N:$N,data_event_inst!$A:$A,"Photoshoot",data_event_inst!$B:$B,$AI$3,data_event_inst!$C:$C,"0-9"),shr,MIN(1,IFERROR(CHOOSE(MATCH($AI$2,{"Avg","p25","p50","p75"},0),AVERAGEIFS(data_event_accrual!$I:$I,data_event_accrual!$A:$A,"Photoshoot",data_event_accrual!$B:$B,$AI$3,data_event_accrual!$C:$C,"0-9",data_event_accrual!$E:$E,$AH12),AVERAGEIFS(data_event_accrual!$K:$K,data_event_accrual!$A:$A,"Photoshoot",data_event_accrual!$B:$B,$AI$3,data_event_accrual!$C:$C,"0-9",data_event_accrual!$E:$E,$AH12),AVERAGEIFS(data_event_accrual!$J:$J,data_event_accrual!$A:$A,"Photoshoot",data_event_accrual!$B:$B,$AI$3,data_event_accrual!$C:$C,"0-9",data_event_accrual!$E:$E,$AH12),AVERAGEIFS(data_event_accrual!$L:$L,data_event_accrual!$A:$A,"Photoshoot",data_event_accrual!$B:$B,$AI$3,data_event_accrual!$C:$C,"0-9",data_event_accrual!$E:$E,$AH12)),1)),COUNTIF($AX$5:$AX$14,"<="&bal*shr)))} | AJ12: {=IF($AH12="","",IF(AI12=0,"{}",LET(m,AI12,s,MMULT(TRANSPOSE((SEQUENCE(10,1,1,1)<=m)*1),VSTACK($H$27:$AB$27,$H$30:$AB$30,$H$33:$AB$33,$H$36:$AB$36,$H$39:$AB$39,$H$42:$AB$42,$H$45:$AB$45,$H$48:$AB$48,$H$51:$AB$51,$H$54:$AB$54)),"{"&TEXTJOIN(", ",TRUE,IF(s>0,$H$24:$AB$24&": "&ROUND(s,2),""))&"}")))} | AK12: {=IF($AH12="","",LET(bal,SUMIFS(data_event_inst!$N:$N,data_event_inst!$A:$A,"Photoshoot",data_event_inst!$B:$B,$AI$3,data_event_inst!$C:$C,"10-19"),shr,MIN(1,IFERROR(CHOOSE(MATCH($AI$2,{"Avg","p25","p50","p75"},0),AVERAGEIFS(data_event_accrual!$I:$I,data_event_accrual!$A:$A,"Photoshoot",data_event_accrual!$B:$B,$AI$3,data_event_accrual!$C:$C,"10-19",data_event_accrual!$E:$E,$AH12),AVERAGEIFS(data_event_accrual!$K:$K,data_event_accrual!$A:$A,"Photoshoot",data_event_accrual!$B:$B,$AI$3,data_event_accrual!$C:$C,"10-19",data_event_accrual!$E:$E,$AH12),AVERAGEIFS(data_event_accrual!$J:$J,data_event_accrual!$A:$A,"Photoshoot",data_event_accrual!$B:$B,$AI$3,data_event_accrual!$C:$C,"10-19",data_event_accrual!$E:$E,$AH12),AVERAGEIFS(data_event_accrual!$L:$L,data_event_accrual!$A:$A,"Photoshoot",data_event_accrual!$B:$B,$AI$3,data_event_accrual!$C:$C,"10-19",data_event_accrual!$E:$E,$AH12)),1)),COUNTIF($AX$5:$AX$14,"<="&bal*shr)))} | AL12: {=IF($AH12="","",IF(AK12=0,"{}",LET(m,AK12,s,MMULT(TRANSPOSE((SEQUENCE(10,1,1,1)<=m)*1),VSTACK($H$27:$AB$27,$H$30:$AB$30,$H$33:$AB$33,$H$36:$AB$36,$H$39:$AB$39,$H$42:$AB$42,$H$45:$AB$45,$H$48:$AB$48,$H$51:$AB$51,$H$54:$AB$54)),"{"&TEXTJOIN(", ",TRUE,IF(s>0,$H$24:$AB$24&": "&ROUND(s,2),""))&"}")))} | AM12: {=IF($AH12="","",LET(bal,SUMIFS(data_event_inst!$N:$N,data_event_inst!$A:$A,"Photoshoot",data_event_inst!$B:$B,$AI$3,data_event_inst!$C:$C,"20-39"),shr,MIN(1,IFERROR(CHOOSE(MATCH($AI$2,{"Avg","p25","p50","p75"},0),AVERAGEIFS(data_event_accrual!$I:$I,data_event_accrual!$A:$A,"Photoshoot",data_event_accrual!$B:$B,$AI$3,data_event_accrual!$C:$C,"20-39",data_event_accrual!$E:$E,$AH12),AVERAGEIFS(data_event_accrual!$K:$K,data_event_accrual!$A:$A,"Photoshoot",data_event_accrual!$B:$B,$AI$3,data_event_accrual!$C:$C,"20-39",data_event_accrual!$E:$E,$AH12),AVERAGEIFS(data_event_accrual!$J:$J,data_event_accrual!$A:$A,"Photoshoot",data_event_accrual!$B:$B,$AI$3,data_event_accrual!$C:$C,"20-39",data_event_accrual!$E:$E,$AH12),AVERAGEIFS(data_event_accrual!$L:$L,data_event_accrual!$A:$A,"Photoshoot",data_event_accrual!$B:$B,$AI$3,data_event_accrual!$C:$C,"20-39",data_event_accrual!$E:$E,$AH12)),1)),COUNTIF($AX$5:$AX$14,"<="&bal*shr)))} | AN12: {=IF($AH12="","",IF(AM12=0,"{}",LET(m,AM12,s,MMULT(TRANSPOSE((SEQUENCE(10,1,1,1)<=m)*1),VSTACK($H$27:$AB$27,$H$30:$AB$30,$H$33:$AB$33,$H$36:$AB$36,$H$39:$AB$39,$H$42:$AB$42,$H$45:$AB$45,$H$48:$AB$48,$H$51:$AB$51,$H$54:$AB$54)),"{"&TEXTJOIN(", ",TRUE,IF(s>0,$H$24:$AB$24&": "&ROUND(s,2),""))&"}")))} | AO12: {=IF($AH12="","",LET(bal,SUMIFS(data_event_inst!$N:$N,data_event_inst!$A:$A,"Photoshoot",data_event_inst!$B:$B,$AI$3,data_event_inst!$C:$C,"40-99"),shr,MIN(1,IFERROR(CHOOSE(MATCH($AI$2,{"Avg","p25","p50","p75"},0),AVERAGEIFS(data_event_accrual!$I:$I,data_event_accrual!$A:$A,"Photoshoot",data_event_accrual!$B:$B,$AI$3,data_event_accrual!$C:$C,"40-99",data_event_accrual!$E:$E,$AH12),AVERAGEIFS(data_event_accrual!$K:$K,data_event_accrual!$A:$A,"Photoshoot",data_event_accrual!$B:$B,$AI$3,data_event_accrual!$C:$C,"40-99",data_event_accrual!$E:$E,$AH12),AVERAGEIFS(data_event_accrual!$J:$J,data_event_accrual!$A:$A,"Photoshoot",data_event_accrual!$B:$B,$AI$3,data_event_accrual!$C:$C,"40-99",data_event_accrual!$E:$E,$AH12),AVERAGEIFS(data_event_accrual!$L:$L,data_event_accrual!$A:$A,"Photoshoot",data_event_accrual!$B:$B,$AI$3,data_event_accrual!$C:$C,"40-99",data_event_accrual!$E:$E,$AH12)),1)),COUNTIF($AX$5:$AX$14,"<="&bal*shr)))} | AP12: {=IF($AH12="","",IF(AO12=0,"{}",LET(m,AO12,s,MMULT(TRANSPOSE((SEQUENCE(10,1,1,1)<=m)*1),VSTACK($H$27:$AB$27,$H$30:$AB$30,$H$33:$AB$33,$H$36:$AB$36,$H$39:$AB$39,$H$42:$AB$42,$H$45:$AB$45,$H$48:$AB$48,$H$51:$AB$51,$H$54:$AB$54)),"{"&TEXTJOIN(", ",TRUE,IF(s>0,$H$24:$AB$24&": "&ROUND(s,2),""))&"}")))} | AQ12: {=IF($AH12="","",LET(bal,SUMIFS(data_event_inst!$N:$N,data_event_inst!$A:$A,"Photoshoot",data_event_inst!$B:$B,$AI$3,data_event_inst!$C:$C,"100+"),shr,MIN(1,IFERROR(CHOOSE(MATCH($AI$2,{"Avg","p25","p50","p75"},0),AVERAGEIFS(data_event_accrual!$I:$I,data_event_accrual!$A:$A,"Photoshoot",data_event_accrual!$B:$B,$AI$3,data_event_accrual!$C:$C,"100+",data_event_accrual!$E:$E,$AH12),AVERAGEIFS(data_event_accrual!$K:$K,data_event_accrual!$A:$A,"Photoshoot",data_event_accrual!$B:$B,$AI$3,data_event_accrual!$C:$C,"100+",data_event_accrual!$E:$E,$AH12),AVERAGEIFS(data_event_accrual!$J:$J,data_event_accrual!$A:$A,"Photoshoot",data_event_accrual!$B:$B,$AI$3,data_event_accrual!$C:$C,"100+",data_event_accrual!$E:$E,$AH12),AVERAGEIFS(data_event_accrual!$L:$L,data_event_accrual!$A:$A,"Photoshoot",data_event_accrual!$B:$B,$AI$3,data_event_accrual!$C:$C,"100+",data_event_accrual!$E:$E,$AH12)),1)),COUNTIF($AX$5:$AX$14,"<="&bal*shr)))} | AR12: {=IF($AH12="","",IF(AQ12=0,"{}",LET(m,AQ12,s,MMULT(TRANSPOSE((SEQUENCE(10,1,1,1)<=m)*1),VSTACK($H$27:$AB$27,$H$30:$AB$30,$H$33:$AB$33,$H$36:$AB$36,$H$39:$AB$39,$H$42:$AB$42,$H$45:$AB$45,$H$48:$AB$48,$H$51:$AB$51,$H$54:$AB$54)),"{"&TEXTJOIN(", ",TRUE,IF(s>0,$H$24:$AB$24&": "&ROUND(s,2),""))&"}")))} | AT12: 8 | AU12: =SUM($F$25:$F32) | AW12: 8 | AX12: 3415
A13: itemLevelUnlocks (per set) | B13: 0, 1, 1, 1, 1, 1, 1, 1, 1, 1 | AT13: 9 | AU13: =SUM($F$25:$F33) | AW13: 9 | AX13: 4675
AT14: 10 | AU14: =SUM($F$25:$F34) | AW14: 10 | AX14: 6735
A15: Streak Multipliers (first-try win streak → token earn multiplier) | AT15: 11 | AU15: =SUM($F$25:$F35)
A16: Tier | B16: Token Multiplier | AT16: 12 | AU16: =SUM($F$25:$F36) | AW16: GREEDY model: buy each set's reward item (item 3) first + the cheapest fillers needed to unlock the set (col E thresholds). AX = cumulative tokens to COMPLETE the set. _ms = # sets (reward milestones) completed; _reward sums those sets' bonuses. Last-day leftover tokens buy non-reward items (no extra reward).
A17: 1 | B17: 1x | AT17: 13 | AU17: =SUM($F$25:$F37)
A18: 2 | B18: 2x | AT18: 14 | AU18: =SUM($F$25:$F38)
A19: 3 | B19: 4x | AT19: 15 | AU19: =SUM($F$25:$F39)
A20: 4 | B20: 6x | AT20: 16 | AU20: =SUM($F$25:$F40)
A21: 5 | B21: 10x | AT21: 17 | AU21: =SUM($F$25:$F41)
AT22: 18 | AU22: =SUM($F$25:$F42)
A23: Goals and Rewards (30 items × 10 milestone tiers) | AT23: 19 | AU23: =SUM($F$25:$F43)
A24: Item Id | B24: Set # | C24: Set Name | D24: Item name | E24: Items to unlock set (from doc) | F24: itemPrices (tokens) | G24: Items Unlocked | H24: Coins | I24: SPT | J24: SPT x2 | K24: Red | L24: Chuck | M24: Bomb | N24: Slingshot | O24: Shuffle | P24: Comet | Q24: Unlimited Lives | R24: Unlimited Red | S24: Unlimited Chuck | T24: Unlimited Bomb | U24: COOP Token | V24: Avatar | W24: 1-star Dly | X24: 2-star Dly | Y24: 3-star Dly | Z24: 4-star Dly | AA24: 5-star Dly | AB24: 6-star Dly | AT24: 20 | AU24: =SUM($F$25:$F44)
A25: 1 | B25: 1 | C25: Red's Headgear | D25: Headgear 1 | E25: 0 | F25: 80 | G25: =A25 | H25: 0 | I25: 0 | J25: 0 | K25: 0 | L25: 0 | M25: 0 | N25: 0 | O25: 0 | P25: 0 | Q25: 0 | R25: 0 | S25: 0 | T25: 0 | U25: 0 | V25: 0 | W25: 0 | X25: 0 | Y25: 0 | Z25: 0 | AA25: 0 | AB25: 0 | AT25: 21 | AU25: =SUM($F$25:$F45)
A26: 2 | B26: 1 | C26: Red's Headgear | D26: Headgear 2 | E26: 0 | F26: 130 | G26: =A26 | H26: 0 | I26: 0 | J26: 0 | K26: 0 | L26: 0 | M26: 0 | N26: 0 | O26: 0 | P26: 0 | Q26: 0 | R26: 0 | S26: 0 | T26: 0 | U26: 0 | V26: 0 | W26: 0 | X26: 0 | Y26: 0 | Z26: 0 | AA26: 0 | AB26: 0 | AT26: 22 | AU26: =SUM($F$25:$F46)
A27: 3 | B27: 1 | C27: Red's Headgear | D27: Headgear 3 | E27: 0 | F27: 155 | G27: =A27 | H27: 0 | I27: 0 | J27: 0 | K27: 0 | L27: 1 | M27: 0 | N27: 0 | O27: 0 | P27: 0 | Q27: 0 | R27: 0 | S27: 0 | T27: 0 | U27: 0 | V27: 0 | W27: 0 | X27: 0 | Y27: 0 | Z27: 0 | AA27: 0 | AB27: 0 | AT27: 23 | AU27: =SUM($F$25:$F47)
A28: 4 | B28: 2 | C28: Red's Body | D28: Body 1 | E28: 2 | F28: 80 | G28: =A28 | H28: 0 | I28: 0 | J28: 0 | K28: 0 | L28: 0 | M28: 0 | N28: 0 | O28: 0 | P28: 0 | Q28: 0 | R28: 0 | S28: 0 | T28: 0 | U28: 0 | V28: 0 | W28: 0 | X28: 0 | Y28: 0 | Z28: 0 | AA28: 0 | AB28: 0 | AT28: 24 | AU28: =SUM($F$25:$F48)
A29: 5 | B29: 2 | C29: Red's Body | D29: Body 2 | E29: 2 | F29: 130 | G29: =A29 | H29: 0 | I29: 0 | J29: 0 | K29: 0 | L29: 0 | M29: 0 | N29: 0 | O29: 0 | P29: 0 | Q29: 0 | R29: 0 | S29: 0 | T29: 0 | U29: 0 | V29: 0 | W29: 0 | X29: 0 | Y29: 0 | Z29: 0 | AA29: 0 | AB29: 0 | AT29: 25 | AU29: =SUM($F$25:$F49)
A30: 6 | B30: 2 | C30: Red's Body | D30: Body 3 | E30: 2 | F30: 160 | G30: =A30 | H30: 0 | I30: 0 | J30: 0 | K30: 0 | L30: 0 | M30: 0 | N30: 0 | O30: 0 | P30: 0 | Q30: 30 | R30: 0 | S30: 0 | T30: 0 | U30: 0 | V30: 0 | W30: 0 | X30: 0 | Y30: 0 | Z30: 0 | AA30: 0 | AB30: 0 | AT30: 26 | AU30: =SUM($F$25:$F50)
A31: 7 | B31: 3 | C31: Chuck's Headgear | D31: Headgear 1 | E31: 4 | F31: 80 | G31: =A31 | H31: 0 | I31: 0 | J31: 0 | K31: 0 | L31: 0 | M31: 0 | N31: 0 | O31: 0 | P31: 0 | Q31: 0 | R31: 0 | S31: 0 | T31: 0 | U31: 0 | V31: 0 | W31: 0 | X31: 0 | Y31: 0 | Z31: 0 | AA31: 0 | AB31: 0 | AT31: 27 | AU31: =SUM($F$25:$F51)
A32: 8 | B32: 3 | C32: Chuck's Headgear | D32: Headgear 2 | E32: 4 | F32: 135 | G32: =A32 | H32: 0 | I32: 0 | J32: 0 | K32: 0 | L32: 0 | M32: 0 | N32: 0 | O32: 0 | P32: 0 | Q32: 0 | R32: 0 | S32: 0 | T32: 0 | U32: 0 | V32: 0 | W32: 0 | X32: 0 | Y32: 0 | Z32: 0 | AA32: 0 | AB32: 0 | AT32: 28 | AU32: =SUM($F$25:$F52)
A33: 9 | B33: 3 | C33: Chuck's Headgear | D33: Headgear 3 | E33: 4 | F33: 165 | G33: =A33 | H33: 25 | I33: 0 | J33: 0 | K33: 0 | L33: 0 | M33: 0 | N33: 0 | O33: 0 | P33: 0 | Q33: 0 | R33: 0 | S33: 0 | T33: 0 | U33: 0 | V33: 0 | W33: 0 | X33: 0 | Y33: 0 | Z33: 0 | AA33: 0 | AB33: 0 | AT33: 29 | AU33: =SUM($F$25:$F53)
A34: 10 | B34: 4 | C34: Bomb's Headgear | D34: Headgear 1 | E34: 6 | F34: 165 | G34: =A34 | H34: 0 | I34: 0 | J34: 0 | K34: 0 | L34: 0 | M34: 0 | N34: 0 | O34: 0 | P34: 0 | Q34: 0 | R34: 0 | S34: 0 | T34: 0 | U34: 0 | V34: 0 | W34: 0 | X34: 0 | Y34: 0 | Z34: 0 | AA34: 0 | AB34: 0 | AT34: 30 | AU34: =SUM($F$25:$F54)
A35: 11 | B35: 4 | C35: Bomb's Headgear | D35: Headgear 2 | E35: 6 | F35: 230 | G35: =A35 | H35: 0 | I35: 0 | J35: 0 | K35: 0 | L35: 0 | M35: 0 | N35: 0 | O35: 0 | P35: 0 | Q35: 0 | R35: 0 | S35: 0 | T35: 0 | U35: 0 | V35: 0 | W35: 0 | X35: 0 | Y35: 0 | Z35: 0 | AA35: 0 | AB35: 0
A36: 12 | B36: 4 | C36: Bomb's Headgear | D36: Headgear 3 | E36: 6 | F36: 265 | G36: =A36 | H36: 0 | I36: 0 | J36: 0 | K36: 0 | L36: 0 | M36: 0 | N36: 0 | O36: 0 | P36: 0 | Q36: 30 | R36: 15 | S36: 0 | T36: 0 | U36: 0 | V36: 0 | W36: 0 | X36: 0 | Y36: 0 | Z36: 0 | AA36: 0 | AB36: 0 | AT36: simplified: items bought sequentially in item-id order (choice ignored)
A37: 13 | B37: 5 | C37: Chuck's Body | D37: Body 1 | E37: 8 | F37: 180 | G37: =A37 | H37: 0 | I37: 0 | J37: 0 | K37: 0 | L37: 0 | M37: 0 | N37: 0 | O37: 0 | P37: 0 | Q37: 0 | R37: 0 | S37: 0 | T37: 0 | U37: 0 | V37: 0 | W37: 0 | X37: 0 | Y37: 0 | Z37: 0 | AA37: 0 | AB37: 0
A38: 14 | B38: 5 | C38: Chuck's Body | D38: Body 2 | E38: 8 | F38: 250 | G38: =A38 | H38: 0 | I38: 0 | J38: 0 | K38: 0 | L38: 0 | M38: 0 | N38: 0 | O38: 0 | P38: 0 | Q38: 0 | R38: 0 | S38: 0 | T38: 0 | U38: 0 | V38: 0 | W38: 0 | X38: 0 | Y38: 0 | Z38: 0 | AA38: 0 | AB38: 0
A39: 15 | B39: 5 | C39: Chuck's Body | D39: Body 3 | E39: 8 | F39: 300 | G39: =A39 | H39: 0 | I39: 0 | J39: 0 | K39: 1 | L39: 0 | M39: 0 | N39: 0 | O39: 0 | P39: 0 | Q39: 0 | R39: 0 | S39: 0 | T39: 0 | U39: 0 | V39: 0 | W39: 0 | X39: 0 | Y39: 0 | Z39: 0 | AA39: 0 | AB39: 0
A40: 16 | B40: 6 | C40: Bomb's Body | D40: Body 1 | E40: 10 | F40: 180 | G40: =A40 | H40: 0 | I40: 0 | J40: 0 | K40: 0 | L40: 0 | M40: 0 | N40: 0 | O40: 0 | P40: 0 | Q40: 0 | R40: 0 | S40: 0 | T40: 0 | U40: 0 | V40: 0 | W40: 0 | X40: 0 | Y40: 0 | Z40: 0 | AA40: 0 | AB40: 0
...
