Workbook

Sheet Sim Per Segment
A1: RAINBOW MAKER - SIM PER SEGMENT (0 players excluded)
A3: ◆ 3-DAY MILESTONE EVENT
B4: ◄ CURRENT (actuals: data + calc) ► | P4: ◄ % Players Reaching Milestone M1–M30 (data) ► | AU4: ◄ SIMULATED (Milestone Event: sim + calc) ►
A5: Segment | B5: avg levels (data) | C5: matches/level (data) | D5: matchables p50 (data) | E5: current gain (data) | F5: saga old (data) | G5: daily old (data) | H5: Hatchling Hideaway Gain (data) | I5: Bomb's Ballet Gain (data) | J5: Photoshoot Gain (data) | K5: Jigsaw Gain (data) | L5: Low Intensity Events Avg (calc) | M5: other gain (calc) | N5: spend (data) | O5: net (calc) | P5: M1 | Q5: M2 | R5: M3 | S5: M4 | T5: M5 | U5: M6 | V5: M7 | W5: M8 | X5: M9 | Y5: M10 | Z5: M11 | AA5: M12 | AB5: M13 | AC5: M14 | AD5: M15 | AE5: M16 | AF5: M17 | AG5: M18 | AH5: M19 | AI5: M20 | AJ5: M21 | AK5: M22 | AL5: M23 | AM5: M24 | AN5: M25 | AO5: M26 | AP5: M27 | AQ5: M28 | AR5: M29 | AS5: M30 | AU5: saga new (sim) | AV5: daily new (sim) | AW5: Milestone Coins (sim) | AX5: sim gain on-top (calc) | AY5: sim gain without (calc) | AZ5: spend same (data) | BA5: net on-top (calc) | BB5: Δ | BC5: net without (calc) | BD5: Δ
A6: NONPAYER
A7: 0-9 | B7: =data_raw_3_day!J3 -> 11.29 | C7: =data_raw_3_day!L3 -> 577.43 | D7: =data_raw_3_day!G3 -> 3935 | E7: =data_raw_3_day!M3 -> 101.63 | F7: =data_raw_3_day!N3 -> 8.12 | G7: =data_raw_3_day!O3 -> 33.72 | H7: =data_raw_3_day!S3 -> 11.73 | I7: =data_raw_3_day!T3 -> 25 | J7: =data_raw_3_day!U3 -> 25 | K7: =data_raw_3_day!V3 -> 29.51 | L7: =AVERAGE(H7:K7) -> 22.81 | M7: =E7-F7-G7-L7 -> 36.98 | N7: =data_raw_3_day!Q3 -> 93.33 | O7: =E7-N7 -> 8.3 | P7: =data_raw_3_day!W3 -> 0.9996 | Q7: =data_raw_3_day!X3 -> 0.9656 | R7: =data_raw_3_day!Y3 -> 0.7836 | S7: =data_raw_3_day!Z3 -> 0.7468 | T7: =data_raw_3_day!AA3 -> 0.6836 | U7: =data_raw_3_day!AB3 -> 0.51 | V7: =data_raw_3_day!AC3 -> 0.4677 | W7: =data_raw_3_day!AD3 -> 0.3916 | ... AS7: =data_raw_3_day!AZ3 -> 0 | AU7: =saga_progression_new!$C$17*B7 -> 6.774 | AV7: =daily_rewards_new!$B$13*data_raw_3_day!K3 -> 33.057143 | AW7: {=SUMPRODUCT($P7:$AS7,TRANSPOSE(milestone_3day_new!$E$4:$E$33))} -> 16.5145 | AX7: =M7+L7+AU7+AV7+AW7 -> 116.13564 | AY7: =M7+AU7+AV7+AW7 -> 93.325643 | AZ7: =N7 -> 93.33 | BA7: =AX7-AZ7 -> 22.805643 | BB7: =BA7-O7 -> 14.505643 | BC7: =AY7-AZ7 -> -0.0043571429 | BD7: =BC7-O7 -> -8.3043571
A8: 10-19 | B8: =data_raw_3_day!J4 -> 33.65 | C8: =data_raw_3_day!L4 -> 582.7 | D8: =data_raw_3_day!G4 -> 15214 | E8: =data_raw_3_day!M4 -> 205.8 | F8: =data_raw_3_day!N4 -> 22.46 | G8: =data_raw_3_day!O4 -> 37.43 | H8: =data_raw_3_day!S4 -> 12.42 | I8: =data_raw_3_day!T4 -> 25.67 | J8: =data_raw_3_day!U4 -> 25 | K8: =data_raw_3_day!V4 -> 34.59 | L8: =AVERAGE(H8:K8) -> 24.42 | M8: =E8-F8-G8-L8 -> 121.49 | N8: =data_raw_3_day!Q4 -> 198.92 | O8: =E8-N8 -> 6.88 | P8: =data_raw_3_day!W4 -> 1 | Q8: =data_raw_3_day!X4 -> 0.9963 | R8: =data_raw_3_day!Y4 -> 0.977 | S8: =data_raw_3_day!Z4 -> 0.9711 | T8: =data_raw_3_day!AA4 -> 0.9609 | U8: =data_raw_3_day!AB4 -> 0.925 | V8: =data_raw_3_day!AC4 -> 0.9104 | W8: =data_raw_3_day!AD4 -> 0.8728 | ... AS8: =data_raw_3_day!AZ4 -> 0 | AU8: =saga_progression_new!$C$17*B8 -> 20.19 | AV8: =daily_rewards_new!$B$13*data_raw_3_day!K4 -> 38.814286 | AW8: {=SUMPRODUCT($P8:$AS8,TRANSPOSE(milestone_3day_new!$E$4:$E$33))} -> 40.399 | AX8: =M8+L8+AU8+AV8+AW8 -> 245.31329 | AY8: =M8+AU8+AV8+AW8 -> 220.89329 | AZ8: =N8 -> 198.92 | BA8: =AX8-AZ8 -> 46.393286 | BB8: =BA8-O8 -> 39.513286 | BC8: =AY8-AZ8 -> 21.973286 | BD8: =BC8-O8 -> 15.093286
A9: 20-39 | B9: =data_raw_3_day!J5 -> 66.04 | C9: =data_raw_3_day!L5 -> 569.72 | D9: =data_raw_3_day!G5 -> 30450 | E9: =data_raw_3_day!M5 -> 364.92 | F9: =data_raw_3_day!N5 -> 44.32 | G9: =data_raw_3_day!O5 -> 38.34 | H9: =data_raw_3_day!S5 -> 21.89 | I9: =data_raw_3_day!T5 -> 26.12 | J9: =data_raw_3_day!U5 -> 25 | K9: =data_raw_3_day!V5 -> 35.31 | L9: =AVERAGE(H9:K9) -> 27.08 | M9: =E9-F9-G9-L9 -> 255.18 | N9: =data_raw_3_day!Q5 -> 353.37 | O9: =E9-N9 -> 11.55 | P9: =data_raw_3_day!W5 -> 1 | Q9: =data_raw_3_day!X5 -> 0.9983 | R9: =data_raw_3_day!Y5 -> 0.988 | S9: =data_raw_3_day!Z5 -> 0.9856 | T9: =data_raw_3_day!AA5 -> 0.9802 | U9: =data_raw_3_day!AB5 -> 0.9612 | V9: =data_raw_3_day!AC5 -> 0.9559 | W9: =data_raw_3_day!AD5 -> 0.9453 | ... AS9: =data_raw_3_day!AZ5 -> 0.0006 | AU9: =saga_progression_new!$C$17*B9 -> 39.624 | AV9: =daily_rewards_new!$B$13*data_raw_3_day!K5 -> 40.671429 | AW9: {=SUMPRODUCT($P9:$AS9,TRANSPOSE(milestone_3day_new!$E$4:$E$33))} -> 61.0325 | AX9: =M9+L9+AU9+AV9+AW9 -> 423.58793 | AY9: =M9+AU9+AV9+AW9 -> 396.50793 | AZ9: =N9 -> 353.37 | BA9: =AX9-AZ9 -> 70.217929 | BB9: =BA9-O9 -> 58.667929 | BC9: =AY9-AZ9 -> 43.137929 | BD9: =BC9-O9 -> 31.587929
A10: 40-99 | B10: =data_raw_3_day!J6 -> 141.77 | C10: =data_raw_3_day!L6 -> 544.31 | D10: =data_raw_3_day!G6 -> 67452 | E10: =data_raw_3_day!M6 -> 700.96 | F10: =data_raw_3_day!N6 -> 93.71 | G10: =data_raw_3_day!O6 -> 40.53 | H10: =data_raw_3_day!S6 -> 40.46 | I10: =data_raw_3_day!T6 -> 28.74 | J10: =data_raw_3_day!U6 -> 27.78 | K10: =data_raw_3_day!V6 -> 38.74 | L10: =AVERAGE(H10:K10) -> 33.93 | M10: =E10-F10-G10-L10 -> 532.79 | N10: =data_raw_3_day!Q6 -> 711.54 | O10: =E10-N10 -> -10.58 | P10: =data_raw_3_day!W6 -> 1 | Q10: =data_raw_3_day!X6 -> 0.9993 | R10: =data_raw_3_day!Y6 -> 0.9941 | S10: =data_raw_3_day!Z6 -> 0.9929 | T10: =data_raw_3_day!AA6 -> 0.9904 | U10: =data_raw_3_day!AB6 -> 0.9847 | V10: =data_raw_3_day!AC6 -> 0.9835 | W10: =data_raw_3_day!AD6 -> 0.9787 | ... AS10: =data_raw_3_day!AZ6 -> 0.0031 | AU10: =saga_progression_new!$C$17*B10 -> 85.062 | AV10: =daily_rewards_new!$B$13*data_raw_3_day!K6 -> 43.828571 | AW10: {=SUMPRODUCT($P10:$AS10,TRANSPOSE(milestone_3day_new!$E$4:$E$33))} -> 103.6015 | AX10: =M10+L10+AU10+AV10+AW10 -> 799.21207 | AY10: =M10+AU10+AV10+AW10 -> 765.28207 | AZ10: =N10 -> 711.54 | BA10: =AX10-AZ10 -> 87.672071 | BB10: =BA10-O10 -> 98.252071 | BC10: =AY10-AZ10 -> 53.742071 | BD10: =BC10-O10 -> 64.322071
A11: 100+ | B11: =data_raw_3_day!J7 -> 282.47 | C11: =data_raw_3_day!L7 -> 510.96 | D11: =data_raw_3_day!G7 -> 127482 | E11: =data_raw_3_day!M7 -> 1335.1 | F11: =data_raw_3_day!N7 -> 239.81 | G11: =data_raw_3_day!O7 -> 48.8 | H11: =data_raw_3_day!S7 -> 54.96 | I11: =data_raw_3_day!T7 -> 38.97 | J11: =data_raw_3_day!U7 -> 25 | K11: =data_raw_3_day!V7 -> 45.83 | L11: =AVERAGE(H11:K11) -> 41.19 | M11: =E11-F11-G11-L11 -> 1005.3 | N11: =data_raw_3_day!Q7 -> 1425.63 | O11: =E11-N11 -> -90.53 | P11: =data_raw_3_day!W7 -> 1 | Q11: =data_raw_3_day!X7 -> 0.9986 | R11: =data_raw_3_day!Y7 -> 0.9973 | S11: =data_raw_3_day!Z7 -> 0.9959 | T11: =data_raw_3_day!AA7 -> 0.9959 | U11: =data_raw_3_day!AB7 -> 0.9945 | V11: =data_raw_3_day!AC7 -> 0.9945 | W11: =data_raw_3_day!AD7 -> 0.9945 | ... AS11: =data_raw_3_day!AZ7 -> 0.0247 | AU11: =saga_progression_new!$C$17*B11 -> 169.482 | AV11: =daily_rewards_new!$B$13*data_raw_3_day!K7 -> 40.485714 | AW11: {=SUMPRODUCT($P11:$AS11,TRANSPOSE(milestone_3day_new!$E$4:$E$33))} -> 213.0715 | AX11: =M11+L11+AU11+AV11+AW11 -> 1469.5292 | AY11: =M11+AU11+AV11+AW11 -> 1428.3392 | AZ11: =N11 -> 1425.63 | BA11: =AX11-AZ11 -> 43.899214 | BB11: =BA11-O11 -> 134.42921 | BC11: =AY11-AZ11 -> 2.7092143 | BD11: =BC11-O11 -> 93.239214
A12: PAYER
A13: 0-9 | B13: =data_raw_3_day!J9 -> 11.67 | C13: =data_raw_3_day!L9 -> 584.05 | D13: =data_raw_3_day!G9 -> 4410 | E13: =data_raw_3_day!M9 -> 145.82 | F13: =data_raw_3_day!N9 -> 7.72 | G13: =data_raw_3_day!O9 -> 36.23 | H13: =data_raw_3_day!S9 -> 11.31 | I13: =data_raw_3_day!T9 -> 25 | J13: =data_raw_3_day!U9 -> 25 | K13: =data_raw_3_day!V9 -> 34.87 | L13: =AVERAGE(H13:K13) -> 24.045 | M13: =E13-F13-G13-L13 -> 77.825 | N13: =data_raw_3_day!Q9 -> 137.93 | O13: =E13-N13 -> 7.89 | P13: =data_raw_3_day!W9 -> 0.9999 | Q13: =data_raw_3_day!X9 -> 0.9783 | R13: =data_raw_3_day!Y9 -> 0.8162 | S13: =data_raw_3_day!Z9 -> 0.7801 | T13: =data_raw_3_day!AA9 -> 0.7201 | U13: =data_raw_3_day!AB9 -> 0.5503 | V13: =data_raw_3_day!AC9 -> 0.5071 | W13: =data_raw_3_day!AD9 -> 0.4298 | ... AS13: =data_raw_3_day!AZ9 -> 0 | AT13: ⭐ | AU13: =saga_progression_new!$C$17*B13 -> 7.002 | AV13: =daily_rewards_new!$B$13*data_raw_3_day!K9 -> 35.285714 | AW13: {=SUMPRODUCT($P13:$AS13,TRANSPOSE(milestone_3day_new!$E$4:$E$33))} -> 17.063 | AX13: =M13+L13+AU13+AV13+AW13 -> 161.22071 | AY13: =M13+AU13+AV13+AW13 -> 137.17571 | AZ13: =N13 -> 137.93 | BA13: =AX13-AZ13 -> 23.290714 | BB13: =BA13-O13 -> 15.400714 | BC13: =AY13-AZ13 -> -0.75428571 | BD13: =BC13-O13 -> -8.6442857
A14: 10-19 | B14: =data_raw_3_day!J10 -> 33.64 | C14: =data_raw_3_day!L10 -> 584.56 | D14: =data_raw_3_day!G10 -> 15870 | E14: =data_raw_3_day!M10 -> 352.7 | F14: =data_raw_3_day!N10 -> 21.87 | G14: =data_raw_3_day!O10 -> 37.72 | H14: =data_raw_3_day!S10 -> 12.17 | I14: =data_raw_3_day!T10 -> 26.01 | J14: =data_raw_3_day!U10 -> 50 | K14: =data_raw_3_day!V10 -> 34.08 | L14: =AVERAGE(H14:K14) -> 30.565 | M14: =E14-F14-G14-L14 -> 262.545 | N14: =data_raw_3_day!Q10 -> 357.26 | O14: =E14-N14 -> -4.56 | P14: =data_raw_3_day!W10 -> 1 | Q14: =data_raw_3_day!X10 -> 0.9967 | R14: =data_raw_3_day!Y10 -> 0.9736 | S14: =data_raw_3_day!Z10 -> 0.9674 | T14: =data_raw_3_day!AA10 -> 0.9557 | U14: =data_raw_3_day!AB10 -> 0.9209 | V14: =data_raw_3_day!AC10 -> 0.9074 | W14: =data_raw_3_day!AD10 -> 0.8817 | ... AS14: =data_raw_3_day!AZ10 -> 0 | AT14: ⭐ | AU14: =saga_progression_new!$C$17*B14 -> 20.184 | AV14: =daily_rewards_new!$B$13*data_raw_3_day!K10 -> 39.371429 | AW14: {=SUMPRODUCT($P14:$AS14,TRANSPOSE(milestone_3day_new!$E$4:$E$33))} -> 41.174 | AX14: =M14+L14+AU14+AV14+AW14 -> 393.83943 | AY14: =M14+AU14+AV14+AW14 -> 363.27443 | AZ14: =N14 -> 357.26 | BA14: =AX14-AZ14 -> 36.579429 | BB14: =BA14-O14 -> 41.139429 | BC14: =AY14-AZ14 -> 6.0144286 | BD14: =BC14-O14 -> 10.574429
A15: 20-39 | B15: =data_raw_3_day!J11 -> 63.87 | C15: =data_raw_3_day!L11 -> 583.77 | D15: =data_raw_3_day!G11 -> 30740 | E15: =data_raw_3_day!M11 -> 701 | F15: =data_raw_3_day!N11 -> 41.5 | G15: =data_raw_3_day!O11 -> 35.43 | H15: =data_raw_3_day!S11 -> 20.24 | I15: =data_raw_3_day!T11 -> 26.08 | J15: =data_raw_3_day!U11 -> 31.25 | K15: =data_raw_3_day!V11 -> 32.95 | L15: =AVERAGE(H15:K15) -> 27.63 | M15: =E15-F15-G15-L15 -> 596.44 | N15: =data_raw_3_day!Q11 -> 710.78 | O15: =E15-N15 -> -9.78 | P15: =data_raw_3_day!W11 -> 1 | Q15: =data_raw_3_day!X11 -> 0.9983 | R15: =data_raw_3_day!Y11 -> 0.9858 | S15: =data_raw_3_day!Z11 -> 0.9831 | T15: =data_raw_3_day!AA11 -> 0.9788 | U15: =data_raw_3_day!AB11 -> 0.9637 | V15: =data_raw_3_day!AC11 -> 0.9604 | W15: =data_raw_3_day!AD11 -> 0.9505 | ... AS15: =data_raw_3_day!AZ11 -> 0.0002 | AT15: ⭐ | AU15: =saga_progression_new!$C$17*B15 -> 38.322 | AV15: =daily_rewards_new!$B$13*data_raw_3_day!K11 -> 39.742857 | AW15: {=SUMPRODUCT($P15:$AS15,TRANSPOSE(milestone_3day_new!$E$4:$E$33))} -> 60.8405 | AX15: =M15+L15+AU15+AV15+AW15 -> 762.97536 | AY15: =M15+AU15+AV15+AW15 -> 735.34536 | AZ15: =N15 -> 710.78 | BA15: =AX15-AZ15 -> 52.195357 | BB15: =BA15-O15 -> 61.975357 | BC15: =AY15-AZ15 -> 24.565357 | BD15: =BC15-O15 -> 34.345357
A16: 40-99 | B16: =data_raw_3_day!J12 -> 134.79 | C16: =data_raw_3_day!L12 -> 576.51 | D16: =data_raw_3_day!G12 -> 65920 | E16: =data_raw_3_day!M12 -> 1450.14 | F16: =data_raw_3_day!N12 -> 84.71 | G16: =data_raw_3_day!O12 -> 35.25 | H16: =data_raw_3_day!S12 -> 35.66 | I16: =data_raw_3_day!T12 -> 28.6 | J16: =data_raw_3_day!U12 -> 25 | K16: =data_raw_3_day!V12 -> 43 | L16: =AVERAGE(H16:K16) -> 33.065 | M16: =E16-F16-G16-L16 -> 1297.115 | N16: =data_raw_3_day!Q12 -> 1498.7 | O16: =E16-N16 -> -48.56 | P16: =data_raw_3_day!W12 -> 1 | Q16: =data_raw_3_day!X12 -> 0.9992 | R16: =data_raw_3_day!Y12 -> 0.9918 | S16: =data_raw_3_day!Z12 -> 0.9906 | T16: =data_raw_3_day!AA12 -> 0.9881 | U16: =data_raw_3_day!AB12 -> 0.9832 | V16: =data_raw_3_day!AC12 -> 0.9807 | W16: =data_raw_3_day!AD12 -> 0.9741 | ... AS16: =data_raw_3_day!AZ12 -> 0.0053 | AT16: ⭐ | AU16: =saga_progression_new!$C$17*B16 -> 80.874 | AV16: =daily_rewards_new!$B$13*data_raw_3_day!K12 -> 41.414286 | AW16: {=SUMPRODUCT($P16:$AS16,TRANSPOSE(milestone_3day_new!$E$4:$E$33))} -> 107.3695 | AX16: =M16+L16+AU16+AV16+AW16 -> 1559.8378 | AY16: =M16+AU16+AV16+AW16 -> 1526.7728 | AZ16: =N16 -> 1498.7 | BA16: =AX16-AZ16 -> 61.137786 | BB16: =BA16-O16 -> 109.69779 | BC16: =AY16-AZ16 -> 28.072786 | BD16: =BC16-O16 -> 76.632786
A17: 100+ | B17: =data_raw_3_day!J13 -> 282.69 | C17: =data_raw_3_day!L13 -> 557.8 | D17: =data_raw_3_day!G13 -> 138432 | E17: =data_raw_3_day!M13 -> 3204.37 | F17: =data_raw_3_day!N13 -> 205.58 | G17: =data_raw_3_day!O13 -> 44.26 | H17: =data_raw_3_day!S13 -> 53.04 | I17: =data_raw_3_day!T13 -> 39.29 | J17: =data_raw_3_day!U13 -> 25 | K17: =data_raw_3_day!V13 -> 50 | L17: =AVERAGE(H17:K17) -> 41.8325 | M17: =E17-F17-G17-L17 -> 2912.6975 | N17: =data_raw_3_day!Q13 -> 3249.47 | O17: =E17-N17 -> -45.1 | P17: =data_raw_3_day!W13 -> 1 | Q17: =data_raw_3_day!X13 -> 1 | R17: =data_raw_3_day!Y13 -> 1 | S17: =data_raw_3_day!Z13 -> 1 | T17: =data_raw_3_day!AA13 -> 1 | U17: =data_raw_3_day!AB13 -> 0.9961 | V17: =data_raw_3_day!AC13 -> 0.9922 | W17: =data_raw_3_day!AD13 -> 0.9922 | ... AS17: =data_raw_3_day!AZ13 -> 0.0581 | AT17: ⭐ | AU17: =saga_progression_new!$C$17*B17 -> 169.614 | AV17: =daily_rewards_new!$B$13*data_raw_3_day!K13 -> 39.185714 | AW17: {=SUMPRODUCT($P17:$AS17,TRANSPOSE(milestone_3day_new!$E$4:$E$33))} -> 268.1205 | AX17: =M17+L17+AU17+AV17+AW17 -> 3431.4502 | AY17: =M17+AU17+AV17+AW17 -> 3389.6177 | AZ17: =N17 -> 3249.47 | BA17: =AX17-AZ17 -> 181.98021 | BB17: =BA17-O17 -> 227.08021 | BC17: =AY17-AZ17 -> 140.14771 | BD17: =BC17-O17 -> 185.24771
A21: ◆ 4-DAY MILESTONE EVENT
B22: ◄ CURRENT (actuals: data + calc) ► | P22: ◄ % Players Reaching Milestone M1–M30 (data) ► | AU22: ◄ SIMULATED (Milestone Event: sim + calc) ►
A23: Segment | B23: avg levels (data) | C23: matches/level (data) | D23: matchables p50 (data) | E23: current gain (data) | F23: saga old (data) | G23: daily old (data) | H23: Hatchling Hideaway Gain (data) | I23: Bomb's Ballet Gain (data) | J23: Photoshoot Gain (data) | K23: Jigsaw Gain (data) | L23: Low Intensity Events Avg (calc) | M23: other gain (calc) | N23: spend (data) | O23: net (calc) | P23: M1 | Q23: M2 | R23: M3 | S23: M4 | T23: M5 | U23: M6 | V23: M7 | W23: M8 | X23: M9 | Y23: M10 | Z23: M11 | AA23: M12 | AB23: M13 | AC23: M14 | AD23: M15 | AE23: M16 | AF23: M17 | AG23: M18 | AH23: M19 | AI23: M20 | AJ23: M21 | AK23: M22 | AL23: M23 | AM23: M24 | AN23: M25 | AO23: M26 | AP23: M27 | AQ23: M28 | AR23: M29 | AS23: M30 | AU23: saga new (sim) | AV23: daily new (sim) | AW23: Milestone Coins (sim) | AX23: sim gain on-top (calc) | AY23: sim gain without (calc) | AZ23: spend same (data) | BA23: net on-top (calc) | BB23: Δ | BC23: net without (calc) | BD23: Δ
A24: NONPAYER
A25: 0-9 | B25: =data_raw_4_day!J3 -> 13.69 | C25: =data_raw_4_day!L3 -> 577.4 | D25: =data_raw_4_day!G3 -> 4553 | E25: =data_raw_4_day!M3 -> 126.92 | F25: =data_raw_4_day!N3 -> 9.92 | G25: =data_raw_4_day!O3 -> 41.77 | H25: =data_raw_4_day!S3 -> 11.78 | I25: =data_raw_4_day!T3 -> 25 | J25: =data_raw_4_day!U3 -> 25 | K25: =data_raw_4_day!V3 -> 33.52 | L25: =AVERAGE(H25:K25) -> 23.825 | M25: =E25-F25-G25-L25 -> 51.405 | N25: =data_raw_4_day!Q3 -> 112.49 | O25: =E25-N25 -> 14.43 | P25: =data_raw_4_day!W3 -> 0.9995 | Q25: =data_raw_4_day!X3 -> 0.9661 | R25: =data_raw_4_day!Y3 -> 0.8038 | S25: =data_raw_4_day!Z3 -> 0.7707 | T25: =data_raw_4_day!AA3 -> 0.7149 | U25: =data_raw_4_day!AB3 -> 0.5559 | V25: =data_raw_4_day!AC3 -> 0.5168 | W25: =data_raw_4_day!AD3 -> 0.4472 | ... AS25: =data_raw_4_day!AZ3 -> 0 | AU25: =saga_progression_new!$C$17*B25 -> 8.214 | AV25: =daily_rewards_new!$B$13*data_raw_4_day!K3 -> 39.557143 | AW25: {=SUMPRODUCT($P25:$AS25,TRANSPOSE(milestone_4day_new!$E$4:$E$33))} -> 19.2455 | AX25: =M25+L25+AU25+AV25+AW25 -> 142.24664 | AY25: =M25+AU25+AV25+AW25 -> 118.42164 | AZ25: =N25 -> 112.49 | BA25: =AX25-AZ25 -> 29.756643 | BB25: =BA25-O25 -> 15.326643 | BC25: =AY25-AZ25 -> 5.9316429 | BD25: =BC25-O25 -> -8.4983571
A26: 10-19 | B26: =data_raw_4_day!J4 -> 42.06 | C26: =data_raw_4_day!L4 -> 582.27 | D26: =data_raw_4_day!G4 -> 19134 | E26: =data_raw_4_day!M4 -> 257.7 | F26: =data_raw_4_day!N4 -> 27.86 | G26: =data_raw_4_day!O4 -> 46.94 | H26: =data_raw_4_day!S4 -> 12.29 | I26: =data_raw_4_day!T4 -> 25.67 | J26: =data_raw_4_day!U4 -> 25 | K26: =data_raw_4_day!V4 -> 33.17 | L26: =AVERAGE(H26:K26) -> 24.0325 | M26: =E26-F26-G26-L26 -> 158.8675 | N26: =data_raw_4_day!Q4 -> 244.11 | O26: =E26-N26 -> 13.59 | P26: =data_raw_4_day!W4 -> 1 | Q26: =data_raw_4_day!X4 -> 0.9972 | R26: =data_raw_4_day!Y4 -> 0.9838 | S26: =data_raw_4_day!Z4 -> 0.9796 | T26: =data_raw_4_day!AA4 -> 0.9729 | U26: =data_raw_4_day!AB4 -> 0.9474 | V26: =data_raw_4_day!AC4 -> 0.9375 | W26: =data_raw_4_day!AD4 -> 0.9085 | ... AS26: =data_raw_4_day!AZ4 -> 0.0001 | AU26: =saga_progression_new!$C$17*B26 -> 25.236 | AV26: =daily_rewards_new!$B$13*data_raw_4_day!K4 -> 48.1 | AW26: {=SUMPRODUCT($P26:$AS26,TRANSPOSE(milestone_4day_new!$E$4:$E$33))} -> 46.81 | AX26: =M26+L26+AU26+AV26+AW26 -> 303.046 | AY26: =M26+AU26+AV26+AW26 -> 279.0135 | AZ26: =N26 -> 244.11 | BA26: =AX26-AZ26 -> 58.936 | BB26: =BA26-O26 -> 45.346 | BC26: =AY26-AZ26 -> 34.9035 | BD26: =BC26-O26 -> 21.3135
A27: 20-39 | B27: =data_raw_4_day!J5 -> 83.17 | C27: =data_raw_4_day!L5 -> 567.3 | D27: =data_raw_4_day!G5 -> 38620 | E27: =data_raw_4_day!M5 -> 446.17 | F27: =data_raw_4_day!N5 -> 55.42 | G27: =data_raw_4_day!O5 -> 47.27 | H27: =data_raw_4_day!S5 -> 20.13 | I27: =data_raw_4_day!T5 -> 26.14 | J27: =data_raw_4_day!U5 -> 25 | K27: =data_raw_4_day!V5 -> 36.27 | L27: =AVERAGE(H27:K27) -> 26.885 | M27: =E27-F27-G27-L27 -> 316.595 | N27: =data_raw_4_day!Q5 -> 432.89 | O27: =E27-N27 -> 13.28 | P27: =data_raw_4_day!W5 -> 1 | Q27: =data_raw_4_day!X5 -> 0.9991 | R27: =data_raw_4_day!Y5 -> 0.9928 | S27: =data_raw_4_day!Z5 -> 0.9912 | T27: =data_raw_4_day!AA5 -> 0.9882 | U27: =data_raw_4_day!AB5 -> 0.9748 | V27: =data_raw_4_day!AC5 -> 0.9711 | W27: =data_raw_4_day!AD5 -> 0.9633 | ... AS27: =data_raw_4_day!AZ5 -> 0.0017 | AU27: =saga_progression_new!$C$17*B27 -> 49.902 | AV27: =daily_rewards_new!$B$13*data_raw_4_day!K5 -> 50.7 | AW27: {=SUMPRODUCT($P27:$AS27,TRANSPOSE(milestone_4day_new!$E$4:$E$33))} -> 72.082 | AX27: =M27+L27+AU27+AV27+AW27 -> 516.164 | AY27: =M27+AU27+AV27+AW27 -> 489.279 | AZ27: =N27 -> 432.89 | BA27: =AX27-AZ27 -> 83.274 | BB27: =BA27-O27 -> 69.994 | BC27: =AY27-AZ27 -> 56.389 | BD27: =BC27-O27 -> 43.109
A28: 40-99 | B28: =data_raw_4_day!J6 -> 177.59 | C28: =data_raw_4_day!L6 -> 543.53 | D28: =data_raw_4_day!G6 -> 83292 | E28: =data_raw_4_day!M6 -> 841.39 | F28: =data_raw_4_day!N6 -> 117.07 | G28: =data_raw_4_day!O6 -> 50.4 | H28: =data_raw_4_day!S6 -> 35.36 | I28: =data_raw_4_day!T6 -> 28.75 | J28: =data_raw_4_day!U6 -> 30 | K28: =data_raw_4_day!V6 -> 44.69 | L28: =AVERAGE(H28:K28) -> 34.7 | M28: =E28-F28-G28-L28 -> 639.22 | N28: =data_raw_4_day!Q6 -> 873.18 | O28: =E28-N28 -> -31.79 | P28: =data_raw_4_day!W6 -> 1 | Q28: =data_raw_4_day!X6 -> 0.9992 | R28: =data_raw_4_day!Y6 -> 0.9964 | S28: =data_raw_4_day!Z6 -> 0.9958 | T28: =data_raw_4_day!AA6 -> 0.9935 | U28: =data_raw_4_day!AB6 -> 0.9897 | V28: =data_raw_4_day!AC6 -> 0.9885 | W28: =data_raw_4_day!AD6 -> 0.9848 | ... AS28: =data_raw_4_day!AZ6 -> 0.009 | AU28: =saga_progression_new!$C$17*B28 -> 106.554 | AV28: =daily_rewards_new!$B$13*data_raw_4_day!K6 -> 54.414286 | AW28: {=SUMPRODUCT($P28:$AS28,TRANSPOSE(milestone_4day_new!$E$4:$E$33))} -> 131.752 | AX28: =M28+L28+AU28+AV28+AW28 -> 966.64029 | AY28: =M28+AU28+AV28+AW28 -> 931.94029 | AZ28: =N28 -> 873.18 | BA28: =AX28-AZ28 -> 93.460286 | BB28: =BA28-O28 -> 125.25029 | BC28: =AY28-AZ28 -> 58.760286 | BD28: =BC28-O28 -> 90.550286
A29: 100+ | B29: =data_raw_4_day!J7 -> 336.56 | C29: =data_raw_4_day!L7 -> 516.87 | D29: =data_raw_4_day!G7 -> 139889 | E29: =data_raw_4_day!M7 -> 1649.81 | F29: =data_raw_4_day!N7 -> 299.58 | G29: =data_raw_4_day!O7 -> 60.75 | H29: =data_raw_4_day!S7 -> 53.54 | I29: =data_raw_4_day!T7 -> 38.97 | J29: =data_raw_4_day!U7 -> 25 | K29: =data_raw_4_day!V7 -> 41.67 | L29: =AVERAGE(H29:K29) -> 39.795 | M29: =E29-F29-G29-L29 -> 1249.685 | N29: =data_raw_4_day!Q7 -> 1775.72 | O29: =E29-N29 -> -125.91 | P29: =data_raw_4_day!W7 -> 1 | Q29: =data_raw_4_day!X7 -> 0.9987 | R29: =data_raw_4_day!Y7 -> 0.9974 | S29: =data_raw_4_day!Z7 -> 0.9974 | T29: =data_raw_4_day!AA7 -> 0.9961 | U29: =data_raw_4_day!AB7 -> 0.9961 | V29: =data_raw_4_day!AC7 -> 0.9949 | W29: =data_raw_4_day!AD7 -> 0.9949 | ... AS29: =data_raw_4_day!AZ7 -> 0.0978 | AU29: =saga_progression_new!$C$17*B29 -> 201.936 | AV29: =daily_rewards_new!$B$13*data_raw_4_day!K7 -> 47.914286 | AW29: {=SUMPRODUCT($P29:$AS29,TRANSPOSE(milestone_4day_new!$E$4:$E$33))} -> 331.1195 | AX29: =M29+L29+AU29+AV29+AW29 -> 1870.4498 | AY29: =M29+AU29+AV29+AW29 -> 1830.6548 | AZ29: =N29 -> 1775.72 | BA29: =AX29-AZ29 -> 94.729786 | BB29: =BA29-O29 -> 220.63979 | BC29: =AY29-AZ29 -> 54.934786 | BD29: =BC29-O29 -> 180.84479
A30: PAYER
A31: 0-9 | B31: =data_raw_4_day!J9 -> 14.56 | C31: =data_raw_4_day!L9 -> 584.43 | D31: =data_raw_4_day!G9 -> 5438 | E31: =data_raw_4_day!M9 -> 191.49 | F31: =data_raw_4_day!N9 -> 9.69 | G31: =data_raw_4_day!O9 -> 45.76 | H31: =data_raw_4_day!S9 -> 11.39 | I31: =data_raw_4_day!T9 -> 25 | J31: =data_raw_4_day!U9 -> 25 | K31: =data_raw_4_day!V9 -> 34.28 | L31: =AVERAGE(H31:K31) -> 23.9175 | M31: =E31-F31-G31-L31 -> 112.1225 | N31: =data_raw_4_day!Q9 -> 172.31 | O31: =E31-N31 -> 19.18 | P31: =data_raw_4_day!W9 -> 0.9998 | Q31: =data_raw_4_day!X9 -> 0.9817 | R31: =data_raw_4_day!Y9 -> 0.8451 | S31: =data_raw_4_day!Z9 -> 0.8172 | T31: =data_raw_4_day!AA9 -> 0.7662 | U31: =data_raw_4_day!AB9 -> 0.6162 | V31: =data_raw_4_day!AC9 -> 0.5767 | W31: =data_raw_4_day!AD9 -> 0.5046 | ... AS31: =data_raw_4_day!AZ9 -> 0.0002 | AT31: ⭐ | AU31: =saga_progression_new!$C$17*B31 -> 8.736 | AV31: =daily_rewards_new!$B$13*data_raw_4_day!K9 -> 43.271429 | AW31: {=SUMPRODUCT($P31:$AS31,TRANSPOSE(milestone_4day_new!$E$4:$E$33))} -> 20.649 | AX31: =M31+L31+AU31+AV31+AW31 -> 208.69643 | AY31: =M31+AU31+AV31+AW31 -> 184.77893 | AZ31: =N31 -> 172.31 | BA31: =AX31-AZ31 -> 36.386429 | BB31: =BA31-O31 -> 17.206429 | BC31: =AY31-AZ31 -> 12.468929 | BD31: =BC31-O31 -> -6.7110714
A32: 10-19 | B32: =data_raw_4_day!J10 -> 42.39 | C32: =data_raw_4_day!L10 -> 584.97 | D32: =data_raw_4_day!G10 -> 20371 | E32: =data_raw_4_day!M10 -> 450.93 | F32: =data_raw_4_day!N10 -> 27.26 | G32: =data_raw_4_day!O10 -> 47.18 | H32: =data_raw_4_day!S10 -> 12.01 | I32: =data_raw_4_day!T10 -> 26 | J32: =data_raw_4_day!U10 -> 43.75 | K32: =data_raw_4_day!V10 -> 34.54 | L32: =AVERAGE(H32:K32) -> 29.075 | M32: =E32-F32-G32-L32 -> 347.415 | N32: =data_raw_4_day!Q10 -> 446.01 | O32: =E32-N32 -> 4.92 | P32: =data_raw_4_day!W10 -> 1 | Q32: =data_raw_4_day!X10 -> 0.9973 | R32: =data_raw_4_day!Y10 -> 0.9822 | S32: =data_raw_4_day!Z10 -> 0.978 | T32: =data_raw_4_day!AA10 -> 0.9711 | U32: =data_raw_4_day!AB10 -> 0.9481 | V32: =data_raw_4_day!AC10 -> 0.9394 | W32: =data_raw_4_day!AD10 -> 0.9196 | ... AS32: =data_raw_4_day!AZ10 -> 0 | AT32: ⭐ | AU32: =saga_progression_new!$C$17*B32 -> 25.434 | AV32: =daily_rewards_new!$B$13*data_raw_4_day!K10 -> 49.214286 | AW32: {=SUMPRODUCT($P32:$AS32,TRANSPOSE(milestone_4day_new!$E$4:$E$33))} -> 47.76 | AX32: =M32+L32+AU32+AV32+AW32 -> 498.89829 | AY32: =M32+AU32+AV32+AW32 -> 469.82329 | AZ32: =N32 -> 446.01 | BA32: =AX32-AZ32 -> 52.888286 | BB32: =BA32-O32 -> 47.968286 | BC32: =AY32-AZ32 -> 23.813286 | BD32: =BC32-O32 -> 18.893286
A33: 20-39 | B33: =data_raw_4_day!J11 -> 79.49 | C33: =data_raw_4_day!L11 -> 583.4 | D33: =data_raw_4_day!G11 -> 38625 | E33: =data_raw_4_day!M11 -> 852.76 | F33: =data_raw_4_day!N11 -> 51.28 | G33: =data_raw_4_day!O11 -> 44.15 | H33: =data_raw_4_day!S11 -> 18.59 | I33: =data_raw_4_day!T11 -> 26.08 | J33: =data_raw_4_day!U11 -> 28.13 | K33: =data_raw_4_day!V11 -> 36.48 | L33: =AVERAGE(H33:K33) -> 27.32 | M33: =E33-F33-G33-L33 -> 730.01 | N33: =data_raw_4_day!Q11 -> 857.67 | O33: =E33-N33 -> -4.91 | P33: =data_raw_4_day!W11 -> 1 | Q33: =data_raw_4_day!X11 -> 0.9992 | R33: =data_raw_4_day!Y11 -> 0.9908 | S33: =data_raw_4_day!Z11 -> 0.9882 | T33: =data_raw_4_day!AA11 -> 0.9858 | U33: =data_raw_4_day!AB11 -> 0.9748 | V33: =data_raw_4_day!AC11 -> 0.9715 | W33: =data_raw_4_day!AD11 -> 0.9642 | ... AS33: =data_raw_4_day!AZ11 -> 0.0012 | AT33: ⭐ | AU33: =saga_progression_new!$C$17*B33 -> 47.694 | AV33: =daily_rewards_new!$B$13*data_raw_4_day!K11 -> 49.214286 | AW33: {=SUMPRODUCT($P33:$AS33,TRANSPOSE(milestone_4day_new!$E$4:$E$33))} -> 70.9025 | AX33: =M33+L33+AU33+AV33+AW33 -> 925.14079 | AY33: =M33+AU33+AV33+AW33 -> 897.82079 | AZ33: =N33 -> 857.67 | BA33: =AX33-AZ33 -> 67.470786 | BB33: =BA33-O33 -> 72.380786 | BC33: =AY33-AZ33 -> 40.150786 | BD33: =BC33-O33 -> 45.060786
A34: 40-99 | B34: =data_raw_4_day!J12 -> 167.58 | C34: =data_raw_4_day!L12 -> 575 | D34: =data_raw_4_day!G12 -> 83537 | E34: =data_raw_4_day!M12 -> 1736.72 | F34: =data_raw_4_day!N12 -> 104.07 | G34: =data_raw_4_day!O12 -> 44.04 | H34: =data_raw_4_day!S12 -> 32.02 | I34: =data_raw_4_day!T12 -> 28.6 | J34: =data_raw_4_day!U12 -> 25 | K34: =data_raw_4_day!V12 -> 43.45 | L34: =AVERAGE(H34:K34) -> 32.2675 | M34: =E34-F34-G34-L34 -> 1556.3425 | N34: =data_raw_4_day!Q12 -> 1806.88 | O34: =E34-N34 -> -70.16 | P34: =data_raw_4_day!W12 -> 1 | Q34: =data_raw_4_day!X12 -> 0.9996 | R34: =data_raw_4_day!Y12 -> 0.9962 | S34: =data_raw_4_day!Z12 -> 0.995 | T34: =data_raw_4_day!AA12 -> 0.9923 | U34: =data_raw_4_day!AB12 -> 0.9881 | V34: =data_raw_4_day!AC12 -> 0.9862 | W34: =data_raw_4_day!AD12 -> 0.9827 | ... AS34: =data_raw_4_day!AZ12 -> 0.0108 | AT34: ⭐ | AU34: =saga_progression_new!$C$17*B34 -> 100.548 | AV34: =daily_rewards_new!$B$13*data_raw_4_day!K12 -> 51.442857 | AW34: {=SUMPRODUCT($P34:$AS34,TRANSPOSE(milestone_4day_new!$E$4:$E$33))} -> 133.1095 | AX34: =M34+L34+AU34+AV34+AW34 -> 1873.7104 | AY34: =M34+AU34+AV34+AW34 -> 1841.4429 | AZ34: =N34 -> 1806.88 | BA34: =AX34-AZ34 -> 66.830357 | BB34: =BA34-O34 -> 136.99036 | BC34: =AY34-AZ34 -> 34.562857 | BD34: =BC34-O34 -> 104.72286
A35: 100+ | B35: =data_raw_4_day!J13 -> 333.42 | C35: =data_raw_4_day!L13 -> 560.04 | D35: =data_raw_4_day!G13 -> 157274 | E35: =data_raw_4_day!M13 -> 3908.46 | F35: =data_raw_4_day!N13 -> 249.57 | G35: =data_raw_4_day!O13 -> 52.3 | H35: =data_raw_4_day!S13 -> 51.5 | I35: =data_raw_4_day!T13 -> 39.17 | J35: =data_raw_4_day!U13 -> 25 | K35: =data_raw_4_day!V13 -> 42.86 | L35: =AVERAGE(H35:K35) -> 39.6325 | M35: =E35-F35-G35-L35 -> 3566.9575 | N35: =data_raw_4_day!Q13 -> 3967.93 | O35: =E35-N35 -> -59.47 | P35: =data_raw_4_day!W13 -> 1 | Q35: =data_raw_4_day!X13 -> 1 | R35: =data_raw_4_day!Y13 -> 1 | S35: =data_raw_4_day!Z13 -> 1 | T35: =data_raw_4_day!AA13 -> 1 | U35: =data_raw_4_day!AB13 -> 0.9964 | V35: =data_raw_4_day!AC13 -> 0.9964 | W35: =data_raw_4_day!AD13 -> 0.9891 | ... AS35: =data_raw_4_day!AZ13 -> 0.0942 | AT35: ⭐ | AU35: =saga_progression_new!$C$17*B35 -> 200.052 | AV35: =daily_rewards_new!$B$13*data_raw_4_day!K13 -> 46.614286 | AW35: {=SUMPRODUCT($P35:$AS35,TRANSPOSE(milestone_4day_new!$E$4:$E$33))} -> 341.1645 | AX35: =M35+L35+AU35+AV35+AW35 -> 4194.4208 | AY35: =M35+AU35+AV35+AW35 -> 4154.7883 | AZ35: =N35 -> 3967.93 | BA35: =AX35-AZ35 -> 226.49079 | BB35: =BA35-O35 -> 285.96079 | BC35: =AY35-AZ35 -> 186.85829 | BD35: =BC35-O35 -> 246.32829

Sheet Sim_Progression_p25
A1: RAINBOW MAKER - SIM PROGRESSION (p25)
A3: ◆ 3-DAY PROGRESSION
A4: Milestone | B4: Matchables Req | C4: Req Accum | D4: Chest | E4: NP 0-9 | F4: NP 10-19 | G4: NP 20-39 | H4: NP 40-99 | I4: NP 100+ | J4: P 0-9 | K4: P 10-19 | L4: P 20-39 | M4: P 40-99 | N4: P 100+
A5: =milestone_3day_new!A4 -> 1 | B5: =milestone_3day_new!B4 -> 130 | C5: =milestone_3day_new!C4 -> 130 | D5: =milestone_3day_new!D4 -> FALSE | E5: =IFERROR(IF(CEILING($C5*3/data_raw_3_day!$F$3,1)>3,"X","D"&CEILING($C5*3/data_raw_3_day!$F$3,1)),"X") -> D1 | F5: =IFERROR(IF(CEILING($C5*3/data_raw_3_day!$F$4,1)>3,"X","D"&CEILING($C5*3/data_raw_3_day!$F$4,1)),"X") -> D1 | G5: =IFERROR(IF(CEILING($C5*3/data_raw_3_day!$F$5,1)>3,"X","D"&CEILING($C5*3/data_raw_3_day!$F$5,1)),"X") -> D1 | H5: =IFERROR(IF(CEILING($C5*3/data_raw_3_day!$F$6,1)>3,"X","D"&CEILING($C5*3/data_raw_3_day!$F$6,1)),"X") -> D1 | I5: =IFERROR(IF(CEILING($C5*3/data_raw_3_day!$F$7,1)>3,"X","D"&CEILING($C5*3/data_raw_3_day!$F$7,1)),"X") -> D1 | J5: =IFERROR(IF(CEILING($C5*3/data_raw_3_day!$F$9,1)>3,"X","D"&CEILING($C5*3/data_raw_3_day!$F$9,1)),"X") -> D1 | K5: =IFERROR(IF(CEILING($C5*3/data_raw_3_day!$F$10,1)>3,"X","D"&CEILING($C5*3/data_raw_3_day!$F$10,1)),"X") -> D1 | L5: =IFERROR(IF(CEILING($C5*3/data_raw_3_day!$F$11,1)>3,"X","D"&CEILING($C5*3/data_raw_3_day!$F$11,1)),"X") -> D1 | M5: =IFERROR(IF(CEILING($C5*3/data_raw_3_day!$F$12,1)>3,"X","D"&CEILING($C5*3/data_raw_3_day!$F$12,1)),"X") -> D1 | N5: =IFERROR(IF(CEILING($C5*3/data_raw_3_day!$F$13,1)>3,"X","D"&CEILING($C5*3/data_raw_3_day!$F$13,1)),"X") -> D1
A6: =milestone_3day_new!A5 -> 2 | B6: =milestone_3day_new!B5 -> 250 | C6: =milestone_3day_new!C5 -> 380 | D6: =milestone_3day_new!D5 -> FALSE | E6: =IFERROR(IF(CEILING($C6*3/data_raw_3_day!$F$3,1)>3,"X","D"&CEILING($C6*3/data_raw_3_day!$F$3,1)),"X") -> D1 | F6: =IFERROR(IF(CEILING($C6*3/data_raw_3_day!$F$4,1)>3,"X","D"&CEILING($C6*3/data_raw_3_day!$F$4,1)),"X") -> D1 | G6: =IFERROR(IF(CEILING($C6*3/data_raw_3_day!$F$5,1)>3,"X","D"&CEILING($C6*3/data_raw_3_day!$F$5,1)),"X") -> D1 | H6: =IFERROR(IF(CEILING($C6*3/data_raw_3_day!$F$6,1)>3,"X","D"&CEILING($C6*3/data_raw_3_day!$F$6,1)),"X") -> D1 | I6: =IFERROR(IF(CEILING($C6*3/data_raw_3_day!$F$7,1)>3,"X","D"&CEILING($C6*3/data_raw_3_day!$F$7,1)),"X") -> D1 | J6: =IFERROR(IF(CEILING($C6*3/data_raw_3_day!$F$9,1)>3,"X","D"&CEILING($C6*3/data_raw_3_day!$F$9,1)),"X") -> D1 | K6: =IFERROR(IF(CEILING($C6*3/data_raw_3_day!$F$10,1)>3,"X","D"&CEILING($C6*3/data_raw_3_day!$F$10,1)),"X") -> D1 | L6: =IFERROR(IF(CEILING($C6*3/data_raw_3_day!$F$11,1)>3,"X","D"&CEILING($C6*3/data_raw_3_day!$F$11,1)),"X") -> D1 | M6: =IFERROR(IF(CEILING($C6*3/data_raw_3_day!$F$12,1)>3,"X","D"&CEILING($C6*3/data_raw_3_day!$F$12,1)),"X") -> D1 | N6: =IFERROR(IF(CEILING($C6*3/data_raw_3_day!$F$13,1)>3,"X","D"&CEILING($C6*3/data_raw_3_day!$F$13,1)),"X") -> D1
A7: =milestone_3day_new!A6 -> 3 | B7: =milestone_3day_new!B6 -> 850 | C7: =milestone_3day_new!C6 -> 1230 | D7: =milestone_3day_new!D6 -> FALSE | E7: =IFERROR(IF(CEILING($C7*3/data_raw_3_day!$F$3,1)>3,"X","D"&CEILING($C7*3/data_raw_3_day!$F$3,1)),"X") -> D3 | F7: =IFERROR(IF(CEILING($C7*3/data_raw_3_day!$F$4,1)>3,"X","D"&CEILING($C7*3/data_raw_3_day!$F$4,1)),"X") -> D1 | G7: =IFERROR(IF(CEILING($C7*3/data_raw_3_day!$F$5,1)>3,"X","D"&CEILING($C7*3/data_raw_3_day!$F$5,1)),"X") -> D1 | H7: =IFERROR(IF(CEILING($C7*3/data_raw_3_day!$F$6,1)>3,"X","D"&CEILING($C7*3/data_raw_3_day!$F$6,1)),"X") -> D1 | I7: =IFERROR(IF(CEILING($C7*3/data_raw_3_day!$F$7,1)>3,"X","D"&CEILING($C7*3/data_raw_3_day!$F$7,1)),"X") -> D1 | J7: =IFERROR(IF(CEILING($C7*3/data_raw_3_day!$F$9,1)>3,"X","D"&CEILING($C7*3/data_raw_3_day!$F$9,1)),"X") -> D2 | K7: =IFERROR(IF(CEILING($C7*3/data_raw_3_day!$F$10,1)>3,"X","D"&CEILING($C7*3/data_raw_3_day!$F$10,1)),"X") -> D1 | L7: =IFERROR(IF(CEILING($C7*3/data_raw_3_day!$F$11,1)>3,"X","D"&CEILING($C7*3/data_raw_3_day!$F$11,1)),"X") -> D1 | M7: =IFERROR(IF(CEILING($C7*3/data_raw_3_day!$F$12,1)>3,"X","D"&CEILING($C7*3/data_raw_3_day!$F$12,1)),"X") -> D1 | N7: =IFERROR(IF(CEILING($C7*3/data_raw_3_day!$F$13,1)>3,"X","D"&CEILING($C7*3/data_raw_3_day!$F$13,1)),"X") -> D1
A8: =milestone_3day_new!A7 -> 4 | B8: =milestone_3day_new!B7 -> 200 | C8: =milestone_3day_new!C7 -> 1430 | D8: =milestone_3day_new!D7 -> FALSE | E8: =IFERROR(IF(CEILING($C8*3/data_raw_3_day!$F$3,1)>3,"X","D"&CEILING($C8*3/data_raw_3_day!$F$3,1)),"X") -> D3 | F8: =IFERROR(IF(CEILING($C8*3/data_raw_3_day!$F$4,1)>3,"X","D"&CEILING($C8*3/data_raw_3_day!$F$4,1)),"X") -> D1 | G8: =IFERROR(IF(CEILING($C8*3/data_raw_3_day!$F$5,1)>3,"X","D"&CEILING($C8*3/data_raw_3_day!$F$5,1)),"X") -> D1 | H8: =IFERROR(IF(CEILING($C8*3/data_raw_3_day!$F$6,1)>3,"X","D"&CEILING($C8*3/data_raw_3_day!$F$6,1)),"X") -> D1 | I8: =IFERROR(IF(CEILING($C8*3/data_raw_3_day!$F$7,1)>3,"X","D"&CEILING($C8*3/data_raw_3_day!$F$7,1)),"X") -> D1 | J8: =IFERROR(IF(CEILING($C8*3/data_raw_3_day!$F$9,1)>3,"X","D"&CEILING($C8*3/data_raw_3_day!$F$9,1)),"X") -> D3 | K8: =IFERROR(IF(CEILING($C8*3/data_raw_3_day!$F$10,1)>3,"X","D"&CEILING($C8*3/data_raw_3_day!$F$10,1)),"X") -> D1 | L8: =IFERROR(IF(CEILING($C8*3/data_raw_3_day!$F$11,1)>3,"X","D"&CEILING($C8*3/data_raw_3_day!$F$11,1)),"X") -> D1 | M8: =IFERROR(IF(CEILING($C8*3/data_raw_3_day!$F$12,1)>3,"X","D"&CEILING($C8*3/data_raw_3_day!$F$12,1)),"X") -> D1 | N8: =IFERROR(IF(CEILING($C8*3/data_raw_3_day!$F$13,1)>3,"X","D"&CEILING($C8*3/data_raw_3_day!$F$13,1)),"X") -> D1
A9: =milestone_3day_new!A8 -> 5 | B9: =milestone_3day_new!B8 -> 450 | C9: =milestone_3day_new!C8 -> 1880 | D9: =milestone_3day_new!D8 -> FALSE | E9: =IFERROR(IF(CEILING($C9*3/data_raw_3_day!$F$3,1)>3,"X","D"&CEILING($C9*3/data_raw_3_day!$F$3,1)),"X") -> X | F9: =IFERROR(IF(CEILING($C9*3/data_raw_3_day!$F$4,1)>3,"X","D"&CEILING($C9*3/data_raw_3_day!$F$4,1)),"X") -> D1 | G9: =IFERROR(IF(CEILING($C9*3/data_raw_3_day!$F$5,1)>3,"X","D"&CEILING($C9*3/data_raw_3_day!$F$5,1)),"X") -> D1 | H9: =IFERROR(IF(CEILING($C9*3/data_raw_3_day!$F$6,1)>3,"X","D"&CEILING($C9*3/data_raw_3_day!$F$6,1)),"X") -> D1 | I9: =IFERROR(IF(CEILING($C9*3/data_raw_3_day!$F$7,1)>3,"X","D"&CEILING($C9*3/data_raw_3_day!$F$7,1)),"X") -> D1 | J9: =IFERROR(IF(CEILING($C9*3/data_raw_3_day!$F$9,1)>3,"X","D"&CEILING($C9*3/data_raw_3_day!$F$9,1)),"X") -> D3 | K9: =IFERROR(IF(CEILING($C9*3/data_raw_3_day!$F$10,1)>3,"X","D"&CEILING($C9*3/data_raw_3_day!$F$10,1)),"X") -> D1 | L9: =IFERROR(IF(CEILING($C9*3/data_raw_3_day!$F$11,1)>3,"X","D"&CEILING($C9*3/data_raw_3_day!$F$11,1)),"X") -> D1 | M9: =IFERROR(IF(CEILING($C9*3/data_raw_3_day!$F$12,1)>3,"X","D"&CEILING($C9*3/data_raw_3_day!$F$12,1)),"X") -> D1 | N9: =IFERROR(IF(CEILING($C9*3/data_raw_3_day!$F$13,1)>3,"X","D"&CEILING($C9*3/data_raw_3_day!$F$13,1)),"X") -> D1
A10: =milestone_3day_new!A9 -> 6 | B10: =milestone_3day_new!B9 -> 1300 | C10: =milestone_3day_new!C9 -> 3180 | D10: =milestone_3day_new!D9 -> TRUE | E10: =IFERROR(IF(CEILING($C10*3/data_raw_3_day!$F$3,1)>3,"X","D"&CEILING($C10*3/data_raw_3_day!$F$3,1)),"X") -> X | F10: =IFERROR(IF(CEILING($C10*3/data_raw_3_day!$F$4,1)>3,"X","D"&CEILING($C10*3/data_raw_3_day!$F$4,1)),"X") -> D2 | G10: =IFERROR(IF(CEILING($C10*3/data_raw_3_day!$F$5,1)>3,"X","D"&CEILING($C10*3/data_raw_3_day!$F$5,1)),"X") -> D1 | H10: =IFERROR(IF(CEILING($C10*3/data_raw_3_day!$F$6,1)>3,"X","D"&CEILING($C10*3/data_raw_3_day!$F$6,1)),"X") -> D1 | I10: =IFERROR(IF(CEILING($C10*3/data_raw_3_day!$F$7,1)>3,"X","D"&CEILING($C10*3/data_raw_3_day!$F$7,1)),"X") -> D1 | J10: =IFERROR(IF(CEILING($C10*3/data_raw_3_day!$F$9,1)>3,"X","D"&CEILING($C10*3/data_raw_3_day!$F$9,1)),"X") -> X | K10: =IFERROR(IF(CEILING($C10*3/data_raw_3_day!$F$10,1)>3,"X","D"&CEILING($C10*3/data_raw_3_day!$F$10,1)),"X") -> D2 | L10: =IFERROR(IF(CEILING($C10*3/data_raw_3_day!$F$11,1)>3,"X","D"&CEILING($C10*3/data_raw_3_day!$F$11,1)),"X") -> D1 | M10: =IFERROR(IF(CEILING($C10*3/data_raw_3_day!$F$12,1)>3,"X","D"&CEILING($C10*3/data_raw_3_day!$F$12,1)),"X") -> D1 | N10: =IFERROR(IF(CEILING($C10*3/data_raw_3_day!$F$13,1)>3,"X","D"&CEILING($C10*3/data_raw_3_day!$F$13,1)),"X") -> D1
A11: =milestone_3day_new!A10 -> 7 | B11: =milestone_3day_new!B10 -> 450 | C11: =milestone_3day_new!C10 -> 3630 | D11: =milestone_3day_new!D10 -> FALSE | E11: =IFERROR(IF(CEILING($C11*3/data_raw_3_day!$F$3,1)>3,"X","D"&CEILING($C11*3/data_raw_3_day!$F$3,1)),"X") -> X | F11: =IFERROR(IF(CEILING($C11*3/data_raw_3_day!$F$4,1)>3,"X","D"&CEILING($C11*3/data_raw_3_day!$F$4,1)),"X") -> D2 | G11: =IFERROR(IF(CEILING($C11*3/data_raw_3_day!$F$5,1)>3,"X","D"&CEILING($C11*3/data_raw_3_day!$F$5,1)),"X") -> D1 | H11: =IFERROR(IF(CEILING($C11*3/data_raw_3_day!$F$6,1)>3,"X","D"&CEILING($C11*3/data_raw_3_day!$F$6,1)),"X") -> D1 | I11: =IFERROR(IF(CEILING($C11*3/data_raw_3_day!$F$7,1)>3,"X","D"&CEILING($C11*3/data_raw_3_day!$F$7,1)),"X") -> D1 | J11: =IFERROR(IF(CEILING($C11*3/data_raw_3_day!$F$9,1)>3,"X","D"&CEILING($C11*3/data_raw_3_day!$F$9,1)),"X") -> X | K11: =IFERROR(IF(CEILING($C11*3/data_raw_3_day!$F$10,1)>3,"X","D"&CEILING($C11*3/data_raw_3_day!$F$10,1)),"X") -> D2 | L11: =IFERROR(IF(CEILING($C11*3/data_raw_3_day!$F$11,1)>3,"X","D"&CEILING($C11*3/data_raw_3_day!$F$11,1)),"X") -> D1 | M11: =IFERROR(IF(CEILING($C11*3/data_raw_3_day!$F$12,1)>3,"X","D"&CEILING($C11*3/data_raw_3_day!$F$12,1)),"X") -> D1 | N11: =IFERROR(IF(CEILING($C11*3/data_raw_3_day!$F$13,1)>3,"X","D"&CEILING($C11*3/data_raw_3_day!$F$13,1)),"X") -> D1
A12: =milestone_3day_new!A11 -> 8 | B12: =milestone_3day_new!B11 -> 820 | C12: =milestone_3day_new!C11 -> 4450 | D12: =milestone_3day_new!D11 -> FALSE | E12: =IFERROR(IF(CEILING($C12*3/data_raw_3_day!$F$3,1)>3,"X","D"&CEILING($C12*3/data_raw_3_day!$F$3,1)),"X") -> X | F12: =IFERROR(IF(CEILING($C12*3/data_raw_3_day!$F$4,1)>3,"X","D"&CEILING($C12*3/data_raw_3_day!$F$4,1)),"X") -> D2 | G12: =IFERROR(IF(CEILING($C12*3/data_raw_3_day!$F$5,1)>3,"X","D"&CEILING($C12*3/data_raw_3_day!$F$5,1)),"X") -> D1 | H12: =IFERROR(IF(CEILING($C12*3/data_raw_3_day!$F$6,1)>3,"X","D"&CEILING($C12*3/data_raw_3_day!$F$6,1)),"X") -> D1 | I12: =IFERROR(IF(CEILING($C12*3/data_raw_3_day!$F$7,1)>3,"X","D"&CEILING($C12*3/data_raw_3_day!$F$7,1)),"X") -> D1 | J12: =IFERROR(IF(CEILING($C12*3/data_raw_3_day!$F$9,1)>3,"X","D"&CEILING($C12*3/data_raw_3_day!$F$9,1)),"X") -> X | K12: =IFERROR(IF(CEILING($C12*3/data_raw_3_day!$F$10,1)>3,"X","D"&CEILING($C12*3/data_raw_3_day!$F$10,1)),"X") -> D2 | L12: =IFERROR(IF(CEILING($C12*3/data_raw_3_day!$F$11,1)>3,"X","D"&CEILING($C12*3/data_raw_3_day!$F$11,1)),"X") -> D1 | M12: =IFERROR(IF(CEILING($C12*3/data_raw_3_day!$F$12,1)>3,"X","D"&CEILING($C12*3/data_raw_3_day!$F$12,1)),"X") -> D1 | N12: =IFERROR(IF(CEILING($C12*3/data_raw_3_day!$F$13,1)>3,"X","D"&CEILING($C12*3/data_raw_3_day!$F$13,1)),"X") -> D1
A13: =milestone_3day_new!A12 -> 9 | B13: =milestone_3day_new!B12 -> 3300 | C13: =milestone_3day_new!C12 -> 7750 | D13: =milestone_3day_new!D12 -> TRUE | E13: =IFERROR(IF(CEILING($C13*3/data_raw_3_day!$F$3,1)>3,"X","D"&CEILING($C13*3/data_raw_3_day!$F$3,1)),"X") -> X | F13: =IFERROR(IF(CEILING($C13*3/data_raw_3_day!$F$4,1)>3,"X","D"&CEILING($C13*3/data_raw_3_day!$F$4,1)),"X") -> D3 | G13: =IFERROR(IF(CEILING($C13*3/data_raw_3_day!$F$5,1)>3,"X","D"&CEILING($C13*3/data_raw_3_day!$F$5,1)),"X") -> D2 | H13: =IFERROR(IF(CEILING($C13*3/data_raw_3_day!$F$6,1)>3,"X","D"&CEILING($C13*3/data_raw_3_day!$F$6,1)),"X") -> D1 | I13: =IFERROR(IF(CEILING($C13*3/data_raw_3_day!$F$7,1)>3,"X","D"&CEILING($C13*3/data_raw_3_day!$F$7,1)),"X") -> D1 | J13: =IFERROR(IF(CEILING($C13*3/data_raw_3_day!$F$9,1)>3,"X","D"&CEILING($C13*3/data_raw_3_day!$F$9,1)),"X") -> X | K13: =IFERROR(IF(CEILING($C13*3/data_raw_3_day!$F$10,1)>3,"X","D"&CEILING($C13*3/data_raw_3_day!$F$10,1)),"X") -> D3 | L13: =IFERROR(IF(CEILING($C13*3/data_raw_3_day!$F$11,1)>3,"X","D"&CEILING($C13*3/data_raw_3_day!$F$11,1)),"X") -> D2 | M13: =IFERROR(IF(CEILING($C13*3/data_raw_3_day!$F$12,1)>3,"X","D"&CEILING($C13*3/data_raw_3_day!$F$12,1)),"X") -> D1 | N13: =IFERROR(IF(CEILING($C13*3/data_raw_3_day!$F$13,1)>3,"X","D"&CEILING($C13*3/data_raw_3_day!$F$13,1)),"X") -> D1
A14: =milestone_3day_new!A13 -> 10 | B14: =milestone_3day_new!B13 -> 1100 | C14: =milestone_3day_new!C13 -> 8850 | D14: =milestone_3day_new!D13 -> FALSE | E14: =IFERROR(IF(CEILING($C14*3/data_raw_3_day!$F$3,1)>3,"X","D"&CEILING($C14*3/data_raw_3_day!$F$3,1)),"X") -> X | F14: =IFERROR(IF(CEILING($C14*3/data_raw_3_day!$F$4,1)>3,"X","D"&CEILING($C14*3/data_raw_3_day!$F$4,1)),"X") -> X | G14: =IFERROR(IF(CEILING($C14*3/data_raw_3_day!$F$5,1)>3,"X","D"&CEILING($C14*3/data_raw_3_day!$F$5,1)),"X") -> D2 | H14: =IFERROR(IF(CEILING($C14*3/data_raw_3_day!$F$6,1)>3,"X","D"&CEILING($C14*3/data_raw_3_day!$F$6,1)),"X") -> D1 | I14: =IFERROR(IF(CEILING($C14*3/data_raw_3_day!$F$7,1)>3,"X","D"&CEILING($C14*3/data_raw_3_day!$F$7,1)),"X") -> D1 | J14: =IFERROR(IF(CEILING($C14*3/data_raw_3_day!$F$9,1)>3,"X","D"&CEILING($C14*3/data_raw_3_day!$F$9,1)),"X") -> X | K14: =IFERROR(IF(CEILING($C14*3/data_raw_3_day!$F$10,1)>3,"X","D"&CEILING($C14*3/data_raw_3_day!$F$10,1)),"X") -> X | L14: =IFERROR(IF(CEILING($C14*3/data_raw_3_day!$F$11,1)>3,"X","D"&CEILING($C14*3/data_raw_3_day!$F$11,1)),"X") -> D2 | M14: =IFERROR(IF(CEILING($C14*3/data_raw_3_day!$F$12,1)>3,"X","D"&CEILING($C14*3/data_raw_3_day!$F$12,1)),"X") -> D1 | N14: =IFERROR(IF(CEILING($C14*3/data_raw_3_day!$F$13,1)>3,"X","D"&CEILING($C14*3/data_raw_3_day!$F$13,1)),"X") -> D1
A15: =milestone_3day_new!A14 -> 11 | B15: =milestone_3day_new!B14 -> 2200 | C15: =milestone_3day_new!C14 -> 11050 | D15: =milestone_3day_new!D14 -> FALSE | E15: =IFERROR(IF(CEILING($C15*3/data_raw_3_day!$F$3,1)>3,"X","D"&CEILING($C15*3/data_raw_3_day!$F$3,1)),"X") -> X | F15: =IFERROR(IF(CEILING($C15*3/data_raw_3_day!$F$4,1)>3,"X","D"&CEILING($C15*3/data_raw_3_day!$F$4,1)),"X") -> X | G15: =IFERROR(IF(CEILING($C15*3/data_raw_3_day!$F$5,1)>3,"X","D"&CEILING($C15*3/data_raw_3_day!$F$5,1)),"X") -> D3 | H15: =IFERROR(IF(CEILING($C15*3/data_raw_3_day!$F$6,1)>3,"X","D"&CEILING($C15*3/data_raw_3_day!$F$6,1)),"X") -> D1 | I15: =IFERROR(IF(CEILING($C15*3/data_raw_3_day!$F$7,1)>3,"X","D"&CEILING($C15*3/data_raw_3_day!$F$7,1)),"X") -> D1 | J15: =IFERROR(IF(CEILING($C15*3/data_raw_3_day!$F$9,1)>3,"X","D"&CEILING($C15*3/data_raw_3_day!$F$9,1)),"X") -> X | K15: =IFERROR(IF(CEILING($C15*3/data_raw_3_day!$F$10,1)>3,"X","D"&CEILING($C15*3/data_raw_3_day!$F$10,1)),"X") -> X | L15: =IFERROR(IF(CEILING($C15*3/data_raw_3_day!$F$11,1)>3,"X","D"&CEILING($C15*3/data_raw_3_day!$F$11,1)),"X") -> D2 | M15: =IFERROR(IF(CEILING($C15*3/data_raw_3_day!$F$12,1)>3,"X","D"&CEILING($C15*3/data_raw_3_day!$F$12,1)),"X") -> D1 | N15: =IFERROR(IF(CEILING($C15*3/data_raw_3_day!$F$13,1)>3,"X","D"&CEILING($C15*3/data_raw_3_day!$F$13,1)),"X") -> D1
A16: =milestone_3day_new!A15 -> 12 | B16: =milestone_3day_new!B15 -> 6500 | C16: =milestone_3day_new!C15 -> 17550 | D16: =milestone_3day_new!D15 -> TRUE | E16: =IFERROR(IF(CEILING($C16*3/data_raw_3_day!$F$3,1)>3,"X","D"&CEILING($C16*3/data_raw_3_day!$F$3,1)),"X") -> X | F16: =IFERROR(IF(CEILING($C16*3/data_raw_3_day!$F$4,1)>3,"X","D"&CEILING($C16*3/data_raw_3_day!$F$4,1)),"X") -> X | G16: =IFERROR(IF(CEILING($C16*3/data_raw_3_day!$F$5,1)>3,"X","D"&CEILING($C16*3/data_raw_3_day!$F$5,1)),"X") -> X | H16: =IFERROR(IF(CEILING($C16*3/data_raw_3_day!$F$6,1)>3,"X","D"&CEILING($C16*3/data_raw_3_day!$F$6,1)),"X") -> D2 | I16: =IFERROR(IF(CEILING($C16*3/data_raw_3_day!$F$7,1)>3,"X","D"&CEILING($C16*3/data_raw_3_day!$F$7,1)),"X") -> D1 | J16: =IFERROR(IF(CEILING($C16*3/data_raw_3_day!$F$9,1)>3,"X","D"&CEILING($C16*3/data_raw_3_day!$F$9,1)),"X") -> X | K16: =IFERROR(IF(CEILING($C16*3/data_raw_3_day!$F$10,1)>3,"X","D"&CEILING($C16*3/data_raw_3_day!$F$10,1)),"X") -> X | L16: =IFERROR(IF(CEILING($C16*3/data_raw_3_day!$F$11,1)>3,"X","D"&CEILING($C16*3/data_raw_3_day!$F$11,1)),"X") -> X | M16: =IFERROR(IF(CEILING($C16*3/data_raw_3_day!$F$12,1)>3,"X","D"&CEILING($C16*3/data_raw_3_day!$F$12,1)),"X") -> D2 | N16: =IFERROR(IF(CEILING($C16*3/data_raw_3_day!$F$13,1)>3,"X","D"&CEILING($C16*3/data_raw_3_day!$F$13,1)),"X") -> D1
... A34: =milestone_3day_new!A33 -> 30 | B34: =milestone_3day_new!B33 -> 67000 | C34: =milestone_3day_new!C33 -> 292010 | D34: =milestone_3day_new!D33 -> TRUE | E34: =IFERROR(IF(CEILING($C34*3/data_raw_3_day!$F$3,1)>3,"X","D"&CEILING($C34*3/data_raw_3_day!$F$3,1)),"X") -> X | F34: =IFERROR(IF(CEILING($C34*3/data_raw_3_day!$F$4,1)>3,"X","D"&CEILING($C34*3/data_raw_3_day!$F$4,1)),"X") -> X | G34: =IFERROR(IF(CEILING($C34*3/data_raw_3_day!$F$5,1)>3,"X","D"&CEILING($C34*3/data_raw_3_day!$F$5,1)),"X") -> X | H34: =IFERROR(IF(CEILING($C34*3/data_raw_3_day!$F$6,1)>3,"X","D"&CEILING($C34*3/data_raw_3_day!$F$6,1)),"X") -> X | I34: =IFERROR(IF(CEILING($C34*3/data_raw_3_day!$F$7,1)>3,"X","D"&CEILING($C34*3/data_raw_3_day!$F$7,1)),"X") -> X | J34: =IFERROR(IF(CEILING($C34*3/data_raw_3_day!$F$9,1)>3,"X","D"&CEILING($C34*3/data_raw_3_day!$F$9,1)),"X") -> X | K34: =IFERROR(IF(CEILING($C34*3/data_raw_3_day!$F$10,1)>3,"X","D"&CEILING($C34*3/data_raw_3_day!$F$10,1)),"X") -> X | L34: =IFERROR(IF(CEILING($C34*3/data_raw_3_day!$F$11,1)>3,"X","D"&CEILING($C34*3/data_raw_3_day!$F$11,1)),"X") -> X | M34: =IFERROR(IF(CEILING($C34*3/data_raw_3_day!$F$12,1)>3,"X","D"&CEILING($C34*3/data_raw_3_day!$F$12,1)),"X") -> X | N34: =IFERROR(IF(CEILING($C34*3/data_raw_3_day!$F$13,1)>3,"X","D"&CEILING($C34*3/data_raw_3_day!$F$13,1)),"X") -> X
A36: ◆ 4-DAY PROGRESSION
A37: Milestone | B37: Matchables Req | C37: Req Accum | D37: Chest | E37: NP 0-9 | F37: NP 10-19 | G37: NP 20-39 | H37: NP 40-99 | I37: NP 100+ | J37: P 0-9 | K37: P 10-19 | L37: P 20-39 | M37: P 40-99 | N37: P 100+
A38: =milestone_4day_new!A4 -> 1 | B38: =milestone_4day_new!B4 -> 160 | C38: =milestone_4day_new!C4 -> 160 | D38: =milestone_4day_new!D4 -> FALSE | E38: =IFERROR(IF(CEILING($C38*4/data_raw_4_day!$F$3,1)>4,"X","D"&CEILING($C38*4/data_raw_4_day!$F$3,1)),"X") -> D1 | F38: =IFERROR(IF(CEILING($C38*4/data_raw_4_day!$F$4,1)>4,"X","D"&CEILING($C38*4/data_raw_4_day!$F$4,1)),"X") -> D1 | G38: =IFERROR(IF(CEILING($C38*4/data_raw_4_day!$F$5,1)>4,"X","D"&CEILING($C38*4/data_raw_4_day!$F$5,1)),"X") -> D1 | H38: =IFERROR(IF(CEILING($C38*4/data_raw_4_day!$F$6,1)>4,"X","D"&CEILING($C38*4/data_raw_4_day!$F$6,1)),"X") -> D1 | I38: =IFERROR(IF(CEILING($C38*4/data_raw_4_day!$F$7,1)>4,"X","D"&CEILING($C38*4/data_raw_4_day!$F$7,1)),"X") -> D1 | J38: =IFERROR(IF(CEILING($C38*4/data_raw_4_day!$F$9,1)>4,"X","D"&CEILING($C38*4/data_raw_4_day!$F$9,1)),"X") -> D1 | K38: =IFERROR(IF(CEILING($C38*4/data_raw_4_day!$F$10,1)>4,"X","D"&CEILING($C38*4/data_raw_4_day!$F$10,1)),"X") -> D1 | L38: =IFERROR(IF(CEILING($C38*4/data_raw_4_day!$F$11,1)>4,"X","D"&CEILING($C38*4/data_raw_4_day!$F$11,1)),"X") -> D1 | M38: =IFERROR(IF(CEILING($C38*4/data_raw_4_day!$F$12,1)>4,"X","D"&CEILING($C38*4/data_raw_4_day!$F$12,1)),"X") -> D1 | N38: =IFERROR(IF(CEILING($C38*4/data_raw_4_day!$F$13,1)>4,"X","D"&CEILING($C38*4/data_raw_4_day!$F$13,1)),"X") -> D1
A39: =milestone_4day_new!A5 -> 2 | B39: =milestone_4day_new!B5 -> 300 | C39: =milestone_4day_new!C5 -> 460 | D39: =milestone_4day_new!D5 -> FALSE | E39: =IFERROR(IF(CEILING($C39*4/data_raw_4_day!$F$3,1)>4,"X","D"&CEILING($C39*4/data_raw_4_day!$F$3,1)),"X") -> D1 | F39: =IFERROR(IF(CEILING($C39*4/data_raw_4_day!$F$4,1)>4,"X","D"&CEILING($C39*4/data_raw_4_day!$F$4,1)),"X") -> D1 | G39: =IFERROR(IF(CEILING($C39*4/data_raw_4_day!$F$5,1)>4,"X","D"&CEILING($C39*4/data_raw_4_day!$F$5,1)),"X") -> D1 | H39: =IFERROR(IF(CEILING($C39*4/data_raw_4_day!$F$6,1)>4,"X","D"&CEILING($C39*4/data_raw_4_day!$F$6,1)),"X") -> D1 | I39: =IFERROR(IF(CEILING($C39*4/data_raw_4_day!$F$7,1)>4,"X","D"&CEILING($C39*4/data_raw_4_day!$F$7,1)),"X") -> D1 | J39: =IFERROR(IF(CEILING($C39*4/data_raw_4_day!$F$9,1)>4,"X","D"&CEILING($C39*4/data_raw_4_day!$F$9,1)),"X") -> D1 | K39: =IFERROR(IF(CEILING($C39*4/data_raw_4_day!$F$10,1)>4,"X","D"&CEILING($C39*4/data_raw_4_day!$F$10,1)),"X") -> D1 | L39: =IFERROR(IF(CEILING($C39*4/data_raw_4_day!$F$11,1)>4,"X","D"&CEILING($C39*4/data_raw_4_day!$F$11,1)),"X") -> D1 | M39: =IFERROR(IF(CEILING($C39*4/data_raw_4_day!$F$12,1)>4,"X","D"&CEILING($C39*4/data_raw_4_day!$F$12,1)),"X") -> D1 | N39: =IFERROR(IF(CEILING($C39*4/data_raw_4_day!$F$13,1)>4,"X","D"&CEILING($C39*4/data_raw_4_day!$F$13,1)),"X") -> D1
A40: =milestone_4day_new!A6 -> 3 | B40: =milestone_4day_new!B6 -> 1000 | C40: =milestone_4day_new!C6 -> 1460 | D40: =milestone_4day_new!D6 -> FALSE | E40: =IFERROR(IF(CEILING($C40*4/data_raw_4_day!$F$3,1)>4,"X","D"&CEILING($C40*4/data_raw_4_day!$F$3,1)),"X") -> D4 | F40: =IFERROR(IF(CEILING($C40*4/data_raw_4_day!$F$4,1)>4,"X","D"&CEILING($C40*4/data_raw_4_day!$F$4,1)),"X") -> D1 | G40: =IFERROR(IF(CEILING($C40*4/data_raw_4_day!$F$5,1)>4,"X","D"&CEILING($C40*4/data_raw_4_day!$F$5,1)),"X") -> D1 | H40: =IFERROR(IF(CEILING($C40*4/data_raw_4_day!$F$6,1)>4,"X","D"&CEILING($C40*4/data_raw_4_day!$F$6,1)),"X") -> D1 | I40: =IFERROR(IF(CEILING($C40*4/data_raw_4_day!$F$7,1)>4,"X","D"&CEILING($C40*4/data_raw_4_day!$F$7,1)),"X") -> D1 | J40: =IFERROR(IF(CEILING($C40*4/data_raw_4_day!$F$9,1)>4,"X","D"&CEILING($C40*4/data_raw_4_day!$F$9,1)),"X") -> D3 | K40: =IFERROR(IF(CEILING($C40*4/data_raw_4_day!$F$10,1)>4,"X","D"&CEILING($C40*4/data_raw_4_day!$F$10,1)),"X") -> D1 | L40: =IFERROR(IF(CEILING($C40*4/data_raw_4_day!$F$11,1)>4,"X","D"&CEILING($C40*4/data_raw_4_day!$F$11,1)),"X") -> D1 | M40: =IFERROR(IF(CEILING($C40*4/data_raw_4_day!$F$12,1)>4,"X","D"&CEILING($C40*4/data_raw_4_day!$F$12,1)),"X") -> D1 | N40: =IFERROR(IF(CEILING($C40*4/data_raw_4_day!$F$13,1)>4,"X","D"&CEILING($C40*4/data_raw_4_day!$F$13,1)),"X") -> D1
A41: =milestone_4day_new!A7 -> 4 | B41: =milestone_4day_new!B7 -> 250 | C41: =milestone_4day_new!C7 -> 1710 | D41: =milestone_4day_new!D7 -> FALSE | E41: =IFERROR(IF(CEILING($C41*4/data_raw_4_day!$F$3,1)>4,"X","D"&CEILING($C41*4/data_raw_4_day!$F$3,1)),"X") -> D4 | F41: =IFERROR(IF(CEILING($C41*4/data_raw_4_day!$F$4,1)>4,"X","D"&CEILING($C41*4/data_raw_4_day!$F$4,1)),"X") -> D1 | G41: =IFERROR(IF(CEILING($C41*4/data_raw_4_day!$F$5,1)>4,"X","D"&CEILING($C41*4/data_raw_4_day!$F$5,1)),"X") -> D1 | H41: =IFERROR(IF(CEILING($C41*4/data_raw_4_day!$F$6,1)>4,"X","D"&CEILING($C41*4/data_raw_4_day!$F$6,1)),"X") -> D1 | I41: =IFERROR(IF(CEILING($C41*4/data_raw_4_day!$F$7,1)>4,"X","D"&CEILING($C41*4/data_raw_4_day!$F$7,1)),"X") -> D1 | J41: =IFERROR(IF(CEILING($C41*4/data_raw_4_day!$F$9,1)>4,"X","D"&CEILING($C41*4/data_raw_4_day!$F$9,1)),"X") -> D3 | K41: =IFERROR(IF(CEILING($C41*4/data_raw_4_day!$F$10,1)>4,"X","D"&CEILING($C41*4/data_raw_4_day!$F$10,1)),"X") -> D1 | L41: =IFERROR(IF(CEILING($C41*4/data_raw_4_day!$F$11,1)>4,"X","D"&CEILING($C41*4/data_raw_4_day!$F$11,1)),"X") -> D1 | M41: =IFERROR(IF(CEILING($C41*4/data_raw_4_day!$F$12,1)>4,"X","D"&CEILING($C41*4/data_raw_4_day!$F$12,1)),"X") -> D1 | N41: =IFERROR(IF(CEILING($C41*4/data_raw_4_day!$F$13,1)>4,"X","D"&CEILING($C41*4/data_raw_4_day!$F$13,1)),"X") -> D1
A42: =milestone_4day_new!A8 -> 5 | B42: =milestone_4day_new!B8 -> 500 | C42: =milestone_4day_new!C8 -> 2210 | D42: =milestone_4day_new!D8 -> FALSE | E42: =IFERROR(IF(CEILING($C42*4/data_raw_4_day!$F$3,1)>4,"X","D"&CEILING($C42*4/data_raw_4_day!$F$3,1)),"X") -> X | F42: =IFERROR(IF(CEILING($C42*4/data_raw_4_day!$F$4,1)>4,"X","D"&CEILING($C42*4/data_raw_4_day!$F$4,1)),"X") -> D1 | G42: =IFERROR(IF(CEILING($C42*4/data_raw_4_day!$F$5,1)>4,"X","D"&CEILING($C42*4/data_raw_4_day!$F$5,1)),"X") -> D1 | H42: =IFERROR(IF(CEILING($C42*4/data_raw_4_day!$F$6,1)>4,"X","D"&CEILING($C42*4/data_raw_4_day!$F$6,1)),"X") -> D1 | I42: =IFERROR(IF(CEILING($C42*4/data_raw_4_day!$F$7,1)>4,"X","D"&CEILING($C42*4/data_raw_4_day!$F$7,1)),"X") -> D1 | J42: =IFERROR(IF(CEILING($C42*4/data_raw_4_day!$F$9,1)>4,"X","D"&CEILING($C42*4/data_raw_4_day!$F$9,1)),"X") -> D4 | K42: =IFERROR(IF(CEILING($C42*4/data_raw_4_day!$F$10,1)>4,"X","D"&CEILING($C42*4/data_raw_4_day!$F$10,1)),"X") -> D1 | L42: =IFERROR(IF(CEILING($C42*4/data_raw_4_day!$F$11,1)>4,"X","D"&CEILING($C42*4/data_raw_4_day!$F$11,1)),"X") -> D1 | M42: =IFERROR(IF(CEILING($C42*4/data_raw_4_day!$F$12,1)>4,"X","D"&CEILING($C42*4/data_raw_4_day!$F$12,1)),"X") -> D1 | N42: =IFERROR(IF(CEILING($C42*4/data_raw_4_day!$F$13,1)>4,"X","D"&CEILING($C42*4/data_raw_4_day!$F$13,1)),"X") -> D1
A43: =milestone_4day_new!A9 -> 6 | B43: =milestone_4day_new!B9 -> 1600 | C43: =milestone_4day_new!C9 -> 3810 | D43: =milestone_4day_new!D9 -> TRUE | E43: =IFERROR(IF(CEILING($C43*4/data_raw_4_day!$F$3,1)>4,"X","D"&CEILING($C43*4/data_raw_4_day!$F$3,1)),"X") -> X | F43: =IFERROR(IF(CEILING($C43*4/data_raw_4_day!$F$4,1)>4,"X","D"&CEILING($C43*4/data_raw_4_day!$F$4,1)),"X") -> D2 | G43: =IFERROR(IF(CEILING($C43*4/data_raw_4_day!$F$5,1)>4,"X","D"&CEILING($C43*4/data_raw_4_day!$F$5,1)),"X") -> D1 | H43: =IFERROR(IF(CEILING($C43*4/data_raw_4_day!$F$6,1)>4,"X","D"&CEILING($C43*4/data_raw_4_day!$F$6,1)),"X") -> D1 | I43: =IFERROR(IF(CEILING($C43*4/data_raw_4_day!$F$7,1)>4,"X","D"&CEILING($C43*4/data_raw_4_day!$F$7,1)),"X") -> D1 | J43: =IFERROR(IF(CEILING($C43*4/data_raw_4_day!$F$9,1)>4,"X","D"&CEILING($C43*4/data_raw_4_day!$F$9,1)),"X") -> X | K43: =IFERROR(IF(CEILING($C43*4/data_raw_4_day!$F$10,1)>4,"X","D"&CEILING($C43*4/data_raw_4_day!$F$10,1)),"X") -> D2 | L43: =IFERROR(IF(CEILING($C43*4/data_raw_4_day!$F$11,1)>4,"X","D"&CEILING($C43*4/data_raw_4_day!$F$11,1)),"X") -> D1 | M43: =IFERROR(IF(CEILING($C43*4/data_raw_4_day!$F$12,1)>4,"X","D"&CEILING($C43*4/data_raw_4_day!$F$12,1)),"X") -> D1 | N43: =IFERROR(IF(CEILING($C43*4/data_raw_4_day!$F$13,1)>4,"X","D"&CEILING($C43*4/data_raw_4_day!$F$13,1)),"X") -> D1
A44: =milestone_4day_new!A10 -> 7 | B44: =milestone_4day_new!B10 -> 500 | C44: =milestone_4day_new!C10 -> 4310 | D44: =milestone_4day_new!D10 -> FALSE | E44: =IFERROR(IF(CEILING($C44*4/data_raw_4_day!$F$3,1)>4,"X","D"&CEILING($C44*4/data_raw_4_day!$F$3,1)),"X") -> X | F44: =IFERROR(IF(CEILING($C44*4/data_raw_4_day!$F$4,1)>4,"X","D"&CEILING($C44*4/data_raw_4_day!$F$4,1)),"X") -> D2 | G44: =IFERROR(IF(CEILING($C44*4/data_raw_4_day!$F$5,1)>4,"X","D"&CEILING($C44*4/data_raw_4_day!$F$5,1)),"X") -> D1 | H44: =IFERROR(IF(CEILING($C44*4/data_raw_4_day!$F$6,1)>4,"X","D"&CEILING($C44*4/data_raw_4_day!$F$6,1)),"X") -> D1 | I44: =IFERROR(IF(CEILING($C44*4/data_raw_4_day!$F$7,1)>4,"X","D"&CEILING($C44*4/data_raw_4_day!$F$7,1)),"X") -> D1 | J44: =IFERROR(IF(CEILING($C44*4/data_raw_4_day!$F$9,1)>4,"X","D"&CEILING($C44*4/data_raw_4_day!$F$9,1)),"X") -> X | K44: =IFERROR(IF(CEILING($C44*4/data_raw_4_day!$F$10,1)>4,"X","D"&CEILING($C44*4/data_raw_4_day!$F$10,1)),"X") -> D2 | L44: =IFERROR(IF(CEILING($C44*4/data_raw_4_day!$F$11,1)>4,"X","D"&CEILING($C44*4/data_raw_4_day!$F$11,1)),"X") -> D1 | M44: =IFERROR(IF(CEILING($C44*4/data_raw_4_day!$F$12,1)>4,"X","D"&CEILING($C44*4/data_raw_4_day!$F$12,1)),"X") -> D1 | N44: =IFERROR(IF(CEILING($C44*4/data_raw_4_day!$F$13,1)>4,"X","D"&CEILING($C44*4/data_raw_4_day!$F$13,1)),"X") -> D1
A45: =milestone_4day_new!A11 -> 8 | B45: =milestone_4day_new!B11 -> 1000 | C45: =milestone_4day_new!C11 -> 5310 | D45: =milestone_4day_new!D11 -> FALSE | E45: =IFERROR(IF(CEILING($C45*4/data_raw_4_day!$F$3,1)>4,"X","D"&CEILING($C45*4/data_raw_4_day!$F$3,1)),"X") -> X | F45: =IFERROR(IF(CEILING($C45*4/data_raw_4_day!$F$4,1)>4,"X","D"&CEILING($C45*4/data_raw_4_day!$F$4,1)),"X") -> D3 | G45: =IFERROR(IF(CEILING($C45*4/data_raw_4_day!$F$5,1)>4,"X","D"&CEILING($C45*4/data_raw_4_day!$F$5,1)),"X") -> D2 | H45: =IFERROR(IF(CEILING($C45*4/data_raw_4_day!$F$6,1)>4,"X","D"&CEILING($C45*4/data_raw_4_day!$F$6,1)),"X") -> D1 | I45: =IFERROR(IF(CEILING($C45*4/data_raw_4_day!$F$7,1)>4,"X","D"&CEILING($C45*4/data_raw_4_day!$F$7,1)),"X") -> D1 | J45: =IFERROR(IF(CEILING($C45*4/data_raw_4_day!$F$9,1)>4,"X","D"&CEILING($C45*4/data_raw_4_day!$F$9,1)),"X") -> X | K45: =IFERROR(IF(CEILING($C45*4/data_raw_4_day!$F$10,1)>4,"X","D"&CEILING($C45*4/data_raw_4_day!$F$10,1)),"X") -> D3 | L45: =IFERROR(IF(CEILING($C45*4/data_raw_4_day!$F$11,1)>4,"X","D"&CEILING($C45*4/data_raw_4_day!$F$11,1)),"X") -> D2 | M45: =IFERROR(IF(CEILING($C45*4/data_raw_4_day!$F$12,1)>4,"X","D"&CEILING($C45*4/data_raw_4_day!$F$12,1)),"X") -> D1 | N45: =IFERROR(IF(CEILING($C45*4/data_raw_4_day!$F$13,1)>4,"X","D"&CEILING($C45*4/data_raw_4_day!$F$13,1)),"X") -> D1
A46: =milestone_4day_new!A12 -> 9 | B46: =milestone_4day_new!B12 -> 3300 | C46: =milestone_4day_new!C12 -> 8610 | D46: =milestone_4day_new!D12 -> TRUE | E46: =IFERROR(IF(CEILING($C46*4/data_raw_4_day!$F$3,1)>4,"X","D"&CEILING($C46*4/data_raw_4_day!$F$3,1)),"X") -> X | F46: =IFERROR(IF(CEILING($C46*4/data_raw_4_day!$F$4,1)>4,"X","D"&CEILING($C46*4/data_raw_4_day!$F$4,1)),"X") -> D4 | G46: =IFERROR(IF(CEILING($C46*4/data_raw_4_day!$F$5,1)>4,"X","D"&CEILING($C46*4/data_raw_4_day!$F$5,1)),"X") -> D2 | H46: =IFERROR(IF(CEILING($C46*4/data_raw_4_day!$F$6,1)>4,"X","D"&CEILING($C46*4/data_raw_4_day!$F$6,1)),"X") -> D1 | I46: =IFERROR(IF(CEILING($C46*4/data_raw_4_day!$F$7,1)>4,"X","D"&CEILING($C46*4/data_raw_4_day!$F$7,1)),"X") -> D1 | J46: =IFERROR(IF(CEILING($C46*4/data_raw_4_day!$F$9,1)>4,"X","D"&CEILING($C46*4/data_raw_4_day!$F$9,1)),"X") -> X | K46: =IFERROR(IF(CEILING($C46*4/data_raw_4_day!$F$10,1)>4,"X","D"&CEILING($C46*4/data_raw_4_day!$F$10,1)),"X") -> D4 | L46: =IFERROR(IF(CEILING($C46*4/data_raw_4_day!$F$11,1)>4,"X","D"&CEILING($C46*4/data_raw_4_day!$F$11,1)),"X") -> D2 | M46: =IFERROR(IF(CEILING($C46*4/data_raw_4_day!$F$12,1)>4,"X","D"&CEILING($C46*4/data_raw_4_day!$F$12,1)),"X") -> D1 | N46: =IFERROR(IF(CEILING($C46*4/data_raw_4_day!$F$13,1)>4,"X","D"&CEILING($C46*4/data_raw_4_day!$F$13,1)),"X") -> D1
A47: =milestone_4day_new!A13 -> 10 | B47: =milestone_4day_new!B13 -> 1100 | C47: =milestone_4day_new!C13 -> 9710 | D47: =milestone_4day_new!D13 -> FALSE | E47: =IFERROR(IF(CEILING($C47*4/data_raw_4_day!$F$3,1)>4,"X","D"&CEILING($C47*4/data_raw_4_day!$F$3,1)),"X") -> X | F47: =IFERROR(IF(CEILING($C47*4/data_raw_4_day!$F$4,1)>4,"X","D"&CEILING($C47*4/data_raw_4_day!$F$4,1)),"X") -> X | G47: =IFERROR(IF(CEILING($C47*4/data_raw_4_day!$F$5,1)>4,"X","D"&CEILING($C47*4/data_raw_4_day!$F$5,1)),"X") -> D3 | H47: =IFERROR(IF(CEILING($C47*4/data_raw_4_day!$F$6,1)>4,"X","D"&CEILING($C47*4/data_raw_4_day!$F$6,1)),"X") -> D1 | I47: =IFERROR(IF(CEILING($C47*4/data_raw_4_day!$F$7,1)>4,"X","D"&CEILING($C47*4/data_raw_4_day!$F$7,1)),"X") -> D1 | J47: =IFERROR(IF(CEILING($C47*4/data_raw_4_day!$F$9,1)>4,"X","D"&CEILING($C47*4/data_raw_4_day!$F$9,1)),"X") -> X | K47: =IFERROR(IF(CEILING($C47*4/data_raw_4_day!$F$10,1)>4,"X","D"&CEILING($C47*4/data_raw_4_day!$F$10,1)),"X") -> D4 | L47: =IFERROR(IF(CEILING($C47*4/data_raw_4_day!$F$11,1)>4,"X","D"&CEILING($C47*4/data_raw_4_day!$F$11,1)),"X") -> D2 | M47: =IFERROR(IF(CEILING($C47*4/data_raw_4_day!$F$12,1)>4,"X","D"&CEILING($C47*4/data_raw_4_day!$F$12,1)),"X") -> D1 | N47: =IFERROR(IF(CEILING($C47*4/data_raw_4_day!$F$13,1)>4,"X","D"&CEILING($C47*4/data_raw_4_day!$F$13,1)),"X") -> D1
A48: =milestone_4day_new!A14 -> 11 | B48: =milestone_4day_new!B14 -> 2200 | C48: =milestone_4day_new!C14 -> 11910 | D48: =milestone_4day_new!D14 -> FALSE | E48: =IFERROR(IF(CEILING($C48*4/data_raw_4_day!$F$3,1)>4,"X","D"&CEILING($C48*4/data_raw_4_day!$F$3,1)),"X") -> X | F48: =IFERROR(IF(CEILING($C48*4/data_raw_4_day!$F$4,1)>4,"X","D"&CEILING($C48*4/data_raw_4_day!$F$4,1)),"X") -> X | G48: =IFERROR(IF(CEILING($C48*4/data_raw_4_day!$F$5,1)>4,"X","D"&CEILING($C48*4/data_raw_4_day!$F$5,1)),"X") -> D3 | H48: =IFERROR(IF(CEILING($C48*4/data_raw_4_day!$F$6,1)>4,"X","D"&CEILING($C48*4/data_raw_4_day!$F$6,1)),"X") -> D2 | I48: =IFERROR(IF(CEILING($C48*4/data_raw_4_day!$F$7,1)>4,"X","D"&CEILING($C48*4/data_raw_4_day!$F$7,1)),"X") -> D1 | J48: =IFERROR(IF(CEILING($C48*4/data_raw_4_day!$F$9,1)>4,"X","D"&CEILING($C48*4/data_raw_4_day!$F$9,1)),"X") -> X | K48: =IFERROR(IF(CEILING($C48*4/data_raw_4_day!$F$10,1)>4,"X","D"&CEILING($C48*4/data_raw_4_day!$F$10,1)),"X") -> X | L48: =IFERROR(IF(CEILING($C48*4/data_raw_4_day!$F$11,1)>4,"X","D"&CEILING($C48*4/data_raw_4_day!$F$11,1)),"X") -> D3 | M48: =IFERROR(IF(CEILING($C48*4/data_raw_4_day!$F$12,1)>4,"X","D"&CEILING($C48*4/data_raw_4_day!$F$12,1)),"X") -> D2 | N48: =IFERROR(IF(CEILING($C48*4/data_raw_4_day!$F$13,1)>4,"X","D"&CEILING($C48*4/data_raw_4_day!$F$13,1)),"X") -> D1
