Workbook

Sheet Sim per Segment
B2: NS Streak Increase Multiplier: | C2: 1.05
C4: Daily HC Gain | Q4: Spend & Net (data) | Y4: P25 | AN4: P50 | BC4: P75 | BR4: P90
B5: Segment | C5: avg_attempts (data) | D5: avg_completes (data) | E5: current gain (data) | F5: saga old (data) | G5: dr old (data) | H5: gain w/o saga & dr & NS (data) | I5: saga new (sim) | J5: dr new (sim) | K5: P_completing_R1 (sim) | L5: P_completing_R2 (sim) | M5: P_completing_R3 (sim) | N5: NS new (sim) | O5: Total Sim Gain (calc) | Q5: spend (data) | R5: net (data) (calc) | S5: streak (data) | T5: streak increase (sim) | U5: slope | V5: net (sim) | W5: net (sim) - with no hc spend change | Y5: Cur Streak (data) | Z5: Cur Gain (data) | AA5: Cur Spend (data) | AB5: Cur Net (data) | AC5: Cur Saga (data) | AD5: New Streak (sim) | AE5: New Gain (sim) | AF5: New Spend (sim) | AG5: New Net (auto) | AH5: New Saga (sim) | AI5: diff Net | AJ5: diff Streak | AK5: diff Saga | AL5: diff Spend | AN5: Cur Streak (data) | AO5: Cur Gain (data) | AP5: Cur Spend (data) | AQ5: Cur Net (data) | AR5: Cur Saga (data) | AS5: New Streak (sim) | AT5: New Gain (sim) | AU5: New Spend (sim) | AV5: New Net (auto) | AW5: New Saga (sim) | AX5: diff Net | AY5: diff Streak | AZ5: diff Saga | BA5: diff Spend | BC5: Cur Streak (data) | BD5: Cur Gain (data) | BE5: Cur Spend (data) | BF5: Cur Net (data) | BG5: Cur Saga (data) | BH5: New Streak (sim) | BI5: New Gain (sim) | BJ5: New Spend (sim) | BK5: New Net (auto) | BL5: New Saga (sim) | BM5: diff Net | BN5: diff Streak | BO5: diff Saga | BP5: diff Spend | BR5: Cur Streak (data) | BS5: Cur Gain (data) | BT5: Cur Spend (data) | BU5: Cur Net (data) | BV5: Cur Saga (data) | BW5: New Streak (sim) | BX5: New Gain (sim) | BY5: New Spend (sim) | BZ5: New Net (auto) | CA5: New Saga (sim) | CB5: diff Net | CC5: diff Streak | CD5: diff Saga | CE5: diff Spend
B6: NONPAYER
B7: 0-9 | C7: =data_processed!E2 -> 13.799245 | D7: =data_processed!G2 -> 5.6785639 | E7: =data_processed!H2 -> 55.056721 | F7: =data_processed!I2 -> 11.09847 | G7: =data_processed!X2 -> 19.725437 | H7: =data_processed!J2 -> 43.958595 | I7: =IFERROR(D7*saga_progression_new!$C17,"") -> 4.258923 | J7: =IFERROR(daily_rewards_new!$B$13*data_processed!Y2,"") -> 13.862335 | K7: =data_processed!L2 -> 0.73165776 | L7: =data_processed!M2 -> 0.30928374 | M7: =data_processed!N2 -> 0.086116813 | N7: =IFERROR(K7*ns_new!$F$5+L7*ns_new!$F$6+M7*ns_new!$F$7,"") -> 4.3845896 | O7: =IFERROR(H7+I7+N7+J7,"") -> 66.464443 | Q7: =data_processed!K2 -> 53.732503 | R7: =IFERROR(E7-Q7,"") -> 1.3242183 | S7: =data_processed!W2 -> 4.0143096 | T7: =IFERROR(S7*($C$2-1),"") -> 0.20071548 | U7: =data_processed!R2 -> 17.833 | V7: =IFERROR(O7-(Q7+U7*T7),"") -> 9.1525809 | W7: =IFERROR(O7-Q7,"") -> 12.73194 | Y7: =SUMPRODUCT((data_segment_HC_gains!$A$48:$A$67="0-9")*(data_segment_HC_gains!$B$48:$B$67="p25")*data_segment_HC_gains!$C$48:$C$67) -> 0 | Z7: =SUMPRODUCT((data_segment_HC_gains!$A$48:$A$67="0-9")*(data_segment_HC_gains!$B$48:$B$67="p25")*data_segment_HC_gains!$E$48:$E$67) -> 22 | AA7: =SUMPRODUCT((data_raw_slopes!$A$2:$A$41="0-9")*(data_raw_slopes!$B$2:$B$41="nonpayer")*(data_raw_slopes!$C$2:$C$41="p25")*data_raw_slopes!$E$2:$E$41) -> 2.03 | AB7: =Z7-AA7 -> 19.97 | AC7: =SUMPRODUCT((data_segment_HC_gains!$A$48:$A$67="0-9")*(data_segment_HC_gains!$B$48:$B$67="p25")*data_segment_HC_gains!$G$48:$G$67) -> 0.16 | AD7: =Y7*1.15 -> 0 | AE7: =Z7-AC7*(1-(saga_progression_new!$C$17/saga_progression_old!$C$16))+IF(Y7<ns_new!$E$5,0,IF(Y7*1.25<ns_new!$E$6-ns_new!$E$5,ns_new!$F$5,IF(Y7*1.25^2<ns_new!$E$7-ns_new!$E$6,ns_new!$F$5+ns_new!$F$6,ns_new!$F$5+ns_new!$F$6+ns_new!$F$7))) -> 21.897143 | AF7: =AA7+(IF(SUMPRODUCT((data_raw_slopes!$A$2:$A$41="0-9")*(data_raw_slopes!$B$2:$B$41="nonpayer")*(data_raw_slopes!$C$2:$C$41="p25")*data_raw_slopes!$F$2:$F$41)>0,SUMPRODUCT((data_raw_slopes!$A$2:$A$41="0-9")*(data_raw_slopes!$B$2:$B$41="nonpayer")*(data_raw_slopes!$C$2:$C$41="p25")*data_raw_slopes!$F$2:$F$41),SUMPRODUCT((data_raw_slopes!$A$2:$A$41="0-9")*(data_raw_slopes!$B$2:$B$41="nonpayer")*(data_raw_slopes!$C$2:$C$41="p25")*data_raw_slopes!$G$2:$G$41)))*Y7*0.15 -> 2.03 | AG7: =AE7-AF7 -> 19.867143 | AH7: =AC7*(saga_progression_new!$C$17/saga_progression_old!$C$16) -> 0.057142857 | AI7: =AG7-AB7 -> -0.10285714 | AJ7: =AD7-Y7 -> 0 | AK7: =AH7-AC7 -> -0.10285714 | AL7: =AF7-AA7 -> 0 | AN7: =SUMPRODUCT((data_segment_HC_gains!$A$48:$A$67="0-9")*(data_segment_HC_gains!$B$48:$B$67="p50")*data_segment_HC_gains!$C$48:$C$67) -> 1 | AO7: =SUMPRODUCT((data_segment_HC_gains!$A$48:$A$67="0-9")*(data_segment_HC_gains!$B$48:$B$67="p50")*data_segment_HC_gains!$E$48:$E$67) -> 28.55 | AP7: =SUMPRODUCT((data_raw_slopes!$A$2:$A$41="0-9")*(data_raw_slopes!$B$2:$B$41="nonpayer")*(data_raw_slopes!$C$2:$C$41="p50")*data_raw_slopes!$E$2:$E$41) -> 20.5 | AQ7: =AO7-AP7 -> 8.05 | AR7: =SUMPRODUCT((data_segment_HC_gains!$A$48:$A$67="0-9")*(data_segment_HC_gains!$B$48:$B$67="p50")*data_segment_HC_gains!$G$48:$G$67) -> 2.2 | AS7: =AN7*1.15 -> 1.15 | AT7: =AO7-AR7*(1-(saga_progression_new!$C$17/saga_progression_old!$C$16))+IF(AN7<ns_new!$E$5,0,IF(AN7*1.25<ns_new!$E$6-ns_new!$E$5,ns_new!$F$5,IF(AN7*1.25^2<ns_new!$E$7-ns_new!$E$6,ns_new!$F$5+ns_new!$F$6,ns_new!$F$5+ns_new!$F$6+ns_new!$F$7))) -> 27.135714 | AU7: =AP7+(IF(SUMPRODUCT((data_raw_slopes!$A$2:$A$41="0-9")*(data_raw_slopes!$B$2:$B$41="nonpayer")*(data_raw_slopes!$C$2:$C$41="p50")*data_raw_slopes!$F$2:$F$41)>0,SUMPRODUCT((data_raw_slopes!$A$2:$A$41="0-9")*(data_raw_slopes!$B$2:$B$41="nonpayer")*(data_raw_slopes!$C$2:$C$41="p50")*data_raw_slopes!$F$2:$F$41),SUMPRODUCT((data_raw_slopes!$A$2:$A$41="0-9")*(data_raw_slopes!$B$2:$B$41="nonpayer")*(data_raw_slopes!$C$2:$C$41="p50")*data_raw_slopes!$G$2:$G$41)))*AN7*0.15 -> 23.17495 | AV7: =AT7-AU7 -> 3.9607643 | AW7: =AR7*(saga_progression_new!$C$17/saga_progression_old!$C$16) -> 0.78571429 | AX7: =AV7-AQ7 -> -4.0892357 | AY7: =AS7-AN7 -> 0.15 | AZ7: =AW7-AR7 -> -1.4142857 | BA7: =AU7-AP7 -> 2.67495 | BC7: =SUMPRODUCT((data_segment_HC_gains!$A$48:$A$67="0-9")*(data_segment_HC_gains!$B$48:$B$67="p75")*data_segment_HC_gains!$C$48:$C$67) -> 3 | BD7: =SUMPRODUCT((data_segment_HC_gains!$A$48:$A$67="0-9")*(data_segment_HC_gains!$B$48:$B$67="p75")*data_segment_HC_gains!$E$48:$E$67) -> 46.44 | BE7: =SUMPRODUCT((data_raw_slopes!$A$2:$A$41="0-9")*(data_raw_slopes!$B$2:$B$41="nonpayer")*(data_raw_slopes!$C$2:$C$41="p75")*data_raw_slopes!$E$2:$E$41) -> 43.7 | BF7: =BD7-BE7 -> 2.74 | BG7: =SUMPRODUCT((data_segment_HC_gains!$A$48:$A$67="0-9")*(data_segment_HC_gains!$B$48:$B$67="p75")*data_segment_HC_gains!$G$48:$G$67) -> 8.05 | BH7: =BC7*1.15 -> 3.45 | BI7: =BD7-BG7*(1-(saga_progression_new!$C$17/saga_progression_old!$C$16))+IF(BC7<ns_new!$E$5,0,IF(BC7*1.25<ns_new!$E$6-ns_new!$E$5,ns_new!$F$5,IF(BC7*1.25^2<ns_new!$E$7-ns_new!$E$6,ns_new!$F$5+ns_new!$F$6,ns_new!$F$5+ns_new!$F$6+ns_new!$F$7))) -> 51.265 | BJ7: =BE7+(IF(SUMPRODUCT((data_raw_slopes!$A$2:$A$41="0-9")*(data_raw_slopes!$B$2:$B$41="nonpayer")*(data_raw_slopes!$C$2:$C$41="p75")*data_raw_slopes!$F$2:$F$41)>0,SUMPRODUCT((data_raw_slopes!$A$2:$A$41="0-9")*(data_raw_slopes!$B$2:$B$41="nonpayer")*(data_raw_slopes!$C$2:$C$41="p75")*data_raw_slopes!$F$2:$F$41),SUMPRODUCT((data_raw_slopes!$A$2:$A$41="0-9")*(data_raw_slopes!$B$2:$B$41="nonpayer")*(data_raw_slopes!$C$2:$C$41="p75")*data_raw_slopes!$G$2:$G$41)))*BC7*0.15 -> 47.582735 | BK7: =BI7-BJ7 -> 3.682265 | BL7: =BG7*(saga_progression_new!$C$17/saga_progression_old!$C$16) -> 2.875 | BM7: =BK7-BF7 -> 0.942265 | BN7: =BH7-BC7 -> 0.45 | BO7: =BL7-BG7 -> -5.175 | BP7: =BJ7-BE7 -> 3.882735 | BR7: =SUMPRODUCT((data_segment_HC_gains!$A$48:$A$67="0-9")*(data_segment_HC_gains!$B$48:$B$67="p90")*data_segment_HC_gains!$C$48:$C$67) -> 7 | BS7: =SUMPRODUCT((data_segment_HC_gains!$A$48:$A$67="0-9")*(data_segment_HC_gains!$B$48:$B$67="p90")*data_segment_HC_gains!$E$48:$E$67) -> 64.94 | BT7: =SUMPRODUCT((data_raw_slopes!$A$2:$A$41="0-9")*(data_raw_slopes!$B$2:$B$41="nonpayer")*(data_raw_slopes!$C$2:$C$41="p90")*data_raw_slopes!$E$2:$E$41) -> 79.1 | BU7: =BS7-BT7 -> -14.16 | BV7: =SUMPRODUCT((data_segment_HC_gains!$A$48:$A$67="0-9")*(data_segment_HC_gains!$B$48:$B$67="p90")*data_segment_HC_gains!$G$48:$G$67) -> 15.63 | BW7: =BR7*1.15 -> 8.05 | BX7: =BS7-BV7*(1-(saga_progression_new!$C$17/saga_progression_old!$C$16))+IF(BR7<ns_new!$E$5,0,IF(BR7*1.25<ns_new!$E$6-ns_new!$E$5,ns_new!$F$5,IF(BR7*1.25^2<ns_new!$E$7-ns_new!$E$6,ns_new!$F$5+ns_new!$F$6,ns_new!$F$5+ns_new!$F$6+ns_new!$F$7))) -> 79.892143 | BY7: =BT7+(IF(SUMPRODUCT((data_raw_slopes!$A$2:$A$41="0-9")*(data_raw_slopes!$B$2:$B$41="nonpayer")*(data_raw_slopes!$C$2:$C$41="p90")*data_raw_slopes!$F$2:$F$41)>0,SUMPRODUCT((data_raw_slopes!$A$2:$A$41="0-9")*(data_raw_slopes!$B$2:$B$41="nonpayer")*(data_raw_slopes!$C$2:$C$41="p90")*data_raw_slopes!$F$2:$F$41),SUMPRODUCT((data_raw_slopes!$A$2:$A$41="0-9")*(data_raw_slopes!$B$2:$B$41="nonpayer")*(data_raw_slopes!$C$2:$C$41="p90")*data_raw_slopes!$G$2:$G$41)))*BR7*0.15 -> 86.442125 | BZ7: =BX7-BY7 -> -6.5499821 | CA7: =BV7*(saga_progression_new!$C$17/saga_progression_old!$C$16) -> 5.5821429 | CB7: =BZ7-BU7 -> 7.6100179 | CC7: =BW7-BR7 -> 1.05 | CD7: =CA7-BV7 -> -10.047857 | CE7: =BY7-BT7 -> 7.342125
B8: 10-19 | C8: =data_processed!E3 -> 26.966064 | D8: =data_processed!G3 -> 14.385494 | E8: =data_processed!H3 -> 100.28446 | F8: =data_processed!I3 -> 27.60078 | G8: =data_processed!X3 -> 20.633988 | H8: =data_processed!J3 -> 72.683758 | I8: =IFERROR(D8*saga_progression_new!$E17,"") -> 10.789121 | J8: =IFERROR(daily_rewards_new!$B$13*data_processed!Y3,"") -> 15.685967 | K8: =data_processed!L3 -> 0.60927831 | L8: =data_processed!M3 -> 0.26257701 | M8: =data_processed!N3 -> 0.046402923 | N8: =IFERROR(K8*ns_new!$F$11+L8*ns_new!$F$12+M8*ns_new!$F$13,"") -> 16.754269 | O8: =IFERROR(H8+I8+N8+J8,"") -> 115.91311 | Q8: =data_processed!K3 -> 101.00605 | R8: =IFERROR(E8-Q8,"") -> -0.72159187 | S8: =data_processed!W3 -> 9.449237 | T8: =IFERROR(S8*($C$2-1),"") -> 0.47246185 | U8: =data_processed!R3 -> 5.3655 | V8: =IFERROR(O8-(Q8+U8*T8),"") -> 12.372066 | W8: =IFERROR(O8-Q8,"") -> 14.90706 | Y8: =SUMPRODUCT((data_segment_HC_gains!$A$48:$A$67="10-19")*(data_segment_HC_gains!$B$48:$B$67="p25")*data_segment_HC_gains!$C$48:$C$67) -> 3 | Z8: =SUMPRODUCT((data_segment_HC_gains!$A$48:$A$67="10-19")*(data_segment_HC_gains!$B$48:$B$67="p25")*data_segment_HC_gains!$E$48:$E$67) -> 73.44 | AA8: =SUMPRODUCT((data_raw_slopes!$A$2:$A$41="10-19")*(data_raw_slopes!$B$2:$B$41="nonpayer")*(data_raw_slopes!$C$2:$C$41="p25")*data_raw_slopes!$E$2:$E$41) -> 60.89 | AB8: =Z8-AA8 -> 12.55 | AC8: =SUMPRODUCT((data_segment_HC_gains!$A$48:$A$67="10-19")*(data_segment_HC_gains!$B$48:$B$67="p25")*data_segment_HC_gains!$G$48:$G$67) -> 16.36 | AD8: =Y8*1.15 -> 3.45 | AE8: =Z8-AC8*(1-(saga_progression_new!$E$17/saga_progression_old!$C$16))+IF(Y8<ns_new!$E$11,0,IF(Y8*1.25<ns_new!$E$12-ns_new!$E$11,ns_new!$F$11,IF(Y8*1.25^2<ns_new!$E$13-ns_new!$E$12,ns_new!$F$11+ns_new!$F$12,ns_new!$F$11+ns_new!$F$12+ns_new!$F$13))) -> 62.922857 | AF8: =AA8+(IF(SUMPRODUCT((data_raw_slopes!$A$2:$A$41="10-19")*(data_raw_slopes!$B$2:$B$41="nonpayer")*(data_raw_slopes!$C$2:$C$41="p25")*data_raw_slopes!$F$2:$F$41)>0,SUMPRODUCT((data_raw_slopes!$A$2:$A$41="10-19")*(data_raw_slopes!$B$2:$B$41="nonpayer")*(data_raw_slopes!$C$2:$C$41="p25")*data_raw_slopes!$F$2:$F$41),SUMPRODUCT((data_raw_slopes!$A$2:$A$41="10-19")*(data_raw_slopes!$B$2:$B$41="nonpayer")*(data_raw_slopes!$C$2:$C$41="p25")*data_raw_slopes!$G$2:$G$41)))*Y8*0.15 -> 65.834105 | AG8: =AE8-AF8 -> -2.9112479 | AH8: =AC8*(saga_progression_new!$E$17/saga_progression_old!$C$16) -> 5.8428571 | AI8: =AG8-AB8 -> -15.461248 | AJ8: =AD8-Y8 -> 0.45 | AK8: =AH8-AC8 -> -10.517143 | AL8: =AF8-AA8 -> 4.944105 | AN8: =SUMPRODUCT((data_segment_HC_gains!$A$48:$A$67="10-19")*(data_segment_HC_gains!$B$48:$B$67="p50")*data_segment_HC_gains!$C$48:$C$67) -> 7 | AO8: =SUMPRODUCT((data_segment_HC_gains!$A$48:$A$67="10-19")*(data_segment_HC_gains!$B$48:$B$67="p50")*data_segment_HC_gains!$E$48:$E$67) -> 92.78 | AP8: =SUMPRODUCT((data_raw_slopes!$A$2:$A$41="10-19")*(data_raw_slopes!$B$2:$B$41="nonpayer")*(data_raw_slopes!$C$2:$C$41="p50")*data_raw_slopes!$E$2:$E$41) -> 91.46 | AQ8: =AO8-AP8 -> 1.32 | AR8: =SUMPRODUCT((data_segment_HC_gains!$A$48:$A$67="10-19")*(data_segment_HC_gains!$B$48:$B$67="p50")*data_segment_HC_gains!$G$48:$G$67) -> 24.86 | AS8: =AN8*1.15 -> 8.05 | AT8: =AO8-AR8*(1-(saga_progression_new!$E$17/saga_progression_old!$C$16))+IF(AN8<ns_new!$E$11,0,IF(AN8*1.25<ns_new!$E$12-ns_new!$E$11,ns_new!$F$11,IF(AN8*1.25^2<ns_new!$E$13-ns_new!$E$12,ns_new!$F$11+ns_new!$F$12,ns_new!$F$11+ns_new!$F$12+ns_new!$F$13))) -> 116.79857 | AU8: =AP8+(IF(SUMPRODUCT((data_raw_slopes!$A$2:$A$41="10-19")*(data_raw_slopes!$B$2:$B$41="nonpayer")*(data_raw_slopes!$C$2:$C$41="p50")*data_raw_slopes!$F$2:$F$41)>0,SUMPRODUCT((data_raw_slopes!$A$2:$A$41="10-19")*(data_raw_slopes!$B$2:$B$41="nonpayer")*(data_raw_slopes!$C$2:$C$41="p50")*data_raw_slopes!$F$2:$F$41),SUMPRODUCT((data_raw_slopes!$A$2:$A$41="10-19")*(data_raw_slopes!$B$2:$B$41="nonpayer")*(data_raw_slopes!$C$2:$C$41="p50")*data_raw_slopes!$G$2:$G$41)))*AN8*0.15 -> 97.093775 | AV8: =AT8-AU8 -> 19.704796 | AW8: =AR8*(saga_progression_new!$E$17/saga_progression_old!$C$16) -> 8.8785714 | AX8: =AV8-AQ8 -> 18.384796 | AY8: =AS8-AN8 -> 1.05 | AZ8: =AW8-AR8 -> -15.981429 | BA8: =AU8-AP8 -> 5.633775 | BC8: =SUMPRODUCT((data_segment_HC_gains!$A$48:$A$67="10-19")*(data_segment_HC_gains!$B$48:$B$67="p75")*data_segment_HC_gains!$C$48:$C$67) -> 13 | BD8: =SUMPRODUCT((data_segment_HC_gains!$A$48:$A$67="10-19")*(data_segment_HC_gains!$B$48:$B$67="p75")*data_segment_HC_gains!$E$48:$E$67) -> 104.9 | BE8: =SUMPRODUCT((data_raw_slopes!$A$2:$A$41="10-19")*(data_raw_slopes!$B$2:$B$41="nonpayer")*(data_raw_slopes!$C$2:$C$41="p75")*data_raw_slopes!$E$2:$E$41) -> 115.5 | BF8: =BD8-BE8 -> -10.6 | BG8: =SUMPRODUCT((data_segment_HC_gains!$A$48:$A$67="10-19")*(data_segment_HC_gains!$B$48:$B$67="p75")*data_segment_HC_gains!$G$48:$G$67) -> 31.52 | BH8: =BC8*1.15 -> 14.95 | BI8: =BD8-BG8*(1-(saga_progression_new!$E$17/saga_progression_old!$C$16))+IF(BC8<ns_new!$E$11,0,IF(BC8*1.25<ns_new!$E$12-ns_new!$E$11,ns_new!$F$11,IF(BC8*1.25^2<ns_new!$E$13-ns_new!$E$12,ns_new!$F$11+ns_new!$F$12,ns_new!$F$11+ns_new!$F$12+ns_new!$F$13))) -> 184.63714 | BJ8: =BE8+(IF(SUMPRODUCT((data_raw_slopes!$A$2:$A$41="10-19")*(data_raw_slopes!$B$2:$B$41="nonpayer")*(data_raw_slopes!$C$2:$C$41="p75")*data_raw_slopes!$F$2:$F$41)>0,SUMPRODUCT((data_raw_slopes!$A$2:$A$41="10-19")*(data_raw_slopes!$B$2:$B$41="nonpayer")*(data_raw_slopes!$C$2:$C$41="p75")*data_raw_slopes!$F$2:$F$41),SUMPRODUCT((data_raw_slopes!$A$2:$A$41="10-19")*(data_raw_slopes!$B$2:$B$41="nonpayer")*(data_raw_slopes!$C$2:$C$41="p75")*data_raw_slopes!$G$2:$G$41)))*BC8*0.15 -> 127.11557 | BK8: =BI8-BJ8 -> 57.521578 | BL8: =BG8*(saga_progression_new!$E$17/saga_progression_old!$C$16) -> 11.257143 | BM8: =BK8-BF8 -> 68.121578 | BN8: =BH8-BC8 -> 1.95 | BO8: =BL8-BG8 -> -20.262857 | BP8: =BJ8-BE8 -> 11.615565 | BR8: =SUMPRODUCT((data_segment_HC_gains!$A$48:$A$67="10-19")*(data_segment_HC_gains!$B$48:$B$67="p90")*data_segment_HC_gains!$C$48:$C$67) -> 19 | BS8: =SUMPRODUCT((data_segment_HC_gains!$A$48:$A$67="10-19")*(data_segment_HC_gains!$B$48:$B$67="p90")*data_segment_HC_gains!$E$48:$E$67) -> 142.33 | BT8: =SUMPRODUCT((data_raw_slopes!$A$2:$A$41="10-19")*(data_raw_slopes!$B$2:$B$41="nonpayer")*(data_raw_slopes!$C$2:$C$41="p90")*data_raw_slopes!$E$2:$E$41) -> 170.28 | BU8: =BS8-BT8 -> -27.95 | BV8: =SUMPRODUCT((data_segment_HC_gains!$A$48:$A$67="10-19")*(data_segment_HC_gains!$B$48:$B$67="p90")*data_segment_HC_gains!$G$48:$G$67) -> 45.45 | BW8: =BR8*1.15 -> 21.85 | BX8: =BS8-BV8*(1-(saga_progression_new!$E$17/saga_progression_old!$C$16))+IF(BR8<ns_new!$E$11,0,IF(BR8*1.25<ns_new!$E$12-ns_new!$E$11,ns_new!$F$11,IF(BR8*1.25^2<ns_new!$E$13-ns_new!$E$12,ns_new!$F$11+ns_new!$F$12,ns_new!$F$11+ns_new!$F$12+ns_new!$F$13))) -> 213.11214 | BY8: =BT8+(IF(SUMPRODUCT((data_raw_slopes!$A$2:$A$41="10-19")*(data_raw_slopes!$B$2:$B$41="nonpayer")*(data_raw_slopes!$C$2:$C$41="p90")*data_raw_slopes!$F$2:$F$41)>0,SUMPRODUCT((data_raw_slopes!$A$2:$A$41="10-19")*(data_raw_slopes!$B$2:$B$41="nonpayer")*(data_raw_slopes!$C$2:$C$41="p90")*data_raw_slopes!$F$2:$F$41),SUMPRODUCT((data_raw_slopes!$A$2:$A$41="10-19")*(data_raw_slopes!$B$2:$B$41="nonpayer")*(data_raw_slopes!$C$2:$C$41="p90")*data_raw_slopes!$G$2:$G$41)))*BR8*0.15 -> 188.74144 | BZ8: =BX8-BY8 -> 24.370698 | CA8: =BV8*(saga_progression_new!$E$17/saga_progression_old!$C$16) -> 16.232143 | CB8: =BZ8-BU8 -> 52.320698 | CC8: =BW8-BR8 -> 2.85 | CD8: =CA8-BV8 -> -29.217857 | CE8: =BY8-BT8 -> 18.461445
B9: 20-39 | C9: =data_processed!E4 -> 41.841104 | D9: =data_processed!G4 -> 27.709983 | E9: =data_processed!H4 -> 170.38752 | F9: =data_processed!I4 -> 53.237215 | G9: =data_processed!X4 -> 20.949968 | H9: =data_processed!J4 -> 117.15079 | I9: =IFERROR(D9*saga_progression_new!$G17,"") -> 20.782488 | J9: =IFERROR(daily_rewards_new!$B$13*data_processed!Y4,"") -> 16.138901 | K9: =data_processed!L4 -> 0.61092145 | L9: =data_processed!M4 -> 0.23962887 | M9: =data_processed!N4 -> 0.069363634 | N9: =IFERROR(K9*ns_new!$F$17+L9*ns_new!$F$18+M9*ns_new!$F$19,"") -> 28.081629 | O9: =IFERROR(H9+I9+N9+J9,"") -> 182.1538 | Q9: =data_processed!K4 -> 174.98742 | R9: =IFERROR(E9-Q9,"") -> -4.5999022 | S9: =data_processed!W4 -> 18.0621 | T9: =IFERROR(S9*($C$2-1),"") -> 0.90310502 | U9: =data_processed!R4 -> 5.6273 | V9: =IFERROR(O9-(Q9+U9*T9),"") -> 2.0843377 | W9: =IFERROR(O9-Q9,"") -> 7.1663806 | Y9: =SUMPRODUCT((data_segment_HC_gains!$A$48:$A$67="20-39")*(data_segment_HC_gains!$B$48:$B$67="p25")*data_segment_HC_gains!$C$48:$C$67) -> 7 | Z9: =SUMPRODUCT((data_segment_HC_gains!$A$48:$A$67="20-39")*(data_segment_HC_gains!$B$48:$B$67="p25")*data_segment_HC_gains!$E$48:$E$67) -> 122.95 | AA9: =SUMPRODUCT((data_raw_slopes!$A$2:$A$41="20-39")*(data_raw_slopes!$B$2:$B$41="nonpayer")*(data_raw_slopes!$C$2:$C$41="p25")*data_raw_slopes!$E$2:$E$41) -> 106.9 | AB9: =Z9-AA9 -> 16.05 | AC9: =SUMPRODUCT((data_segment_HC_gains!$A$48:$A$67="20-39")*(data_segment_HC_gains!$B$48:$B$67="p25")*data_segment_HC_gains!$G$48:$G$67) -> 34.28 | AD9: =Y9*1.15 -> 8.05 | AE9: =Z9-AC9*(1-(saga_progression_new!$G$17/saga_progression_old!$C$16))+IF(Y9<ns_new!$E$17,0,IF(Y9*1.25<ns_new!$E$18-ns_new!$E$17,ns_new!$F$17,IF(Y9*1.25^2<ns_new!$E$19-ns_new!$E$18,ns_new!$F$17+ns_new!$F$18,ns_new!$F$17+ns_new!$F$18+ns_new!$F$19))) -> 100.91286 | AF9: =AA9+(IF(SUMPRODUCT((data_raw_slopes!$A$2:$A$41="20-39")*(data_raw_slopes!$B$2:$B$41="nonpayer")*(data_raw_slopes!$C$2:$C$41="p25")*data_raw_slopes!$F$2:$F$41)>0,SUMPRODUCT((data_raw_slopes!$A$2:$A$41="20-39")*(data_raw_slopes!$B$2:$B$41="nonpayer")*(data_raw_slopes!$C$2:$C$41="p25")*data_raw_slopes!$F$2:$F$41),SUMPRODUCT((data_raw_slopes!$A$2:$A$41="20-39")*(data_raw_slopes!$B$2:$B$41="nonpayer")*(data_raw_slopes!$C$2:$C$41="p25")*data_raw_slopes!$G$2:$G$41)))*Y9*0.15 -> 116.88729 | AG9: =AE9-AF9 -> -15.974428 | AH9: =AC9*(saga_progression_new!$G$17/saga_progression_old!$C$16) -> 12.242857 | AI9: =AG9-AB9 -> -32.024428 | AJ9: =AD9-Y9 -> 1.05 | AK9: =AH9-AC9 -> -22.037143 | AL9: =AF9-AA9 -> 9.987285 | AN9: =SUMPRODUCT((data_segment_HC_gains!$A$48:$A$67="20-39")*(data_segment_HC_gains!$B$48:$B$67="p50")*data_segment_HC_gains!$C$48:$C$67) -> 14 | AO9: =SUMPRODUCT((data_segment_HC_gains!$A$48:$A$67="20-39")*(data_segment_HC_gains!$B$48:$B$67="p50")*data_segment_HC_gains!$E$48:$E$67) -> 163.46 | AP9: =SUMPRODUCT((data_raw_slopes!$A$2:$A$41="20-39")*(data_raw_slopes!$B$2:$B$41="nonpayer")*(data_raw_slopes!$C$2:$C$41="p50")*data_raw_slopes!$E$2:$E$41) -> 158.17 | AQ9: =AO9-AP9 -> 5.29 | AR9: =SUMPRODUCT((data_segment_HC_gains!$A$48:$A$67="20-39")*(data_segment_HC_gains!$B$48:$B$67="p50")*data_segment_HC_gains!$G$48:$G$67) -> 51.4 | AS9: =AN9*1.15 -> 16.1 | AT9: =AO9-AR9*(1-(saga_progression_new!$G$17/saga_progression_old!$C$16))+IF(AN9<ns_new!$E$17,0,IF(AN9*1.25<ns_new!$E$18-ns_new!$E$17,ns_new!$F$17,IF(AN9*1.25^2<ns_new!$E$19-ns_new!$E$18,ns_new!$F$17+ns_new!$F$18,ns_new!$F$17+ns_new!$F$18+ns_new!$F$19))) -> 295.41714 | AU9: =AP9+(IF(SUMPRODUCT((data_raw_slopes!$A$2:$A$41="20-39")*(data_raw_slopes!$B$2:$B$41="nonpayer")*(data_raw_slopes!$C$2:$C$41="p50")*data_raw_slopes!$F$2:$F$41)>0,SUMPRODUCT((data_raw_slopes!$A$2:$A$41="20-39")*(data_raw_slopes!$B$2:$B$41="nonpayer")*(data_raw_slopes!$C$2:$C$41="p50")*data_raw_slopes!$F$2:$F$41),SUMPRODUCT((data_raw_slopes!$A$2:$A$41="20-39")*(data_raw_slopes!$B$2:$B$41="nonpayer")*(data_raw_slopes!$C$2:$C$41="p50")*data_raw_slopes!$G$2:$G$41)))*AN9*0.15 -> 169.98733 | AV9: =AT9-AU9 -> 125.42981 | AW9: =AR9*(saga_progression_new!$G$17/saga_progression_old!$C$16) -> 18.357143 | AX9: =AV9-AQ9 -> 120.13981 | AY9: =AS9-AN9 -> 2.1 | AZ9: =AW9-AR9 -> -33.042857 | BA9: =AU9-AP9 -> 11.81733 | BC9: =SUMPRODUCT((data_segment_HC_gains!$A$48:$A$67="20-39")*(data_segment_HC_gains!$B$48:$B$67="p75")*data_segment_HC_gains!$C$48:$C$67) -> 25 | BD9: =SUMPRODUCT((data_segment_HC_gains!$A$48:$A$67="20-39")*(data_segment_HC_gains!$B$48:$B$67="p75")*data_segment_HC_gains!$E$48:$E$67) -> 184.96 | BE9: =SUMPRODUCT((data_raw_slopes!$A$2:$A$41="20-39")*(data_raw_slopes!$B$2:$B$41="nonpayer")*(data_raw_slopes!$C$2:$C$41="p75")*data_raw_slopes!$E$2:$E$41) -> 205.98 | BF9: =BD9-BE9 -> -21.02 | BG9: =SUMPRODUCT((data_segment_HC_gains!$A$48:$A$67="20-39")*(data_segment_HC_gains!$B$48:$B$67="p75")*data_segment_HC_gains!$G$48:$G$67) -> 60.44 | BH9: =BC9*1.15 -> 28.75 | BI9: =BD9-BG9*(1-(saga_progression_new!$G$17/saga_progression_old!$C$16))+IF(BC9<ns_new!$E$17,0,IF(BC9*1.25<ns_new!$E$18-ns_new!$E$17,ns_new!$F$17,IF(BC9*1.25^2<ns_new!$E$19-ns_new!$E$18,ns_new!$F$17+ns_new!$F$18,ns_new!$F$17+ns_new!$F$18+ns_new!$F$19))) -> 311.10571 | BJ9: =BE9+(IF(SUMPRODUCT((data_raw_slopes!$A$2:$A$41="20-39")*(data_raw_slopes!$B$2:$B$41="nonpayer")*(data_raw_slopes!$C$2:$C$41="p75")*data_raw_slopes!$F$2:$F$41)>0,SUMPRODUCT((data_raw_slopes!$A$2:$A$41="20-39")*(data_raw_slopes!$B$2:$B$41="nonpayer")*(data_raw_slopes!$C$2:$C$41="p75")*data_raw_slopes!$F$2:$F$41),SUMPRODUCT((data_raw_slopes!$A$2:$A$41="20-39")*(data_raw_slopes!$B$2:$B$41="nonpayer")*(data_raw_slopes!$C$2:$C$41="p75")*data_raw_slopes!$G$2:$G$41)))*BC9*0.15 -> 226.40363 | BK9: =BI9-BJ9 -> 84.702089 | BL9: =BG9*(saga_progression_new!$G$17/saga_progression_old!$C$16) -> 21.585714 | BM9: =BK9-BF9 -> 105.72209 | BN9: =BH9-BC9 -> 3.75 | BO9: =BL9-BG9 -> -38.854286 | BP9: =BJ9-BE9 -> 20.423625 | BR9: =SUMPRODUCT((data_segment_HC_gains!$A$48:$A$67="20-39")*(data_segment_HC_gains!$B$48:$B$67="p90")*data_segment_HC_gains!$C$48:$C$67) -> 36 | BS9: =SUMPRODUCT((data_segment_HC_gains!$A$48:$A$67="20-39")*(data_segment_HC_gains!$B$48:$B$67="p90")*data_segment_HC_gains!$E$48:$E$67) -> 247.92 | BT9: =SUMPRODUCT((data_raw_slopes!$A$2:$A$41="20-39")*(data_raw_slopes!$B$2:$B$41="nonpayer")*(data_raw_slopes!$C$2:$C$41="p90")*data_raw_slopes!$E$2:$E$41) -> 295.42 | BU9: =BS9-BT9 -> -47.5 | BV9: =SUMPRODUCT((data_segment_HC_gains!$A$48:$A$67="20-39")*(data_segment_HC_gains!$B$48:$B$67="p90")*data_segment_HC_gains!$G$48:$G$67) -> 84.07 | BW9: =BR9*1.15 -> 41.4 | BX9: =BS9-BV9*(1-(saga_progression_new!$G$17/saga_progression_old!$C$16))+IF(BR9<ns_new!$E$17,0,IF(BR9*1.25<ns_new!$E$18-ns_new!$E$17,ns_new!$F$17,IF(BR9*1.25^2<ns_new!$E$19-ns_new!$E$18,ns_new!$F$17+ns_new!$F$18,ns_new!$F$17+ns_new!$F$18+ns_new!$F$19))) -> 358.875 | BY9: =BT9+(IF(SUMPRODUCT((data_raw_slopes!$A$2:$A$41="20-39")*(data_raw_slopes!$B$2:$B$41="nonpayer")*(data_raw_slopes!$C$2:$C$41="p90")*data_raw_slopes!$F$2:$F$41)>0,SUMPRODUCT((data_raw_slopes!$A$2:$A$41="20-39")*(data_raw_slopes!$B$2:$B$41="nonpayer")*(data_raw_slopes!$C$2:$C$41="p90")*data_raw_slopes!$F$2:$F$41),SUMPRODUCT((data_raw_slopes!$A$2:$A$41="20-39")*(data_raw_slopes!$B$2:$B$41="nonpayer")*(data_raw_slopes!$C$2:$C$41="p90")*data_raw_slopes!$G$2:$G$41)))*BR9*0.15 -> 325.59898 | BZ9: =BX9-BY9 -> 33.27602 | CA9: =BV9*(saga_progression_new!$G$17/saga_progression_old!$C$16) -> 30.025 | CB9: =BZ9-BU9 -> 80.77602 | CC9: =BW9-BR9 -> 5.4 | CD9: =CA9-BV9 -> -54.045 | CE9: =BY9-BT9 -> 30.17898
B10: 40-99 | C10: =data_processed!E5 -> 71.430605 | D10: =data_processed!G5 -> 56.270393 | E10: =data_processed!H5 -> 314.99462 | F10: =data_processed!I5 -> 109.4148 | G10: =data_processed!X5 -> 21.838502 | H10: =data_processed!J5 -> 205.57903 | I10: =IFERROR(D10*saga_progression_new!$I17,"") -> 42.202795 | J10: =IFERROR(daily_rewards_new!$B$13*data_processed!Y5,"") -> 17.124364 | K10: =data_processed!L5 -> 0.53582225 | L10: =data_processed!M5 -> 0.19671082 | M10: =data_processed!N5 -> 0.047749505 | N10: =IFERROR(K10*ns_new!$F$23+L10*ns_new!$F$24+M10*ns_new!$F$25,"") -> 62.333788 | O10: =IFERROR(H10+I10+N10+J10,"") -> 327.23997 | Q10: =data_processed!K5 -> 330.35282 | R10: =IFERROR(E10-Q10,"") -> -15.358201 | S10: =data_processed!W5 -> 38.001617 | T10: =IFERROR(S10*($C$2-1),"") -> 1.9000809 | U10: =data_processed!R5 -> 5.0627 | V10: =IFERROR(O10-(Q10+U10*T10),"") -> -12.732386 | W10: =IFERROR(O10-Q10,"") -> -3.1128462 | Y10: =SUMPRODUCT((data_segment_HC_gains!$A$48:$A$67="40-99")*(data_segment_HC_gains!$B$48:$B$67="p25")*data_segment_HC_gains!$C$48:$C$67) -> 14 | Z10: =SUMPRODUCT((data_segment_HC_gains!$A$48:$A$67="40-99")*(data_segment_HC_gains!$B$48:$B$67="p25")*data_segment_HC_gains!$E$48:$E$67) -> 237.49 | AA10: =SUMPRODUCT((data_raw_slopes!$A$2:$A$41="40-99")*(data_raw_slopes!$B$2:$B$41="nonpayer")*(data_raw_slopes!$C$2:$C$41="p25")*data_raw_slopes!$E$2:$E$41) -> 208.48 | AB10: =Z10-AA10 -> 29.01 | AC10: =SUMPRODUCT((data_segment_HC_gains!$A$48:$A$67="40-99")*(data_segment_HC_gains!$B$48:$B$67="p25")*data_segment_HC_gains!$G$48:$G$67) -> 75.36 | AD10: =Y10*1.15 -> 16.1 | AE10: =Z10-AC10*(1-(saga_progression_new!$I$17/saga_progression_old!$C$16))+IF(Y10<ns_new!$E$23,0,IF(Y10*1.25<ns_new!$E$24-ns_new!$E$23,ns_new!$F$23,IF(Y10*1.25^2<ns_new!$E$25-ns_new!$E$24,ns_new!$F$23+ns_new!$F$24,ns_new!$F$23+ns_new!$F$24+ns_new!$F$25))) -> 189.04429 | AF10: =AA10+(IF(SUMPRODUCT((data_raw_slopes!$A$2:$A$41="40-99")*(data_raw_slopes!$B$2:$B$41="nonpayer")*(data_raw_slopes!$C$2:$C$41="p25")*data_raw_slopes!$F$2:$F$41)>0,SUMPRODUCT((data_raw_slopes!$A$2:$A$41="40-99")*(data_raw_slopes!$B$2:$B$41="nonpayer")*(data_raw_slopes!$C$2:$C$41="p25")*data_raw_slopes!$F$2:$F$41),SUMPRODUCT((data_raw_slopes!$A$2:$A$41="40-99")*(data_raw_slopes!$B$2:$B$41="nonpayer")*(data_raw_slopes!$C$2:$C$41="p25")*data_raw_slopes!$G$2:$G$41)))*Y10*0.15 -> 226.61035 | AG10: =AE10-AF10 -> -37.566064 | AH10: =AC10*(saga_progression_new!$I$17/saga_progression_old!$C$16) -> 26.914286 | AI10: =AG10-AB10 -> -66.576064 | AJ10: =AD10-Y10 -> 2.1 | AK10: =AH10-AC10 -> -48.445714 | AL10: =AF10-AA10 -> 18.13035 | AN10: =SUMPRODUCT((data_segment_HC_gains!$A$48:$A$67="40-99")*(data_segment_HC_gains!$B$48:$B$67="p50")*data_segment_HC_gains!$C$48:$C$67) -> 29 | AO10: =SUMPRODUCT((data_segment_HC_gains!$A$48:$A$67="40-99")*(data_segment_HC_gains!$B$48:$B$67="p50")*data_segment_HC_gains!$E$48:$E$67) -> 303.92 | AP10: =SUMPRODUCT((data_raw_slopes!$A$2:$A$41="40-99")*(data_raw_slopes!$B$2:$B$41="nonpayer")*(data_raw_slopes!$C$2:$C$41="p50")*data_raw_slopes!$E$2:$E$41) -> 307.03 | AQ10: =AO10-AP10 -> -3.11 | AR10: =SUMPRODUCT((data_segment_HC_gains!$A$48:$A$67="40-99")*(data_segment_HC_gains!$B$48:$B$67="p50")*data_segment_HC_gains!$G$48:$G$67) -> 102.38 | AS10: =AN10*1.15 -> 33.35 | AT10: =AO10-AR10*(1-(saga_progression_new!$I$17/saga_progression_old!$C$16))+IF(AN10<ns_new!$E$23,0,IF(AN10*1.25<ns_new!$E$24-ns_new!$E$23,ns_new!$F$23,IF(AN10*1.25^2<ns_new!$E$25-ns_new!$E$24,ns_new!$F$23+ns_new!$F$24,ns_new!$F$23+ns_new!$F$24+ns_new!$F$25))) -> 658.10429 | AU10: =AP10+(IF(SUMPRODUCT((data_raw_slopes!$A$2:$A$41="40-99")*(data_raw_slopes!$B$2:$B$41="nonpayer")*(data_raw_slopes!$C$2:$C$41="p50")*data_raw_slopes!$F$2:$F$41)>0,SUMPRODUCT((data_raw_slopes!$A$2:$A$41="40-99")*(data_raw_slopes!$B$2:$B$41="nonpayer")*(data_raw_slopes!$C$2:$C$41="p50")*data_raw_slopes!$F$2:$F$41),SUMPRODUCT((data_raw_slopes!$A$2:$A$41="40-99")*(data_raw_slopes!$B$2:$B$41="nonpayer")*(data_raw_slopes!$C$2:$C$41="p50")*data_raw_slopes!$G$2:$G$41)))*AN10*0.15 -> 329.05275 | AV10: =AT10-AU10 -> 329.05154 | AW10: =AR10*(saga_progression_new!$I$17/saga_progression_old!$C$16) -> 36.564286 | AX10: =AV10-AQ10 -> 332.16154 | AY10: =AS10-AN10 -> 4.35 | AZ10: =AW10-AR10 -> -65.815714 | BA10: =AU10-AP10 -> 22.022745 | BC10: =SUMPRODUCT((data_segment_HC_gains!$A$48:$A$67="40-99")*(data_segment_HC_gains!$B$48:$B$67="p75")*data_segment_HC_gains!$C$48:$C$67) -> 50 | BD10: =SUMPRODUCT((data_segment_HC_gains!$A$48:$A$67="40-99")*(data_segment_HC_gains!$B$48:$B$67="p75")*data_segment_HC_gains!$E$48:$E$67) -> 352.42 | BE10: =SUMPRODUCT((data_raw_slopes!$A$2:$A$41="40-99")*(data_raw_slopes!$B$2:$B$41="nonpayer")*(data_raw_slopes!$C$2:$C$41="p75")*data_raw_slopes!$E$2:$E$41) -> 390.26 | BF10: =BD10-BE10 -> -37.84 | BG10: =SUMPRODUCT((data_segment_HC_gains!$A$48:$A$67="40-99")*(data_segment_HC_gains!$B$48:$B$67="p75")*data_segment_HC_gains!$G$48:$G$67) -> 120.97 | BH10: =BC10*1.15 -> 57.5 | BI10: =BD10-BG10*(1-(saga_progression_new!$I$17/saga_progression_old!$C$16))+IF(BC10<ns_new!$E$23,0,IF(BC10*1.25<ns_new!$E$24-ns_new!$E$23,ns_new!$F$23,IF(BC10*1.25^2<ns_new!$E$25-ns_new!$E$24,ns_new!$F$23+ns_new!$F$24,ns_new!$F$23+ns_new!$F$24+ns_new!$F$25))) -> 694.65357 | BJ10: =BE10+(IF(SUMPRODUCT((data_raw_slopes!$A$2:$A$41="40-99")*(data_raw_slopes!$B$2:$B$41="nonpayer")*(data_raw_slopes!$C$2:$C$41="p75")*data_raw_slopes!$F$2:$F$41)>0,SUMPRODUCT((data_raw_slopes!$A$2:$A$41="40-99")*(data_raw_slopes!$B$2:$B$41="nonpayer")*(data_raw_slopes!$C$2:$C$41="p75")*data_raw_slopes!$F$2:$F$41),SUMPRODUCT((data_raw_slopes!$A$2:$A$41="40-99")*(data_raw_slopes!$B$2:$B$41="nonpayer")*(data_raw_slopes!$C$2:$C$41="p75")*data_raw_slopes!$G$2:$G$41)))*BC10*0.15 -> 421.76825 | BK10: =BI10-BJ10 -> 272.88532 | BL10: =BG10*(saga_progression_new!$I$17/saga_progression_old!$C$16) -> 43.203571 | BM10: =BK10-BF10 -> 310.72532 | BN10: =BH10-BC10 -> 7.5 | BO10: =BL10-BG10 -> -77.766429 | BP10: =BJ10-BE10 -> 31.50825 | BR10: =SUMPRODUCT((data_segment_HC_gains!$A$48:$A$67="40-99")*(data_segment_HC_gains!$B$48:$B$67="p90")*data_segment_HC_gains!$C$48:$C$67) -> 76 | BS10: =SUMPRODUCT((data_segment_HC_gains!$A$48:$A$67="40-99")*(data_segment_HC_gains!$B$48:$B$67="p90")*data_segment_HC_gains!$E$48:$E$67) -> 466.06 | BT10: =SUMPRODUCT((data_raw_slopes!$A$2:$A$41="40-99")*(data_raw_slopes!$B$2:$B$41="nonpayer")*(data_raw_slopes!$C$2:$C$41="p90")*data_raw_slopes!$E$2:$E$41) -> 547.26 | BU10: =BS10-BT10 -> -81.2 | BV10: =SUMPRODUCT((data_segment_HC_gains!$A$48:$A$67="40-99")*(data_segment_HC_gains!$B$48:$B$67="p90")*data_segment_HC_gains!$G$48:$G$67) -> 170.37 | BW10: =BR10*1.15 -> 87.4 | BX10: =BS10-BV10*(1-(saga_progression_new!$I$17/saga_progression_old!$C$16))+IF(BR10<ns_new!$E$23,0,IF(BR10*1.25<ns_new!$E$24-ns_new!$E$23,ns_new!$F$23,IF(BR10*1.25^2<ns_new!$E$25-ns_new!$E$24,ns_new!$F$23+ns_new!$F$24,ns_new!$F$23+ns_new!$F$24+ns_new!$F$25))) -> 776.53643 | BY10: =BT10+(IF(SUMPRODUCT((data_raw_slopes!$A$2:$A$41="40-99")*(data_raw_slopes!$B$2:$B$41="nonpayer")*(data_raw_slopes!$C$2:$C$41="p90")*data_raw_slopes!$F$2:$F$41)>0,SUMPRODUCT((data_raw_slopes!$A$2:$A$41="40-99")*(data_raw_slopes!$B$2:$B$41="nonpayer")*(data_raw_slopes!$C$2:$C$41="p90")*data_raw_slopes!$F$2:$F$41),SUMPRODUCT((data_raw_slopes!$A$2:$A$41="40-99")*(data_raw_slopes!$B$2:$B$41="nonpayer")*(data_raw_slopes!$C$2:$C$41="p90")*data_raw_slopes!$G$2:$G$41)))*BR10*0.15 -> 610.12758 | BZ10: =BX10-BY10 -> 166.40885 | CA10: =BV10*(saga_progression_new!$I$17/saga_progression_old!$C$16) -> 60.846429 | CB10: =BZ10-BU10 -> 247.60885 | CC10: =BW10-BR10 -> 11.4 | CD10: =CA10-BV10 -> -109.52357 | CE10: =BY10-BT10 -> 62.86758
B11: 100+ | C11: =data_processed!E6 -> 144.47267 | D11: =data_processed!G6 -> 126.44089 | E11: =data_processed!H6 -> 616.81017 | F11: =data_processed!I6 -> 252.57991 | G11: =data_processed!X6 -> 23.431515 | H11: =data_processed!J6 -> 364.22986 | I11: =IFERROR(D11*saga_progression_new!$K17,"") -> 94.830671 | J11: =IFERROR(daily_rewards_new!$B$13*data_processed!Y6,"") -> 17.761737 | K11: =data_processed!L6 -> 0.4732223 | L11: =data_processed!M6 -> 0.10358635 | M11: =data_processed!N6 -> 0.013922355 | N11: =IFERROR(K11*ns_new!$F$29+L11*ns_new!$F$30+M11*ns_new!$F$31,"") -> 83.967079 | O11: =IFERROR(H11+I11+N11+J11,"") -> 560.78935 | Q11: =data_processed!K6 -> 689.68873 | R11: =IFERROR(E11-Q11,"") -> -72.878559 | S11: =data_processed!W6 -> 88.588364 | T11: =IFERROR(S11*($C$2-1),"") -> 4.4294182 | U11: =data_processed!R6 -> 3.9052 | V11: =IFERROR(O11-(Q11+U11*T11),"") -> -146.19715 | W11: =IFERROR(O11-Q11,"") -> -128.89939 | Y11: =SUMPRODUCT((data_segment_HC_gains!$A$48:$A$67="100+")*(data_segment_HC_gains!$B$48:$B$67="p25")*data_segment_HC_gains!$C$48:$C$67) -> 33 | Z11: =SUMPRODUCT((data_segment_HC_gains!$A$48:$A$67="100+")*(data_segment_HC_gains!$B$48:$B$67="p25")*data_segment_HC_gains!$E$48:$E$67) -> 518.1 | AA11: =SUMPRODUCT((data_raw_slopes!$A$2:$A$41="100+")*(data_raw_slopes!$B$2:$B$41="nonpayer")*(data_raw_slopes!$C$2:$C$41="p25")*data_raw_slopes!$E$2:$E$41) -> 459.17 | AB11: =Z11-AA11 -> 58.93 | AC11: =SUMPRODUCT((data_segment_HC_gains!$A$48:$A$67="100+")*(data_segment_HC_gains!$B$48:$B$67="p25")*data_segment_HC_gains!$G$48:$G$67) -> 200.98 | AD11: =Y11*1.15 -> 37.95 | AE11: =Z11-AC11*(1-(saga_progression_new!$K$17/saga_progression_old!$C$16))+IF(Y11<ns_new!$E$29,0,IF(Y11*1.25<ns_new!$E$30-ns_new!$E$29,ns_new!$F$29,IF(Y11*1.25^2<ns_new!$E$31-ns_new!$E$30,ns_new!$F$29+ns_new!$F$30,ns_new!$F$29+ns_new!$F$30+ns_new!$F$31))) -> 388.89857 | AF11: =AA11+(IF(SUMPRODUCT((data_raw_slopes!$A$2:$A$41="100+")*(data_raw_slopes!$B$2:$B$41="nonpayer")*(data_raw_slopes!$C$2:$C$41="p25")*data_raw_slopes!$F$2:$F$41)>0,SUMPRODUCT((data_raw_slopes!$A$2:$A$41="100+")*(data_raw_slopes!$B$2:$B$41="nonpayer")*(data_raw_slopes!$C$2:$C$41="p25")*data_raw_slopes!$F$2:$F$41),SUMPRODUCT((data_raw_slopes!$A$2:$A$41="100+")*(data_raw_slopes!$B$2:$B$41="nonpayer")*(data_raw_slopes!$C$2:$C$41="p25")*data_raw_slopes!$G$2:$G$41)))*Y11*0.15 -> 488.21512 | AG11: =AE11-AF11 -> -99.316544 | AH11: =AC11*(saga_progression_new!$K$17/saga_progression_old!$C$16) -> 71.778571 | AI11: =AG11-AB11 -> -158.24654 | AJ11: =AD11-Y11 -> 4.95 | AK11: =AH11-AC11 -> -129.20143 | AL11: =AF11-AA11 -> 29.045115 | AN11: =SUMPRODUCT((data_segment_HC_gains!$A$48:$A$67="100+")*(data_segment_HC_gains!$B$48:$B$67="p50")*data_segment_HC_gains!$C$48:$C$67) -> 68 | AO11: =SUMPRODUCT((data_segment_HC_gains!$A$48:$A$67="100+")*(data_segment_HC_gains!$B$48:$B$67="p50")*data_segment_HC_gains!$E$48:$E$67) -> 624.31 | AP11: =SUMPRODUCT((data_raw_slopes!$A$2:$A$41="100+")*(data_raw_slopes!$B$2:$B$41="nonpayer")*(data_raw_slopes!$C$2:$C$41="p50")*data_raw_slopes!$E$2:$E$41) -> 634.17 | AQ11: =AO11-AP11 -> -9.86 | AR11: =SUMPRODUCT((data_segment_HC_gains!$A$48:$A$67="100+")*(data_segment_HC_gains!$B$48:$B$67="p50")*data_segment_HC_gains!$G$48:$G$67) -> 247.18 | AS11: =AN11*1.15 -> 78.2 | AT11: =AO11-AR11*(1-(saga_progression_new!$K$17/saga_progression_old!$C$16))+IF(AN11<ns_new!$E$29,0,IF(AN11*1.25<ns_new!$E$30-ns_new!$E$29,ns_new!$F$29,IF(AN11*1.25^2<ns_new!$E$31-ns_new!$E$30,ns_new!$F$29+ns_new!$F$30,ns_new!$F$29+ns_new!$F$30+ns_new!$F$31))) -> 465.40857 | AU11: =AP11+(IF(SUMPRODUCT((data_raw_slopes!$A$2:$A$41="100+")*(data_raw_slopes!$B$2:$B$41="nonpayer")*(data_raw_slopes!$C$2:$C$41="p50")*data_raw_slopes!$F$2:$F$41)>0,SUMPRODUCT((data_raw_slopes!$A$2:$A$41="100+")*(data_raw_slopes!$B$2:$B$41="nonpayer")*(data_raw_slopes!$C$2:$C$41="p50")*data_raw_slopes!$F$2:$F$41),SUMPRODUCT((data_raw_slopes!$A$2:$A$41="100+")*(data_raw_slopes!$B$2:$B$41="nonpayer")*(data_raw_slopes!$C$2:$C$41="p50")*data_raw_slopes!$G$2:$G$41)))*AN11*0.15 -> 674.00304 | AV11: =AT11-AU11 -> -208.59447 | AW11: =AR11*(saga_progression_new!$K$17/saga_progression_old!$C$16) -> 88.278571 | AX11: =AV11-AQ11 -> -198.73447 | AY11: =AS11-AN11 -> 10.2 | AZ11: =AW11-AR11 -> -158.90143 | BA11: =AU11-AP11 -> 39.83304 | BC11: =SUMPRODUCT((data_segment_HC_gains!$A$48:$A$67="100+")*(data_segment_HC_gains!$B$48:$B$67="p75")*data_segment_HC_gains!$C$48:$C$67) -> 118 | BD11: =SUMPRODUCT((data_segment_HC_gains!$A$48:$A$67="100+")*(data_segment_HC_gains!$B$48:$B$67="p75")*data_segment_HC_gains!$E$48:$E$67) -> 687.28 | BE11: =SUMPRODUCT((data_raw_slopes!$A$2:$A$41="100+")*(data_raw_slopes!$B$2:$B$41="nonpayer")*(data_raw_slopes!$C$2:$C$41="p75")*data_raw_slopes!$E$2:$E$41) -> 792.43 | BF11: =BD11-BE11 -> -105.15 | BG11: =SUMPRODUCT((data_segment_HC_gains!$A$48:$A$67="100+")*(data_segment_HC_gains!$B$48:$B$67="p75")*data_segment_HC_gains!$G$48:$G$67) -> 279.6 | BH11: =BC11*1.15 -> 135.7 | BI11: =BD11-BG11*(1-(saga_progression_new!$K$17/saga_progression_old!$C$16))+IF(BC11<ns_new!$E$29,0,IF(BC11*1.25<ns_new!$E$30-ns_new!$E$29,ns_new!$F$29,IF(BC11*1.25^2<ns_new!$E$31-ns_new!$E$30,ns_new!$F$29+ns_new!$F$30,ns_new!$F$29+ns_new!$F$30+ns_new!$F$31))) -> 1307.5371 | BJ11: =BE11+(IF(SUMPRODUCT((data_raw_slopes!$A$2:$A$41="100+")*(data_raw_slopes!$B$2:$B$41="nonpayer")*(data_raw_slopes!$C$2:$C$41="p75")*data_raw_slopes!$F$2:$F$41)>0,SUMPRODUCT((data_raw_slopes!$A$2:$A$41="100+")*(data_raw_slopes!$B$2:$B$41="nonpayer")*(data_raw_slopes!$C$2:$C$41="p75")*data_raw_slopes!$F$2:$F$41),SUMPRODUCT((data_raw_slopes!$A$2:$A$41="100+")*(data_raw_slopes!$B$2:$B$41="nonpayer")*(data_raw_slopes!$C$2:$C$41="p75")*data_raw_slopes!$G$2:$G$41)))*BC11*0.15 -> 864.98053 | BK11: =BI11-BJ11 -> 442.55661 | BL11: =BG11*(saga_progression_new!$K$17/saga_progression_old!$C$16) -> 99.857143 | BM11: =BK11-BF11 -> 547.70661 | BN11: =BH11-BC11 -> 17.7 | BO11: =BL11-BG11 -> -179.74286 | BP11: =BJ11-BE11 -> 72.55053 | BR11: =SUMPRODUCT((data_segment_HC_gains!$A$48:$A$67="100+")*(data_segment_HC_gains!$B$48:$B$67="p90")*data_segment_HC_gains!$C$48:$C$67) -> 172 | BS11: =SUMPRODUCT((data_segment_HC_gains!$A$48:$A$67="100+")*(data_segment_HC_gains!$B$48:$B$67="p90")*data_segment_HC_gains!$E$48:$E$67) -> 912.86 | BT11: =SUMPRODUCT((data_raw_slopes!$A$2:$A$41="100+")*(data_raw_slopes!$B$2:$B$41="nonpayer")*(data_raw_slopes!$C$2:$C$41="p90")*data_raw_slopes!$E$2:$E$41) -> 1103.44 | BU11: =BS11-BT11 -> -190.58 | BV11: =SUMPRODUCT((data_segment_HC_gains!$A$48:$A$67="100+")*(data_segment_HC_gains!$B$48:$B$67="p90")*data_segment_HC_gains!$G$48:$G$67) -> 381.8 | BW11: =BR11*1.15 -> 197.8 | BX11: =BS11-BV11*(1-(saga_progression_new!$K$17/saga_progression_old!$C$16))+IF(BR11<ns_new!$E$29,0,IF(BR11*1.25<ns_new!$E$30-ns_new!$E$29,ns_new!$F$29,IF(BR11*1.25^2<ns_new!$E$31-ns_new!$E$30,ns_new!$F$29+ns_new!$F$30,ns_new!$F$29+ns_new!$F$30+ns_new!$F$31))) -> 1467.4171 | BY11: =BT11+(IF(SUMPRODUCT((data_raw_slopes!$A$2:$A$41="100+")*(data_raw_slopes!$B$2:$B$41="nonpayer")*(data_raw_slopes!$C$2:$C$41="p90")*data_raw_slopes!$F$2:$F$41)>0,SUMPRODUCT((data_raw_slopes!$A$2:$A$41="100+")*(data_raw_slopes!$B$2:$B$41="nonpayer")*(data_raw_slopes!$C$2:$C$41="p90")*data_raw_slopes!$F$2:$F$41),SUMPRODUCT((data_raw_slopes!$A$2:$A$41="100+")*(data_raw_slopes!$B$2:$B$41="nonpayer")*(data_raw_slopes!$C$2:$C$41="p90")*data_raw_slopes!$G$2:$G$41)))*BR11*0.15 -> 1219.6535 | BZ11: =BX11-BY11 -> 247.76362 | CA11: =BV11*(saga_progression_new!$K$17/saga_progression_old!$C$16) -> 136.35714 | CB11: =BZ11-BU11 -> 438.34362 | CC11: =BW11-BR11 -> 25.8 | CD11: =CA11-BV11 -> -245.44286 | CE11: =BY11-BT11 -> 116.21352
B13: PAYERS
B14: 0-9 | C14: =data_processed!E7 -> 17.583935 | D14: =data_processed!G7 -> 5.3576657 | E14: =data_processed!H7 -> 75.580818 | F14: =data_processed!I7 -> 10.435025 | G14: =data_processed!X7 -> 20.447022 | H14: =data_processed!J7 -> 65.146107 | I14: =IFERROR(D14*saga_progression_new!$C17,"") -> 4.0182493 | J14: =IFERROR(daily_rewards_new!$B$13*data_processed!Y7,"") -> 14.423205 | K14: =data_processed!L7 -> 0.66797371 | L14: =data_processed!M7 -> 0.24991682 | M14: =data_processed!N7 -> 0.069544411 | N14: =IFERROR(K14*ns_new!$F$5+L14*ns_new!$F$6+M14*ns_new!$F$7,"") -> 3.5423344 | O14: =IFERROR(H14+I14+N14+J14,"") -> 87.129895 | Q14: =data_processed!K7 -> 77.209809 | R14: =IFERROR(E14-Q14,"") -> -1.6289908 | S14: =data_processed!W7 -> 3.5477807 | T14: =IFERROR(S14*($C$2-1),"") -> 0.17738904 | U14: =data_processed!R7 -> 28.5464 | V14: =IFERROR(O14-(Q14+U14*T14),"") -> 4.8562677 | W14: =IFERROR(O14-Q14,"") -> 9.9200861 | Y14: =SUMPRODUCT((data_segment_HC_gains!$A$25:$A$44="0-9")*(data_segment_HC_gains!$B$25:$B$44="p25")*data_segment_HC_gains!$C$25:$C$44) -> 0 | Z14: =SUMPRODUCT((data_segment_HC_gains!$A$25:$A$44="0-9")*(data_segment_HC_gains!$B$25:$B$44="p25")*data_segment_HC_gains!$E$25:$E$44) -> 27.59 | AA14: =SUMPRODUCT((data_raw_slopes!$A$2:$A$41="0-9")*(data_raw_slopes!$B$2:$B$41="payer")*(data_raw_slopes!$C$2:$C$41="p25")*data_raw_slopes!$E$2:$E$41) -> 2.25 | AB14: =Z14-AA14 -> 25.34 | AC14: =SUMPRODUCT((data_segment_HC_gains!$A$25:$A$44="0-9")*(data_segment_HC_gains!$B$25:$B$44="p25")*data_segment_HC_gains!$G$25:$G$44) -> 0.07 | AD14: =Y14*1.15 -> 0 | AE14: =Z14-AC14*(1-(saga_progression_new!$C$17/saga_progression_old!$C$16))+IF(Y14<ns_new!$E$5,0,IF(Y14*1.25<ns_new!$E$6-ns_new!$E$5,ns_new!$F$5,IF(Y14*1.25^2<ns_new!$E$7-ns_new!$E$6,ns_new!$F$5+ns_new!$F$6,ns_new!$F$5+ns_new!$F$6+ns_new!$F$7))) -> 27.545 | AF14: =AA14+(IF(SUMPRODUCT((data_raw_slopes!$A$2:$A$41="0-9")*(data_raw_slopes!$B$2:$B$41="payer")*(data_raw_slopes!$C$2:$C$41="p25")*data_raw_slopes!$F$2:$F$41)>0,SUMPRODUCT((data_raw_slopes!$A$2:$A$41="0-9")*(data_raw_slopes!$B$2:$B$41="payer")*(data_raw_slopes!$C$2:$C$41="p25")*data_raw_slopes!$F$2:$F$41),SUMPRODUCT((data_raw_slopes!$A$2:$A$41="0-9")*(data_raw_slopes!$B$2:$B$41="payer")*(data_raw_slopes!$C$2:$C$41="p25")*data_raw_slopes!$G$2:$G$41)))*Y14*0.15 -> 2.25 | AG14: =AE14-AF14 -> 25.295 | AH14: =AC14*(saga_progression_new!$C$17/saga_progression_old!$C$16) -> 0.025 | AI14: =AG14-AB14 -> -0.045 | AJ14: =AD14-Y14 -> 0 | AK14: =AH14-AC14 -> -0.045 | AL14: =AF14-AA14 -> 0 | AN14: =SUMPRODUCT((data_segment_HC_gains!$A$25:$A$44="0-9")*(data_segment_HC_gains!$B$25:$B$44="p50")*data_segment_HC_gains!$C$25:$C$44) -> 1 | AO14: =SUMPRODUCT((data_segment_HC_gains!$A$25:$A$44="0-9")*(data_segment_HC_gains!$B$25:$B$44="p50")*data_segment_HC_gains!$E$25:$E$44) -> 38.94 | AP14: =SUMPRODUCT((data_raw_slopes!$A$2:$A$41="0-9")*(data_raw_slopes!$B$2:$B$41="payer")*(data_raw_slopes!$C$2:$C$41="p50")*data_raw_slopes!$E$2:$E$41) -> 24.74 | AQ14: =AO14-AP14 -> 14.2 | AR14: =SUMPRODUCT((data_segment_HC_gains!$A$25:$A$44="0-9")*(data_segment_HC_gains!$B$25:$B$44="p50")*data_segment_HC_gains!$G$25:$G$44) -> 2.96 | AS14: =AN14*1.15 -> 1.15 | AT14: =AO14-AR14*(1-(saga_progression_new!$C$17/saga_progression_old!$C$16))+IF(AN14<ns_new!$E$5,0,IF(AN14*1.25<ns_new!$E$6-ns_new!$E$5,ns_new!$F$5,IF(AN14*1.25^2<ns_new!$E$7-ns_new!$E$6,ns_new!$F$5+ns_new!$F$6,ns_new!$F$5+ns_new!$F$6+ns_new!$F$7))) -> 37.037143 | AU14: =AP14+(IF(SUMPRODUCT((data_raw_slopes!$A$2:$A$41="0-9")*(data_raw_slopes!$B$2:$B$41="payer")*(data_raw_slopes!$C$2:$C$41="p50")*data_raw_slopes!$F$2:$F$41)>0,SUMPRODUCT((data_raw_slopes!$A$2:$A$41="0-9")*(data_raw_slopes!$B$2:$B$41="payer")*(data_raw_slopes!$C$2:$C$41="p50")*data_raw_slopes!$F$2:$F$41),SUMPRODUCT((data_raw_slopes!$A$2:$A$41="0-9")*(data_raw_slopes!$B$2:$B$41="payer")*(data_raw_slopes!$C$2:$C$41="p50")*data_raw_slopes!$G$2:$G$41)))*AN14*0.15 -> 29.02196 | AV14: =AT14-AU14 -> 8.0151829 | AW14: =AR14*(saga_progression_new!$C$17/saga_progression_old!$C$16) -> 1.0571429 | AX14: =AV14-AQ14 -> -6.1848171 | AY14: =AS14-AN14 -> 0.15 | AZ14: =AW14-AR14 -> -1.9028571 | BA14: =AU14-AP14 -> 4.28196 | BC14: =SUMPRODUCT((data_segment_HC_gains!$A$25:$A$44="0-9")*(data_segment_HC_gains!$B$25:$B$44="p75")*data_segment_HC_gains!$C$25:$C$44) -> 3 | BD14: =SUMPRODUCT((data_segment_HC_gains!$A$25:$A$44="0-9")*(data_segment_HC_gains!$B$25:$B$44="p75")*data_segment_HC_gains!$E$25:$E$44) -> 58.44 | BE14: =SUMPRODUCT((data_raw_slopes!$A$2:$A$41="0-9")*(data_raw_slopes!$B$2:$B$41="payer")*(data_raw_slopes!$C$2:$C$41="p75")*data_raw_slopes!$E$2:$E$41) -> 56.58 | BF14: =BD14-BE14 -> 1.86 | BG14: =SUMPRODUCT((data_segment_HC_gains!$A$25:$A$44="0-9")*(data_segment_HC_gains!$B$25:$B$44="p75")*data_segment_HC_gains!$G$25:$G$44) -> 7.56 | BH14: =BC14*1.15 -> 3.45 | BI14: =BD14-BG14*(1-(saga_progression_new!$C$17/saga_progression_old!$C$16))+IF(BC14<ns_new!$E$5,0,IF(BC14*1.25<ns_new!$E$6-ns_new!$E$5,ns_new!$F$5,IF(BC14*1.25^2<ns_new!$E$7-ns_new!$E$6,ns_new!$F$5+ns_new!$F$6,ns_new!$F$5+ns_new!$F$6+ns_new!$F$7))) -> 63.58 | BJ14: =BE14+(IF(SUMPRODUCT((data_raw_slopes!$A$2:$A$41="0-9")*(data_raw_slopes!$B$2:$B$41="payer")*(data_raw_slopes!$C$2:$C$41="p75")*data_raw_slopes!$F$2:$F$41)>0,SUMPRODUCT((data_raw_slopes!$A$2:$A$41="0-9")*(data_raw_slopes!$B$2:$B$41="payer")*(data_raw_slopes!$C$2:$C$41="p75")*data_raw_slopes!$F$2:$F$41),SUMPRODUCT((data_raw_slopes!$A$2:$A$41="0-9")*(data_raw_slopes!$B$2:$B$41="payer")*(data_raw_slopes!$C$2:$C$41="p75")*data_raw_slopes!$G$2:$G$41)))*BC14*0.15 -> 64.376565 | BK14: =BI14-BJ14 -> -0.796565 | BL14: =BG14*(saga_progression_new!$C$17/saga_progression_old!$C$16) -> 2.7 | BM14: =BK14-BF14 -> -2.656565 | BN14: =BH14-BC14 -> 0.45 | BO14: =BL14-BG14 -> -4.86 | BP14: =BJ14-BE14 -> 7.796565 | BR14: =SUMPRODUCT((data_segment_HC_gains!$A$25:$A$44="0-9")*(data_segment_HC_gains!$B$25:$B$44="p90")*data_segment_HC_gains!$C$25:$C$44) -> 6 | BS14: =SUMPRODUCT((data_segment_HC_gains!$A$25:$A$44="0-9")*(data_segment_HC_gains!$B$25:$B$44="p90")*data_segment_HC_gains!$E$25:$E$44) -> 110.87 | BT14: =SUMPRODUCT((data_raw_slopes!$A$2:$A$41="0-9")*(data_raw_slopes!$B$2:$B$41="payer")*(data_raw_slopes!$C$2:$C$41="p90")*data_raw_slopes!$E$2:$E$41) -> 121.33 | BU14: =BS14-BT14 -> -10.46 | BV14: =SUMPRODUCT((data_segment_HC_gains!$A$25:$A$44="0-9")*(data_segment_HC_gains!$B$25:$B$44="p90")*data_segment_HC_gains!$G$25:$G$44) -> 16.94 | BW14: =BR14*1.15 -> 6.9 | BX14: =BS14-BV14*(1-(saga_progression_new!$C$17/saga_progression_old!$C$16))+IF(BR14<ns_new!$E$5,0,IF(BR14*1.25<ns_new!$E$6-ns_new!$E$5,ns_new!$F$5,IF(BR14*1.25^2<ns_new!$E$7-ns_new!$E$6,ns_new!$F$5+ns_new!$F$6,ns_new!$F$5+ns_new!$F$6+ns_new!$F$7))) -> 124.98 | BY14: =BT14+(IF(SUMPRODUCT((data_raw_slopes!$A$2:$A$41="0-9")*(data_raw_slopes!$B$2:$B$41="payer")*(data_raw_slopes!$C$2:$C$41="p90")*data_raw_slopes!$F$2:$F$41)>0,SUMPRODUCT((data_raw_slopes!$A$2:$A$41="0-9")*(data_raw_slopes!$B$2:$B$41="payer")*(data_raw_slopes!$C$2:$C$41="p90")*data_raw_slopes!$F$2:$F$41),SUMPRODUCT((data_raw_slopes!$A$2:$A$41="0-9")*(data_raw_slopes!$B$2:$B$41="payer")*(data_raw_slopes!$C$2:$C$41="p90")*data_raw_slopes!$G$2:$G$41)))*BR14*0.15 -> 134.71012 | BZ14: =BX14-BY14 -> -9.73012 | CA14: =BV14*(saga_progression_new!$C$17/saga_progression_old!$C$16) -> 6.05 | CB14: =BZ14-BU14 -> 0.72988 | CC14: =BW14-BR14 -> 0.9 | CD14: =CA14-BV14 -> -10.89 | CE14: =BY14-BT14 -> 13.38012
B15: 10-19 | C15: =data_processed!E8 -> 34.26795 | D15: =data_processed!G8 -> 14.124382 | E15: =data_processed!H8 -> 175.78658 | F15: =data_processed!I8 -> 27.043509 | G15: =data_processed!X8 -> 21.036063 | H15: =data_processed!J8 -> 148.7436 | I15: =IFERROR(D15*saga_progression_new!$E17,"") -> 10.593287 | J15: =IFERROR(daily_rewards_new!$B$13*data_processed!Y8,"") -> 15.527882 | K15: =data_processed!L8 -> 0.54521614 | L15: =data_processed!M8 -> 0.24569015 | M15: =data_processed!N8 -> 0.048395913 | N15: =IFERROR(K15*ns_new!$F$11+L15*ns_new!$F$12+M15*ns_new!$F$13,"") -> 15.726621 | O15: =IFERROR(H15+I15+N15+J15,"") -> 190.59139 | Q15: =data_processed!K8 -> 181.42485 | R15: =IFERROR(E15-Q15,"") -> -5.6382709 | S15: =data_processed!W8 -> 8.8916592 | T15: =IFERROR(S15*($C$2-1),"") -> 0.44458296 | U15: =data_processed!R8 -> 13.3578 | V15: =IFERROR(O15-(Q15+U15*T15),"") -> 3.2278839 | W15: =IFERROR(O15-Q15,"") -> 9.1665341 | Y15: =SUMPRODUCT((data_segment_HC_gains!$A$25:$A$44="10-19")*(data_segment_HC_gains!$B$25:$B$44="p25")*data_segment_HC_gains!$C$25:$C$44) -> 3 | Z15: =SUMPRODUCT((data_segment_HC_gains!$A$25:$A$44="10-19")*(data_segment_HC_gains!$B$25:$B$44="p25")*data_segment_HC_gains!$E$25:$E$44) -> 93.5 | AA15: =SUMPRODUCT((data_raw_slopes!$A$2:$A$41="10-19")*(data_raw_slopes!$B$2:$B$41="payer")*(data_raw_slopes!$C$2:$C$41="p25")*data_raw_slopes!$E$2:$E$41) -> 89.02 | AB15: =Z15-AA15 -> 4.48 | AC15: =SUMPRODUCT((data_segment_HC_gains!$A$25:$A$44="10-19")*(data_segment_HC_gains!$B$25:$B$44="p25")*data_segment_HC_gains!$G$25:$G$44) -> 14.79 | AD15: =Y15*1.15 -> 3.45 | AE15: =Z15-AC15*(1-(saga_progression_new!$E$17/saga_progression_old!$C$16))+IF(Y15<ns_new!$E$11,0,IF(Y15*1.25<ns_new!$E$12-ns_new!$E$11,ns_new!$F$11,IF(Y15*1.25^2<ns_new!$E$13-ns_new!$E$12,ns_new!$F$11+ns_new!$F$12,ns_new!$F$11+ns_new!$F$12+ns_new!$F$13))) -> 83.992143 | AF15: =AA15+(IF(SUMPRODUCT((data_raw_slopes!$A$2:$A$41="10-19")*(data_raw_slopes!$B$2:$B$41="payer")*(data_raw_slopes!$C$2:$C$41="p25")*data_raw_slopes!$F$2:$F$41)>0,SUMPRODUCT((data_raw_slopes!$A$2:$A$41="10-19")*(data_raw_slopes!$B$2:$B$41="payer")*(data_raw_slopes!$C$2:$C$41="p25")*data_raw_slopes!$F$2:$F$41),SUMPRODUCT((data_raw_slopes!$A$2:$A$41="10-19")*(data_raw_slopes!$B$2:$B$41="payer")*(data_raw_slopes!$C$2:$C$41="p25")*data_raw_slopes!$G$2:$G$41)))*Y15*0.15 -> 99.424135 | AG15: =AE15-AF15 -> -15.431992 | AH15: =AC15*(saga_progression_new!$E$17/saga_progression_old!$C$16) -> 5.2821429 | AI15: =AG15-AB15 -> -19.911992 | AJ15: =AD15-Y15 -> 0.45 | AK15: =AH15-AC15 -> -9.5078571 | AL15: =AF15-AA15 -> 10.404135 | AN15: =SUMPRODUCT((data_segment_HC_gains!$A$25:$A$44="10-19")*(data_segment_HC_gains!$B$25:$B$44="p50")*data_segment_HC_gains!$C$25:$C$44) -> 6 | AO15: =SUMPRODUCT((data_segment_HC_gains!$A$25:$A$44="10-19")*(data_segment_HC_gains!$B$25:$B$44="p50")*data_segment_HC_gains!$E$25:$E$44) -> 148.23 | AP15: =SUMPRODUCT((data_raw_slopes!$A$2:$A$41="10-19")*(data_raw_slopes!$B$2:$B$41="payer")*(data_raw_slopes!$C$2:$C$41="p50")*data_raw_slopes!$E$2:$E$41) -> 151.27 | AQ15: =AO15-AP15 -> -3.04 | AR15: =SUMPRODUCT((data_segment_HC_gains!$A$25:$A$44="10-19")*(data_segment_HC_gains!$B$25:$B$44="p50")*data_segment_HC_gains!$G$25:$G$44) -> 25.07 | AS15: =AN15*1.15 -> 6.9 | AT15: =AO15-AR15*(1-(saga_progression_new!$E$17/saga_progression_old!$C$16))+IF(AN15<ns_new!$E$11,0,IF(AN15*1.25<ns_new!$E$12-ns_new!$E$11,ns_new!$F$11,IF(AN15*1.25^2<ns_new!$E$13-ns_new!$E$12,ns_new!$F$11+ns_new!$F$12,ns_new!$F$11+ns_new!$F$12+ns_new!$F$13))) -> 172.11357 | AU15: =AP15+(IF(SUMPRODUCT((data_raw_slopes!$A$2:$A$41="10-19")*(data_raw_slopes!$B$2:$B$41="payer")*(data_raw_slopes!$C$2:$C$41="p50")*data_raw_slopes!$F$2:$F$41)>0,SUMPRODUCT((data_raw_slopes!$A$2:$A$41="10-19")*(data_raw_slopes!$B$2:$B$41="payer")*(data_raw_slopes!$C$2:$C$41="p50")*data_raw_slopes!$F$2:$F$41),SUMPRODUCT((data_raw_slopes!$A$2:$A$41="10-19")*(data_raw_slopes!$B$2:$B$41="payer")*(data_raw_slopes!$C$2:$C$41="p50")*data_raw_slopes!$G$2:$G$41)))*AN15*0.15 -> 163.29202 | AV15: =AT15-AU15 -> 8.8215514 | AW15: =AR15*(saga_progression_new!$E$17/saga_progression_old!$C$16) -> 8.9535714 | AX15: =AV15-AQ15 -> 11.861551 | AY15: =AS15-AN15 -> 0.9 | AZ15: =AW15-AR15 -> -16.116429 | BA15: =AU15-AP15 -> 12.02202 | BC15: =SUMPRODUCT((data_segment_HC_gains!$A$25:$A$44="10-19")*(data_segment_HC_gains!$B$25:$B$44="p75")*data_segment_HC_gains!$C$25:$C$44) -> 12 | BD15: =SUMPRODUCT((data_segment_HC_gains!$A$25:$A$44="10-19")*(data_segment_HC_gains!$B$25:$B$44="p75")*data_segment_HC_gains!$E$25:$E$44) -> 200.4 | BE15: =SUMPRODUCT((data_raw_slopes!$A$2:$A$41="10-19")*(data_raw_slopes!$B$2:$B$41="payer")*(data_raw_slopes!$C$2:$C$41="p75")*data_raw_slopes!$E$2:$E$41) -> 210.6 | BF15: =BD15-BE15 -> -10.2 | BG15: =SUMPRODUCT((data_segment_HC_gains!$A$25:$A$44="10-19")*(data_segment_HC_gains!$B$25:$B$44="p75")*data_segment_HC_gains!$G$25:$G$44) -> 32.05 | BH15: =BC15*1.15 -> 13.8 | BI15: =BD15-BG15*(1-(saga_progression_new!$E$17/saga_progression_old!$C$16))+IF(BC15<ns_new!$E$11,0,IF(BC15*1.25<ns_new!$E$12-ns_new!$E$11,ns_new!$F$11,IF(BC15*1.25^2<ns_new!$E$13-ns_new!$E$12,ns_new!$F$11+ns_new!$F$12,ns_new!$F$11+ns_new!$F$12+ns_new!$F$13))) -> 279.79643 | BJ15: =BE15+(IF(SUMPRODUCT((data_raw_slopes!$A$2:$A$41="10-19")*(data_raw_slopes!$B$2:$B$41="payer")*(data_raw_slopes!$C$2:$C$41="p75")*data_raw_slopes!$F$2:$F$41)>0,SUMPRODUCT((data_raw_slopes!$A$2:$A$41="10-19")*(data_raw_slopes!$B$2:$B$41="payer")*(data_raw_slopes!$C$2:$C$41="p75")*data_raw_slopes!$F$2:$F$41),SUMPRODUCT((data_raw_slopes!$A$2:$A$41="10-19")*(data_raw_slopes!$B$2:$B$41="payer")*(data_raw_slopes!$C$2:$C$41="p75")*data_raw_slopes!$G$2:$G$41)))*BC15*0.15 -> 232.49736 | BK15: =BI15-BJ15 -> 47.299069 | BL15: =BG15*(saga_progression_new!$E$17/saga_progression_old!$C$16) -> 11.446429 | BM15: =BK15-BF15 -> 57.499069 | BN15: =BH15-BC15 -> 1.8 | BO15: =BL15-BG15 -> -20.603571 | BP15: =BJ15-BE15 -> 21.89736 | BR15: =SUMPRODUCT((data_segment_HC_gains!$A$25:$A$44="10-19")*(data_segment_HC_gains!$B$25:$B$44="p90")*data_segment_HC_gains!$C$25:$C$44) -> 20 | BS15: =SUMPRODUCT((data_segment_HC_gains!$A$25:$A$44="10-19")*(data_segment_HC_gains!$B$25:$B$44="p90")*data_segment_HC_gains!$E$25:$E$44) -> 315.99 | BT15: =SUMPRODUCT((data_raw_slopes!$A$2:$A$41="10-19")*(data_raw_slopes!$B$2:$B$41="payer")*(data_raw_slopes!$C$2:$C$41="p90")*data_raw_slopes!$E$2:$E$41) -> 343.63 | BU15: =BS15-BT15 -> -27.64 | BV15: =SUMPRODUCT((data_segment_HC_gains!$A$25:$A$44="10-19")*(data_segment_HC_gains!$B$25:$B$44="p90")*data_segment_HC_gains!$G$25:$G$44) -> 46.02 | BW15: =BR15*1.15 -> 23 | BX15: =BS15-BV15*(1-(saga_progression_new!$E$17/saga_progression_old!$C$16))+IF(BR15<ns_new!$E$11,0,IF(BR15*1.25<ns_new!$E$12-ns_new!$E$11,ns_new!$F$11,IF(BR15*1.25^2<ns_new!$E$13-ns_new!$E$12,ns_new!$F$11+ns_new!$F$12,ns_new!$F$11+ns_new!$F$12+ns_new!$F$13))) -> 386.40571 | BY15: =BT15+(IF(SUMPRODUCT((data_raw_slopes!$A$2:$A$41="10-19")*(data_raw_slopes!$B$2:$B$41="payer")*(data_raw_slopes!$C$2:$C$41="p90")*data_raw_slopes!$F$2:$F$41)>0,SUMPRODUCT((data_raw_slopes!$A$2:$A$41="10-19")*(data_raw_slopes!$B$2:$B$41="payer")*(data_raw_slopes!$C$2:$C$41="p90")*data_raw_slopes!$F$2:$F$41),SUMPRODUCT((data_raw_slopes!$A$2:$A$41="10-19")*(data_raw_slopes!$B$2:$B$41="payer")*(data_raw_slopes!$C$2:$C$41="p90")*data_raw_slopes!$G$2:$G$41)))*BR15*0.15 -> 394.3387 | BZ15: =BX15-BY15 -> -7.9329857 | CA15: =BV15*(saga_progression_new!$E$17/saga_progression_old!$C$16) -> 16.435714 | CB15: =BZ15-BU15 -> 19.707014 | CC15: =BW15-BR15 -> 3 | CD15: =CA15-BV15 -> -29.584286 | CE15: =BY15-BT15 -> 50.7087
