Workbook

Sheet cal_parsed
A1: calendar | B1: event | C1: start | D1: dur
A2: cal_curr | B2: Kite Festival | C2: 3 | D2: 3
A3: cal_curr | B3: Kite Festival | C3: 10 | D3: 3
A4: cal_curr | B4: Kite Festival | C4: 17 | D4: 3
A5: cal_curr | B5: Hatchling Hideaway | C5: 6 | D5: 4
A6: cal_curr | B6: Hatchling Hideaway | C6: 20 | D6: 4
A7: cal_curr | B7: Hatchling Hideaway | C7: 1 | D7: 2
A8: cal_curr | B8: Hatchling Hideaway | C8: 13 | D8: 4
A9: cal_curr | B9: Progress Pack | C9: 3 | D9: 3
A10: cal_curr | B10: Progress Pack | C10: 10 | D10: 3
A11: cal_curr | B11: Progress Pack | C11: 17 | D11: 3
A12: cal_curr | B12: Top Teams Leaderboard | C12: 6 | D12: 7
A13: cal_curr | B13: Top Teams Leaderboard | C13: 13 | D13: 7
... A195: cal_new | B195: Night Sky | C195: 21 | D195: 1

Sheet contents
A1: Name | B1: Link to old | C1: Link to new
A2: =RR_v2!A1 -> River Rush | B2: RR | C2: RR_v2
A3: =NS_v2!A1 -> Night Sky (5 Segment) - weekend (⚠️ WARNING: This sheet no longe represents the NS_v2, it's the Weekend version of NS_v2 instead) | B3: NS | C3: NS_v2
A4: =J_v2!A1 -> Jigsaw Puzzle | B4: J | C4: J_v2
A5: =TaD_v2!A1 -> Target Day | B5: TaD | C5: TaD_v2
A6: =c_day_v2!A1 -> Daily Rewards - NEW | B6: c_day | C6: c_day_v2
A7: =c_saga_v2!A1 -> Saga Progression - NEW | B7: c_saga | C7: c_saga_v2
A8: =F_v2!A1 -> Flock Flurry | B8: F | C8: F_v2
A9: =Ki_v2!A1 -> Kite Festival | B9: Ki | C9: Ki_v2
A10: =BB_v2!A1 -> Bomb's Ballet | B10: BB | C10: BB_v2
A11: =Ph_v2!A1 -> Photoshoot | B11: Ph | C11: Ph_v2
A12: =Race_v2!A1 -> All LB Challenges | B12: Race | C12: Race_v2
A13: =HH_v2!A1 -> Hatchling Hideaway | B13: HH | C13: HH_v2
A14: SP | B14: SP | C14: SP_v2
A15: SP_lb | B15: SP_lb | C15: SP_lb_v2
A16: Raindbow Maker | B16: - | C16: RM_1st | D16: RM_2nd

Sheet c_saga
A1: Saga Progression - Variant LiveOps 2.0
B3: 0-9 | E3: 10-19 | H3: 20-39 | K3: 40-99 | N3: 100+ | AB3: all segs
A4: Node | B4: Levels Req | C4: RewardChestId | D4: HC Reward | E4: Levels Req | F4: RewardChestId | G4: HC Reward | H4: Levels Req | I4: RewardChestId | J4: HC Reward | K4: Levels Req | L4: RewardChestId | M4: HC Reward | N4: Levels Req | O4: RewardChestId | P4: HC Reward | R4: 👁 | Y4: Original | Z4: Old Nerf | AB4: SPT | AC4: Red | AD4: Chuck | AE4: Bomb | AF4: Slingshot | AG4: Shuffle | AH4: Comet | AI4: Unlimited Lives | AJ4: Unlimited Red | AK4: Unlimited Chuck | AL4: Unlimited Bomb | AM4: Coin Val | AO4: cur | AP4: image
A5: 1 | B5: 10 | C5: 1 | D5: 10 | E5: 10 | F5: 1 | G5: 10 | H5: 10 | I5: 1 | J5: 10 | K5: 10 | L5: 1 | M5: 10 | N5: 10 | O5: 1 | P5: 10 | S5: 10 | U5: 15 | Y5: 15 | Z5: 10 | AB5: 0 | AC5: 0 | AD5: 0 | AE5: 0 | AF5: 0 | AG5: 0 | AH5: 0 | AI5: 15 | AJ5: 0 | AK5: 0 | AL5: 0 | AM5: 62.55 | AN5: 100 | AO5: Coins | AQ5: -37.45
A6: 2 | B6: 10 | C6: 1 | D6: 0 | E6: 10 | F6: 1 | G6: 0 | H6: 10 | I6: 1 | J6: 0 | K6: 10 | L6: 1 | M6: 0 | N6: 10 | O6: 1 | P6: 0 | S6: 1 | U6: 15 | Y6: 15 | Z6: 10 | AB6: 0 | AC6: 1 | AD6: 0 | AE6: 0 | AF6: 0 | AG6: 0 | AH6: 0 | AI6: 15 | AJ6: 0 | AK6: 0 | AL6: 0 | AM6: 95.55 | AN6: 112.55 | AO6: SPT | AQ6: -17
A7: 3 | B7: 10 | C7: 2 | D7: 10 | E7: 10 | F7: 2 | G7: 10 | H7: 10 | I7: 2 | J7: 10 | K7: 10 | L7: 2 | M7: 10 | N7: 10 | O7: 2 | P7: 10 | S7: 10 | U7: 15 | Y7: 15 | Z7: 10 | AB7: 0 | AC7: 0 | AD7: 0 | AE7: 0 | AF7: 0 | AG7: 0 | AH7: 0 | AI7: 15 | AJ7: 0 | AK7: 0 | AL7: 0 | AM7: 62.55 | AN7: 95.55 | AO7: Red | AQ7: -33
A8: 4 | B8: 10 | C8: 2 | D8: 0 | E8: 10 | F8: 2 | G8: 0 | H8: 10 | I8: 2 | J8: 0 | K8: 10 | L8: 2 | M8: 0 | N8: 10 | O8: 2 | P8: 0 | S8: 1 | U8: 15 | Y8: 20 | Z8: 10 | AB8: 0 | AC8: 0 | AD8: 0 | AE8: 0 | AF8: 1 | AG8: 0 | AH8: 0 | AI8: 15 | AJ8: 0 | AK8: 0 | AL8: 0 | AM8: 229.55 | AN8: 95.55 | AO8: Chuck | AQ8: 134
A9: 5 | B9: 10 | C9: 2 | D9: 0 | E9: 10 | F9: 2 | G9: 0 | H9: 10 | I9: 2 | J9: 0 | K9: 10 | L9: 2 | M9: 0 | N9: 10 | O9: 2 | P9: 0 | S9: 1 | U9: 15 | Y9: 20 | Z9: 10 | AB9: 0 | AC9: 0 | AD9: 1 | AE9: 0 | AF9: 0 | AG9: 0 | AH9: 0 | AI9: 15 | AJ9: 0 | AK9: 0 | AL9: 0 | AM9: 112.55 | AN9: 100 | AO9: Bomb | AQ9: 12.55
A10: 6 | B10: 10 | C10: 3 | D10: 0 | E10: 10 | F10: 3 | G10: 0 | H10: 10 | I10: 3 | J10: 0 | K10: 10 | L10: 3 | M10: 0 | N10: 10 | O10: 3 | P10: 0 | S10: 1 | U10: 20 | Y10: 20 | Z10: 15 | AB10: 0 | AC10: 0 | AD10: 0 | AE10: 0 | AF10: 0 | AG10: 1 | AH10: 1 | AI10: 20 | AJ10: 0 | AK10: 0 | AL10: 0 | AM10: 150.4 | AN10: 229.55 | AO10: Slingshot | AQ10: -79.15
A11: 7 | B11: 10 | C11: 3 | D11: 10 | E11: 10 | F11: 3 | G11: 10 | H11: 10 | I11: 3 | J11: 10 | K11: 10 | L11: 3 | M11: 10 | N11: 10 | O11: 3 | P11: 10 | S11: 10 | U11: 20 | Y11: 25 | Z11: 15 | AB11: 0 | AC11: 0 | AD11: 0 | AE11: 0 | AF11: 0 | AG11: 0 | AH11: 0 | AI11: 20 | AJ11: 0 | AK11: 0 | AL11: 0 | AM11: 83.4 | AN11: 192.1 | AO11: Shuffle | AQ11: -108.7
A12: 8 | B12: 10 | C12: 3 | D12: 0 | E12: 10 | F12: 3 | G12: 0 | H12: 10 | I12: 3 | J12: 0 | K12: 10 | L12: 3 | M12: 0 | N12: 10 | O12: 3 | P12: 0 | S12: 1 | U12: 30 | Y12: 25 | Z12: 15 | AB12: 0 | AC12: 0 | AD12: 0 | AE12: 1 | AF12: 0 | AG12: 0 | AH12: 0 | AI12: 30 | AJ12: 0 | AK12: 0 | AL12: 0 | AM12: 192.1 | AN12: 217 | AO12: Comet | AQ12: -24.9
A13: 9 | B13: 10 | C13: 3 | D13: 10 | E13: 10 | F13: 3 | G13: 10 | H13: 10 | I13: 3 | J13: 10 | K13: 10 | L13: 3 | M13: 10 | N13: 10 | O13: 3 | P13: 10 | S13: 10 | U13: 60 | Y13: 25 | Z13: 15 | AB13: 0 | AC13: 0 | AD13: 0 | AE13: 0 | AF13: 0 | AG13: 0 | AH13: 0 | AI13: 60 | AJ13: 0 | AK13: 0 | AL13: 0 | AM13: 250.2 | AN13: 300.2 | AO13: Unlimited Lives | AQ13: -50
A14: 10 | B14: 10 | C14: 4 | D14: 20 | E14: 10 | F14: 4 | G14: 20 | H14: 10 | I14: 4 | J14: 20 | K14: 10 | L14: 4 | M14: 20 | N14: 10 | O14: 4 | P14: 20 | S14: 20 | U14: 60 | Y14: 30 | Z14: 20 | AB14: 0 | AC14: 0 | AD14: 0 | AE14: 1 | AF14: 0 | AG14: 0 | AH14: 0 | AI14: 60 | AJ14: 0 | AK14: 0 | AL14: 0 | AM14: 250.2 | AN14: 117 | AO14: Unlimited Red | AQ14: 133.2
A16: Total per cycle | B16: =SUM(B5:B14) -> 100 | D16: =SUM(D5:D14) -> 60 | E16: =SUM(E5:E14) -> 100 | G16: =SUM(G5:G14) -> 60 | H16: =SUM(H5:H14) -> 100 | J16: =SUM(J5:J14) -> 60 | K16: =SUM(K5:K14) -> 100 | M16: =SUM(M5:M14) -> 60 | N16: =SUM(N5:N14) -> 100 | P16: =SUM(P5:P14) -> 60 | Y16: =SUM(Y5:Y14) -> 210 | Z16: =SUM(Z5:Z14) -> 130 | AC16: =SUM(AC5:AC14) -> 1 | AD16: =SUM(AD5:AD14) -> 1 | AE16: =SUM(AE5:AE14) -> 2 | AF16: =SUM(AF5:AF14) -> 1 | AG16: =SUM(AG5:AG14) -> 1 | AH16: =SUM(AH5:AH14) -> 1
A17: HC per level | D17: =D16/B16 -> 0.6 | G17: =G16/E16 -> 0.6 | J17: =J16/H16 -> 0.6 | M17: =M16/K16 -> 0.6 | P17: =P16/N16 -> 0.6 | Y17: =Y16/$N$16 -> 2.1 | Z17: =Z16/$N$16 -> 1.3
Y19: =Y16/saga_progression_old!$C$15 -> #REF! | Z19: =Z16/saga_progression_old!$C$15 -> #REF!
D28: 0-9 | E28: 10-19 | G28: 20-39 | H28: 40-99 | J28: 100+ | M28: =IFERROR(__xludf.DUMMYFUNCTION("join("","", D28:J28)"),"0-9,10-19,,20-39,40-99,,100+") -> 0-9,10-19,,20-39,40-99,,100+
D31: {=TRANSPOSE(D28:J28)} -> 0-9
D32: 10-19
D34: 20-39
D35: 40-99
D37: 100+

Sheet c_saga_v2
A1: Saga Progression - NEW
B3: 0-9 | E3: 10-19 | H3: 20-39 | K3: 40-99 | N3: 100+ | AB3: all segs
A4: Node | B4: Levels Req | C4: RewardChestId | D4: HC Reward | E4: Levels Req | F4: RewardChestId | G4: HC Reward | H4: Levels Req | I4: RewardChestId | J4: HC Reward | K4: Levels Req | L4: RewardChestId | M4: HC Reward | N4: Levels Req | O4: RewardChestId | P4: HC Reward | R4: 👁 | Y4: Original | Z4: Old Nerf | AB4: SPT | AC4: Red | AD4: Chuck | AE4: Bomb | AF4: Slingshot | AG4: Shuffle | AH4: Comet | AI4: Unlimited Lives | AJ4: Unlimited Red | AK4: Unlimited Chuck | AL4: Unlimited Bomb | AM4: Coin Val | AO4: cur | AP4: image
A5: 1 | B5: 10 | C5: 1 | D5: 10 | E5: 10 | F5: 1 | G5: 10 | H5: 10 | I5: 1 | J5: 10 | K5: 10 | L5: 1 | M5: 10 | N5: 10 | O5: 1 | P5: 10 | R5: =IFERROR(__xludf.DUMMYFUNCTION("LET( names, HSTACK(""Coins"", AB$4:AL$4), amounts, HSTACK(D5, AB5:AL5), lookupNames, $AO$5:$AO$16, lookupImages, $AP$5:$AP$16, imgs, MAP(names, LAMBDA(n, XLOOKUP(n, lookupNames, lookupImages))), keepImgs, FILTER(imgs, amounts<>0), keepAmount"&"s, FILTER(amounts, amounts<>0), MAKEARRAY( 1, COLUMNS(keepAmounts)*2, LAMBDA(r,c, IF( ISODD(c), INDEX(keepImgs, 1, ROUNDUP(c/2)), INDEX(keepAmounts, 1, c/2) ) ) ) )"),"") | S5: =IFERROR(__xludf.DUMMYFUNCTION("""COMPUTED_VALUE"""),10.0) -> 10 | T5: =IFERROR(__xludf.DUMMYFUNCTION("""COMPUTED_VALUE"""),"") | U5: =IFERROR(__xludf.DUMMYFUNCTION("""COMPUTED_VALUE"""),15.0) -> 15 | Y5: 15 | Z5: 10 | AB5: 0 | AC5: 0 | AD5: 0 | AE5: 0 | AF5: 0 | AG5: 0 | AH5: 0 | AI5: 15 | AJ5: 0 | AK5: 0 | AL5: 0 | AM5: =SUMPRODUCT(AB5:AL5, {0,33,50,67,167,67,50,4.17,7.56,12.17,16.22}) -> 62.55 | AN5: 100 | AO5: Coins | AQ5: =AM5-AN5 -> -37.45
A6: 2 | B6: 10 | C6: 1 | D6: 0 | E6: 10 | F6: 1 | G6: 0 | H6: 10 | I6: 1 | J6: 0 | K6: 10 | L6: 1 | M6: 0 | N6: 10 | O6: 1 | P6: 0 | R6: =IFERROR(__xludf.DUMMYFUNCTION("LET( names, HSTACK(""Coins"", AB$4:AL$4), amounts, HSTACK(D6, AB6:AL6), lookupNames, $AO$5:$AO$16, lookupImages, $AP$5:$AP$16, imgs, MAP(names, LAMBDA(n, XLOOKUP(n, lookupNames, lookupImages))), keepImgs, FILTER(imgs, amounts<>0), keepAmount"&"s, FILTER(amounts, amounts<>0), MAKEARRAY( 1, COLUMNS(keepAmounts)*2, LAMBDA(r,c, IF( ISODD(c), INDEX(keepImgs, 1, ROUNDUP(c/2)), INDEX(keepAmounts, 1, c/2) ) ) ) )"),"") | S6: =IFERROR(__xludf.DUMMYFUNCTION("""COMPUTED_VALUE"""),1.0) -> 1 | T6: =IFERROR(__xludf.DUMMYFUNCTION("""COMPUTED_VALUE"""),"") | U6: =IFERROR(__xludf.DUMMYFUNCTION("""COMPUTED_VALUE"""),15.0) -> 15 | Y6: 15 | Z6: 10 | AB6: 0 | AC6: 1 | AD6: 0 | AE6: 0 | AF6: 0 | AG6: 0 | AH6: 0 | AI6: 15 | AJ6: 0 | AK6: 0 | AL6: 0 | AM6: =SUMPRODUCT(AB6:AL6, {0,33,50,67,167,67,50,4.17,7.56,12.17,16.22}) -> 95.55 | AN6: 112.55 | AO6: {=TRANSPOSE(AB4:AL4)} -> SPT | AQ6: =AM6-AN6 -> -17
A7: 3 | B7: 10 | C7: 2 | D7: 10 | E7: 10 | F7: 2 | G7: 10 | H7: 10 | I7: 2 | J7: 10 | K7: 10 | L7: 2 | M7: 10 | N7: 10 | O7: 2 | P7: 10 | R7: =IFERROR(__xludf.DUMMYFUNCTION("LET( names, HSTACK(""Coins"", AB$4:AL$4), amounts, HSTACK(D7, AB7:AL7), lookupNames, $AO$5:$AO$16, lookupImages, $AP$5:$AP$16, imgs, MAP(names, LAMBDA(n, XLOOKUP(n, lookupNames, lookupImages))), keepImgs, FILTER(imgs, amounts<>0), keepAmount"&"s, FILTER(amounts, amounts<>0), MAKEARRAY( 1, COLUMNS(keepAmounts)*2, LAMBDA(r,c, IF( ISODD(c), INDEX(keepImgs, 1, ROUNDUP(c/2)), INDEX(keepAmounts, 1, c/2) ) ) ) )"),"") | S7: =IFERROR(__xludf.DUMMYFUNCTION("""COMPUTED_VALUE"""),10.0) -> 10 | T7: =IFERROR(__xludf.DUMMYFUNCTION("""COMPUTED_VALUE"""),"") | U7: =IFERROR(__xludf.DUMMYFUNCTION("""COMPUTED_VALUE"""),15.0) -> 15 | Y7: 15 | Z7: 10 | AB7: 0 | AC7: 0 | AD7: 0 | AE7: 0 | AF7: 0 | AG7: 0 | AH7: 0 | AI7: 15 | AJ7: 0 | AK7: 0 | AL7: 0 | AM7: =SUMPRODUCT(AB7:AL7, {0,33,50,67,167,67,50,4.17,7.56,12.17,16.22}) -> 62.55 | AN7: 95.55 | AO7: Red | AQ7: =AM7-AN7 -> -33
A8: 4 | B8: 10 | C8: 2 | D8: 0 | E8: 10 | F8: 2 | G8: 0 | H8: 10 | I8: 2 | J8: 0 | K8: 10 | L8: 2 | M8: 0 | N8: 10 | O8: 2 | P8: 0 | R8: =IFERROR(__xludf.DUMMYFUNCTION("LET( names, HSTACK(""Coins"", AB$4:AL$4), amounts, HSTACK(D8, AB8:AL8), lookupNames, $AO$5:$AO$16, lookupImages, $AP$5:$AP$16, imgs, MAP(names, LAMBDA(n, XLOOKUP(n, lookupNames, lookupImages))), keepImgs, FILTER(imgs, amounts<>0), keepAmount"&"s, FILTER(amounts, amounts<>0), MAKEARRAY( 1, COLUMNS(keepAmounts)*2, LAMBDA(r,c, IF( ISODD(c), INDEX(keepImgs, 1, ROUNDUP(c/2)), INDEX(keepAmounts, 1, c/2) ) ) ) )"),"") | S8: =IFERROR(__xludf.DUMMYFUNCTION("""COMPUTED_VALUE"""),1.0) -> 1 | T8: =IFERROR(__xludf.DUMMYFUNCTION("""COMPUTED_VALUE"""),"") | U8: =IFERROR(__xludf.DUMMYFUNCTION("""COMPUTED_VALUE"""),15.0) -> 15 | Y8: 20 | Z8: 10 | AB8: 0 | AC8: 0 | AD8: 0 | AE8: 0 | AF8: 1 | AG8: 0 | AH8: 0 | AI8: 15 | AJ8: 0 | AK8: 0 | AL8: 0 | AM8: =SUMPRODUCT(AB8:AL8, {0,33,50,67,167,67,50,4.17,7.56,12.17,16.22}) -> 229.55 | AN8: 95.55 | AO8: Chuck | AQ8: =AM8-AN8 -> 134
A9: 5 | B9: 10 | C9: 2 | D9: 0 | E9: 10 | F9: 2 | G9: 0 | H9: 10 | I9: 2 | J9: 0 | K9: 10 | L9: 2 | M9: 0 | N9: 10 | O9: 2 | P9: 0 | R9: =IFERROR(__xludf.DUMMYFUNCTION("LET( names, HSTACK(""Coins"", AB$4:AL$4), amounts, HSTACK(D9, AB9:AL9), lookupNames, $AO$5:$AO$16, lookupImages, $AP$5:$AP$16, imgs, MAP(names, LAMBDA(n, XLOOKUP(n, lookupNames, lookupImages))), keepImgs, FILTER(imgs, amounts<>0), keepAmount"&"s, FILTER(amounts, amounts<>0), MAKEARRAY( 1, COLUMNS(keepAmounts)*2, LAMBDA(r,c, IF( ISODD(c), INDEX(keepImgs, 1, ROUNDUP(c/2)), INDEX(keepAmounts, 1, c/2) ) ) ) )"),"") | S9: =IFERROR(__xludf.DUMMYFUNCTION("""COMPUTED_VALUE"""),1.0) -> 1 | T9: =IFERROR(__xludf.DUMMYFUNCTION("""COMPUTED_VALUE"""),"") | U9: =IFERROR(__xludf.DUMMYFUNCTION("""COMPUTED_VALUE"""),15.0) -> 15 | Y9: 20 | Z9: 10 | AB9: 0 | AC9: 0 | AD9: 1 | AE9: 0 | AF9: 0 | AG9: 0 | AH9: 0 | AI9: 15 | AJ9: 0 | AK9: 0 | AL9: 0 | AM9: =SUMPRODUCT(AB9:AL9, {0,33,50,67,167,67,50,4.17,7.56,12.17,16.22}) -> 112.55 | AN9: 100 | AO9: Bomb | AQ9: =AM9-AN9 -> 12.55
A10: 6 | B10: 10 | C10: 3 | D10: 0 | E10: 10 | F10: 3 | G10: 0 | H10: 10 | I10: 3 | J10: 0 | K10: 10 | L10: 3 | M10: 0 | N10: 10 | O10: 3 | P10: 0 | R10: =IFERROR(__xludf.DUMMYFUNCTION("LET( names, HSTACK(""Coins"", AB$4:AL$4), amounts, HSTACK(D10, AB10:AL10), lookupNames, $AO$5:$AO$16, lookupImages, $AP$5:$AP$16, imgs, MAP(names, LAMBDA(n, XLOOKUP(n, lookupNames, lookupImages))), keepImgs, FILTER(imgs, amounts<>0), keepAmo"&"unts, FILTER(amounts, amounts<>0), MAKEARRAY( 1, COLUMNS(keepAmounts)*2, LAMBDA(r,c, IF( ISODD(c), INDEX(keepImgs, 1, ROUNDUP(c/2)), INDEX(keepAmounts, 1, c/2) ) ) ) )"),"") | S10: =IFERROR(__xludf.DUMMYFUNCTION("""COMPUTED_VALUE"""),1.0) -> 1 | T10: =IFERROR(__xludf.DUMMYFUNCTION("""COMPUTED_VALUE"""),"") | U10: =IFERROR(__xludf.DUMMYFUNCTION("""COMPUTED_VALUE"""),1.0) -> 1 | V10: =IFERROR(__xludf.DUMMYFUNCTION("""COMPUTED_VALUE"""),"") | W10: =IFERROR(__xludf.DUMMYFUNCTION("""COMPUTED_VALUE"""),20.0) -> 20 | Y10: 20 | Z10: 15 | AB10: 0 | AC10: 0 | AD10: 0 | AE10: 0 | AF10: 0 | AG10: 1 | AH10: 1 | AI10: 20 | AJ10: 0 | AK10: 0 | AL10: 0 | AM10: =SUMPRODUCT(AB10:AL10, {0,33,50,67,167,67,50,4.17,7.56,12.17,16.22}) -> 200.4 | AN10: 229.55 | AO10: Slingshot | AQ10: =AM10-AN10 -> -29.15
A11: 7 | B11: 10 | C11: 3 | D11: 10 | E11: 10 | F11: 3 | G11: 10 | H11: 10 | I11: 3 | J11: 10 | K11: 10 | L11: 3 | M11: 10 | N11: 10 | O11: 3 | P11: 10 | R11: =IFERROR(__xludf.DUMMYFUNCTION("LET( names, HSTACK(""Coins"", AB$4:AL$4), amounts, HSTACK(D11, AB11:AL11), lookupNames, $AO$5:$AO$16, lookupImages, $AP$5:$AP$16, imgs, MAP(names, LAMBDA(n, XLOOKUP(n, lookupNames, lookupImages))), keepImgs, FILTER(imgs, amounts<>0), keepAmo"&"unts, FILTER(amounts, amounts<>0), MAKEARRAY( 1, COLUMNS(keepAmounts)*2, LAMBDA(r,c, IF( ISODD(c), INDEX(keepImgs, 1, ROUNDUP(c/2)), INDEX(keepAmounts, 1, c/2) ) ) ) )"),"") | S11: =IFERROR(__xludf.DUMMYFUNCTION("""COMPUTED_VALUE"""),10.0) -> 10 | T11: =IFERROR(__xludf.DUMMYFUNCTION("""COMPUTED_VALUE"""),"") | U11: =IFERROR(__xludf.DUMMYFUNCTION("""COMPUTED_VALUE"""),20.0) -> 20 | Y11: 25 | Z11: 15 | AB11: 0 | AC11: 0 | AD11: 0 | AE11: 0 | AF11: 0 | AG11: 0 | AH11: 0 | AI11: 20 | AJ11: 0 | AK11: 0 | AL11: 0 | AM11: =SUMPRODUCT(AB11:AL11, {0,33,50,67,167,67,50,4.17,7.56,12.17,16.22}) -> 83.4 | AN11: 192.1 | AO11: Shuffle | AQ11: =AM11-AN11 -> -108.7
A12: 8 | B12: 10 | C12: 3 | D12: 0 | E12: 10 | F12: 3 | G12: 0 | H12: 10 | I12: 3 | J12: 0 | K12: 10 | L12: 3 | M12: 0 | N12: 10 | O12: 3 | P12: 0 | R12: =IFERROR(__xludf.DUMMYFUNCTION("LET( names, HSTACK(""Coins"", AB$4:AL$4), amounts, HSTACK(D12, AB12:AL12), lookupNames, $AO$5:$AO$16, lookupImages, $AP$5:$AP$16, imgs, MAP(names, LAMBDA(n, XLOOKUP(n, lookupNames, lookupImages))), keepImgs, FILTER(imgs, amounts<>0), keepAmo"&"unts, FILTER(amounts, amounts<>0), MAKEARRAY( 1, COLUMNS(keepAmounts)*2, LAMBDA(r,c, IF( ISODD(c), INDEX(keepImgs, 1, ROUNDUP(c/2)), INDEX(keepAmounts, 1, c/2) ) ) ) )"),"") | S12: =IFERROR(__xludf.DUMMYFUNCTION("""COMPUTED_VALUE"""),1.0) -> 1 | T12: =IFERROR(__xludf.DUMMYFUNCTION("""COMPUTED_VALUE"""),"") | U12: =IFERROR(__xludf.DUMMYFUNCTION("""COMPUTED_VALUE"""),30.0) -> 30 | Y12: 25 | Z12: 15 | AB12: 0 | AC12: 0 | AD12: 0 | AE12: 1 | AF12: 0 | AG12: 0 | AH12: 0 | AI12: 30 | AJ12: 0 | AK12: 0 | AL12: 0 | AM12: =SUMPRODUCT(AB12:AL12, {0,33,50,67,167,67,50,4.17,7.56,12.17,16.22}) -> 192.1 | AN12: 217 | AO12: Comet | AQ12: =AM12-AN12 -> -24.9
A13: 9 | B13: 10 | C13: 3 | D13: 10 | E13: 10 | F13: 3 | G13: 10 | H13: 10 | I13: 3 | J13: 10 | K13: 10 | L13: 3 | M13: 10 | N13: 10 | O13: 3 | P13: 10 | R13: =IFERROR(__xludf.DUMMYFUNCTION("LET( names, HSTACK(""Coins"", AB$4:AL$4), amounts, HSTACK(D13, AB13:AL13), lookupNames, $AO$5:$AO$16, lookupImages, $AP$5:$AP$16, imgs, MAP(names, LAMBDA(n, XLOOKUP(n, lookupNames, lookupImages))), keepImgs, FILTER(imgs, amounts<>0), keepAmo"&"unts, FILTER(amounts, amounts<>0), MAKEARRAY( 1, COLUMNS(keepAmounts)*2, LAMBDA(r,c, IF( ISODD(c), INDEX(keepImgs, 1, ROUNDUP(c/2)), INDEX(keepAmounts, 1, c/2) ) ) ) )"),"") | S13: =IFERROR(__xludf.DUMMYFUNCTION("""COMPUTED_VALUE"""),10.0) -> 10 | T13: =IFERROR(__xludf.DUMMYFUNCTION("""COMPUTED_VALUE"""),"") | U13: =IFERROR(__xludf.DUMMYFUNCTION("""COMPUTED_VALUE"""),60.0) -> 60 | Y13: 25 | Z13: 15 | AB13: 0 | AC13: 0 | AD13: 0 | AE13: 0 | AF13: 0 | AG13: 0 | AH13: 0 | AI13: 60 | AJ13: 0 | AK13: 0 | AL13: 0 | AM13: =SUMPRODUCT(AB13:AL13, {0,33,50,67,167,67,50,4.17,7.56,12.17,16.22}) -> 250.2 | AN13: 300.2 | AO13: Unlimited Lives | AQ13: =AM13-AN13 -> -50
A14: 10 | B14: 10 | C14: 4 | D14: 20 | E14: 10 | F14: 4 | G14: 20 | H14: 10 | I14: 4 | J14: 20 | K14: 10 | L14: 4 | M14: 20 | N14: 10 | O14: 4 | P14: 20 | R14: =IFERROR(__xludf.DUMMYFUNCTION("LET( names, HSTACK(""Coins"", AB$4:AL$4), amounts, HSTACK(D14, AB14:AL14), lookupNames, $AO$5:$AO$16, lookupImages, $AP$5:$AP$16, imgs, MAP(names, LAMBDA(n, XLOOKUP(n, lookupNames, lookupImages))), keepImgs, FILTER(imgs, amounts<>0), keepAmo"&"unts, FILTER(amounts, amounts<>0), MAKEARRAY( 1, COLUMNS(keepAmounts)*2, LAMBDA(r,c, IF( ISODD(c), INDEX(keepImgs, 1, ROUNDUP(c/2)), INDEX(keepAmounts, 1, c/2) ) ) ) )"),"") | S14: =IFERROR(__xludf.DUMMYFUNCTION("""COMPUTED_VALUE"""),20.0) -> 20 | T14: =IFERROR(__xludf.DUMMYFUNCTION("""COMPUTED_VALUE"""),"") | U14: =IFERROR(__xludf.DUMMYFUNCTION("""COMPUTED_VALUE"""),1.0) -> 1 | V14: =IFERROR(__xludf.DUMMYFUNCTION("""COMPUTED_VALUE"""),"") | W14: =IFERROR(__xludf.DUMMYFUNCTION("""COMPUTED_VALUE"""),60.0) -> 60 | Y14: 30 | Z14: 20 | AB14: 0 | AC14: 0 | AD14: 0 | AE14: 1 | AF14: 0 | AG14: 0 | AH14: 0 | AI14: 60 | AJ14: 0 | AK14: 0 | AL14: 0 | AM14: =SUMPRODUCT(AB14:AL14, {0,33,50,67,167,67,50,4.17,7.56,12.17,16.22}) -> 317.2 | AN14: 117 | AO14: Unlimited Red | AQ14: =AM14-AN14 -> 200.2
AO15: Unlimited Chuck
A16: Total per cycle | B16: =SUM(B5:B14) -> 100 | D16: =SUM(D5:D14) -> 60 | E16: =SUM(E5:E14) -> 100 | G16: =SUM(G5:G14) -> 60 | H16: =SUM(H5:H14) -> 100 | J16: =SUM(J5:J14) -> 60 | K16: =SUM(K5:K14) -> 100 | M16: =SUM(M5:M14) -> 60 | N16: =SUM(N5:N14) -> 100 | P16: =SUM(P5:P14) -> 60 | Y16: =SUM(Y5:Y14) -> 210 | Z16: =SUM(Z5:Z14) -> 130 | AO16: Unlimited Bomb
A17: HC per level | D17: =D16/B16 -> 0.6 | G17: =G16/E16 -> 0.6 | J17: =J16/H16 -> 0.6 | M17: =M16/K16 -> 0.6 | P17: =P16/N16 -> 0.6 | Y17: =Y16/$N$16 -> 2.1 | Z17: =Z16/$N$16 -> 1.3
Y19: =Y16/saga_progression_old!$C$15 -> #REF! | Z19: =Z16/saga_progression_old!$C$15 -> #REF!

Sheet c_day
A1: Daily Rewards - OLD
L2: all segs
A3: Day | B3: HC Reward | E3: 👁 | L3: Variant 1 | AB3: cur | AC3: image
A4: 1 | B4: =average(M5,M16,M26,M35,M45) -> 10 | L4: Day | M4: Coin | N4: SPT | O4: Red | P4: Chuck | Q4: Bomb | R4: Slingshot | S4: Shuffle | T4: Comet | U4: Unlimited Lives | V4: Unlimited Red | W4: Unlimited Chuck | X4: Unlimited Bomb | AB4: Coins
A5: 2 | B5: 0 | E5: =IFERROR(__xludf.DUMMYFUNCTION("LET( names, HSTACK(""Coins"", $N$4:$X$4), amounts, HSTACK(M5, N5:X5), lookupNames, $AB$4:$AB$15, lookupImages, $AC$4:$AC$15, imgs, MAP(names, LAMBDA(n, XLOOKUP(n, lookupNames, lookupImages))), keepImgs, FILTER(imgs, amounts<>0), keepAmounts,"&" FILTER(amounts, amounts<>0), MAKEARRAY( 1, COLUMNS(keepAmounts)*2, LAMBDA(r,c, IF( ISODD(c), INDEX(keepImgs, 1, ROUNDUP(c/2)), INDEX(keepAmounts, 1, c/2) ) ) ) )"),"") | F5: =IFERROR(__xludf.DUMMYFUNCTION("""COMPUTED_VALUE"""),10.0) -> 10 | L5: 1 | M5: 10 | N5: 0 | O5: 0 | P5: 0 | Q5: 0 | R5: 0 | S5: 0 | T5: 0 | U5: 0 | V5: 0 | W5: 0 | X5: 0 | AB5: SPT
A6: 3 | B6: 0 | E6: =IFERROR(__xludf.DUMMYFUNCTION("LET( names, HSTACK(""Coins"", $N$4:$X$4), amounts, HSTACK(M6, N6:X6), lookupNames, $AB$4:$AB$15, lookupImages, $AC$4:$AC$15, imgs, MAP(names, LAMBDA(n, XLOOKUP(n, lookupNames, lookupImages))), keepImgs, FILTER(imgs, amounts<>0), keepAmounts,"&" FILTER(amounts, amounts<>0), MAKEARRAY( 1, COLUMNS(keepAmounts)*2, LAMBDA(r,c, IF( ISODD(c), INDEX(keepImgs, 1, ROUNDUP(c/2)), INDEX(keepAmounts, 1, c/2) ) ) ) )"),"") | F6: =IFERROR(__xludf.DUMMYFUNCTION("""COMPUTED_VALUE"""),15.0) -> 15 | L6: 2 | M6: 0 | N6: 0 | O6: 0 | P6: 0 | Q6: 0 | R6: 0 | S6: 0 | T6: 0 | U6: 15 | V6: 0 | W6: 0 | X6: 0 | AB6: Red
A7: 4 | B7: =mround(average(M8,M18,M28), 1) -> 10 | E7: =IFERROR(__xludf.DUMMYFUNCTION("LET( names, HSTACK(""Coins"", $N$4:$X$4), amounts, HSTACK(M7, N7:X7), lookupNames, $AB$4:$AB$15, lookupImages, $AC$4:$AC$15, imgs, MAP(names, LAMBDA(n, XLOOKUP(n, lookupNames, lookupImages))), keepImgs, FILTER(imgs, amounts<>0), keepAmounts,"&" FILTER(amounts, amounts<>0), MAKEARRAY( 1, COLUMNS(keepAmounts)*2, LAMBDA(r,c, IF( ISODD(c), INDEX(keepImgs, 1, ROUNDUP(c/2)), INDEX(keepAmounts, 1, c/2) ) ) ) )"),"") | F7: =IFERROR(__xludf.DUMMYFUNCTION("""COMPUTED_VALUE"""),1.0) -> 1 | L7: 3 | M7: 0 | N7: 0 | O7: 0 | P7: 0 | Q7: 0 | R7: 1 | S7: 0 | T7: 0 | U7: 0 | V7: 0 | W7: 0 | X7: 0 | AB7: Chuck
A8: 5 | B8: 0 | E8: =IFERROR(__xludf.DUMMYFUNCTION("LET( names, HSTACK(""Coins"", $N$4:$X$4), amounts, HSTACK(M8, N8:X8), lookupNames, $AB$4:$AB$15, lookupImages, $AC$4:$AC$15, imgs, MAP(names, LAMBDA(n, XLOOKUP(n, lookupNames, lookupImages))), keepImgs, FILTER(imgs, amounts<>0), keepAmounts,"&" FILTER(amounts, amounts<>0), MAKEARRAY( 1, COLUMNS(keepAmounts)*2, LAMBDA(r,c, IF( ISODD(c), INDEX(keepImgs, 1, ROUNDUP(c/2)), INDEX(keepAmounts, 1, c/2) ) ) ) )"),"") | F8: =IFERROR(__xludf.DUMMYFUNCTION("""COMPUTED_VALUE"""),10.0) -> 10 | L8: 4 | M8: 10 | N8: 0 | O8: 0 | P8: 0 | Q8: 0 | R8: 0 | S8: 0 | T8: 0 | U8: 0 | V8: 0 | W8: 0 | X8: 0 | AB8: Bomb
A9: 6 | B9: =mround(AVERAGE(M10, M20, M30, M50),1) -> 10 | E9: =IFERROR(__xludf.DUMMYFUNCTION("LET( names, HSTACK(""Coins"", $N$4:$X$4), amounts, HSTACK(M9, N9:X9), lookupNames, $AB$4:$AB$15, lookupImages, $AC$4:$AC$15, imgs, MAP(names, LAMBDA(n, XLOOKUP(n, lookupNames, lookupImages))), keepImgs, FILTER(imgs, amounts<>0), keepAmounts,"&" FILTER(amounts, amounts<>0), MAKEARRAY( 1, COLUMNS(keepAmounts)*2, LAMBDA(r,c, IF( ISODD(c), INDEX(keepImgs, 1, ROUNDUP(c/2)), INDEX(keepAmounts, 1, c/2) ) ) ) )"),"") | F9: =IFERROR(__xludf.DUMMYFUNCTION("""COMPUTED_VALUE"""),1.0) -> 1 | L9: 5 | M9: 0 | N9: 0 | O9: 0 | P9: 0 | Q9: 0 | R9: 0 | S9: 1 | T9: 0 | U9: 0 | V9: 0 | W9: 0 | X9: 0 | AB9: Slingshot
A10: 7 | B10: 100 | E10: =IFERROR(__xludf.DUMMYFUNCTION("LET( names, HSTACK(""Coins"", $N$4:$X$4), amounts, HSTACK(M10, N10:X10), lookupNames, $AB$4:$AB$15, lookupImages, $AC$4:$AC$15, imgs, MAP(names, LAMBDA(n, XLOOKUP(n, lookupNames, lookupImages))), keepImgs, FILTER(imgs, amounts<>0), keepAmoun"&"ts, FILTER(amounts, amounts<>0), MAKEARRAY( 1, COLUMNS(keepAmounts)*2, LAMBDA(r,c, IF( ISODD(c), INDEX(keepImgs, 1, ROUNDUP(c/2)), INDEX(keepAmounts, 1, c/2) ) ) ) )"),"") | F10: =IFERROR(__xludf.DUMMYFUNCTION("""COMPUTED_VALUE"""),10.0) -> 10 | L10: 6 | M10: 10 | N10: 0 | O10: 0 | P10: 0 | Q10: 0 | R10: 0 | S10: 0 | T10: 0 | U10: 0 | V10: 0 | W10: 0 | X10: 0 | AB10: Shuffle
E11: =IFERROR(__xludf.DUMMYFUNCTION("LET( names, HSTACK(""Coins"", $N$4:$X$4), amounts, HSTACK(M11, N11:X11), lookupNames, $AB$4:$AB$15, lookupImages, $AC$4:$AC$15, imgs, MAP(names, LAMBDA(n, XLOOKUP(n, lookupNames, lookupImages))), keepImgs, FILTER(imgs, amounts<>0), keepAmoun"&"ts, FILTER(amounts, amounts<>0), MAKEARRAY( 1, COLUMNS(keepAmounts)*2, LAMBDA(r,c, IF( ISODD(c), INDEX(keepImgs, 1, ROUNDUP(c/2)), INDEX(keepAmounts, 1, c/2) ) ) ) )"),"") | F11: =IFERROR(__xludf.DUMMYFUNCTION("""COMPUTED_VALUE"""),100.0) -> 100 | G11: =IFERROR(__xludf.DUMMYFUNCTION("""COMPUTED_VALUE"""),"") | H11: =IFERROR(__xludf.DUMMYFUNCTION("""COMPUTED_VALUE"""),120.0) -> 120 | I11: =IFERROR(__xludf.DUMMYFUNCTION("""COMPUTED_VALUE"""),"") | J11: =IFERROR(__xludf.DUMMYFUNCTION("""COMPUTED_VALUE"""),60.0) -> 60 | L11: 7 | M11: 100 | N11: 0 | O11: 0 | P11: 0 | Q11: 0 | R11: 0 | S11: 0 | T11: 0 | U11: 120 | V11: 60 | W11: 0 | X11: 0 | AB11: Comet
A12: Total per cycle | B12: =SUM(B4:B10) -> 130 | AB12: Unlimited Lives
A13: Avg HC/day (7d) | B13: =B12/7 -> 18.571429 | L13: Variant 2 | AB13: Unlimited Red
L14: Day | M14: Coin | N14: SPT | O14: Red | P14: Chuck | Q14: Bomb | R14: Slingshot | S14: Shuffle | T14: Comet | U14: Unlimited Lives | V14: Unlimited Red | W14: Unlimited Chuck | X14: Unlimited Bomb | AB14: Unlimited Chuck
E15: =IFERROR(__xludf.DUMMYFUNCTION("LET( names, HSTACK(""Coins"", $N$4:$X$4), amounts, HSTACK(M15, N15:X15), lookupNames, $AB$4:$AB$15, lookupImages, $AC$4:$AC$15, imgs, MAP(names, LAMBDA(n, XLOOKUP(n, lookupNames, lookupImages))), keepImgs, FILTER(imgs, amounts<>0), keepAmoun"&"ts, FILTER(amounts, amounts<>0), MAKEARRAY( 1, COLUMNS(keepAmounts)*2, LAMBDA(r,c, IF( ISODD(c), INDEX(keepImgs, 1, ROUNDUP(c/2)), INDEX(keepAmounts, 1, c/2) ) ) ) )"),"") | F15: =IFERROR(__xludf.DUMMYFUNCTION("""COMPUTED_VALUE"""),20.0) -> 20 | L15: 1 | M15: 0 | N15: 0 | O15: 0 | P15: 0 | Q15: 0 | R15: 0 | S15: 0 | T15: 0 | U15: 20 | V15: 0 | W15: 0 | X15: 0 | AB15: Unlimited Bomb
E16: =IFERROR(__xludf.DUMMYFUNCTION("LET( names, HSTACK(""Coins"", $N$4:$X$4), amounts, HSTACK(M16, N16:X16), lookupNames, $AB$4:$AB$15, lookupImages, $AC$4:$AC$15, imgs, MAP(names, LAMBDA(n, XLOOKUP(n, lookupNames, lookupImages))), keepImgs, FILTER(imgs, amounts<>0), keepAmoun"&"ts, FILTER(amounts, amounts<>0), MAKEARRAY( 1, COLUMNS(keepAmounts)*2, LAMBDA(r,c, IF( ISODD(c), INDEX(keepImgs, 1, ROUNDUP(c/2)), INDEX(keepAmounts, 1, c/2) ) ) ) )"),"") | F16: =IFERROR(__xludf.DUMMYFUNCTION("""COMPUTED_VALUE"""),10.0) -> 10 | L16: 2 | M16: 10 | N16: 0 | O16: 0 | P16: 0 | Q16: 0 | R16: 0 | S16: 0 | T16: 0 | U16: 0 | V16: 0 | W16: 0 | X16: 0
E17: =IFERROR(__xludf.DUMMYFUNCTION("LET( names, HSTACK(""Coins"", $N$4:$X$4), amounts, HSTACK(M17, N17:X17), lookupNames, $AB$4:$AB$15, lookupImages, $AC$4:$AC$15, imgs, MAP(names, LAMBDA(n, XLOOKUP(n, lookupNames, lookupImages))), keepImgs, FILTER(imgs, amounts<>0), keepAmoun"&"ts, FILTER(amounts, amounts<>0), MAKEARRAY( 1, COLUMNS(keepAmounts)*2, LAMBDA(r,c, IF( ISODD(c), INDEX(keepImgs, 1, ROUNDUP(c/2)), INDEX(keepAmounts, 1, c/2) ) ) ) )"),"") | F17: =IFERROR(__xludf.DUMMYFUNCTION("""COMPUTED_VALUE"""),1.0) -> 1 | L17: 3 | M17: 0 | N17: 0 | O17: 0 | P17: 0 | Q17: 0 | R17: 1 | S17: 0 | T17: 0 | U17: 0 | V17: 0 | W17: 0 | X17: 0
E18: =IFERROR(__xludf.DUMMYFUNCTION("LET( names, HSTACK(""Coins"", $N$4:$X$4), amounts, HSTACK(M18, N18:X18), lookupNames, $AB$4:$AB$15, lookupImages, $AC$4:$AC$15, imgs, MAP(names, LAMBDA(n, XLOOKUP(n, lookupNames, lookupImages))), keepImgs, FILTER(imgs, amounts<>0), keepAmoun"&"ts, FILTER(amounts, amounts<>0), MAKEARRAY( 1, COLUMNS(keepAmounts)*2, LAMBDA(r,c, IF( ISODD(c), INDEX(keepImgs, 1, ROUNDUP(c/2)), INDEX(keepAmounts, 1, c/2) ) ) ) )"),"") | F18: =IFERROR(__xludf.DUMMYFUNCTION("""COMPUTED_VALUE"""),10.0) -> 10 | L18: 4 | M18: 10 | N18: 0 | O18: 0 | P18: 0 | Q18: 0 | R18: 0 | S18: 0 | T18: 0 | U18: 0 | V18: 0 | W18: 0 | X18: 0
E19: =IFERROR(__xludf.DUMMYFUNCTION("LET( names, HSTACK(""Coins"", $N$4:$X$4), amounts, HSTACK(M19, N19:X19), lookupNames, $AB$4:$AB$15, lookupImages, $AC$4:$AC$15, imgs, MAP(names, LAMBDA(n, XLOOKUP(n, lookupNames, lookupImages))), keepImgs, FILTER(imgs, amounts<>0), keepAmoun"&"ts, FILTER(amounts, amounts<>0), MAKEARRAY( 1, COLUMNS(keepAmounts)*2, LAMBDA(r,c, IF( ISODD(c), INDEX(keepImgs, 1, ROUNDUP(c/2)), INDEX(keepAmounts, 1, c/2) ) ) ) )"),"") | F19: =IFERROR(__xludf.DUMMYFUNCTION("""COMPUTED_VALUE"""),1.0) -> 1 | L19: 5 | M19: 0 | N19: 0 | O19: 0 | P19: 0 | Q19: 0 | R19: 0 | S19: 1 | T19: 0 | U19: 0 | V19: 0 | W19: 0 | X19: 0
E20: =IFERROR(__xludf.DUMMYFUNCTION("LET( names, HSTACK(""Coins"", $N$4:$X$4), amounts, HSTACK(M20, N20:X20), lookupNames, $AB$4:$AB$15, lookupImages, $AC$4:$AC$15, imgs, MAP(names, LAMBDA(n, XLOOKUP(n, lookupNames, lookupImages))), keepImgs, FILTER(imgs, amounts<>0), keepAmoun"&"ts, FILTER(amounts, amounts<>0), MAKEARRAY( 1, COLUMNS(keepAmounts)*2, LAMBDA(r,c, IF( ISODD(c), INDEX(keepImgs, 1, ROUNDUP(c/2)), INDEX(keepAmounts, 1, c/2) ) ) ) )"),"") | F20: =IFERROR(__xludf.DUMMYFUNCTION("""COMPUTED_VALUE"""),10.0) -> 10 | L20: 6 | M20: 10 | N20: 0 | O20: 0 | P20: 0 | Q20: 0 | R20: 0 | S20: 0 | T20: 0 | U20: 0 | V20: 0 | W20: 0 | X20: 0
E21: =IFERROR(__xludf.DUMMYFUNCTION("LET( names, HSTACK(""Coins"", $N$4:$X$4), amounts, HSTACK(M21, N21:X21), lookupNames, $AB$4:$AB$15, lookupImages, $AC$4:$AC$15, imgs, MAP(names, LAMBDA(n, XLOOKUP(n, lookupNames, lookupImages))), keepImgs, FILTER(imgs, amounts<>0), keepAmoun"&"ts, FILTER(amounts, amounts<>0), MAKEARRAY( 1, COLUMNS(keepAmounts)*2, LAMBDA(r,c, IF( ISODD(c), INDEX(keepImgs, 1, ROUNDUP(c/2)), INDEX(keepAmounts, 1, c/2) ) ) ) )"),"") | F21: =IFERROR(__xludf.DUMMYFUNCTION("""COMPUTED_VALUE"""),100.0) -> 100 | G21: =IFERROR(__xludf.DUMMYFUNCTION("""COMPUTED_VALUE"""),"") | H21: =IFERROR(__xludf.DUMMYFUNCTION("""COMPUTED_VALUE"""),120.0) -> 120 | I21: =IFERROR(__xludf.DUMMYFUNCTION("""COMPUTED_VALUE"""),"") | J21: =IFERROR(__xludf.DUMMYFUNCTION("""COMPUTED_VALUE"""),60.0) -> 60 | L21: 7 | M21: 100 | N21: 0 | O21: 0 | P21: 0 | Q21: 0 | R21: 0 | S21: 0 | T21: 0 | U21: 120 | V21: 0 | W21: 60 | X21: 0
L23: Variant 3
L24: Day | M24: Coin | N24: SPT | O24: Red | P24: Chuck | Q24: Bomb | R24: Slingshot | S24: Shuffle | T24: Comet | U24: Unlimited Lives | V24: Unlimited Red | W24: Unlimited Chuck | X24: Unlimited Bomb
E25: =IFERROR(__xludf.DUMMYFUNCTION("LET( names, HSTACK(""Coins"", $N$4:$X$4), amounts, HSTACK(M25, N25:X25), lookupNames, $AB$4:$AB$15, lookupImages, $AC$4:$AC$15, imgs, MAP(names, LAMBDA(n, XLOOKUP(n, lookupNames, lookupImages))), keepImgs, FILTER(imgs, amounts<>0), keepAmoun"&"ts, FILTER(amounts, amounts<>0), MAKEARRAY( 1, COLUMNS(keepAmounts)*2, LAMBDA(r,c, IF( ISODD(c), INDEX(keepImgs, 1, ROUNDUP(c/2)), INDEX(keepAmounts, 1, c/2) ) ) ) )"),"") | F25: =IFERROR(__xludf.DUMMYFUNCTION("""COMPUTED_VALUE"""),15.0) -> 15 | L25: 1 | M25: 0 | N25: 0 | O25: 0 | P25: 0 | Q25: 0 | R25: 0 | S25: 0 | T25: 0 | U25: 15 | V25: 0 | W25: 0 | X25: 0
E26: =IFERROR(__xludf.DUMMYFUNCTION("LET( names, HSTACK(""Coins"", $N$4:$X$4), amounts, HSTACK(M26, N26:X26), lookupNames, $AB$4:$AB$15, lookupImages, $AC$4:$AC$15, imgs, MAP(names, LAMBDA(n, XLOOKUP(n, lookupNames, lookupImages))), keepImgs, FILTER(imgs, amounts<>0), keepAmoun"&"ts, FILTER(amounts, amounts<>0), MAKEARRAY( 1, COLUMNS(keepAmounts)*2, LAMBDA(r,c, IF( ISODD(c), INDEX(keepImgs, 1, ROUNDUP(c/2)), INDEX(keepAmounts, 1, c/2) ) ) ) )"),"") | F26: =IFERROR(__xludf.DUMMYFUNCTION("""COMPUTED_VALUE"""),10.0) -> 10 | L26: 2 | M26: 10 | N26: 0 | O26: 0 | P26: 0 | Q26: 0 | R26: 0 | S26: 0 | T26: 0 | U26: 0 | V26: 0 | W26: 0 | X26: 0
E27: =IFERROR(__xludf.DUMMYFUNCTION("LET( names, HSTACK(""Coins"", $N$4:$X$4), amounts, HSTACK(M27, N27:X27), lookupNames, $AB$4:$AB$15, lookupImages, $AC$4:$AC$15, imgs, MAP(names, LAMBDA(n, XLOOKUP(n, lookupNames, lookupImages))), keepImgs, FILTER(imgs, amounts<>0), keepAmoun"&"ts, FILTER(amounts, amounts<>0), MAKEARRAY( 1, COLUMNS(keepAmounts)*2, LAMBDA(r,c, IF( ISODD(c), INDEX(keepImgs, 1, ROUNDUP(c/2)), INDEX(keepAmounts, 1, c/2) ) ) ) )"),"") | F27: =IFERROR(__xludf.DUMMYFUNCTION("""COMPUTED_VALUE"""),1.0) -> 1 | L27: 3 | M27: 0 | N27: 0 | O27: 0 | P27: 0 | Q27: 0 | R27: 1 | S27: 0 | T27: 0 | U27: 0 | V27: 0 | W27: 0 | X27: 0
E28: =IFERROR(__xludf.DUMMYFUNCTION("LET( names, HSTACK(""Coins"", $N$4:$X$4), amounts, HSTACK(M28, N28:X28), lookupNames, $AB$4:$AB$15, lookupImages, $AC$4:$AC$15, imgs, MAP(names, LAMBDA(n, XLOOKUP(n, lookupNames, lookupImages))), keepImgs, FILTER(imgs, amounts<>0), keepAmoun"&"ts, FILTER(amounts, amounts<>0), MAKEARRAY( 1, COLUMNS(keepAmounts)*2, LAMBDA(r,c, IF( ISODD(c), INDEX(keepImgs, 1, ROUNDUP(c/2)), INDEX(keepAmounts, 1, c/2) ) ) ) )"),"") | F28: =IFERROR(__xludf.DUMMYFUNCTION("""COMPUTED_VALUE"""),10.0) -> 10 | L28: 4 | M28: 10 | N28: 0 | O28: 0 | P28: 0 | Q28: 0 | R28: 0 | S28: 0 | T28: 0 | U28: 0 | V28: 0 | W28: 0 | X28: 0
E29: =IFERROR(__xludf.DUMMYFUNCTION("LET( names, HSTACK(""Coins"", $N$4:$X$4), amounts, HSTACK(M29, N29:X29), lookupNames, $AB$4:$AB$15, lookupImages, $AC$4:$AC$15, imgs, MAP(names, LAMBDA(n, XLOOKUP(n, lookupNames, lookupImages))), keepImgs, FILTER(imgs, amounts<>0), keepAmoun"&"ts, FILTER(amounts, amounts<>0), MAKEARRAY( 1, COLUMNS(keepAmounts)*2, LAMBDA(r,c, IF( ISODD(c), INDEX(keepImgs, 1, ROUNDUP(c/2)), INDEX(keepAmounts, 1, c/2) ) ) ) )"),"") | F29: =IFERROR(__xludf.DUMMYFUNCTION("""COMPUTED_VALUE"""),1.0) -> 1 | L29: 5 | M29: 0 | N29: 0 | O29: 0 | P29: 0 | Q29: 0 | R29: 0 | S29: 1 | T29: 0 | U29: 0 | V29: 0 | W29: 0 | X29: 0
E30: =IFERROR(__xludf.DUMMYFUNCTION("LET( names, HSTACK(""Coins"", $N$4:$X$4), amounts, HSTACK(M30, N30:X30), lookupNames, $AB$4:$AB$15, lookupImages, $AC$4:$AC$15, imgs, MAP(names, LAMBDA(n, XLOOKUP(n, lookupNames, lookupImages))), keepImgs, FILTER(imgs, amounts<>0), keepAmoun"&"ts, FILTER(amounts, amounts<>0), MAKEARRAY( 1, COLUMNS(keepAmounts)*2, LAMBDA(r,c, IF( ISODD(c), INDEX(keepImgs, 1, ROUNDUP(c/2)), INDEX(keepAmounts, 1, c/2) ) ) ) )"),"") | F30: =IFERROR(__xludf.DUMMYFUNCTION("""COMPUTED_VALUE"""),10.0) -> 10 | L30: 6 | M30: 10 | N30: 0 | O30: 0 | P30: 0 | Q30: 0 | R30: 0 | S30: 0 | T30: 0 | U30: 0 | V30: 0 | W30: 0 | X30: 0
E31: =IFERROR(__xludf.DUMMYFUNCTION("LET( names, HSTACK(""Coins"", $N$4:$X$4), amounts, HSTACK(M31, N31:X31), lookupNames, $AB$4:$AB$15, lookupImages, $AC$4:$AC$15, imgs, MAP(names, LAMBDA(n, XLOOKUP(n, lookupNames, lookupImages))), keepImgs, FILTER(imgs, amounts<>0), keepAmoun"&"ts, FILTER(amounts, amounts<>0), MAKEARRAY( 1, COLUMNS(keepAmounts)*2, LAMBDA(r,c, IF( ISODD(c), INDEX(keepImgs, 1, ROUNDUP(c/2)), INDEX(keepAmounts, 1, c/2) ) ) ) )"),"") | F31: =IFERROR(__xludf.DUMMYFUNCTION("""COMPUTED_VALUE"""),100.0) -> 100 | G31: =IFERROR(__xludf.DUMMYFUNCTION("""COMPUTED_VALUE"""),"") | H31: =IFERROR(__xludf.DUMMYFUNCTION("""COMPUTED_VALUE"""),120.0) -> 120 | I31: =IFERROR(__xludf.DUMMYFUNCTION("""COMPUTED_VALUE"""),"") | J31: =IFERROR(__xludf.DUMMYFUNCTION("""COMPUTED_VALUE"""),30.0) -> 30 | L31: 7 | M31: 100 | N31: 0 | O31: 0 | P31: 0 | Q31: 0 | R31: 0 | S31: 0 | T31: 0 | U31: 120 | V31: 0 | W31: 0 | X31: 30
L33: Variant 4
L34: Day | M34: Coin | N34: SPT | O34: Red | P34: Chuck | Q34: Bomb | R34: Slingshot | S34: Shuffle | T34: Comet | U34: Unlimited Lives | V34: Unlimited Red | W34: Unlimited Chuck | X34: Unlimited Bomb
E35: =IFERROR(__xludf.DUMMYFUNCTION("LET( names, HSTACK(""Coins"", $N$4:$X$4), amounts, HSTACK(M35, N35:X35), lookupNames, $AB$4:$AB$15, lookupImages, $AC$4:$AC$15, imgs, MAP(names, LAMBDA(n, XLOOKUP(n, lookupNames, lookupImages))), keepImgs, FILTER(imgs, amounts<>0), keepAmoun"&"ts, FILTER(amounts, amounts<>0), MAKEARRAY( 1, COLUMNS(keepAmounts)*2, LAMBDA(r,c, IF( ISODD(c), INDEX(keepImgs, 1, ROUNDUP(c/2)), INDEX(keepAmounts, 1, c/2) ) ) ) )"),"") | F35: =IFERROR(__xludf.DUMMYFUNCTION("""COMPUTED_VALUE"""),10.0) -> 10 | L35: 1 | M35: 10 | N35: 0 | O35: 0 | P35: 0 | Q35: 0 | R35: 0 | S35: 0 | T35: 0 | U35: 0 | V35: 0 | W35: 0 | X35: 0
E36: =IFERROR(__xludf.DUMMYFUNCTION("LET( names, HSTACK(""Coins"", $N$4:$X$4), amounts, HSTACK(M36, N36:X36), lookupNames, $AB$4:$AB$15, lookupImages, $AC$4:$AC$15, imgs, MAP(names, LAMBDA(n, XLOOKUP(n, lookupNames, lookupImages))), keepImgs, FILTER(imgs, amounts<>0), keepAmoun"&"ts, FILTER(amounts, amounts<>0), MAKEARRAY( 1, COLUMNS(keepAmounts)*2, LAMBDA(r,c, IF( ISODD(c), INDEX(keepImgs, 1, ROUNDUP(c/2)), INDEX(keepAmounts, 1, c/2) ) ) ) )"),"") | F36: =IFERROR(__xludf.DUMMYFUNCTION("""COMPUTED_VALUE"""),30.0) -> 30 | L36: 2 | M36: 0 | N36: 0 | O36: 0 | P36: 0 | Q36: 0 | R36: 0 | S36: 0 | T36: 0 | U36: 30 | V36: 0 | W36: 0 | X36: 0
E37: =IFERROR(__xludf.DUMMYFUNCTION("LET( names, HSTACK(""Coins"", $N$4:$X$4), amounts, HSTACK(M37, N37:X37), lookupNames, $AB$4:$AB$15, lookupImages, $AC$4:$AC$15, imgs, MAP(names, LAMBDA(n, XLOOKUP(n, lookupNames, lookupImages))), keepImgs, FILTER(imgs, amounts<>0), keepAmoun"&"ts, FILTER(amounts, amounts<>0), MAKEARRAY( 1, COLUMNS(keepAmounts)*2, LAMBDA(r,c, IF( ISODD(c), INDEX(keepImgs, 1, ROUNDUP(c/2)), INDEX(keepAmounts, 1, c/2) ) ) ) )"),"") | F37: =IFERROR(__xludf.DUMMYFUNCTION("""COMPUTED_VALUE"""),1.0) -> 1 | L37: 3 | M37: 0 | N37: 0 | O37: 0 | P37: 0 | Q37: 0 | R37: 0 | S37: 1 | T37: 0 | U37: 0 | V37: 0 | W37: 0 | X37: 0
E38: =IFERROR(__xludf.DUMMYFUNCTION("LET( names, HSTACK(""Coins"", $N$4:$X$4), amounts, HSTACK(M38, N38:X38), lookupNames, $AB$4:$AB$15, lookupImages, $AC$4:$AC$15, imgs, MAP(names, LAMBDA(n, XLOOKUP(n, lookupNames, lookupImages))), keepImgs, FILTER(imgs, amounts<>0), keepAmoun"&"ts, FILTER(amounts, amounts<>0), MAKEARRAY( 1, COLUMNS(keepAmounts)*2, LAMBDA(r,c, IF( ISODD(c), INDEX(keepImgs, 1, ROUNDUP(c/2)), INDEX(keepAmounts, 1, c/2) ) ) ) )"),"") | F38: =IFERROR(__xludf.DUMMYFUNCTION("""COMPUTED_VALUE"""),1.0) -> 1 | L38: 4 | M38: 0 | N38: 0 | O38: 0 | P38: 0 | Q38: 0 | R38: 1 | S38: 0 | T38: 0 | U38: 0 | V38: 0 | W38: 0 | X38: 0
E39: =IFERROR(__xludf.DUMMYFUNCTION("LET( names, HSTACK(""Coins"", $N$4:$X$4), amounts, HSTACK(M39, N39:X39), lookupNames, $AB$4:$AB$15, lookupImages, $AC$4:$AC$15, imgs, MAP(names, LAMBDA(n, XLOOKUP(n, lookupNames, lookupImages))), keepImgs, FILTER(imgs, amounts<>0), keepAmoun"&"ts, FILTER(amounts, amounts<>0), MAKEARRAY( 1, COLUMNS(keepAmounts)*2, LAMBDA(r,c, IF( ISODD(c), INDEX(keepImgs, 1, ROUNDUP(c/2)), INDEX(keepAmounts, 1, c/2) ) ) ) )"),"") | F39: =IFERROR(__xludf.DUMMYFUNCTION("""COMPUTED_VALUE"""),10.0) -> 10 | L39: 5 | M39: 10 | N39: 0 | O39: 0 | P39: 0 | Q39: 0 | R39: 0 | S39: 0 | T39: 0 | U39: 0 | V39: 0 | W39: 0 | X39: 0
E40: =IFERROR(__xludf.DUMMYFUNCTION("LET( names, HSTACK(""Coins"", $N$4:$X$4), amounts, HSTACK(M40, N40:X40), lookupNames, $AB$4:$AB$15, lookupImages, $AC$4:$AC$15, imgs, MAP(names, LAMBDA(n, XLOOKUP(n, lookupNames, lookupImages))), keepImgs, FILTER(imgs, amounts<>0), keepAmoun"&"ts, FILTER(amounts, amounts<>0), MAKEARRAY( 1, COLUMNS(keepAmounts)*2, LAMBDA(r,c, IF( ISODD(c), INDEX(keepImgs, 1, ROUNDUP(c/2)), INDEX(keepAmounts, 1, c/2) ) ) ) )"),"") | F40: =IFERROR(__xludf.DUMMYFUNCTION("""COMPUTED_VALUE"""),1.0) -> 1 | L40: 6 | M40: 0 | N40: 0 | O40: 0 | P40: 0 | Q40: 0 | R40: 1 | S40: 0 | T40: 0 | U40: 0 | V40: 0 | W40: 0 | X40: 0
E41: =IFERROR(__xludf.DUMMYFUNCTION("LET( names, HSTACK(""Coins"", $N$4:$X$4), amounts, HSTACK(M41, N41:X41), lookupNames, $AB$4:$AB$15, lookupImages, $AC$4:$AC$15, imgs, MAP(names, LAMBDA(n, XLOOKUP(n, lookupNames, lookupImages))), keepImgs, FILTER(imgs, amounts<>0), keepAmoun"&"ts, FILTER(amounts, amounts<>0), MAKEARRAY( 1, COLUMNS(keepAmounts)*2, LAMBDA(r,c, IF( ISODD(c), INDEX(keepImgs, 1, ROUNDUP(c/2)), INDEX(keepAmounts, 1, c/2) ) ) ) )"),"") | F41: =IFERROR(__xludf.DUMMYFUNCTION("""COMPUTED_VALUE"""),100.0) -> 100 | G41: =IFERROR(__xludf.DUMMYFUNCTION("""COMPUTED_VALUE"""),"") | H41: =IFERROR(__xludf.DUMMYFUNCTION("""COMPUTED_VALUE"""),1.0) -> 1 | I41: =IFERROR(__xludf.DUMMYFUNCTION("""COMPUTED_VALUE"""),"") | J41: =IFERROR(__xludf.DUMMYFUNCTION("""COMPUTED_VALUE"""),120.0) -> 120 | L41: 7 | M41: 100 | N41: 0 | O41: 0 | P41: 0 | Q41: 0 | R41: 0 | S41: 0 | T41: 1 | U41: 120 | V41: 0 | W41: 0 | X41: 0
L43: Variant 5
...

Sheet c_day_v2
A1: Daily Rewards - NEW
L2: all segs
A3: Day | B3: HC Reward | E3: 👁 | L3: Variant 1 | AB3: cur | AC3: image
A4: 1 | B4: =average(M5,M16,M26,M35,M45) -> 10 | L4: Day | M4: Coin | N4: SPT | O4: Red | P4: Chuck | Q4: Bomb | R4: Slingshot | S4: Shuffle | T4: Comet | U4: Unlimited Lives | V4: Unlimited Red | W4: Unlimited Chuck | X4: Unlimited Bomb | Y4: 1 | AB4: Coins
A5: 2 | B5: 0 | E5: =IFERROR(__xludf.DUMMYFUNCTION("LET( names, HSTACK(""Coins"", $N$4:$X$4), amounts, HSTACK(M5, N5:X5), lookupNames, $AB$4:$AB$15, lookupImages, $AC$4:$AC$15, imgs, MAP(names, LAMBDA(n, XLOOKUP(n, lookupNames, lookupImages))), keepImgs, FILTER(imgs, amounts<>0), keepAmounts,"&" FILTER(amounts, amounts<>0), MAKEARRAY( 1, COLUMNS(keepAmounts)*2, LAMBDA(r,c, IF( ISODD(c), INDEX(keepImgs, 1, ROUNDUP(c/2)), INDEX(keepAmounts, 1, c/2) ) ) ) )"),"") | F5: =IFERROR(__xludf.DUMMYFUNCTION("""COMPUTED_VALUE"""),10.0) -> 10 | L5: 1 | M5: 10 | N5: 0 | O5: 0 | P5: 0 | Q5: 0 | R5: 0 | S5: 0 | T5: 0 | U5: 0 | V5: 0 | W5: 0 | X5: 0 | AB5: SPT
A6: 3 | B6: 0 | E6: =IFERROR(__xludf.DUMMYFUNCTION("LET( names, HSTACK(""Coins"", $N$4:$X$4), amounts, HSTACK(M6, N6:X6), lookupNames, $AB$4:$AB$15, lookupImages, $AC$4:$AC$15, imgs, MAP(names, LAMBDA(n, XLOOKUP(n, lookupNames, lookupImages))), keepImgs, FILTER(imgs, amounts<>0), keepAmounts,"&" FILTER(amounts, amounts<>0), MAKEARRAY( 1, COLUMNS(keepAmounts)*2, LAMBDA(r,c, IF( ISODD(c), INDEX(keepImgs, 1, ROUNDUP(c/2)), INDEX(keepAmounts, 1, c/2) ) ) ) )"),"") | F6: =IFERROR(__xludf.DUMMYFUNCTION("""COMPUTED_VALUE"""),15.0) -> 15 | L6: 2 | M6: 0 | N6: 0 | O6: 0 | P6: 0 | Q6: 0 | R6: 0 | S6: 0 | T6: 0 | U6: 15 | V6: 0 | W6: 0 | X6: 0 | AB6: Red
A7: 4 | B7: =mround(average(M8,M18,M28), 1) -> 10 | E7: =IFERROR(__xludf.DUMMYFUNCTION("LET( names, HSTACK(""Coins"", $N$4:$X$4), amounts, HSTACK(M7, N7:X7), lookupNames, $AB$4:$AB$15, lookupImages, $AC$4:$AC$15, imgs, MAP(names, LAMBDA(n, XLOOKUP(n, lookupNames, lookupImages))), keepImgs, FILTER(imgs, amounts<>0), keepAmounts,"&" FILTER(amounts, amounts<>0), MAKEARRAY( 1, COLUMNS(keepAmounts)*2, LAMBDA(r,c, IF( ISODD(c), INDEX(keepImgs, 1, ROUNDUP(c/2)), INDEX(keepAmounts, 1, c/2) ) ) ) )"),"") | F7: =IFERROR(__xludf.DUMMYFUNCTION("""COMPUTED_VALUE"""),1.0) -> 1 | L7: 3 | M7: 0 | N7: 0 | O7: 0 | P7: 0 | Q7: 0 | R7: 1 | S7: 0 | T7: 0 | U7: 0 | V7: 0 | W7: 0 | X7: 0 | AB7: Chuck
A8: 5 | B8: 0 | E8: =IFERROR(__xludf.DUMMYFUNCTION("LET( names, HSTACK(""Coins"", $N$4:$X$4), amounts, HSTACK(M8, N8:X8), lookupNames, $AB$4:$AB$15, lookupImages, $AC$4:$AC$15, imgs, MAP(names, LAMBDA(n, XLOOKUP(n, lookupNames, lookupImages))), keepImgs, FILTER(imgs, amounts<>0), keepAmounts,"&" FILTER(amounts, amounts<>0), MAKEARRAY( 1, COLUMNS(keepAmounts)*2, LAMBDA(r,c, IF( ISODD(c), INDEX(keepImgs, 1, ROUNDUP(c/2)), INDEX(keepAmounts, 1, c/2) ) ) ) )"),"") | F8: =IFERROR(__xludf.DUMMYFUNCTION("""COMPUTED_VALUE"""),10.0) -> 10 | L8: 4 | M8: 10 | N8: 0 | O8: 0 | P8: 0 | Q8: 0 | R8: 0 | S8: 0 | T8: 0 | U8: 0 | V8: 0 | W8: 0 | X8: 0 | AB8: Bomb
A9: 6 | B9: =mround(AVERAGE(M10, M20, M30, M50),1) -> 10 | E9: =IFERROR(__xludf.DUMMYFUNCTION("LET( names, HSTACK(""Coins"", $N$4:$X$4), amounts, HSTACK(M9, N9:X9), lookupNames, $AB$4:$AB$15, lookupImages, $AC$4:$AC$15, imgs, MAP(names, LAMBDA(n, XLOOKUP(n, lookupNames, lookupImages))), keepImgs, FILTER(imgs, amounts<>0), keepAmounts,"&" FILTER(amounts, amounts<>0), MAKEARRAY( 1, COLUMNS(keepAmounts)*2, LAMBDA(r,c, IF( ISODD(c), INDEX(keepImgs, 1, ROUNDUP(c/2)), INDEX(keepAmounts, 1, c/2) ) ) ) )"),"") | F9: =IFERROR(__xludf.DUMMYFUNCTION("""COMPUTED_VALUE"""),1.0) -> 1 | L9: 5 | M9: 0 | N9: 0 | O9: 0 | P9: 0 | Q9: 0 | R9: 0 | S9: 1 | T9: 0 | U9: 0 | V9: 0 | W9: 0 | X9: 0 | AB9: Slingshot
A10: 7 | B10: 100 | E10: =IFERROR(__xludf.DUMMYFUNCTION("LET( names, HSTACK(""Coins"", $N$4:$X$4), amounts, HSTACK(M10, N10:X10), lookupNames, $AB$4:$AB$15, lookupImages, $AC$4:$AC$15, imgs, MAP(names, LAMBDA(n, XLOOKUP(n, lookupNames, lookupImages))), keepImgs, FILTER(imgs, amounts<>0), keepAmoun"&"ts, FILTER(amounts, amounts<>0), MAKEARRAY( 1, COLUMNS(keepAmounts)*2, LAMBDA(r,c, IF( ISODD(c), INDEX(keepImgs, 1, ROUNDUP(c/2)), INDEX(keepAmounts, 1, c/2) ) ) ) )"),"") | F10: =IFERROR(__xludf.DUMMYFUNCTION("""COMPUTED_VALUE"""),10.0) -> 10 | L10: 6 | M10: 10 | N10: 0 | O10: 0 | P10: 0 | Q10: 0 | R10: 0 | S10: 0 | T10: 0 | U10: 0 | V10: 0 | W10: 0 | X10: 0 | AB10: Shuffle
E11: =IFERROR(__xludf.DUMMYFUNCTION("LET( names, HSTACK(""Coins"", $N$4:$X$4), amounts, HSTACK(M11, N11:X11), lookupNames, $AB$4:$AB$15, lookupImages, $AC$4:$AC$15, imgs, MAP(names, LAMBDA(n, XLOOKUP(n, lookupNames, lookupImages))), keepImgs, FILTER(imgs, amounts<>0), keepAmoun"&"ts, FILTER(amounts, amounts<>0), MAKEARRAY( 1, COLUMNS(keepAmounts)*2, LAMBDA(r,c, IF( ISODD(c), INDEX(keepImgs, 1, ROUNDUP(c/2)), INDEX(keepAmounts, 1, c/2) ) ) ) )"),"") | F11: =IFERROR(__xludf.DUMMYFUNCTION("""COMPUTED_VALUE"""),100.0) -> 100 | G11: =IFERROR(__xludf.DUMMYFUNCTION("""COMPUTED_VALUE"""),"") | H11: =IFERROR(__xludf.DUMMYFUNCTION("""COMPUTED_VALUE"""),120.0) -> 120 | I11: =IFERROR(__xludf.DUMMYFUNCTION("""COMPUTED_VALUE"""),"") | J11: =IFERROR(__xludf.DUMMYFUNCTION("""COMPUTED_VALUE"""),60.0) -> 60 | L11: 7 | M11: 100 | N11: 0 | O11: 0 | P11: 0 | Q11: 0 | R11: 0 | S11: 0 | T11: 0 | U11: 120 | V11: 60 | W11: 0 | X11: 0 | AB11: Comet
A12: Total per cycle | B12: =SUM(B4:B10) -> 130 | AB12: Unlimited Lives
A13: Avg HC/day (7d) | B13: =B12/7 -> 18.571429 | L13: Variant 2 | AB13: Unlimited Red
L14: Day | M14: Coin | N14: SPT | O14: Red | P14: Chuck | Q14: Bomb | R14: Slingshot | S14: Shuffle | T14: Comet | U14: Unlimited Lives | V14: Unlimited Red | W14: Unlimited Chuck | X14: Unlimited Bomb | AB14: Unlimited Chuck
A15: % of old | B15: =B12/c_day!B12 -> 1 | E15: =IFERROR(__xludf.DUMMYFUNCTION("LET( names, HSTACK(""Coins"", $N$4:$X$4), amounts, HSTACK(M15, N15:X15), lookupNames, $AB$4:$AB$15, lookupImages, $AC$4:$AC$15, imgs, MAP(names, LAMBDA(n, XLOOKUP(n, lookupNames, lookupImages))), keepImgs, FILTER(imgs, amounts<>0), keepAmoun"&"ts, FILTER(amounts, amounts<>0), MAKEARRAY( 1, COLUMNS(keepAmounts)*2, LAMBDA(r,c, IF( ISODD(c), INDEX(keepImgs, 1, ROUNDUP(c/2)), INDEX(keepAmounts, 1, c/2) ) ) ) )"),"") | F15: =IFERROR(__xludf.DUMMYFUNCTION("""COMPUTED_VALUE"""),20.0) -> 20 | L15: 1 | M15: 0 | N15: 0 | O15: 0 | P15: 0 | Q15: 0 | R15: 0 | S15: 0 | T15: 0 | U15: 20 | V15: 0 | W15: 0 | X15: 0 | AB15: Unlimited Bomb
E16: =IFERROR(__xludf.DUMMYFUNCTION("LET( names, HSTACK(""Coins"", $N$4:$X$4), amounts, HSTACK(M16, N16:X16), lookupNames, $AB$4:$AB$15, lookupImages, $AC$4:$AC$15, imgs, MAP(names, LAMBDA(n, XLOOKUP(n, lookupNames, lookupImages))), keepImgs, FILTER(imgs, amounts<>0), keepAmoun"&"ts, FILTER(amounts, amounts<>0), MAKEARRAY( 1, COLUMNS(keepAmounts)*2, LAMBDA(r,c, IF( ISODD(c), INDEX(keepImgs, 1, ROUNDUP(c/2)), INDEX(keepAmounts, 1, c/2) ) ) ) )"),"") | F16: =IFERROR(__xludf.DUMMYFUNCTION("""COMPUTED_VALUE"""),10.0) -> 10 | L16: 2 | M16: 10 | N16: 0 | O16: 0 | P16: 0 | Q16: 0 | R16: 0 | S16: 0 | T16: 0 | U16: 0 | V16: 0 | W16: 0 | X16: 0
E17: =IFERROR(__xludf.DUMMYFUNCTION("LET( names, HSTACK(""Coins"", $N$4:$X$4), amounts, HSTACK(M17, N17:X17), lookupNames, $AB$4:$AB$15, lookupImages, $AC$4:$AC$15, imgs, MAP(names, LAMBDA(n, XLOOKUP(n, lookupNames, lookupImages))), keepImgs, FILTER(imgs, amounts<>0), keepAmoun"&"ts, FILTER(amounts, amounts<>0), MAKEARRAY( 1, COLUMNS(keepAmounts)*2, LAMBDA(r,c, IF( ISODD(c), INDEX(keepImgs, 1, ROUNDUP(c/2)), INDEX(keepAmounts, 1, c/2) ) ) ) )"),"") | F17: =IFERROR(__xludf.DUMMYFUNCTION("""COMPUTED_VALUE"""),1.0) -> 1 | L17: 3 | M17: 0 | N17: 0 | O17: 0 | P17: 0 | Q17: 0 | R17: 1 | S17: 0 | T17: 0 | U17: 0 | V17: 0 | W17: 0 | X17: 0 | Y17: 1
E18: =IFERROR(__xludf.DUMMYFUNCTION("LET( names, HSTACK(""Coins"", $N$4:$X$4), amounts, HSTACK(M18, N18:X18), lookupNames, $AB$4:$AB$15, lookupImages, $AC$4:$AC$15, imgs, MAP(names, LAMBDA(n, XLOOKUP(n, lookupNames, lookupImages))), keepImgs, FILTER(imgs, amounts<>0), keepAmoun"&"ts, FILTER(amounts, amounts<>0), MAKEARRAY( 1, COLUMNS(keepAmounts)*2, LAMBDA(r,c, IF( ISODD(c), INDEX(keepImgs, 1, ROUNDUP(c/2)), INDEX(keepAmounts, 1, c/2) ) ) ) )"),"") | F18: =IFERROR(__xludf.DUMMYFUNCTION("""COMPUTED_VALUE"""),10.0) -> 10 | L18: 4 | M18: 10 | N18: 0 | O18: 0 | P18: 0 | Q18: 0 | R18: 0 | S18: 0 | T18: 0 | U18: 0 | V18: 0 | W18: 0 | X18: 0
E19: =IFERROR(__xludf.DUMMYFUNCTION("LET( names, HSTACK(""Coins"", $N$4:$X$4), amounts, HSTACK(M19, N19:X19), lookupNames, $AB$4:$AB$15, lookupImages, $AC$4:$AC$15, imgs, MAP(names, LAMBDA(n, XLOOKUP(n, lookupNames, lookupImages))), keepImgs, FILTER(imgs, amounts<>0), keepAmoun"&"ts, FILTER(amounts, amounts<>0), MAKEARRAY( 1, COLUMNS(keepAmounts)*2, LAMBDA(r,c, IF( ISODD(c), INDEX(keepImgs, 1, ROUNDUP(c/2)), INDEX(keepAmounts, 1, c/2) ) ) ) )"),"") | F19: =IFERROR(__xludf.DUMMYFUNCTION("""COMPUTED_VALUE"""),1.0) -> 1 | L19: 5 | M19: 0 | N19: 0 | O19: 0 | P19: 0 | Q19: 0 | R19: 0 | S19: 1 | T19: 0 | U19: 0 | V19: 0 | W19: 0 | X19: 0
E20: =IFERROR(__xludf.DUMMYFUNCTION("LET( names, HSTACK(""Coins"", $N$4:$X$4), amounts, HSTACK(M20, N20:X20), lookupNames, $AB$4:$AB$15, lookupImages, $AC$4:$AC$15, imgs, MAP(names, LAMBDA(n, XLOOKUP(n, lookupNames, lookupImages))), keepImgs, FILTER(imgs, amounts<>0), keepAmoun"&"ts, FILTER(amounts, amounts<>0), MAKEARRAY( 1, COLUMNS(keepAmounts)*2, LAMBDA(r,c, IF( ISODD(c), INDEX(keepImgs, 1, ROUNDUP(c/2)), INDEX(keepAmounts, 1, c/2) ) ) ) )"),"") | F20: =IFERROR(__xludf.DUMMYFUNCTION("""COMPUTED_VALUE"""),10.0) -> 10 | L20: 6 | M20: 10 | N20: 0 | O20: 0 | P20: 0 | Q20: 0 | R20: 0 | S20: 0 | T20: 0 | U20: 0 | V20: 0 | W20: 0 | X20: 0
E21: =IFERROR(__xludf.DUMMYFUNCTION("LET( names, HSTACK(""Coins"", $N$4:$X$4), amounts, HSTACK(M21, N21:X21), lookupNames, $AB$4:$AB$15, lookupImages, $AC$4:$AC$15, imgs, MAP(names, LAMBDA(n, XLOOKUP(n, lookupNames, lookupImages))), keepImgs, FILTER(imgs, amounts<>0), keepAmoun"&"ts, FILTER(amounts, amounts<>0), MAKEARRAY( 1, COLUMNS(keepAmounts)*2, LAMBDA(r,c, IF( ISODD(c), INDEX(keepImgs, 1, ROUNDUP(c/2)), INDEX(keepAmounts, 1, c/2) ) ) ) )"),"") | F21: =IFERROR(__xludf.DUMMYFUNCTION("""COMPUTED_VALUE"""),100.0) -> 100 | G21: =IFERROR(__xludf.DUMMYFUNCTION("""COMPUTED_VALUE"""),"") | H21: =IFERROR(__xludf.DUMMYFUNCTION("""COMPUTED_VALUE"""),120.0) -> 120 | I21: =IFERROR(__xludf.DUMMYFUNCTION("""COMPUTED_VALUE"""),"") | J21: =IFERROR(__xludf.DUMMYFUNCTION("""COMPUTED_VALUE"""),60.0) -> 60 | L21: 7 | M21: 100 | N21: 0 | O21: 0 | P21: 0 | Q21: 0 | R21: 0 | S21: 0 | T21: 0 | U21: 120 | V21: 0 | W21: 60 | X21: 0
L23: Variant 3
L24: Day | M24: Coin | N24: SPT | O24: Red | P24: Chuck | Q24: Bomb | R24: Slingshot | S24: Shuffle | T24: Comet | U24: Unlimited Lives | V24: Unlimited Red | W24: Unlimited Chuck | X24: Unlimited Bomb
E25: =IFERROR(__xludf.DUMMYFUNCTION("LET( names, HSTACK(""Coins"", $N$4:$X$4), amounts, HSTACK(M25, N25:X25), lookupNames, $AB$4:$AB$15, lookupImages, $AC$4:$AC$15, imgs, MAP(names, LAMBDA(n, XLOOKUP(n, lookupNames, lookupImages))), keepImgs, FILTER(imgs, amounts<>0), keepAmoun"&"ts, FILTER(amounts, amounts<>0), MAKEARRAY( 1, COLUMNS(keepAmounts)*2, LAMBDA(r,c, IF( ISODD(c), INDEX(keepImgs, 1, ROUNDUP(c/2)), INDEX(keepAmounts, 1, c/2) ) ) ) )"),"") | F25: =IFERROR(__xludf.DUMMYFUNCTION("""COMPUTED_VALUE"""),15.0) -> 15 | L25: 1 | M25: 0 | N25: 0 | O25: 0 | P25: 0 | Q25: 0 | R25: 0 | S25: 0 | T25: 0 | U25: 15 | V25: 0 | W25: 0 | X25: 0
E26: =IFERROR(__xludf.DUMMYFUNCTION("LET( names, HSTACK(""Coins"", $N$4:$X$4), amounts, HSTACK(M26, N26:X26), lookupNames, $AB$4:$AB$15, lookupImages, $AC$4:$AC$15, imgs, MAP(names, LAMBDA(n, XLOOKUP(n, lookupNames, lookupImages))), keepImgs, FILTER(imgs, amounts<>0), keepAmoun"&"ts, FILTER(amounts, amounts<>0), MAKEARRAY( 1, COLUMNS(keepAmounts)*2, LAMBDA(r,c, IF( ISODD(c), INDEX(keepImgs, 1, ROUNDUP(c/2)), INDEX(keepAmounts, 1, c/2) ) ) ) )"),"") | F26: =IFERROR(__xludf.DUMMYFUNCTION("""COMPUTED_VALUE"""),10.0) -> 10 | L26: 2 | M26: 10 | N26: 0 | O26: 0 | P26: 0 | Q26: 0 | R26: 0 | S26: 0 | T26: 0 | U26: 0 | V26: 0 | W26: 0 | X26: 0
E27: =IFERROR(__xludf.DUMMYFUNCTION("LET( names, HSTACK(""Coins"", $N$4:$X$4), amounts, HSTACK(M27, N27:X27), lookupNames, $AB$4:$AB$15, lookupImages, $AC$4:$AC$15, imgs, MAP(names, LAMBDA(n, XLOOKUP(n, lookupNames, lookupImages))), keepImgs, FILTER(imgs, amounts<>0), keepAmoun"&"ts, FILTER(amounts, amounts<>0), MAKEARRAY( 1, COLUMNS(keepAmounts)*2, LAMBDA(r,c, IF( ISODD(c), INDEX(keepImgs, 1, ROUNDUP(c/2)), INDEX(keepAmounts, 1, c/2) ) ) ) )"),"") | F27: =IFERROR(__xludf.DUMMYFUNCTION("""COMPUTED_VALUE"""),1.0) -> 1 | L27: 3 | M27: 0 | N27: 0 | O27: 0 | P27: 0 | Q27: 0 | R27: 1 | S27: 0 | T27: 0 | U27: 0 | V27: 0 | W27: 0 | X27: 0
E28: =IFERROR(__xludf.DUMMYFUNCTION("LET( names, HSTACK(""Coins"", $N$4:$X$4), amounts, HSTACK(M28, N28:X28), lookupNames, $AB$4:$AB$15, lookupImages, $AC$4:$AC$15, imgs, MAP(names, LAMBDA(n, XLOOKUP(n, lookupNames, lookupImages))), keepImgs, FILTER(imgs, amounts<>0), keepAmoun"&"ts, FILTER(amounts, amounts<>0), MAKEARRAY( 1, COLUMNS(keepAmounts)*2, LAMBDA(r,c, IF( ISODD(c), INDEX(keepImgs, 1, ROUNDUP(c/2)), INDEX(keepAmounts, 1, c/2) ) ) ) )"),"") | F28: =IFERROR(__xludf.DUMMYFUNCTION("""COMPUTED_VALUE"""),10.0) -> 10 | L28: 4 | M28: 10 | N28: 0 | O28: 0 | P28: 0 | Q28: 0 | R28: 0 | S28: 0 | T28: 0 | U28: 0 | V28: 0 | W28: 0 | X28: 0
E29: =IFERROR(__xludf.DUMMYFUNCTION("LET( names, HSTACK(""Coins"", $N$4:$X$4), amounts, HSTACK(M29, N29:X29), lookupNames, $AB$4:$AB$15, lookupImages, $AC$4:$AC$15, imgs, MAP(names, LAMBDA(n, XLOOKUP(n, lookupNames, lookupImages))), keepImgs, FILTER(imgs, amounts<>0), keepAmoun"&"ts, FILTER(amounts, amounts<>0), MAKEARRAY( 1, COLUMNS(keepAmounts)*2, LAMBDA(r,c, IF( ISODD(c), INDEX(keepImgs, 1, ROUNDUP(c/2)), INDEX(keepAmounts, 1, c/2) ) ) ) )"),"") | F29: =IFERROR(__xludf.DUMMYFUNCTION("""COMPUTED_VALUE"""),1.0) -> 1 | L29: 5 | M29: 0 | N29: 0 | O29: 0 | P29: 0 | Q29: 0 | R29: 0 | S29: 1 | T29: 0 | U29: 0 | V29: 0 | W29: 0 | X29: 0
E30: =IFERROR(__xludf.DUMMYFUNCTION("LET( names, HSTACK(""Coins"", $N$4:$X$4), amounts, HSTACK(M30, N30:X30), lookupNames, $AB$4:$AB$15, lookupImages, $AC$4:$AC$15, imgs, MAP(names, LAMBDA(n, XLOOKUP(n, lookupNames, lookupImages))), keepImgs, FILTER(imgs, amounts<>0), keepAmoun"&"ts, FILTER(amounts, amounts<>0), MAKEARRAY( 1, COLUMNS(keepAmounts)*2, LAMBDA(r,c, IF( ISODD(c), INDEX(keepImgs, 1, ROUNDUP(c/2)), INDEX(keepAmounts, 1, c/2) ) ) ) )"),"") | F30: =IFERROR(__xludf.DUMMYFUNCTION("""COMPUTED_VALUE"""),10.0) -> 10 | L30: 6 | M30: 10 | N30: 0 | O30: 0 | P30: 0 | Q30: 0 | R30: 0 | S30: 0 | T30: 0 | U30: 0 | V30: 0 | W30: 0 | X30: 0
E31: =IFERROR(__xludf.DUMMYFUNCTION("LET( names, HSTACK(""Coins"", $N$4:$X$4), amounts, HSTACK(M31, N31:X31), lookupNames, $AB$4:$AB$15, lookupImages, $AC$4:$AC$15, imgs, MAP(names, LAMBDA(n, XLOOKUP(n, lookupNames, lookupImages))), keepImgs, FILTER(imgs, amounts<>0), keepAmoun"&"ts, FILTER(amounts, amounts<>0), MAKEARRAY( 1, COLUMNS(keepAmounts)*2, LAMBDA(r,c, IF( ISODD(c), INDEX(keepImgs, 1, ROUNDUP(c/2)), INDEX(keepAmounts, 1, c/2) ) ) ) )"),"") | F31: =IFERROR(__xludf.DUMMYFUNCTION("""COMPUTED_VALUE"""),100.0) -> 100 | G31: =IFERROR(__xludf.DUMMYFUNCTION("""COMPUTED_VALUE"""),"") | H31: =IFERROR(__xludf.DUMMYFUNCTION("""COMPUTED_VALUE"""),120.0) -> 120 | I31: =IFERROR(__xludf.DUMMYFUNCTION("""COMPUTED_VALUE"""),"") | J31: =IFERROR(__xludf.DUMMYFUNCTION("""COMPUTED_VALUE"""),30.0) -> 30 | L31: 7 | M31: 100 | N31: 0 | O31: 0 | P31: 0 | Q31: 0 | R31: 0 | S31: 0 | T31: 0 | U31: 120 | V31: 0 | W31: 0 | X31: 30
L33: Variant 4
L34: Day | M34: Coin | N34: SPT | O34: Red | P34: Chuck | Q34: Bomb | R34: Slingshot | S34: Shuffle | T34: Comet | U34: Unlimited Lives | V34: Unlimited Red | W34: Unlimited Chuck | X34: Unlimited Bomb
E35: =IFERROR(__xludf.DUMMYFUNCTION("LET( names, HSTACK(""Coins"", $N$4:$X$4), amounts, HSTACK(M35, N35:X35), lookupNames, $AB$4:$AB$15, lookupImages, $AC$4:$AC$15, imgs, MAP(names, LAMBDA(n, XLOOKUP(n, lookupNames, lookupImages))), keepImgs, FILTER(imgs, amounts<>0), keepAmoun"&"ts, FILTER(amounts, amounts<>0), MAKEARRAY( 1, COLUMNS(keepAmounts)*2, LAMBDA(r,c, IF( ISODD(c), INDEX(keepImgs, 1, ROUNDUP(c/2)), INDEX(keepAmounts, 1, c/2) ) ) ) )"),"") | F35: =IFERROR(__xludf.DUMMYFUNCTION("""COMPUTED_VALUE"""),10.0) -> 10 | L35: 1 | M35: 10 | N35: 0 | O35: 0 | P35: 0 | Q35: 0 | R35: 0 | S35: 0 | T35: 0 | U35: 0 | V35: 0 | W35: 0 | X35: 0
E36: =IFERROR(__xludf.DUMMYFUNCTION("LET( names, HSTACK(""Coins"", $N$4:$X$4), amounts, HSTACK(M36, N36:X36), lookupNames, $AB$4:$AB$15, lookupImages, $AC$4:$AC$15, imgs, MAP(names, LAMBDA(n, XLOOKUP(n, lookupNames, lookupImages))), keepImgs, FILTER(imgs, amounts<>0), keepAmoun"&"ts, FILTER(amounts, amounts<>0), MAKEARRAY( 1, COLUMNS(keepAmounts)*2, LAMBDA(r,c, IF( ISODD(c), INDEX(keepImgs, 1, ROUNDUP(c/2)), INDEX(keepAmounts, 1, c/2) ) ) ) )"),"") | F36: =IFERROR(__xludf.DUMMYFUNCTION("""COMPUTED_VALUE"""),30.0) -> 30 | L36: 2 | M36: 0 | N36: 0 | O36: 0 | P36: 0 | Q36: 0 | R36: 0 | S36: 0 | T36: 0 | U36: 30 | V36: 0 | W36: 0 | X36: 0
E37: =IFERROR(__xludf.DUMMYFUNCTION("LET( names, HSTACK(""Coins"", $N$4:$X$4), amounts, HSTACK(M37, N37:X37), lookupNames, $AB$4:$AB$15, lookupImages, $AC$4:$AC$15, imgs, MAP(names, LAMBDA(n, XLOOKUP(n, lookupNames, lookupImages))), keepImgs, FILTER(imgs, amounts<>0), keepAmoun"&"ts, FILTER(amounts, amounts<>0), MAKEARRAY( 1, COLUMNS(keepAmounts)*2, LAMBDA(r,c, IF( ISODD(c), INDEX(keepImgs, 1, ROUNDUP(c/2)), INDEX(keepAmounts, 1, c/2) ) ) ) )"),"") | F37: =IFERROR(__xludf.DUMMYFUNCTION("""COMPUTED_VALUE"""),1.0) -> 1 | L37: 3 | M37: 0 | N37: 0 | O37: 0 | P37: 0 | Q37: 0 | R37: 0 | S37: 1 | T37: 0 | U37: 0 | V37: 0 | W37: 0 | X37: 0
E38: =IFERROR(__xludf.DUMMYFUNCTION("LET( names, HSTACK(""Coins"", $N$4:$X$4), amounts, HSTACK(M38, N38:X38), lookupNames, $AB$4:$AB$15, lookupImages, $AC$4:$AC$15, imgs, MAP(names, LAMBDA(n, XLOOKUP(n, lookupNames, lookupImages))), keepImgs, FILTER(imgs, amounts<>0), keepAmoun"&"ts, FILTER(amounts, amounts<>0), MAKEARRAY( 1, COLUMNS(keepAmounts)*2, LAMBDA(r,c, IF( ISODD(c), INDEX(keepImgs, 1, ROUNDUP(c/2)), INDEX(keepAmounts, 1, c/2) ) ) ) )"),"") | F38: =IFERROR(__xludf.DUMMYFUNCTION("""COMPUTED_VALUE"""),1.0) -> 1 | L38: 4 | M38: 0 | N38: 0 | O38: 0 | P38: 0 | Q38: 0 | R38: 1 | S38: 0 | T38: 0 | U38: 0 | V38: 0 | W38: 0 | X38: 0
E39: =IFERROR(__xludf.DUMMYFUNCTION("LET( names, HSTACK(""Coins"", $N$4:$X$4), amounts, HSTACK(M39, N39:X39), lookupNames, $AB$4:$AB$15, lookupImages, $AC$4:$AC$15, imgs, MAP(names, LAMBDA(n, XLOOKUP(n, lookupNames, lookupImages))), keepImgs, FILTER(imgs, amounts<>0), keepAmoun"&"ts, FILTER(amounts, amounts<>0), MAKEARRAY( 1, COLUMNS(keepAmounts)*2, LAMBDA(r,c, IF( ISODD(c), INDEX(keepImgs, 1, ROUNDUP(c/2)), INDEX(keepAmounts, 1, c/2) ) ) ) )"),"") | F39: =IFERROR(__xludf.DUMMYFUNCTION("""COMPUTED_VALUE"""),10.0) -> 10 | L39: 5 | M39: 10 | N39: 0 | O39: 0 | P39: 0 | Q39: 0 | R39: 0 | S39: 0 | T39: 0 | U39: 0 | V39: 0 | W39: 0 | X39: 0
E40: =IFERROR(__xludf.DUMMYFUNCTION("LET( names, HSTACK(""Coins"", $N$4:$X$4), amounts, HSTACK(M40, N40:X40), lookupNames, $AB$4:$AB$15, lookupImages, $AC$4:$AC$15, imgs, MAP(names, LAMBDA(n, XLOOKUP(n, lookupNames, lookupImages))), keepImgs, FILTER(imgs, amounts<>0), keepAmoun"&"ts, FILTER(amounts, amounts<>0), MAKEARRAY( 1, COLUMNS(keepAmounts)*2, LAMBDA(r,c, IF( ISODD(c), INDEX(keepImgs, 1, ROUNDUP(c/2)), INDEX(keepAmounts, 1, c/2) ) ) ) )"),"") | F40: =IFERROR(__xludf.DUMMYFUNCTION("""COMPUTED_VALUE"""),1.0) -> 1 | L40: 6 | M40: 0 | N40: 0 | O40: 0 | P40: 0 | Q40: 0 | R40: 1 | S40: 0 | T40: 0 | U40: 0 | V40: 0 | W40: 0 | X40: 0
