Workbook

Sheet By Bucket
A1: A/B Test Summary By 7d Completion Bucket
A3: Category | B3: Metric | C3: 0 | F3: 1-9 | I3: 10-19 | L3: 20-39 | O3: 40-99 | R3: 100+
C4: Control | D4: Variant | E4: Δ % | F4: Control | G4: Variant | H4: Δ % | I4: Control | J4: Variant | K4: Δ % | L4: Control | M4: Variant | N4: Δ % | O4: Control | P4: Variant | Q4: Δ % | R4: Control | S4: Variant | T4: Δ %
A5: Players
B6: Players (sum) | C6: =SUMIFS(Raw_Data_Daily!$D:$D, Raw_Data_Daily!$B:$B, "Control", Raw_Data_Daily!$C:$C, "A. 0") -> 102894 | D6: =SUMIFS(Raw_Data_Daily!$D:$D, Raw_Data_Daily!$B:$B, "Variant", Raw_Data_Daily!$C:$C, "A. 0") -> 103236 | E6: =IFERROR((D6-C6)/ABS(C6),"") -> 0.003323809 | F6: =SUMIFS(Raw_Data_Daily!$D:$D, Raw_Data_Daily!$B:$B, "Control", Raw_Data_Daily!$C:$C, "B. 1-9") -> 157641 | G6: =SUMIFS(Raw_Data_Daily!$D:$D, Raw_Data_Daily!$B:$B, "Variant", Raw_Data_Daily!$C:$C, "B. 1-9") -> 154944 | H6: =IFERROR((G6-F6)/ABS(F6),"") -> -0.017108493 | I6: =SUMIFS(Raw_Data_Daily!$D:$D, Raw_Data_Daily!$B:$B, "Control", Raw_Data_Daily!$C:$C, "C. 10-19") -> 122073 | J6: =SUMIFS(Raw_Data_Daily!$D:$D, Raw_Data_Daily!$B:$B, "Variant", Raw_Data_Daily!$C:$C, "C. 10-19") -> 121963 | K6: =IFERROR((J6-I6)/ABS(I6),"") -> -0.00090110016 | L6: =SUMIFS(Raw_Data_Daily!$D:$D, Raw_Data_Daily!$B:$B, "Control", Raw_Data_Daily!$C:$C, "D. 20-39") -> 101078 | M6: =SUMIFS(Raw_Data_Daily!$D:$D, Raw_Data_Daily!$B:$B, "Variant", Raw_Data_Daily!$C:$C, "D. 20-39") -> 102900 | N6: =IFERROR((M6-L6)/ABS(L6),"") -> 0.018025683 | O6: =SUMIFS(Raw_Data_Daily!$D:$D, Raw_Data_Daily!$B:$B, "Control", Raw_Data_Daily!$C:$C, "E. 40-99") -> 65813 | P6: =SUMIFS(Raw_Data_Daily!$D:$D, Raw_Data_Daily!$B:$B, "Variant", Raw_Data_Daily!$C:$C, "E. 40-99") -> 62772 | Q6: =IFERROR((P6-O6)/ABS(O6),"") -> -0.046206676 | R6: =SUMIFS(Raw_Data_Daily!$D:$D, Raw_Data_Daily!$B:$B, "Control", Raw_Data_Daily!$C:$C, "F. 100+") -> 9596 | S6: =SUMIFS(Raw_Data_Daily!$D:$D, Raw_Data_Daily!$B:$B, "Variant", Raw_Data_Daily!$C:$C, "F. 100+") -> 9017 | T6: =IFERROR((S6-R6)/ABS(R6),"") -> -0.060337641
A7: Revenue
B8: Total revenue | C8: =SUMIFS(Raw_Data_Daily!$F:$F, Raw_Data_Daily!$B:$B, "Control", Raw_Data_Daily!$C:$C, "A. 0") -> 8193.45 | D8: =SUMIFS(Raw_Data_Daily!$F:$F, Raw_Data_Daily!$B:$B, "Variant", Raw_Data_Daily!$C:$C, "A. 0") -> 6330.06 | E8: =IFERROR((D8-C8)/ABS(C8),"") -> -0.22742435 | F8: =SUMIFS(Raw_Data_Daily!$F:$F, Raw_Data_Daily!$B:$B, "Control", Raw_Data_Daily!$C:$C, "B. 1-9") -> 2646.07 | G8: =SUMIFS(Raw_Data_Daily!$F:$F, Raw_Data_Daily!$B:$B, "Variant", Raw_Data_Daily!$C:$C, "B. 1-9") -> 2614.16 | H8: =IFERROR((G8-F8)/ABS(F8),"") -> -0.012059394 | I8: =SUMIFS(Raw_Data_Daily!$F:$F, Raw_Data_Daily!$B:$B, "Control", Raw_Data_Daily!$C:$C, "C. 10-19") -> 7313.33 | J8: =SUMIFS(Raw_Data_Daily!$F:$F, Raw_Data_Daily!$B:$B, "Variant", Raw_Data_Daily!$C:$C, "C. 10-19") -> 8034.94 | K8: =IFERROR((J8-I8)/ABS(I8),"") -> 0.09867051 | L8: =SUMIFS(Raw_Data_Daily!$F:$F, Raw_Data_Daily!$B:$B, "Control", Raw_Data_Daily!$C:$C, "D. 20-39") -> 12223.99 | M8: =SUMIFS(Raw_Data_Daily!$F:$F, Raw_Data_Daily!$B:$B, "Variant", Raw_Data_Daily!$C:$C, "D. 20-39") -> 12474.94 | N8: =IFERROR((M8-L8)/ABS(L8),"") -> 0.020529303 | O8: =SUMIFS(Raw_Data_Daily!$F:$F, Raw_Data_Daily!$B:$B, "Control", Raw_Data_Daily!$C:$C, "E. 40-99") -> 15152.74 | P8: =SUMIFS(Raw_Data_Daily!$F:$F, Raw_Data_Daily!$B:$B, "Variant", Raw_Data_Daily!$C:$C, "E. 40-99") -> 13041.14 | Q8: =IFERROR((P8-O8)/ABS(O8),"") -> -0.13935433 | R8: =SUMIFS(Raw_Data_Daily!$F:$F, Raw_Data_Daily!$B:$B, "Control", Raw_Data_Daily!$C:$C, "F. 100+") -> 4974.31 | S8: =SUMIFS(Raw_Data_Daily!$F:$F, Raw_Data_Daily!$B:$B, "Variant", Raw_Data_Daily!$C:$C, "F. 100+") -> 3434.25 | T8: =IFERROR((S8-R8)/ABS(R8),"") -> -0.30960274
B9: ARPDAU | C9: =IFERROR(SUMIFS(Raw_Data_Daily!$F:$F, Raw_Data_Daily!$B:$B, "Control", Raw_Data_Daily!$C:$C, "A. 0")/SUMIFS(Raw_Data_Daily!$D:$D, Raw_Data_Daily!$B:$B, "Control", Raw_Data_Daily!$C:$C, "A. 0"),"") -> 0.079630008 | D9: =IFERROR(SUMIFS(Raw_Data_Daily!$F:$F, Raw_Data_Daily!$B:$B, "Variant", Raw_Data_Daily!$C:$C, "A. 0")/SUMIFS(Raw_Data_Daily!$D:$D, Raw_Data_Daily!$B:$B, "Variant", Raw_Data_Daily!$C:$C, "A. 0"),"") -> 0.061316401 | E9: =IFERROR((D9-C9)/ABS(C9),"") -> -0.22998373 | F9: =IFERROR(SUMIFS(Raw_Data_Daily!$F:$F, Raw_Data_Daily!$B:$B, "Control", Raw_Data_Daily!$C:$C, "B. 1-9")/SUMIFS(Raw_Data_Daily!$D:$D, Raw_Data_Daily!$B:$B, "Control", Raw_Data_Daily!$C:$C, "B. 1-9"),"") -> 0.016785418 | G9: =IFERROR(SUMIFS(Raw_Data_Daily!$F:$F, Raw_Data_Daily!$B:$B, "Variant", Raw_Data_Daily!$C:$C, "B. 1-9")/SUMIFS(Raw_Data_Daily!$D:$D, Raw_Data_Daily!$B:$B, "Variant", Raw_Data_Daily!$C:$C, "B. 1-9"),"") -> 0.016871644 | H9: =IFERROR((G9-F9)/ABS(F9),"") -> 0.0051369857 | I9: =IFERROR(SUMIFS(Raw_Data_Daily!$F:$F, Raw_Data_Daily!$B:$B, "Control", Raw_Data_Daily!$C:$C, "C. 10-19")/SUMIFS(Raw_Data_Daily!$D:$D, Raw_Data_Daily!$B:$B, "Control", Raw_Data_Daily!$C:$C, "C. 10-19"),"") -> 0.05990948 | J9: =IFERROR(SUMIFS(Raw_Data_Daily!$F:$F, Raw_Data_Daily!$B:$B, "Variant", Raw_Data_Daily!$C:$C, "C. 10-19")/SUMIFS(Raw_Data_Daily!$D:$D, Raw_Data_Daily!$B:$B, "Variant", Raw_Data_Daily!$C:$C, "C. 10-19"),"") -> 0.065880144 | K9: =IFERROR((J9-I9)/ABS(I9),"") -> 0.099661415 | L9: =IFERROR(SUMIFS(Raw_Data_Daily!$F:$F, Raw_Data_Daily!$B:$B, "Control", Raw_Data_Daily!$C:$C, "D. 20-39")/SUMIFS(Raw_Data_Daily!$D:$D, Raw_Data_Daily!$B:$B, "Control", Raw_Data_Daily!$C:$C, "D. 20-39"),"") -> 0.12093621 | M9: =IFERROR(SUMIFS(Raw_Data_Daily!$F:$F, Raw_Data_Daily!$B:$B, "Variant", Raw_Data_Daily!$C:$C, "D. 20-39")/SUMIFS(Raw_Data_Daily!$D:$D, Raw_Data_Daily!$B:$B, "Variant", Raw_Data_Daily!$C:$C, "D. 20-39"),"") -> 0.12123362 | N9: =IFERROR((M9-L9)/ABS(L9),"") -> 0.0024592899 | O9: =IFERROR(SUMIFS(Raw_Data_Daily!$F:$F, Raw_Data_Daily!$B:$B, "Control", Raw_Data_Daily!$C:$C, "E. 40-99")/SUMIFS(Raw_Data_Daily!$D:$D, Raw_Data_Daily!$B:$B, "Control", Raw_Data_Daily!$C:$C, "E. 40-99"),"") -> 0.23023931 | P9: =IFERROR(SUMIFS(Raw_Data_Daily!$F:$F, Raw_Data_Daily!$B:$B, "Variant", Raw_Data_Daily!$C:$C, "E. 40-99")/SUMIFS(Raw_Data_Daily!$D:$D, Raw_Data_Daily!$B:$B, "Variant", Raw_Data_Daily!$C:$C, "E. 40-99"),"") -> 0.20775409 | Q9: =IFERROR((P9-O9)/ABS(O9),"") -> -0.097660212 | R9: =IFERROR(SUMIFS(Raw_Data_Daily!$F:$F, Raw_Data_Daily!$B:$B, "Control", Raw_Data_Daily!$C:$C, "F. 100+")/SUMIFS(Raw_Data_Daily!$D:$D, Raw_Data_Daily!$B:$B, "Control", Raw_Data_Daily!$C:$C, "F. 100+"),"") -> 0.51837328 | S9: =IFERROR(SUMIFS(Raw_Data_Daily!$F:$F, Raw_Data_Daily!$B:$B, "Variant", Raw_Data_Daily!$C:$C, "F. 100+")/SUMIFS(Raw_Data_Daily!$D:$D, Raw_Data_Daily!$B:$B, "Variant", Raw_Data_Daily!$C:$C, "F. 100+"),"") -> 0.38086392 | T9: =IFERROR((S9-R9)/ABS(R9),"") -> -0.26527092
B10: AVG Payer day (%) | C10: =IFERROR(SUMPRODUCT((Raw_Data_Daily!$B$2:$B$9999="Control")*(Raw_Data_Daily!$C$2:$C$9999="A. 0")*Raw_Data_Daily!$D$2:$D$9999*Raw_Data_Daily!$H$2:$H$9999/100)/SUMIFS(Raw_Data_Daily!$D:$D, Raw_Data_Daily!$B:$B, "Control", Raw_Data_Daily!$C:$C, "A. 0")*100,"") -> 1.0554593 | D10: =IFERROR(SUMPRODUCT((Raw_Data_Daily!$B$2:$B$9999="Variant")*(Raw_Data_Daily!$C$2:$C$9999="A. 0")*Raw_Data_Daily!$D$2:$D$9999*Raw_Data_Daily!$H$2:$H$9999/100)/SUMIFS(Raw_Data_Daily!$D:$D, Raw_Data_Daily!$B:$B, "Variant", Raw_Data_Daily!$C:$C, "A. 0")*100,"") -> 0.93880071 | E10: =IFERROR((D10-C10)/ABS(C10),"") -> -0.11052875 | F10: =IFERROR(SUMPRODUCT((Raw_Data_Daily!$B$2:$B$9999="Control")*(Raw_Data_Daily!$C$2:$C$9999="B. 1-9")*Raw_Data_Daily!$D$2:$D$9999*Raw_Data_Daily!$H$2:$H$9999/100)/SUMIFS(Raw_Data_Daily!$D:$D, Raw_Data_Daily!$B:$B, "Control", Raw_Data_Daily!$C:$C, "B. 1-9")*100,"") -> 0.7122687 | G10: =IFERROR(SUMPRODUCT((Raw_Data_Daily!$B$2:$B$9999="Variant")*(Raw_Data_Daily!$C$2:$C$9999="B. 1-9")*Raw_Data_Daily!$D$2:$D$9999*Raw_Data_Daily!$H$2:$H$9999/100)/SUMIFS(Raw_Data_Daily!$D:$D, Raw_Data_Daily!$B:$B, "Variant", Raw_Data_Daily!$C:$C, "B. 1-9")*100,"") -> 0.71842892 | H10: =IFERROR((G10-F10)/ABS(F10),"") -> 0.0086487264 | I10: =IFERROR(SUMPRODUCT((Raw_Data_Daily!$B$2:$B$9999="Control")*(Raw_Data_Daily!$C$2:$C$9999="C. 10-19")*Raw_Data_Daily!$D$2:$D$9999*Raw_Data_Daily!$H$2:$H$9999/100)/SUMIFS(Raw_Data_Daily!$D:$D, Raw_Data_Daily!$B:$B, "Control", Raw_Data_Daily!$C:$C, "C. 10-19")*100,"") -> 1.8751551 | J10: =IFERROR(SUMPRODUCT((Raw_Data_Daily!$B$2:$B$9999="Variant")*(Raw_Data_Daily!$C$2:$C$9999="C. 10-19")*Raw_Data_Daily!$D$2:$D$9999*Raw_Data_Daily!$H$2:$H$9999/100)/SUMIFS(Raw_Data_Daily!$D:$D, Raw_Data_Daily!$B:$B, "Variant", Raw_Data_Daily!$C:$C, "C. 10-19")*100,"") -> 1.9719162 | K10: =IFERROR((J10-I10)/ABS(I10),"") -> 0.051601621 | L10: =IFERROR(SUMPRODUCT((Raw_Data_Daily!$B$2:$B$9999="Control")*(Raw_Data_Daily!$C$2:$C$9999="D. 20-39")*Raw_Data_Daily!$D$2:$D$9999*Raw_Data_Daily!$H$2:$H$9999/100)/SUMIFS(Raw_Data_Daily!$D:$D, Raw_Data_Daily!$B:$B, "Control", Raw_Data_Daily!$C:$C, "D. 20-39")*100,"") -> 2.5994915 | M10: =IFERROR(SUMPRODUCT((Raw_Data_Daily!$B$2:$B$9999="Variant")*(Raw_Data_Daily!$C$2:$C$9999="D. 20-39")*Raw_Data_Daily!$D$2:$D$9999*Raw_Data_Daily!$H$2:$H$9999/100)/SUMIFS(Raw_Data_Daily!$D:$D, Raw_Data_Daily!$B:$B, "Variant", Raw_Data_Daily!$C:$C, "D. 20-39")*100,"") -> 2.6479356 | N10: =IFERROR((M10-L10)/ABS(L10),"") -> 0.018635986 | O10: =IFERROR(SUMPRODUCT((Raw_Data_Daily!$B$2:$B$9999="Control")*(Raw_Data_Daily!$C$2:$C$9999="E. 40-99")*Raw_Data_Daily!$D$2:$D$9999*Raw_Data_Daily!$H$2:$H$9999/100)/SUMIFS(Raw_Data_Daily!$D:$D, Raw_Data_Daily!$B:$B, "Control", Raw_Data_Daily!$C:$C, "E. 40-99")*100,"") -> 3.8401333 | P10: =IFERROR(SUMPRODUCT((Raw_Data_Daily!$B$2:$B$9999="Variant")*(Raw_Data_Daily!$C$2:$C$9999="E. 40-99")*Raw_Data_Daily!$D$2:$D$9999*Raw_Data_Daily!$H$2:$H$9999/100)/SUMIFS(Raw_Data_Daily!$D:$D, Raw_Data_Daily!$B:$B, "Variant", Raw_Data_Daily!$C:$C, "E. 40-99")*100,"") -> 3.7465626 | Q10: =IFERROR((P10-O10)/ABS(O10),"") -> -0.024366503 | R10: =IFERROR(SUMPRODUCT((Raw_Data_Daily!$B$2:$B$9999="Control")*(Raw_Data_Daily!$C$2:$C$9999="F. 100+")*Raw_Data_Daily!$D$2:$D$9999*Raw_Data_Daily!$H$2:$H$9999/100)/SUMIFS(Raw_Data_Daily!$D:$D, Raw_Data_Daily!$B:$B, "Control", Raw_Data_Daily!$C:$C, "F. 100+")*100,"") -> 6.5955648 | S10: =IFERROR(SUMPRODUCT((Raw_Data_Daily!$B$2:$B$9999="Variant")*(Raw_Data_Daily!$C$2:$C$9999="F. 100+")*Raw_Data_Daily!$D$2:$D$9999*Raw_Data_Daily!$H$2:$H$9999/100)/SUMIFS(Raw_Data_Daily!$D:$D, Raw_Data_Daily!$B:$B, "Variant", Raw_Data_Daily!$C:$C, "F. 100+")*100,"") -> 5.866979 | T10: =IFERROR((S10-R10)/ABS(R10),"") -> -0.11046602
B11: ARPPU | C11: =IFERROR(SUMIFS(Raw_Data_Daily!$F:$F, Raw_Data_Daily!$B:$B, "Control", Raw_Data_Daily!$C:$C, "A. 0")/SUMPRODUCT((Raw_Data_Daily!$B$2:$B$9999="Control")*(Raw_Data_Daily!$C$2:$C$9999="A. 0")*Raw_Data_Daily!$D$2:$D$9999*Raw_Data_Daily!$H$2:$H$9999/100),"") -> 7.5445834 | D11: =IFERROR(SUMIFS(Raw_Data_Daily!$F:$F, Raw_Data_Daily!$B:$B, "Variant", Raw_Data_Daily!$C:$C, "A. 0")/SUMPRODUCT((Raw_Data_Daily!$B$2:$B$9999="Variant")*(Raw_Data_Daily!$C$2:$C$9999="A. 0")*Raw_Data_Daily!$D$2:$D$9999*Raw_Data_Daily!$H$2:$H$9999/100),"") -> 6.5313544 | E11: =IFERROR((D11-C11)/ABS(C11),"") -> -0.13429887 | F11: =IFERROR(SUMIFS(Raw_Data_Daily!$F:$F, Raw_Data_Daily!$B:$B, "Control", Raw_Data_Daily!$C:$C, "B. 1-9")/SUMPRODUCT((Raw_Data_Daily!$B$2:$B$9999="Control")*(Raw_Data_Daily!$C$2:$C$9999="B. 1-9")*Raw_Data_Daily!$D$2:$D$9999*Raw_Data_Daily!$H$2:$H$9999/100),"") -> 2.3566131 | G11: =IFERROR(SUMIFS(Raw_Data_Daily!$F:$F, Raw_Data_Daily!$B:$B, "Variant", Raw_Data_Daily!$C:$C, "B. 1-9")/SUMPRODUCT((Raw_Data_Daily!$B$2:$B$9999="Variant")*(Raw_Data_Daily!$C$2:$C$9999="B. 1-9")*Raw_Data_Daily!$D$2:$D$9999*Raw_Data_Daily!$H$2:$H$9999/100),"") -> 2.3484083 | H11: =IFERROR((G11-F11)/ABS(F11),"") -> -0.0034816291 | I11: =IFERROR(SUMIFS(Raw_Data_Daily!$F:$F, Raw_Data_Daily!$B:$B, "Control", Raw_Data_Daily!$C:$C, "C. 10-19")/SUMPRODUCT((Raw_Data_Daily!$B$2:$B$9999="Control")*(Raw_Data_Daily!$C$2:$C$9999="C. 10-19")*Raw_Data_Daily!$D$2:$D$9999*Raw_Data_Daily!$H$2:$H$9999/100),"") -> 3.194908 | J11: =IFERROR(SUMIFS(Raw_Data_Daily!$F:$F, Raw_Data_Daily!$B:$B, "Variant", Raw_Data_Daily!$C:$C, "C. 10-19")/SUMPRODUCT((Raw_Data_Daily!$B$2:$B$9999="Variant")*(Raw_Data_Daily!$C$2:$C$9999="C. 10-19")*Raw_Data_Daily!$D$2:$D$9999*Raw_Data_Daily!$H$2:$H$9999/100),"") -> 3.3409201 | K11: =IFERROR((J11-I11)/ABS(I11),"") -> 0.045701522 | L11: =IFERROR(SUMIFS(Raw_Data_Daily!$F:$F, Raw_Data_Daily!$B:$B, "Control", Raw_Data_Daily!$C:$C, "D. 20-39")/SUMPRODUCT((Raw_Data_Daily!$B$2:$B$9999="Control")*(Raw_Data_Daily!$C$2:$C$9999="D. 20-39")*Raw_Data_Daily!$D$2:$D$9999*Raw_Data_Daily!$H$2:$H$9999/100),"") -> 4.6523025 | M11: =IFERROR(SUMIFS(Raw_Data_Daily!$F:$F, Raw_Data_Daily!$B:$B, "Variant", Raw_Data_Daily!$C:$C, "D. 20-39")/SUMPRODUCT((Raw_Data_Daily!$B$2:$B$9999="Variant")*(Raw_Data_Daily!$C$2:$C$9999="D. 20-39")*Raw_Data_Daily!$D$2:$D$9999*Raw_Data_Daily!$H$2:$H$9999/100),"") -> 4.5784205 | N11: =IFERROR((M11-L11)/ABS(L11),"") -> -0.015880743 | O11: =IFERROR(SUMIFS(Raw_Data_Daily!$F:$F, Raw_Data_Daily!$B:$B, "Control", Raw_Data_Daily!$C:$C, "E. 40-99")/SUMPRODUCT((Raw_Data_Daily!$B$2:$B$9999="Control")*(Raw_Data_Daily!$C$2:$C$9999="E. 40-99")*Raw_Data_Daily!$D$2:$D$9999*Raw_Data_Daily!$H$2:$H$9999/100),"") -> 5.9956074 | P11: =IFERROR(SUMIFS(Raw_Data_Daily!$F:$F, Raw_Data_Daily!$B:$B, "Variant", Raw_Data_Daily!$C:$C, "E. 40-99")/SUMPRODUCT((Raw_Data_Daily!$B$2:$B$9999="Variant")*(Raw_Data_Daily!$C$2:$C$9999="E. 40-99")*Raw_Data_Daily!$D$2:$D$9999*Raw_Data_Daily!$H$2:$H$9999/100),"") -> 5.5451921 | Q11: =IFERROR((P11-O11)/ABS(O11),"") -> -0.075124224 | R11: =IFERROR(SUMIFS(Raw_Data_Daily!$F:$F, Raw_Data_Daily!$B:$B, "Control", Raw_Data_Daily!$C:$C, "F. 100+")/SUMPRODUCT((Raw_Data_Daily!$B$2:$B$9999="Control")*(Raw_Data_Daily!$C$2:$C$9999="F. 100+")*Raw_Data_Daily!$D$2:$D$9999*Raw_Data_Daily!$H$2:$H$9999/100),"") -> 7.8594221 | S11: =IFERROR(SUMIFS(Raw_Data_Daily!$F:$F, Raw_Data_Daily!$B:$B, "Variant", Raw_Data_Daily!$C:$C, "F. 100+")/SUMPRODUCT((Raw_Data_Daily!$B$2:$B$9999="Variant")*(Raw_Data_Daily!$C$2:$C$9999="F. 100+")*Raw_Data_Daily!$D$2:$D$9999*Raw_Data_Daily!$H$2:$H$9999/100),"") -> 6.491653 | T11: =IFERROR((S11-R11)/ABS(R11),"") -> -0.17402922
A12: Engagement
B13: Time spent (mins) | C13: =IFERROR(SUMPRODUCT((Raw_Data_Daily!$B$2:$B$9999="Control")*(Raw_Data_Daily!$C$2:$C$9999="A. 0")*Raw_Data_Daily!$D$2:$D$9999*Raw_Data_Daily!$J$2:$J$9999)/SUMIFS(Raw_Data_Daily!$D:$D, Raw_Data_Daily!$B:$B, "Control", Raw_Data_Daily!$C:$C, "A. 0"),"") -> 18.368162 | D13: =IFERROR(SUMPRODUCT((Raw_Data_Daily!$B$2:$B$9999="Variant")*(Raw_Data_Daily!$C$2:$C$9999="A. 0")*Raw_Data_Daily!$D$2:$D$9999*Raw_Data_Daily!$J$2:$J$9999)/SUMIFS(Raw_Data_Daily!$D:$D, Raw_Data_Daily!$B:$B, "Variant", Raw_Data_Daily!$C:$C, "A. 0"),"") -> 19.623008 | E13: =IFERROR((D13-C13)/ABS(C13),"") -> 0.068316387 | F13: =IFERROR(SUMPRODUCT((Raw_Data_Daily!$B$2:$B$9999="Control")*(Raw_Data_Daily!$C$2:$C$9999="B. 1-9")*Raw_Data_Daily!$D$2:$D$9999*Raw_Data_Daily!$J$2:$J$9999)/SUMIFS(Raw_Data_Daily!$D:$D, Raw_Data_Daily!$B:$B, "Control", Raw_Data_Daily!$C:$C, "B. 1-9"),"") -> 20.568706 | G13: =IFERROR(SUMPRODUCT((Raw_Data_Daily!$B$2:$B$9999="Variant")*(Raw_Data_Daily!$C$2:$C$9999="B. 1-9")*Raw_Data_Daily!$D$2:$D$9999*Raw_Data_Daily!$J$2:$J$9999)/SUMIFS(Raw_Data_Daily!$D:$D, Raw_Data_Daily!$B:$B, "Variant", Raw_Data_Daily!$C:$C, "B. 1-9"),"") -> 20.665973 | H13: =IFERROR((G13-F13)/ABS(F13),"") -> 0.0047289085 | I13: =IFERROR(SUMPRODUCT((Raw_Data_Daily!$B$2:$B$9999="Control")*(Raw_Data_Daily!$C$2:$C$9999="C. 10-19")*Raw_Data_Daily!$D$2:$D$9999*Raw_Data_Daily!$J$2:$J$9999)/SUMIFS(Raw_Data_Daily!$D:$D, Raw_Data_Daily!$B:$B, "Control", Raw_Data_Daily!$C:$C, "C. 10-19"),"") -> 39.44283 | J13: =IFERROR(SUMPRODUCT((Raw_Data_Daily!$B$2:$B$9999="Variant")*(Raw_Data_Daily!$C$2:$C$9999="C. 10-19")*Raw_Data_Daily!$D$2:$D$9999*Raw_Data_Daily!$J$2:$J$9999)/SUMIFS(Raw_Data_Daily!$D:$D, Raw_Data_Daily!$B:$B, "Variant", Raw_Data_Daily!$C:$C, "C. 10-19"),"") -> 41.292372 | K13: =IFERROR((J13-I13)/ABS(I13),"") -> 0.046891702 | L13: =IFERROR(SUMPRODUCT((Raw_Data_Daily!$B$2:$B$9999="Control")*(Raw_Data_Daily!$C$2:$C$9999="D. 20-39")*Raw_Data_Daily!$D$2:$D$9999*Raw_Data_Daily!$J$2:$J$9999)/SUMIFS(Raw_Data_Daily!$D:$D, Raw_Data_Daily!$B:$B, "Control", Raw_Data_Daily!$C:$C, "D. 20-39"),"") -> 60.460918 | M13: =IFERROR(SUMPRODUCT((Raw_Data_Daily!$B$2:$B$9999="Variant")*(Raw_Data_Daily!$C$2:$C$9999="D. 20-39")*Raw_Data_Daily!$D$2:$D$9999*Raw_Data_Daily!$J$2:$J$9999)/SUMIFS(Raw_Data_Daily!$D:$D, Raw_Data_Daily!$B:$B, "Variant", Raw_Data_Daily!$C:$C, "D. 20-39"),"") -> 63.21944 | N13: =IFERROR((M13-L13)/ABS(L13),"") -> 0.045624889 | O13: =IFERROR(SUMPRODUCT((Raw_Data_Daily!$B$2:$B$9999="Control")*(Raw_Data_Daily!$C$2:$C$9999="E. 40-99")*Raw_Data_Daily!$D$2:$D$9999*Raw_Data_Daily!$J$2:$J$9999)/SUMIFS(Raw_Data_Daily!$D:$D, Raw_Data_Daily!$B:$B, "Control", Raw_Data_Daily!$C:$C, "E. 40-99"),"") -> 111.62043 | P13: =IFERROR(SUMPRODUCT((Raw_Data_Daily!$B$2:$B$9999="Variant")*(Raw_Data_Daily!$C$2:$C$9999="E. 40-99")*Raw_Data_Daily!$D$2:$D$9999*Raw_Data_Daily!$J$2:$J$9999)/SUMIFS(Raw_Data_Daily!$D:$D, Raw_Data_Daily!$B:$B, "Variant", Raw_Data_Daily!$C:$C, "E. 40-99"),"") -> 114.52549 | Q13: =IFERROR((P13-O13)/ABS(O13),"") -> 0.026026217 | R13: =IFERROR(SUMPRODUCT((Raw_Data_Daily!$B$2:$B$9999="Control")*(Raw_Data_Daily!$C$2:$C$9999="F. 100+")*Raw_Data_Daily!$D$2:$D$9999*Raw_Data_Daily!$J$2:$J$9999)/SUMIFS(Raw_Data_Daily!$D:$D, Raw_Data_Daily!$B:$B, "Control", Raw_Data_Daily!$C:$C, "F. 100+"),"") -> 234.94855 | S13: =IFERROR(SUMPRODUCT((Raw_Data_Daily!$B$2:$B$9999="Variant")*(Raw_Data_Daily!$C$2:$C$9999="F. 100+")*Raw_Data_Daily!$D$2:$D$9999*Raw_Data_Daily!$J$2:$J$9999)/SUMIFS(Raw_Data_Daily!$D:$D, Raw_Data_Daily!$B:$B, "Variant", Raw_Data_Daily!$C:$C, "F. 100+"),"") -> 240.20177 | T13: =IFERROR((S13-R13)/ABS(R13),"") -> 0.022359012
B14: Level attempts / player | C14: =IFERROR(SUMPRODUCT((Raw_Data_Daily!$B$2:$B$9999="Control")*(Raw_Data_Daily!$C$2:$C$9999="A. 0")*Raw_Data_Daily!$D$2:$D$9999*Raw_Data_Daily!$K$2:$K$9999)/SUMIFS(Raw_Data_Daily!$D:$D, Raw_Data_Daily!$B:$B, "Control", Raw_Data_Daily!$C:$C, "A. 0"),"") -> 10.072469 | D14: =IFERROR(SUMPRODUCT((Raw_Data_Daily!$B$2:$B$9999="Variant")*(Raw_Data_Daily!$C$2:$C$9999="A. 0")*Raw_Data_Daily!$D$2:$D$9999*Raw_Data_Daily!$K$2:$K$9999)/SUMIFS(Raw_Data_Daily!$D:$D, Raw_Data_Daily!$B:$B, "Variant", Raw_Data_Daily!$C:$C, "A. 0"),"") -> 10.544212 | E14: =IFERROR((D14-C14)/ABS(C14),"") -> 0.046834848 | F14: =IFERROR(SUMPRODUCT((Raw_Data_Daily!$B$2:$B$9999="Control")*(Raw_Data_Daily!$C$2:$C$9999="B. 1-9")*Raw_Data_Daily!$D$2:$D$9999*Raw_Data_Daily!$K$2:$K$9999)/SUMIFS(Raw_Data_Daily!$D:$D, Raw_Data_Daily!$B:$B, "Control", Raw_Data_Daily!$C:$C, "B. 1-9"),"") -> 10.850446 | G14: =IFERROR(SUMPRODUCT((Raw_Data_Daily!$B$2:$B$9999="Variant")*(Raw_Data_Daily!$C$2:$C$9999="B. 1-9")*Raw_Data_Daily!$D$2:$D$9999*Raw_Data_Daily!$K$2:$K$9999)/SUMIFS(Raw_Data_Daily!$D:$D, Raw_Data_Daily!$B:$B, "Variant", Raw_Data_Daily!$C:$C, "B. 1-9"),"") -> 10.677886 | H14: =IFERROR((G14-F14)/ABS(F14),"") -> -0.015903541 | I14: =IFERROR(SUMPRODUCT((Raw_Data_Daily!$B$2:$B$9999="Control")*(Raw_Data_Daily!$C$2:$C$9999="C. 10-19")*Raw_Data_Daily!$D$2:$D$9999*Raw_Data_Daily!$K$2:$K$9999)/SUMIFS(Raw_Data_Daily!$D:$D, Raw_Data_Daily!$B:$B, "Control", Raw_Data_Daily!$C:$C, "C. 10-19"),"") -> 21.888789 | J14: =IFERROR(SUMPRODUCT((Raw_Data_Daily!$B$2:$B$9999="Variant")*(Raw_Data_Daily!$C$2:$C$9999="C. 10-19")*Raw_Data_Daily!$D$2:$D$9999*Raw_Data_Daily!$K$2:$K$9999)/SUMIFS(Raw_Data_Daily!$D:$D, Raw_Data_Daily!$B:$B, "Variant", Raw_Data_Daily!$C:$C, "C. 10-19"),"") -> 22.361657 | K14: =IFERROR((J14-I14)/ABS(I14),"") -> 0.021603231 | L14: =IFERROR(SUMPRODUCT((Raw_Data_Daily!$B$2:$B$9999="Control")*(Raw_Data_Daily!$C$2:$C$9999="D. 20-39")*Raw_Data_Daily!$D$2:$D$9999*Raw_Data_Daily!$K$2:$K$9999)/SUMIFS(Raw_Data_Daily!$D:$D, Raw_Data_Daily!$B:$B, "Control", Raw_Data_Daily!$C:$C, "D. 20-39"),"") -> 35.616451 | M14: =IFERROR(SUMPRODUCT((Raw_Data_Daily!$B$2:$B$9999="Variant")*(Raw_Data_Daily!$C$2:$C$9999="D. 20-39")*Raw_Data_Daily!$D$2:$D$9999*Raw_Data_Daily!$K$2:$K$9999)/SUMIFS(Raw_Data_Daily!$D:$D, Raw_Data_Daily!$B:$B, "Variant", Raw_Data_Daily!$C:$C, "D. 20-39"),"") -> 36.291976 | N14: =IFERROR((M14-L14)/ABS(L14),"") -> 0.018966672 | O14: =IFERROR(SUMPRODUCT((Raw_Data_Daily!$B$2:$B$9999="Control")*(Raw_Data_Daily!$C$2:$C$9999="E. 40-99")*Raw_Data_Daily!$D$2:$D$9999*Raw_Data_Daily!$K$2:$K$9999)/SUMIFS(Raw_Data_Daily!$D:$D, Raw_Data_Daily!$B:$B, "Control", Raw_Data_Daily!$C:$C, "E. 40-99"),"") -> 70.000774 | P14: =IFERROR(SUMPRODUCT((Raw_Data_Daily!$B$2:$B$9999="Variant")*(Raw_Data_Daily!$C$2:$C$9999="E. 40-99")*Raw_Data_Daily!$D$2:$D$9999*Raw_Data_Daily!$K$2:$K$9999)/SUMIFS(Raw_Data_Daily!$D:$D, Raw_Data_Daily!$B:$B, "Variant", Raw_Data_Daily!$C:$C, "E. 40-99"),"") -> 71.082636 | Q14: =IFERROR((P14-O14)/ABS(O14),"") -> 0.01545501 | R14: =IFERROR(SUMPRODUCT((Raw_Data_Daily!$B$2:$B$9999="Control")*(Raw_Data_Daily!$C$2:$C$9999="F. 100+")*Raw_Data_Daily!$D$2:$D$9999*Raw_Data_Daily!$K$2:$K$9999)/SUMIFS(Raw_Data_Daily!$D:$D, Raw_Data_Daily!$B:$B, "Control", Raw_Data_Daily!$C:$C, "F. 100+"),"") -> 162.46144 | S14: =IFERROR(SUMPRODUCT((Raw_Data_Daily!$B$2:$B$9999="Variant")*(Raw_Data_Daily!$C$2:$C$9999="F. 100+")*Raw_Data_Daily!$D$2:$D$9999*Raw_Data_Daily!$K$2:$K$9999)/SUMIFS(Raw_Data_Daily!$D:$D, Raw_Data_Daily!$B:$B, "Variant", Raw_Data_Daily!$C:$C, "F. 100+"),"") -> 166.44763 | T14: =IFERROR((S14-R14)/ABS(R14),"") -> 0.024536268
B15: Level completes / player | C15: =IFERROR(SUMPRODUCT((Raw_Data_Daily!$B$2:$B$9999="Control")*(Raw_Data_Daily!$C$2:$C$9999="A. 0")*Raw_Data_Daily!$D$2:$D$9999*Raw_Data_Daily!$L$2:$L$9999)/SUMIFS(Raw_Data_Daily!$D:$D, Raw_Data_Daily!$B:$B, "Control", Raw_Data_Daily!$C:$C, "A. 0"),"") -> 6.7675205 | D15: =IFERROR(SUMPRODUCT((Raw_Data_Daily!$B$2:$B$9999="Variant")*(Raw_Data_Daily!$C$2:$C$9999="A. 0")*Raw_Data_Daily!$D$2:$D$9999*Raw_Data_Daily!$L$2:$L$9999)/SUMIFS(Raw_Data_Daily!$D:$D, Raw_Data_Daily!$B:$B, "Variant", Raw_Data_Daily!$C:$C, "A. 0"),"") -> 7.1752982 | E15: =IFERROR((D15-C15)/ABS(C15),"") -> 0.060255125 | F15: =IFERROR(SUMPRODUCT((Raw_Data_Daily!$B$2:$B$9999="Control")*(Raw_Data_Daily!$C$2:$C$9999="B. 1-9")*Raw_Data_Daily!$D$2:$D$9999*Raw_Data_Daily!$L$2:$L$9999)/SUMIFS(Raw_Data_Daily!$D:$D, Raw_Data_Daily!$B:$B, "Control", Raw_Data_Daily!$C:$C, "B. 1-9"),"") -> 5.1459232 | G15: =IFERROR(SUMPRODUCT((Raw_Data_Daily!$B$2:$B$9999="Variant")*(Raw_Data_Daily!$C$2:$C$9999="B. 1-9")*Raw_Data_Daily!$D$2:$D$9999*Raw_Data_Daily!$L$2:$L$9999)/SUMIFS(Raw_Data_Daily!$D:$D, Raw_Data_Daily!$B:$B, "Variant", Raw_Data_Daily!$C:$C, "B. 1-9"),"") -> 5.1034039 | H15: =IFERROR((G15-F15)/ABS(F15),"") -> -0.0082627215 | I15: =IFERROR(SUMPRODUCT((Raw_Data_Daily!$B$2:$B$9999="Control")*(Raw_Data_Daily!$C$2:$C$9999="C. 10-19")*Raw_Data_Daily!$D$2:$D$9999*Raw_Data_Daily!$L$2:$L$9999)/SUMIFS(Raw_Data_Daily!$D:$D, Raw_Data_Daily!$B:$B, "Control", Raw_Data_Daily!$C:$C, "C. 10-19"),"") -> 13.5322 | J15: =IFERROR(SUMPRODUCT((Raw_Data_Daily!$B$2:$B$9999="Variant")*(Raw_Data_Daily!$C$2:$C$9999="C. 10-19")*Raw_Data_Daily!$D$2:$D$9999*Raw_Data_Daily!$L$2:$L$9999)/SUMIFS(Raw_Data_Daily!$D:$D, Raw_Data_Daily!$B:$B, "Variant", Raw_Data_Daily!$C:$C, "C. 10-19"),"") -> 13.363786 | K15: =IFERROR((J15-I15)/ABS(I15),"") -> -0.012445481 | L15: =IFERROR(SUMPRODUCT((Raw_Data_Daily!$B$2:$B$9999="Control")*(Raw_Data_Daily!$C$2:$C$9999="D. 20-39")*Raw_Data_Daily!$D$2:$D$9999*Raw_Data_Daily!$L$2:$L$9999)/SUMIFS(Raw_Data_Daily!$D:$D, Raw_Data_Daily!$B:$B, "Control", Raw_Data_Daily!$C:$C, "D. 20-39"),"") -> 25.541551 | M15: =IFERROR(SUMPRODUCT((Raw_Data_Daily!$B$2:$B$9999="Variant")*(Raw_Data_Daily!$C$2:$C$9999="D. 20-39")*Raw_Data_Daily!$D$2:$D$9999*Raw_Data_Daily!$L$2:$L$9999)/SUMIFS(Raw_Data_Daily!$D:$D, Raw_Data_Daily!$B:$B, "Variant", Raw_Data_Daily!$C:$C, "D. 20-39"),"") -> 25.348972 | N15: =IFERROR((M15-L15)/ABS(L15),"") -> -0.0075398269 | O15: =IFERROR(SUMPRODUCT((Raw_Data_Daily!$B$2:$B$9999="Control")*(Raw_Data_Daily!$C$2:$C$9999="E. 40-99")*Raw_Data_Daily!$D$2:$D$9999*Raw_Data_Daily!$L$2:$L$9999)/SUMIFS(Raw_Data_Daily!$D:$D, Raw_Data_Daily!$B:$B, "Control", Raw_Data_Daily!$C:$C, "E. 40-99"),"") -> 52.483629 | P15: =IFERROR(SUMPRODUCT((Raw_Data_Daily!$B$2:$B$9999="Variant")*(Raw_Data_Daily!$C$2:$C$9999="E. 40-99")*Raw_Data_Daily!$D$2:$D$9999*Raw_Data_Daily!$L$2:$L$9999)/SUMIFS(Raw_Data_Daily!$D:$D, Raw_Data_Daily!$B:$B, "Variant", Raw_Data_Daily!$C:$C, "E. 40-99"),"") -> 52.100151 | Q15: =IFERROR((P15-O15)/ABS(O15),"") -> -0.0073066164 | R15: =IFERROR(SUMPRODUCT((Raw_Data_Daily!$B$2:$B$9999="Control")*(Raw_Data_Daily!$C$2:$C$9999="F. 100+")*Raw_Data_Daily!$D$2:$D$9999*Raw_Data_Daily!$L$2:$L$9999)/SUMIFS(Raw_Data_Daily!$D:$D, Raw_Data_Daily!$B:$B, "Control", Raw_Data_Daily!$C:$C, "F. 100+"),"") -> 124.90036 | S15: =IFERROR(SUMPRODUCT((Raw_Data_Daily!$B$2:$B$9999="Variant")*(Raw_Data_Daily!$C$2:$C$9999="F. 100+")*Raw_Data_Daily!$D$2:$D$9999*Raw_Data_Daily!$L$2:$L$9999)/SUMIFS(Raw_Data_Daily!$D:$D, Raw_Data_Daily!$B:$B, "Variant", Raw_Data_Daily!$C:$C, "F. 100+"),"") -> 123.66318 | T15: =IFERROR((S15-R15)/ABS(R15),"") -> -0.0099053445
A16: Daily Streak
B17: Avg daily streak | C17: =IFERROR(SUMPRODUCT((Raw_Data_Daily!$B$2:$B$9999="Control")*(Raw_Data_Daily!$C$2:$C$9999="A. 0")*Raw_Data_Daily!$D$2:$D$9999*Raw_Data_Daily!$AD$2:$AD$9999)/SUMIFS(Raw_Data_Daily!$D:$D, Raw_Data_Daily!$B:$B, "Control", Raw_Data_Daily!$C:$C, "A. 0"),"") -> 0 | D17: =IFERROR(SUMPRODUCT((Raw_Data_Daily!$B$2:$B$9999="Variant")*(Raw_Data_Daily!$C$2:$C$9999="A. 0")*Raw_Data_Daily!$D$2:$D$9999*Raw_Data_Daily!$AD$2:$AD$9999)/SUMIFS(Raw_Data_Daily!$D:$D, Raw_Data_Daily!$B:$B, "Variant", Raw_Data_Daily!$C:$C, "A. 0"),"") -> 0 | E17: =IFERROR((D17-C17)/ABS(C17),"") | F17: =IFERROR(SUMPRODUCT((Raw_Data_Daily!$B$2:$B$9999="Control")*(Raw_Data_Daily!$C$2:$C$9999="B. 1-9")*Raw_Data_Daily!$D$2:$D$9999*Raw_Data_Daily!$AD$2:$AD$9999)/SUMIFS(Raw_Data_Daily!$D:$D, Raw_Data_Daily!$B:$B, "Control", Raw_Data_Daily!$C:$C, "B. 1-9"),"") -> 3.9808569 | G17: =IFERROR(SUMPRODUCT((Raw_Data_Daily!$B$2:$B$9999="Variant")*(Raw_Data_Daily!$C$2:$C$9999="B. 1-9")*Raw_Data_Daily!$D$2:$D$9999*Raw_Data_Daily!$AD$2:$AD$9999)/SUMIFS(Raw_Data_Daily!$D:$D, Raw_Data_Daily!$B:$B, "Variant", Raw_Data_Daily!$C:$C, "B. 1-9"),"") -> 3.9893559 | H17: =IFERROR((G17-F17)/ABS(F17),"") -> 0.0021349547 | I17: =IFERROR(SUMPRODUCT((Raw_Data_Daily!$B$2:$B$9999="Control")*(Raw_Data_Daily!$C$2:$C$9999="C. 10-19")*Raw_Data_Daily!$D$2:$D$9999*Raw_Data_Daily!$AD$2:$AD$9999)/SUMIFS(Raw_Data_Daily!$D:$D, Raw_Data_Daily!$B:$B, "Control", Raw_Data_Daily!$C:$C, "C. 10-19"),"") -> 9.5947188 | J17: =IFERROR(SUMPRODUCT((Raw_Data_Daily!$B$2:$B$9999="Variant")*(Raw_Data_Daily!$C$2:$C$9999="C. 10-19")*Raw_Data_Daily!$D$2:$D$9999*Raw_Data_Daily!$AD$2:$AD$9999)/SUMIFS(Raw_Data_Daily!$D:$D, Raw_Data_Daily!$B:$B, "Variant", Raw_Data_Daily!$C:$C, "C. 10-19"),"") -> 9.4334283 | K17: =IFERROR((J17-I17)/ABS(I17),"") -> -0.01681034 | L17: =IFERROR(SUMPRODUCT((Raw_Data_Daily!$B$2:$B$9999="Control")*(Raw_Data_Daily!$C$2:$C$9999="D. 20-39")*Raw_Data_Daily!$D$2:$D$9999*Raw_Data_Daily!$AD$2:$AD$9999)/SUMIFS(Raw_Data_Daily!$D:$D, Raw_Data_Daily!$B:$B, "Control", Raw_Data_Daily!$C:$C, "D. 20-39"),"") -> 16.473461 | M17: =IFERROR(SUMPRODUCT((Raw_Data_Daily!$B$2:$B$9999="Variant")*(Raw_Data_Daily!$C$2:$C$9999="D. 20-39")*Raw_Data_Daily!$D$2:$D$9999*Raw_Data_Daily!$AD$2:$AD$9999)/SUMIFS(Raw_Data_Daily!$D:$D, Raw_Data_Daily!$B:$B, "Variant", Raw_Data_Daily!$C:$C, "D. 20-39"),"") -> 16.132569 | N17: =IFERROR((M17-L17)/ABS(L17),"") -> -0.020693393 | O17: =IFERROR(SUMPRODUCT((Raw_Data_Daily!$B$2:$B$9999="Control")*(Raw_Data_Daily!$C$2:$C$9999="E. 40-99")*Raw_Data_Daily!$D$2:$D$9999*Raw_Data_Daily!$AD$2:$AD$9999)/SUMIFS(Raw_Data_Daily!$D:$D, Raw_Data_Daily!$B:$B, "Control", Raw_Data_Daily!$C:$C, "E. 40-99"),"") -> 29.215168 | P17: =IFERROR(SUMPRODUCT((Raw_Data_Daily!$B$2:$B$9999="Variant")*(Raw_Data_Daily!$C$2:$C$9999="E. 40-99")*Raw_Data_Daily!$D$2:$D$9999*Raw_Data_Daily!$AD$2:$AD$9999)/SUMIFS(Raw_Data_Daily!$D:$D, Raw_Data_Daily!$B:$B, "Variant", Raw_Data_Daily!$C:$C, "E. 40-99"),"") -> 27.80775 | Q17: =IFERROR((P17-O17)/ABS(O17),"") -> -0.048174202 | R17: =IFERROR(SUMPRODUCT((Raw_Data_Daily!$B$2:$B$9999="Control")*(Raw_Data_Daily!$C$2:$C$9999="F. 100+")*Raw_Data_Daily!$D$2:$D$9999*Raw_Data_Daily!$AD$2:$AD$9999)/SUMIFS(Raw_Data_Daily!$D:$D, Raw_Data_Daily!$B:$B, "Control", Raw_Data_Daily!$C:$C, "F. 100+"),"") -> 55.636733 | S17: =IFERROR(SUMPRODUCT((Raw_Data_Daily!$B$2:$B$9999="Variant")*(Raw_Data_Daily!$C$2:$C$9999="F. 100+")*Raw_Data_Daily!$D$2:$D$9999*Raw_Data_Daily!$AD$2:$AD$9999)/SUMIFS(Raw_Data_Daily!$D:$D, Raw_Data_Daily!$B:$B, "Variant", Raw_Data_Daily!$C:$C, "F. 100+"),"") -> 50.148643 | T17: =IFERROR((S17-R17)/ABS(R17),"") -> -0.098641494
B18: P25 daily streak | C18: =IFERROR(SUMPRODUCT((Raw_Data_Daily!$B$2:$B$9999="Control")*(Raw_Data_Daily!$C$2:$C$9999="A. 0")*Raw_Data_Daily!$D$2:$D$9999*Raw_Data_Daily!$AE$2:$AE$9999)/SUMIFS(Raw_Data_Daily!$D:$D, Raw_Data_Daily!$B:$B, "Control", Raw_Data_Daily!$C:$C, "A. 0"),"") -> 0 | D18: =IFERROR(SUMPRODUCT((Raw_Data_Daily!$B$2:$B$9999="Variant")*(Raw_Data_Daily!$C$2:$C$9999="A. 0")*Raw_Data_Daily!$D$2:$D$9999*Raw_Data_Daily!$AE$2:$AE$9999)/SUMIFS(Raw_Data_Daily!$D:$D, Raw_Data_Daily!$B:$B, "Variant", Raw_Data_Daily!$C:$C, "A. 0"),"") -> 0 | E18: =IFERROR((D18-C18)/ABS(C18),"") | F18: =IFERROR(SUMPRODUCT((Raw_Data_Daily!$B$2:$B$9999="Control")*(Raw_Data_Daily!$C$2:$C$9999="B. 1-9")*Raw_Data_Daily!$D$2:$D$9999*Raw_Data_Daily!$AE$2:$AE$9999)/SUMIFS(Raw_Data_Daily!$D:$D, Raw_Data_Daily!$B:$B, "Control", Raw_Data_Daily!$C:$C, "B. 1-9"),"") -> 1.5768804 | G18: =IFERROR(SUMPRODUCT((Raw_Data_Daily!$B$2:$B$9999="Variant")*(Raw_Data_Daily!$C$2:$C$9999="B. 1-9")*Raw_Data_Daily!$D$2:$D$9999*Raw_Data_Daily!$AE$2:$AE$9999)/SUMIFS(Raw_Data_Daily!$D:$D, Raw_Data_Daily!$B:$B, "Variant", Raw_Data_Daily!$C:$C, "B. 1-9"),"") -> 1.484588 | H18: =IFERROR((G18-F18)/ABS(F18),"") -> -0.058528472 | I18: =IFERROR(SUMPRODUCT((Raw_Data_Daily!$B$2:$B$9999="Control")*(Raw_Data_Daily!$C$2:$C$9999="C. 10-19")*Raw_Data_Daily!$D$2:$D$9999*Raw_Data_Daily!$AE$2:$AE$9999)/SUMIFS(Raw_Data_Daily!$D:$D, Raw_Data_Daily!$B:$B, "Control", Raw_Data_Daily!$C:$C, "C. 10-19"),"") -> 4.0462101 | J18: =IFERROR(SUMPRODUCT((Raw_Data_Daily!$B$2:$B$9999="Variant")*(Raw_Data_Daily!$C$2:$C$9999="C. 10-19")*Raw_Data_Daily!$D$2:$D$9999*Raw_Data_Daily!$AE$2:$AE$9999)/SUMIFS(Raw_Data_Daily!$D:$D, Raw_Data_Daily!$B:$B, "Variant", Raw_Data_Daily!$C:$C, "C. 10-19"),"") -> 4.0511221 | K18: =IFERROR((J18-I18)/ABS(I18),"") -> 0.0012139773 | L18: =IFERROR(SUMPRODUCT((Raw_Data_Daily!$B$2:$B$9999="Control")*(Raw_Data_Daily!$C$2:$C$9999="D. 20-39")*Raw_Data_Daily!$D$2:$D$9999*Raw_Data_Daily!$AE$2:$AE$9999)/SUMIFS(Raw_Data_Daily!$D:$D, Raw_Data_Daily!$B:$B, "Control", Raw_Data_Daily!$C:$C, "D. 20-39"),"") -> 6.9561824 | M18: =IFERROR(SUMPRODUCT((Raw_Data_Daily!$B$2:$B$9999="Variant")*(Raw_Data_Daily!$C$2:$C$9999="D. 20-39")*Raw_Data_Daily!$D$2:$D$9999*Raw_Data_Daily!$AE$2:$AE$9999)/SUMIFS(Raw_Data_Daily!$D:$D, Raw_Data_Daily!$B:$B, "Variant", Raw_Data_Daily!$C:$C, "D. 20-39"),"") -> 6.8269193 | N18: =IFERROR((M18-L18)/ABS(L18),"") -> -0.018582465 | O18: =IFERROR(SUMPRODUCT((Raw_Data_Daily!$B$2:$B$9999="Control")*(Raw_Data_Daily!$C$2:$C$9999="E. 40-99")*Raw_Data_Daily!$D$2:$D$9999*Raw_Data_Daily!$AE$2:$AE$9999)/SUMIFS(Raw_Data_Daily!$D:$D, Raw_Data_Daily!$B:$B, "Control", Raw_Data_Daily!$C:$C, "E. 40-99"),"") -> 11.049549 | P18: =IFERROR(SUMPRODUCT((Raw_Data_Daily!$B$2:$B$9999="Variant")*(Raw_Data_Daily!$C$2:$C$9999="E. 40-99")*Raw_Data_Daily!$D$2:$D$9999*Raw_Data_Daily!$AE$2:$AE$9999)/SUMIFS(Raw_Data_Daily!$D:$D, Raw_Data_Daily!$B:$B, "Variant", Raw_Data_Daily!$C:$C, "E. 40-99"),"") -> 10.486682 | Q18: =IFERROR((P18-O18)/ABS(O18),"") -> -0.050940314 | R18: =IFERROR(SUMPRODUCT((Raw_Data_Daily!$B$2:$B$9999="Control")*(Raw_Data_Daily!$C$2:$C$9999="F. 100+")*Raw_Data_Daily!$D$2:$D$9999*Raw_Data_Daily!$AE$2:$AE$9999)/SUMIFS(Raw_Data_Daily!$D:$D, Raw_Data_Daily!$B:$B, "Control", Raw_Data_Daily!$C:$C, "F. 100+"),"") -> 20.697582 | S18: =IFERROR(SUMPRODUCT((Raw_Data_Daily!$B$2:$B$9999="Variant")*(Raw_Data_Daily!$C$2:$C$9999="F. 100+")*Raw_Data_Daily!$D$2:$D$9999*Raw_Data_Daily!$AE$2:$AE$9999)/SUMIFS(Raw_Data_Daily!$D:$D, Raw_Data_Daily!$B:$B, "Variant", Raw_Data_Daily!$C:$C, "F. 100+"),"") -> 19.571587 | T18: =IFERROR((S18-R18)/ABS(R18),"") -> -0.054402263
B19: P50 daily streak | C19: =IFERROR(SUMPRODUCT((Raw_Data_Daily!$B$2:$B$9999="Control")*(Raw_Data_Daily!$C$2:$C$9999="A. 0")*Raw_Data_Daily!$D$2:$D$9999*Raw_Data_Daily!$AF$2:$AF$9999)/SUMIFS(Raw_Data_Daily!$D:$D, Raw_Data_Daily!$B:$B, "Control", Raw_Data_Daily!$C:$C, "A. 0"),"") -> 0 | D19: =IFERROR(SUMPRODUCT((Raw_Data_Daily!$B$2:$B$9999="Variant")*(Raw_Data_Daily!$C$2:$C$9999="A. 0")*Raw_Data_Daily!$D$2:$D$9999*Raw_Data_Daily!$AF$2:$AF$9999)/SUMIFS(Raw_Data_Daily!$D:$D, Raw_Data_Daily!$B:$B, "Variant", Raw_Data_Daily!$C:$C, "A. 0"),"") -> 0 | E19: =IFERROR((D19-C19)/ABS(C19),"") | F19: =IFERROR(SUMPRODUCT((Raw_Data_Daily!$B$2:$B$9999="Control")*(Raw_Data_Daily!$C$2:$C$9999="B. 1-9")*Raw_Data_Daily!$D$2:$D$9999*Raw_Data_Daily!$AF$2:$AF$9999)/SUMIFS(Raw_Data_Daily!$D:$D, Raw_Data_Daily!$B:$B, "Control", Raw_Data_Daily!$C:$C, "B. 1-9"),"") -> 3 | G19: =IFERROR(SUMPRODUCT((Raw_Data_Daily!$B$2:$B$9999="Variant")*(Raw_Data_Daily!$C$2:$C$9999="B. 1-9")*Raw_Data_Daily!$D$2:$D$9999*Raw_Data_Daily!$AF$2:$AF$9999)/SUMIFS(Raw_Data_Daily!$D:$D, Raw_Data_Daily!$B:$B, "Variant", Raw_Data_Daily!$C:$C, "B. 1-9"),"") -> 3 | H19: =IFERROR((G19-F19)/ABS(F19),"") -> 0 | I19: =IFERROR(SUMPRODUCT((Raw_Data_Daily!$B$2:$B$9999="Control")*(Raw_Data_Daily!$C$2:$C$9999="C. 10-19")*Raw_Data_Daily!$D$2:$D$9999*Raw_Data_Daily!$AF$2:$AF$9999)/SUMIFS(Raw_Data_Daily!$D:$D, Raw_Data_Daily!$B:$B, "Control", Raw_Data_Daily!$C:$C, "C. 10-19"),"") -> 8.4249916 | J19: =IFERROR(SUMPRODUCT((Raw_Data_Daily!$B$2:$B$9999="Variant")*(Raw_Data_Daily!$C$2:$C$9999="C. 10-19")*Raw_Data_Daily!$D$2:$D$9999*Raw_Data_Daily!$AF$2:$AF$9999)/SUMIFS(Raw_Data_Daily!$D:$D, Raw_Data_Daily!$B:$B, "Variant", Raw_Data_Daily!$C:$C, "C. 10-19"),"") -> 8.1546289 | K19: =IFERROR((J19-I19)/ABS(I19),"") -> -0.032090565 | L19: =IFERROR(SUMPRODUCT((Raw_Data_Daily!$B$2:$B$9999="Control")*(Raw_Data_Daily!$C$2:$C$9999="D. 20-39")*Raw_Data_Daily!$D$2:$D$9999*Raw_Data_Daily!$AF$2:$AF$9999)/SUMIFS(Raw_Data_Daily!$D:$D, Raw_Data_Daily!$B:$B, "Control", Raw_Data_Daily!$C:$C, "D. 20-39"),"") -> 13.144947 | M19: =IFERROR(SUMPRODUCT((Raw_Data_Daily!$B$2:$B$9999="Variant")*(Raw_Data_Daily!$C$2:$C$9999="D. 20-39")*Raw_Data_Daily!$D$2:$D$9999*Raw_Data_Daily!$AF$2:$AF$9999)/SUMIFS(Raw_Data_Daily!$D:$D, Raw_Data_Daily!$B:$B, "Variant", Raw_Data_Daily!$C:$C, "D. 20-39"),"") -> 12.67276 | N19: =IFERROR((M19-L19)/ABS(L19),"") -> -0.035921597 | O19: =IFERROR(SUMPRODUCT((Raw_Data_Daily!$B$2:$B$9999="Control")*(Raw_Data_Daily!$C$2:$C$9999="E. 40-99")*Raw_Data_Daily!$D$2:$D$9999*Raw_Data_Daily!$AF$2:$AF$9999)/SUMIFS(Raw_Data_Daily!$D:$D, Raw_Data_Daily!$B:$B, "Control", Raw_Data_Daily!$C:$C, "E. 40-99"),"") -> 21.475575 | P19: =IFERROR(SUMPRODUCT((Raw_Data_Daily!$B$2:$B$9999="Variant")*(Raw_Data_Daily!$C$2:$C$9999="E. 40-99")*Raw_Data_Daily!$D$2:$D$9999*Raw_Data_Daily!$AF$2:$AF$9999)/SUMIFS(Raw_Data_Daily!$D:$D, Raw_Data_Daily!$B:$B, "Variant", Raw_Data_Daily!$C:$C, "E. 40-99"),"") -> 20.145909 | Q19: =IFERROR((P19-O19)/ABS(O19),"") -> -0.061915257 | R19: =IFERROR(SUMPRODUCT((Raw_Data_Daily!$B$2:$B$9999="Control")*(Raw_Data_Daily!$C$2:$C$9999="F. 100+")*Raw_Data_Daily!$D$2:$D$9999*Raw_Data_Daily!$AF$2:$AF$9999)/SUMIFS(Raw_Data_Daily!$D:$D, Raw_Data_Daily!$B:$B, "Control", Raw_Data_Daily!$C:$C, "F. 100+"),"") -> 39.234473 | S19: =IFERROR(SUMPRODUCT((Raw_Data_Daily!$B$2:$B$9999="Variant")*(Raw_Data_Daily!$C$2:$C$9999="F. 100+")*Raw_Data_Daily!$D$2:$D$9999*Raw_Data_Daily!$AF$2:$AF$9999)/SUMIFS(Raw_Data_Daily!$D:$D, Raw_Data_Daily!$B:$B, "Variant", Raw_Data_Daily!$C:$C, "F. 100+"),"") -> 35.583232 | T19: =IFERROR((S19-R19)/ABS(R19),"") -> -0.093062064
B20: P75 daily streak | C20: =IFERROR(SUMPRODUCT((Raw_Data_Daily!$B$2:$B$9999="Control")*(Raw_Data_Daily!$C$2:$C$9999="A. 0")*Raw_Data_Daily!$D$2:$D$9999*Raw_Data_Daily!$AG$2:$AG$9999)/SUMIFS(Raw_Data_Daily!$D:$D, Raw_Data_Daily!$B:$B, "Control", Raw_Data_Daily!$C:$C, "A. 0"),"") -> 0 | D20: =IFERROR(SUMPRODUCT((Raw_Data_Daily!$B$2:$B$9999="Variant")*(Raw_Data_Daily!$C$2:$C$9999="A. 0")*Raw_Data_Daily!$D$2:$D$9999*Raw_Data_Daily!$AG$2:$AG$9999)/SUMIFS(Raw_Data_Daily!$D:$D, Raw_Data_Daily!$B:$B, "Variant", Raw_Data_Daily!$C:$C, "A. 0"),"") -> 0 | E20: =IFERROR((D20-C20)/ABS(C20),"") | F20: =IFERROR(SUMPRODUCT((Raw_Data_Daily!$B$2:$B$9999="Control")*(Raw_Data_Daily!$C$2:$C$9999="B. 1-9")*Raw_Data_Daily!$D$2:$D$9999*Raw_Data_Daily!$AG$2:$AG$9999)/SUMIFS(Raw_Data_Daily!$D:$D, Raw_Data_Daily!$B:$B, "Control", Raw_Data_Daily!$C:$C, "B. 1-9"),"") -> 5.1450765 | G20: =IFERROR(SUMPRODUCT((Raw_Data_Daily!$B$2:$B$9999="Variant")*(Raw_Data_Daily!$C$2:$C$9999="B. 1-9")*Raw_Data_Daily!$D$2:$D$9999*Raw_Data_Daily!$AG$2:$AG$9999)/SUMIFS(Raw_Data_Daily!$D:$D, Raw_Data_Daily!$B:$B, "Variant", Raw_Data_Daily!$C:$C, "B. 1-9"),"") -> 5.2844576 | H20: =IFERROR((G20-F20)/ABS(F20),"") -> 0.027090198 | I20: =IFERROR(SUMPRODUCT((Raw_Data_Daily!$B$2:$B$9999="Control")*(Raw_Data_Daily!$C$2:$C$9999="C. 10-19")*Raw_Data_Daily!$D$2:$D$9999*Raw_Data_Daily!$AG$2:$AG$9999)/SUMIFS(Raw_Data_Daily!$D:$D, Raw_Data_Daily!$B:$B, "Control", Raw_Data_Daily!$C:$C, "C. 10-19"),"") -> 13 | J20: =IFERROR(SUMPRODUCT((Raw_Data_Daily!$B$2:$B$9999="Variant")*(Raw_Data_Daily!$C$2:$C$9999="C. 10-19")*Raw_Data_Daily!$D$2:$D$9999*Raw_Data_Daily!$AG$2:$AG$9999)/SUMIFS(Raw_Data_Daily!$D:$D, Raw_Data_Daily!$B:$B, "Variant", Raw_Data_Daily!$C:$C, "C. 10-19"),"") -> 12.965301 | K20: =IFERROR((J20-I20)/ABS(I20),"") -> -0.0026691575 | L20: =IFERROR(SUMPRODUCT((Raw_Data_Daily!$B$2:$B$9999="Control")*(Raw_Data_Daily!$C$2:$C$9999="D. 20-39")*Raw_Data_Daily!$D$2:$D$9999*Raw_Data_Daily!$AG$2:$AG$9999)/SUMIFS(Raw_Data_Daily!$D:$D, Raw_Data_Daily!$B:$B, "Control", Raw_Data_Daily!$C:$C, "D. 20-39"),"") -> 23.048834 | M20: =IFERROR(SUMPRODUCT((Raw_Data_Daily!$B$2:$B$9999="Variant")*(Raw_Data_Daily!$C$2:$C$9999="D. 20-39")*Raw_Data_Daily!$D$2:$D$9999*Raw_Data_Daily!$AG$2:$AG$9999)/SUMIFS(Raw_Data_Daily!$D:$D, Raw_Data_Daily!$B:$B, "Variant", Raw_Data_Daily!$C:$C, "D. 20-39"),"") -> 22.387085 | N20: =IFERROR((M20-L20)/ABS(L20),"") -> -0.028710738 | O20: =IFERROR(SUMPRODUCT((Raw_Data_Daily!$B$2:$B$9999="Control")*(Raw_Data_Daily!$C$2:$C$9999="E. 40-99")*Raw_Data_Daily!$D$2:$D$9999*Raw_Data_Daily!$AG$2:$AG$9999)/SUMIFS(Raw_Data_Daily!$D:$D, Raw_Data_Daily!$B:$B, "Control", Raw_Data_Daily!$C:$C, "E. 40-99"),"") -> 40.58534 | P20: =IFERROR(SUMPRODUCT((Raw_Data_Daily!$B$2:$B$9999="Variant")*(Raw_Data_Daily!$C$2:$C$9999="E. 40-99")*Raw_Data_Daily!$D$2:$D$9999*Raw_Data_Daily!$AG$2:$AG$9999)/SUMIFS(Raw_Data_Daily!$D:$D, Raw_Data_Daily!$B:$B, "Variant", Raw_Data_Daily!$C:$C, "E. 40-99"),"") -> 38.59235 | Q20: =IFERROR((P20-O20)/ABS(O20),"") -> -0.049106159 | R20: =IFERROR(SUMPRODUCT((Raw_Data_Daily!$B$2:$B$9999="Control")*(Raw_Data_Daily!$C$2:$C$9999="F. 100+")*Raw_Data_Daily!$D$2:$D$9999*Raw_Data_Daily!$AG$2:$AG$9999)/SUMIFS(Raw_Data_Daily!$D:$D, Raw_Data_Daily!$B:$B, "Control", Raw_Data_Daily!$C:$C, "F. 100+"),"") -> 74.597749 | S20: =IFERROR(SUMPRODUCT((Raw_Data_Daily!$B$2:$B$9999="Variant")*(Raw_Data_Daily!$C$2:$C$9999="F. 100+")*Raw_Data_Daily!$D$2:$D$9999*Raw_Data_Daily!$AG$2:$AG$9999)/SUMIFS(Raw_Data_Daily!$D:$D, Raw_Data_Daily!$B:$B, "Variant", Raw_Data_Daily!$C:$C, "F. 100+"),"") -> 64.225907 | T20: =IFERROR((S20-R20)/ABS(R20),"") -> -0.13903694
B21: P90 daily streak | C21: =IFERROR(SUMPRODUCT((Raw_Data_Daily!$B$2:$B$9999="Control")*(Raw_Data_Daily!$C$2:$C$9999="A. 0")*Raw_Data_Daily!$D$2:$D$9999*Raw_Data_Daily!$AH$2:$AH$9999)/SUMIFS(Raw_Data_Daily!$D:$D, Raw_Data_Daily!$B:$B, "Control", Raw_Data_Daily!$C:$C, "A. 0"),"") -> 0 | D21: =IFERROR(SUMPRODUCT((Raw_Data_Daily!$B$2:$B$9999="Variant")*(Raw_Data_Daily!$C$2:$C$9999="A. 0")*Raw_Data_Daily!$D$2:$D$9999*Raw_Data_Daily!$AH$2:$AH$9999)/SUMIFS(Raw_Data_Daily!$D:$D, Raw_Data_Daily!$B:$B, "Variant", Raw_Data_Daily!$C:$C, "A. 0"),"") -> 0 | E21: =IFERROR((D21-C21)/ABS(C21),"") | F21: =IFERROR(SUMPRODUCT((Raw_Data_Daily!$B$2:$B$9999="Control")*(Raw_Data_Daily!$C$2:$C$9999="B. 1-9")*Raw_Data_Daily!$D$2:$D$9999*Raw_Data_Daily!$AH$2:$AH$9999)/SUMIFS(Raw_Data_Daily!$D:$D, Raw_Data_Daily!$B:$B, "Control", Raw_Data_Daily!$C:$C, "B. 1-9"),"") -> 8.1395957 | G21: =IFERROR(SUMPRODUCT((Raw_Data_Daily!$B$2:$B$9999="Variant")*(Raw_Data_Daily!$C$2:$C$9999="B. 1-9")*Raw_Data_Daily!$D$2:$D$9999*Raw_Data_Daily!$AH$2:$AH$9999)/SUMIFS(Raw_Data_Daily!$D:$D, Raw_Data_Daily!$B:$B, "Variant", Raw_Data_Daily!$C:$C, "B. 1-9"),"") -> 8.1882809 | H21: =IFERROR((G21-F21)/ABS(F21),"") -> 0.0059812877 | I21: =IFERROR(SUMPRODUCT((Raw_Data_Daily!$B$2:$B$9999="Control")*(Raw_Data_Daily!$C$2:$C$9999="C. 10-19")*Raw_Data_Daily!$D$2:$D$9999*Raw_Data_Daily!$AH$2:$AH$9999)/SUMIFS(Raw_Data_Daily!$D:$D, Raw_Data_Daily!$B:$B, "Control", Raw_Data_Daily!$C:$C, "C. 10-19"),"") -> 18.519107 | J21: =IFERROR(SUMPRODUCT((Raw_Data_Daily!$B$2:$B$9999="Variant")*(Raw_Data_Daily!$C$2:$C$9999="C. 10-19")*Raw_Data_Daily!$D$2:$D$9999*Raw_Data_Daily!$AH$2:$AH$9999)/SUMIFS(Raw_Data_Daily!$D:$D, Raw_Data_Daily!$B:$B, "Variant", Raw_Data_Daily!$C:$C, "C. 10-19"),"") -> 18.301067 | K21: =IFERROR((J21-I21)/ABS(I21),"") -> -0.011773824 | L21: =IFERROR(SUMPRODUCT((Raw_Data_Daily!$B$2:$B$9999="Control")*(Raw_Data_Daily!$C$2:$C$9999="D. 20-39")*Raw_Data_Daily!$D$2:$D$9999*Raw_Data_Daily!$AH$2:$AH$9999)/SUMIFS(Raw_Data_Daily!$D:$D, Raw_Data_Daily!$B:$B, "Control", Raw_Data_Daily!$C:$C, "D. 20-39"),"") -> 33.229625 | M21: =IFERROR(SUMPRODUCT((Raw_Data_Daily!$B$2:$B$9999="Variant")*(Raw_Data_Daily!$C$2:$C$9999="D. 20-39")*Raw_Data_Daily!$D$2:$D$9999*Raw_Data_Daily!$AH$2:$AH$9999)/SUMIFS(Raw_Data_Daily!$D:$D, Raw_Data_Daily!$B:$B, "Variant", Raw_Data_Daily!$C:$C, "D. 20-39"),"") -> 32.572536 | N21: =IFERROR((M21-L21)/ABS(L21),"") -> -0.019774169 | O21: =IFERROR(SUMPRODUCT((Raw_Data_Daily!$B$2:$B$9999="Control")*(Raw_Data_Daily!$C$2:$C$9999="E. 40-99")*Raw_Data_Daily!$D$2:$D$9999*Raw_Data_Daily!$AH$2:$AH$9999)/SUMIFS(Raw_Data_Daily!$D:$D, Raw_Data_Daily!$B:$B, "Control", Raw_Data_Daily!$C:$C, "E. 40-99"),"") -> 61.757495 | P21: =IFERROR(SUMPRODUCT((Raw_Data_Daily!$B$2:$B$9999="Variant")*(Raw_Data_Daily!$C$2:$C$9999="E. 40-99")*Raw_Data_Daily!$D$2:$D$9999*Raw_Data_Daily!$AH$2:$AH$9999)/SUMIFS(Raw_Data_Daily!$D:$D, Raw_Data_Daily!$B:$B, "Variant", Raw_Data_Daily!$C:$C, "E. 40-99"),"") -> 58.506691 | Q21: =IFERROR((P21-O21)/ABS(O21),"") -> -0.052638208 | R21: =IFERROR(SUMPRODUCT((Raw_Data_Daily!$B$2:$B$9999="Control")*(Raw_Data_Daily!$C$2:$C$9999="F. 100+")*Raw_Data_Daily!$D$2:$D$9999*Raw_Data_Daily!$AH$2:$AH$9999)/SUMIFS(Raw_Data_Daily!$D:$D, Raw_Data_Daily!$B:$B, "Control", Raw_Data_Daily!$C:$C, "F. 100+"),"") -> 123.24646 | S21: =IFERROR(SUMPRODUCT((Raw_Data_Daily!$B$2:$B$9999="Variant")*(Raw_Data_Daily!$C$2:$C$9999="F. 100+")*Raw_Data_Daily!$D$2:$D$9999*Raw_Data_Daily!$AH$2:$AH$9999)/SUMIFS(Raw_Data_Daily!$D:$D, Raw_Data_Daily!$B:$B, "Variant", Raw_Data_Daily!$C:$C, "F. 100+"),"") -> 110.28136 | T21: =IFERROR((S21-R21)/ABS(R21),"") -> -0.10519653
B22: P99 daily streak | C22: =IFERROR(SUMPRODUCT((Raw_Data_Daily!$B$2:$B$9999="Control")*(Raw_Data_Daily!$C$2:$C$9999="A. 0")*Raw_Data_Daily!$D$2:$D$9999*Raw_Data_Daily!$BC$2:$BC$9999)/SUMIFS(Raw_Data_Daily!$D:$D, Raw_Data_Daily!$B:$B, "Control", Raw_Data_Daily!$C:$C, "A. 0"),"") -> 0 | D22: =IFERROR(SUMPRODUCT((Raw_Data_Daily!$B$2:$B$9999="Variant")*(Raw_Data_Daily!$C$2:$C$9999="A. 0")*Raw_Data_Daily!$D$2:$D$9999*Raw_Data_Daily!$BC$2:$BC$9999)/SUMIFS(Raw_Data_Daily!$D:$D, Raw_Data_Daily!$B:$B, "Variant", Raw_Data_Daily!$C:$C, "A. 0"),"") -> 0 | E22: =IFERROR((D22-C22)/ABS(C22),"") | F22: =IFERROR(SUMPRODUCT((Raw_Data_Daily!$B$2:$B$9999="Control")*(Raw_Data_Daily!$C$2:$C$9999="B. 1-9")*Raw_Data_Daily!$D$2:$D$9999*Raw_Data_Daily!$BC$2:$BC$9999)/SUMIFS(Raw_Data_Daily!$D:$D, Raw_Data_Daily!$B:$B, "Control", Raw_Data_Daily!$C:$C, "B. 1-9"),"") -> 16.31547 | G22: =IFERROR(SUMPRODUCT((Raw_Data_Daily!$B$2:$B$9999="Variant")*(Raw_Data_Daily!$C$2:$C$9999="B. 1-9")*Raw_Data_Daily!$D$2:$D$9999*Raw_Data_Daily!$BC$2:$BC$9999)/SUMIFS(Raw_Data_Daily!$D:$D, Raw_Data_Daily!$B:$B, "Variant", Raw_Data_Daily!$C:$C, "B. 1-9"),"") -> 16.329713 | H22: =IFERROR((G22-F22)/ABS(F22),"") -> 0.0008729574 | I22: =IFERROR(SUMPRODUCT((Raw_Data_Daily!$B$2:$B$9999="Control")*(Raw_Data_Daily!$C$2:$C$9999="C. 10-19")*Raw_Data_Daily!$D$2:$D$9999*Raw_Data_Daily!$BC$2:$BC$9999)/SUMIFS(Raw_Data_Daily!$D:$D, Raw_Data_Daily!$B:$B, "Control", Raw_Data_Daily!$C:$C, "C. 10-19"),"") -> 34.265038 | J22: =IFERROR(SUMPRODUCT((Raw_Data_Daily!$B$2:$B$9999="Variant")*(Raw_Data_Daily!$C$2:$C$9999="C. 10-19")*Raw_Data_Daily!$D$2:$D$9999*Raw_Data_Daily!$BC$2:$BC$9999)/SUMIFS(Raw_Data_Daily!$D:$D, Raw_Data_Daily!$B:$B, "Variant", Raw_Data_Daily!$C:$C, "C. 10-19"),"") -> 33.537401 | K22: =IFERROR((J22-I22)/ABS(I22),"") -> -0.021235565 | L22: =IFERROR(SUMPRODUCT((Raw_Data_Daily!$B$2:$B$9999="Control")*(Raw_Data_Daily!$C$2:$C$9999="D. 20-39")*Raw_Data_Daily!$D$2:$D$9999*Raw_Data_Daily!$BC$2:$BC$9999)/SUMIFS(Raw_Data_Daily!$D:$D, Raw_Data_Daily!$B:$B, "Control", Raw_Data_Daily!$C:$C, "D. 20-39"),"") -> 61.429925 | M22: =IFERROR(SUMPRODUCT((Raw_Data_Daily!$B$2:$B$9999="Variant")*(Raw_Data_Daily!$C$2:$C$9999="D. 20-39")*Raw_Data_Daily!$D$2:$D$9999*Raw_Data_Daily!$BC$2:$BC$9999)/SUMIFS(Raw_Data_Daily!$D:$D, Raw_Data_Daily!$B:$B, "Variant", Raw_Data_Daily!$C:$C, "D. 20-39"),"") -> 59.984363 | N22: =IFERROR((M22-L22)/ABS(L22),"") -> -0.023531885 | O22: =IFERROR(SUMPRODUCT((Raw_Data_Daily!$B$2:$B$9999="Control")*(Raw_Data_Daily!$C$2:$C$9999="E. 40-99")*Raw_Data_Daily!$D$2:$D$9999*Raw_Data_Daily!$BC$2:$BC$9999)/SUMIFS(Raw_Data_Daily!$D:$D, Raw_Data_Daily!$B:$B, "Control", Raw_Data_Daily!$C:$C, "E. 40-99"),"") -> 121.59505 | P22: =IFERROR(SUMPRODUCT((Raw_Data_Daily!$B$2:$B$9999="Variant")*(Raw_Data_Daily!$C$2:$C$9999="E. 40-99")*Raw_Data_Daily!$D$2:$D$9999*Raw_Data_Daily!$BC$2:$BC$9999)/SUMIFS(Raw_Data_Daily!$D:$D, Raw_Data_Daily!$B:$B, "Variant", Raw_Data_Daily!$C:$C, "E. 40-99"),"") -> 117.50336 | Q22: =IFERROR((P22-O22)/ABS(O22),"") -> -0.033650122 | R22: =IFERROR(SUMPRODUCT((Raw_Data_Daily!$B$2:$B$9999="Control")*(Raw_Data_Daily!$C$2:$C$9999="F. 100+")*Raw_Data_Daily!$D$2:$D$9999*Raw_Data_Daily!$BC$2:$BC$9999)/SUMIFS(Raw_Data_Daily!$D:$D, Raw_Data_Daily!$B:$B, "Control", Raw_Data_Daily!$C:$C, "F. 100+"),"") -> 239.85202 | S22: =IFERROR(SUMPRODUCT((Raw_Data_Daily!$B$2:$B$9999="Variant")*(Raw_Data_Daily!$C$2:$C$9999="F. 100+")*Raw_Data_Daily!$D$2:$D$9999*Raw_Data_Daily!$BC$2:$BC$9999)/SUMIFS(Raw_Data_Daily!$D:$D, Raw_Data_Daily!$B:$B, "Variant", Raw_Data_Daily!$C:$C, "F. 100+"),"") -> 222.55229 | T22: =IFERROR((S22-R22)/ABS(R22),"") -> -0.072126686
A23: Difficulty
B24: Pass rate | C24: =IFERROR(SUMPRODUCT((Raw_Data_Daily!$B$2:$B$9999="Control")*(Raw_Data_Daily!$C$2:$C$9999="A. 0")*Raw_Data_Daily!$D$2:$D$9999*Raw_Data_Daily!$M$2:$M$9999)/SUMIFS(Raw_Data_Daily!$D:$D, Raw_Data_Daily!$B:$B, "Control", Raw_Data_Daily!$C:$C, "A. 0"),"") -> 0.60880537 | D24: =IFERROR(SUMPRODUCT((Raw_Data_Daily!$B$2:$B$9999="Variant")*(Raw_Data_Daily!$C$2:$C$9999="A. 0")*Raw_Data_Daily!$D$2:$D$9999*Raw_Data_Daily!$M$2:$M$9999)/SUMIFS(Raw_Data_Daily!$D:$D, Raw_Data_Daily!$B:$B, "Variant", Raw_Data_Daily!$C:$C, "A. 0"),"") -> 0.61427066 | E24: =IFERROR((D24-C24)/ABS(C24),"") -> 0.0089770772 | F24: =IFERROR(SUMPRODUCT((Raw_Data_Daily!$B$2:$B$9999="Control")*(Raw_Data_Daily!$C$2:$C$9999="B. 1-9")*Raw_Data_Daily!$D$2:$D$9999*Raw_Data_Daily!$M$2:$M$9999)/SUMIFS(Raw_Data_Daily!$D:$D, Raw_Data_Daily!$B:$B, "Control", Raw_Data_Daily!$C:$C, "B. 1-9"),"") -> 0.47578812 | G24: =IFERROR(SUMPRODUCT((Raw_Data_Daily!$B$2:$B$9999="Variant")*(Raw_Data_Daily!$C$2:$C$9999="B. 1-9")*Raw_Data_Daily!$D$2:$D$9999*Raw_Data_Daily!$M$2:$M$9999)/SUMIFS(Raw_Data_Daily!$D:$D, Raw_Data_Daily!$B:$B, "Variant", Raw_Data_Daily!$C:$C, "B. 1-9"),"") -> 0.47865521 | H24: =IFERROR((G24-F24)/ABS(F24),"") -> 0.0060259869 | I24: =IFERROR(SUMPRODUCT((Raw_Data_Daily!$B$2:$B$9999="Control")*(Raw_Data_Daily!$C$2:$C$9999="C. 10-19")*Raw_Data_Daily!$D$2:$D$9999*Raw_Data_Daily!$M$2:$M$9999)/SUMIFS(Raw_Data_Daily!$D:$D, Raw_Data_Daily!$B:$B, "Control", Raw_Data_Daily!$C:$C, "C. 10-19"),"") -> 0.61898995 | J24: =IFERROR(SUMPRODUCT((Raw_Data_Daily!$B$2:$B$9999="Variant")*(Raw_Data_Daily!$C$2:$C$9999="C. 10-19")*Raw_Data_Daily!$D$2:$D$9999*Raw_Data_Daily!$M$2:$M$9999)/SUMIFS(Raw_Data_Daily!$D:$D, Raw_Data_Daily!$B:$B, "Variant", Raw_Data_Daily!$C:$C, "C. 10-19"),"") -> 0.59801757 | K24: =IFERROR((J24-I24)/ABS(I24),"") -> -0.033881624 | L24: =IFERROR(SUMPRODUCT((Raw_Data_Daily!$B$2:$B$9999="Control")*(Raw_Data_Daily!$C$2:$C$9999="D. 20-39")*Raw_Data_Daily!$D$2:$D$9999*Raw_Data_Daily!$M$2:$M$9999)/SUMIFS(Raw_Data_Daily!$D:$D, Raw_Data_Daily!$B:$B, "Control", Raw_Data_Daily!$C:$C, "D. 20-39"),"") -> 0.71732456 | M24: =IFERROR(SUMPRODUCT((Raw_Data_Daily!$B$2:$B$9999="Variant")*(Raw_Data_Daily!$C$2:$C$9999="D. 20-39")*Raw_Data_Daily!$D$2:$D$9999*Raw_Data_Daily!$M$2:$M$9999)/SUMIFS(Raw_Data_Daily!$D:$D, Raw_Data_Daily!$B:$B, "Variant", Raw_Data_Daily!$C:$C, "D. 20-39"),"") -> 0.69850235 | N24: =IFERROR((M24-L24)/ABS(L24),"") -> -0.026239471 | O24: =IFERROR(SUMPRODUCT((Raw_Data_Daily!$B$2:$B$9999="Control")*(Raw_Data_Daily!$C$2:$C$9999="E. 40-99")*Raw_Data_Daily!$D$2:$D$9999*Raw_Data_Daily!$M$2:$M$9999)/SUMIFS(Raw_Data_Daily!$D:$D, Raw_Data_Daily!$B:$B, "Control", Raw_Data_Daily!$C:$C, "E. 40-99"),"") -> 0.74981114 | P24: =IFERROR(SUMPRODUCT((Raw_Data_Daily!$B$2:$B$9999="Variant")*(Raw_Data_Daily!$C$2:$C$9999="E. 40-99")*Raw_Data_Daily!$D$2:$D$9999*Raw_Data_Daily!$M$2:$M$9999)/SUMIFS(Raw_Data_Daily!$D:$D, Raw_Data_Daily!$B:$B, "Variant", Raw_Data_Daily!$C:$C, "E. 40-99"),"") -> 0.73269794 | Q24: =IFERROR((P24-O24)/ABS(O24),"") -> -0.022823346 | R24: =IFERROR(SUMPRODUCT((Raw_Data_Daily!$B$2:$B$9999="Control")*(Raw_Data_Daily!$C$2:$C$9999="F. 100+")*Raw_Data_Daily!$D$2:$D$9999*Raw_Data_Daily!$M$2:$M$9999)/SUMIFS(Raw_Data_Daily!$D:$D, Raw_Data_Daily!$B:$B, "Control", Raw_Data_Daily!$C:$C, "F. 100+"),"") -> 0.76889658 | S24: =IFERROR(SUMPRODUCT((Raw_Data_Daily!$B$2:$B$9999="Variant")*(Raw_Data_Daily!$C$2:$C$9999="F. 100+")*Raw_Data_Daily!$D$2:$D$9999*Raw_Data_Daily!$M$2:$M$9999)/SUMIFS(Raw_Data_Daily!$D:$D, Raw_Data_Daily!$B:$B, "Variant", Raw_Data_Daily!$C:$C, "F. 100+"),"") -> 0.74292216 | T24: =IFERROR((S24-R24)/ABS(R24),"") -> -0.033781427
B25: OOM rate | C25: =IFERROR(SUMPRODUCT((Raw_Data_Daily!$B$2:$B$9999="Control")*(Raw_Data_Daily!$C$2:$C$9999="A. 0")*Raw_Data_Daily!$D$2:$D$9999*Raw_Data_Daily!$N$2:$N$9999)/SUMIFS(Raw_Data_Daily!$D:$D, Raw_Data_Daily!$B:$B, "Control", Raw_Data_Daily!$C:$C, "A. 0"),"") -> 0.49128375 | D25: =IFERROR(SUMPRODUCT((Raw_Data_Daily!$B$2:$B$9999="Variant")*(Raw_Data_Daily!$C$2:$C$9999="A. 0")*Raw_Data_Daily!$D$2:$D$9999*Raw_Data_Daily!$N$2:$N$9999)/SUMIFS(Raw_Data_Daily!$D:$D, Raw_Data_Daily!$B:$B, "Variant", Raw_Data_Daily!$C:$C, "A. 0"),"") -> 0.49165454 | E25: =IFERROR((D25-C25)/ABS(C25),"") -> 0.00075473262 | F25: =IFERROR(SUMPRODUCT((Raw_Data_Daily!$B$2:$B$9999="Control")*(Raw_Data_Daily!$C$2:$C$9999="B. 1-9")*Raw_Data_Daily!$D$2:$D$9999*Raw_Data_Daily!$N$2:$N$9999)/SUMIFS(Raw_Data_Daily!$D:$D, Raw_Data_Daily!$B:$B, "Control", Raw_Data_Daily!$C:$C, "B. 1-9"),"") -> 0.6313484 | G25: =IFERROR(SUMPRODUCT((Raw_Data_Daily!$B$2:$B$9999="Variant")*(Raw_Data_Daily!$C$2:$C$9999="B. 1-9")*Raw_Data_Daily!$D$2:$D$9999*Raw_Data_Daily!$N$2:$N$9999)/SUMIFS(Raw_Data_Daily!$D:$D, Raw_Data_Daily!$B:$B, "Variant", Raw_Data_Daily!$C:$C, "B. 1-9"),"") -> 0.62456567 | H25: =IFERROR((G25-F25)/ABS(F25),"") -> -0.010743252 | I25: =IFERROR(SUMPRODUCT((Raw_Data_Daily!$B$2:$B$9999="Control")*(Raw_Data_Daily!$C$2:$C$9999="C. 10-19")*Raw_Data_Daily!$D$2:$D$9999*Raw_Data_Daily!$N$2:$N$9999)/SUMIFS(Raw_Data_Daily!$D:$D, Raw_Data_Daily!$B:$B, "Control", Raw_Data_Daily!$C:$C, "C. 10-19"),"") -> 0.50434497 | J25: =IFERROR(SUMPRODUCT((Raw_Data_Daily!$B$2:$B$9999="Variant")*(Raw_Data_Daily!$C$2:$C$9999="C. 10-19")*Raw_Data_Daily!$D$2:$D$9999*Raw_Data_Daily!$N$2:$N$9999)/SUMIFS(Raw_Data_Daily!$D:$D, Raw_Data_Daily!$B:$B, "Variant", Raw_Data_Daily!$C:$C, "C. 10-19"),"") -> 0.52182987 | K25: =IFERROR((J25-I25)/ABS(I25),"") -> 0.034668546 | L25: =IFERROR(SUMPRODUCT((Raw_Data_Daily!$B$2:$B$9999="Control")*(Raw_Data_Daily!$C$2:$C$9999="D. 20-39")*Raw_Data_Daily!$D$2:$D$9999*Raw_Data_Daily!$N$2:$N$9999)/SUMIFS(Raw_Data_Daily!$D:$D, Raw_Data_Daily!$B:$B, "Control", Raw_Data_Daily!$C:$C, "D. 20-39"),"") -> 0.40567422 | M25: =IFERROR(SUMPRODUCT((Raw_Data_Daily!$B$2:$B$9999="Variant")*(Raw_Data_Daily!$C$2:$C$9999="D. 20-39")*Raw_Data_Daily!$D$2:$D$9999*Raw_Data_Daily!$N$2:$N$9999)/SUMIFS(Raw_Data_Daily!$D:$D, Raw_Data_Daily!$B:$B, "Variant", Raw_Data_Daily!$C:$C, "D. 20-39"),"") -> 0.42265732 | N25: =IFERROR((M25-L25)/ABS(L25),"") -> 0.041863885 | O25: =IFERROR(SUMPRODUCT((Raw_Data_Daily!$B$2:$B$9999="Control")*(Raw_Data_Daily!$C$2:$C$9999="E. 40-99")*Raw_Data_Daily!$D$2:$D$9999*Raw_Data_Daily!$N$2:$N$9999)/SUMIFS(Raw_Data_Daily!$D:$D, Raw_Data_Daily!$B:$B, "Control", Raw_Data_Daily!$C:$C, "E. 40-99"),"") -> 0.36180119 | P25: =IFERROR(SUMPRODUCT((Raw_Data_Daily!$B$2:$B$9999="Variant")*(Raw_Data_Daily!$C$2:$C$9999="E. 40-99")*Raw_Data_Daily!$D$2:$D$9999*Raw_Data_Daily!$N$2:$N$9999)/SUMIFS(Raw_Data_Daily!$D:$D, Raw_Data_Daily!$B:$B, "Variant", Raw_Data_Daily!$C:$C, "E. 40-99"),"") -> 0.3742933 | Q25: =IFERROR((P25-O25)/ABS(O25),"") -> 0.034527571 | R25: =IFERROR(SUMPRODUCT((Raw_Data_Daily!$B$2:$B$9999="Control")*(Raw_Data_Daily!$C$2:$C$9999="F. 100+")*Raw_Data_Daily!$D$2:$D$9999*Raw_Data_Daily!$N$2:$N$9999)/SUMIFS(Raw_Data_Daily!$D:$D, Raw_Data_Daily!$B:$B, "Control", Raw_Data_Daily!$C:$C, "F. 100+"),"") -> 0.31597447 | S25: =IFERROR(SUMPRODUCT((Raw_Data_Daily!$B$2:$B$9999="Variant")*(Raw_Data_Daily!$C$2:$C$9999="F. 100+")*Raw_Data_Daily!$D$2:$D$9999*Raw_Data_Daily!$N$2:$N$9999)/SUMIFS(Raw_Data_Daily!$D:$D, Raw_Data_Daily!$B:$B, "Variant", Raw_Data_Daily!$C:$C, "F. 100+"),"") -> 0.33336909 | T25: =IFERROR((S25-R25)/ABS(R25),"") -> 0.055050724
B26: First-try OOM rate | C26: =IFERROR(SUMPRODUCT((Raw_Data_Daily!$B$2:$B$9999="Control")*(Raw_Data_Daily!$C$2:$C$9999="A. 0")*Raw_Data_Daily!$D$2:$D$9999*Raw_Data_Daily!$O$2:$O$9999)/SUMIFS(Raw_Data_Daily!$D:$D, Raw_Data_Daily!$B:$B, "Control", Raw_Data_Daily!$C:$C, "A. 0"),"") -> 0.25363678 | D26: =IFERROR(SUMPRODUCT((Raw_Data_Daily!$B$2:$B$9999="Variant")*(Raw_Data_Daily!$C$2:$C$9999="A. 0")*Raw_Data_Daily!$D$2:$D$9999*Raw_Data_Daily!$O$2:$O$9999)/SUMIFS(Raw_Data_Daily!$D:$D, Raw_Data_Daily!$B:$B, "Variant", Raw_Data_Daily!$C:$C, "A. 0"),"") -> 0.26289074 | E26: =IFERROR((D26-C26)/ABS(C26),"") -> 0.036485091 | F26: =IFERROR(SUMPRODUCT((Raw_Data_Daily!$B$2:$B$9999="Control")*(Raw_Data_Daily!$C$2:$C$9999="B. 1-9")*Raw_Data_Daily!$D$2:$D$9999*Raw_Data_Daily!$O$2:$O$9999)/SUMIFS(Raw_Data_Daily!$D:$D, Raw_Data_Daily!$B:$B, "Control", Raw_Data_Daily!$C:$C, "B. 1-9"),"") -> 0.38194839 | G26: =IFERROR(SUMPRODUCT((Raw_Data_Daily!$B$2:$B$9999="Variant")*(Raw_Data_Daily!$C$2:$C$9999="B. 1-9")*Raw_Data_Daily!$D$2:$D$9999*Raw_Data_Daily!$O$2:$O$9999)/SUMIFS(Raw_Data_Daily!$D:$D, Raw_Data_Daily!$B:$B, "Variant", Raw_Data_Daily!$C:$C, "B. 1-9"),"") -> 0.36965303 | H26: =IFERROR((G26-F26)/ABS(F26),"") -> -0.032191158 | I26: =IFERROR(SUMPRODUCT((Raw_Data_Daily!$B$2:$B$9999="Control")*(Raw_Data_Daily!$C$2:$C$9999="C. 10-19")*Raw_Data_Daily!$D$2:$D$9999*Raw_Data_Daily!$O$2:$O$9999)/SUMIFS(Raw_Data_Daily!$D:$D, Raw_Data_Daily!$B:$B, "Control", Raw_Data_Daily!$C:$C, "C. 10-19"),"") -> 0.30783522 | J26: =IFERROR(SUMPRODUCT((Raw_Data_Daily!$B$2:$B$9999="Variant")*(Raw_Data_Daily!$C$2:$C$9999="C. 10-19")*Raw_Data_Daily!$D$2:$D$9999*Raw_Data_Daily!$O$2:$O$9999)/SUMIFS(Raw_Data_Daily!$D:$D, Raw_Data_Daily!$B:$B, "Variant", Raw_Data_Daily!$C:$C, "C. 10-19"),"") -> 0.31221516 | K26: =IFERROR((J26-I26)/ABS(I26),"") -> 0.014228192 | L26: =IFERROR(SUMPRODUCT((Raw_Data_Daily!$B$2:$B$9999="Control")*(Raw_Data_Daily!$C$2:$C$9999="D. 20-39")*Raw_Data_Daily!$D$2:$D$9999*Raw_Data_Daily!$O$2:$O$9999)/SUMIFS(Raw_Data_Daily!$D:$D, Raw_Data_Daily!$B:$B, "Control", Raw_Data_Daily!$C:$C, "D. 20-39"),"") -> 0.26295841 | M26: =IFERROR(SUMPRODUCT((Raw_Data_Daily!$B$2:$B$9999="Variant")*(Raw_Data_Daily!$C$2:$C$9999="D. 20-39")*Raw_Data_Daily!$D$2:$D$9999*Raw_Data_Daily!$O$2:$O$9999)/SUMIFS(Raw_Data_Daily!$D:$D, Raw_Data_Daily!$B:$B, "Variant", Raw_Data_Daily!$C:$C, "D. 20-39"),"") -> 0.26751807 | N26: =IFERROR((M26-L26)/ABS(L26),"") -> 0.017339862 | O26: =IFERROR(SUMPRODUCT((Raw_Data_Daily!$B$2:$B$9999="Control")*(Raw_Data_Daily!$C$2:$C$9999="E. 40-99")*Raw_Data_Daily!$D$2:$D$9999*Raw_Data_Daily!$O$2:$O$9999)/SUMIFS(Raw_Data_Daily!$D:$D, Raw_Data_Daily!$B:$B, "Control", Raw_Data_Daily!$C:$C, "E. 40-99"),"") -> 0.23806964 | P26: =IFERROR(SUMPRODUCT((Raw_Data_Daily!$B$2:$B$9999="Variant")*(Raw_Data_Daily!$C$2:$C$9999="E. 40-99")*Raw_Data_Daily!$D$2:$D$9999*Raw_Data_Daily!$O$2:$O$9999)/SUMIFS(Raw_Data_Daily!$D:$D, Raw_Data_Daily!$B:$B, "Variant", Raw_Data_Daily!$C:$C, "E. 40-99"),"") -> 0.24087973 | Q26: =IFERROR((P26-O26)/ABS(O26),"") -> 0.011803647 | R26: =IFERROR(SUMPRODUCT((Raw_Data_Daily!$B$2:$B$9999="Control")*(Raw_Data_Daily!$C$2:$C$9999="F. 100+")*Raw_Data_Daily!$D$2:$D$9999*Raw_Data_Daily!$O$2:$O$9999)/SUMIFS(Raw_Data_Daily!$D:$D, Raw_Data_Daily!$B:$B, "Control", Raw_Data_Daily!$C:$C, "F. 100+"),"") -> 0.20535182 | S26: =IFERROR(SUMPRODUCT((Raw_Data_Daily!$B$2:$B$9999="Variant")*(Raw_Data_Daily!$C$2:$C$9999="F. 100+")*Raw_Data_Daily!$D$2:$D$9999*Raw_Data_Daily!$O$2:$O$9999)/SUMIFS(Raw_Data_Daily!$D:$D, Raw_Data_Daily!$B:$B, "Variant", Raw_Data_Daily!$C:$C, "F. 100+"),"") -> 0.21258268 | T26: =IFERROR((S26-R26)/ABS(R26),"") -> 0.035212025 | V26: todo
