Workbook

Sheet By Bucket
A1: A/B Test Summary By 7d Completion Bucket
A3: Category | B3: Metric | C3: 0 | F3: 1-9 | I3: 10-19 | L3: 20-39 | O3: 40-99 | R3: 100+
C4: Control | D4: Variant | E4: Δ % | F4: Control | G4: Variant | H4: Δ % | I4: Control | J4: Variant | K4: Δ % | L4: Control | M4: Variant | N4: Δ % | O4: Control | P4: Variant | Q4: Δ % | R4: Control | S4: Variant | T4: Δ %
A5: Players
B6: Players (sum) | C6: =SUMIFS('Raw Data'!$D:$D, 'Raw Data'!$B:$B, "Control", 'Raw Data'!$C:$C, "A. 0") -> 24509 | D6: =SUMIFS('Raw Data'!$D:$D, 'Raw Data'!$B:$B, "Variant", 'Raw Data'!$C:$C, "A. 0") -> 24119 | E6: =IFERROR((D6-C6)/ABS(C6),"") -> -0.015912522 | F6: =SUMIFS('Raw Data'!$D:$D, 'Raw Data'!$B:$B, "Control", 'Raw Data'!$C:$C, "B. 1-9") -> 49087 | G6: =SUMIFS('Raw Data'!$D:$D, 'Raw Data'!$B:$B, "Variant", 'Raw Data'!$C:$C, "B. 1-9") -> 47191 | H6: =IFERROR((G6-F6)/ABS(F6),"") -> -0.038625298 | I6: =SUMIFS('Raw Data'!$D:$D, 'Raw Data'!$B:$B, "Control", 'Raw Data'!$C:$C, "C. 10-19") -> 39905 | J6: =SUMIFS('Raw Data'!$D:$D, 'Raw Data'!$B:$B, "Variant", 'Raw Data'!$C:$C, "C. 10-19") -> 40363 | K6: =IFERROR((J6-I6)/ABS(I6),"") -> 0.011477258 | L6: =SUMIFS('Raw Data'!$D:$D, 'Raw Data'!$B:$B, "Control", 'Raw Data'!$C:$C, "D. 20-39") -> 27297 | M6: =SUMIFS('Raw Data'!$D:$D, 'Raw Data'!$B:$B, "Variant", 'Raw Data'!$C:$C, "D. 20-39") -> 29185 | N6: =IFERROR((M6-L6)/ABS(L6),"") -> 0.06916511 | O6: =SUMIFS('Raw Data'!$D:$D, 'Raw Data'!$B:$B, "Control", 'Raw Data'!$C:$C, "E. 40-99") -> 16786 | P6: =SUMIFS('Raw Data'!$D:$D, 'Raw Data'!$B:$B, "Variant", 'Raw Data'!$C:$C, "E. 40-99") -> 16595 | Q6: =IFERROR((P6-O6)/ABS(O6),"") -> -0.01137853 | R6: =SUMIFS('Raw Data'!$D:$D, 'Raw Data'!$B:$B, "Control", 'Raw Data'!$C:$C, "F. 100+") -> 2488 | S6: =SUMIFS('Raw Data'!$D:$D, 'Raw Data'!$B:$B, "Variant", 'Raw Data'!$C:$C, "F. 100+") -> 2343 | T6: =IFERROR((S6-R6)/ABS(R6),"") -> -0.058279743
A7: Revenue
B8: Total revenue | C8: =SUMIFS('Raw Data'!$F:$F, 'Raw Data'!$B:$B, "Control", 'Raw Data'!$C:$C, "A. 0") -> 54.19 | D8: =SUMIFS('Raw Data'!$F:$F, 'Raw Data'!$B:$B, "Variant", 'Raw Data'!$C:$C, "A. 0") -> 120.81 | E8: =IFERROR((D8-C8)/ABS(C8),"") -> 1.2293781 | F8: =SUMIFS('Raw Data'!$F:$F, 'Raw Data'!$B:$B, "Control", 'Raw Data'!$C:$C, "B. 1-9") -> 1494.72 | G8: =SUMIFS('Raw Data'!$F:$F, 'Raw Data'!$B:$B, "Variant", 'Raw Data'!$C:$C, "B. 1-9") -> 1482.43 | H8: =IFERROR((G8-F8)/ABS(F8),"") -> -0.0082222757 | I8: =SUMIFS('Raw Data'!$F:$F, 'Raw Data'!$B:$B, "Control", 'Raw Data'!$C:$C, "C. 10-19") -> 4500.07 | J8: =SUMIFS('Raw Data'!$F:$F, 'Raw Data'!$B:$B, "Variant", 'Raw Data'!$C:$C, "C. 10-19") -> 4418.07 | K8: =IFERROR((J8-I8)/ABS(I8),"") -> -0.018221939 | L8: =SUMIFS('Raw Data'!$F:$F, 'Raw Data'!$B:$B, "Control", 'Raw Data'!$C:$C, "D. 20-39") -> 7226.99 | M8: =SUMIFS('Raw Data'!$F:$F, 'Raw Data'!$B:$B, "Variant", 'Raw Data'!$C:$C, "D. 20-39") -> 6881.55 | N8: =IFERROR((M8-L8)/ABS(L8),"") -> -0.047798599 | O8: =SUMIFS('Raw Data'!$F:$F, 'Raw Data'!$B:$B, "Control", 'Raw Data'!$C:$C, "E. 40-99") -> 7593.51 | P8: =SUMIFS('Raw Data'!$F:$F, 'Raw Data'!$B:$B, "Variant", 'Raw Data'!$C:$C, "E. 40-99") -> 7975.84 | Q8: =IFERROR((P8-O8)/ABS(O8),"") -> 0.050349575 | R8: =SUMIFS('Raw Data'!$F:$F, 'Raw Data'!$B:$B, "Control", 'Raw Data'!$C:$C, "F. 100+") -> 1247.99 | S8: =SUMIFS('Raw Data'!$F:$F, 'Raw Data'!$B:$B, "Variant", 'Raw Data'!$C:$C, "F. 100+") -> 1817.49 | T8: =IFERROR((S8-R8)/ABS(R8),"") -> 0.45633378
B9: ARPDAU | C9: =IFERROR(SUMIFS('Raw Data'!$F:$F, 'Raw Data'!$B:$B, "Control", 'Raw Data'!$C:$C, "A. 0")/SUMIFS('Raw Data'!$D:$D, 'Raw Data'!$B:$B, "Control", 'Raw Data'!$C:$C, "A. 0"),"") -> 0.0022110245 | D9: =IFERROR(SUMIFS('Raw Data'!$F:$F, 'Raw Data'!$B:$B, "Variant", 'Raw Data'!$C:$C, "A. 0")/SUMIFS('Raw Data'!$D:$D, 'Raw Data'!$B:$B, "Variant", 'Raw Data'!$C:$C, "A. 0"),"") -> 0.0050089141 | E9: =IFERROR((D9-C9)/ABS(C9),"") -> 1.2654268 | F9: =IFERROR(SUMIFS('Raw Data'!$F:$F, 'Raw Data'!$B:$B, "Control", 'Raw Data'!$C:$C, "B. 1-9")/SUMIFS('Raw Data'!$D:$D, 'Raw Data'!$B:$B, "Control", 'Raw Data'!$C:$C, "B. 1-9"),"") -> 0.030450425 | G9: =IFERROR(SUMIFS('Raw Data'!$F:$F, 'Raw Data'!$B:$B, "Variant", 'Raw Data'!$C:$C, "B. 1-9")/SUMIFS('Raw Data'!$D:$D, 'Raw Data'!$B:$B, "Variant", 'Raw Data'!$C:$C, "B. 1-9"),"") -> 0.031413405 | H9: =IFERROR((G9-F9)/ABS(F9),"") -> 0.031624529 | I9: =IFERROR(SUMIFS('Raw Data'!$F:$F, 'Raw Data'!$B:$B, "Control", 'Raw Data'!$C:$C, "C. 10-19")/SUMIFS('Raw Data'!$D:$D, 'Raw Data'!$B:$B, "Control", 'Raw Data'!$C:$C, "C. 10-19"),"") -> 0.11276958 | J9: =IFERROR(SUMIFS('Raw Data'!$F:$F, 'Raw Data'!$B:$B, "Variant", 'Raw Data'!$C:$C, "C. 10-19")/SUMIFS('Raw Data'!$D:$D, 'Raw Data'!$B:$B, "Variant", 'Raw Data'!$C:$C, "C. 10-19"),"") -> 0.10945841 | K9: =IFERROR((J9-I9)/ABS(I9),"") -> -0.0293622 | L9: =IFERROR(SUMIFS('Raw Data'!$F:$F, 'Raw Data'!$B:$B, "Control", 'Raw Data'!$C:$C, "D. 20-39")/SUMIFS('Raw Data'!$D:$D, 'Raw Data'!$B:$B, "Control", 'Raw Data'!$C:$C, "D. 20-39"),"") -> 0.264754 | M9: =IFERROR(SUMIFS('Raw Data'!$F:$F, 'Raw Data'!$B:$B, "Variant", 'Raw Data'!$C:$C, "D. 20-39")/SUMIFS('Raw Data'!$D:$D, 'Raw Data'!$B:$B, "Variant", 'Raw Data'!$C:$C, "D. 20-39"),"") -> 0.23579065 | N9: =IFERROR((M9-L9)/ABS(L9),"") -> -0.10939724 | O9: =IFERROR(SUMIFS('Raw Data'!$F:$F, 'Raw Data'!$B:$B, "Control", 'Raw Data'!$C:$C, "E. 40-99")/SUMIFS('Raw Data'!$D:$D, 'Raw Data'!$B:$B, "Control", 'Raw Data'!$C:$C, "E. 40-99"),"") -> 0.45237162 | P9: =IFERROR(SUMIFS('Raw Data'!$F:$F, 'Raw Data'!$B:$B, "Variant", 'Raw Data'!$C:$C, "E. 40-99")/SUMIFS('Raw Data'!$D:$D, 'Raw Data'!$B:$B, "Variant", 'Raw Data'!$C:$C, "E. 40-99"),"") -> 0.48061705 | Q9: =IFERROR((P9-O9)/ABS(O9),"") -> 0.062438564 | R9: =IFERROR(SUMIFS('Raw Data'!$F:$F, 'Raw Data'!$B:$B, "Control", 'Raw Data'!$C:$C, "F. 100+")/SUMIFS('Raw Data'!$D:$D, 'Raw Data'!$B:$B, "Control", 'Raw Data'!$C:$C, "F. 100+"),"") -> 0.5016037 | S9: =IFERROR(SUMIFS('Raw Data'!$F:$F, 'Raw Data'!$B:$B, "Variant", 'Raw Data'!$C:$C, "F. 100+")/SUMIFS('Raw Data'!$D:$D, 'Raw Data'!$B:$B, "Variant", 'Raw Data'!$C:$C, "F. 100+"),"") -> 0.77571063 | T9: =IFERROR((S9-R9)/ABS(R9),"") -> 0.54646114
B10: AVG Payer day (%) | C10: =IFERROR(SUMPRODUCT(('Raw Data'!$B$2:$B$9999="Control")*('Raw Data'!$C$2:$C$9999="A. 0")*'Raw Data'!$D$2:$D$9999*'Raw Data'!$H$2:$H$9999/100)/SUMIFS('Raw Data'!$D:$D, 'Raw Data'!$B:$B, "Control", 'Raw Data'!$C:$C, "A. 0")*100,"") -> 0.053851646 | D10: =IFERROR(SUMPRODUCT(('Raw Data'!$B$2:$B$9999="Variant")*('Raw Data'!$C$2:$C$9999="A. 0")*'Raw Data'!$D$2:$D$9999*'Raw Data'!$H$2:$H$9999/100)/SUMIFS('Raw Data'!$D:$D, 'Raw Data'!$B:$B, "Variant", 'Raw Data'!$C:$C, "A. 0")*100,"") -> 0.052130685 | E10: =IFERROR((D10-C10)/ABS(C10),"") -> -0.031957444 | F10: =IFERROR(SUMPRODUCT(('Raw Data'!$B$2:$B$9999="Control")*('Raw Data'!$C$2:$C$9999="B. 1-9")*'Raw Data'!$D$2:$D$9999*'Raw Data'!$H$2:$H$9999/100)/SUMIFS('Raw Data'!$D:$D, 'Raw Data'!$B:$B, "Control", 'Raw Data'!$C:$C, "B. 1-9")*100,"") -> 1.3240569 | G10: =IFERROR(SUMPRODUCT(('Raw Data'!$B$2:$B$9999="Variant")*('Raw Data'!$C$2:$C$9999="B. 1-9")*'Raw Data'!$D$2:$D$9999*'Raw Data'!$H$2:$H$9999/100)/SUMIFS('Raw Data'!$D:$D, 'Raw Data'!$B:$B, "Variant", 'Raw Data'!$C:$C, "B. 1-9")*100,"") -> 1.3132349 | H10: =IFERROR((G10-F10)/ABS(F10),"") -> -0.0081733194 | I10: =IFERROR(SUMPRODUCT(('Raw Data'!$B$2:$B$9999="Control")*('Raw Data'!$C$2:$C$9999="C. 10-19")*'Raw Data'!$D$2:$D$9999*'Raw Data'!$H$2:$H$9999/100)/SUMIFS('Raw Data'!$D:$D, 'Raw Data'!$B:$B, "Control", 'Raw Data'!$C:$C, "C. 10-19")*100,"") -> 3.3664122 | J10: =IFERROR(SUMPRODUCT(('Raw Data'!$B$2:$B$9999="Variant")*('Raw Data'!$C$2:$C$9999="C. 10-19")*'Raw Data'!$D$2:$D$9999*'Raw Data'!$H$2:$H$9999/100)/SUMIFS('Raw Data'!$D:$D, 'Raw Data'!$B:$B, "Variant", 'Raw Data'!$C:$C, "C. 10-19")*100,"") -> 3.3764933 | K10: =IFERROR((J10-I10)/ABS(I10),"") -> 0.0029946107 | L10: =IFERROR(SUMPRODUCT(('Raw Data'!$B$2:$B$9999="Control")*('Raw Data'!$C$2:$C$9999="D. 20-39")*'Raw Data'!$D$2:$D$9999*'Raw Data'!$H$2:$H$9999/100)/SUMIFS('Raw Data'!$D:$D, 'Raw Data'!$B:$B, "Control", 'Raw Data'!$C:$C, "D. 20-39")*100,"") -> 5.249489 | M10: =IFERROR(SUMPRODUCT(('Raw Data'!$B$2:$B$9999="Variant")*('Raw Data'!$C$2:$C$9999="D. 20-39")*'Raw Data'!$D$2:$D$9999*'Raw Data'!$H$2:$H$9999/100)/SUMIFS('Raw Data'!$D:$D, 'Raw Data'!$B:$B, "Variant", 'Raw Data'!$C:$C, "D. 20-39")*100,"") -> 5.018184 | N10: =IFERROR((M10-L10)/ABS(L10),"") -> -0.044062376 | O10: =IFERROR(SUMPRODUCT(('Raw Data'!$B$2:$B$9999="Control")*('Raw Data'!$C$2:$C$9999="E. 40-99")*'Raw Data'!$D$2:$D$9999*'Raw Data'!$H$2:$H$9999/100)/SUMIFS('Raw Data'!$D:$D, 'Raw Data'!$B:$B, "Control", 'Raw Data'!$C:$C, "E. 40-99")*100,"") -> 6.3865209 | P10: =IFERROR(SUMPRODUCT(('Raw Data'!$B$2:$B$9999="Variant")*('Raw Data'!$C$2:$C$9999="E. 40-99")*'Raw Data'!$D$2:$D$9999*'Raw Data'!$H$2:$H$9999/100)/SUMIFS('Raw Data'!$D:$D, 'Raw Data'!$B:$B, "Variant", 'Raw Data'!$C:$C, "E. 40-99")*100,"") -> 6.1884875 | Q10: =IFERROR((P10-O10)/ABS(O10),"") -> -0.031008027 | R10: =IFERROR(SUMPRODUCT(('Raw Data'!$B$2:$B$9999="Control")*('Raw Data'!$C$2:$C$9999="F. 100+")*'Raw Data'!$D$2:$D$9999*'Raw Data'!$H$2:$H$9999/100)/SUMIFS('Raw Data'!$D:$D, 'Raw Data'!$B:$B, "Control", 'Raw Data'!$C:$C, "F. 100+")*100,"") -> 6.9537701 | S10: =IFERROR(SUMPRODUCT(('Raw Data'!$B$2:$B$9999="Variant")*('Raw Data'!$C$2:$C$9999="F. 100+")*'Raw Data'!$D$2:$D$9999*'Raw Data'!$H$2:$H$9999/100)/SUMIFS('Raw Data'!$D:$D, 'Raw Data'!$B:$B, "Variant", 'Raw Data'!$C:$C, "F. 100+")*100,"") -> 6.4860948 | T10: =IFERROR((S10-R10)/ABS(R10),"") -> -0.067254934
B11: ARPPU | C11: =IFERROR(SUMIFS('Raw Data'!$F:$F, 'Raw Data'!$B:$B, "Control", 'Raw Data'!$C:$C, "A. 0")/SUMPRODUCT(('Raw Data'!$B$2:$B$9999="Control")*('Raw Data'!$C$2:$C$9999="A. 0")*'Raw Data'!$D$2:$D$9999*'Raw Data'!$H$2:$H$9999/100),"") -> 4.1057696 | D11: =IFERROR(SUMIFS('Raw Data'!$F:$F, 'Raw Data'!$B:$B, "Variant", 'Raw Data'!$C:$C, "A. 0")/SUMPRODUCT(('Raw Data'!$B$2:$B$9999="Variant")*('Raw Data'!$C$2:$C$9999="A. 0")*'Raw Data'!$D$2:$D$9999*'Raw Data'!$H$2:$H$9999/100),"") -> 9.6083796 | E11: =IFERROR((D11-C11)/ABS(C11),"") -> 1.340214 | F11: =IFERROR(SUMIFS('Raw Data'!$F:$F, 'Raw Data'!$B:$B, "Control", 'Raw Data'!$C:$C, "B. 1-9")/SUMPRODUCT(('Raw Data'!$B$2:$B$9999="Control")*('Raw Data'!$C$2:$C$9999="B. 1-9")*'Raw Data'!$D$2:$D$9999*'Raw Data'!$H$2:$H$9999/100),"") -> 2.2997822 | G11: =IFERROR(SUMIFS('Raw Data'!$F:$F, 'Raw Data'!$B:$B, "Variant", 'Raw Data'!$C:$C, "B. 1-9")/SUMPRODUCT(('Raw Data'!$B$2:$B$9999="Variant")*('Raw Data'!$C$2:$C$9999="B. 1-9")*'Raw Data'!$D$2:$D$9999*'Raw Data'!$H$2:$H$9999/100),"") -> 2.3920628 | H11: =IFERROR((G11-F11)/ABS(F11),"") -> 0.040125809 | I11: =IFERROR(SUMIFS('Raw Data'!$F:$F, 'Raw Data'!$B:$B, "Control", 'Raw Data'!$C:$C, "C. 10-19")/SUMPRODUCT(('Raw Data'!$B$2:$B$9999="Control")*('Raw Data'!$C$2:$C$9999="C. 10-19")*'Raw Data'!$D$2:$D$9999*'Raw Data'!$H$2:$H$9999/100),"") -> 3.3498446 | J11: =IFERROR(SUMIFS('Raw Data'!$F:$F, 'Raw Data'!$B:$B, "Variant", 'Raw Data'!$C:$C, "C. 10-19")/SUMPRODUCT(('Raw Data'!$B$2:$B$9999="Variant")*('Raw Data'!$C$2:$C$9999="C. 10-19")*'Raw Data'!$D$2:$D$9999*'Raw Data'!$H$2:$H$9999/100),"") -> 3.2417779 | K11: =IFERROR((J11-I11)/ABS(I11),"") -> -0.032260204 | L11: =IFERROR(SUMIFS('Raw Data'!$F:$F, 'Raw Data'!$B:$B, "Control", 'Raw Data'!$C:$C, "D. 20-39")/SUMPRODUCT(('Raw Data'!$B$2:$B$9999="Control")*('Raw Data'!$C$2:$C$9999="D. 20-39")*'Raw Data'!$D$2:$D$9999*'Raw Data'!$H$2:$H$9999/100),"") -> 5.0434243 | M11: =IFERROR(SUMIFS('Raw Data'!$F:$F, 'Raw Data'!$B:$B, "Variant", 'Raw Data'!$C:$C, "D. 20-39")/SUMPRODUCT(('Raw Data'!$B$2:$B$9999="Variant")*('Raw Data'!$C$2:$C$9999="D. 20-39")*'Raw Data'!$D$2:$D$9999*'Raw Data'!$H$2:$H$9999/100),"") -> 4.6987246 | N11: =IFERROR((M11-L11)/ABS(L11),"") -> -0.068346364 | O11: =IFERROR(SUMIFS('Raw Data'!$F:$F, 'Raw Data'!$B:$B, "Control", 'Raw Data'!$C:$C, "E. 40-99")/SUMPRODUCT(('Raw Data'!$B$2:$B$9999="Control")*('Raw Data'!$C$2:$C$9999="E. 40-99")*'Raw Data'!$D$2:$D$9999*'Raw Data'!$H$2:$H$9999/100),"") -> 7.0832246 | P11: =IFERROR(SUMIFS('Raw Data'!$F:$F, 'Raw Data'!$B:$B, "Variant", 'Raw Data'!$C:$C, "E. 40-99")/SUMPRODUCT(('Raw Data'!$B$2:$B$9999="Variant")*('Raw Data'!$C$2:$C$9999="E. 40-99")*'Raw Data'!$D$2:$D$9999*'Raw Data'!$H$2:$H$9999/100),"") -> 7.7663089 | Q11: =IFERROR((P11-O11)/ABS(O11),"") -> 0.096436909 | R11: =IFERROR(SUMIFS('Raw Data'!$F:$F, 'Raw Data'!$B:$B, "Control", 'Raw Data'!$C:$C, "F. 100+")/SUMPRODUCT(('Raw Data'!$B$2:$B$9999="Control")*('Raw Data'!$C$2:$C$9999="F. 100+")*'Raw Data'!$D$2:$D$9999*'Raw Data'!$H$2:$H$9999/100),"") -> 7.2134064 | S11: =IFERROR(SUMIFS('Raw Data'!$F:$F, 'Raw Data'!$B:$B, "Variant", 'Raw Data'!$C:$C, "F. 100+")/SUMPRODUCT(('Raw Data'!$B$2:$B$9999="Variant")*('Raw Data'!$C$2:$C$9999="F. 100+")*'Raw Data'!$D$2:$D$9999*'Raw Data'!$H$2:$H$9999/100),"") -> 11.959594 | T11: =IFERROR((S11-R11)/ABS(R11),"") -> 0.65796765
A12: Engagement
B13: Time spent (mins) | C13: =IFERROR(SUMPRODUCT(('Raw Data'!$B$2:$B$9999="Control")*('Raw Data'!$C$2:$C$9999="A. 0")*'Raw Data'!$D$2:$D$9999*'Raw Data'!$J$2:$J$9999)/SUMIFS('Raw Data'!$D:$D, 'Raw Data'!$B:$B, "Control", 'Raw Data'!$C:$C, "A. 0"),"") -> 6.5418352 | D13: =IFERROR(SUMPRODUCT(('Raw Data'!$B$2:$B$9999="Variant")*('Raw Data'!$C$2:$C$9999="A. 0")*'Raw Data'!$D$2:$D$9999*'Raw Data'!$J$2:$J$9999)/SUMIFS('Raw Data'!$D:$D, 'Raw Data'!$B:$B, "Variant", 'Raw Data'!$C:$C, "A. 0"),"") -> 6.6944952 | E13: =IFERROR((D13-C13)/ABS(C13),"") -> 0.023335954 | F13: =IFERROR(SUMPRODUCT(('Raw Data'!$B$2:$B$9999="Control")*('Raw Data'!$C$2:$C$9999="B. 1-9")*'Raw Data'!$D$2:$D$9999*'Raw Data'!$J$2:$J$9999)/SUMIFS('Raw Data'!$D:$D, 'Raw Data'!$B:$B, "Control", 'Raw Data'!$C:$C, "B. 1-9"),"") -> 30.677692 | G13: =IFERROR(SUMPRODUCT(('Raw Data'!$B$2:$B$9999="Variant")*('Raw Data'!$C$2:$C$9999="B. 1-9")*'Raw Data'!$D$2:$D$9999*'Raw Data'!$J$2:$J$9999)/SUMIFS('Raw Data'!$D:$D, 'Raw Data'!$B:$B, "Variant", 'Raw Data'!$C:$C, "B. 1-9"),"") -> 31.73679 | H13: =IFERROR((G13-F13)/ABS(F13),"") -> 0.034523406 | I13: =IFERROR(SUMPRODUCT(('Raw Data'!$B$2:$B$9999="Control")*('Raw Data'!$C$2:$C$9999="C. 10-19")*'Raw Data'!$D$2:$D$9999*'Raw Data'!$J$2:$J$9999)/SUMIFS('Raw Data'!$D:$D, 'Raw Data'!$B:$B, "Control", 'Raw Data'!$C:$C, "C. 10-19"),"") -> 54.387947 | J13: =IFERROR(SUMPRODUCT(('Raw Data'!$B$2:$B$9999="Variant")*('Raw Data'!$C$2:$C$9999="C. 10-19")*'Raw Data'!$D$2:$D$9999*'Raw Data'!$J$2:$J$9999)/SUMIFS('Raw Data'!$D:$D, 'Raw Data'!$B:$B, "Variant", 'Raw Data'!$C:$C, "C. 10-19"),"") -> 57.628402 | K13: =IFERROR((J13-I13)/ABS(I13),"") -> 0.05958039 | L13: =IFERROR(SUMPRODUCT(('Raw Data'!$B$2:$B$9999="Control")*('Raw Data'!$C$2:$C$9999="D. 20-39")*'Raw Data'!$D$2:$D$9999*'Raw Data'!$J$2:$J$9999)/SUMIFS('Raw Data'!$D:$D, 'Raw Data'!$B:$B, "Control", 'Raw Data'!$C:$C, "D. 20-39"),"") -> 80.318698 | M13: =IFERROR(SUMPRODUCT(('Raw Data'!$B$2:$B$9999="Variant")*('Raw Data'!$C$2:$C$9999="D. 20-39")*'Raw Data'!$D$2:$D$9999*'Raw Data'!$J$2:$J$9999)/SUMIFS('Raw Data'!$D:$D, 'Raw Data'!$B:$B, "Variant", 'Raw Data'!$C:$C, "D. 20-39"),"") -> 85.205112 | N13: =IFERROR((M13-L13)/ABS(L13),"") -> 0.060837821 | O13: =IFERROR(SUMPRODUCT(('Raw Data'!$B$2:$B$9999="Control")*('Raw Data'!$C$2:$C$9999="E. 40-99")*'Raw Data'!$D$2:$D$9999*'Raw Data'!$J$2:$J$9999)/SUMIFS('Raw Data'!$D:$D, 'Raw Data'!$B:$B, "Control", 'Raw Data'!$C:$C, "E. 40-99"),"") -> 135.85759 | P13: =IFERROR(SUMPRODUCT(('Raw Data'!$B$2:$B$9999="Variant")*('Raw Data'!$C$2:$C$9999="E. 40-99")*'Raw Data'!$D$2:$D$9999*'Raw Data'!$J$2:$J$9999)/SUMIFS('Raw Data'!$D:$D, 'Raw Data'!$B:$B, "Variant", 'Raw Data'!$C:$C, "E. 40-99"),"") -> 139.83879 | Q13: =IFERROR((P13-O13)/ABS(O13),"") -> 0.029304204 | R13: =IFERROR(SUMPRODUCT(('Raw Data'!$B$2:$B$9999="Control")*('Raw Data'!$C$2:$C$9999="F. 100+")*'Raw Data'!$D$2:$D$9999*'Raw Data'!$J$2:$J$9999)/SUMIFS('Raw Data'!$D:$D, 'Raw Data'!$B:$B, "Control", 'Raw Data'!$C:$C, "F. 100+"),"") -> 245.64839 | S13: =IFERROR(SUMPRODUCT(('Raw Data'!$B$2:$B$9999="Variant")*('Raw Data'!$C$2:$C$9999="F. 100+")*'Raw Data'!$D$2:$D$9999*'Raw Data'!$J$2:$J$9999)/SUMIFS('Raw Data'!$D:$D, 'Raw Data'!$B:$B, "Variant", 'Raw Data'!$C:$C, "F. 100+"),"") -> 260.46055 | T13: =IFERROR((S13-R13)/ABS(R13),"") -> 0.060298245
B14: Level attempts / player | C14: =IFERROR(SUMPRODUCT(('Raw Data'!$B$2:$B$9999="Control")*('Raw Data'!$C$2:$C$9999="A. 0")*'Raw Data'!$D$2:$D$9999*'Raw Data'!$K$2:$K$9999)/SUMIFS('Raw Data'!$D:$D, 'Raw Data'!$B:$B, "Control", 'Raw Data'!$C:$C, "A. 0"),"") -> 2.7931352 | D14: =IFERROR(SUMPRODUCT(('Raw Data'!$B$2:$B$9999="Variant")*('Raw Data'!$C$2:$C$9999="A. 0")*'Raw Data'!$D$2:$D$9999*'Raw Data'!$K$2:$K$9999)/SUMIFS('Raw Data'!$D:$D, 'Raw Data'!$B:$B, "Variant", 'Raw Data'!$C:$C, "A. 0"),"") -> 2.7643389 | E14: =IFERROR((D14-C14)/ABS(C14),"") -> -0.010309659 | F14: =IFERROR(SUMPRODUCT(('Raw Data'!$B$2:$B$9999="Control")*('Raw Data'!$C$2:$C$9999="B. 1-9")*'Raw Data'!$D$2:$D$9999*'Raw Data'!$K$2:$K$9999)/SUMIFS('Raw Data'!$D:$D, 'Raw Data'!$B:$B, "Control", 'Raw Data'!$C:$C, "B. 1-9"),"") -> 14.859619 | G14: =IFERROR(SUMPRODUCT(('Raw Data'!$B$2:$B$9999="Variant")*('Raw Data'!$C$2:$C$9999="B. 1-9")*'Raw Data'!$D$2:$D$9999*'Raw Data'!$K$2:$K$9999)/SUMIFS('Raw Data'!$D:$D, 'Raw Data'!$B:$B, "Variant", 'Raw Data'!$C:$C, "B. 1-9"),"") -> 15.053953 | H14: =IFERROR((G14-F14)/ABS(F14),"") -> 0.013077982 | I14: =IFERROR(SUMPRODUCT(('Raw Data'!$B$2:$B$9999="Control")*('Raw Data'!$C$2:$C$9999="C. 10-19")*'Raw Data'!$D$2:$D$9999*'Raw Data'!$K$2:$K$9999)/SUMIFS('Raw Data'!$D:$D, 'Raw Data'!$B:$B, "Control", 'Raw Data'!$C:$C, "C. 10-19"),"") -> 27.107111 | J14: =IFERROR(SUMPRODUCT(('Raw Data'!$B$2:$B$9999="Variant")*('Raw Data'!$C$2:$C$9999="C. 10-19")*'Raw Data'!$D$2:$D$9999*'Raw Data'!$K$2:$K$9999)/SUMIFS('Raw Data'!$D:$D, 'Raw Data'!$B:$B, "Variant", 'Raw Data'!$C:$C, "C. 10-19"),"") -> 28.19692 | K14: =IFERROR((J14-I14)/ABS(I14),"") -> 0.040203797 | L14: =IFERROR(SUMPRODUCT(('Raw Data'!$B$2:$B$9999="Control")*('Raw Data'!$C$2:$C$9999="D. 20-39")*'Raw Data'!$D$2:$D$9999*'Raw Data'!$K$2:$K$9999)/SUMIFS('Raw Data'!$D:$D, 'Raw Data'!$B:$B, "Control", 'Raw Data'!$C:$C, "D. 20-39"),"") -> 42.373994 | M14: =IFERROR(SUMPRODUCT(('Raw Data'!$B$2:$B$9999="Variant")*('Raw Data'!$C$2:$C$9999="D. 20-39")*'Raw Data'!$D$2:$D$9999*'Raw Data'!$K$2:$K$9999)/SUMIFS('Raw Data'!$D:$D, 'Raw Data'!$B:$B, "Variant", 'Raw Data'!$C:$C, "D. 20-39"),"") -> 43.865058 | N14: =IFERROR((M14-L14)/ABS(L14),"") -> 0.035188191 | O14: =IFERROR(SUMPRODUCT(('Raw Data'!$B$2:$B$9999="Control")*('Raw Data'!$C$2:$C$9999="E. 40-99")*'Raw Data'!$D$2:$D$9999*'Raw Data'!$K$2:$K$9999)/SUMIFS('Raw Data'!$D:$D, 'Raw Data'!$B:$B, "Control", 'Raw Data'!$C:$C, "E. 40-99"),"") -> 78.271315 | P14: =IFERROR(SUMPRODUCT(('Raw Data'!$B$2:$B$9999="Variant")*('Raw Data'!$C$2:$C$9999="E. 40-99")*'Raw Data'!$D$2:$D$9999*'Raw Data'!$K$2:$K$9999)/SUMIFS('Raw Data'!$D:$D, 'Raw Data'!$B:$B, "Variant", 'Raw Data'!$C:$C, "E. 40-99"),"") -> 78.731769 | Q14: =IFERROR((P14-O14)/ABS(O14),"") -> 0.0058827991 | R14: =IFERROR(SUMPRODUCT(('Raw Data'!$B$2:$B$9999="Control")*('Raw Data'!$C$2:$C$9999="F. 100+")*'Raw Data'!$D$2:$D$9999*'Raw Data'!$K$2:$K$9999)/SUMIFS('Raw Data'!$D:$D, 'Raw Data'!$B:$B, "Control", 'Raw Data'!$C:$C, "F. 100+"),"") -> 153.22973 | S14: =IFERROR(SUMPRODUCT(('Raw Data'!$B$2:$B$9999="Variant")*('Raw Data'!$C$2:$C$9999="F. 100+")*'Raw Data'!$D$2:$D$9999*'Raw Data'!$K$2:$K$9999)/SUMIFS('Raw Data'!$D:$D, 'Raw Data'!$B:$B, "Variant", 'Raw Data'!$C:$C, "F. 100+"),"") -> 157.79761 | T14: =IFERROR((S14-R14)/ABS(R14),"") -> 0.029810631
B15: Level completes / player | C15: =IFERROR(SUMPRODUCT(('Raw Data'!$B$2:$B$9999="Control")*('Raw Data'!$C$2:$C$9999="A. 0")*'Raw Data'!$D$2:$D$9999*'Raw Data'!$L$2:$L$9999)/SUMIFS('Raw Data'!$D:$D, 'Raw Data'!$B:$B, "Control", 'Raw Data'!$C:$C, "A. 0"),"") -> 0.11914113 | D15: =IFERROR(SUMPRODUCT(('Raw Data'!$B$2:$B$9999="Variant")*('Raw Data'!$C$2:$C$9999="A. 0")*'Raw Data'!$D$2:$D$9999*'Raw Data'!$L$2:$L$9999)/SUMIFS('Raw Data'!$D:$D, 'Raw Data'!$B:$B, "Variant", 'Raw Data'!$C:$C, "A. 0"),"") -> 0.097158672 | E15: =IFERROR((D15-C15)/ABS(C15),"") -> -0.18450773 | F15: =IFERROR(SUMPRODUCT(('Raw Data'!$B$2:$B$9999="Control")*('Raw Data'!$C$2:$C$9999="B. 1-9")*'Raw Data'!$D$2:$D$9999*'Raw Data'!$L$2:$L$9999)/SUMIFS('Raw Data'!$D:$D, 'Raw Data'!$B:$B, "Control", 'Raw Data'!$C:$C, "B. 1-9"),"") -> 5.8272158 | G15: =IFERROR(SUMPRODUCT(('Raw Data'!$B$2:$B$9999="Variant")*('Raw Data'!$C$2:$C$9999="B. 1-9")*'Raw Data'!$D$2:$D$9999*'Raw Data'!$L$2:$L$9999)/SUMIFS('Raw Data'!$D:$D, 'Raw Data'!$B:$B, "Variant", 'Raw Data'!$C:$C, "B. 1-9"),"") -> 5.8389295 | H15: =IFERROR((G15-F15)/ABS(F15),"") -> 0.0020101705 | I15: =IFERROR(SUMPRODUCT(('Raw Data'!$B$2:$B$9999="Control")*('Raw Data'!$C$2:$C$9999="C. 10-19")*'Raw Data'!$D$2:$D$9999*'Raw Data'!$L$2:$L$9999)/SUMIFS('Raw Data'!$D:$D, 'Raw Data'!$B:$B, "Control", 'Raw Data'!$C:$C, "C. 10-19"),"") -> 14.726566 | J15: =IFERROR(SUMPRODUCT(('Raw Data'!$B$2:$B$9999="Variant")*('Raw Data'!$C$2:$C$9999="C. 10-19")*'Raw Data'!$D$2:$D$9999*'Raw Data'!$L$2:$L$9999)/SUMIFS('Raw Data'!$D:$D, 'Raw Data'!$B:$B, "Variant", 'Raw Data'!$C:$C, "C. 10-19"),"") -> 14.8565 | K15: =IFERROR((J15-I15)/ABS(I15),"") -> 0.00882308 | L15: =IFERROR(SUMPRODUCT(('Raw Data'!$B$2:$B$9999="Control")*('Raw Data'!$C$2:$C$9999="D. 20-39")*'Raw Data'!$D$2:$D$9999*'Raw Data'!$L$2:$L$9999)/SUMIFS('Raw Data'!$D:$D, 'Raw Data'!$B:$B, "Control", 'Raw Data'!$C:$C, "D. 20-39"),"") -> 28.563784 | M15: =IFERROR(SUMPRODUCT(('Raw Data'!$B$2:$B$9999="Variant")*('Raw Data'!$C$2:$C$9999="D. 20-39")*'Raw Data'!$D$2:$D$9999*'Raw Data'!$L$2:$L$9999)/SUMIFS('Raw Data'!$D:$D, 'Raw Data'!$B:$B, "Variant", 'Raw Data'!$C:$C, "D. 20-39"),"") -> 28.918449 | N15: =IFERROR((M15-L15)/ABS(L15),"") -> 0.01241657 | O15: =IFERROR(SUMPRODUCT(('Raw Data'!$B$2:$B$9999="Control")*('Raw Data'!$C$2:$C$9999="E. 40-99")*'Raw Data'!$D$2:$D$9999*'Raw Data'!$L$2:$L$9999)/SUMIFS('Raw Data'!$D:$D, 'Raw Data'!$B:$B, "Control", 'Raw Data'!$C:$C, "E. 40-99"),"") -> 59.008855 | P15: =IFERROR(SUMPRODUCT(('Raw Data'!$B$2:$B$9999="Variant")*('Raw Data'!$C$2:$C$9999="E. 40-99")*'Raw Data'!$D$2:$D$9999*'Raw Data'!$L$2:$L$9999)/SUMIFS('Raw Data'!$D:$D, 'Raw Data'!$B:$B, "Variant", 'Raw Data'!$C:$C, "E. 40-99"),"") -> 58.84794 | Q15: =IFERROR((P15-O15)/ABS(O15),"") -> -0.0027269578 | R15: =IFERROR(SUMPRODUCT(('Raw Data'!$B$2:$B$9999="Control")*('Raw Data'!$C$2:$C$9999="F. 100+")*'Raw Data'!$D$2:$D$9999*'Raw Data'!$L$2:$L$9999)/SUMIFS('Raw Data'!$D:$D, 'Raw Data'!$B:$B, "Control", 'Raw Data'!$C:$C, "F. 100+"),"") -> 126.88003 | S15: =IFERROR(SUMPRODUCT(('Raw Data'!$B$2:$B$9999="Variant")*('Raw Data'!$C$2:$C$9999="F. 100+")*'Raw Data'!$D$2:$D$9999*'Raw Data'!$L$2:$L$9999)/SUMIFS('Raw Data'!$D:$D, 'Raw Data'!$B:$B, "Variant", 'Raw Data'!$C:$C, "F. 100+"),"") -> 128.30067 | T15: =IFERROR((S15-R15)/ABS(R15),"") -> 0.011196734
A16: Daily Streak
B17: Avg daily streak | C17: =IFERROR(SUMPRODUCT(('Raw Data'!$B$2:$B$9999="Control")*('Raw Data'!$C$2:$C$9999="A. 0")*'Raw Data'!$D$2:$D$9999*'Raw Data'!$AD$2:$AD$9999)/SUMIFS('Raw Data'!$D:$D, 'Raw Data'!$B:$B, "Control", 'Raw Data'!$C:$C, "A. 0"),"") -> 0 | D17: =IFERROR(SUMPRODUCT(('Raw Data'!$B$2:$B$9999="Variant")*('Raw Data'!$C$2:$C$9999="A. 0")*'Raw Data'!$D$2:$D$9999*'Raw Data'!$AD$2:$AD$9999)/SUMIFS('Raw Data'!$D:$D, 'Raw Data'!$B:$B, "Variant", 'Raw Data'!$C:$C, "A. 0"),"") -> 0 | E17: =IFERROR((D17-C17)/ABS(C17),"") | F17: =IFERROR(SUMPRODUCT(('Raw Data'!$B$2:$B$9999="Control")*('Raw Data'!$C$2:$C$9999="B. 1-9")*'Raw Data'!$D$2:$D$9999*'Raw Data'!$AD$2:$AD$9999)/SUMIFS('Raw Data'!$D:$D, 'Raw Data'!$B:$B, "Control", 'Raw Data'!$C:$C, "B. 1-9"),"") -> 4.0777762 | G17: =IFERROR(SUMPRODUCT(('Raw Data'!$B$2:$B$9999="Variant")*('Raw Data'!$C$2:$C$9999="B. 1-9")*'Raw Data'!$D$2:$D$9999*'Raw Data'!$AD$2:$AD$9999)/SUMIFS('Raw Data'!$D:$D, 'Raw Data'!$B:$B, "Variant", 'Raw Data'!$C:$C, "B. 1-9"),"") -> 4.0968074 | H17: =IFERROR((G17-F17)/ABS(F17),"") -> 0.0046670656 | I17: =IFERROR(SUMPRODUCT(('Raw Data'!$B$2:$B$9999="Control")*('Raw Data'!$C$2:$C$9999="C. 10-19")*'Raw Data'!$D$2:$D$9999*'Raw Data'!$AD$2:$AD$9999)/SUMIFS('Raw Data'!$D:$D, 'Raw Data'!$B:$B, "Control", 'Raw Data'!$C:$C, "C. 10-19"),"") -> 9.4993194 | J17: =IFERROR(SUMPRODUCT(('Raw Data'!$B$2:$B$9999="Variant")*('Raw Data'!$C$2:$C$9999="C. 10-19")*'Raw Data'!$D$2:$D$9999*'Raw Data'!$AD$2:$AD$9999)/SUMIFS('Raw Data'!$D:$D, 'Raw Data'!$B:$B, "Variant", 'Raw Data'!$C:$C, "C. 10-19"),"") -> 9.551543 | K17: =IFERROR((J17-I17)/ABS(I17),"") -> 0.0054976164 | L17: =IFERROR(SUMPRODUCT(('Raw Data'!$B$2:$B$9999="Control")*('Raw Data'!$C$2:$C$9999="D. 20-39")*'Raw Data'!$D$2:$D$9999*'Raw Data'!$AD$2:$AD$9999)/SUMIFS('Raw Data'!$D:$D, 'Raw Data'!$B:$B, "Control", 'Raw Data'!$C:$C, "D. 20-39"),"") -> 17.945381 | M17: =IFERROR(SUMPRODUCT(('Raw Data'!$B$2:$B$9999="Variant")*('Raw Data'!$C$2:$C$9999="D. 20-39")*'Raw Data'!$D$2:$D$9999*'Raw Data'!$AD$2:$AD$9999)/SUMIFS('Raw Data'!$D:$D, 'Raw Data'!$B:$B, "Variant", 'Raw Data'!$C:$C, "D. 20-39"),"") -> 17.774488 | N17: =IFERROR((M17-L17)/ABS(L17),"") -> -0.009522966 | O17: =IFERROR(SUMPRODUCT(('Raw Data'!$B$2:$B$9999="Control")*('Raw Data'!$C$2:$C$9999="E. 40-99")*'Raw Data'!$D$2:$D$9999*'Raw Data'!$AD$2:$AD$9999)/SUMIFS('Raw Data'!$D:$D, 'Raw Data'!$B:$B, "Control", 'Raw Data'!$C:$C, "E. 40-99"),"") -> 34.327524 | P17: =IFERROR(SUMPRODUCT(('Raw Data'!$B$2:$B$9999="Variant")*('Raw Data'!$C$2:$C$9999="E. 40-99")*'Raw Data'!$D$2:$D$9999*'Raw Data'!$AD$2:$AD$9999)/SUMIFS('Raw Data'!$D:$D, 'Raw Data'!$B:$B, "Variant", 'Raw Data'!$C:$C, "E. 40-99"),"") -> 33.111094 | Q17: =IFERROR((P17-O17)/ABS(O17),"") -> -0.035435974 | R17: =IFERROR(SUMPRODUCT(('Raw Data'!$B$2:$B$9999="Control")*('Raw Data'!$C$2:$C$9999="F. 100+")*'Raw Data'!$D$2:$D$9999*'Raw Data'!$AD$2:$AD$9999)/SUMIFS('Raw Data'!$D:$D, 'Raw Data'!$B:$B, "Control", 'Raw Data'!$C:$C, "F. 100+"),"") -> 66.792094 | S17: =IFERROR(SUMPRODUCT(('Raw Data'!$B$2:$B$9999="Variant")*('Raw Data'!$C$2:$C$9999="F. 100+")*'Raw Data'!$D$2:$D$9999*'Raw Data'!$AD$2:$AD$9999)/SUMIFS('Raw Data'!$D:$D, 'Raw Data'!$B:$B, "Variant", 'Raw Data'!$C:$C, "F. 100+"),"") -> 64.344738 | T17: =IFERROR((S17-R17)/ABS(R17),"") -> -0.03664141
B18: P25 daily streak | C18: =IFERROR(SUMPRODUCT(('Raw Data'!$B$2:$B$9999="Control")*('Raw Data'!$C$2:$C$9999="A. 0")*'Raw Data'!$D$2:$D$9999*'Raw Data'!$AE$2:$AE$9999)/SUMIFS('Raw Data'!$D:$D, 'Raw Data'!$B:$B, "Control", 'Raw Data'!$C:$C, "A. 0"),"") -> 0 | D18: =IFERROR(SUMPRODUCT(('Raw Data'!$B$2:$B$9999="Variant")*('Raw Data'!$C$2:$C$9999="A. 0")*'Raw Data'!$D$2:$D$9999*'Raw Data'!$AE$2:$AE$9999)/SUMIFS('Raw Data'!$D:$D, 'Raw Data'!$B:$B, "Variant", 'Raw Data'!$C:$C, "A. 0"),"") -> 0 | E18: =IFERROR((D18-C18)/ABS(C18),"") | F18: =IFERROR(SUMPRODUCT(('Raw Data'!$B$2:$B$9999="Control")*('Raw Data'!$C$2:$C$9999="B. 1-9")*'Raw Data'!$D$2:$D$9999*'Raw Data'!$AE$2:$AE$9999)/SUMIFS('Raw Data'!$D:$D, 'Raw Data'!$B:$B, "Control", 'Raw Data'!$C:$C, "B. 1-9"),"") -> 1.1393852 | G18: =IFERROR(SUMPRODUCT(('Raw Data'!$B$2:$B$9999="Variant")*('Raw Data'!$C$2:$C$9999="B. 1-9")*'Raw Data'!$D$2:$D$9999*'Raw Data'!$AE$2:$AE$9999)/SUMIFS('Raw Data'!$D:$D, 'Raw Data'!$B:$B, "Variant", 'Raw Data'!$C:$C, "B. 1-9"),"") -> 1.1451548 | H18: =IFERROR((G18-F18)/ABS(F18),"") -> 0.005063804 | I18: =IFERROR(SUMPRODUCT(('Raw Data'!$B$2:$B$9999="Control")*('Raw Data'!$C$2:$C$9999="C. 10-19")*'Raw Data'!$D$2:$D$9999*'Raw Data'!$AE$2:$AE$9999)/SUMIFS('Raw Data'!$D:$D, 'Raw Data'!$B:$B, "Control", 'Raw Data'!$C:$C, "C. 10-19"),"") -> 3.7123669 | J18: =IFERROR(SUMPRODUCT(('Raw Data'!$B$2:$B$9999="Variant")*('Raw Data'!$C$2:$C$9999="C. 10-19")*'Raw Data'!$D$2:$D$9999*'Raw Data'!$AE$2:$AE$9999)/SUMIFS('Raw Data'!$D:$D, 'Raw Data'!$B:$B, "Variant", 'Raw Data'!$C:$C, "C. 10-19"),"") -> 3.5979734 | K18: =IFERROR((J18-I18)/ABS(I18),"") -> -0.030814164 | L18: =IFERROR(SUMPRODUCT(('Raw Data'!$B$2:$B$9999="Control")*('Raw Data'!$C$2:$C$9999="D. 20-39")*'Raw Data'!$D$2:$D$9999*'Raw Data'!$AE$2:$AE$9999)/SUMIFS('Raw Data'!$D:$D, 'Raw Data'!$B:$B, "Control", 'Raw Data'!$C:$C, "D. 20-39"),"") -> 7.4316958 | M18: =IFERROR(SUMPRODUCT(('Raw Data'!$B$2:$B$9999="Variant")*('Raw Data'!$C$2:$C$9999="D. 20-39")*'Raw Data'!$D$2:$D$9999*'Raw Data'!$AE$2:$AE$9999)/SUMIFS('Raw Data'!$D:$D, 'Raw Data'!$B:$B, "Variant", 'Raw Data'!$C:$C, "D. 20-39"),"") -> 7.1617612 | N18: =IFERROR((M18-L18)/ABS(L18),"") -> -0.036322075 | O18: =IFERROR(SUMPRODUCT(('Raw Data'!$B$2:$B$9999="Control")*('Raw Data'!$C$2:$C$9999="E. 40-99")*'Raw Data'!$D$2:$D$9999*'Raw Data'!$AE$2:$AE$9999)/SUMIFS('Raw Data'!$D:$D, 'Raw Data'!$B:$B, "Control", 'Raw Data'!$C:$C, "E. 40-99"),"") -> 13.016919 | P18: =IFERROR(SUMPRODUCT(('Raw Data'!$B$2:$B$9999="Variant")*('Raw Data'!$C$2:$C$9999="E. 40-99")*'Raw Data'!$D$2:$D$9999*'Raw Data'!$AE$2:$AE$9999)/SUMIFS('Raw Data'!$D:$D, 'Raw Data'!$B:$B, "Variant", 'Raw Data'!$C:$C, "E. 40-99"),"") -> 12.61868 | Q18: =IFERROR((P18-O18)/ABS(O18),"") -> -0.030593917 | R18: =IFERROR(SUMPRODUCT(('Raw Data'!$B$2:$B$9999="Control")*('Raw Data'!$C$2:$C$9999="F. 100+")*'Raw Data'!$D$2:$D$9999*'Raw Data'!$AE$2:$AE$9999)/SUMIFS('Raw Data'!$D:$D, 'Raw Data'!$B:$B, "Control", 'Raw Data'!$C:$C, "F. 100+"),"") -> 23.055466 | S18: =IFERROR(SUMPRODUCT(('Raw Data'!$B$2:$B$9999="Variant")*('Raw Data'!$C$2:$C$9999="F. 100+")*'Raw Data'!$D$2:$D$9999*'Raw Data'!$AE$2:$AE$9999)/SUMIFS('Raw Data'!$D:$D, 'Raw Data'!$B:$B, "Variant", 'Raw Data'!$C:$C, "F. 100+"),"") -> 21.76099 | T18: =IFERROR((S18-R18)/ABS(R18),"") -> -0.056146167
B19: P50 daily streak | C19: =IFERROR(SUMPRODUCT(('Raw Data'!$B$2:$B$9999="Control")*('Raw Data'!$C$2:$C$9999="A. 0")*'Raw Data'!$D$2:$D$9999*'Raw Data'!$AF$2:$AF$9999)/SUMIFS('Raw Data'!$D:$D, 'Raw Data'!$B:$B, "Control", 'Raw Data'!$C:$C, "A. 0"),"") -> 0 | D19: =IFERROR(SUMPRODUCT(('Raw Data'!$B$2:$B$9999="Variant")*('Raw Data'!$C$2:$C$9999="A. 0")*'Raw Data'!$D$2:$D$9999*'Raw Data'!$AF$2:$AF$9999)/SUMIFS('Raw Data'!$D:$D, 'Raw Data'!$B:$B, "Variant", 'Raw Data'!$C:$C, "A. 0"),"") -> 0 | E19: =IFERROR((D19-C19)/ABS(C19),"") | F19: =IFERROR(SUMPRODUCT(('Raw Data'!$B$2:$B$9999="Control")*('Raw Data'!$C$2:$C$9999="B. 1-9")*'Raw Data'!$D$2:$D$9999*'Raw Data'!$AF$2:$AF$9999)/SUMIFS('Raw Data'!$D:$D, 'Raw Data'!$B:$B, "Control", 'Raw Data'!$C:$C, "B. 1-9"),"") -> 3 | G19: =IFERROR(SUMPRODUCT(('Raw Data'!$B$2:$B$9999="Variant")*('Raw Data'!$C$2:$C$9999="B. 1-9")*'Raw Data'!$D$2:$D$9999*'Raw Data'!$AF$2:$AF$9999)/SUMIFS('Raw Data'!$D:$D, 'Raw Data'!$B:$B, "Variant", 'Raw Data'!$C:$C, "B. 1-9"),"") -> 3 | H19: =IFERROR((G19-F19)/ABS(F19),"") -> 0 | I19: =IFERROR(SUMPRODUCT(('Raw Data'!$B$2:$B$9999="Control")*('Raw Data'!$C$2:$C$9999="C. 10-19")*'Raw Data'!$D$2:$D$9999*'Raw Data'!$AF$2:$AF$9999)/SUMIFS('Raw Data'!$D:$D, 'Raw Data'!$B:$B, "Control", 'Raw Data'!$C:$C, "C. 10-19"),"") -> 7.5577497 | J19: =IFERROR(SUMPRODUCT(('Raw Data'!$B$2:$B$9999="Variant")*('Raw Data'!$C$2:$C$9999="C. 10-19")*'Raw Data'!$D$2:$D$9999*'Raw Data'!$AF$2:$AF$9999)/SUMIFS('Raw Data'!$D:$D, 'Raw Data'!$B:$B, "Variant", 'Raw Data'!$C:$C, "C. 10-19"),"") -> 7.7521492 | K19: =IFERROR((J19-I19)/ABS(I19),"") -> 0.025721888 | L19: =IFERROR(SUMPRODUCT(('Raw Data'!$B$2:$B$9999="Control")*('Raw Data'!$C$2:$C$9999="D. 20-39")*'Raw Data'!$D$2:$D$9999*'Raw Data'!$AF$2:$AF$9999)/SUMIFS('Raw Data'!$D:$D, 'Raw Data'!$B:$B, "Control", 'Raw Data'!$C:$C, "D. 20-39"),"") -> 13.723156 | M19: =IFERROR(SUMPRODUCT(('Raw Data'!$B$2:$B$9999="Variant")*('Raw Data'!$C$2:$C$9999="D. 20-39")*'Raw Data'!$D$2:$D$9999*'Raw Data'!$AF$2:$AF$9999)/SUMIFS('Raw Data'!$D:$D, 'Raw Data'!$B:$B, "Variant", 'Raw Data'!$C:$C, "D. 20-39"),"") -> 13.610656 | N19: =IFERROR((M19-L19)/ABS(L19),"") -> -0.0081978394 | O19: =IFERROR(SUMPRODUCT(('Raw Data'!$B$2:$B$9999="Control")*('Raw Data'!$C$2:$C$9999="E. 40-99")*'Raw Data'!$D$2:$D$9999*'Raw Data'!$AF$2:$AF$9999)/SUMIFS('Raw Data'!$D:$D, 'Raw Data'!$B:$B, "Control", 'Raw Data'!$C:$C, "E. 40-99"),"") -> 24.892172 | P19: =IFERROR(SUMPRODUCT(('Raw Data'!$B$2:$B$9999="Variant")*('Raw Data'!$C$2:$C$9999="E. 40-99")*'Raw Data'!$D$2:$D$9999*'Raw Data'!$AF$2:$AF$9999)/SUMIFS('Raw Data'!$D:$D, 'Raw Data'!$B:$B, "Variant", 'Raw Data'!$C:$C, "E. 40-99"),"") -> 23.969931 | Q19: =IFERROR((P19-O19)/ABS(O19),"") -> -0.037049453 | R19: =IFERROR(SUMPRODUCT(('Raw Data'!$B$2:$B$9999="Control")*('Raw Data'!$C$2:$C$9999="F. 100+")*'Raw Data'!$D$2:$D$9999*'Raw Data'!$AF$2:$AF$9999)/SUMIFS('Raw Data'!$D:$D, 'Raw Data'!$B:$B, "Control", 'Raw Data'!$C:$C, "F. 100+"),"") -> 46.420418 | S19: =IFERROR(SUMPRODUCT(('Raw Data'!$B$2:$B$9999="Variant")*('Raw Data'!$C$2:$C$9999="F. 100+")*'Raw Data'!$D$2:$D$9999*'Raw Data'!$AF$2:$AF$9999)/SUMIFS('Raw Data'!$D:$D, 'Raw Data'!$B:$B, "Variant", 'Raw Data'!$C:$C, "F. 100+"),"") -> 42.664959 | T19: =IFERROR((S19-R19)/ABS(R19),"") -> -0.080901007
B20: P75 daily streak | C20: =IFERROR(SUMPRODUCT(('Raw Data'!$B$2:$B$9999="Control")*('Raw Data'!$C$2:$C$9999="A. 0")*'Raw Data'!$D$2:$D$9999*'Raw Data'!$AG$2:$AG$9999)/SUMIFS('Raw Data'!$D:$D, 'Raw Data'!$B:$B, "Control", 'Raw Data'!$C:$C, "A. 0"),"") -> 0 | D20: =IFERROR(SUMPRODUCT(('Raw Data'!$B$2:$B$9999="Variant")*('Raw Data'!$C$2:$C$9999="A. 0")*'Raw Data'!$D$2:$D$9999*'Raw Data'!$AG$2:$AG$9999)/SUMIFS('Raw Data'!$D:$D, 'Raw Data'!$B:$B, "Variant", 'Raw Data'!$C:$C, "A. 0"),"") -> 0 | E20: =IFERROR((D20-C20)/ABS(C20),"") | F20: =IFERROR(SUMPRODUCT(('Raw Data'!$B$2:$B$9999="Control")*('Raw Data'!$C$2:$C$9999="B. 1-9")*'Raw Data'!$D$2:$D$9999*'Raw Data'!$AG$2:$AG$9999)/SUMIFS('Raw Data'!$D:$D, 'Raw Data'!$B:$B, "Control", 'Raw Data'!$C:$C, "B. 1-9"),"") -> 5.2819687 | G20: =IFERROR(SUMPRODUCT(('Raw Data'!$B$2:$B$9999="Variant")*('Raw Data'!$C$2:$C$9999="B. 1-9")*'Raw Data'!$D$2:$D$9999*'Raw Data'!$AG$2:$AG$9999)/SUMIFS('Raw Data'!$D:$D, 'Raw Data'!$B:$B, "Variant", 'Raw Data'!$C:$C, "B. 1-9"),"") -> 5.1451548 | H20: =IFERROR((G20-F20)/ABS(F20),"") -> -0.025902075 | I20: =IFERROR(SUMPRODUCT(('Raw Data'!$B$2:$B$9999="Control")*('Raw Data'!$C$2:$C$9999="C. 10-19")*'Raw Data'!$D$2:$D$9999*'Raw Data'!$AG$2:$AG$9999)/SUMIFS('Raw Data'!$D:$D, 'Raw Data'!$B:$B, "Control", 'Raw Data'!$C:$C, "C. 10-19"),"") -> 12.980529 | J20: =IFERROR(SUMPRODUCT(('Raw Data'!$B$2:$B$9999="Variant")*('Raw Data'!$C$2:$C$9999="C. 10-19")*'Raw Data'!$D$2:$D$9999*'Raw Data'!$AG$2:$AG$9999)/SUMIFS('Raw Data'!$D:$D, 'Raw Data'!$B:$B, "Variant", 'Raw Data'!$C:$C, "C. 10-19"),"") -> 13.013701 | K20: =IFERROR((J20-I20)/ABS(I20),"") -> 0.0025555131 | L20: =IFERROR(SUMPRODUCT(('Raw Data'!$B$2:$B$9999="Control")*('Raw Data'!$C$2:$C$9999="D. 20-39")*'Raw Data'!$D$2:$D$9999*'Raw Data'!$AG$2:$AG$9999)/SUMIFS('Raw Data'!$D:$D, 'Raw Data'!$B:$B, "Control", 'Raw Data'!$C:$C, "D. 20-39"),"") -> 24.426054 | M20: =IFERROR(SUMPRODUCT(('Raw Data'!$B$2:$B$9999="Variant")*('Raw Data'!$C$2:$C$9999="D. 20-39")*'Raw Data'!$D$2:$D$9999*'Raw Data'!$AG$2:$AG$9999)/SUMIFS('Raw Data'!$D:$D, 'Raw Data'!$B:$B, "Variant", 'Raw Data'!$C:$C, "D. 20-39"),"") -> 24.351345 | N20: =IFERROR((M20-L20)/ABS(L20),"") -> -0.0030585896 | O20: =IFERROR(SUMPRODUCT(('Raw Data'!$B$2:$B$9999="Control")*('Raw Data'!$C$2:$C$9999="E. 40-99")*'Raw Data'!$D$2:$D$9999*'Raw Data'!$AG$2:$AG$9999)/SUMIFS('Raw Data'!$D:$D, 'Raw Data'!$B:$B, "Control", 'Raw Data'!$C:$C, "E. 40-99"),"") -> 46.414631 | P20: =IFERROR(SUMPRODUCT(('Raw Data'!$B$2:$B$9999="Variant")*('Raw Data'!$C$2:$C$9999="E. 40-99")*'Raw Data'!$D$2:$D$9999*'Raw Data'!$AG$2:$AG$9999)/SUMIFS('Raw Data'!$D:$D, 'Raw Data'!$B:$B, "Variant", 'Raw Data'!$C:$C, "E. 40-99"),"") -> 44.346309 | Q20: =IFERROR((P20-O20)/ABS(O20),"") -> -0.044561856 | R20: =IFERROR(SUMPRODUCT(('Raw Data'!$B$2:$B$9999="Control")*('Raw Data'!$C$2:$C$9999="F. 100+")*'Raw Data'!$D$2:$D$9999*'Raw Data'!$AG$2:$AG$9999)/SUMIFS('Raw Data'!$D:$D, 'Raw Data'!$B:$B, "Control", 'Raw Data'!$C:$C, "F. 100+"),"") -> 96.777733 | S20: =IFERROR(SUMPRODUCT(('Raw Data'!$B$2:$B$9999="Variant")*('Raw Data'!$C$2:$C$9999="F. 100+")*'Raw Data'!$D$2:$D$9999*'Raw Data'!$AG$2:$AG$9999)/SUMIFS('Raw Data'!$D:$D, 'Raw Data'!$B:$B, "Variant", 'Raw Data'!$C:$C, "F. 100+"),"") -> 90.081519 | T20: =IFERROR((S20-R20)/ABS(R20),"") -> -0.069191678
B21: P90 daily streak | C21: =IFERROR(SUMPRODUCT(('Raw Data'!$B$2:$B$9999="Control")*('Raw Data'!$C$2:$C$9999="A. 0")*'Raw Data'!$D$2:$D$9999*'Raw Data'!$AH$2:$AH$9999)/SUMIFS('Raw Data'!$D:$D, 'Raw Data'!$B:$B, "Control", 'Raw Data'!$C:$C, "A. 0"),"") -> 0 | D21: =IFERROR(SUMPRODUCT(('Raw Data'!$B$2:$B$9999="Variant")*('Raw Data'!$C$2:$C$9999="A. 0")*'Raw Data'!$D$2:$D$9999*'Raw Data'!$AH$2:$AH$9999)/SUMIFS('Raw Data'!$D:$D, 'Raw Data'!$B:$B, "Variant", 'Raw Data'!$C:$C, "A. 0"),"") -> 0 | E21: =IFERROR((D21-C21)/ABS(C21),"") | F21: =IFERROR(SUMPRODUCT(('Raw Data'!$B$2:$B$9999="Control")*('Raw Data'!$C$2:$C$9999="B. 1-9")*'Raw Data'!$D$2:$D$9999*'Raw Data'!$AH$2:$AH$9999)/SUMIFS('Raw Data'!$D:$D, 'Raw Data'!$B:$B, "Control", 'Raw Data'!$C:$C, "B. 1-9"),"") -> 9.1425836 | G21: =IFERROR(SUMPRODUCT(('Raw Data'!$B$2:$B$9999="Variant")*('Raw Data'!$C$2:$C$9999="B. 1-9")*'Raw Data'!$D$2:$D$9999*'Raw Data'!$AH$2:$AH$9999)/SUMIFS('Raw Data'!$D:$D, 'Raw Data'!$B:$B, "Variant", 'Raw Data'!$C:$C, "B. 1-9"),"") -> 9 | H21: =IFERROR((G21-F21)/ABS(F21),"") -> -0.015595545 | I21: =IFERROR(SUMPRODUCT(('Raw Data'!$B$2:$B$9999="Control")*('Raw Data'!$C$2:$C$9999="C. 10-19")*'Raw Data'!$D$2:$D$9999*'Raw Data'!$AH$2:$AH$9999)/SUMIFS('Raw Data'!$D:$D, 'Raw Data'!$B:$B, "Control", 'Raw Data'!$C:$C, "C. 10-19"),"") -> 19.9581 | J21: =IFERROR(SUMPRODUCT(('Raw Data'!$B$2:$B$9999="Variant")*('Raw Data'!$C$2:$C$9999="C. 10-19")*'Raw Data'!$D$2:$D$9999*'Raw Data'!$AH$2:$AH$9999)/SUMIFS('Raw Data'!$D:$D, 'Raw Data'!$B:$B, "Variant", 'Raw Data'!$C:$C, "C. 10-19"),"") -> 20.167877 | K21: =IFERROR((J21-I21)/ABS(I21),"") -> 0.010510822 | L21: =IFERROR(SUMPRODUCT(('Raw Data'!$B$2:$B$9999="Control")*('Raw Data'!$C$2:$C$9999="D. 20-39")*'Raw Data'!$D$2:$D$9999*'Raw Data'!$AH$2:$AH$9999)/SUMIFS('Raw Data'!$D:$D, 'Raw Data'!$B:$B, "Control", 'Raw Data'!$C:$C, "D. 20-39"),"") -> 37.945965 | M21: =IFERROR(SUMPRODUCT(('Raw Data'!$B$2:$B$9999="Variant")*('Raw Data'!$C$2:$C$9999="D. 20-39")*'Raw Data'!$D$2:$D$9999*'Raw Data'!$AH$2:$AH$9999)/SUMIFS('Raw Data'!$D:$D, 'Raw Data'!$B:$B, "Variant", 'Raw Data'!$C:$C, "D. 20-39"),"") -> 37.615008 | N21: =IFERROR((M21-L21)/ABS(L21),"") -> -0.0087217982 | O21: =IFERROR(SUMPRODUCT(('Raw Data'!$B$2:$B$9999="Control")*('Raw Data'!$C$2:$C$9999="E. 40-99")*'Raw Data'!$D$2:$D$9999*'Raw Data'!$AH$2:$AH$9999)/SUMIFS('Raw Data'!$D:$D, 'Raw Data'!$B:$B, "Control", 'Raw Data'!$C:$C, "E. 40-99"),"") -> 74.410461 | P21: =IFERROR(SUMPRODUCT(('Raw Data'!$B$2:$B$9999="Variant")*('Raw Data'!$C$2:$C$9999="E. 40-99")*'Raw Data'!$D$2:$D$9999*'Raw Data'!$AH$2:$AH$9999)/SUMIFS('Raw Data'!$D:$D, 'Raw Data'!$B:$B, "Variant", 'Raw Data'!$C:$C, "E. 40-99"),"") -> 72.151371 | Q21: =IFERROR((P21-O21)/ABS(O21),"") -> -0.030359847 | R21: =IFERROR(SUMPRODUCT(('Raw Data'!$B$2:$B$9999="Control")*('Raw Data'!$C$2:$C$9999="F. 100+")*'Raw Data'!$D$2:$D$9999*'Raw Data'!$AH$2:$AH$9999)/SUMIFS('Raw Data'!$D:$D, 'Raw Data'!$B:$B, "Control", 'Raw Data'!$C:$C, "F. 100+"),"") -> 148.05949 | S21: =IFERROR(SUMPRODUCT(('Raw Data'!$B$2:$B$9999="Variant")*('Raw Data'!$C$2:$C$9999="F. 100+")*'Raw Data'!$D$2:$D$9999*'Raw Data'!$AH$2:$AH$9999)/SUMIFS('Raw Data'!$D:$D, 'Raw Data'!$B:$B, "Variant", 'Raw Data'!$C:$C, "F. 100+"),"") -> 150.52668 | T21: =IFERROR((S21-R21)/ABS(R21),"") -> 0.016663503
A22: Difficulty
B23: Pass rate | C23: =IFERROR(SUMPRODUCT(('Raw Data'!$B$2:$B$9999="Control")*('Raw Data'!$C$2:$C$9999="A. 0")*'Raw Data'!$D$2:$D$9999*'Raw Data'!$M$2:$M$9999)/SUMIFS('Raw Data'!$D:$D, 'Raw Data'!$B:$B, "Control", 'Raw Data'!$C:$C, "A. 0"),"") -> 0.043204451 | D23: =IFERROR(SUMPRODUCT(('Raw Data'!$B$2:$B$9999="Variant")*('Raw Data'!$C$2:$C$9999="A. 0")*'Raw Data'!$D$2:$D$9999*'Raw Data'!$M$2:$M$9999)/SUMIFS('Raw Data'!$D:$D, 'Raw Data'!$B:$B, "Variant", 'Raw Data'!$C:$C, "A. 0"),"") -> 0.034307426 | E23: =IFERROR((D23-C23)/ABS(C23),"") -> -0.20592845 | F23: =IFERROR(SUMPRODUCT(('Raw Data'!$B$2:$B$9999="Control")*('Raw Data'!$C$2:$C$9999="B. 1-9")*'Raw Data'!$D$2:$D$9999*'Raw Data'!$M$2:$M$9999)/SUMIFS('Raw Data'!$D:$D, 'Raw Data'!$B:$B, "Control", 'Raw Data'!$C:$C, "B. 1-9"),"") -> 0.39278798 | G23: =IFERROR(SUMPRODUCT(('Raw Data'!$B$2:$B$9999="Variant")*('Raw Data'!$C$2:$C$9999="B. 1-9")*'Raw Data'!$D$2:$D$9999*'Raw Data'!$M$2:$M$9999)/SUMIFS('Raw Data'!$D:$D, 'Raw Data'!$B:$B, "Variant", 'Raw Data'!$C:$C, "B. 1-9"),"") -> 0.3882988 | H23: =IFERROR((G23-F23)/ABS(F23),"") -> -0.01142901 | I23: =IFERROR(SUMPRODUCT(('Raw Data'!$B$2:$B$9999="Control")*('Raw Data'!$C$2:$C$9999="C. 10-19")*'Raw Data'!$D$2:$D$9999*'Raw Data'!$M$2:$M$9999)/SUMIFS('Raw Data'!$D:$D, 'Raw Data'!$B:$B, "Control", 'Raw Data'!$C:$C, "C. 10-19"),"") -> 0.54414751 | J23: =IFERROR(SUMPRODUCT(('Raw Data'!$B$2:$B$9999="Variant")*('Raw Data'!$C$2:$C$9999="C. 10-19")*'Raw Data'!$D$2:$D$9999*'Raw Data'!$M$2:$M$9999)/SUMIFS('Raw Data'!$D:$D, 'Raw Data'!$B:$B, "Variant", 'Raw Data'!$C:$C, "C. 10-19"),"") -> 0.52703692 | K23: =IFERROR((J23-I23)/ABS(I23),"") -> -0.031444765 | L23: =IFERROR(SUMPRODUCT(('Raw Data'!$B$2:$B$9999="Control")*('Raw Data'!$C$2:$C$9999="D. 20-39")*'Raw Data'!$D$2:$D$9999*'Raw Data'!$M$2:$M$9999)/SUMIFS('Raw Data'!$D:$D, 'Raw Data'!$B:$B, "Control", 'Raw Data'!$C:$C, "D. 20-39"),"") -> 0.6741993 | M23: =IFERROR(SUMPRODUCT(('Raw Data'!$B$2:$B$9999="Variant")*('Raw Data'!$C$2:$C$9999="D. 20-39")*'Raw Data'!$D$2:$D$9999*'Raw Data'!$M$2:$M$9999)/SUMIFS('Raw Data'!$D:$D, 'Raw Data'!$B:$B, "Variant", 'Raw Data'!$C:$C, "D. 20-39"),"") -> 0.65903121 | N23: =IFERROR((M23-L23)/ABS(L23),"") -> -0.022497931 | O23: =IFERROR(SUMPRODUCT(('Raw Data'!$B$2:$B$9999="Control")*('Raw Data'!$C$2:$C$9999="E. 40-99")*'Raw Data'!$D$2:$D$9999*'Raw Data'!$M$2:$M$9999)/SUMIFS('Raw Data'!$D:$D, 'Raw Data'!$B:$B, "Control", 'Raw Data'!$C:$C, "E. 40-99"),"") -> 0.75409219 | P23: =IFERROR(SUMPRODUCT(('Raw Data'!$B$2:$B$9999="Variant")*('Raw Data'!$C$2:$C$9999="E. 40-99")*'Raw Data'!$D$2:$D$9999*'Raw Data'!$M$2:$M$9999)/SUMIFS('Raw Data'!$D:$D, 'Raw Data'!$B:$B, "Variant", 'Raw Data'!$C:$C, "E. 40-99"),"") -> 0.74696371 | Q23: =IFERROR((P23-O23)/ABS(O23),"") -> -0.009453059 | R23: =IFERROR(SUMPRODUCT(('Raw Data'!$B$2:$B$9999="Control")*('Raw Data'!$C$2:$C$9999="F. 100+")*'Raw Data'!$D$2:$D$9999*'Raw Data'!$M$2:$M$9999)/SUMIFS('Raw Data'!$D:$D, 'Raw Data'!$B:$B, "Control", 'Raw Data'!$C:$C, "F. 100+"),"") -> 0.82801379 | S23: =IFERROR(SUMPRODUCT(('Raw Data'!$B$2:$B$9999="Variant")*('Raw Data'!$C$2:$C$9999="F. 100+")*'Raw Data'!$D$2:$D$9999*'Raw Data'!$M$2:$M$9999)/SUMIFS('Raw Data'!$D:$D, 'Raw Data'!$B:$B, "Variant", 'Raw Data'!$C:$C, "F. 100+"),"") -> 0.8129411 | T23: =IFERROR((S23-R23)/ABS(R23),"") -> -0.018203423
B24: OOM rate | C24: =IFERROR(SUMPRODUCT(('Raw Data'!$B$2:$B$9999="Control")*('Raw Data'!$C$2:$C$9999="A. 0")*'Raw Data'!$D$2:$D$9999*'Raw Data'!$N$2:$N$9999)/SUMIFS('Raw Data'!$D:$D, 'Raw Data'!$B:$B, "Control", 'Raw Data'!$C:$C, "A. 0"),"") -> 0.96253898 | D24: =IFERROR(SUMPRODUCT(('Raw Data'!$B$2:$B$9999="Variant")*('Raw Data'!$C$2:$C$9999="A. 0")*'Raw Data'!$D$2:$D$9999*'Raw Data'!$N$2:$N$9999)/SUMIFS('Raw Data'!$D:$D, 'Raw Data'!$B:$B, "Variant", 'Raw Data'!$C:$C, "A. 0"),"") -> 0.97222892 | E24: =IFERROR((D24-C24)/ABS(C24),"") -> 0.010067064 | F24: =IFERROR(SUMPRODUCT(('Raw Data'!$B$2:$B$9999="Control")*('Raw Data'!$C$2:$C$9999="B. 1-9")*'Raw Data'!$D$2:$D$9999*'Raw Data'!$N$2:$N$9999)/SUMIFS('Raw Data'!$D:$D, 'Raw Data'!$B:$B, "Control", 'Raw Data'!$C:$C, "B. 1-9"),"") -> 0.73621247 | G24: =IFERROR(SUMPRODUCT(('Raw Data'!$B$2:$B$9999="Variant")*('Raw Data'!$C$2:$C$9999="B. 1-9")*'Raw Data'!$D$2:$D$9999*'Raw Data'!$N$2:$N$9999)/SUMIFS('Raw Data'!$D:$D, 'Raw Data'!$B:$B, "Variant", 'Raw Data'!$C:$C, "B. 1-9"),"") -> 0.7376751 | H24: =IFERROR((G24-F24)/ABS(F24),"") -> 0.0019866891 | I24: =IFERROR(SUMPRODUCT(('Raw Data'!$B$2:$B$9999="Control")*('Raw Data'!$C$2:$C$9999="C. 10-19")*'Raw Data'!$D$2:$D$9999*'Raw Data'!$N$2:$N$9999)/SUMIFS('Raw Data'!$D:$D, 'Raw Data'!$B:$B, "Control", 'Raw Data'!$C:$C, "C. 10-19"),"") -> 0.61209578 | J24: =IFERROR(SUMPRODUCT(('Raw Data'!$B$2:$B$9999="Variant")*('Raw Data'!$C$2:$C$9999="C. 10-19")*'Raw Data'!$D$2:$D$9999*'Raw Data'!$N$2:$N$9999)/SUMIFS('Raw Data'!$D:$D, 'Raw Data'!$B:$B, "Variant", 'Raw Data'!$C:$C, "C. 10-19"),"") -> 0.62387463 | K24: =IFERROR((J24-I24)/ABS(I24),"") -> 0.019243484 | L24: =IFERROR(SUMPRODUCT(('Raw Data'!$B$2:$B$9999="Control")*('Raw Data'!$C$2:$C$9999="D. 20-39")*'Raw Data'!$D$2:$D$9999*'Raw Data'!$N$2:$N$9999)/SUMIFS('Raw Data'!$D:$D, 'Raw Data'!$B:$B, "Control", 'Raw Data'!$C:$C, "D. 20-39"),"") -> 0.49060209 | M24: =IFERROR(SUMPRODUCT(('Raw Data'!$B$2:$B$9999="Variant")*('Raw Data'!$C$2:$C$9999="D. 20-39")*'Raw Data'!$D$2:$D$9999*'Raw Data'!$N$2:$N$9999)/SUMIFS('Raw Data'!$D:$D, 'Raw Data'!$B:$B, "Variant", 'Raw Data'!$C:$C, "D. 20-39"),"") -> 0.50362104 | N24: =IFERROR((M24-L24)/ABS(L24),"") -> 0.026536686 | O24: =IFERROR(SUMPRODUCT(('Raw Data'!$B$2:$B$9999="Control")*('Raw Data'!$C$2:$C$9999="E. 40-99")*'Raw Data'!$D$2:$D$9999*'Raw Data'!$N$2:$N$9999)/SUMIFS('Raw Data'!$D:$D, 'Raw Data'!$B:$B, "Control", 'Raw Data'!$C:$C, "E. 40-99"),"") -> 0.39978795 | P24: =IFERROR(SUMPRODUCT(('Raw Data'!$B$2:$B$9999="Variant")*('Raw Data'!$C$2:$C$9999="E. 40-99")*'Raw Data'!$D$2:$D$9999*'Raw Data'!$N$2:$N$9999)/SUMIFS('Raw Data'!$D:$D, 'Raw Data'!$B:$B, "Variant", 'Raw Data'!$C:$C, "E. 40-99"),"") -> 0.40718959 | Q24: =IFERROR((P24-O24)/ABS(O24),"") -> 0.018513912 | R24: =IFERROR(SUMPRODUCT(('Raw Data'!$B$2:$B$9999="Control")*('Raw Data'!$C$2:$C$9999="F. 100+")*'Raw Data'!$D$2:$D$9999*'Raw Data'!$N$2:$N$9999)/SUMIFS('Raw Data'!$D:$D, 'Raw Data'!$B:$B, "Control", 'Raw Data'!$C:$C, "F. 100+"),"") -> 0.31380719 | S24: =IFERROR(SUMPRODUCT(('Raw Data'!$B$2:$B$9999="Variant")*('Raw Data'!$C$2:$C$9999="F. 100+")*'Raw Data'!$D$2:$D$9999*'Raw Data'!$N$2:$N$9999)/SUMIFS('Raw Data'!$D:$D, 'Raw Data'!$B:$B, "Variant", 'Raw Data'!$C:$C, "F. 100+"),"") -> 0.3291936 | T24: =IFERROR((S24-R24)/ABS(R24),"") -> 0.049031392
B25: First-try OOM rate | C25: =IFERROR(SUMPRODUCT(('Raw Data'!$B$2:$B$9999="Control")*('Raw Data'!$C$2:$C$9999="A. 0")*'Raw Data'!$D$2:$D$9999*'Raw Data'!$O$2:$O$9999)/SUMIFS('Raw Data'!$D:$D, 'Raw Data'!$B:$B, "Control", 'Raw Data'!$C:$C, "A. 0"),"") -> 0.68893428 | D25: =IFERROR(SUMPRODUCT(('Raw Data'!$B$2:$B$9999="Variant")*('Raw Data'!$C$2:$C$9999="A. 0")*'Raw Data'!$D$2:$D$9999*'Raw Data'!$O$2:$O$9999)/SUMIFS('Raw Data'!$D:$D, 'Raw Data'!$B:$B, "Variant", 'Raw Data'!$C:$C, "A. 0"),"") -> 0.72933158 | E25: =IFERROR((D25-C25)/ABS(C25),"") -> 0.058637372 | F25: =IFERROR(SUMPRODUCT(('Raw Data'!$B$2:$B$9999="Control")*('Raw Data'!$C$2:$C$9999="B. 1-9")*'Raw Data'!$D$2:$D$9999*'Raw Data'!$O$2:$O$9999)/SUMIFS('Raw Data'!$D:$D, 'Raw Data'!$B:$B, "Control", 'Raw Data'!$C:$C, "B. 1-9"),"") -> 0.51329685 | G25: =IFERROR(SUMPRODUCT(('Raw Data'!$B$2:$B$9999="Variant")*('Raw Data'!$C$2:$C$9999="B. 1-9")*'Raw Data'!$D$2:$D$9999*'Raw Data'!$O$2:$O$9999)/SUMIFS('Raw Data'!$D:$D, 'Raw Data'!$B:$B, "Variant", 'Raw Data'!$C:$C, "B. 1-9"),"") -> 0.50997797 | H25: =IFERROR((G25-F25)/ABS(F25),"") -> -0.0064658226 | I25: =IFERROR(SUMPRODUCT(('Raw Data'!$B$2:$B$9999="Control")*('Raw Data'!$C$2:$C$9999="C. 10-19")*'Raw Data'!$D$2:$D$9999*'Raw Data'!$O$2:$O$9999)/SUMIFS('Raw Data'!$D:$D, 'Raw Data'!$B:$B, "Control", 'Raw Data'!$C:$C, "C. 10-19"),"") -> 0.40639881 | J25: =IFERROR(SUMPRODUCT(('Raw Data'!$B$2:$B$9999="Variant")*('Raw Data'!$C$2:$C$9999="C. 10-19")*'Raw Data'!$D$2:$D$9999*'Raw Data'!$O$2:$O$9999)/SUMIFS('Raw Data'!$D:$D, 'Raw Data'!$B:$B, "Variant", 'Raw Data'!$C:$C, "C. 10-19"),"") -> 0.40849604 | K25: =IFERROR((J25-I25)/ABS(I25),"") -> 0.0051605312 | L25: =IFERROR(SUMPRODUCT(('Raw Data'!$B$2:$B$9999="Control")*('Raw Data'!$C$2:$C$9999="D. 20-39")*'Raw Data'!$D$2:$D$9999*'Raw Data'!$O$2:$O$9999)/SUMIFS('Raw Data'!$D:$D, 'Raw Data'!$B:$B, "Control", 'Raw Data'!$C:$C, "D. 20-39"),"") -> 0.3328279 | M25: =IFERROR(SUMPRODUCT(('Raw Data'!$B$2:$B$9999="Variant")*('Raw Data'!$C$2:$C$9999="D. 20-39")*'Raw Data'!$D$2:$D$9999*'Raw Data'!$O$2:$O$9999)/SUMIFS('Raw Data'!$D:$D, 'Raw Data'!$B:$B, "Variant", 'Raw Data'!$C:$C, "D. 20-39"),"") -> 0.33725834 | N25: =IFERROR((M25-L25)/ABS(L25),"") -> 0.013311486 | O25: =IFERROR(SUMPRODUCT(('Raw Data'!$B$2:$B$9999="Control")*('Raw Data'!$C$2:$C$9999="E. 40-99")*'Raw Data'!$D$2:$D$9999*'Raw Data'!$O$2:$O$9999)/SUMIFS('Raw Data'!$D:$D, 'Raw Data'!$B:$B, "Control", 'Raw Data'!$C:$C, "E. 40-99"),"") -> 0.27983061 | P25: =IFERROR(SUMPRODUCT(('Raw Data'!$B$2:$B$9999="Variant")*('Raw Data'!$C$2:$C$9999="E. 40-99")*'Raw Data'!$D$2:$D$9999*'Raw Data'!$O$2:$O$9999)/SUMIFS('Raw Data'!$D:$D, 'Raw Data'!$B:$B, "Variant", 'Raw Data'!$C:$C, "E. 40-99"),"") -> 0.28572386 | Q25: =IFERROR((P25-O25)/ABS(O25),"") -> 0.021060054 | R25: =IFERROR(SUMPRODUCT(('Raw Data'!$B$2:$B$9999="Control")*('Raw Data'!$C$2:$C$9999="F. 100+")*'Raw Data'!$D$2:$D$9999*'Raw Data'!$O$2:$O$9999)/SUMIFS('Raw Data'!$D:$D, 'Raw Data'!$B:$B, "Control", 'Raw Data'!$C:$C, "F. 100+"),"") -> 0.23806849 | S25: =IFERROR(SUMPRODUCT(('Raw Data'!$B$2:$B$9999="Variant")*('Raw Data'!$C$2:$C$9999="F. 100+")*'Raw Data'!$D$2:$D$9999*'Raw Data'!$O$2:$O$9999)/SUMIFS('Raw Data'!$D:$D, 'Raw Data'!$B:$B, "Variant", 'Raw Data'!$C:$C, "F. 100+"),"") -> 0.2473207 | T25: =IFERROR((S25-R25)/ABS(R25),"") -> 0.038863653 | V25: todo
B26: Attempts per completion | C26: =IFERROR(SUMPRODUCT(('Raw Data'!$B$2:$B$9999="Control")*('Raw Data'!$C$2:$C$9999="A. 0")*'Raw Data'!$D$2:$D$9999*'Raw Data'!$P$2:$P$9999)/SUMIFS('Raw Data'!$D:$D, 'Raw Data'!$B:$B, "Control", 'Raw Data'!$C:$C, "A. 0"),"") -> 80.98766 | D26: =IFERROR(SUMPRODUCT(('Raw Data'!$B$2:$B$9999="Variant")*('Raw Data'!$C$2:$C$9999="A. 0")*'Raw Data'!$D$2:$D$9999*'Raw Data'!$P$2:$P$9999)/SUMIFS('Raw Data'!$D:$D, 'Raw Data'!$B:$B, "Variant", 'Raw Data'!$C:$C, "A. 0"),"") -> 142.61531 | E26: =IFERROR((D26-C26)/ABS(C26),"") -> 0.76095109 | F26: =IFERROR(SUMPRODUCT(('Raw Data'!$B$2:$B$9999="Control")*('Raw Data'!$C$2:$C$9999="B. 1-9")*'Raw Data'!$D$2:$D$9999*'Raw Data'!$P$2:$P$9999)/SUMIFS('Raw Data'!$D:$D, 'Raw Data'!$B:$B, "Control", 'Raw Data'!$C:$C, "B. 1-9"),"") -> 2.5508191 | G26: =IFERROR(SUMPRODUCT(('Raw Data'!$B$2:$B$9999="Variant")*('Raw Data'!$C$2:$C$9999="B. 1-9")*'Raw Data'!$D$2:$D$9999*'Raw Data'!$P$2:$P$9999)/SUMIFS('Raw Data'!$D:$D, 'Raw Data'!$B:$B, "Variant", 'Raw Data'!$C:$C, "B. 1-9"),"") -> 2.5771259 | H26: =IFERROR((G26-F26)/ABS(F26),"") -> 0.01031308 | I26: =IFERROR(SUMPRODUCT(('Raw Data'!$B$2:$B$9999="Control")*('Raw Data'!$C$2:$C$9999="C. 10-19")*'Raw Data'!$D$2:$D$9999*'Raw Data'!$P$2:$P$9999)/SUMIFS('Raw Data'!$D:$D, 'Raw Data'!$B:$B, "Control", 'Raw Data'!$C:$C, "C. 10-19"),"") -> 1.8396824 | J26: =IFERROR(SUMPRODUCT(('Raw Data'!$B$2:$B$9999="Variant")*('Raw Data'!$C$2:$C$9999="C. 10-19")*'Raw Data'!$D$2:$D$9999*'Raw Data'!$P$2:$P$9999)/SUMIFS('Raw Data'!$D:$D, 'Raw Data'!$B:$B, "Variant", 'Raw Data'!$C:$C, "C. 10-19"),"") -> 1.8978615 | K26: =IFERROR((J26-I26)/ABS(I26),"") -> 0.031624568 | L26: =IFERROR(SUMPRODUCT(('Raw Data'!$B$2:$B$9999="Control")*('Raw Data'!$C$2:$C$9999="D. 20-39")*'Raw Data'!$D$2:$D$9999*'Raw Data'!$P$2:$P$9999)/SUMIFS('Raw Data'!$D:$D, 'Raw Data'!$B:$B, "Control", 'Raw Data'!$C:$C, "D. 20-39"),"") -> 1.484143 | M26: =IFERROR(SUMPRODUCT(('Raw Data'!$B$2:$B$9999="Variant")*('Raw Data'!$C$2:$C$9999="D. 20-39")*'Raw Data'!$D$2:$D$9999*'Raw Data'!$P$2:$P$9999)/SUMIFS('Raw Data'!$D:$D, 'Raw Data'!$B:$B, "Variant", 'Raw Data'!$C:$C, "D. 20-39"),"") -> 1.5179495 | N26: =IFERROR((M26-L26)/ABS(L26),"") -> 0.022778513 | O26: =IFERROR(SUMPRODUCT(('Raw Data'!$B$2:$B$9999="Control")*('Raw Data'!$C$2:$C$9999="E. 40-99")*'Raw Data'!$D$2:$D$9999*'Raw Data'!$P$2:$P$9999)/SUMIFS('Raw Data'!$D:$D, 'Raw Data'!$B:$B, "Control", 'Raw Data'!$C:$C, "E. 40-99"),"") -> 1.3265486 | P26: =IFERROR(SUMPRODUCT(('Raw Data'!$B$2:$B$9999="Variant")*('Raw Data'!$C$2:$C$9999="E. 40-99")*'Raw Data'!$D$2:$D$9999*'Raw Data'!$P$2:$P$9999)/SUMIFS('Raw Data'!$D:$D, 'Raw Data'!$B:$B, "Variant", 'Raw Data'!$C:$C, "E. 40-99"),"") -> 1.3389506 | Q26: =IFERROR((P26-O26)/ABS(O26),"") -> 0.0093491046 | R26: =IFERROR(SUMPRODUCT(('Raw Data'!$B$2:$B$9999="Control")*('Raw Data'!$C$2:$C$9999="F. 100+")*'Raw Data'!$D$2:$D$9999*'Raw Data'!$P$2:$P$9999)/SUMIFS('Raw Data'!$D:$D, 'Raw Data'!$B:$B, "Control", 'Raw Data'!$C:$C, "F. 100+"),"") -> 1.208009 | S26: =IFERROR(SUMPRODUCT(('Raw Data'!$B$2:$B$9999="Variant")*('Raw Data'!$C$2:$C$9999="F. 100+")*'Raw Data'!$D$2:$D$9999*'Raw Data'!$P$2:$P$9999)/SUMIFS('Raw Data'!$D:$D, 'Raw Data'!$B:$B, "Variant", 'Raw Data'!$C:$C, "F. 100+"),"") -> 1.2302382 | T26: =IFERROR((S26-R26)/ABS(R26),"") -> 0.018401481 | V26: NS reward increase (careful wiht 100+)
A27: HC Economy | V27: look into 100+ net
B28: HC gain total / player | C28: =IFERROR(SUMPRODUCT(('Raw Data'!$B$2:$B$9999="Control")*('Raw Data'!$C$2:$C$9999="A. 0")*'Raw Data'!$D$2:$D$9999*'Raw Data'!$Q$2:$Q$9999)/SUMIFS('Raw Data'!$D:$D, 'Raw Data'!$B:$B, "Control", 'Raw Data'!$C:$C, "A. 0"),"") -> 25.223021 | D28: =IFERROR(SUMPRODUCT(('Raw Data'!$B$2:$B$9999="Variant")*('Raw Data'!$C$2:$C$9999="A. 0")*'Raw Data'!$D$2:$D$9999*'Raw Data'!$Q$2:$Q$9999)/SUMIFS('Raw Data'!$D:$D, 'Raw Data'!$B:$B, "Variant", 'Raw Data'!$C:$C, "A. 0"),"") -> 21.134658 | E28: =IFERROR((D28-C28)/ABS(C28),"") -> -0.16208855 | F28: =IFERROR(SUMPRODUCT(('Raw Data'!$B$2:$B$9999="Control")*('Raw Data'!$C$2:$C$9999="B. 1-9")*'Raw Data'!$D$2:$D$9999*'Raw Data'!$Q$2:$Q$9999)/SUMIFS('Raw Data'!$D:$D, 'Raw Data'!$B:$B, "Control", 'Raw Data'!$C:$C, "B. 1-9"),"") -> 59.656549 | G28: =IFERROR(SUMPRODUCT(('Raw Data'!$B$2:$B$9999="Variant")*('Raw Data'!$C$2:$C$9999="B. 1-9")*'Raw Data'!$D$2:$D$9999*'Raw Data'!$Q$2:$Q$9999)/SUMIFS('Raw Data'!$D:$D, 'Raw Data'!$B:$B, "Variant", 'Raw Data'!$C:$C, "B. 1-9"),"") -> 54.719125 | H28: =IFERROR((G28-F28)/ABS(F28),"") -> -0.082764143 | I28: =IFERROR(SUMPRODUCT(('Raw Data'!$B$2:$B$9999="Control")*('Raw Data'!$C$2:$C$9999="C. 10-19")*'Raw Data'!$D$2:$D$9999*'Raw Data'!$Q$2:$Q$9999)/SUMIFS('Raw Data'!$D:$D, 'Raw Data'!$B:$B, "Control", 'Raw Data'!$C:$C, "C. 10-19"),"") -> 111.19809 | J28: =IFERROR(SUMPRODUCT(('Raw Data'!$B$2:$B$9999="Variant")*('Raw Data'!$C$2:$C$9999="C. 10-19")*'Raw Data'!$D$2:$D$9999*'Raw Data'!$Q$2:$Q$9999)/SUMIFS('Raw Data'!$D:$D, 'Raw Data'!$B:$B, "Variant", 'Raw Data'!$C:$C, "C. 10-19"),"") -> 102.03001 | K28: =IFERROR((J28-I28)/ABS(I28),"") -> -0.082448232 | L28: =IFERROR(SUMPRODUCT(('Raw Data'!$B$2:$B$9999="Control")*('Raw Data'!$C$2:$C$9999="D. 20-39")*'Raw Data'!$D$2:$D$9999*'Raw Data'!$Q$2:$Q$9999)/SUMIFS('Raw Data'!$D:$D, 'Raw Data'!$B:$B, "Control", 'Raw Data'!$C:$C, "D. 20-39"),"") -> 198.04659 | M28: =IFERROR(SUMPRODUCT(('Raw Data'!$B$2:$B$9999="Variant")*('Raw Data'!$C$2:$C$9999="D. 20-39")*'Raw Data'!$D$2:$D$9999*'Raw Data'!$Q$2:$Q$9999)/SUMIFS('Raw Data'!$D:$D, 'Raw Data'!$B:$B, "Variant", 'Raw Data'!$C:$C, "D. 20-39"),"") -> 183.42344 | N28: =IFERROR((M28-L28)/ABS(L28),"") -> -0.073836903 | O28: =IFERROR(SUMPRODUCT(('Raw Data'!$B$2:$B$9999="Control")*('Raw Data'!$C$2:$C$9999="E. 40-99")*'Raw Data'!$D$2:$D$9999*'Raw Data'!$Q$2:$Q$9999)/SUMIFS('Raw Data'!$D:$D, 'Raw Data'!$B:$B, "Control", 'Raw Data'!$C:$C, "E. 40-99"),"") -> 363.99016 | P28: =IFERROR(SUMPRODUCT(('Raw Data'!$B$2:$B$9999="Variant")*('Raw Data'!$C$2:$C$9999="E. 40-99")*'Raw Data'!$D$2:$D$9999*'Raw Data'!$Q$2:$Q$9999)/SUMIFS('Raw Data'!$D:$D, 'Raw Data'!$B:$B, "Variant", 'Raw Data'!$C:$C, "E. 40-99"),"") -> 340.30097 | Q28: =IFERROR((P28-O28)/ABS(O28),"") -> -0.065081971 | R28: =IFERROR(SUMPRODUCT(('Raw Data'!$B$2:$B$9999="Control")*('Raw Data'!$C$2:$C$9999="F. 100+")*'Raw Data'!$D$2:$D$9999*'Raw Data'!$Q$2:$Q$9999)/SUMIFS('Raw Data'!$D:$D, 'Raw Data'!$B:$B, "Control", 'Raw Data'!$C:$C, "F. 100+"),"") -> 662.96494 | S28: =IFERROR(SUMPRODUCT(('Raw Data'!$B$2:$B$9999="Variant")*('Raw Data'!$C$2:$C$9999="F. 100+")*'Raw Data'!$D$2:$D$9999*'Raw Data'!$Q$2:$Q$9999)/SUMIFS('Raw Data'!$D:$D, 'Raw Data'!$B:$B, "Variant", 'Raw Data'!$C:$C, "F. 100+"),"") -> 618.50246 | T28: =IFERROR((S28-R28)/ABS(R28),"") -> -0.067066113 | V28: Booster analysis
B29: HC gain PAID / player | C29: =IFERROR(SUMPRODUCT(('Raw Data'!$B$2:$B$9999="Control")*('Raw Data'!$C$2:$C$9999="A. 0")*'Raw Data'!$D$2:$D$9999*'Raw Data'!$T$2:$T$9999)/SUMIFS('Raw Data'!$D:$D, 'Raw Data'!$B:$B, "Control", 'Raw Data'!$C:$C, "A. 0"),"") -> 0.17192909 | D29: =IFERROR(SUMPRODUCT(('Raw Data'!$B$2:$B$9999="Variant")*('Raw Data'!$C$2:$C$9999="A. 0")*'Raw Data'!$D$2:$D$9999*'Raw Data'!$T$2:$T$9999)/SUMIFS('Raw Data'!$D:$D, 'Raw Data'!$B:$B, "Variant", 'Raw Data'!$C:$C, "A. 0"),"") -> 0.61063228 | E29: =IFERROR((D29-C29)/ABS(C29),"") -> 2.551652 | F29: =IFERROR(SUMPRODUCT(('Raw Data'!$B$2:$B$9999="Control")*('Raw Data'!$C$2:$C$9999="B. 1-9")*'Raw Data'!$D$2:$D$9999*'Raw Data'!$T$2:$T$9999)/SUMIFS('Raw Data'!$D:$D, 'Raw Data'!$B:$B, "Control", 'Raw Data'!$C:$C, "B. 1-9"),"") -> 2.7446198 | G29: =IFERROR(SUMPRODUCT(('Raw Data'!$B$2:$B$9999="Variant")*('Raw Data'!$C$2:$C$9999="B. 1-9")*'Raw Data'!$D$2:$D$9999*'Raw Data'!$T$2:$T$9999)/SUMIFS('Raw Data'!$D:$D, 'Raw Data'!$B:$B, "Variant", 'Raw Data'!$C:$C, "B. 1-9"),"") -> 2.639285 | H29: =IFERROR((G29-F29)/ABS(F29),"") -> -0.038378622 | I29: =IFERROR(SUMPRODUCT(('Raw Data'!$B$2:$B$9999="Control")*('Raw Data'!$C$2:$C$9999="C. 10-19")*'Raw Data'!$D$2:$D$9999*'Raw Data'!$T$2:$T$9999)/SUMIFS('Raw Data'!$D:$D, 'Raw Data'!$B:$B, "Control", 'Raw Data'!$C:$C, "C. 10-19"),"") -> 9.2873399 | J29: =IFERROR(SUMPRODUCT(('Raw Data'!$B$2:$B$9999="Variant")*('Raw Data'!$C$2:$C$9999="C. 10-19")*'Raw Data'!$D$2:$D$9999*'Raw Data'!$T$2:$T$9999)/SUMIFS('Raw Data'!$D:$D, 'Raw Data'!$B:$B, "Variant", 'Raw Data'!$C:$C, "C. 10-19"),"") -> 9.1106474 | K29: =IFERROR((J29-I29)/ABS(I29),"") -> -0.019025099 | L29: =IFERROR(SUMPRODUCT(('Raw Data'!$B$2:$B$9999="Control")*('Raw Data'!$C$2:$C$9999="D. 20-39")*'Raw Data'!$D$2:$D$9999*'Raw Data'!$T$2:$T$9999)/SUMIFS('Raw Data'!$D:$D, 'Raw Data'!$B:$B, "Control", 'Raw Data'!$C:$C, "D. 20-39"),"") -> 22.32101 | M29: =IFERROR(SUMPRODUCT(('Raw Data'!$B$2:$B$9999="Variant")*('Raw Data'!$C$2:$C$9999="D. 20-39")*'Raw Data'!$D$2:$D$9999*'Raw Data'!$T$2:$T$9999)/SUMIFS('Raw Data'!$D:$D, 'Raw Data'!$B:$B, "Variant", 'Raw Data'!$C:$C, "D. 20-39"),"") -> 20.120028 | N29: =IFERROR((M29-L29)/ABS(L29),"") -> -0.098605853 | O29: =IFERROR(SUMPRODUCT(('Raw Data'!$B$2:$B$9999="Control")*('Raw Data'!$C$2:$C$9999="E. 40-99")*'Raw Data'!$D$2:$D$9999*'Raw Data'!$T$2:$T$9999)/SUMIFS('Raw Data'!$D:$D, 'Raw Data'!$B:$B, "Control", 'Raw Data'!$C:$C, "E. 40-99"),"") -> 39.245935 | P29: =IFERROR(SUMPRODUCT(('Raw Data'!$B$2:$B$9999="Variant")*('Raw Data'!$C$2:$C$9999="E. 40-99")*'Raw Data'!$D$2:$D$9999*'Raw Data'!$T$2:$T$9999)/SUMIFS('Raw Data'!$D:$D, 'Raw Data'!$B:$B, "Variant", 'Raw Data'!$C:$C, "E. 40-99"),"") -> 39.460642 | Q29: =IFERROR((P29-O29)/ABS(O29),"") -> 0.0054708101 | R29: =IFERROR(SUMPRODUCT(('Raw Data'!$B$2:$B$9999="Control")*('Raw Data'!$C$2:$C$9999="F. 100+")*'Raw Data'!$D$2:$D$9999*'Raw Data'!$T$2:$T$9999)/SUMIFS('Raw Data'!$D:$D, 'Raw Data'!$B:$B, "Control", 'Raw Data'!$C:$C, "F. 100+"),"") -> 56.229317 | S29: =IFERROR(SUMPRODUCT(('Raw Data'!$B$2:$B$9999="Variant")*('Raw Data'!$C$2:$C$9999="F. 100+")*'Raw Data'!$D$2:$D$9999*'Raw Data'!$T$2:$T$9999)/SUMIFS('Raw Data'!$D:$D, 'Raw Data'!$B:$B, "Variant", 'Raw Data'!$C:$C, "F. 100+"),"") -> 61.049927 | T29: =IFERROR((S29-R29)/ABS(R29),"") -> 0.08573127 | V29: ulbs
