Workbook

Sheet By Bucket
A1: A/B Test Summary By 7d Completion Bucket
A3: Category | B3: Metric | C3: 0 | F3: 1-9 | I3: 10-19 | L3: 20-39 | O3: 40-99 | R3: 100+
C4: Control | D4: Variant | E4: Δ % | F4: Control | G4: Variant | H4: Δ % | I4: Control | J4: Variant | K4: Δ % | L4: Control | M4: Variant | N4: Δ % | O4: Control | P4: Variant | Q4: Δ % | R4: Control | S4: Variant | T4: Δ %
A5: Players
B6: Players (sum) | C6: =SUMIFS(Raw_Data_Daily!$D:$D, Raw_Data_Daily!$B:$B, "Control", Raw_Data_Daily!$C:$C, "A. 0") -> 37219 | D6: =SUMIFS(Raw_Data_Daily!$D:$D, Raw_Data_Daily!$B:$B, "Variant", Raw_Data_Daily!$C:$C, "A. 0") -> 36892 | E6: =IFERROR((D6-C6)/ABS(C6),"") -> -0.0087858352 | F6: =SUMIFS(Raw_Data_Daily!$D:$D, Raw_Data_Daily!$B:$B, "Control", Raw_Data_Daily!$C:$C, "B. 1-9") -> 52186 | G6: =SUMIFS(Raw_Data_Daily!$D:$D, Raw_Data_Daily!$B:$B, "Variant", Raw_Data_Daily!$C:$C, "B. 1-9") -> 52224 | H6: =IFERROR((G6-F6)/ABS(F6),"") -> 0.00072816464 | I6: =SUMIFS(Raw_Data_Daily!$D:$D, Raw_Data_Daily!$B:$B, "Control", Raw_Data_Daily!$C:$C, "C. 10-19") -> 41272 | J6: =SUMIFS(Raw_Data_Daily!$D:$D, Raw_Data_Daily!$B:$B, "Variant", Raw_Data_Daily!$C:$C, "C. 10-19") -> 41673 | K6: =IFERROR((J6-I6)/ABS(I6),"") -> 0.0097160302 | L6: =SUMIFS(Raw_Data_Daily!$D:$D, Raw_Data_Daily!$B:$B, "Control", Raw_Data_Daily!$C:$C, "D. 20-39") -> 32231 | M6: =SUMIFS(Raw_Data_Daily!$D:$D, Raw_Data_Daily!$B:$B, "Variant", Raw_Data_Daily!$C:$C, "D. 20-39") -> 31954 | N6: =IFERROR((M6-L6)/ABS(L6),"") -> -0.0085942105 | O6: =SUMIFS(Raw_Data_Daily!$D:$D, Raw_Data_Daily!$B:$B, "Control", Raw_Data_Daily!$C:$C, "E. 40-99") -> 18255 | P6: =SUMIFS(Raw_Data_Daily!$D:$D, Raw_Data_Daily!$B:$B, "Variant", Raw_Data_Daily!$C:$C, "E. 40-99") -> 17364 | Q6: =IFERROR((P6-O6)/ABS(O6),"") -> -0.048808546 | R6: =SUMIFS(Raw_Data_Daily!$D:$D, Raw_Data_Daily!$B:$B, "Control", Raw_Data_Daily!$C:$C, "F. 100+") -> 2672 | S6: =SUMIFS(Raw_Data_Daily!$D:$D, Raw_Data_Daily!$B:$B, "Variant", Raw_Data_Daily!$C:$C, "F. 100+") -> 2405 | T6: =IFERROR((S6-R6)/ABS(R6),"") -> -0.09992515
A7: Revenue
B8: Total revenue | C8: =SUMIFS(Raw_Data_Daily!$F:$F, Raw_Data_Daily!$B:$B, "Control", Raw_Data_Daily!$C:$C, "A. 0") -> 3422.13 | D8: =SUMIFS(Raw_Data_Daily!$F:$F, Raw_Data_Daily!$B:$B, "Variant", Raw_Data_Daily!$C:$C, "A. 0") -> 3941.97 | E8: =IFERROR((D8-C8)/ABS(C8),"") -> 0.15190539 | F8: =SUMIFS(Raw_Data_Daily!$F:$F, Raw_Data_Daily!$B:$B, "Control", Raw_Data_Daily!$C:$C, "B. 1-9") -> 1483.5 | G8: =SUMIFS(Raw_Data_Daily!$F:$F, Raw_Data_Daily!$B:$B, "Variant", Raw_Data_Daily!$C:$C, "B. 1-9") -> 1360.84 | H8: =IFERROR((G8-F8)/ABS(F8),"") -> -0.082682845 | I8: =SUMIFS(Raw_Data_Daily!$F:$F, Raw_Data_Daily!$B:$B, "Control", Raw_Data_Daily!$C:$C, "C. 10-19") -> 4052.57 | J8: =SUMIFS(Raw_Data_Daily!$F:$F, Raw_Data_Daily!$B:$B, "Variant", Raw_Data_Daily!$C:$C, "C. 10-19") -> 4051.34 | K8: =IFERROR((J8-I8)/ABS(I8),"") -> -0.00030351111 | L8: =SUMIFS(Raw_Data_Daily!$F:$F, Raw_Data_Daily!$B:$B, "Control", Raw_Data_Daily!$C:$C, "D. 20-39") -> 6915.24 | M8: =SUMIFS(Raw_Data_Daily!$F:$F, Raw_Data_Daily!$B:$B, "Variant", Raw_Data_Daily!$C:$C, "D. 20-39") -> 6219.38 | N8: =IFERROR((M8-L8)/ABS(L8),"") -> -0.10062702 | O8: =SUMIFS(Raw_Data_Daily!$F:$F, Raw_Data_Daily!$B:$B, "Control", Raw_Data_Daily!$C:$C, "E. 40-99") -> 8534.93 | P8: =SUMIFS(Raw_Data_Daily!$F:$F, Raw_Data_Daily!$B:$B, "Variant", Raw_Data_Daily!$C:$C, "E. 40-99") -> 8769.3 | Q8: =IFERROR((P8-O8)/ABS(O8),"") -> 0.027460096 | R8: =SUMIFS(Raw_Data_Daily!$F:$F, Raw_Data_Daily!$B:$B, "Control", Raw_Data_Daily!$C:$C, "F. 100+") -> 3131.81 | S8: =SUMIFS(Raw_Data_Daily!$F:$F, Raw_Data_Daily!$B:$B, "Variant", Raw_Data_Daily!$C:$C, "F. 100+") -> 1715.56 | T8: =IFERROR((S8-R8)/ABS(R8),"") -> -0.45221453
B9: ARPDAU | C9: =IFERROR(SUMIFS(Raw_Data_Daily!$F:$F, Raw_Data_Daily!$B:$B, "Control", Raw_Data_Daily!$C:$C, "A. 0")/SUMIFS(Raw_Data_Daily!$D:$D, Raw_Data_Daily!$B:$B, "Control", Raw_Data_Daily!$C:$C, "A. 0"),"") -> 0.09194578 | D9: =IFERROR(SUMIFS(Raw_Data_Daily!$F:$F, Raw_Data_Daily!$B:$B, "Variant", Raw_Data_Daily!$C:$C, "A. 0")/SUMIFS(Raw_Data_Daily!$D:$D, Raw_Data_Daily!$B:$B, "Variant", Raw_Data_Daily!$C:$C, "A. 0"),"") -> 0.10685162 | E9: =IFERROR((D9-C9)/ABS(C9),"") -> 0.16211555 | F9: =IFERROR(SUMIFS(Raw_Data_Daily!$F:$F, Raw_Data_Daily!$B:$B, "Control", Raw_Data_Daily!$C:$C, "B. 1-9")/SUMIFS(Raw_Data_Daily!$D:$D, Raw_Data_Daily!$B:$B, "Control", Raw_Data_Daily!$C:$C, "B. 1-9"),"") -> 0.028427164 | G9: =IFERROR(SUMIFS(Raw_Data_Daily!$F:$F, Raw_Data_Daily!$B:$B, "Variant", Raw_Data_Daily!$C:$C, "B. 1-9")/SUMIFS(Raw_Data_Daily!$D:$D, Raw_Data_Daily!$B:$B, "Variant", Raw_Data_Daily!$C:$C, "B. 1-9"),"") -> 0.026057751 | H9: =IFERROR((G9-F9)/ABS(F9),"") -> -0.083350317 | I9: =IFERROR(SUMIFS(Raw_Data_Daily!$F:$F, Raw_Data_Daily!$B:$B, "Control", Raw_Data_Daily!$C:$C, "C. 10-19")/SUMIFS(Raw_Data_Daily!$D:$D, Raw_Data_Daily!$B:$B, "Control", Raw_Data_Daily!$C:$C, "C. 10-19"),"") -> 0.098191752 | J9: =IFERROR(SUMIFS(Raw_Data_Daily!$F:$F, Raw_Data_Daily!$B:$B, "Variant", Raw_Data_Daily!$C:$C, "C. 10-19")/SUMIFS(Raw_Data_Daily!$D:$D, Raw_Data_Daily!$B:$B, "Variant", Raw_Data_Daily!$C:$C, "C. 10-19"),"") -> 0.097217383 | K9: =IFERROR((J9-I9)/ABS(I9),"") -> -0.0099231279 | L9: =IFERROR(SUMIFS(Raw_Data_Daily!$F:$F, Raw_Data_Daily!$B:$B, "Control", Raw_Data_Daily!$C:$C, "D. 20-39")/SUMIFS(Raw_Data_Daily!$D:$D, Raw_Data_Daily!$B:$B, "Control", Raw_Data_Daily!$C:$C, "D. 20-39"),"") -> 0.21455245 | M9: =IFERROR(SUMIFS(Raw_Data_Daily!$F:$F, Raw_Data_Daily!$B:$B, "Variant", Raw_Data_Daily!$C:$C, "D. 20-39")/SUMIFS(Raw_Data_Daily!$D:$D, Raw_Data_Daily!$B:$B, "Variant", Raw_Data_Daily!$C:$C, "D. 20-39"),"") -> 0.19463541 | N9: =IFERROR((M9-L9)/ABS(L9),"") -> -0.092830616 | O9: =IFERROR(SUMIFS(Raw_Data_Daily!$F:$F, Raw_Data_Daily!$B:$B, "Control", Raw_Data_Daily!$C:$C, "E. 40-99")/SUMIFS(Raw_Data_Daily!$D:$D, Raw_Data_Daily!$B:$B, "Control", Raw_Data_Daily!$C:$C, "E. 40-99"),"") -> 0.4675393 | P9: =IFERROR(SUMIFS(Raw_Data_Daily!$F:$F, Raw_Data_Daily!$B:$B, "Variant", Raw_Data_Daily!$C:$C, "E. 40-99")/SUMIFS(Raw_Data_Daily!$D:$D, Raw_Data_Daily!$B:$B, "Variant", Raw_Data_Daily!$C:$C, "E. 40-99"),"") -> 0.50502764 | Q9: =IFERROR((P9-O9)/ABS(O9),"") -> 0.080182219 | R9: =IFERROR(SUMIFS(Raw_Data_Daily!$F:$F, Raw_Data_Daily!$B:$B, "Control", Raw_Data_Daily!$C:$C, "F. 100+")/SUMIFS(Raw_Data_Daily!$D:$D, Raw_Data_Daily!$B:$B, "Control", Raw_Data_Daily!$C:$C, "F. 100+"),"") -> 1.1720846 | S9: =IFERROR(SUMIFS(Raw_Data_Daily!$F:$F, Raw_Data_Daily!$B:$B, "Variant", Raw_Data_Daily!$C:$C, "F. 100+")/SUMIFS(Raw_Data_Daily!$D:$D, Raw_Data_Daily!$B:$B, "Variant", Raw_Data_Daily!$C:$C, "F. 100+"),"") -> 0.71333056 | T9: =IFERROR((S9-R9)/ABS(R9),"") -> -0.3914001
B10: AVG Payer day (%) | C10: =IFERROR(SUMPRODUCT((Raw_Data_Daily!$B$2:$B$9999="Control")*(Raw_Data_Daily!$C$2:$C$9999="A. 0")*Raw_Data_Daily!$D$2:$D$9999*Raw_Data_Daily!$H$2:$H$9999/100)/SUMIFS(Raw_Data_Daily!$D:$D, Raw_Data_Daily!$B:$B, "Control", Raw_Data_Daily!$C:$C, "A. 0")*100,"") -> 1.1033765 | D10: =IFERROR(SUMPRODUCT((Raw_Data_Daily!$B$2:$B$9999="Variant")*(Raw_Data_Daily!$C$2:$C$9999="A. 0")*Raw_Data_Daily!$D$2:$D$9999*Raw_Data_Daily!$H$2:$H$9999/100)/SUMIFS(Raw_Data_Daily!$D:$D, Raw_Data_Daily!$B:$B, "Variant", Raw_Data_Daily!$C:$C, "A. 0")*100,"") -> 1.0271007 | E10: =IFERROR((D10-C10)/ABS(C10),"") -> -0.069129417 | F10: =IFERROR(SUMPRODUCT((Raw_Data_Daily!$B$2:$B$9999="Control")*(Raw_Data_Daily!$C$2:$C$9999="B. 1-9")*Raw_Data_Daily!$D$2:$D$9999*Raw_Data_Daily!$H$2:$H$9999/100)/SUMIFS(Raw_Data_Daily!$D:$D, Raw_Data_Daily!$B:$B, "Control", Raw_Data_Daily!$C:$C, "B. 1-9")*100,"") -> 1.0378464 | G10: =IFERROR(SUMPRODUCT((Raw_Data_Daily!$B$2:$B$9999="Variant")*(Raw_Data_Daily!$C$2:$C$9999="B. 1-9")*Raw_Data_Daily!$D$2:$D$9999*Raw_Data_Daily!$H$2:$H$9999/100)/SUMIFS(Raw_Data_Daily!$D:$D, Raw_Data_Daily!$B:$B, "Variant", Raw_Data_Daily!$C:$C, "B. 1-9")*100,"") -> 1.0432958 | H10: =IFERROR((G10-F10)/ABS(F10),"") -> 0.0052507246 | I10: =IFERROR(SUMPRODUCT((Raw_Data_Daily!$B$2:$B$9999="Control")*(Raw_Data_Daily!$C$2:$C$9999="C. 10-19")*Raw_Data_Daily!$D$2:$D$9999*Raw_Data_Daily!$H$2:$H$9999/100)/SUMIFS(Raw_Data_Daily!$D:$D, Raw_Data_Daily!$B:$B, "Control", Raw_Data_Daily!$C:$C, "C. 10-19")*100,"") -> 2.7450434 | J10: =IFERROR(SUMPRODUCT((Raw_Data_Daily!$B$2:$B$9999="Variant")*(Raw_Data_Daily!$C$2:$C$9999="C. 10-19")*Raw_Data_Daily!$D$2:$D$9999*Raw_Data_Daily!$H$2:$H$9999/100)/SUMIFS(Raw_Data_Daily!$D:$D, Raw_Data_Daily!$B:$B, "Variant", Raw_Data_Daily!$C:$C, "C. 10-19")*100,"") -> 2.8531152 | K10: =IFERROR((J10-I10)/ABS(I10),"") -> 0.03936981 | L10: =IFERROR(SUMPRODUCT((Raw_Data_Daily!$B$2:$B$9999="Control")*(Raw_Data_Daily!$C$2:$C$9999="D. 20-39")*Raw_Data_Daily!$D$2:$D$9999*Raw_Data_Daily!$H$2:$H$9999/100)/SUMIFS(Raw_Data_Daily!$D:$D, Raw_Data_Daily!$B:$B, "Control", Raw_Data_Daily!$C:$C, "D. 20-39")*100,"") -> 4.0453222 | M10: =IFERROR(SUMPRODUCT((Raw_Data_Daily!$B$2:$B$9999="Variant")*(Raw_Data_Daily!$C$2:$C$9999="D. 20-39")*Raw_Data_Daily!$D$2:$D$9999*Raw_Data_Daily!$H$2:$H$9999/100)/SUMIFS(Raw_Data_Daily!$D:$D, Raw_Data_Daily!$B:$B, "Variant", Raw_Data_Daily!$C:$C, "D. 20-39")*100,"") -> 3.8866251 | N10: =IFERROR((M10-L10)/ABS(L10),"") -> -0.039229769 | O10: =IFERROR(SUMPRODUCT((Raw_Data_Daily!$B$2:$B$9999="Control")*(Raw_Data_Daily!$C$2:$C$9999="E. 40-99")*Raw_Data_Daily!$D$2:$D$9999*Raw_Data_Daily!$H$2:$H$9999/100)/SUMIFS(Raw_Data_Daily!$D:$D, Raw_Data_Daily!$B:$B, "Control", Raw_Data_Daily!$C:$C, "E. 40-99")*100,"") -> 6.387817 | P10: =IFERROR(SUMPRODUCT((Raw_Data_Daily!$B$2:$B$9999="Variant")*(Raw_Data_Daily!$C$2:$C$9999="E. 40-99")*Raw_Data_Daily!$D$2:$D$9999*Raw_Data_Daily!$H$2:$H$9999/100)/SUMIFS(Raw_Data_Daily!$D:$D, Raw_Data_Daily!$B:$B, "Variant", Raw_Data_Daily!$C:$C, "E. 40-99")*100,"") -> 6.29162 | Q10: =IFERROR((P10-O10)/ABS(O10),"") -> -0.015059451 | R10: =IFERROR(SUMPRODUCT((Raw_Data_Daily!$B$2:$B$9999="Control")*(Raw_Data_Daily!$C$2:$C$9999="F. 100+")*Raw_Data_Daily!$D$2:$D$9999*Raw_Data_Daily!$H$2:$H$9999/100)/SUMIFS(Raw_Data_Daily!$D:$D, Raw_Data_Daily!$B:$B, "Control", Raw_Data_Daily!$C:$C, "F. 100+")*100,"") -> 9.430101 | S10: =IFERROR(SUMPRODUCT((Raw_Data_Daily!$B$2:$B$9999="Variant")*(Raw_Data_Daily!$C$2:$C$9999="F. 100+")*Raw_Data_Daily!$D$2:$D$9999*Raw_Data_Daily!$H$2:$H$9999/100)/SUMIFS(Raw_Data_Daily!$D:$D, Raw_Data_Daily!$B:$B, "Variant", Raw_Data_Daily!$C:$C, "F. 100+")*100,"") -> 7.7742204 | T10: =IFERROR((S10-R10)/ABS(R10),"") -> -0.17559522
B11: ARPPU | C11: =IFERROR(SUMIFS(Raw_Data_Daily!$F:$F, Raw_Data_Daily!$B:$B, "Control", Raw_Data_Daily!$C:$C, "A. 0")/SUMPRODUCT((Raw_Data_Daily!$B$2:$B$9999="Control")*(Raw_Data_Daily!$C$2:$C$9999="A. 0")*Raw_Data_Daily!$D$2:$D$9999*Raw_Data_Daily!$H$2:$H$9999/100),"") -> 8.3331284 | D11: =IFERROR(SUMIFS(Raw_Data_Daily!$F:$F, Raw_Data_Daily!$B:$B, "Variant", Raw_Data_Daily!$C:$C, "A. 0")/SUMPRODUCT((Raw_Data_Daily!$B$2:$B$9999="Variant")*(Raw_Data_Daily!$C$2:$C$9999="A. 0")*Raw_Data_Daily!$D$2:$D$9999*Raw_Data_Daily!$H$2:$H$9999/100),"") -> 10.403227 | E11: =IFERROR((D11-C11)/ABS(C11),"") -> 0.24841795 | F11: =IFERROR(SUMIFS(Raw_Data_Daily!$F:$F, Raw_Data_Daily!$B:$B, "Control", Raw_Data_Daily!$C:$C, "B. 1-9")/SUMPRODUCT((Raw_Data_Daily!$B$2:$B$9999="Control")*(Raw_Data_Daily!$C$2:$C$9999="B. 1-9")*Raw_Data_Daily!$D$2:$D$9999*Raw_Data_Daily!$H$2:$H$9999/100),"") -> 2.7390532 | G11: =IFERROR(SUMIFS(Raw_Data_Daily!$F:$F, Raw_Data_Daily!$B:$B, "Variant", Raw_Data_Daily!$C:$C, "B. 1-9")/SUMPRODUCT((Raw_Data_Daily!$B$2:$B$9999="Variant")*(Raw_Data_Daily!$C$2:$C$9999="B. 1-9")*Raw_Data_Daily!$D$2:$D$9999*Raw_Data_Daily!$H$2:$H$9999/100),"") -> 2.4976379 | H11: =IFERROR((G11-F11)/ABS(F11),"") -> -0.088138251 | I11: =IFERROR(SUMIFS(Raw_Data_Daily!$F:$F, Raw_Data_Daily!$B:$B, "Control", Raw_Data_Daily!$C:$C, "C. 10-19")/SUMPRODUCT((Raw_Data_Daily!$B$2:$B$9999="Control")*(Raw_Data_Daily!$C$2:$C$9999="C. 10-19")*Raw_Data_Daily!$D$2:$D$9999*Raw_Data_Daily!$H$2:$H$9999/100),"") -> 3.5770565 | J11: =IFERROR(SUMIFS(Raw_Data_Daily!$F:$F, Raw_Data_Daily!$B:$B, "Variant", Raw_Data_Daily!$C:$C, "C. 10-19")/SUMPRODUCT((Raw_Data_Daily!$B$2:$B$9999="Variant")*(Raw_Data_Daily!$C$2:$C$9999="C. 10-19")*Raw_Data_Daily!$D$2:$D$9999*Raw_Data_Daily!$H$2:$H$9999/100),"") -> 3.4074118 | K11: =IFERROR((J11-I11)/ABS(I11),"") -> -0.047425793 | L11: =IFERROR(SUMIFS(Raw_Data_Daily!$F:$F, Raw_Data_Daily!$B:$B, "Control", Raw_Data_Daily!$C:$C, "D. 20-39")/SUMPRODUCT((Raw_Data_Daily!$B$2:$B$9999="Control")*(Raw_Data_Daily!$C$2:$C$9999="D. 20-39")*Raw_Data_Daily!$D$2:$D$9999*Raw_Data_Daily!$H$2:$H$9999/100),"") -> 5.3037172 | M11: =IFERROR(SUMIFS(Raw_Data_Daily!$F:$F, Raw_Data_Daily!$B:$B, "Variant", Raw_Data_Daily!$C:$C, "D. 20-39")/SUMPRODUCT((Raw_Data_Daily!$B$2:$B$9999="Variant")*(Raw_Data_Daily!$C$2:$C$9999="D. 20-39")*Raw_Data_Daily!$D$2:$D$9999*Raw_Data_Daily!$H$2:$H$9999/100),"") -> 5.0078257 | N11: =IFERROR((M11-L11)/ABS(L11),"") -> -0.055789454 | O11: =IFERROR(SUMIFS(Raw_Data_Daily!$F:$F, Raw_Data_Daily!$B:$B, "Control", Raw_Data_Daily!$C:$C, "E. 40-99")/SUMPRODUCT((Raw_Data_Daily!$B$2:$B$9999="Control")*(Raw_Data_Daily!$C$2:$C$9999="E. 40-99")*Raw_Data_Daily!$D$2:$D$9999*Raw_Data_Daily!$H$2:$H$9999/100),"") -> 7.3192344 | P11: =IFERROR(SUMIFS(Raw_Data_Daily!$F:$F, Raw_Data_Daily!$B:$B, "Variant", Raw_Data_Daily!$C:$C, "E. 40-99")/SUMPRODUCT((Raw_Data_Daily!$B$2:$B$9999="Variant")*(Raw_Data_Daily!$C$2:$C$9999="E. 40-99")*Raw_Data_Daily!$D$2:$D$9999*Raw_Data_Daily!$H$2:$H$9999/100),"") -> 8.0269889 | Q11: =IFERROR((P11-O11)/ABS(O11),"") -> 0.096697888 | R11: =IFERROR(SUMIFS(Raw_Data_Daily!$F:$F, Raw_Data_Daily!$B:$B, "Control", Raw_Data_Daily!$C:$C, "F. 100+")/SUMPRODUCT((Raw_Data_Daily!$B$2:$B$9999="Control")*(Raw_Data_Daily!$C$2:$C$9999="F. 100+")*Raw_Data_Daily!$D$2:$D$9999*Raw_Data_Daily!$H$2:$H$9999/100),"") -> 12.429184 | S11: =IFERROR(SUMIFS(Raw_Data_Daily!$F:$F, Raw_Data_Daily!$B:$B, "Variant", Raw_Data_Daily!$C:$C, "F. 100+")/SUMPRODUCT((Raw_Data_Daily!$B$2:$B$9999="Variant")*(Raw_Data_Daily!$C$2:$C$9999="F. 100+")*Raw_Data_Daily!$D$2:$D$9999*Raw_Data_Daily!$H$2:$H$9999/100),"") -> 9.1755897 | T11: =IFERROR((S11-R11)/ABS(R11),"") -> -0.26177053
A12: Engagement
B13: Time spent (mins) | C13: =IFERROR(SUMPRODUCT((Raw_Data_Daily!$B$2:$B$9999="Control")*(Raw_Data_Daily!$C$2:$C$9999="A. 0")*Raw_Data_Daily!$D$2:$D$9999*Raw_Data_Daily!$J$2:$J$9999)/SUMIFS(Raw_Data_Daily!$D:$D, Raw_Data_Daily!$B:$B, "Control", Raw_Data_Daily!$C:$C, "A. 0"),"") -> 17.31001 | D13: =IFERROR(SUMPRODUCT((Raw_Data_Daily!$B$2:$B$9999="Variant")*(Raw_Data_Daily!$C$2:$C$9999="A. 0")*Raw_Data_Daily!$D$2:$D$9999*Raw_Data_Daily!$J$2:$J$9999)/SUMIFS(Raw_Data_Daily!$D:$D, Raw_Data_Daily!$B:$B, "Variant", Raw_Data_Daily!$C:$C, "A. 0"),"") -> 18.642683 | E13: =IFERROR((D13-C13)/ABS(C13),"") -> 0.076988559 | F13: =IFERROR(SUMPRODUCT((Raw_Data_Daily!$B$2:$B$9999="Control")*(Raw_Data_Daily!$C$2:$C$9999="B. 1-9")*Raw_Data_Daily!$D$2:$D$9999*Raw_Data_Daily!$J$2:$J$9999)/SUMIFS(Raw_Data_Daily!$D:$D, Raw_Data_Daily!$B:$B, "Control", Raw_Data_Daily!$C:$C, "B. 1-9"),"") -> 22.448482 | G13: =IFERROR(SUMPRODUCT((Raw_Data_Daily!$B$2:$B$9999="Variant")*(Raw_Data_Daily!$C$2:$C$9999="B. 1-9")*Raw_Data_Daily!$D$2:$D$9999*Raw_Data_Daily!$J$2:$J$9999)/SUMIFS(Raw_Data_Daily!$D:$D, Raw_Data_Daily!$B:$B, "Variant", Raw_Data_Daily!$C:$C, "B. 1-9"),"") -> 22.33624 | H13: =IFERROR((G13-F13)/ABS(F13),"") -> -0.0049999444 | I13: =IFERROR(SUMPRODUCT((Raw_Data_Daily!$B$2:$B$9999="Control")*(Raw_Data_Daily!$C$2:$C$9999="C. 10-19")*Raw_Data_Daily!$D$2:$D$9999*Raw_Data_Daily!$J$2:$J$9999)/SUMIFS(Raw_Data_Daily!$D:$D, Raw_Data_Daily!$B:$B, "Control", Raw_Data_Daily!$C:$C, "C. 10-19"),"") -> 45.107712 | J13: =IFERROR(SUMPRODUCT((Raw_Data_Daily!$B$2:$B$9999="Variant")*(Raw_Data_Daily!$C$2:$C$9999="C. 10-19")*Raw_Data_Daily!$D$2:$D$9999*Raw_Data_Daily!$J$2:$J$9999)/SUMIFS(Raw_Data_Daily!$D:$D, Raw_Data_Daily!$B:$B, "Variant", Raw_Data_Daily!$C:$C, "C. 10-19"),"") -> 46.388918 | K13: =IFERROR((J13-I13)/ABS(I13),"") -> 0.028403269 | L13: =IFERROR(SUMPRODUCT((Raw_Data_Daily!$B$2:$B$9999="Control")*(Raw_Data_Daily!$C$2:$C$9999="D. 20-39")*Raw_Data_Daily!$D$2:$D$9999*Raw_Data_Daily!$J$2:$J$9999)/SUMIFS(Raw_Data_Daily!$D:$D, Raw_Data_Daily!$B:$B, "Control", Raw_Data_Daily!$C:$C, "D. 20-39"),"") -> 68.765068 | M13: =IFERROR(SUMPRODUCT((Raw_Data_Daily!$B$2:$B$9999="Variant")*(Raw_Data_Daily!$C$2:$C$9999="D. 20-39")*Raw_Data_Daily!$D$2:$D$9999*Raw_Data_Daily!$J$2:$J$9999)/SUMIFS(Raw_Data_Daily!$D:$D, Raw_Data_Daily!$B:$B, "Variant", Raw_Data_Daily!$C:$C, "D. 20-39"),"") -> 71.822631 | N13: =IFERROR((M13-L13)/ABS(L13),"") -> 0.044463896 | O13: =IFERROR(SUMPRODUCT((Raw_Data_Daily!$B$2:$B$9999="Control")*(Raw_Data_Daily!$C$2:$C$9999="E. 40-99")*Raw_Data_Daily!$D$2:$D$9999*Raw_Data_Daily!$J$2:$J$9999)/SUMIFS(Raw_Data_Daily!$D:$D, Raw_Data_Daily!$B:$B, "Control", Raw_Data_Daily!$C:$C, "E. 40-99"),"") -> 120.53259 | P13: =IFERROR(SUMPRODUCT((Raw_Data_Daily!$B$2:$B$9999="Variant")*(Raw_Data_Daily!$C$2:$C$9999="E. 40-99")*Raw_Data_Daily!$D$2:$D$9999*Raw_Data_Daily!$J$2:$J$9999)/SUMIFS(Raw_Data_Daily!$D:$D, Raw_Data_Daily!$B:$B, "Variant", Raw_Data_Daily!$C:$C, "E. 40-99"),"") -> 122.77153 | Q13: =IFERROR((P13-O13)/ABS(O13),"") -> 0.018575387 | R13: =IFERROR(SUMPRODUCT((Raw_Data_Daily!$B$2:$B$9999="Control")*(Raw_Data_Daily!$C$2:$C$9999="F. 100+")*Raw_Data_Daily!$D$2:$D$9999*Raw_Data_Daily!$J$2:$J$9999)/SUMIFS(Raw_Data_Daily!$D:$D, Raw_Data_Daily!$B:$B, "Control", Raw_Data_Daily!$C:$C, "F. 100+"),"") -> 247.79763 | S13: =IFERROR(SUMPRODUCT((Raw_Data_Daily!$B$2:$B$9999="Variant")*(Raw_Data_Daily!$C$2:$C$9999="F. 100+")*Raw_Data_Daily!$D$2:$D$9999*Raw_Data_Daily!$J$2:$J$9999)/SUMIFS(Raw_Data_Daily!$D:$D, Raw_Data_Daily!$B:$B, "Variant", Raw_Data_Daily!$C:$C, "F. 100+"),"") -> 243.32833 | T13: =IFERROR((S13-R13)/ABS(R13),"") -> -0.018036097
B14: Level attempts / player | C14: =IFERROR(SUMPRODUCT((Raw_Data_Daily!$B$2:$B$9999="Control")*(Raw_Data_Daily!$C$2:$C$9999="A. 0")*Raw_Data_Daily!$D$2:$D$9999*Raw_Data_Daily!$K$2:$K$9999)/SUMIFS(Raw_Data_Daily!$D:$D, Raw_Data_Daily!$B:$B, "Control", Raw_Data_Daily!$C:$C, "A. 0"),"") -> 9.258141 | D14: =IFERROR(SUMPRODUCT((Raw_Data_Daily!$B$2:$B$9999="Variant")*(Raw_Data_Daily!$C$2:$C$9999="A. 0")*Raw_Data_Daily!$D$2:$D$9999*Raw_Data_Daily!$K$2:$K$9999)/SUMIFS(Raw_Data_Daily!$D:$D, Raw_Data_Daily!$B:$B, "Variant", Raw_Data_Daily!$C:$C, "A. 0"),"") -> 9.9051784 | E14: =IFERROR((D14-C14)/ABS(C14),"") -> 0.069888475 | F14: =IFERROR(SUMPRODUCT((Raw_Data_Daily!$B$2:$B$9999="Control")*(Raw_Data_Daily!$C$2:$C$9999="B. 1-9")*Raw_Data_Daily!$D$2:$D$9999*Raw_Data_Daily!$K$2:$K$9999)/SUMIFS(Raw_Data_Daily!$D:$D, Raw_Data_Daily!$B:$B, "Control", Raw_Data_Daily!$C:$C, "B. 1-9"),"") -> 11.648771 | G14: =IFERROR(SUMPRODUCT((Raw_Data_Daily!$B$2:$B$9999="Variant")*(Raw_Data_Daily!$C$2:$C$9999="B. 1-9")*Raw_Data_Daily!$D$2:$D$9999*Raw_Data_Daily!$K$2:$K$9999)/SUMIFS(Raw_Data_Daily!$D:$D, Raw_Data_Daily!$B:$B, "Variant", Raw_Data_Daily!$C:$C, "B. 1-9"),"") -> 11.40699 | H14: =IFERROR((G14-F14)/ABS(F14),"") -> -0.02075596 | I14: =IFERROR(SUMPRODUCT((Raw_Data_Daily!$B$2:$B$9999="Control")*(Raw_Data_Daily!$C$2:$C$9999="C. 10-19")*Raw_Data_Daily!$D$2:$D$9999*Raw_Data_Daily!$K$2:$K$9999)/SUMIFS(Raw_Data_Daily!$D:$D, Raw_Data_Daily!$B:$B, "Control", Raw_Data_Daily!$C:$C, "C. 10-19"),"") -> 24.366102 | J14: =IFERROR(SUMPRODUCT((Raw_Data_Daily!$B$2:$B$9999="Variant")*(Raw_Data_Daily!$C$2:$C$9999="C. 10-19")*Raw_Data_Daily!$D$2:$D$9999*Raw_Data_Daily!$K$2:$K$9999)/SUMIFS(Raw_Data_Daily!$D:$D, Raw_Data_Daily!$B:$B, "Variant", Raw_Data_Daily!$C:$C, "C. 10-19"),"") -> 24.897393 | K14: =IFERROR((J14-I14)/ABS(I14),"") -> 0.021804517 | L14: =IFERROR(SUMPRODUCT((Raw_Data_Daily!$B$2:$B$9999="Control")*(Raw_Data_Daily!$C$2:$C$9999="D. 20-39")*Raw_Data_Daily!$D$2:$D$9999*Raw_Data_Daily!$K$2:$K$9999)/SUMIFS(Raw_Data_Daily!$D:$D, Raw_Data_Daily!$B:$B, "Control", Raw_Data_Daily!$C:$C, "D. 20-39"),"") -> 39.05534 | M14: =IFERROR(SUMPRODUCT((Raw_Data_Daily!$B$2:$B$9999="Variant")*(Raw_Data_Daily!$C$2:$C$9999="D. 20-39")*Raw_Data_Daily!$D$2:$D$9999*Raw_Data_Daily!$K$2:$K$9999)/SUMIFS(Raw_Data_Daily!$D:$D, Raw_Data_Daily!$B:$B, "Variant", Raw_Data_Daily!$C:$C, "D. 20-39"),"") -> 40.585598 | N14: =IFERROR((M14-L14)/ABS(L14),"") -> 0.039181791 | O14: =IFERROR(SUMPRODUCT((Raw_Data_Daily!$B$2:$B$9999="Control")*(Raw_Data_Daily!$C$2:$C$9999="E. 40-99")*Raw_Data_Daily!$D$2:$D$9999*Raw_Data_Daily!$K$2:$K$9999)/SUMIFS(Raw_Data_Daily!$D:$D, Raw_Data_Daily!$B:$B, "Control", Raw_Data_Daily!$C:$C, "E. 40-99"),"") -> 72.515629 | P14: =IFERROR(SUMPRODUCT((Raw_Data_Daily!$B$2:$B$9999="Variant")*(Raw_Data_Daily!$C$2:$C$9999="E. 40-99")*Raw_Data_Daily!$D$2:$D$9999*Raw_Data_Daily!$K$2:$K$9999)/SUMIFS(Raw_Data_Daily!$D:$D, Raw_Data_Daily!$B:$B, "Variant", Raw_Data_Daily!$C:$C, "E. 40-99"),"") -> 74.460091 | Q14: =IFERROR((P14-O14)/ABS(O14),"") -> 0.026814391 | R14: =IFERROR(SUMPRODUCT((Raw_Data_Daily!$B$2:$B$9999="Control")*(Raw_Data_Daily!$C$2:$C$9999="F. 100+")*Raw_Data_Daily!$D$2:$D$9999*Raw_Data_Daily!$K$2:$K$9999)/SUMIFS(Raw_Data_Daily!$D:$D, Raw_Data_Daily!$B:$B, "Control", Raw_Data_Daily!$C:$C, "F. 100+"),"") -> 164.67101 | S14: =IFERROR(SUMPRODUCT((Raw_Data_Daily!$B$2:$B$9999="Variant")*(Raw_Data_Daily!$C$2:$C$9999="F. 100+")*Raw_Data_Daily!$D$2:$D$9999*Raw_Data_Daily!$K$2:$K$9999)/SUMIFS(Raw_Data_Daily!$D:$D, Raw_Data_Daily!$B:$B, "Variant", Raw_Data_Daily!$C:$C, "F. 100+"),"") -> 161.46999 | T14: =IFERROR((S14-R14)/ABS(R14),"") -> -0.019438898
B15: Level completes / player | C15: =IFERROR(SUMPRODUCT((Raw_Data_Daily!$B$2:$B$9999="Control")*(Raw_Data_Daily!$C$2:$C$9999="A. 0")*Raw_Data_Daily!$D$2:$D$9999*Raw_Data_Daily!$L$2:$L$9999)/SUMIFS(Raw_Data_Daily!$D:$D, Raw_Data_Daily!$B:$B, "Control", Raw_Data_Daily!$C:$C, "A. 0"),"") -> 5.9097861 | D15: =IFERROR(SUMPRODUCT((Raw_Data_Daily!$B$2:$B$9999="Variant")*(Raw_Data_Daily!$C$2:$C$9999="A. 0")*Raw_Data_Daily!$D$2:$D$9999*Raw_Data_Daily!$L$2:$L$9999)/SUMIFS(Raw_Data_Daily!$D:$D, Raw_Data_Daily!$B:$B, "Variant", Raw_Data_Daily!$C:$C, "A. 0"),"") -> 6.5726315 | E15: =IFERROR((D15-C15)/ABS(C15),"") -> 0.11216063 | F15: =IFERROR(SUMPRODUCT((Raw_Data_Daily!$B$2:$B$9999="Control")*(Raw_Data_Daily!$C$2:$C$9999="B. 1-9")*Raw_Data_Daily!$D$2:$D$9999*Raw_Data_Daily!$L$2:$L$9999)/SUMIFS(Raw_Data_Daily!$D:$D, Raw_Data_Daily!$B:$B, "Control", Raw_Data_Daily!$C:$C, "B. 1-9"),"") -> 5.2682463 | G15: =IFERROR(SUMPRODUCT((Raw_Data_Daily!$B$2:$B$9999="Variant")*(Raw_Data_Daily!$C$2:$C$9999="B. 1-9")*Raw_Data_Daily!$D$2:$D$9999*Raw_Data_Daily!$L$2:$L$9999)/SUMIFS(Raw_Data_Daily!$D:$D, Raw_Data_Daily!$B:$B, "Variant", Raw_Data_Daily!$C:$C, "B. 1-9"),"") -> 5.2100565 | H15: =IFERROR((G15-F15)/ABS(F15),"") -> -0.011045381 | I15: =IFERROR(SUMPRODUCT((Raw_Data_Daily!$B$2:$B$9999="Control")*(Raw_Data_Daily!$C$2:$C$9999="C. 10-19")*Raw_Data_Daily!$D$2:$D$9999*Raw_Data_Daily!$L$2:$L$9999)/SUMIFS(Raw_Data_Daily!$D:$D, Raw_Data_Daily!$B:$B, "Control", Raw_Data_Daily!$C:$C, "C. 10-19"),"") -> 13.828845 | J15: =IFERROR(SUMPRODUCT((Raw_Data_Daily!$B$2:$B$9999="Variant")*(Raw_Data_Daily!$C$2:$C$9999="C. 10-19")*Raw_Data_Daily!$D$2:$D$9999*Raw_Data_Daily!$L$2:$L$9999)/SUMIFS(Raw_Data_Daily!$D:$D, Raw_Data_Daily!$B:$B, "Variant", Raw_Data_Daily!$C:$C, "C. 10-19"),"") -> 13.814269 | K15: =IFERROR((J15-I15)/ABS(I15),"") -> -0.0010539786 | L15: =IFERROR(SUMPRODUCT((Raw_Data_Daily!$B$2:$B$9999="Control")*(Raw_Data_Daily!$C$2:$C$9999="D. 20-39")*Raw_Data_Daily!$D$2:$D$9999*Raw_Data_Daily!$L$2:$L$9999)/SUMIFS(Raw_Data_Daily!$D:$D, Raw_Data_Daily!$B:$B, "Control", Raw_Data_Daily!$C:$C, "D. 20-39"),"") -> 26.064324 | M15: =IFERROR(SUMPRODUCT((Raw_Data_Daily!$B$2:$B$9999="Variant")*(Raw_Data_Daily!$C$2:$C$9999="D. 20-39")*Raw_Data_Daily!$D$2:$D$9999*Raw_Data_Daily!$L$2:$L$9999)/SUMIFS(Raw_Data_Daily!$D:$D, Raw_Data_Daily!$B:$B, "Variant", Raw_Data_Daily!$C:$C, "D. 20-39"),"") -> 26.450961 | N15: =IFERROR((M15-L15)/ABS(L15),"") -> 0.014833941 | O15: =IFERROR(SUMPRODUCT((Raw_Data_Daily!$B$2:$B$9999="Control")*(Raw_Data_Daily!$C$2:$C$9999="E. 40-99")*Raw_Data_Daily!$D$2:$D$9999*Raw_Data_Daily!$L$2:$L$9999)/SUMIFS(Raw_Data_Daily!$D:$D, Raw_Data_Daily!$B:$B, "Control", Raw_Data_Daily!$C:$C, "E. 40-99"),"") -> 53.136709 | P15: =IFERROR(SUMPRODUCT((Raw_Data_Daily!$B$2:$B$9999="Variant")*(Raw_Data_Daily!$C$2:$C$9999="E. 40-99")*Raw_Data_Daily!$D$2:$D$9999*Raw_Data_Daily!$L$2:$L$9999)/SUMIFS(Raw_Data_Daily!$D:$D, Raw_Data_Daily!$B:$B, "Variant", Raw_Data_Daily!$C:$C, "E. 40-99"),"") -> 54.229709 | Q15: =IFERROR((P15-O15)/ABS(O15),"") -> 0.020569579 | R15: =IFERROR(SUMPRODUCT((Raw_Data_Daily!$B$2:$B$9999="Control")*(Raw_Data_Daily!$C$2:$C$9999="F. 100+")*Raw_Data_Daily!$D$2:$D$9999*Raw_Data_Daily!$L$2:$L$9999)/SUMIFS(Raw_Data_Daily!$D:$D, Raw_Data_Daily!$B:$B, "Control", Raw_Data_Daily!$C:$C, "F. 100+"),"") -> 128.41218 | S15: =IFERROR(SUMPRODUCT((Raw_Data_Daily!$B$2:$B$9999="Variant")*(Raw_Data_Daily!$C$2:$C$9999="F. 100+")*Raw_Data_Daily!$D$2:$D$9999*Raw_Data_Daily!$L$2:$L$9999)/SUMIFS(Raw_Data_Daily!$D:$D, Raw_Data_Daily!$B:$B, "Variant", Raw_Data_Daily!$C:$C, "F. 100+"),"") -> 123.87504 | T15: =IFERROR((S15-R15)/ABS(R15),"") -> -0.035332615
A16: Daily Streak
B17: Avg daily streak | C17: =IFERROR(SUMPRODUCT((Raw_Data_Daily!$B$2:$B$9999="Control")*(Raw_Data_Daily!$C$2:$C$9999="A. 0")*Raw_Data_Daily!$D$2:$D$9999*Raw_Data_Daily!$AD$2:$AD$9999)/SUMIFS(Raw_Data_Daily!$D:$D, Raw_Data_Daily!$B:$B, "Control", Raw_Data_Daily!$C:$C, "A. 0"),"") -> 0 | D17: =IFERROR(SUMPRODUCT((Raw_Data_Daily!$B$2:$B$9999="Variant")*(Raw_Data_Daily!$C$2:$C$9999="A. 0")*Raw_Data_Daily!$D$2:$D$9999*Raw_Data_Daily!$AD$2:$AD$9999)/SUMIFS(Raw_Data_Daily!$D:$D, Raw_Data_Daily!$B:$B, "Variant", Raw_Data_Daily!$C:$C, "A. 0"),"") -> 0 | E17: =IFERROR((D17-C17)/ABS(C17),"") | F17: =IFERROR(SUMPRODUCT((Raw_Data_Daily!$B$2:$B$9999="Control")*(Raw_Data_Daily!$C$2:$C$9999="B. 1-9")*Raw_Data_Daily!$D$2:$D$9999*Raw_Data_Daily!$AD$2:$AD$9999)/SUMIFS(Raw_Data_Daily!$D:$D, Raw_Data_Daily!$B:$B, "Control", Raw_Data_Daily!$C:$C, "B. 1-9"),"") -> 4.0603037 | G17: =IFERROR(SUMPRODUCT((Raw_Data_Daily!$B$2:$B$9999="Variant")*(Raw_Data_Daily!$C$2:$C$9999="B. 1-9")*Raw_Data_Daily!$D$2:$D$9999*Raw_Data_Daily!$AD$2:$AD$9999)/SUMIFS(Raw_Data_Daily!$D:$D, Raw_Data_Daily!$B:$B, "Variant", Raw_Data_Daily!$C:$C, "B. 1-9"),"") -> 4.0732652 | H17: =IFERROR((G17-F17)/ABS(F17),"") -> 0.0031922351 | I17: =IFERROR(SUMPRODUCT((Raw_Data_Daily!$B$2:$B$9999="Control")*(Raw_Data_Daily!$C$2:$C$9999="C. 10-19")*Raw_Data_Daily!$D$2:$D$9999*Raw_Data_Daily!$AD$2:$AD$9999)/SUMIFS(Raw_Data_Daily!$D:$D, Raw_Data_Daily!$B:$B, "Control", Raw_Data_Daily!$C:$C, "C. 10-19"),"") -> 9.4589957 | J17: =IFERROR(SUMPRODUCT((Raw_Data_Daily!$B$2:$B$9999="Variant")*(Raw_Data_Daily!$C$2:$C$9999="C. 10-19")*Raw_Data_Daily!$D$2:$D$9999*Raw_Data_Daily!$AD$2:$AD$9999)/SUMIFS(Raw_Data_Daily!$D:$D, Raw_Data_Daily!$B:$B, "Variant", Raw_Data_Daily!$C:$C, "C. 10-19"),"") -> 9.4649761 | K17: =IFERROR((J17-I17)/ABS(I17),"") -> 0.00063224857 | L17: =IFERROR(SUMPRODUCT((Raw_Data_Daily!$B$2:$B$9999="Control")*(Raw_Data_Daily!$C$2:$C$9999="D. 20-39")*Raw_Data_Daily!$D$2:$D$9999*Raw_Data_Daily!$AD$2:$AD$9999)/SUMIFS(Raw_Data_Daily!$D:$D, Raw_Data_Daily!$B:$B, "Control", Raw_Data_Daily!$C:$C, "D. 20-39"),"") -> 16.636809 | M17: =IFERROR(SUMPRODUCT((Raw_Data_Daily!$B$2:$B$9999="Variant")*(Raw_Data_Daily!$C$2:$C$9999="D. 20-39")*Raw_Data_Daily!$D$2:$D$9999*Raw_Data_Daily!$AD$2:$AD$9999)/SUMIFS(Raw_Data_Daily!$D:$D, Raw_Data_Daily!$B:$B, "Variant", Raw_Data_Daily!$C:$C, "D. 20-39"),"") -> 16.663539 | N17: =IFERROR((M17-L17)/ABS(L17),"") -> 0.0016066327 | O17: =IFERROR(SUMPRODUCT((Raw_Data_Daily!$B$2:$B$9999="Control")*(Raw_Data_Daily!$C$2:$C$9999="E. 40-99")*Raw_Data_Daily!$D$2:$D$9999*Raw_Data_Daily!$AD$2:$AD$9999)/SUMIFS(Raw_Data_Daily!$D:$D, Raw_Data_Daily!$B:$B, "Control", Raw_Data_Daily!$C:$C, "E. 40-99"),"") -> 30.505617 | P17: =IFERROR(SUMPRODUCT((Raw_Data_Daily!$B$2:$B$9999="Variant")*(Raw_Data_Daily!$C$2:$C$9999="E. 40-99")*Raw_Data_Daily!$D$2:$D$9999*Raw_Data_Daily!$AD$2:$AD$9999)/SUMIFS(Raw_Data_Daily!$D:$D, Raw_Data_Daily!$B:$B, "Variant", Raw_Data_Daily!$C:$C, "E. 40-99"),"") -> 30.607191 | Q17: =IFERROR((P17-O17)/ABS(O17),"") -> 0.0033297072 | R17: =IFERROR(SUMPRODUCT((Raw_Data_Daily!$B$2:$B$9999="Control")*(Raw_Data_Daily!$C$2:$C$9999="F. 100+")*Raw_Data_Daily!$D$2:$D$9999*Raw_Data_Daily!$AD$2:$AD$9999)/SUMIFS(Raw_Data_Daily!$D:$D, Raw_Data_Daily!$B:$B, "Control", Raw_Data_Daily!$C:$C, "F. 100+"),"") -> 57.792201 | S17: =IFERROR(SUMPRODUCT((Raw_Data_Daily!$B$2:$B$9999="Variant")*(Raw_Data_Daily!$C$2:$C$9999="F. 100+")*Raw_Data_Daily!$D$2:$D$9999*Raw_Data_Daily!$AD$2:$AD$9999)/SUMIFS(Raw_Data_Daily!$D:$D, Raw_Data_Daily!$B:$B, "Variant", Raw_Data_Daily!$C:$C, "F. 100+"),"") -> 56.87259 | T17: =IFERROR((S17-R17)/ABS(R17),"") -> -0.015912358
B18: P25 daily streak | C18: =IFERROR(SUMPRODUCT((Raw_Data_Daily!$B$2:$B$9999="Control")*(Raw_Data_Daily!$C$2:$C$9999="A. 0")*Raw_Data_Daily!$D$2:$D$9999*Raw_Data_Daily!$AE$2:$AE$9999)/SUMIFS(Raw_Data_Daily!$D:$D, Raw_Data_Daily!$B:$B, "Control", Raw_Data_Daily!$C:$C, "A. 0"),"") -> 0 | D18: =IFERROR(SUMPRODUCT((Raw_Data_Daily!$B$2:$B$9999="Variant")*(Raw_Data_Daily!$C$2:$C$9999="A. 0")*Raw_Data_Daily!$D$2:$D$9999*Raw_Data_Daily!$AE$2:$AE$9999)/SUMIFS(Raw_Data_Daily!$D:$D, Raw_Data_Daily!$B:$B, "Variant", Raw_Data_Daily!$C:$C, "A. 0"),"") -> 0 | E18: =IFERROR((D18-C18)/ABS(C18),"") | F18: =IFERROR(SUMPRODUCT((Raw_Data_Daily!$B$2:$B$9999="Control")*(Raw_Data_Daily!$C$2:$C$9999="B. 1-9")*Raw_Data_Daily!$D$2:$D$9999*Raw_Data_Daily!$AE$2:$AE$9999)/SUMIFS(Raw_Data_Daily!$D:$D, Raw_Data_Daily!$B:$B, "Control", Raw_Data_Daily!$C:$C, "B. 1-9"),"") -> 1.3558617 | G18: =IFERROR(SUMPRODUCT((Raw_Data_Daily!$B$2:$B$9999="Variant")*(Raw_Data_Daily!$C$2:$C$9999="B. 1-9")*Raw_Data_Daily!$D$2:$D$9999*Raw_Data_Daily!$AE$2:$AE$9999)/SUMIFS(Raw_Data_Daily!$D:$D, Raw_Data_Daily!$B:$B, "Variant", Raw_Data_Daily!$C:$C, "B. 1-9"),"") -> 1.283184 | H18: =IFERROR((G18-F18)/ABS(F18),"") -> -0.053602626 | I18: =IFERROR(SUMPRODUCT((Raw_Data_Daily!$B$2:$B$9999="Control")*(Raw_Data_Daily!$C$2:$C$9999="C. 10-19")*Raw_Data_Daily!$D$2:$D$9999*Raw_Data_Daily!$AE$2:$AE$9999)/SUMIFS(Raw_Data_Daily!$D:$D, Raw_Data_Daily!$B:$B, "Control", Raw_Data_Daily!$C:$C, "C. 10-19"),"") -> 4.1431479 | J18: =IFERROR(SUMPRODUCT((Raw_Data_Daily!$B$2:$B$9999="Variant")*(Raw_Data_Daily!$C$2:$C$9999="C. 10-19")*Raw_Data_Daily!$D$2:$D$9999*Raw_Data_Daily!$AE$2:$AE$9999)/SUMIFS(Raw_Data_Daily!$D:$D, Raw_Data_Daily!$B:$B, "Variant", Raw_Data_Daily!$C:$C, "C. 10-19"),"") -> 4.1459458 | K18: =IFERROR((J18-I18)/ABS(I18),"") -> 0.00067531245 | L18: =IFERROR(SUMPRODUCT((Raw_Data_Daily!$B$2:$B$9999="Control")*(Raw_Data_Daily!$C$2:$C$9999="D. 20-39")*Raw_Data_Daily!$D$2:$D$9999*Raw_Data_Daily!$AE$2:$AE$9999)/SUMIFS(Raw_Data_Daily!$D:$D, Raw_Data_Daily!$B:$B, "Control", Raw_Data_Daily!$C:$C, "D. 20-39"),"") -> 6.9520648 | M18: =IFERROR(SUMPRODUCT((Raw_Data_Daily!$B$2:$B$9999="Variant")*(Raw_Data_Daily!$C$2:$C$9999="D. 20-39")*Raw_Data_Daily!$D$2:$D$9999*Raw_Data_Daily!$AE$2:$AE$9999)/SUMIFS(Raw_Data_Daily!$D:$D, Raw_Data_Daily!$B:$B, "Variant", Raw_Data_Daily!$C:$C, "D. 20-39"),"") -> 7.1522814 | N18: =IFERROR((M18-L18)/ABS(L18),"") -> 0.028799591 | O18: =IFERROR(SUMPRODUCT((Raw_Data_Daily!$B$2:$B$9999="Control")*(Raw_Data_Daily!$C$2:$C$9999="E. 40-99")*Raw_Data_Daily!$D$2:$D$9999*Raw_Data_Daily!$AE$2:$AE$9999)/SUMIFS(Raw_Data_Daily!$D:$D, Raw_Data_Daily!$B:$B, "Control", Raw_Data_Daily!$C:$C, "E. 40-99"),"") -> 12.107258 | P18: =IFERROR(SUMPRODUCT((Raw_Data_Daily!$B$2:$B$9999="Variant")*(Raw_Data_Daily!$C$2:$C$9999="E. 40-99")*Raw_Data_Daily!$D$2:$D$9999*Raw_Data_Daily!$AE$2:$AE$9999)/SUMIFS(Raw_Data_Daily!$D:$D, Raw_Data_Daily!$B:$B, "Variant", Raw_Data_Daily!$C:$C, "E. 40-99"),"") -> 12.572852 | Q18: =IFERROR((P18-O18)/ABS(O18),"") -> 0.038455741 | R18: =IFERROR(SUMPRODUCT((Raw_Data_Daily!$B$2:$B$9999="Control")*(Raw_Data_Daily!$C$2:$C$9999="F. 100+")*Raw_Data_Daily!$D$2:$D$9999*Raw_Data_Daily!$AE$2:$AE$9999)/SUMIFS(Raw_Data_Daily!$D:$D, Raw_Data_Daily!$B:$B, "Control", Raw_Data_Daily!$C:$C, "F. 100+"),"") -> 23.00524 | S18: =IFERROR(SUMPRODUCT((Raw_Data_Daily!$B$2:$B$9999="Variant")*(Raw_Data_Daily!$C$2:$C$9999="F. 100+")*Raw_Data_Daily!$D$2:$D$9999*Raw_Data_Daily!$AE$2:$AE$9999)/SUMIFS(Raw_Data_Daily!$D:$D, Raw_Data_Daily!$B:$B, "Variant", Raw_Data_Daily!$C:$C, "F. 100+"),"") -> 23.13763 | T18: =IFERROR((S18-R18)/ABS(R18),"") -> 0.0057547941
B19: P50 daily streak | C19: =IFERROR(SUMPRODUCT((Raw_Data_Daily!$B$2:$B$9999="Control")*(Raw_Data_Daily!$C$2:$C$9999="A. 0")*Raw_Data_Daily!$D$2:$D$9999*Raw_Data_Daily!$AF$2:$AF$9999)/SUMIFS(Raw_Data_Daily!$D:$D, Raw_Data_Daily!$B:$B, "Control", Raw_Data_Daily!$C:$C, "A. 0"),"") -> 0 | D19: =IFERROR(SUMPRODUCT((Raw_Data_Daily!$B$2:$B$9999="Variant")*(Raw_Data_Daily!$C$2:$C$9999="A. 0")*Raw_Data_Daily!$D$2:$D$9999*Raw_Data_Daily!$AF$2:$AF$9999)/SUMIFS(Raw_Data_Daily!$D:$D, Raw_Data_Daily!$B:$B, "Variant", Raw_Data_Daily!$C:$C, "A. 0"),"") -> 0 | E19: =IFERROR((D19-C19)/ABS(C19),"") | F19: =IFERROR(SUMPRODUCT((Raw_Data_Daily!$B$2:$B$9999="Control")*(Raw_Data_Daily!$C$2:$C$9999="B. 1-9")*Raw_Data_Daily!$D$2:$D$9999*Raw_Data_Daily!$AF$2:$AF$9999)/SUMIFS(Raw_Data_Daily!$D:$D, Raw_Data_Daily!$B:$B, "Control", Raw_Data_Daily!$C:$C, "B. 1-9"),"") -> 3 | G19: =IFERROR(SUMPRODUCT((Raw_Data_Daily!$B$2:$B$9999="Variant")*(Raw_Data_Daily!$C$2:$C$9999="B. 1-9")*Raw_Data_Daily!$D$2:$D$9999*Raw_Data_Daily!$AF$2:$AF$9999)/SUMIFS(Raw_Data_Daily!$D:$D, Raw_Data_Daily!$B:$B, "Variant", Raw_Data_Daily!$C:$C, "B. 1-9"),"") -> 3 | H19: =IFERROR((G19-F19)/ABS(F19),"") -> 0 | I19: =IFERROR(SUMPRODUCT((Raw_Data_Daily!$B$2:$B$9999="Control")*(Raw_Data_Daily!$C$2:$C$9999="C. 10-19")*Raw_Data_Daily!$D$2:$D$9999*Raw_Data_Daily!$AF$2:$AF$9999)/SUMIFS(Raw_Data_Daily!$D:$D, Raw_Data_Daily!$B:$B, "Control", Raw_Data_Daily!$C:$C, "C. 10-19"),"") -> 7.9223929 | J19: =IFERROR(SUMPRODUCT((Raw_Data_Daily!$B$2:$B$9999="Variant")*(Raw_Data_Daily!$C$2:$C$9999="C. 10-19")*Raw_Data_Daily!$D$2:$D$9999*Raw_Data_Daily!$AF$2:$AF$9999)/SUMIFS(Raw_Data_Daily!$D:$D, Raw_Data_Daily!$B:$B, "Variant", Raw_Data_Daily!$C:$C, "C. 10-19"),"") -> 8.2851487 | K19: =IFERROR((J19-I19)/ABS(I19),"") -> 0.04578866 | L19: =IFERROR(SUMPRODUCT((Raw_Data_Daily!$B$2:$B$9999="Control")*(Raw_Data_Daily!$C$2:$C$9999="D. 20-39")*Raw_Data_Daily!$D$2:$D$9999*Raw_Data_Daily!$AF$2:$AF$9999)/SUMIFS(Raw_Data_Daily!$D:$D, Raw_Data_Daily!$B:$B, "Control", Raw_Data_Daily!$C:$C, "D. 20-39"),"") -> 13.149576 | M19: =IFERROR(SUMPRODUCT((Raw_Data_Daily!$B$2:$B$9999="Variant")*(Raw_Data_Daily!$C$2:$C$9999="D. 20-39")*Raw_Data_Daily!$D$2:$D$9999*Raw_Data_Daily!$AF$2:$AF$9999)/SUMIFS(Raw_Data_Daily!$D:$D, Raw_Data_Daily!$B:$B, "Variant", Raw_Data_Daily!$C:$C, "D. 20-39"),"") -> 13.152281 | N19: =IFERROR((M19-L19)/ABS(L19),"") -> 0.00020570319 | O19: =IFERROR(SUMPRODUCT((Raw_Data_Daily!$B$2:$B$9999="Control")*(Raw_Data_Daily!$C$2:$C$9999="E. 40-99")*Raw_Data_Daily!$D$2:$D$9999*Raw_Data_Daily!$AF$2:$AF$9999)/SUMIFS(Raw_Data_Daily!$D:$D, Raw_Data_Daily!$B:$B, "Control", Raw_Data_Daily!$C:$C, "E. 40-99"),"") -> 23.010572 | P19: =IFERROR(SUMPRODUCT((Raw_Data_Daily!$B$2:$B$9999="Variant")*(Raw_Data_Daily!$C$2:$C$9999="E. 40-99")*Raw_Data_Daily!$D$2:$D$9999*Raw_Data_Daily!$AF$2:$AF$9999)/SUMIFS(Raw_Data_Daily!$D:$D, Raw_Data_Daily!$B:$B, "Variant", Raw_Data_Daily!$C:$C, "E. 40-99"),"") -> 23.433598 | Q19: =IFERROR((P19-O19)/ABS(O19),"") -> 0.018383976 | R19: =IFERROR(SUMPRODUCT((Raw_Data_Daily!$B$2:$B$9999="Control")*(Raw_Data_Daily!$C$2:$C$9999="F. 100+")*Raw_Data_Daily!$D$2:$D$9999*Raw_Data_Daily!$AF$2:$AF$9999)/SUMIFS(Raw_Data_Daily!$D:$D, Raw_Data_Daily!$B:$B, "Control", Raw_Data_Daily!$C:$C, "F. 100+"),"") -> 41.220434 | S19: =IFERROR(SUMPRODUCT((Raw_Data_Daily!$B$2:$B$9999="Variant")*(Raw_Data_Daily!$C$2:$C$9999="F. 100+")*Raw_Data_Daily!$D$2:$D$9999*Raw_Data_Daily!$AF$2:$AF$9999)/SUMIFS(Raw_Data_Daily!$D:$D, Raw_Data_Daily!$B:$B, "Variant", Raw_Data_Daily!$C:$C, "F. 100+"),"") -> 42.282744 | T19: =IFERROR((S19-R19)/ABS(R19),"") -> 0.025771445
B20: P75 daily streak | C20: =IFERROR(SUMPRODUCT((Raw_Data_Daily!$B$2:$B$9999="Control")*(Raw_Data_Daily!$C$2:$C$9999="A. 0")*Raw_Data_Daily!$D$2:$D$9999*Raw_Data_Daily!$AG$2:$AG$9999)/SUMIFS(Raw_Data_Daily!$D:$D, Raw_Data_Daily!$B:$B, "Control", Raw_Data_Daily!$C:$C, "A. 0"),"") -> 0 | D20: =IFERROR(SUMPRODUCT((Raw_Data_Daily!$B$2:$B$9999="Variant")*(Raw_Data_Daily!$C$2:$C$9999="A. 0")*Raw_Data_Daily!$D$2:$D$9999*Raw_Data_Daily!$AG$2:$AG$9999)/SUMIFS(Raw_Data_Daily!$D:$D, Raw_Data_Daily!$B:$B, "Variant", Raw_Data_Daily!$C:$C, "A. 0"),"") -> 0 | E20: =IFERROR((D20-C20)/ABS(C20),"") | F20: =IFERROR(SUMPRODUCT((Raw_Data_Daily!$B$2:$B$9999="Control")*(Raw_Data_Daily!$C$2:$C$9999="B. 1-9")*Raw_Data_Daily!$D$2:$D$9999*Raw_Data_Daily!$AG$2:$AG$9999)/SUMIFS(Raw_Data_Daily!$D:$D, Raw_Data_Daily!$B:$B, "Control", Raw_Data_Daily!$C:$C, "B. 1-9"),"") -> 5.4941747 | G20: =IFERROR(SUMPRODUCT((Raw_Data_Daily!$B$2:$B$9999="Variant")*(Raw_Data_Daily!$C$2:$C$9999="B. 1-9")*Raw_Data_Daily!$D$2:$D$9999*Raw_Data_Daily!$AG$2:$AG$9999)/SUMIFS(Raw_Data_Daily!$D:$D, Raw_Data_Daily!$B:$B, "Variant", Raw_Data_Daily!$C:$C, "B. 1-9"),"") -> 5.4936045 | H20: =IFERROR((G20-F20)/ABS(F20),"") -> -0.00010378444 | I20: =IFERROR(SUMPRODUCT((Raw_Data_Daily!$B$2:$B$9999="Control")*(Raw_Data_Daily!$C$2:$C$9999="C. 10-19")*Raw_Data_Daily!$D$2:$D$9999*Raw_Data_Daily!$AG$2:$AG$9999)/SUMIFS(Raw_Data_Daily!$D:$D, Raw_Data_Daily!$B:$B, "Control", Raw_Data_Daily!$C:$C, "C. 10-19"),"") -> 12.922393 | J20: =IFERROR(SUMPRODUCT((Raw_Data_Daily!$B$2:$B$9999="Variant")*(Raw_Data_Daily!$C$2:$C$9999="C. 10-19")*Raw_Data_Daily!$D$2:$D$9999*Raw_Data_Daily!$AG$2:$AG$9999)/SUMIFS(Raw_Data_Daily!$D:$D, Raw_Data_Daily!$B:$B, "Variant", Raw_Data_Daily!$C:$C, "C. 10-19"),"") -> 13 | K20: =IFERROR((J20-I20)/ABS(I20),"") -> 0.0060056288 | L20: =IFERROR(SUMPRODUCT((Raw_Data_Daily!$B$2:$B$9999="Control")*(Raw_Data_Daily!$C$2:$C$9999="D. 20-39")*Raw_Data_Daily!$D$2:$D$9999*Raw_Data_Daily!$AG$2:$AG$9999)/SUMIFS(Raw_Data_Daily!$D:$D, Raw_Data_Daily!$B:$B, "Control", Raw_Data_Daily!$C:$C, "D. 20-39"),"") -> 23.012193 | M20: =IFERROR(SUMPRODUCT((Raw_Data_Daily!$B$2:$B$9999="Variant")*(Raw_Data_Daily!$C$2:$C$9999="D. 20-39")*Raw_Data_Daily!$D$2:$D$9999*Raw_Data_Daily!$AG$2:$AG$9999)/SUMIFS(Raw_Data_Daily!$D:$D, Raw_Data_Daily!$B:$B, "Variant", Raw_Data_Daily!$C:$C, "D. 20-39"),"") -> 23.156976 | N20: =IFERROR((M20-L20)/ABS(L20),"") -> 0.0062915525 | O20: =IFERROR(SUMPRODUCT((Raw_Data_Daily!$B$2:$B$9999="Control")*(Raw_Data_Daily!$C$2:$C$9999="E. 40-99")*Raw_Data_Daily!$D$2:$D$9999*Raw_Data_Daily!$AG$2:$AG$9999)/SUMIFS(Raw_Data_Daily!$D:$D, Raw_Data_Daily!$B:$B, "Control", Raw_Data_Daily!$C:$C, "E. 40-99"),"") -> 41.696576 | P20: =IFERROR(SUMPRODUCT((Raw_Data_Daily!$B$2:$B$9999="Variant")*(Raw_Data_Daily!$C$2:$C$9999="E. 40-99")*Raw_Data_Daily!$D$2:$D$9999*Raw_Data_Daily!$AG$2:$AG$9999)/SUMIFS(Raw_Data_Daily!$D:$D, Raw_Data_Daily!$B:$B, "Variant", Raw_Data_Daily!$C:$C, "E. 40-99"),"") -> 41.92329 | Q20: =IFERROR((P20-O20)/ABS(O20),"") -> 0.0054372158 | R20: =IFERROR(SUMPRODUCT((Raw_Data_Daily!$B$2:$B$9999="Control")*(Raw_Data_Daily!$C$2:$C$9999="F. 100+")*Raw_Data_Daily!$D$2:$D$9999*Raw_Data_Daily!$AG$2:$AG$9999)/SUMIFS(Raw_Data_Daily!$D:$D, Raw_Data_Daily!$B:$B, "Control", Raw_Data_Daily!$C:$C, "F. 100+"),"") -> 75.334955 | S20: =IFERROR(SUMPRODUCT((Raw_Data_Daily!$B$2:$B$9999="Variant")*(Raw_Data_Daily!$C$2:$C$9999="F. 100+")*Raw_Data_Daily!$D$2:$D$9999*Raw_Data_Daily!$AG$2:$AG$9999)/SUMIFS(Raw_Data_Daily!$D:$D, Raw_Data_Daily!$B:$B, "Variant", Raw_Data_Daily!$C:$C, "F. 100+"),"") -> 74.793347 | T20: =IFERROR((S20-R20)/ABS(R20),"") -> -0.0071893306
B21: P90 daily streak | C21: =IFERROR(SUMPRODUCT((Raw_Data_Daily!$B$2:$B$9999="Control")*(Raw_Data_Daily!$C$2:$C$9999="A. 0")*Raw_Data_Daily!$D$2:$D$9999*Raw_Data_Daily!$AH$2:$AH$9999)/SUMIFS(Raw_Data_Daily!$D:$D, Raw_Data_Daily!$B:$B, "Control", Raw_Data_Daily!$C:$C, "A. 0"),"") -> 0 | D21: =IFERROR(SUMPRODUCT((Raw_Data_Daily!$B$2:$B$9999="Variant")*(Raw_Data_Daily!$C$2:$C$9999="A. 0")*Raw_Data_Daily!$D$2:$D$9999*Raw_Data_Daily!$AH$2:$AH$9999)/SUMIFS(Raw_Data_Daily!$D:$D, Raw_Data_Daily!$B:$B, "Variant", Raw_Data_Daily!$C:$C, "A. 0"),"") -> 0 | E21: =IFERROR((D21-C21)/ABS(C21),"") | F21: =IFERROR(SUMPRODUCT((Raw_Data_Daily!$B$2:$B$9999="Control")*(Raw_Data_Daily!$C$2:$C$9999="B. 1-9")*Raw_Data_Daily!$D$2:$D$9999*Raw_Data_Daily!$AH$2:$AH$9999)/SUMIFS(Raw_Data_Daily!$D:$D, Raw_Data_Daily!$B:$B, "Control", Raw_Data_Daily!$C:$C, "B. 1-9"),"") -> 8.4941747 | G21: =IFERROR(SUMPRODUCT((Raw_Data_Daily!$B$2:$B$9999="Variant")*(Raw_Data_Daily!$C$2:$C$9999="B. 1-9")*Raw_Data_Daily!$D$2:$D$9999*Raw_Data_Daily!$AH$2:$AH$9999)/SUMIFS(Raw_Data_Daily!$D:$D, Raw_Data_Daily!$B:$B, "Variant", Raw_Data_Daily!$C:$C, "B. 1-9"),"") -> 8.6365464 | H21: =IFERROR((G21-F21)/ABS(F21),"") -> 0.016761103 | I21: =IFERROR(SUMPRODUCT((Raw_Data_Daily!$B$2:$B$9999="Control")*(Raw_Data_Daily!$C$2:$C$9999="C. 10-19")*Raw_Data_Daily!$D$2:$D$9999*Raw_Data_Daily!$AH$2:$AH$9999)/SUMIFS(Raw_Data_Daily!$D:$D, Raw_Data_Daily!$B:$B, "Control", Raw_Data_Daily!$C:$C, "C. 10-19"),"") -> 18.642542 | J21: =IFERROR(SUMPRODUCT((Raw_Data_Daily!$B$2:$B$9999="Variant")*(Raw_Data_Daily!$C$2:$C$9999="C. 10-19")*Raw_Data_Daily!$D$2:$D$9999*Raw_Data_Daily!$AH$2:$AH$9999)/SUMIFS(Raw_Data_Daily!$D:$D, Raw_Data_Daily!$B:$B, "Variant", Raw_Data_Daily!$C:$C, "C. 10-19"),"") -> 18.639287 | K21: =IFERROR((J21-I21)/ABS(I21),"") -> -0.0001746184 | L21: =IFERROR(SUMPRODUCT((Raw_Data_Daily!$B$2:$B$9999="Control")*(Raw_Data_Daily!$C$2:$C$9999="D. 20-39")*Raw_Data_Daily!$D$2:$D$9999*Raw_Data_Daily!$AH$2:$AH$9999)/SUMIFS(Raw_Data_Daily!$D:$D, Raw_Data_Daily!$B:$B, "Control", Raw_Data_Daily!$C:$C, "D. 20-39"),"") -> 33.850424 | M21: =IFERROR(SUMPRODUCT((Raw_Data_Daily!$B$2:$B$9999="Variant")*(Raw_Data_Daily!$C$2:$C$9999="D. 20-39")*Raw_Data_Daily!$D$2:$D$9999*Raw_Data_Daily!$AH$2:$AH$9999)/SUMIFS(Raw_Data_Daily!$D:$D, Raw_Data_Daily!$B:$B, "Variant", Raw_Data_Daily!$C:$C, "D. 20-39"),"") -> 34.014552 | N21: =IFERROR((M21-L21)/ABS(L21),"") -> 0.0048486443 | O21: =IFERROR(SUMPRODUCT((Raw_Data_Daily!$B$2:$B$9999="Control")*(Raw_Data_Daily!$C$2:$C$9999="E. 40-99")*Raw_Data_Daily!$D$2:$D$9999*Raw_Data_Daily!$AH$2:$AH$9999)/SUMIFS(Raw_Data_Daily!$D:$D, Raw_Data_Daily!$B:$B, "Control", Raw_Data_Daily!$C:$C, "E. 40-99"),"") -> 63.492632 | P21: =IFERROR(SUMPRODUCT((Raw_Data_Daily!$B$2:$B$9999="Variant")*(Raw_Data_Daily!$C$2:$C$9999="E. 40-99")*Raw_Data_Daily!$D$2:$D$9999*Raw_Data_Daily!$AH$2:$AH$9999)/SUMIFS(Raw_Data_Daily!$D:$D, Raw_Data_Daily!$B:$B, "Variant", Raw_Data_Daily!$C:$C, "E. 40-99"),"") -> 63.119155 | Q21: =IFERROR((P21-O21)/ABS(O21),"") -> -0.0058822192 | R21: =IFERROR(SUMPRODUCT((Raw_Data_Daily!$B$2:$B$9999="Control")*(Raw_Data_Daily!$C$2:$C$9999="F. 100+")*Raw_Data_Daily!$D$2:$D$9999*Raw_Data_Daily!$AH$2:$AH$9999)/SUMIFS(Raw_Data_Daily!$D:$D, Raw_Data_Daily!$B:$B, "Control", Raw_Data_Daily!$C:$C, "F. 100+"),"") -> 126.09618 | S21: =IFERROR(SUMPRODUCT((Raw_Data_Daily!$B$2:$B$9999="Variant")*(Raw_Data_Daily!$C$2:$C$9999="F. 100+")*Raw_Data_Daily!$D$2:$D$9999*Raw_Data_Daily!$AH$2:$AH$9999)/SUMIFS(Raw_Data_Daily!$D:$D, Raw_Data_Daily!$B:$B, "Variant", Raw_Data_Daily!$C:$C, "F. 100+"),"") -> 118.0973 | T21: =IFERROR((S21-R21)/ABS(R21),"") -> -0.063434794
B22: P99 daily streak | C22: =IFERROR(SUMPRODUCT((Raw_Data_Daily!$B$2:$B$9999="Control")*(Raw_Data_Daily!$C$2:$C$9999="A. 0")*Raw_Data_Daily!$D$2:$D$9999*Raw_Data_Daily!$BC$2:$BC$9999)/SUMIFS(Raw_Data_Daily!$D:$D, Raw_Data_Daily!$B:$B, "Control", Raw_Data_Daily!$C:$C, "A. 0"),"") -> 0 | D22: =IFERROR(SUMPRODUCT((Raw_Data_Daily!$B$2:$B$9999="Variant")*(Raw_Data_Daily!$C$2:$C$9999="A. 0")*Raw_Data_Daily!$D$2:$D$9999*Raw_Data_Daily!$BC$2:$BC$9999)/SUMIFS(Raw_Data_Daily!$D:$D, Raw_Data_Daily!$B:$B, "Variant", Raw_Data_Daily!$C:$C, "A. 0"),"") -> 0 | E22: =IFERROR((D22-C22)/ABS(C22),"") | F22: =IFERROR(SUMPRODUCT((Raw_Data_Daily!$B$2:$B$9999="Control")*(Raw_Data_Daily!$C$2:$C$9999="B. 1-9")*Raw_Data_Daily!$D$2:$D$9999*Raw_Data_Daily!$BC$2:$BC$9999)/SUMIFS(Raw_Data_Daily!$D:$D, Raw_Data_Daily!$B:$B, "Control", Raw_Data_Daily!$C:$C, "B. 1-9"),"") -> 16.855344 | G22: =IFERROR(SUMPRODUCT((Raw_Data_Daily!$B$2:$B$9999="Variant")*(Raw_Data_Daily!$C$2:$C$9999="B. 1-9")*Raw_Data_Daily!$D$2:$D$9999*Raw_Data_Daily!$BC$2:$BC$9999)/SUMIFS(Raw_Data_Daily!$D:$D, Raw_Data_Daily!$B:$B, "Variant", Raw_Data_Daily!$C:$C, "B. 1-9"),"") -> 17.073663 | H22: =IFERROR((G22-F22)/ABS(F22),"") -> 0.012952515 | I22: =IFERROR(SUMPRODUCT((Raw_Data_Daily!$B$2:$B$9999="Control")*(Raw_Data_Daily!$C$2:$C$9999="C. 10-19")*Raw_Data_Daily!$D$2:$D$9999*Raw_Data_Daily!$BC$2:$BC$9999)/SUMIFS(Raw_Data_Daily!$D:$D, Raw_Data_Daily!$B:$B, "Control", Raw_Data_Daily!$C:$C, "C. 10-19"),"") -> 33.846264 | J22: =IFERROR(SUMPRODUCT((Raw_Data_Daily!$B$2:$B$9999="Variant")*(Raw_Data_Daily!$C$2:$C$9999="C. 10-19")*Raw_Data_Daily!$D$2:$D$9999*Raw_Data_Daily!$BC$2:$BC$9999)/SUMIFS(Raw_Data_Daily!$D:$D, Raw_Data_Daily!$B:$B, "Variant", Raw_Data_Daily!$C:$C, "C. 10-19"),"") -> 34.20884 | K22: =IFERROR((J22-I22)/ABS(I22),"") -> 0.010712451 | L22: =IFERROR(SUMPRODUCT((Raw_Data_Daily!$B$2:$B$9999="Control")*(Raw_Data_Daily!$C$2:$C$9999="D. 20-39")*Raw_Data_Daily!$D$2:$D$9999*Raw_Data_Daily!$BC$2:$BC$9999)/SUMIFS(Raw_Data_Daily!$D:$D, Raw_Data_Daily!$B:$B, "Control", Raw_Data_Daily!$C:$C, "D. 20-39"),"") -> 61.754057 | M22: =IFERROR(SUMPRODUCT((Raw_Data_Daily!$B$2:$B$9999="Variant")*(Raw_Data_Daily!$C$2:$C$9999="D. 20-39")*Raw_Data_Daily!$D$2:$D$9999*Raw_Data_Daily!$BC$2:$BC$9999)/SUMIFS(Raw_Data_Daily!$D:$D, Raw_Data_Daily!$B:$B, "Variant", Raw_Data_Daily!$C:$C, "D. 20-39"),"") -> 61.236246 | N22: =IFERROR((M22-L22)/ABS(L22),"") -> -0.0083850491 | O22: =IFERROR(SUMPRODUCT((Raw_Data_Daily!$B$2:$B$9999="Control")*(Raw_Data_Daily!$C$2:$C$9999="E. 40-99")*Raw_Data_Daily!$D$2:$D$9999*Raw_Data_Daily!$BC$2:$BC$9999)/SUMIFS(Raw_Data_Daily!$D:$D, Raw_Data_Daily!$B:$B, "Control", Raw_Data_Daily!$C:$C, "E. 40-99"),"") -> 124.1198 | P22: =IFERROR(SUMPRODUCT((Raw_Data_Daily!$B$2:$B$9999="Variant")*(Raw_Data_Daily!$C$2:$C$9999="E. 40-99")*Raw_Data_Daily!$D$2:$D$9999*Raw_Data_Daily!$BC$2:$BC$9999)/SUMIFS(Raw_Data_Daily!$D:$D, Raw_Data_Daily!$B:$B, "Variant", Raw_Data_Daily!$C:$C, "E. 40-99"),"") -> 118.95652 | Q22: =IFERROR((P22-O22)/ABS(O22),"") -> -0.041599192 | R22: =IFERROR(SUMPRODUCT((Raw_Data_Daily!$B$2:$B$9999="Control")*(Raw_Data_Daily!$C$2:$C$9999="F. 100+")*Raw_Data_Daily!$D$2:$D$9999*Raw_Data_Daily!$BC$2:$BC$9999)/SUMIFS(Raw_Data_Daily!$D:$D, Raw_Data_Daily!$B:$B, "Control", Raw_Data_Daily!$C:$C, "F. 100+"),"") -> 254.06774 | S22: =IFERROR(SUMPRODUCT((Raw_Data_Daily!$B$2:$B$9999="Variant")*(Raw_Data_Daily!$C$2:$C$9999="F. 100+")*Raw_Data_Daily!$D$2:$D$9999*Raw_Data_Daily!$BC$2:$BC$9999)/SUMIFS(Raw_Data_Daily!$D:$D, Raw_Data_Daily!$B:$B, "Variant", Raw_Data_Daily!$C:$C, "F. 100+"),"") -> 237.80665 | T22: =IFERROR((S22-R22)/ABS(R22),"") -> -0.064002957
A23: Difficulty
B24: Pass rate | C24: =IFERROR(SUMPRODUCT((Raw_Data_Daily!$B$2:$B$9999="Control")*(Raw_Data_Daily!$C$2:$C$9999="A. 0")*Raw_Data_Daily!$D$2:$D$9999*Raw_Data_Daily!$M$2:$M$9999)/SUMIFS(Raw_Data_Daily!$D:$D, Raw_Data_Daily!$B:$B, "Control", Raw_Data_Daily!$C:$C, "A. 0"),"") -> 0.57545837 | D24: =IFERROR(SUMPRODUCT((Raw_Data_Daily!$B$2:$B$9999="Variant")*(Raw_Data_Daily!$C$2:$C$9999="A. 0")*Raw_Data_Daily!$D$2:$D$9999*Raw_Data_Daily!$M$2:$M$9999)/SUMIFS(Raw_Data_Daily!$D:$D, Raw_Data_Daily!$B:$B, "Variant", Raw_Data_Daily!$C:$C, "A. 0"),"") -> 0.60411321 | E24: =IFERROR((D24-C24)/ABS(C24),"") -> 0.049794811 | F24: =IFERROR(SUMPRODUCT((Raw_Data_Daily!$B$2:$B$9999="Control")*(Raw_Data_Daily!$C$2:$C$9999="B. 1-9")*Raw_Data_Daily!$D$2:$D$9999*Raw_Data_Daily!$M$2:$M$9999)/SUMIFS(Raw_Data_Daily!$D:$D, Raw_Data_Daily!$B:$B, "Control", Raw_Data_Daily!$C:$C, "B. 1-9"),"") -> 0.45455381 | G24: =IFERROR(SUMPRODUCT((Raw_Data_Daily!$B$2:$B$9999="Variant")*(Raw_Data_Daily!$C$2:$C$9999="B. 1-9")*Raw_Data_Daily!$D$2:$D$9999*Raw_Data_Daily!$M$2:$M$9999)/SUMIFS(Raw_Data_Daily!$D:$D, Raw_Data_Daily!$B:$B, "Variant", Raw_Data_Daily!$C:$C, "B. 1-9"),"") -> 0.4609512 | H24: =IFERROR((G24-F24)/ABS(F24),"") -> 0.014074002 | I24: =IFERROR(SUMPRODUCT((Raw_Data_Daily!$B$2:$B$9999="Control")*(Raw_Data_Daily!$C$2:$C$9999="C. 10-19")*Raw_Data_Daily!$D$2:$D$9999*Raw_Data_Daily!$M$2:$M$9999)/SUMIFS(Raw_Data_Daily!$D:$D, Raw_Data_Daily!$B:$B, "Control", Raw_Data_Daily!$C:$C, "C. 10-19"),"") -> 0.56860522 | J24: =IFERROR(SUMPRODUCT((Raw_Data_Daily!$B$2:$B$9999="Variant")*(Raw_Data_Daily!$C$2:$C$9999="C. 10-19")*Raw_Data_Daily!$D$2:$D$9999*Raw_Data_Daily!$M$2:$M$9999)/SUMIFS(Raw_Data_Daily!$D:$D, Raw_Data_Daily!$B:$B, "Variant", Raw_Data_Daily!$C:$C, "C. 10-19"),"") -> 0.55741126 | K24: =IFERROR((J24-I24)/ABS(I24),"") -> -0.019686687 | L24: =IFERROR(SUMPRODUCT((Raw_Data_Daily!$B$2:$B$9999="Control")*(Raw_Data_Daily!$C$2:$C$9999="D. 20-39")*Raw_Data_Daily!$D$2:$D$9999*Raw_Data_Daily!$M$2:$M$9999)/SUMIFS(Raw_Data_Daily!$D:$D, Raw_Data_Daily!$B:$B, "Control", Raw_Data_Daily!$C:$C, "D. 20-39"),"") -> 0.66742436 | M24: =IFERROR(SUMPRODUCT((Raw_Data_Daily!$B$2:$B$9999="Variant")*(Raw_Data_Daily!$C$2:$C$9999="D. 20-39")*Raw_Data_Daily!$D$2:$D$9999*Raw_Data_Daily!$M$2:$M$9999)/SUMIFS(Raw_Data_Daily!$D:$D, Raw_Data_Daily!$B:$B, "Variant", Raw_Data_Daily!$C:$C, "D. 20-39"),"") -> 0.65233135 | N24: =IFERROR((M24-L24)/ABS(L24),"") -> -0.022613805 | O24: =IFERROR(SUMPRODUCT((Raw_Data_Daily!$B$2:$B$9999="Control")*(Raw_Data_Daily!$C$2:$C$9999="E. 40-99")*Raw_Data_Daily!$D$2:$D$9999*Raw_Data_Daily!$M$2:$M$9999)/SUMIFS(Raw_Data_Daily!$D:$D, Raw_Data_Daily!$B:$B, "Control", Raw_Data_Daily!$C:$C, "E. 40-99"),"") -> 0.73277901 | P24: =IFERROR(SUMPRODUCT((Raw_Data_Daily!$B$2:$B$9999="Variant")*(Raw_Data_Daily!$C$2:$C$9999="E. 40-99")*Raw_Data_Daily!$D$2:$D$9999*Raw_Data_Daily!$M$2:$M$9999)/SUMIFS(Raw_Data_Daily!$D:$D, Raw_Data_Daily!$B:$B, "Variant", Raw_Data_Daily!$C:$C, "E. 40-99"),"") -> 0.72835119 | Q24: =IFERROR((P24-O24)/ABS(O24),"") -> -0.0060425064 | R24: =IFERROR(SUMPRODUCT((Raw_Data_Daily!$B$2:$B$9999="Control")*(Raw_Data_Daily!$C$2:$C$9999="F. 100+")*Raw_Data_Daily!$D$2:$D$9999*Raw_Data_Daily!$M$2:$M$9999)/SUMIFS(Raw_Data_Daily!$D:$D, Raw_Data_Daily!$B:$B, "Control", Raw_Data_Daily!$C:$C, "F. 100+"),"") -> 0.78005951 | S24: =IFERROR(SUMPRODUCT((Raw_Data_Daily!$B$2:$B$9999="Variant")*(Raw_Data_Daily!$C$2:$C$9999="F. 100+")*Raw_Data_Daily!$D$2:$D$9999*Raw_Data_Daily!$M$2:$M$9999)/SUMIFS(Raw_Data_Daily!$D:$D, Raw_Data_Daily!$B:$B, "Variant", Raw_Data_Daily!$C:$C, "F. 100+"),"") -> 0.76718312 | T24: =IFERROR((S24-R24)/ABS(R24),"") -> -0.01650693
B25: OOM rate | C25: =IFERROR(SUMPRODUCT((Raw_Data_Daily!$B$2:$B$9999="Control")*(Raw_Data_Daily!$C$2:$C$9999="A. 0")*Raw_Data_Daily!$D$2:$D$9999*Raw_Data_Daily!$N$2:$N$9999)/SUMIFS(Raw_Data_Daily!$D:$D, Raw_Data_Daily!$B:$B, "Control", Raw_Data_Daily!$C:$C, "A. 0"),"") -> 0.52652232 | D25: =IFERROR(SUMPRODUCT((Raw_Data_Daily!$B$2:$B$9999="Variant")*(Raw_Data_Daily!$C$2:$C$9999="A. 0")*Raw_Data_Daily!$D$2:$D$9999*Raw_Data_Daily!$N$2:$N$9999)/SUMIFS(Raw_Data_Daily!$D:$D, Raw_Data_Daily!$B:$B, "Variant", Raw_Data_Daily!$C:$C, "A. 0"),"") -> 0.50720175 | E25: =IFERROR((D25-C25)/ABS(C25),"") -> -0.036694675 | F25: =IFERROR(SUMPRODUCT((Raw_Data_Daily!$B$2:$B$9999="Control")*(Raw_Data_Daily!$C$2:$C$9999="B. 1-9")*Raw_Data_Daily!$D$2:$D$9999*Raw_Data_Daily!$N$2:$N$9999)/SUMIFS(Raw_Data_Daily!$D:$D, Raw_Data_Daily!$B:$B, "Control", Raw_Data_Daily!$C:$C, "B. 1-9"),"") -> 0.65183815 | G25: =IFERROR(SUMPRODUCT((Raw_Data_Daily!$B$2:$B$9999="Variant")*(Raw_Data_Daily!$C$2:$C$9999="B. 1-9")*Raw_Data_Daily!$D$2:$D$9999*Raw_Data_Daily!$N$2:$N$9999)/SUMIFS(Raw_Data_Daily!$D:$D, Raw_Data_Daily!$B:$B, "Variant", Raw_Data_Daily!$C:$C, "B. 1-9"),"") -> 0.64410258 | H25: =IFERROR((G25-F25)/ABS(F25),"") -> -0.011867312 | I25: =IFERROR(SUMPRODUCT((Raw_Data_Daily!$B$2:$B$9999="Control")*(Raw_Data_Daily!$C$2:$C$9999="C. 10-19")*Raw_Data_Daily!$D$2:$D$9999*Raw_Data_Daily!$N$2:$N$9999)/SUMIFS(Raw_Data_Daily!$D:$D, Raw_Data_Daily!$B:$B, "Control", Raw_Data_Daily!$C:$C, "C. 10-19"),"") -> 0.5586567 | J25: =IFERROR(SUMPRODUCT((Raw_Data_Daily!$B$2:$B$9999="Variant")*(Raw_Data_Daily!$C$2:$C$9999="C. 10-19")*Raw_Data_Daily!$D$2:$D$9999*Raw_Data_Daily!$N$2:$N$9999)/SUMIFS(Raw_Data_Daily!$D:$D, Raw_Data_Daily!$B:$B, "Variant", Raw_Data_Daily!$C:$C, "C. 10-19"),"") -> 0.56476395 | K25: =IFERROR((J25-I25)/ABS(I25),"") -> 0.010932015 | L25: =IFERROR(SUMPRODUCT((Raw_Data_Daily!$B$2:$B$9999="Control")*(Raw_Data_Daily!$C$2:$C$9999="D. 20-39")*Raw_Data_Daily!$D$2:$D$9999*Raw_Data_Daily!$N$2:$N$9999)/SUMIFS(Raw_Data_Daily!$D:$D, Raw_Data_Daily!$B:$B, "Control", Raw_Data_Daily!$C:$C, "D. 20-39"),"") -> 0.46892129 | M25: =IFERROR(SUMPRODUCT((Raw_Data_Daily!$B$2:$B$9999="Variant")*(Raw_Data_Daily!$C$2:$C$9999="D. 20-39")*Raw_Data_Daily!$D$2:$D$9999*Raw_Data_Daily!$N$2:$N$9999)/SUMIFS(Raw_Data_Daily!$D:$D, Raw_Data_Daily!$B:$B, "Variant", Raw_Data_Daily!$C:$C, "D. 20-39"),"") -> 0.4805561 | N25: =IFERROR((M25-L25)/ABS(L25),"") -> 0.024811846 | O25: =IFERROR(SUMPRODUCT((Raw_Data_Daily!$B$2:$B$9999="Control")*(Raw_Data_Daily!$C$2:$C$9999="E. 40-99")*Raw_Data_Daily!$D$2:$D$9999*Raw_Data_Daily!$N$2:$N$9999)/SUMIFS(Raw_Data_Daily!$D:$D, Raw_Data_Daily!$B:$B, "Control", Raw_Data_Daily!$C:$C, "E. 40-99"),"") -> 0.39893738 | P25: =IFERROR(SUMPRODUCT((Raw_Data_Daily!$B$2:$B$9999="Variant")*(Raw_Data_Daily!$C$2:$C$9999="E. 40-99")*Raw_Data_Daily!$D$2:$D$9999*Raw_Data_Daily!$N$2:$N$9999)/SUMIFS(Raw_Data_Daily!$D:$D, Raw_Data_Daily!$B:$B, "Variant", Raw_Data_Daily!$C:$C, "E. 40-99"),"") -> 0.4028953 | Q25: =IFERROR((P25-O25)/ABS(O25),"") -> 0.0099211676 | R25: =IFERROR(SUMPRODUCT((Raw_Data_Daily!$B$2:$B$9999="Control")*(Raw_Data_Daily!$C$2:$C$9999="F. 100+")*Raw_Data_Daily!$D$2:$D$9999*Raw_Data_Daily!$N$2:$N$9999)/SUMIFS(Raw_Data_Daily!$D:$D, Raw_Data_Daily!$B:$B, "Control", Raw_Data_Daily!$C:$C, "F. 100+"),"") -> 0.32501688 | S25: =IFERROR(SUMPRODUCT((Raw_Data_Daily!$B$2:$B$9999="Variant")*(Raw_Data_Daily!$C$2:$C$9999="F. 100+")*Raw_Data_Daily!$D$2:$D$9999*Raw_Data_Daily!$N$2:$N$9999)/SUMIFS(Raw_Data_Daily!$D:$D, Raw_Data_Daily!$B:$B, "Variant", Raw_Data_Daily!$C:$C, "F. 100+"),"") -> 0.33744042 | T25: =IFERROR((S25-R25)/ABS(R25),"") -> 0.038224283
B26: First-try OOM rate | C26: =IFERROR(SUMPRODUCT((Raw_Data_Daily!$B$2:$B$9999="Control")*(Raw_Data_Daily!$C$2:$C$9999="A. 0")*Raw_Data_Daily!$D$2:$D$9999*Raw_Data_Daily!$O$2:$O$9999)/SUMIFS(Raw_Data_Daily!$D:$D, Raw_Data_Daily!$B:$B, "Control", Raw_Data_Daily!$C:$C, "A. 0"),"") -> 0.26604102 | D26: =IFERROR(SUMPRODUCT((Raw_Data_Daily!$B$2:$B$9999="Variant")*(Raw_Data_Daily!$C$2:$C$9999="A. 0")*Raw_Data_Daily!$D$2:$D$9999*Raw_Data_Daily!$O$2:$O$9999)/SUMIFS(Raw_Data_Daily!$D:$D, Raw_Data_Daily!$B:$B, "Variant", Raw_Data_Daily!$C:$C, "A. 0"),"") -> 0.2542265 | E26: =IFERROR((D26-C26)/ABS(C26),"") -> -0.044408632 | F26: =IFERROR(SUMPRODUCT((Raw_Data_Daily!$B$2:$B$9999="Control")*(Raw_Data_Daily!$C$2:$C$9999="B. 1-9")*Raw_Data_Daily!$D$2:$D$9999*Raw_Data_Daily!$O$2:$O$9999)/SUMIFS(Raw_Data_Daily!$D:$D, Raw_Data_Daily!$B:$B, "Control", Raw_Data_Daily!$C:$C, "B. 1-9"),"") -> 0.39299808 | G26: =IFERROR(SUMPRODUCT((Raw_Data_Daily!$B$2:$B$9999="Variant")*(Raw_Data_Daily!$C$2:$C$9999="B. 1-9")*Raw_Data_Daily!$D$2:$D$9999*Raw_Data_Daily!$O$2:$O$9999)/SUMIFS(Raw_Data_Daily!$D:$D, Raw_Data_Daily!$B:$B, "Variant", Raw_Data_Daily!$C:$C, "B. 1-9"),"") -> 0.38042953 | H26: =IFERROR((G26-F26)/ABS(F26),"") -> -0.031981213 | I26: =IFERROR(SUMPRODUCT((Raw_Data_Daily!$B$2:$B$9999="Control")*(Raw_Data_Daily!$C$2:$C$9999="C. 10-19")*Raw_Data_Daily!$D$2:$D$9999*Raw_Data_Daily!$O$2:$O$9999)/SUMIFS(Raw_Data_Daily!$D:$D, Raw_Data_Daily!$B:$B, "Control", Raw_Data_Daily!$C:$C, "C. 10-19"),"") -> 0.33475368 | J26: =IFERROR(SUMPRODUCT((Raw_Data_Daily!$B$2:$B$9999="Variant")*(Raw_Data_Daily!$C$2:$C$9999="C. 10-19")*Raw_Data_Daily!$D$2:$D$9999*Raw_Data_Daily!$O$2:$O$9999)/SUMIFS(Raw_Data_Daily!$D:$D, Raw_Data_Daily!$B:$B, "Variant", Raw_Data_Daily!$C:$C, "C. 10-19"),"") -> 0.33207356 | K26: =IFERROR((J26-I26)/ABS(I26),"") -> -0.0080062583 | L26: =IFERROR(SUMPRODUCT((Raw_Data_Daily!$B$2:$B$9999="Control")*(Raw_Data_Daily!$C$2:$C$9999="D. 20-39")*Raw_Data_Daily!$D$2:$D$9999*Raw_Data_Daily!$O$2:$O$9999)/SUMIFS(Raw_Data_Daily!$D:$D, Raw_Data_Daily!$B:$B, "Control", Raw_Data_Daily!$C:$C, "D. 20-39"),"") -> 0.29009336 | M26: =IFERROR(SUMPRODUCT((Raw_Data_Daily!$B$2:$B$9999="Variant")*(Raw_Data_Daily!$C$2:$C$9999="D. 20-39")*Raw_Data_Daily!$D$2:$D$9999*Raw_Data_Daily!$O$2:$O$9999)/SUMIFS(Raw_Data_Daily!$D:$D, Raw_Data_Daily!$B:$B, "Variant", Raw_Data_Daily!$C:$C, "D. 20-39"),"") -> 0.29132128 | N26: =IFERROR((M26-L26)/ABS(L26),"") -> 0.004232834 | O26: =IFERROR(SUMPRODUCT((Raw_Data_Daily!$B$2:$B$9999="Control")*(Raw_Data_Daily!$C$2:$C$9999="E. 40-99")*Raw_Data_Daily!$D$2:$D$9999*Raw_Data_Daily!$O$2:$O$9999)/SUMIFS(Raw_Data_Daily!$D:$D, Raw_Data_Daily!$B:$B, "Control", Raw_Data_Daily!$C:$C, "E. 40-99"),"") -> 0.25072898 | P26: =IFERROR(SUMPRODUCT((Raw_Data_Daily!$B$2:$B$9999="Variant")*(Raw_Data_Daily!$C$2:$C$9999="E. 40-99")*Raw_Data_Daily!$D$2:$D$9999*Raw_Data_Daily!$O$2:$O$9999)/SUMIFS(Raw_Data_Daily!$D:$D, Raw_Data_Daily!$B:$B, "Variant", Raw_Data_Daily!$C:$C, "E. 40-99"),"") -> 0.25082966 | Q26: =IFERROR((P26-O26)/ABS(O26),"") -> 0.00040155303 | R26: =IFERROR(SUMPRODUCT((Raw_Data_Daily!$B$2:$B$9999="Control")*(Raw_Data_Daily!$C$2:$C$9999="F. 100+")*Raw_Data_Daily!$D$2:$D$9999*Raw_Data_Daily!$O$2:$O$9999)/SUMIFS(Raw_Data_Daily!$D:$D, Raw_Data_Daily!$B:$B, "Control", Raw_Data_Daily!$C:$C, "F. 100+"),"") -> 0.2032314 | S26: =IFERROR(SUMPRODUCT((Raw_Data_Daily!$B$2:$B$9999="Variant")*(Raw_Data_Daily!$C$2:$C$9999="F. 100+")*Raw_Data_Daily!$D$2:$D$9999*Raw_Data_Daily!$O$2:$O$9999)/SUMIFS(Raw_Data_Daily!$D:$D, Raw_Data_Daily!$B:$B, "Variant", Raw_Data_Daily!$C:$C, "F. 100+"),"") -> 0.20566728 | T26: =IFERROR((S26-R26)/ABS(R26),"") -> 0.011985731 | V26: todo
