Workbook

Sheet contents
A1: Name | B1: Link to old | C1: Link to new
A2: =RR_v2!A1 -> River Rush | B2: RR | C2: RR_v2
A3: =NS_v2!A1 -> Night Sky (5 Segment) | B3: NS | C3: NS_v2
A4: =J_v2!A1 -> Jigsaw Puzzle | B4: J | C4: J_v2
A5: =TaD_v2!A1 -> Target Day | B5: TaD | C5: TaD_v2
A6: =c_day_v2!A1 -> Daily Rewards - NEW | B6: c_day | C6: c_day_v2
A7: =c_saga_v2!A1 -> Saga Progression - NEW | B7: c_saga | C7: c_saga_v2
A8: =F_v2!A1 -> Flock Flurry | B8: F | C8: F_v2
A9: =Ki_v2!A1 -> Kite Festival | B9: Ki | C9: Ki_v2
A10: =BB_v2!A1 -> Bomb's Ballet | B10: BB | C10: BB_v2
A11: =Ph_v2!A1 -> Photoshoot | B11: Ph | C11: Ph_v2
A12: =Race_v2!A1 -> All LB Challenges | B12: Race | C12: Race_v2
A13: =HH_v2!A1 -> Hatchling Hideaway | B13: HH | C13: HH_v2

Sheet cal_parsed
A1: calendar | B1: event | C1: start | D1: dur
A2: cal_curr | B2: Target Day | C2: 10 | D2: 7
A3: cal_curr | B3: Target Day | C3: 24 | D3: 7
A4: cal_curr | B4: Target Day | C4: 1 | D4: 2
A5: cal_curr | B5: Top Players Leaderboard | C5: 6 | D5: 7
A6: cal_curr | B6: Top Players Leaderboard | C6: 13 | D6: 7
A7: cal_curr | B7: Top Players Leaderboard | C7: 20 | D7: 7
A8: cal_curr | B8: Top Players Leaderboard | C8: 27 | D8: 7
A9: cal_curr | B9: Top Players Leaderboard | C9: 1 | D9: 5
A10: cal_curr | B10: Jigsaw Puzzle | C10: 1 | D10: 3
A11: cal_curr | B11: Jigsaw Puzzle | C11: 14 | D11: 4
A12: cal_curr | B12: Jigsaw Puzzle | C12: 28 | D12: 4
A13: cal_curr | B13: Photoshoot | C13: 7 | D13: 4
... A284: cal_new | B284: Night Sky | C284: 33 | D284: 1

Sheet c_saga
A1: Saga Progression - OLD
B3: 0-9 | D3: 10-19 | F3: 20-39 | H3: 40-99 | J3: 100+ | W3: all segs
A4: Node | B4: Levels Req | C4: HC Reward | D4: Levels Req | E4: HC Reward | F4: Levels Req | G4: HC Reward | H4: Levels Req | I4: HC Reward | J4: Levels Req | K4: HC Reward | M4: 👁 | T4: Original | U4: Old Nerf | W4: SPT | X4: Red | Y4: Chuck | Z4: Bomb | AA4: Slingshot | AB4: Shuffle | AC4: Comet | AD4: Unlimited Lives | AE4: Unlimited Red | AF4: Unlimited Chuck | AG4: Unlimited Bomb | AH4: Coin Val | AJ4: cur | AK4: image
A5: 1 | B5: 10 | C5: 10 | D5: 10 | E5: 10 | F5: 10 | G5: 10 | H5: 10 | I5: 10 | J5: 10 | K5: 10 | M5: =IFERROR(__xludf.DUMMYFUNCTION("LET( names, HSTACK(""Coins"", W$4:AG$4), amounts, HSTACK(C5, W5:AG5), lookupNames, $AJ$5:$AJ$16, lookupImages, $AK$5:$AK$16, imgs, MAP(names, LAMBDA(n, XLOOKUP(n, lookupNames, lookupImages))), keepImgs, FILTER(imgs, amounts<>0), keepAmounts,"&" FILTER(amounts, amounts<>0), MAKEARRAY( 1, COLUMNS(keepAmounts)*2, LAMBDA(r,c, IF( ISODD(c), INDEX(keepImgs, 1, ROUNDUP(c/2)), INDEX(keepAmounts, 1, c/2) ) ) ) )"),"") | N5: =IFERROR(__xludf.DUMMYFUNCTION("""COMPUTED_VALUE"""),10.0) -> 10 | O5: =IFERROR(__xludf.DUMMYFUNCTION("""COMPUTED_VALUE"""),"") | P5: =IFERROR(__xludf.DUMMYFUNCTION("""COMPUTED_VALUE"""),1.0) -> 1 | Q5: =IFERROR(__xludf.DUMMYFUNCTION("""COMPUTED_VALUE"""),"") | R5: =IFERROR(__xludf.DUMMYFUNCTION("""COMPUTED_VALUE"""),15.0) -> 15 | T5: 15 | U5: 10 | W5: 0 | X5: 1 | Y5: 0 | Z5: 0 | AA5: 0 | AB5: 0 | AC5: 0 | AD5: 15 | AE5: 0 | AF5: 0 | AG5: 0 | AH5: =SUMPRODUCT(W5:AG5, {0,33,50,67,167,67,50,4.17,7.56,12.17,16.22}) -> 95.55 | AI5: 100 | AJ5: Coins | AL5: =AH5-AI5 -> -4.45
A6: 2 | B6: 10 | C6: 0 | D6: 10 | E6: 0 | F6: 10 | G6: 0 | H6: 10 | I6: 0 | J6: 10 | K6: 0 | M6: =IFERROR(__xludf.DUMMYFUNCTION("LET( names, HSTACK(""Coins"", W$4:AG$4), amounts, HSTACK(C6, W6:AG6), lookupNames, $AJ$5:$AJ$16, lookupImages, $AK$5:$AK$16, imgs, MAP(names, LAMBDA(n, XLOOKUP(n, lookupNames, lookupImages))), keepImgs, FILTER(imgs, amounts<>0), keepAmounts,"&" FILTER(amounts, amounts<>0), MAKEARRAY( 1, COLUMNS(keepAmounts)*2, LAMBDA(r,c, IF( ISODD(c), INDEX(keepImgs, 1, ROUNDUP(c/2)), INDEX(keepAmounts, 1, c/2) ) ) ) )"),"") | N6: =IFERROR(__xludf.DUMMYFUNCTION("""COMPUTED_VALUE"""),1.0) -> 1 | O6: =IFERROR(__xludf.DUMMYFUNCTION("""COMPUTED_VALUE"""),"") | P6: =IFERROR(__xludf.DUMMYFUNCTION("""COMPUTED_VALUE"""),1.0) -> 1 | Q6: =IFERROR(__xludf.DUMMYFUNCTION("""COMPUTED_VALUE"""),"") | R6: =IFERROR(__xludf.DUMMYFUNCTION("""COMPUTED_VALUE"""),15.0) -> 15 | T6: 15 | U6: 10 | W6: 0 | X6: 1 | Y6: 1 | Z6: 0 | AA6: 0 | AB6: 0 | AC6: 0 | AD6: 15 | AE6: 0 | AF6: 0 | AG6: 0 | AH6: =SUMPRODUCT(W6:AG6, {0,33,50,67,167,67,50,4.17,7.56,12.17,16.22}) -> 145.55 | AI6: 112.55 | AJ6: {=TRANSPOSE(W4:AG4)} -> SPT | AL6: =AH6-AI6 -> 33
A7: 3 | B7: 10 | C7: 10 | D7: 10 | E7: 10 | F7: 10 | G7: 10 | H7: 10 | I7: 10 | J7: 10 | K7: 10 | M7: =IFERROR(__xludf.DUMMYFUNCTION("LET( names, HSTACK(""Coins"", W$4:AG$4), amounts, HSTACK(C7, W7:AG7), lookupNames, $AJ$5:$AJ$16, lookupImages, $AK$5:$AK$16, imgs, MAP(names, LAMBDA(n, XLOOKUP(n, lookupNames, lookupImages))), keepImgs, FILTER(imgs, amounts<>0), keepAmounts,"&" FILTER(amounts, amounts<>0), MAKEARRAY( 1, COLUMNS(keepAmounts)*2, LAMBDA(r,c, IF( ISODD(c), INDEX(keepImgs, 1, ROUNDUP(c/2)), INDEX(keepAmounts, 1, c/2) ) ) ) )"),"") | N7: =IFERROR(__xludf.DUMMYFUNCTION("""COMPUTED_VALUE"""),10.0) -> 10 | O7: =IFERROR(__xludf.DUMMYFUNCTION("""COMPUTED_VALUE"""),"") | P7: =IFERROR(__xludf.DUMMYFUNCTION("""COMPUTED_VALUE"""),1.0) -> 1 | Q7: =IFERROR(__xludf.DUMMYFUNCTION("""COMPUTED_VALUE"""),"") | R7: =IFERROR(__xludf.DUMMYFUNCTION("""COMPUTED_VALUE"""),15.0) -> 15 | T7: 15 | U7: 10 | W7: 0 | X7: 0 | Y7: 0 | Z7: 1 | AA7: 0 | AB7: 0 | AC7: 0 | AD7: 15 | AE7: 0 | AF7: 0 | AG7: 0 | AH7: =SUMPRODUCT(W7:AG7, {0,33,50,67,167,67,50,4.17,7.56,12.17,16.22}) -> 129.55 | AI7: 95.55 | AJ7: Red | AL7: =AH7-AI7 -> 34
A8: 4 | B8: 10 | C8: 0 | D8: 10 | E8: 0 | F8: 10 | G8: 0 | H8: 10 | I8: 0 | J8: 10 | K8: 0 | M8: =IFERROR(__xludf.DUMMYFUNCTION("LET( names, HSTACK(""Coins"", W$4:AG$4), amounts, HSTACK(C8, W8:AG8), lookupNames, $AJ$5:$AJ$16, lookupImages, $AK$5:$AK$16, imgs, MAP(names, LAMBDA(n, XLOOKUP(n, lookupNames, lookupImages))), keepImgs, FILTER(imgs, amounts<>0), keepAmounts,"&" FILTER(amounts, amounts<>0), MAKEARRAY( 1, COLUMNS(keepAmounts)*2, LAMBDA(r,c, IF( ISODD(c), INDEX(keepImgs, 1, ROUNDUP(c/2)), INDEX(keepAmounts, 1, c/2) ) ) ) )"),"") | N8: =IFERROR(__xludf.DUMMYFUNCTION("""COMPUTED_VALUE"""),1.0) -> 1 | O8: =IFERROR(__xludf.DUMMYFUNCTION("""COMPUTED_VALUE"""),"") | P8: =IFERROR(__xludf.DUMMYFUNCTION("""COMPUTED_VALUE"""),1.0) -> 1 | Q8: =IFERROR(__xludf.DUMMYFUNCTION("""COMPUTED_VALUE"""),"") | R8: =IFERROR(__xludf.DUMMYFUNCTION("""COMPUTED_VALUE"""),15.0) -> 15 | T8: 20 | U8: 10 | W8: 0 | X8: 1 | Y8: 0 | Z8: 0 | AA8: 0 | AB8: 1 | AC8: 0 | AD8: 15 | AE8: 0 | AF8: 0 | AG8: 0 | AH8: =SUMPRODUCT(W8:AG8, {0,33,50,67,167,67,50,4.17,7.56,12.17,16.22}) -> 162.55 | AI8: 95.55 | AJ8: Chuck | AL8: =AH8-AI8 -> 67
A9: 5 | B9: 10 | C9: 10 | D9: 10 | E9: 10 | F9: 10 | G9: 10 | H9: 10 | I9: 10 | J9: 10 | K9: 10 | M9: =IFERROR(__xludf.DUMMYFUNCTION("LET( names, HSTACK(""Coins"", W$4:AG$4), amounts, HSTACK(C9, W9:AG9), lookupNames, $AJ$5:$AJ$16, lookupImages, $AK$5:$AK$16, imgs, MAP(names, LAMBDA(n, XLOOKUP(n, lookupNames, lookupImages))), keepImgs, FILTER(imgs, amounts<>0), keepAmounts,"&" FILTER(amounts, amounts<>0), MAKEARRAY( 1, COLUMNS(keepAmounts)*2, LAMBDA(r,c, IF( ISODD(c), INDEX(keepImgs, 1, ROUNDUP(c/2)), INDEX(keepAmounts, 1, c/2) ) ) ) )"),"") | N9: =IFERROR(__xludf.DUMMYFUNCTION("""COMPUTED_VALUE"""),10.0) -> 10 | O9: =IFERROR(__xludf.DUMMYFUNCTION("""COMPUTED_VALUE"""),"") | P9: =IFERROR(__xludf.DUMMYFUNCTION("""COMPUTED_VALUE"""),1.0) -> 1 | Q9: =IFERROR(__xludf.DUMMYFUNCTION("""COMPUTED_VALUE"""),"") | R9: =IFERROR(__xludf.DUMMYFUNCTION("""COMPUTED_VALUE"""),15.0) -> 15 | T9: 20 | U9: 10 | W9: 0 | X9: 0 | Y9: 0 | Z9: 1 | AA9: 0 | AB9: 0 | AC9: 0 | AD9: 15 | AE9: 0 | AF9: 0 | AG9: 0 | AH9: =SUMPRODUCT(W9:AG9, {0,33,50,67,167,67,50,4.17,7.56,12.17,16.22}) -> 129.55 | AI9: 100 | AJ9: Bomb | AL9: =AH9-AI9 -> 29.55
A10: 6 | B10: 10 | C10: 0 | D10: 10 | E10: 0 | F10: 10 | G10: 0 | H10: 10 | I10: 0 | J10: 10 | K10: 0 | M10: =IFERROR(__xludf.DUMMYFUNCTION("LET( names, HSTACK(""Coins"", W$4:AG$4), amounts, HSTACK(C10, W10:AG10), lookupNames, $AJ$5:$AJ$16, lookupImages, $AK$5:$AK$16, imgs, MAP(names, LAMBDA(n, XLOOKUP(n, lookupNames, lookupImages))), keepImgs, FILTER(imgs, amounts<>0), keepAmoun"&"ts, FILTER(amounts, amounts<>0), MAKEARRAY( 1, COLUMNS(keepAmounts)*2, LAMBDA(r,c, IF( ISODD(c), INDEX(keepImgs, 1, ROUNDUP(c/2)), INDEX(keepAmounts, 1, c/2) ) ) ) )"),"") | N10: =IFERROR(__xludf.DUMMYFUNCTION("""COMPUTED_VALUE"""),1.0) -> 1 | O10: =IFERROR(__xludf.DUMMYFUNCTION("""COMPUTED_VALUE"""),"") | P10: =IFERROR(__xludf.DUMMYFUNCTION("""COMPUTED_VALUE"""),1.0) -> 1 | Q10: =IFERROR(__xludf.DUMMYFUNCTION("""COMPUTED_VALUE"""),"") | R10: =IFERROR(__xludf.DUMMYFUNCTION("""COMPUTED_VALUE"""),20.0) -> 20 | T10: 20 | U10: 15 | W10: 0 | X10: 0 | Y10: 1 | Z10: 0 | AA10: 0 | AB10: 0 | AC10: 1 | AD10: 20 | AE10: 0 | AF10: 0 | AG10: 0 | AH10: =SUMPRODUCT(W10:AG10, {0,33,50,67,167,67,50,4.17,7.56,12.17,16.22}) -> 183.4 | AI10: 229.55 | AJ10: Slingshot | AL10: =AH10-AI10 -> -46.15
A11: 7 | B11: 10 | C11: 10 | D11: 10 | E11: 10 | F11: 10 | G11: 10 | H11: 10 | I11: 10 | J11: 10 | K11: 10 | M11: =IFERROR(__xludf.DUMMYFUNCTION("LET( names, HSTACK(""Coins"", W$4:AG$4), amounts, HSTACK(C11, W11:AG11), lookupNames, $AJ$5:$AJ$16, lookupImages, $AK$5:$AK$16, imgs, MAP(names, LAMBDA(n, XLOOKUP(n, lookupNames, lookupImages))), keepImgs, FILTER(imgs, amounts<>0), keepAmoun"&"ts, FILTER(amounts, amounts<>0), MAKEARRAY( 1, COLUMNS(keepAmounts)*2, LAMBDA(r,c, IF( ISODD(c), INDEX(keepImgs, 1, ROUNDUP(c/2)), INDEX(keepAmounts, 1, c/2) ) ) ) )"),"") | N11: =IFERROR(__xludf.DUMMYFUNCTION("""COMPUTED_VALUE"""),10.0) -> 10 | O11: =IFERROR(__xludf.DUMMYFUNCTION("""COMPUTED_VALUE"""),"") | P11: =IFERROR(__xludf.DUMMYFUNCTION("""COMPUTED_VALUE"""),1.0) -> 1 | Q11: =IFERROR(__xludf.DUMMYFUNCTION("""COMPUTED_VALUE"""),"") | R11: =IFERROR(__xludf.DUMMYFUNCTION("""COMPUTED_VALUE"""),20.0) -> 20 | T11: 25 | U11: 15 | W11: 0 | X11: 0 | Y11: 0 | Z11: 1 | AA11: 0 | AB11: 0 | AC11: 0 | AD11: 20 | AE11: 0 | AF11: 0 | AG11: 0 | AH11: =SUMPRODUCT(W11:AG11, {0,33,50,67,167,67,50,4.17,7.56,12.17,16.22}) -> 150.4 | AI11: 192.1 | AJ11: Shuffle | AL11: =AH11-AI11 -> -41.7
A12: 8 | B12: 10 | C12: 0 | D12: 10 | E12: 0 | F12: 10 | G12: 0 | H12: 10 | I12: 0 | J12: 10 | K12: 0 | M12: =IFERROR(__xludf.DUMMYFUNCTION("LET( names, HSTACK(""Coins"", W$4:AG$4), amounts, HSTACK(C12, W12:AG12), lookupNames, $AJ$5:$AJ$16, lookupImages, $AK$5:$AK$16, imgs, MAP(names, LAMBDA(n, XLOOKUP(n, lookupNames, lookupImages))), keepImgs, FILTER(imgs, amounts<>0), keepAmoun"&"ts, FILTER(amounts, amounts<>0), MAKEARRAY( 1, COLUMNS(keepAmounts)*2, LAMBDA(r,c, IF( ISODD(c), INDEX(keepImgs, 1, ROUNDUP(c/2)), INDEX(keepAmounts, 1, c/2) ) ) ) )"),"") | N12: =IFERROR(__xludf.DUMMYFUNCTION("""COMPUTED_VALUE"""),1.0) -> 1 | O12: =IFERROR(__xludf.DUMMYFUNCTION("""COMPUTED_VALUE"""),"") | P12: =IFERROR(__xludf.DUMMYFUNCTION("""COMPUTED_VALUE"""),1.0) -> 1 | Q12: =IFERROR(__xludf.DUMMYFUNCTION("""COMPUTED_VALUE"""),"") | R12: =IFERROR(__xludf.DUMMYFUNCTION("""COMPUTED_VALUE"""),30.0) -> 30 | T12: 25 | U12: 15 | W12: 0 | X12: 0 | Y12: 1 | Z12: 0 | AA12: 1 | AB12: 0 | AC12: 0 | AD12: 30 | AE12: 0 | AF12: 0 | AG12: 0 | AH12: =SUMPRODUCT(W12:AG12, {0,33,50,67,167,67,50,4.17,7.56,12.17,16.22}) -> 342.1 | AI12: 217 | AJ12: Comet | AL12: =AH12-AI12 -> 125.1
A13: 9 | B13: 10 | C13: 10 | D13: 10 | E13: 10 | F13: 10 | G13: 10 | H13: 10 | I13: 10 | J13: 10 | K13: 10 | M13: =IFERROR(__xludf.DUMMYFUNCTION("LET( names, HSTACK(""Coins"", W$4:AG$4), amounts, HSTACK(C13, W13:AG13), lookupNames, $AJ$5:$AJ$16, lookupImages, $AK$5:$AK$16, imgs, MAP(names, LAMBDA(n, XLOOKUP(n, lookupNames, lookupImages))), keepImgs, FILTER(imgs, amounts<>0), keepAmoun"&"ts, FILTER(amounts, amounts<>0), MAKEARRAY( 1, COLUMNS(keepAmounts)*2, LAMBDA(r,c, IF( ISODD(c), INDEX(keepImgs, 1, ROUNDUP(c/2)), INDEX(keepAmounts, 1, c/2) ) ) ) )"),"") | N13: =IFERROR(__xludf.DUMMYFUNCTION("""COMPUTED_VALUE"""),10.0) -> 10 | O13: =IFERROR(__xludf.DUMMYFUNCTION("""COMPUTED_VALUE"""),"") | P13: =IFERROR(__xludf.DUMMYFUNCTION("""COMPUTED_VALUE"""),1.0) -> 1 | Q13: =IFERROR(__xludf.DUMMYFUNCTION("""COMPUTED_VALUE"""),"") | R13: =IFERROR(__xludf.DUMMYFUNCTION("""COMPUTED_VALUE"""),60.0) -> 60 | T13: 25 | U13: 15 | W13: 0 | X13: 0 | Y13: 0 | Z13: 0 | AA13: 0 | AB13: 1 | AC13: 0 | AD13: 60 | AE13: 0 | AF13: 0 | AG13: 0 | AH13: =SUMPRODUCT(W13:AG13, {0,33,50,67,167,67,50,4.17,7.56,12.17,16.22}) -> 317.2 | AI13: 300.2 | AJ13: Unlimited Lives | AL13: =AH13-AI13 -> 17
A14: 10 | B14: 10 | C14: 25 | D14: 10 | E14: 25 | F14: 10 | G14: 25 | H14: 10 | I14: 25 | J14: 10 | K14: 25 | M14: =IFERROR(__xludf.DUMMYFUNCTION("LET( names, HSTACK(""Coins"", W$4:AG$4), amounts, HSTACK(C14, W14:AG14), lookupNames, $AJ$5:$AJ$16, lookupImages, $AK$5:$AK$16, imgs, MAP(names, LAMBDA(n, XLOOKUP(n, lookupNames, lookupImages))), keepImgs, FILTER(imgs, amounts<>0), keepAmoun"&"ts, FILTER(amounts, amounts<>0), MAKEARRAY( 1, COLUMNS(keepAmounts)*2, LAMBDA(r,c, IF( ISODD(c), INDEX(keepImgs, 1, ROUNDUP(c/2)), INDEX(keepAmounts, 1, c/2) ) ) ) )"),"") | N14: =IFERROR(__xludf.DUMMYFUNCTION("""COMPUTED_VALUE"""),25.0) -> 25 | O14: =IFERROR(__xludf.DUMMYFUNCTION("""COMPUTED_VALUE"""),"") | P14: =IFERROR(__xludf.DUMMYFUNCTION("""COMPUTED_VALUE"""),1.0) -> 1 | Q14: =IFERROR(__xludf.DUMMYFUNCTION("""COMPUTED_VALUE"""),"") | R14: =IFERROR(__xludf.DUMMYFUNCTION("""COMPUTED_VALUE"""),60.0) -> 60 | T14: 30 | U14: 20 | W14: 0 | X14: 0 | Y14: 0 | Z14: 0 | AA14: 0 | AB14: 0 | AC14: 1 | AD14: 60 | AE14: 0 | AF14: 0 | AG14: 0 | AH14: =SUMPRODUCT(W14:AG14, {0,33,50,67,167,67,50,4.17,7.56,12.17,16.22}) -> 300.2 | AI14: 117 | AJ14: Unlimited Red | AL14: =AH14-AI14 -> 183.2
AJ15: Unlimited Chuck
A16: Total per cycle | B16: =SUM(B5:B14) -> 100 | C16: =SUM(C5:C14) -> 75 | D16: =SUM(D5:D14) -> 100 | E16: =SUM(E5:E14) -> 75 | F16: =SUM(F5:F14) -> 100 | G16: =SUM(G5:G14) -> 75 | H16: =SUM(H5:H14) -> 100 | I16: =SUM(I5:I14) -> 75 | ... K16: =SUM(K5:K14) -> 75 | T16: =SUM(T5:T14) -> 210 | U16: =SUM(U5:U14) -> 130 | AJ16: Unlimited Bomb
A17: HC per level | C17: =C16/B16 -> 0.75 | E17: =E16/D16 -> 0.75 | G17: =G16/F16 -> 0.75 | I17: =I16/H16 -> 0.75 | K17: =K16/J16 -> 0.75 | T17: =T16/$J$16 -> 2.1 | U17: =U16/$J$16 -> 1.3
T19: =T16/saga_progression_old!$C$15 -> #REF! | U19: =U16/saga_progression_old!$C$15 -> #REF!

Sheet c_saga_v2
A1: Saga Progression - NEW
B3: 0-9 | D3: 10-19 | F3: 20-39 | H3: 40-99 | J3: 100+ | W3: all segs
A4: Node | B4: Levels Req | C4: HC Reward | D4: Levels Req | E4: HC Reward | F4: Levels Req | G4: HC Reward | H4: Levels Req | I4: HC Reward | J4: Levels Req | K4: HC Reward | M4: 👁 | T4: Original | U4: Old Nerf | W4: SPT | X4: Red | Y4: Chuck | Z4: Bomb | AA4: Slingshot | AB4: Shuffle | AC4: Comet | AD4: Unlimited Lives | AE4: Unlimited Red | AF4: Unlimited Chuck | AG4: Unlimited Bomb | AH4: Coin Val | AJ4: cur | AK4: image
A5: 1 | B5: 10 | C5: 10 | D5: 10 | E5: 10 | F5: 10 | G5: 10 | H5: 10 | I5: 10 | J5: 10 | K5: 10 | M5: =IFERROR(__xludf.DUMMYFUNCTION("LET( names, HSTACK(""Coins"", W$4:AG$4), amounts, HSTACK(C5, W5:AG5), lookupNames, $AJ$5:$AJ$16, lookupImages, $AK$5:$AK$16, imgs, MAP(names, LAMBDA(n, XLOOKUP(n, lookupNames, lookupImages))), keepImgs, FILTER(imgs, amounts<>0), keepAmounts,"&" FILTER(amounts, amounts<>0), MAKEARRAY( 1, COLUMNS(keepAmounts)*2, LAMBDA(r,c, IF( ISODD(c), INDEX(keepImgs, 1, ROUNDUP(c/2)), INDEX(keepAmounts, 1, c/2) ) ) ) )"),"") | N5: =IFERROR(__xludf.DUMMYFUNCTION("""COMPUTED_VALUE"""),10.0) -> 10 | O5: =IFERROR(__xludf.DUMMYFUNCTION("""COMPUTED_VALUE"""),"") | P5: =IFERROR(__xludf.DUMMYFUNCTION("""COMPUTED_VALUE"""),15.0) -> 15 | T5: 15 | U5: 10 | W5: 0 | X5: 0 | Y5: 0 | Z5: 0 | AA5: 0 | AB5: 0 | AC5: 0 | AD5: 15 | AE5: 0 | AF5: 0 | AG5: 0 | AH5: =SUMPRODUCT(W5:AG5, {0,33,50,67,167,67,50,4.17,7.56,12.17,16.22}) -> 62.55 | AI5: 100 | AJ5: Coins | AL5: =AH5-AI5 -> -37.45
A6: 2 | B6: 10 | C6: 0 | D6: 10 | E6: 0 | F6: 10 | G6: 0 | H6: 10 | I6: 0 | J6: 10 | K6: 0 | M6: =IFERROR(__xludf.DUMMYFUNCTION("LET( names, HSTACK(""Coins"", W$4:AG$4), amounts, HSTACK(C6, W6:AG6), lookupNames, $AJ$5:$AJ$16, lookupImages, $AK$5:$AK$16, imgs, MAP(names, LAMBDA(n, XLOOKUP(n, lookupNames, lookupImages))), keepImgs, FILTER(imgs, amounts<>0), keepAmounts,"&" FILTER(amounts, amounts<>0), MAKEARRAY( 1, COLUMNS(keepAmounts)*2, LAMBDA(r,c, IF( ISODD(c), INDEX(keepImgs, 1, ROUNDUP(c/2)), INDEX(keepAmounts, 1, c/2) ) ) ) )"),"") | N6: =IFERROR(__xludf.DUMMYFUNCTION("""COMPUTED_VALUE"""),1.0) -> 1 | O6: =IFERROR(__xludf.DUMMYFUNCTION("""COMPUTED_VALUE"""),"") | P6: =IFERROR(__xludf.DUMMYFUNCTION("""COMPUTED_VALUE"""),15.0) -> 15 | T6: 15 | U6: 10 | W6: 0 | X6: 1 | Y6: 0 | Z6: 0 | AA6: 0 | AB6: 0 | AC6: 0 | AD6: 15 | AE6: 0 | AF6: 0 | AG6: 0 | AH6: =SUMPRODUCT(W6:AG6, {0,33,50,67,167,67,50,4.17,7.56,12.17,16.22}) -> 95.55 | AI6: 112.55 | AJ6: {=TRANSPOSE(W4:AG4)} -> SPT | AL6: =AH6-AI6 -> -17
A7: 3 | B7: 10 | C7: 10 | D7: 10 | E7: 10 | F7: 10 | G7: 10 | H7: 10 | I7: 10 | J7: 10 | K7: 10 | M7: =IFERROR(__xludf.DUMMYFUNCTION("LET( names, HSTACK(""Coins"", W$4:AG$4), amounts, HSTACK(C7, W7:AG7), lookupNames, $AJ$5:$AJ$16, lookupImages, $AK$5:$AK$16, imgs, MAP(names, LAMBDA(n, XLOOKUP(n, lookupNames, lookupImages))), keepImgs, FILTER(imgs, amounts<>0), keepAmounts,"&" FILTER(amounts, amounts<>0), MAKEARRAY( 1, COLUMNS(keepAmounts)*2, LAMBDA(r,c, IF( ISODD(c), INDEX(keepImgs, 1, ROUNDUP(c/2)), INDEX(keepAmounts, 1, c/2) ) ) ) )"),"") | N7: =IFERROR(__xludf.DUMMYFUNCTION("""COMPUTED_VALUE"""),10.0) -> 10 | O7: =IFERROR(__xludf.DUMMYFUNCTION("""COMPUTED_VALUE"""),"") | P7: =IFERROR(__xludf.DUMMYFUNCTION("""COMPUTED_VALUE"""),15.0) -> 15 | T7: 15 | U7: 10 | W7: 0 | X7: 0 | Y7: 0 | Z7: 0 | AA7: 0 | AB7: 0 | AC7: 0 | AD7: 15 | AE7: 0 | AF7: 0 | AG7: 0 | AH7: =SUMPRODUCT(W7:AG7, {0,33,50,67,167,67,50,4.17,7.56,12.17,16.22}) -> 62.55 | AI7: 95.55 | AJ7: Red | AL7: =AH7-AI7 -> -33
A8: 4 | B8: 10 | C8: 0 | D8: 10 | E8: 0 | F8: 10 | G8: 0 | H8: 10 | I8: 0 | J8: 10 | K8: 0 | M8: =IFERROR(__xludf.DUMMYFUNCTION("LET( names, HSTACK(""Coins"", W$4:AG$4), amounts, HSTACK(C8, W8:AG8), lookupNames, $AJ$5:$AJ$16, lookupImages, $AK$5:$AK$16, imgs, MAP(names, LAMBDA(n, XLOOKUP(n, lookupNames, lookupImages))), keepImgs, FILTER(imgs, amounts<>0), keepAmounts,"&" FILTER(amounts, amounts<>0), MAKEARRAY( 1, COLUMNS(keepAmounts)*2, LAMBDA(r,c, IF( ISODD(c), INDEX(keepImgs, 1, ROUNDUP(c/2)), INDEX(keepAmounts, 1, c/2) ) ) ) )"),"") | N8: =IFERROR(__xludf.DUMMYFUNCTION("""COMPUTED_VALUE"""),1.0) -> 1 | O8: =IFERROR(__xludf.DUMMYFUNCTION("""COMPUTED_VALUE"""),"") | P8: =IFERROR(__xludf.DUMMYFUNCTION("""COMPUTED_VALUE"""),15.0) -> 15 | T8: 20 | U8: 10 | W8: 0 | X8: 1 | Y8: 0 | Z8: 0 | AA8: 0 | AB8: 0 | AC8: 0 | AD8: 15 | AE8: 0 | AF8: 0 | AG8: 0 | AH8: =SUMPRODUCT(W8:AG8, {0,33,50,67,167,67,50,4.17,7.56,12.17,16.22}) -> 95.55 | AI8: 95.55 | AJ8: Chuck | AL8: =AH8-AI8 -> 0
A9: 5 | B9: 10 | C9: 0 | D9: 10 | E9: 0 | F9: 10 | G9: 0 | H9: 10 | I9: 0 | J9: 10 | K9: 0 | M9: =IFERROR(__xludf.DUMMYFUNCTION("LET( names, HSTACK(""Coins"", W$4:AG$4), amounts, HSTACK(C9, W9:AG9), lookupNames, $AJ$5:$AJ$16, lookupImages, $AK$5:$AK$16, imgs, MAP(names, LAMBDA(n, XLOOKUP(n, lookupNames, lookupImages))), keepImgs, FILTER(imgs, amounts<>0), keepAmounts,"&" FILTER(amounts, amounts<>0), MAKEARRAY( 1, COLUMNS(keepAmounts)*2, LAMBDA(r,c, IF( ISODD(c), INDEX(keepImgs, 1, ROUNDUP(c/2)), INDEX(keepAmounts, 1, c/2) ) ) ) )"),"") | N9: =IFERROR(__xludf.DUMMYFUNCTION("""COMPUTED_VALUE"""),1.0) -> 1 | O9: =IFERROR(__xludf.DUMMYFUNCTION("""COMPUTED_VALUE"""),"") | P9: =IFERROR(__xludf.DUMMYFUNCTION("""COMPUTED_VALUE"""),15.0) -> 15 | T9: 20 | U9: 10 | W9: 0 | X9: 0 | Y9: 1 | Z9: 0 | AA9: 0 | AB9: 0 | AC9: 0 | AD9: 15 | AE9: 0 | AF9: 0 | AG9: 0 | AH9: =SUMPRODUCT(W9:AG9, {0,33,50,67,167,67,50,4.17,7.56,12.17,16.22}) -> 112.55 | AI9: 100 | AJ9: Bomb | AL9: =AH9-AI9 -> 12.55
A10: 6 | B10: 10 | C10: 0 | D10: 10 | E10: 0 | F10: 10 | G10: 0 | H10: 10 | I10: 0 | J10: 10 | K10: 0 | M10: =IFERROR(__xludf.DUMMYFUNCTION("LET( names, HSTACK(""Coins"", W$4:AG$4), amounts, HSTACK(C10, W10:AG10), lookupNames, $AJ$5:$AJ$16, lookupImages, $AK$5:$AK$16, imgs, MAP(names, LAMBDA(n, XLOOKUP(n, lookupNames, lookupImages))), keepImgs, FILTER(imgs, amounts<>0), keepAmoun"&"ts, FILTER(amounts, amounts<>0), MAKEARRAY( 1, COLUMNS(keepAmounts)*2, LAMBDA(r,c, IF( ISODD(c), INDEX(keepImgs, 1, ROUNDUP(c/2)), INDEX(keepAmounts, 1, c/2) ) ) ) )"),"") | N10: =IFERROR(__xludf.DUMMYFUNCTION("""COMPUTED_VALUE"""),1.0) -> 1 | O10: =IFERROR(__xludf.DUMMYFUNCTION("""COMPUTED_VALUE"""),"") | P10: =IFERROR(__xludf.DUMMYFUNCTION("""COMPUTED_VALUE"""),20.0) -> 20 | T10: 20 | U10: 15 | W10: 0 | X10: 0 | Y10: 1 | Z10: 0 | AA10: 0 | AB10: 0 | AC10: 0 | AD10: 20 | AE10: 0 | AF10: 0 | AG10: 0 | AH10: =SUMPRODUCT(W10:AG10, {0,33,50,67,167,67,50,4.17,7.56,12.17,16.22}) -> 133.4 | AI10: 229.55 | AJ10: Slingshot | AL10: =AH10-AI10 -> -96.15
A11: 7 | B11: 10 | C11: 10 | D11: 10 | E11: 10 | F11: 10 | G11: 10 | H11: 10 | I11: 10 | J11: 10 | K11: 10 | M11: =IFERROR(__xludf.DUMMYFUNCTION("LET( names, HSTACK(""Coins"", W$4:AG$4), amounts, HSTACK(C11, W11:AG11), lookupNames, $AJ$5:$AJ$16, lookupImages, $AK$5:$AK$16, imgs, MAP(names, LAMBDA(n, XLOOKUP(n, lookupNames, lookupImages))), keepImgs, FILTER(imgs, amounts<>0), keepAmoun"&"ts, FILTER(amounts, amounts<>0), MAKEARRAY( 1, COLUMNS(keepAmounts)*2, LAMBDA(r,c, IF( ISODD(c), INDEX(keepImgs, 1, ROUNDUP(c/2)), INDEX(keepAmounts, 1, c/2) ) ) ) )"),"") | N11: =IFERROR(__xludf.DUMMYFUNCTION("""COMPUTED_VALUE"""),10.0) -> 10 | O11: =IFERROR(__xludf.DUMMYFUNCTION("""COMPUTED_VALUE"""),"") | P11: =IFERROR(__xludf.DUMMYFUNCTION("""COMPUTED_VALUE"""),20.0) -> 20 | T11: 25 | U11: 15 | W11: 0 | X11: 0 | Y11: 0 | Z11: 0 | AA11: 0 | AB11: 0 | AC11: 0 | AD11: 20 | AE11: 0 | AF11: 0 | AG11: 0 | AH11: =SUMPRODUCT(W11:AG11, {0,33,50,67,167,67,50,4.17,7.56,12.17,16.22}) -> 83.4 | AI11: 192.1 | AJ11: Shuffle | AL11: =AH11-AI11 -> -108.7
A12: 8 | B12: 10 | C12: 0 | D12: 10 | E12: 0 | F12: 10 | G12: 0 | H12: 10 | I12: 0 | J12: 10 | K12: 0 | M12: =IFERROR(__xludf.DUMMYFUNCTION("LET( names, HSTACK(""Coins"", W$4:AG$4), amounts, HSTACK(C12, W12:AG12), lookupNames, $AJ$5:$AJ$16, lookupImages, $AK$5:$AK$16, imgs, MAP(names, LAMBDA(n, XLOOKUP(n, lookupNames, lookupImages))), keepImgs, FILTER(imgs, amounts<>0), keepAmoun"&"ts, FILTER(amounts, amounts<>0), MAKEARRAY( 1, COLUMNS(keepAmounts)*2, LAMBDA(r,c, IF( ISODD(c), INDEX(keepImgs, 1, ROUNDUP(c/2)), INDEX(keepAmounts, 1, c/2) ) ) ) )"),"") | N12: =IFERROR(__xludf.DUMMYFUNCTION("""COMPUTED_VALUE"""),1.0) -> 1 | O12: =IFERROR(__xludf.DUMMYFUNCTION("""COMPUTED_VALUE"""),"") | P12: =IFERROR(__xludf.DUMMYFUNCTION("""COMPUTED_VALUE"""),30.0) -> 30 | T12: 25 | U12: 15 | W12: 0 | X12: 0 | Y12: 0 | Z12: 1 | AA12: 0 | AB12: 0 | AC12: 0 | AD12: 30 | AE12: 0 | AF12: 0 | AG12: 0 | AH12: =SUMPRODUCT(W12:AG12, {0,33,50,67,167,67,50,4.17,7.56,12.17,16.22}) -> 192.1 | AI12: 217 | AJ12: Comet | AL12: =AH12-AI12 -> -24.9
A13: 9 | B13: 10 | C13: 10 | D13: 10 | E13: 10 | F13: 10 | G13: 10 | H13: 10 | I13: 10 | J13: 10 | K13: 10 | M13: =IFERROR(__xludf.DUMMYFUNCTION("LET( names, HSTACK(""Coins"", W$4:AG$4), amounts, HSTACK(C13, W13:AG13), lookupNames, $AJ$5:$AJ$16, lookupImages, $AK$5:$AK$16, imgs, MAP(names, LAMBDA(n, XLOOKUP(n, lookupNames, lookupImages))), keepImgs, FILTER(imgs, amounts<>0), keepAmoun"&"ts, FILTER(amounts, amounts<>0), MAKEARRAY( 1, COLUMNS(keepAmounts)*2, LAMBDA(r,c, IF( ISODD(c), INDEX(keepImgs, 1, ROUNDUP(c/2)), INDEX(keepAmounts, 1, c/2) ) ) ) )"),"") | N13: =IFERROR(__xludf.DUMMYFUNCTION("""COMPUTED_VALUE"""),10.0) -> 10 | O13: =IFERROR(__xludf.DUMMYFUNCTION("""COMPUTED_VALUE"""),"") | P13: =IFERROR(__xludf.DUMMYFUNCTION("""COMPUTED_VALUE"""),60.0) -> 60 | T13: 25 | U13: 15 | W13: 0 | X13: 0 | Y13: 0 | Z13: 0 | AA13: 0 | AB13: 0 | AC13: 0 | AD13: 60 | AE13: 0 | AF13: 0 | AG13: 0 | AH13: =SUMPRODUCT(W13:AG13, {0,33,50,67,167,67,50,4.17,7.56,12.17,16.22}) -> 250.2 | AI13: 300.2 | AJ13: Unlimited Lives | AL13: =AH13-AI13 -> -50
A14: 10 | B14: 10 | C14: 20 | D14: 10 | E14: 20 | F14: 10 | G14: 20 | H14: 10 | I14: 20 | J14: 10 | K14: 20 | M14: =IFERROR(__xludf.DUMMYFUNCTION("LET( names, HSTACK(""Coins"", W$4:AG$4), amounts, HSTACK(C14, W14:AG14), lookupNames, $AJ$5:$AJ$16, lookupImages, $AK$5:$AK$16, imgs, MAP(names, LAMBDA(n, XLOOKUP(n, lookupNames, lookupImages))), keepImgs, FILTER(imgs, amounts<>0), keepAmoun"&"ts, FILTER(amounts, amounts<>0), MAKEARRAY( 1, COLUMNS(keepAmounts)*2, LAMBDA(r,c, IF( ISODD(c), INDEX(keepImgs, 1, ROUNDUP(c/2)), INDEX(keepAmounts, 1, c/2) ) ) ) )"),"") | N14: =IFERROR(__xludf.DUMMYFUNCTION("""COMPUTED_VALUE"""),20.0) -> 20 | O14: =IFERROR(__xludf.DUMMYFUNCTION("""COMPUTED_VALUE"""),"") | P14: =IFERROR(__xludf.DUMMYFUNCTION("""COMPUTED_VALUE"""),60.0) -> 60 | T14: 30 | U14: 20 | W14: 0 | X14: 0 | Y14: 0 | Z14: 0 | AA14: 0 | AB14: 0 | AC14: 0 | AD14: 60 | AE14: 0 | AF14: 0 | AG14: 0 | AH14: =SUMPRODUCT(W14:AG14, {0,33,50,67,167,67,50,4.17,7.56,12.17,16.22}) -> 250.2 | AI14: 117 | AJ14: Unlimited Red | AL14: =AH14-AI14 -> 133.2
AJ15: Unlimited Chuck
A16: Total per cycle | B16: =SUM(B5:B14) -> 100 | C16: =SUM(C5:C14) -> 60 | D16: =SUM(D5:D14) -> 100 | E16: =SUM(E5:E14) -> 60 | F16: =SUM(F5:F14) -> 100 | G16: =SUM(G5:G14) -> 60 | H16: =SUM(H5:H14) -> 100 | I16: =SUM(I5:I14) -> 60 | ... K16: =SUM(K5:K14) -> 60 | T16: =SUM(T5:T14) -> 210 | U16: =SUM(U5:U14) -> 130 | AJ16: Unlimited Bomb
A17: HC per level | C17: =C16/B16 -> 0.6 | E17: =E16/D16 -> 0.6 | G17: =G16/F16 -> 0.6 | I17: =I16/H16 -> 0.6 | K17: =K16/J16 -> 0.6 | T17: =T16/$J$16 -> 2.1 | U17: =U16/$J$16 -> 1.3
T19: =T16/saga_progression_old!$C$15 -> #REF! | U19: =U16/saga_progression_old!$C$15 -> #REF!

Sheet c_day
A1: Daily Rewards - OLD
A3: Day | B3: HC Reward | E3: 👁 | L3: Variant 1 | AB3: cur | AC3: image
A4: 1 | B4: =average(M5,M16,M26,M35,M45) -> 22 | L4: Day | M4: Coin | N4: SPT | O4: Red | P4: Chuck | Q4: Bomb | R4: Slingshot | S4: Shuffle | T4: Comet | U4: Unlimited Lives | V4: Unlimited Red | W4: Unlimited Chuck | X4: Unlimited Bomb | AB4: Coins
A5: 2 | B5: 0 | E5: =IFERROR(__xludf.DUMMYFUNCTION("LET( names, HSTACK(""Coins"", $N$4:$X$4), amounts, HSTACK(M5, N5:X5), lookupNames, $AB$4:$AB$15, lookupImages, $AC$4:$AC$15, imgs, MAP(names, LAMBDA(n, XLOOKUP(n, lookupNames, lookupImages))), keepImgs, FILTER(imgs, amounts<>0), keepAmounts,"&" FILTER(amounts, amounts<>0), MAKEARRAY( 1, COLUMNS(keepAmounts)*2, LAMBDA(r,c, IF( ISODD(c), INDEX(keepImgs, 1, ROUNDUP(c/2)), INDEX(keepAmounts, 1, c/2) ) ) ) )"),"") | F5: =IFERROR(__xludf.DUMMYFUNCTION("""COMPUTED_VALUE"""),20.0) -> 20 | L5: 1 | M5: 20 | N5: 0 | O5: 0 | P5: 0 | Q5: 0 | R5: 0 | S5: 0 | T5: 0 | U5: 0 | V5: 0 | W5: 0 | X5: 0 | AB5: SPT
A6: 3 | B6: 0 | E6: =IFERROR(__xludf.DUMMYFUNCTION("LET( names, HSTACK(""Coins"", $N$4:$X$4), amounts, HSTACK(M6, N6:X6), lookupNames, $AB$4:$AB$15, lookupImages, $AC$4:$AC$15, imgs, MAP(names, LAMBDA(n, XLOOKUP(n, lookupNames, lookupImages))), keepImgs, FILTER(imgs, amounts<>0), keepAmounts,"&" FILTER(amounts, amounts<>0), MAKEARRAY( 1, COLUMNS(keepAmounts)*2, LAMBDA(r,c, IF( ISODD(c), INDEX(keepImgs, 1, ROUNDUP(c/2)), INDEX(keepAmounts, 1, c/2) ) ) ) )"),"") | F6: =IFERROR(__xludf.DUMMYFUNCTION("""COMPUTED_VALUE"""),15.0) -> 15 | L6: 2 | M6: 0 | N6: 0 | O6: 0 | P6: 0 | Q6: 0 | R6: 0 | S6: 0 | T6: 0 | U6: 15 | V6: 0 | W6: 0 | X6: 0 | AB6: Red
A7: 4 | B7: =mround(average(M8,M18,M28), 1) -> 27 | E7: =IFERROR(__xludf.DUMMYFUNCTION("LET( names, HSTACK(""Coins"", $N$4:$X$4), amounts, HSTACK(M7, N7:X7), lookupNames, $AB$4:$AB$15, lookupImages, $AC$4:$AC$15, imgs, MAP(names, LAMBDA(n, XLOOKUP(n, lookupNames, lookupImages))), keepImgs, FILTER(imgs, amounts<>0), keepAmounts,"&" FILTER(amounts, amounts<>0), MAKEARRAY( 1, COLUMNS(keepAmounts)*2, LAMBDA(r,c, IF( ISODD(c), INDEX(keepImgs, 1, ROUNDUP(c/2)), INDEX(keepAmounts, 1, c/2) ) ) ) )"),"") | F7: =IFERROR(__xludf.DUMMYFUNCTION("""COMPUTED_VALUE"""),1.0) -> 1 | L7: 3 | M7: 0 | N7: 0 | O7: 0 | P7: 0 | Q7: 0 | R7: 1 | S7: 0 | T7: 0 | U7: 0 | V7: 0 | W7: 0 | X7: 0 | AB7: Chuck
A8: 5 | B8: 0 | E8: =IFERROR(__xludf.DUMMYFUNCTION("LET( names, HSTACK(""Coins"", $N$4:$X$4), amounts, HSTACK(M8, N8:X8), lookupNames, $AB$4:$AB$15, lookupImages, $AC$4:$AC$15, imgs, MAP(names, LAMBDA(n, XLOOKUP(n, lookupNames, lookupImages))), keepImgs, FILTER(imgs, amounts<>0), keepAmounts,"&" FILTER(amounts, amounts<>0), MAKEARRAY( 1, COLUMNS(keepAmounts)*2, LAMBDA(r,c, IF( ISODD(c), INDEX(keepImgs, 1, ROUNDUP(c/2)), INDEX(keepAmounts, 1, c/2) ) ) ) )"),"") | F8: =IFERROR(__xludf.DUMMYFUNCTION("""COMPUTED_VALUE"""),25.0) -> 25 | L8: 4 | M8: 25 | N8: 0 | O8: 0 | P8: 0 | Q8: 0 | R8: 0 | S8: 0 | T8: 0 | U8: 0 | V8: 0 | W8: 0 | X8: 0 | AB8: Bomb
A9: 6 | B9: =mround(AVERAGE(M10, M20, M30, M50),1) -> 33 | E9: =IFERROR(__xludf.DUMMYFUNCTION("LET( names, HSTACK(""Coins"", $N$4:$X$4), amounts, HSTACK(M9, N9:X9), lookupNames, $AB$4:$AB$15, lookupImages, $AC$4:$AC$15, imgs, MAP(names, LAMBDA(n, XLOOKUP(n, lookupNames, lookupImages))), keepImgs, FILTER(imgs, amounts<>0), keepAmounts,"&" FILTER(amounts, amounts<>0), MAKEARRAY( 1, COLUMNS(keepAmounts)*2, LAMBDA(r,c, IF( ISODD(c), INDEX(keepImgs, 1, ROUNDUP(c/2)), INDEX(keepAmounts, 1, c/2) ) ) ) )"),"") | F9: =IFERROR(__xludf.DUMMYFUNCTION("""COMPUTED_VALUE"""),1.0) -> 1 | L9: 5 | M9: 0 | N9: 0 | O9: 0 | P9: 0 | Q9: 0 | R9: 0 | S9: 1 | T9: 0 | U9: 0 | V9: 0 | W9: 0 | X9: 0 | AB9: Slingshot
A10: 7 | B10: 100 | E10: =IFERROR(__xludf.DUMMYFUNCTION("LET( names, HSTACK(""Coins"", $N$4:$X$4), amounts, HSTACK(M10, N10:X10), lookupNames, $AB$4:$AB$15, lookupImages, $AC$4:$AC$15, imgs, MAP(names, LAMBDA(n, XLOOKUP(n, lookupNames, lookupImages))), keepImgs, FILTER(imgs, amounts<>0), keepAmoun"&"ts, FILTER(amounts, amounts<>0), MAKEARRAY( 1, COLUMNS(keepAmounts)*2, LAMBDA(r,c, IF( ISODD(c), INDEX(keepImgs, 1, ROUNDUP(c/2)), INDEX(keepAmounts, 1, c/2) ) ) ) )"),"") | F10: =IFERROR(__xludf.DUMMYFUNCTION("""COMPUTED_VALUE"""),30.0) -> 30 | L10: 6 | M10: 30 | N10: 0 | O10: 0 | P10: 0 | Q10: 0 | R10: 0 | S10: 0 | T10: 0 | U10: 0 | V10: 0 | W10: 0 | X10: 0 | AB10: Shuffle
E11: =IFERROR(__xludf.DUMMYFUNCTION("LET( names, HSTACK(""Coins"", $N$4:$X$4), amounts, HSTACK(M11, N11:X11), lookupNames, $AB$4:$AB$15, lookupImages, $AC$4:$AC$15, imgs, MAP(names, LAMBDA(n, XLOOKUP(n, lookupNames, lookupImages))), keepImgs, FILTER(imgs, amounts<>0), keepAmoun"&"ts, FILTER(amounts, amounts<>0), MAKEARRAY( 1, COLUMNS(keepAmounts)*2, LAMBDA(r,c, IF( ISODD(c), INDEX(keepImgs, 1, ROUNDUP(c/2)), INDEX(keepAmounts, 1, c/2) ) ) ) )"),"") | F11: =IFERROR(__xludf.DUMMYFUNCTION("""COMPUTED_VALUE"""),100.0) -> 100 | G11: =IFERROR(__xludf.DUMMYFUNCTION("""COMPUTED_VALUE"""),"") | H11: =IFERROR(__xludf.DUMMYFUNCTION("""COMPUTED_VALUE"""),120.0) -> 120 | I11: =IFERROR(__xludf.DUMMYFUNCTION("""COMPUTED_VALUE"""),"") | J11: =IFERROR(__xludf.DUMMYFUNCTION("""COMPUTED_VALUE"""),60.0) -> 60 | L11: 7 | M11: 100 | N11: 0 | O11: 0 | P11: 0 | Q11: 0 | R11: 0 | S11: 0 | T11: 0 | U11: 120 | V11: 60 | W11: 0 | X11: 0 | AB11: Comet
A12: Total per cycle | B12: =SUM(B4:B10) -> 182 | AB12: Unlimited Lives
A13: Avg HC/day (7d) | B13: =B12/7 -> 26 | L13: Variant 2 | AB13: Unlimited Red
L14: Day | M14: Coin | N14: SPT | O14: Red | P14: Chuck | Q14: Bomb | R14: Slingshot | S14: Shuffle | T14: Comet | U14: Unlimited Lives | V14: Unlimited Red | W14: Unlimited Chuck | X14: Unlimited Bomb | AB14: Unlimited Chuck
E15: =IFERROR(__xludf.DUMMYFUNCTION("LET( names, HSTACK(""Coins"", $N$4:$X$4), amounts, HSTACK(M15, N15:X15), lookupNames, $AB$4:$AB$15, lookupImages, $AC$4:$AC$15, imgs, MAP(names, LAMBDA(n, XLOOKUP(n, lookupNames, lookupImages))), keepImgs, FILTER(imgs, amounts<>0), keepAmoun"&"ts, FILTER(amounts, amounts<>0), MAKEARRAY( 1, COLUMNS(keepAmounts)*2, LAMBDA(r,c, IF( ISODD(c), INDEX(keepImgs, 1, ROUNDUP(c/2)), INDEX(keepAmounts, 1, c/2) ) ) ) )"),"") | F15: =IFERROR(__xludf.DUMMYFUNCTION("""COMPUTED_VALUE"""),20.0) -> 20 | L15: 1 | M15: 0 | N15: 0 | O15: 0 | P15: 0 | Q15: 0 | R15: 0 | S15: 0 | T15: 0 | U15: 20 | V15: 0 | W15: 0 | X15: 0 | AB15: Unlimited Bomb
E16: =IFERROR(__xludf.DUMMYFUNCTION("LET( names, HSTACK(""Coins"", $N$4:$X$4), amounts, HSTACK(M16, N16:X16), lookupNames, $AB$4:$AB$15, lookupImages, $AC$4:$AC$15, imgs, MAP(names, LAMBDA(n, XLOOKUP(n, lookupNames, lookupImages))), keepImgs, FILTER(imgs, amounts<>0), keepAmoun"&"ts, FILTER(amounts, amounts<>0), MAKEARRAY( 1, COLUMNS(keepAmounts)*2, LAMBDA(r,c, IF( ISODD(c), INDEX(keepImgs, 1, ROUNDUP(c/2)), INDEX(keepAmounts, 1, c/2) ) ) ) )"),"") | F16: =IFERROR(__xludf.DUMMYFUNCTION("""COMPUTED_VALUE"""),25.0) -> 25 | L16: 2 | M16: 25 | N16: 0 | O16: 0 | P16: 0 | Q16: 0 | R16: 0 | S16: 0 | T16: 0 | U16: 0 | V16: 0 | W16: 0 | X16: 0
E17: =IFERROR(__xludf.DUMMYFUNCTION("LET( names, HSTACK(""Coins"", $N$4:$X$4), amounts, HSTACK(M17, N17:X17), lookupNames, $AB$4:$AB$15, lookupImages, $AC$4:$AC$15, imgs, MAP(names, LAMBDA(n, XLOOKUP(n, lookupNames, lookupImages))), keepImgs, FILTER(imgs, amounts<>0), keepAmoun"&"ts, FILTER(amounts, amounts<>0), MAKEARRAY( 1, COLUMNS(keepAmounts)*2, LAMBDA(r,c, IF( ISODD(c), INDEX(keepImgs, 1, ROUNDUP(c/2)), INDEX(keepAmounts, 1, c/2) ) ) ) )"),"") | F17: =IFERROR(__xludf.DUMMYFUNCTION("""COMPUTED_VALUE"""),1.0) -> 1 | L17: 3 | M17: 0 | N17: 0 | O17: 0 | P17: 0 | Q17: 0 | R17: 1 | S17: 0 | T17: 0 | U17: 0 | V17: 0 | W17: 0 | X17: 0
E18: =IFERROR(__xludf.DUMMYFUNCTION("LET( names, HSTACK(""Coins"", $N$4:$X$4), amounts, HSTACK(M18, N18:X18), lookupNames, $AB$4:$AB$15, lookupImages, $AC$4:$AC$15, imgs, MAP(names, LAMBDA(n, XLOOKUP(n, lookupNames, lookupImages))), keepImgs, FILTER(imgs, amounts<>0), keepAmoun"&"ts, FILTER(amounts, amounts<>0), MAKEARRAY( 1, COLUMNS(keepAmounts)*2, LAMBDA(r,c, IF( ISODD(c), INDEX(keepImgs, 1, ROUNDUP(c/2)), INDEX(keepAmounts, 1, c/2) ) ) ) )"),"") | F18: =IFERROR(__xludf.DUMMYFUNCTION("""COMPUTED_VALUE"""),30.0) -> 30 | L18: 4 | M18: 30 | N18: 0 | O18: 0 | P18: 0 | Q18: 0 | R18: 0 | S18: 0 | T18: 0 | U18: 0 | V18: 0 | W18: 0 | X18: 0
E19: =IFERROR(__xludf.DUMMYFUNCTION("LET( names, HSTACK(""Coins"", $N$4:$X$4), amounts, HSTACK(M19, N19:X19), lookupNames, $AB$4:$AB$15, lookupImages, $AC$4:$AC$15, imgs, MAP(names, LAMBDA(n, XLOOKUP(n, lookupNames, lookupImages))), keepImgs, FILTER(imgs, amounts<>0), keepAmoun"&"ts, FILTER(amounts, amounts<>0), MAKEARRAY( 1, COLUMNS(keepAmounts)*2, LAMBDA(r,c, IF( ISODD(c), INDEX(keepImgs, 1, ROUNDUP(c/2)), INDEX(keepAmounts, 1, c/2) ) ) ) )"),"") | F19: =IFERROR(__xludf.DUMMYFUNCTION("""COMPUTED_VALUE"""),1.0) -> 1 | L19: 5 | M19: 0 | N19: 0 | O19: 0 | P19: 0 | Q19: 0 | R19: 0 | S19: 1 | T19: 0 | U19: 0 | V19: 0 | W19: 0 | X19: 0
E20: =IFERROR(__xludf.DUMMYFUNCTION("LET( names, HSTACK(""Coins"", $N$4:$X$4), amounts, HSTACK(M20, N20:X20), lookupNames, $AB$4:$AB$15, lookupImages, $AC$4:$AC$15, imgs, MAP(names, LAMBDA(n, XLOOKUP(n, lookupNames, lookupImages))), keepImgs, FILTER(imgs, amounts<>0), keepAmoun"&"ts, FILTER(amounts, amounts<>0), MAKEARRAY( 1, COLUMNS(keepAmounts)*2, LAMBDA(r,c, IF( ISODD(c), INDEX(keepImgs, 1, ROUNDUP(c/2)), INDEX(keepAmounts, 1, c/2) ) ) ) )"),"") | F20: =IFERROR(__xludf.DUMMYFUNCTION("""COMPUTED_VALUE"""),35.0) -> 35 | L20: 6 | M20: 35 | N20: 0 | O20: 0 | P20: 0 | Q20: 0 | R20: 0 | S20: 0 | T20: 0 | U20: 0 | V20: 0 | W20: 0 | X20: 0
E21: =IFERROR(__xludf.DUMMYFUNCTION("LET( names, HSTACK(""Coins"", $N$4:$X$4), amounts, HSTACK(M21, N21:X21), lookupNames, $AB$4:$AB$15, lookupImages, $AC$4:$AC$15, imgs, MAP(names, LAMBDA(n, XLOOKUP(n, lookupNames, lookupImages))), keepImgs, FILTER(imgs, amounts<>0), keepAmoun"&"ts, FILTER(amounts, amounts<>0), MAKEARRAY( 1, COLUMNS(keepAmounts)*2, LAMBDA(r,c, IF( ISODD(c), INDEX(keepImgs, 1, ROUNDUP(c/2)), INDEX(keepAmounts, 1, c/2) ) ) ) )"),"") | F21: =IFERROR(__xludf.DUMMYFUNCTION("""COMPUTED_VALUE"""),100.0) -> 100 | G21: =IFERROR(__xludf.DUMMYFUNCTION("""COMPUTED_VALUE"""),"") | H21: =IFERROR(__xludf.DUMMYFUNCTION("""COMPUTED_VALUE"""),120.0) -> 120 | I21: =IFERROR(__xludf.DUMMYFUNCTION("""COMPUTED_VALUE"""),"") | J21: =IFERROR(__xludf.DUMMYFUNCTION("""COMPUTED_VALUE"""),60.0) -> 60 | L21: 7 | M21: 100 | N21: 0 | O21: 0 | P21: 0 | Q21: 0 | R21: 0 | S21: 0 | T21: 0 | U21: 120 | V21: 0 | W21: 60 | X21: 0
L23: Variant 3
L24: Day | M24: Coin | N24: SPT | O24: Red | P24: Chuck | Q24: Bomb | R24: Slingshot | S24: Shuffle | T24: Comet | U24: Unlimited Lives | V24: Unlimited Red | W24: Unlimited Chuck | X24: Unlimited Bomb
E25: =IFERROR(__xludf.DUMMYFUNCTION("LET( names, HSTACK(""Coins"", $N$4:$X$4), amounts, HSTACK(M25, N25:X25), lookupNames, $AB$4:$AB$15, lookupImages, $AC$4:$AC$15, imgs, MAP(names, LAMBDA(n, XLOOKUP(n, lookupNames, lookupImages))), keepImgs, FILTER(imgs, amounts<>0), keepAmoun"&"ts, FILTER(amounts, amounts<>0), MAKEARRAY( 1, COLUMNS(keepAmounts)*2, LAMBDA(r,c, IF( ISODD(c), INDEX(keepImgs, 1, ROUNDUP(c/2)), INDEX(keepAmounts, 1, c/2) ) ) ) )"),"") | F25: =IFERROR(__xludf.DUMMYFUNCTION("""COMPUTED_VALUE"""),15.0) -> 15 | L25: 1 | M25: 0 | N25: 0 | O25: 0 | P25: 0 | Q25: 0 | R25: 0 | S25: 0 | T25: 0 | U25: 15 | V25: 0 | W25: 0 | X25: 0
E26: =IFERROR(__xludf.DUMMYFUNCTION("LET( names, HSTACK(""Coins"", $N$4:$X$4), amounts, HSTACK(M26, N26:X26), lookupNames, $AB$4:$AB$15, lookupImages, $AC$4:$AC$15, imgs, MAP(names, LAMBDA(n, XLOOKUP(n, lookupNames, lookupImages))), keepImgs, FILTER(imgs, amounts<>0), keepAmoun"&"ts, FILTER(amounts, amounts<>0), MAKEARRAY( 1, COLUMNS(keepAmounts)*2, LAMBDA(r,c, IF( ISODD(c), INDEX(keepImgs, 1, ROUNDUP(c/2)), INDEX(keepAmounts, 1, c/2) ) ) ) )"),"") | F26: =IFERROR(__xludf.DUMMYFUNCTION("""COMPUTED_VALUE"""),20.0) -> 20 | L26: 2 | M26: 20 | N26: 0 | O26: 0 | P26: 0 | Q26: 0 | R26: 0 | S26: 0 | T26: 0 | U26: 0 | V26: 0 | W26: 0 | X26: 0
E27: =IFERROR(__xludf.DUMMYFUNCTION("LET( names, HSTACK(""Coins"", $N$4:$X$4), amounts, HSTACK(M27, N27:X27), lookupNames, $AB$4:$AB$15, lookupImages, $AC$4:$AC$15, imgs, MAP(names, LAMBDA(n, XLOOKUP(n, lookupNames, lookupImages))), keepImgs, FILTER(imgs, amounts<>0), keepAmoun"&"ts, FILTER(amounts, amounts<>0), MAKEARRAY( 1, COLUMNS(keepAmounts)*2, LAMBDA(r,c, IF( ISODD(c), INDEX(keepImgs, 1, ROUNDUP(c/2)), INDEX(keepAmounts, 1, c/2) ) ) ) )"),"") | F27: =IFERROR(__xludf.DUMMYFUNCTION("""COMPUTED_VALUE"""),1.0) -> 1 | L27: 3 | M27: 0 | N27: 0 | O27: 0 | P27: 0 | Q27: 0 | R27: 1 | S27: 0 | T27: 0 | U27: 0 | V27: 0 | W27: 0 | X27: 0
E28: =IFERROR(__xludf.DUMMYFUNCTION("LET( names, HSTACK(""Coins"", $N$4:$X$4), amounts, HSTACK(M28, N28:X28), lookupNames, $AB$4:$AB$15, lookupImages, $AC$4:$AC$15, imgs, MAP(names, LAMBDA(n, XLOOKUP(n, lookupNames, lookupImages))), keepImgs, FILTER(imgs, amounts<>0), keepAmoun"&"ts, FILTER(amounts, amounts<>0), MAKEARRAY( 1, COLUMNS(keepAmounts)*2, LAMBDA(r,c, IF( ISODD(c), INDEX(keepImgs, 1, ROUNDUP(c/2)), INDEX(keepAmounts, 1, c/2) ) ) ) )"),"") | F28: =IFERROR(__xludf.DUMMYFUNCTION("""COMPUTED_VALUE"""),25.0) -> 25 | L28: 4 | M28: 25 | N28: 0 | O28: 0 | P28: 0 | Q28: 0 | R28: 0 | S28: 0 | T28: 0 | U28: 0 | V28: 0 | W28: 0 | X28: 0
E29: =IFERROR(__xludf.DUMMYFUNCTION("LET( names, HSTACK(""Coins"", $N$4:$X$4), amounts, HSTACK(M29, N29:X29), lookupNames, $AB$4:$AB$15, lookupImages, $AC$4:$AC$15, imgs, MAP(names, LAMBDA(n, XLOOKUP(n, lookupNames, lookupImages))), keepImgs, FILTER(imgs, amounts<>0), keepAmoun"&"ts, FILTER(amounts, amounts<>0), MAKEARRAY( 1, COLUMNS(keepAmounts)*2, LAMBDA(r,c, IF( ISODD(c), INDEX(keepImgs, 1, ROUNDUP(c/2)), INDEX(keepAmounts, 1, c/2) ) ) ) )"),"") | F29: =IFERROR(__xludf.DUMMYFUNCTION("""COMPUTED_VALUE"""),1.0) -> 1 | L29: 5 | M29: 0 | N29: 0 | O29: 0 | P29: 0 | Q29: 0 | R29: 0 | S29: 1 | T29: 0 | U29: 0 | V29: 0 | W29: 0 | X29: 0
E30: =IFERROR(__xludf.DUMMYFUNCTION("LET( names, HSTACK(""Coins"", $N$4:$X$4), amounts, HSTACK(M30, N30:X30), lookupNames, $AB$4:$AB$15, lookupImages, $AC$4:$AC$15, imgs, MAP(names, LAMBDA(n, XLOOKUP(n, lookupNames, lookupImages))), keepImgs, FILTER(imgs, amounts<>0), keepAmoun"&"ts, FILTER(amounts, amounts<>0), MAKEARRAY( 1, COLUMNS(keepAmounts)*2, LAMBDA(r,c, IF( ISODD(c), INDEX(keepImgs, 1, ROUNDUP(c/2)), INDEX(keepAmounts, 1, c/2) ) ) ) )"),"") | F30: =IFERROR(__xludf.DUMMYFUNCTION("""COMPUTED_VALUE"""),30.0) -> 30 | L30: 6 | M30: 30 | N30: 0 | O30: 0 | P30: 0 | Q30: 0 | R30: 0 | S30: 0 | T30: 0 | U30: 0 | V30: 0 | W30: 0 | X30: 0
E31: =IFERROR(__xludf.DUMMYFUNCTION("LET( names, HSTACK(""Coins"", $N$4:$X$4), amounts, HSTACK(M31, N31:X31), lookupNames, $AB$4:$AB$15, lookupImages, $AC$4:$AC$15, imgs, MAP(names, LAMBDA(n, XLOOKUP(n, lookupNames, lookupImages))), keepImgs, FILTER(imgs, amounts<>0), keepAmoun"&"ts, FILTER(amounts, amounts<>0), MAKEARRAY( 1, COLUMNS(keepAmounts)*2, LAMBDA(r,c, IF( ISODD(c), INDEX(keepImgs, 1, ROUNDUP(c/2)), INDEX(keepAmounts, 1, c/2) ) ) ) )"),"") | F31: =IFERROR(__xludf.DUMMYFUNCTION("""COMPUTED_VALUE"""),100.0) -> 100 | G31: =IFERROR(__xludf.DUMMYFUNCTION("""COMPUTED_VALUE"""),"") | H31: =IFERROR(__xludf.DUMMYFUNCTION("""COMPUTED_VALUE"""),120.0) -> 120 | I31: =IFERROR(__xludf.DUMMYFUNCTION("""COMPUTED_VALUE"""),"") | J31: =IFERROR(__xludf.DUMMYFUNCTION("""COMPUTED_VALUE"""),30.0) -> 30 | L31: 7 | M31: 100 | N31: 0 | O31: 0 | P31: 0 | Q31: 0 | R31: 0 | S31: 0 | T31: 0 | U31: 120 | V31: 0 | W31: 0 | X31: 30
L33: Variant 4
L34: Day | M34: Coin | N34: SPT | O34: Red | P34: Chuck | Q34: Bomb | R34: Slingshot | S34: Shuffle | T34: Comet | U34: Unlimited Lives | V34: Unlimited Red | W34: Unlimited Chuck | X34: Unlimited Bomb
E35: =IFERROR(__xludf.DUMMYFUNCTION("LET( names, HSTACK(""Coins"", $N$4:$X$4), amounts, HSTACK(M35, N35:X35), lookupNames, $AB$4:$AB$15, lookupImages, $AC$4:$AC$15, imgs, MAP(names, LAMBDA(n, XLOOKUP(n, lookupNames, lookupImages))), keepImgs, FILTER(imgs, amounts<>0), keepAmoun"&"ts, FILTER(amounts, amounts<>0), MAKEARRAY( 1, COLUMNS(keepAmounts)*2, LAMBDA(r,c, IF( ISODD(c), INDEX(keepImgs, 1, ROUNDUP(c/2)), INDEX(keepAmounts, 1, c/2) ) ) ) )"),"") | F35: =IFERROR(__xludf.DUMMYFUNCTION("""COMPUTED_VALUE"""),25.0) -> 25 | L35: 1 | M35: 25 | N35: 0 | O35: 0 | P35: 0 | Q35: 0 | R35: 0 | S35: 0 | T35: 0 | U35: 0 | V35: 0 | W35: 0 | X35: 0
E36: =IFERROR(__xludf.DUMMYFUNCTION("LET( names, HSTACK(""Coins"", $N$4:$X$4), amounts, HSTACK(M36, N36:X36), lookupNames, $AB$4:$AB$15, lookupImages, $AC$4:$AC$15, imgs, MAP(names, LAMBDA(n, XLOOKUP(n, lookupNames, lookupImages))), keepImgs, FILTER(imgs, amounts<>0), keepAmoun"&"ts, FILTER(amounts, amounts<>0), MAKEARRAY( 1, COLUMNS(keepAmounts)*2, LAMBDA(r,c, IF( ISODD(c), INDEX(keepImgs, 1, ROUNDUP(c/2)), INDEX(keepAmounts, 1, c/2) ) ) ) )"),"") | F36: =IFERROR(__xludf.DUMMYFUNCTION("""COMPUTED_VALUE"""),30.0) -> 30 | L36: 2 | M36: 0 | N36: 0 | O36: 0 | P36: 0 | Q36: 0 | R36: 0 | S36: 0 | T36: 0 | U36: 30 | V36: 0 | W36: 0 | X36: 0
E37: =IFERROR(__xludf.DUMMYFUNCTION("LET( names, HSTACK(""Coins"", $N$4:$X$4), amounts, HSTACK(M37, N37:X37), lookupNames, $AB$4:$AB$15, lookupImages, $AC$4:$AC$15, imgs, MAP(names, LAMBDA(n, XLOOKUP(n, lookupNames, lookupImages))), keepImgs, FILTER(imgs, amounts<>0), keepAmoun"&"ts, FILTER(amounts, amounts<>0), MAKEARRAY( 1, COLUMNS(keepAmounts)*2, LAMBDA(r,c, IF( ISODD(c), INDEX(keepImgs, 1, ROUNDUP(c/2)), INDEX(keepAmounts, 1, c/2) ) ) ) )"),"") | F37: =IFERROR(__xludf.DUMMYFUNCTION("""COMPUTED_VALUE"""),1.0) -> 1 | L37: 3 | M37: 0 | N37: 0 | O37: 0 | P37: 0 | Q37: 0 | R37: 0 | S37: 1 | T37: 0 | U37: 0 | V37: 0 | W37: 0 | X37: 0
E38: =IFERROR(__xludf.DUMMYFUNCTION("LET( names, HSTACK(""Coins"", $N$4:$X$4), amounts, HSTACK(M38, N38:X38), lookupNames, $AB$4:$AB$15, lookupImages, $AC$4:$AC$15, imgs, MAP(names, LAMBDA(n, XLOOKUP(n, lookupNames, lookupImages))), keepImgs, FILTER(imgs, amounts<>0), keepAmoun"&"ts, FILTER(amounts, amounts<>0), MAKEARRAY( 1, COLUMNS(keepAmounts)*2, LAMBDA(r,c, IF( ISODD(c), INDEX(keepImgs, 1, ROUNDUP(c/2)), INDEX(keepAmounts, 1, c/2) ) ) ) )"),"") | F38: =IFERROR(__xludf.DUMMYFUNCTION("""COMPUTED_VALUE"""),1.0) -> 1 | L38: 4 | M38: 0 | N38: 0 | O38: 0 | P38: 0 | Q38: 0 | R38: 1 | S38: 0 | T38: 0 | U38: 0 | V38: 0 | W38: 0 | X38: 0
E39: =IFERROR(__xludf.DUMMYFUNCTION("LET( names, HSTACK(""Coins"", $N$4:$X$4), amounts, HSTACK(M39, N39:X39), lookupNames, $AB$4:$AB$15, lookupImages, $AC$4:$AC$15, imgs, MAP(names, LAMBDA(n, XLOOKUP(n, lookupNames, lookupImages))), keepImgs, FILTER(imgs, amounts<>0), keepAmoun"&"ts, FILTER(amounts, amounts<>0), MAKEARRAY( 1, COLUMNS(keepAmounts)*2, LAMBDA(r,c, IF( ISODD(c), INDEX(keepImgs, 1, ROUNDUP(c/2)), INDEX(keepAmounts, 1, c/2) ) ) ) )"),"") | F39: =IFERROR(__xludf.DUMMYFUNCTION("""COMPUTED_VALUE"""),30.0) -> 30 | L39: 5 | M39: 30 | N39: 0 | O39: 0 | P39: 0 | Q39: 0 | R39: 0 | S39: 0 | T39: 0 | U39: 0 | V39: 0 | W39: 0 | X39: 0
E40: =IFERROR(__xludf.DUMMYFUNCTION("LET( names, HSTACK(""Coins"", $N$4:$X$4), amounts, HSTACK(M40, N40:X40), lookupNames, $AB$4:$AB$15, lookupImages, $AC$4:$AC$15, imgs, MAP(names, LAMBDA(n, XLOOKUP(n, lookupNames, lookupImages))), keepImgs, FILTER(imgs, amounts<>0), keepAmoun"&"ts, FILTER(amounts, amounts<>0), MAKEARRAY( 1, COLUMNS(keepAmounts)*2, LAMBDA(r,c, IF( ISODD(c), INDEX(keepImgs, 1, ROUNDUP(c/2)), INDEX(keepAmounts, 1, c/2) ) ) ) )"),"") | F40: =IFERROR(__xludf.DUMMYFUNCTION("""COMPUTED_VALUE"""),1.0) -> 1 | L40: 6 | M40: 0 | N40: 0 | O40: 0 | P40: 0 | Q40: 0 | R40: 1 | S40: 0 | T40: 0 | U40: 0 | V40: 0 | W40: 0 | X40: 0
E41: =IFERROR(__xludf.DUMMYFUNCTION("LET( names, HSTACK(""Coins"", $N$4:$X$4), amounts, HSTACK(M41, N41:X41), lookupNames, $AB$4:$AB$15, lookupImages, $AC$4:$AC$15, imgs, MAP(names, LAMBDA(n, XLOOKUP(n, lookupNames, lookupImages))), keepImgs, FILTER(imgs, amounts<>0), keepAmoun"&"ts, FILTER(amounts, amounts<>0), MAKEARRAY( 1, COLUMNS(keepAmounts)*2, LAMBDA(r,c, IF( ISODD(c), INDEX(keepImgs, 1, ROUNDUP(c/2)), INDEX(keepAmounts, 1, c/2) ) ) ) )"),"") | F41: =IFERROR(__xludf.DUMMYFUNCTION("""COMPUTED_VALUE"""),100.0) -> 100 | G41: =IFERROR(__xludf.DUMMYFUNCTION("""COMPUTED_VALUE"""),"") | H41: =IFERROR(__xludf.DUMMYFUNCTION("""COMPUTED_VALUE"""),1.0) -> 1 | I41: =IFERROR(__xludf.DUMMYFUNCTION("""COMPUTED_VALUE"""),"") | J41: =IFERROR(__xludf.DUMMYFUNCTION("""COMPUTED_VALUE"""),120.0) -> 120 | L41: 7 | M41: 100 | N41: 0 | O41: 0 | P41: 0 | Q41: 0 | R41: 0 | S41: 0 | T41: 1 | U41: 120 | V41: 0 | W41: 0 | X41: 0
L43: Variant 5
L44: Day | M44: Coin | N44: SPT | O44: Red | P44: Chuck | Q44: Bomb | R44: Slingshot | S44: Shuffle | T44: Comet | U44: Unlimited Lives | V44: Unlimited Red | W44: Unlimited Chuck | X44: Unlimited Bomb
...

Sheet c_day_v2
A1: Daily Rewards - NEW
L2: all segs
A3: Day | B3: HC Reward | E3: 👁 | L3: Variant 1 | AB3: cur | AC3: image
A4: 1 | B4: =average(M5,M16,M26,M35,M45) -> 10 | L4: Day | M4: Coin | N4: SPT | O4: Red | P4: Chuck | Q4: Bomb | R4: Slingshot | S4: Shuffle | T4: Comet | U4: Unlimited Lives | V4: Unlimited Red | W4: Unlimited Chuck | X4: Unlimited Bomb | AB4: Coins
A5: 2 | B5: 0 | E5: =IFERROR(__xludf.DUMMYFUNCTION("LET( names, HSTACK(""Coins"", $N$4:$X$4), amounts, HSTACK(M5, N5:X5), lookupNames, $AB$4:$AB$15, lookupImages, $AC$4:$AC$15, imgs, MAP(names, LAMBDA(n, XLOOKUP(n, lookupNames, lookupImages))), keepImgs, FILTER(imgs, amounts<>0), keepAmounts,"&" FILTER(amounts, amounts<>0), MAKEARRAY( 1, COLUMNS(keepAmounts)*2, LAMBDA(r,c, IF( ISODD(c), INDEX(keepImgs, 1, ROUNDUP(c/2)), INDEX(keepAmounts, 1, c/2) ) ) ) )"),"") | F5: =IFERROR(__xludf.DUMMYFUNCTION("""COMPUTED_VALUE"""),10.0) -> 10 | L5: 1 | M5: 10 | N5: 0 | O5: 0 | P5: 0 | Q5: 0 | R5: 0 | S5: 0 | T5: 0 | U5: 0 | V5: 0 | W5: 0 | X5: 0 | AB5: SPT
A6: 3 | B6: 0 | E6: =IFERROR(__xludf.DUMMYFUNCTION("LET( names, HSTACK(""Coins"", $N$4:$X$4), amounts, HSTACK(M6, N6:X6), lookupNames, $AB$4:$AB$15, lookupImages, $AC$4:$AC$15, imgs, MAP(names, LAMBDA(n, XLOOKUP(n, lookupNames, lookupImages))), keepImgs, FILTER(imgs, amounts<>0), keepAmounts,"&" FILTER(amounts, amounts<>0), MAKEARRAY( 1, COLUMNS(keepAmounts)*2, LAMBDA(r,c, IF( ISODD(c), INDEX(keepImgs, 1, ROUNDUP(c/2)), INDEX(keepAmounts, 1, c/2) ) ) ) )"),"") | F6: =IFERROR(__xludf.DUMMYFUNCTION("""COMPUTED_VALUE"""),15.0) -> 15 | L6: 2 | M6: 0 | N6: 0 | O6: 0 | P6: 0 | Q6: 0 | R6: 0 | S6: 0 | T6: 0 | U6: 15 | V6: 0 | W6: 0 | X6: 0 | AB6: Red
A7: 4 | B7: =mround(average(M8,M18,M28), 1) -> 10 | E7: =IFERROR(__xludf.DUMMYFUNCTION("LET( names, HSTACK(""Coins"", $N$4:$X$4), amounts, HSTACK(M7, N7:X7), lookupNames, $AB$4:$AB$15, lookupImages, $AC$4:$AC$15, imgs, MAP(names, LAMBDA(n, XLOOKUP(n, lookupNames, lookupImages))), keepImgs, FILTER(imgs, amounts<>0), keepAmounts,"&" FILTER(amounts, amounts<>0), MAKEARRAY( 1, COLUMNS(keepAmounts)*2, LAMBDA(r,c, IF( ISODD(c), INDEX(keepImgs, 1, ROUNDUP(c/2)), INDEX(keepAmounts, 1, c/2) ) ) ) )"),"") | F7: =IFERROR(__xludf.DUMMYFUNCTION("""COMPUTED_VALUE"""),1.0) -> 1 | L7: 3 | M7: 0 | N7: 0 | O7: 0 | P7: 0 | Q7: 0 | R7: 1 | S7: 0 | T7: 0 | U7: 0 | V7: 0 | W7: 0 | X7: 0 | AB7: Chuck
A8: 5 | B8: 0 | E8: =IFERROR(__xludf.DUMMYFUNCTION("LET( names, HSTACK(""Coins"", $N$4:$X$4), amounts, HSTACK(M8, N8:X8), lookupNames, $AB$4:$AB$15, lookupImages, $AC$4:$AC$15, imgs, MAP(names, LAMBDA(n, XLOOKUP(n, lookupNames, lookupImages))), keepImgs, FILTER(imgs, amounts<>0), keepAmounts,"&" FILTER(amounts, amounts<>0), MAKEARRAY( 1, COLUMNS(keepAmounts)*2, LAMBDA(r,c, IF( ISODD(c), INDEX(keepImgs, 1, ROUNDUP(c/2)), INDEX(keepAmounts, 1, c/2) ) ) ) )"),"") | F8: =IFERROR(__xludf.DUMMYFUNCTION("""COMPUTED_VALUE"""),10.0) -> 10 | L8: 4 | M8: 10 | N8: 0 | O8: 0 | P8: 0 | Q8: 0 | R8: 0 | S8: 0 | T8: 0 | U8: 0 | V8: 0 | W8: 0 | X8: 0 | AB8: Bomb
A9: 6 | B9: =mround(AVERAGE(M10, M20, M30, M50),1) -> 10 | E9: =IFERROR(__xludf.DUMMYFUNCTION("LET( names, HSTACK(""Coins"", $N$4:$X$4), amounts, HSTACK(M9, N9:X9), lookupNames, $AB$4:$AB$15, lookupImages, $AC$4:$AC$15, imgs, MAP(names, LAMBDA(n, XLOOKUP(n, lookupNames, lookupImages))), keepImgs, FILTER(imgs, amounts<>0), keepAmounts,"&" FILTER(amounts, amounts<>0), MAKEARRAY( 1, COLUMNS(keepAmounts)*2, LAMBDA(r,c, IF( ISODD(c), INDEX(keepImgs, 1, ROUNDUP(c/2)), INDEX(keepAmounts, 1, c/2) ) ) ) )"),"") | F9: =IFERROR(__xludf.DUMMYFUNCTION("""COMPUTED_VALUE"""),1.0) -> 1 | L9: 5 | M9: 0 | N9: 0 | O9: 0 | P9: 0 | Q9: 0 | R9: 0 | S9: 1 | T9: 0 | U9: 0 | V9: 0 | W9: 0 | X9: 0 | AB9: Slingshot
A10: 7 | B10: 100 | E10: =IFERROR(__xludf.DUMMYFUNCTION("LET( names, HSTACK(""Coins"", $N$4:$X$4), amounts, HSTACK(M10, N10:X10), lookupNames, $AB$4:$AB$15, lookupImages, $AC$4:$AC$15, imgs, MAP(names, LAMBDA(n, XLOOKUP(n, lookupNames, lookupImages))), keepImgs, FILTER(imgs, amounts<>0), keepAmoun"&"ts, FILTER(amounts, amounts<>0), MAKEARRAY( 1, COLUMNS(keepAmounts)*2, LAMBDA(r,c, IF( ISODD(c), INDEX(keepImgs, 1, ROUNDUP(c/2)), INDEX(keepAmounts, 1, c/2) ) ) ) )"),"") | F10: =IFERROR(__xludf.DUMMYFUNCTION("""COMPUTED_VALUE"""),10.0) -> 10 | L10: 6 | M10: 10 | N10: 0 | O10: 0 | P10: 0 | Q10: 0 | R10: 0 | S10: 0 | T10: 0 | U10: 0 | V10: 0 | W10: 0 | X10: 0 | AB10: Shuffle
E11: =IFERROR(__xludf.DUMMYFUNCTION("LET( names, HSTACK(""Coins"", $N$4:$X$4), amounts, HSTACK(M11, N11:X11), lookupNames, $AB$4:$AB$15, lookupImages, $AC$4:$AC$15, imgs, MAP(names, LAMBDA(n, XLOOKUP(n, lookupNames, lookupImages))), keepImgs, FILTER(imgs, amounts<>0), keepAmoun"&"ts, FILTER(amounts, amounts<>0), MAKEARRAY( 1, COLUMNS(keepAmounts)*2, LAMBDA(r,c, IF( ISODD(c), INDEX(keepImgs, 1, ROUNDUP(c/2)), INDEX(keepAmounts, 1, c/2) ) ) ) )"),"") | F11: =IFERROR(__xludf.DUMMYFUNCTION("""COMPUTED_VALUE"""),100.0) -> 100 | G11: =IFERROR(__xludf.DUMMYFUNCTION("""COMPUTED_VALUE"""),"") | H11: =IFERROR(__xludf.DUMMYFUNCTION("""COMPUTED_VALUE"""),120.0) -> 120 | I11: =IFERROR(__xludf.DUMMYFUNCTION("""COMPUTED_VALUE"""),"") | J11: =IFERROR(__xludf.DUMMYFUNCTION("""COMPUTED_VALUE"""),60.0) -> 60 | L11: 7 | M11: 100 | N11: 0 | O11: 0 | P11: 0 | Q11: 0 | R11: 0 | S11: 0 | T11: 0 | U11: 120 | V11: 60 | W11: 0 | X11: 0 | AB11: Comet
A12: Total per cycle | B12: =SUM(B4:B10) -> 130 | AB12: Unlimited Lives
A13: Avg HC/day (7d) | B13: =B12/7 -> 18.571429 | L13: Variant 2 | AB13: Unlimited Red
L14: Day | M14: Coin | N14: SPT | O14: Red | P14: Chuck | Q14: Bomb | R14: Slingshot | S14: Shuffle | T14: Comet | U14: Unlimited Lives | V14: Unlimited Red | W14: Unlimited Chuck | X14: Unlimited Bomb | AB14: Unlimited Chuck
A15: % of old | B15: =B12/c_day!B12 -> 0.71428571 | E15: =IFERROR(__xludf.DUMMYFUNCTION("LET( names, HSTACK(""Coins"", $N$4:$X$4), amounts, HSTACK(M15, N15:X15), lookupNames, $AB$4:$AB$15, lookupImages, $AC$4:$AC$15, imgs, MAP(names, LAMBDA(n, XLOOKUP(n, lookupNames, lookupImages))), keepImgs, FILTER(imgs, amounts<>0), keepAmoun"&"ts, FILTER(amounts, amounts<>0), MAKEARRAY( 1, COLUMNS(keepAmounts)*2, LAMBDA(r,c, IF( ISODD(c), INDEX(keepImgs, 1, ROUNDUP(c/2)), INDEX(keepAmounts, 1, c/2) ) ) ) )"),"") | F15: =IFERROR(__xludf.DUMMYFUNCTION("""COMPUTED_VALUE"""),20.0) -> 20 | L15: 1 | M15: 0 | N15: 0 | O15: 0 | P15: 0 | Q15: 0 | R15: 0 | S15: 0 | T15: 0 | U15: 20 | V15: 0 | W15: 0 | X15: 0 | AB15: Unlimited Bomb
E16: =IFERROR(__xludf.DUMMYFUNCTION("LET( names, HSTACK(""Coins"", $N$4:$X$4), amounts, HSTACK(M16, N16:X16), lookupNames, $AB$4:$AB$15, lookupImages, $AC$4:$AC$15, imgs, MAP(names, LAMBDA(n, XLOOKUP(n, lookupNames, lookupImages))), keepImgs, FILTER(imgs, amounts<>0), keepAmoun"&"ts, FILTER(amounts, amounts<>0), MAKEARRAY( 1, COLUMNS(keepAmounts)*2, LAMBDA(r,c, IF( ISODD(c), INDEX(keepImgs, 1, ROUNDUP(c/2)), INDEX(keepAmounts, 1, c/2) ) ) ) )"),"") | F16: =IFERROR(__xludf.DUMMYFUNCTION("""COMPUTED_VALUE"""),10.0) -> 10 | L16: 2 | M16: 10 | N16: 0 | O16: 0 | P16: 0 | Q16: 0 | R16: 0 | S16: 0 | T16: 0 | U16: 0 | V16: 0 | W16: 0 | X16: 0
E17: =IFERROR(__xludf.DUMMYFUNCTION("LET( names, HSTACK(""Coins"", $N$4:$X$4), amounts, HSTACK(M17, N17:X17), lookupNames, $AB$4:$AB$15, lookupImages, $AC$4:$AC$15, imgs, MAP(names, LAMBDA(n, XLOOKUP(n, lookupNames, lookupImages))), keepImgs, FILTER(imgs, amounts<>0), keepAmoun"&"ts, FILTER(amounts, amounts<>0), MAKEARRAY( 1, COLUMNS(keepAmounts)*2, LAMBDA(r,c, IF( ISODD(c), INDEX(keepImgs, 1, ROUNDUP(c/2)), INDEX(keepAmounts, 1, c/2) ) ) ) )"),"") | F17: =IFERROR(__xludf.DUMMYFUNCTION("""COMPUTED_VALUE"""),1.0) -> 1 | L17: 3 | M17: 0 | N17: 0 | O17: 0 | P17: 0 | Q17: 0 | R17: 1 | S17: 0 | T17: 0 | U17: 0 | V17: 0 | W17: 0 | X17: 0
E18: =IFERROR(__xludf.DUMMYFUNCTION("LET( names, HSTACK(""Coins"", $N$4:$X$4), amounts, HSTACK(M18, N18:X18), lookupNames, $AB$4:$AB$15, lookupImages, $AC$4:$AC$15, imgs, MAP(names, LAMBDA(n, XLOOKUP(n, lookupNames, lookupImages))), keepImgs, FILTER(imgs, amounts<>0), keepAmoun"&"ts, FILTER(amounts, amounts<>0), MAKEARRAY( 1, COLUMNS(keepAmounts)*2, LAMBDA(r,c, IF( ISODD(c), INDEX(keepImgs, 1, ROUNDUP(c/2)), INDEX(keepAmounts, 1, c/2) ) ) ) )"),"") | F18: =IFERROR(__xludf.DUMMYFUNCTION("""COMPUTED_VALUE"""),10.0) -> 10 | L18: 4 | M18: 10 | N18: 0 | O18: 0 | P18: 0 | Q18: 0 | R18: 0 | S18: 0 | T18: 0 | U18: 0 | V18: 0 | W18: 0 | X18: 0
E19: =IFERROR(__xludf.DUMMYFUNCTION("LET( names, HSTACK(""Coins"", $N$4:$X$4), amounts, HSTACK(M19, N19:X19), lookupNames, $AB$4:$AB$15, lookupImages, $AC$4:$AC$15, imgs, MAP(names, LAMBDA(n, XLOOKUP(n, lookupNames, lookupImages))), keepImgs, FILTER(imgs, amounts<>0), keepAmoun"&"ts, FILTER(amounts, amounts<>0), MAKEARRAY( 1, COLUMNS(keepAmounts)*2, LAMBDA(r,c, IF( ISODD(c), INDEX(keepImgs, 1, ROUNDUP(c/2)), INDEX(keepAmounts, 1, c/2) ) ) ) )"),"") | F19: =IFERROR(__xludf.DUMMYFUNCTION("""COMPUTED_VALUE"""),1.0) -> 1 | L19: 5 | M19: 0 | N19: 0 | O19: 0 | P19: 0 | Q19: 0 | R19: 0 | S19: 1 | T19: 0 | U19: 0 | V19: 0 | W19: 0 | X19: 0
E20: =IFERROR(__xludf.DUMMYFUNCTION("LET( names, HSTACK(""Coins"", $N$4:$X$4), amounts, HSTACK(M20, N20:X20), lookupNames, $AB$4:$AB$15, lookupImages, $AC$4:$AC$15, imgs, MAP(names, LAMBDA(n, XLOOKUP(n, lookupNames, lookupImages))), keepImgs, FILTER(imgs, amounts<>0), keepAmoun"&"ts, FILTER(amounts, amounts<>0), MAKEARRAY( 1, COLUMNS(keepAmounts)*2, LAMBDA(r,c, IF( ISODD(c), INDEX(keepImgs, 1, ROUNDUP(c/2)), INDEX(keepAmounts, 1, c/2) ) ) ) )"),"") | F20: =IFERROR(__xludf.DUMMYFUNCTION("""COMPUTED_VALUE"""),10.0) -> 10 | L20: 6 | M20: 10 | N20: 0 | O20: 0 | P20: 0 | Q20: 0 | R20: 0 | S20: 0 | T20: 0 | U20: 0 | V20: 0 | W20: 0 | X20: 0
E21: =IFERROR(__xludf.DUMMYFUNCTION("LET( names, HSTACK(""Coins"", $N$4:$X$4), amounts, HSTACK(M21, N21:X21), lookupNames, $AB$4:$AB$15, lookupImages, $AC$4:$AC$15, imgs, MAP(names, LAMBDA(n, XLOOKUP(n, lookupNames, lookupImages))), keepImgs, FILTER(imgs, amounts<>0), keepAmoun"&"ts, FILTER(amounts, amounts<>0), MAKEARRAY( 1, COLUMNS(keepAmounts)*2, LAMBDA(r,c, IF( ISODD(c), INDEX(keepImgs, 1, ROUNDUP(c/2)), INDEX(keepAmounts, 1, c/2) ) ) ) )"),"") | F21: =IFERROR(__xludf.DUMMYFUNCTION("""COMPUTED_VALUE"""),100.0) -> 100 | G21: =IFERROR(__xludf.DUMMYFUNCTION("""COMPUTED_VALUE"""),"") | H21: =IFERROR(__xludf.DUMMYFUNCTION("""COMPUTED_VALUE"""),120.0) -> 120 | I21: =IFERROR(__xludf.DUMMYFUNCTION("""COMPUTED_VALUE"""),"") | J21: =IFERROR(__xludf.DUMMYFUNCTION("""COMPUTED_VALUE"""),60.0) -> 60 | L21: 7 | M21: 100 | N21: 0 | O21: 0 | P21: 0 | Q21: 0 | R21: 0 | S21: 0 | T21: 0 | U21: 120 | V21: 0 | W21: 60 | X21: 0
L23: Variant 3
L24: Day | M24: Coin | N24: SPT | O24: Red | P24: Chuck | Q24: Bomb | R24: Slingshot | S24: Shuffle | T24: Comet | U24: Unlimited Lives | V24: Unlimited Red | W24: Unlimited Chuck | X24: Unlimited Bomb
E25: =IFERROR(__xludf.DUMMYFUNCTION("LET( names, HSTACK(""Coins"", $N$4:$X$4), amounts, HSTACK(M25, N25:X25), lookupNames, $AB$4:$AB$15, lookupImages, $AC$4:$AC$15, imgs, MAP(names, LAMBDA(n, XLOOKUP(n, lookupNames, lookupImages))), keepImgs, FILTER(imgs, amounts<>0), keepAmoun"&"ts, FILTER(amounts, amounts<>0), MAKEARRAY( 1, COLUMNS(keepAmounts)*2, LAMBDA(r,c, IF( ISODD(c), INDEX(keepImgs, 1, ROUNDUP(c/2)), INDEX(keepAmounts, 1, c/2) ) ) ) )"),"") | F25: =IFERROR(__xludf.DUMMYFUNCTION("""COMPUTED_VALUE"""),15.0) -> 15 | L25: 1 | M25: 0 | N25: 0 | O25: 0 | P25: 0 | Q25: 0 | R25: 0 | S25: 0 | T25: 0 | U25: 15 | V25: 0 | W25: 0 | X25: 0
E26: =IFERROR(__xludf.DUMMYFUNCTION("LET( names, HSTACK(""Coins"", $N$4:$X$4), amounts, HSTACK(M26, N26:X26), lookupNames, $AB$4:$AB$15, lookupImages, $AC$4:$AC$15, imgs, MAP(names, LAMBDA(n, XLOOKUP(n, lookupNames, lookupImages))), keepImgs, FILTER(imgs, amounts<>0), keepAmoun"&"ts, FILTER(amounts, amounts<>0), MAKEARRAY( 1, COLUMNS(keepAmounts)*2, LAMBDA(r,c, IF( ISODD(c), INDEX(keepImgs, 1, ROUNDUP(c/2)), INDEX(keepAmounts, 1, c/2) ) ) ) )"),"") | F26: =IFERROR(__xludf.DUMMYFUNCTION("""COMPUTED_VALUE"""),10.0) -> 10 | L26: 2 | M26: 10 | N26: 0 | O26: 0 | P26: 0 | Q26: 0 | R26: 0 | S26: 0 | T26: 0 | U26: 0 | V26: 0 | W26: 0 | X26: 0
E27: =IFERROR(__xludf.DUMMYFUNCTION("LET( names, HSTACK(""Coins"", $N$4:$X$4), amounts, HSTACK(M27, N27:X27), lookupNames, $AB$4:$AB$15, lookupImages, $AC$4:$AC$15, imgs, MAP(names, LAMBDA(n, XLOOKUP(n, lookupNames, lookupImages))), keepImgs, FILTER(imgs, amounts<>0), keepAmoun"&"ts, FILTER(amounts, amounts<>0), MAKEARRAY( 1, COLUMNS(keepAmounts)*2, LAMBDA(r,c, IF( ISODD(c), INDEX(keepImgs, 1, ROUNDUP(c/2)), INDEX(keepAmounts, 1, c/2) ) ) ) )"),"") | F27: =IFERROR(__xludf.DUMMYFUNCTION("""COMPUTED_VALUE"""),1.0) -> 1 | L27: 3 | M27: 0 | N27: 0 | O27: 0 | P27: 0 | Q27: 0 | R27: 1 | S27: 0 | T27: 0 | U27: 0 | V27: 0 | W27: 0 | X27: 0
E28: =IFERROR(__xludf.DUMMYFUNCTION("LET( names, HSTACK(""Coins"", $N$4:$X$4), amounts, HSTACK(M28, N28:X28), lookupNames, $AB$4:$AB$15, lookupImages, $AC$4:$AC$15, imgs, MAP(names, LAMBDA(n, XLOOKUP(n, lookupNames, lookupImages))), keepImgs, FILTER(imgs, amounts<>0), keepAmoun"&"ts, FILTER(amounts, amounts<>0), MAKEARRAY( 1, COLUMNS(keepAmounts)*2, LAMBDA(r,c, IF( ISODD(c), INDEX(keepImgs, 1, ROUNDUP(c/2)), INDEX(keepAmounts, 1, c/2) ) ) ) )"),"") | F28: =IFERROR(__xludf.DUMMYFUNCTION("""COMPUTED_VALUE"""),10.0) -> 10 | L28: 4 | M28: 10 | N28: 0 | O28: 0 | P28: 0 | Q28: 0 | R28: 0 | S28: 0 | T28: 0 | U28: 0 | V28: 0 | W28: 0 | X28: 0
