Workbook

Sheet By Bucket
A1: A/B Test Summary By 7d Completion Bucket
A3: Category | B3: Metric | C3: 0 | F3: 1-9 | I3: 10-19 | L3: 20-39 | O3: 40-99 | R3: 100+
C4: Control | D4: Variant | E4: Δ % | F4: Control | G4: Variant | H4: Δ % | I4: Control | J4: Variant | K4: Δ % | L4: Control | M4: Variant | N4: Δ % | O4: Control | P4: Variant | Q4: Δ % | R4: Control | S4: Variant | T4: Δ %
A5: Players
B6: Players (sum) | C6: =SUMIFS('Raw Data'!$D:$D, 'Raw Data'!$B:$B, "Control", 'Raw Data'!$C:$C, "A. 0") -> 467890 | D6: =SUMIFS('Raw Data'!$D:$D, 'Raw Data'!$B:$B, "Variant", 'Raw Data'!$C:$C, "A. 0") -> 475895 | E6: =IFERROR((D6-C6)/ABS(C6),"") -> 0.017108722 | F6: =SUMIFS('Raw Data'!$D:$D, 'Raw Data'!$B:$B, "Control", 'Raw Data'!$C:$C, "B. 1-9") -> 916871 | G6: =SUMIFS('Raw Data'!$D:$D, 'Raw Data'!$B:$B, "Variant", 'Raw Data'!$C:$C, "B. 1-9") -> 881788 | H6: =IFERROR((G6-F6)/ABS(F6),"") -> -0.038263834 | I6: =SUMIFS('Raw Data'!$D:$D, 'Raw Data'!$B:$B, "Control", 'Raw Data'!$C:$C, "C. 10-19") -> 551945 | J6: =SUMIFS('Raw Data'!$D:$D, 'Raw Data'!$B:$B, "Variant", 'Raw Data'!$C:$C, "C. 10-19") -> 552886 | K6: =IFERROR((J6-I6)/ABS(I6),"") -> 0.00170488 | L6: =SUMIFS('Raw Data'!$D:$D, 'Raw Data'!$B:$B, "Control", 'Raw Data'!$C:$C, "D. 20-39") -> 300214 | M6: =SUMIFS('Raw Data'!$D:$D, 'Raw Data'!$B:$B, "Variant", 'Raw Data'!$C:$C, "D. 20-39") -> 307551 | N6: =IFERROR((M6-L6)/ABS(L6),"") -> 0.024439233 | O6: =SUMIFS('Raw Data'!$D:$D, 'Raw Data'!$B:$B, "Control", 'Raw Data'!$C:$C, "E. 40-99") -> 119870 | P6: =SUMIFS('Raw Data'!$D:$D, 'Raw Data'!$B:$B, "Variant", 'Raw Data'!$C:$C, "E. 40-99") -> 128100 | Q6: =IFERROR((P6-O6)/ABS(O6),"") -> 0.068657713 | R6: =SUMIFS('Raw Data'!$D:$D, 'Raw Data'!$B:$B, "Control", 'Raw Data'!$C:$C, "F. 100+") -> 13045 | S6: =SUMIFS('Raw Data'!$D:$D, 'Raw Data'!$B:$B, "Variant", 'Raw Data'!$C:$C, "F. 100+") -> 14508 | T6: =IFERROR((S6-R6)/ABS(R6),"") -> 0.11215025
A7: Revenue
B8: Total revenue | C8: =SUMIFS('Raw Data'!$F:$F, 'Raw Data'!$B:$B, "Control", 'Raw Data'!$C:$C, "A. 0") -> 2400.05 | D8: =SUMIFS('Raw Data'!$F:$F, 'Raw Data'!$B:$B, "Variant", 'Raw Data'!$C:$C, "A. 0") -> 2067.13 | E8: =IFERROR((D8-C8)/ABS(C8),"") -> -0.13871378 | F8: =SUMIFS('Raw Data'!$F:$F, 'Raw Data'!$B:$B, "Control", 'Raw Data'!$C:$C, "B. 1-9") -> 96065.51 | G8: =SUMIFS('Raw Data'!$F:$F, 'Raw Data'!$B:$B, "Variant", 'Raw Data'!$C:$C, "B. 1-9") -> 94348.51 | H8: =IFERROR((G8-F8)/ABS(F8),"") -> -0.01787322 | I8: =SUMIFS('Raw Data'!$F:$F, 'Raw Data'!$B:$B, "Control", 'Raw Data'!$C:$C, "C. 10-19") -> 208718.62 | J8: =SUMIFS('Raw Data'!$F:$F, 'Raw Data'!$B:$B, "Variant", 'Raw Data'!$C:$C, "C. 10-19") -> 211098.24 | K8: =IFERROR((J8-I8)/ABS(I8),"") -> 0.011401091 | L8: =SUMIFS('Raw Data'!$F:$F, 'Raw Data'!$B:$B, "Control", 'Raw Data'!$C:$C, "D. 20-39") -> 263848.34 | M8: =SUMIFS('Raw Data'!$F:$F, 'Raw Data'!$B:$B, "Variant", 'Raw Data'!$C:$C, "D. 20-39") -> 263600.45 | N8: =IFERROR((M8-L8)/ABS(L8),"") -> -0.000939517 | O8: =SUMIFS('Raw Data'!$F:$F, 'Raw Data'!$B:$B, "Control", 'Raw Data'!$C:$C, "E. 40-99") -> 222590.87 | P8: =SUMIFS('Raw Data'!$F:$F, 'Raw Data'!$B:$B, "Variant", 'Raw Data'!$C:$C, "E. 40-99") -> 247929.7 | Q8: =IFERROR((P8-O8)/ABS(O8),"") -> 0.11383589 | R8: =SUMIFS('Raw Data'!$F:$F, 'Raw Data'!$B:$B, "Control", 'Raw Data'!$C:$C, "F. 100+") -> 42946.19 | S8: =SUMIFS('Raw Data'!$F:$F, 'Raw Data'!$B:$B, "Variant", 'Raw Data'!$C:$C, "F. 100+") -> 54761.93 | T8: =IFERROR((S8-R8)/ABS(R8),"") -> 0.27512895
B9: ARPDAU | C9: =IFERROR(SUMIFS('Raw Data'!$F:$F, 'Raw Data'!$B:$B, "Control", 'Raw Data'!$C:$C, "A. 0")/SUMIFS('Raw Data'!$D:$D, 'Raw Data'!$B:$B, "Control", 'Raw Data'!$C:$C, "A. 0"),"") -> 0.0051295176 | D9: =IFERROR(SUMIFS('Raw Data'!$F:$F, 'Raw Data'!$B:$B, "Variant", 'Raw Data'!$C:$C, "A. 0")/SUMIFS('Raw Data'!$D:$D, 'Raw Data'!$B:$B, "Variant", 'Raw Data'!$C:$C, "A. 0"),"") -> 0.0043436682 | E9: =IFERROR((D9-C9)/ABS(C9),"") -> -0.15320142 | F9: =IFERROR(SUMIFS('Raw Data'!$F:$F, 'Raw Data'!$B:$B, "Control", 'Raw Data'!$C:$C, "B. 1-9")/SUMIFS('Raw Data'!$D:$D, 'Raw Data'!$B:$B, "Control", 'Raw Data'!$C:$C, "B. 1-9"),"") -> 0.10477538 | G9: =IFERROR(SUMIFS('Raw Data'!$F:$F, 'Raw Data'!$B:$B, "Variant", 'Raw Data'!$C:$C, "B. 1-9")/SUMIFS('Raw Data'!$D:$D, 'Raw Data'!$B:$B, "Variant", 'Raw Data'!$C:$C, "B. 1-9"),"") -> 0.10699682 | H9: =IFERROR((G9-F9)/ABS(F9),"") -> 0.021201879 | I9: =IFERROR(SUMIFS('Raw Data'!$F:$F, 'Raw Data'!$B:$B, "Control", 'Raw Data'!$C:$C, "C. 10-19")/SUMIFS('Raw Data'!$D:$D, 'Raw Data'!$B:$B, "Control", 'Raw Data'!$C:$C, "C. 10-19"),"") -> 0.37815112 | J9: =IFERROR(SUMIFS('Raw Data'!$F:$F, 'Raw Data'!$B:$B, "Variant", 'Raw Data'!$C:$C, "C. 10-19")/SUMIFS('Raw Data'!$D:$D, 'Raw Data'!$B:$B, "Variant", 'Raw Data'!$C:$C, "C. 10-19"),"") -> 0.38181151 | K9: =IFERROR((J9-I9)/ABS(I9),"") -> 0.0096797083 | L9: =IFERROR(SUMIFS('Raw Data'!$F:$F, 'Raw Data'!$B:$B, "Control", 'Raw Data'!$C:$C, "D. 20-39")/SUMIFS('Raw Data'!$D:$D, 'Raw Data'!$B:$B, "Control", 'Raw Data'!$C:$C, "D. 20-39"),"") -> 0.87886754 | M9: =IFERROR(SUMIFS('Raw Data'!$F:$F, 'Raw Data'!$B:$B, "Variant", 'Raw Data'!$C:$C, "D. 20-39")/SUMIFS('Raw Data'!$D:$D, 'Raw Data'!$B:$B, "Variant", 'Raw Data'!$C:$C, "D. 20-39"),"") -> 0.85709508 | N9: =IFERROR((M9-L9)/ABS(L9),"") -> -0.02477331 | O9: =IFERROR(SUMIFS('Raw Data'!$F:$F, 'Raw Data'!$B:$B, "Control", 'Raw Data'!$C:$C, "E. 40-99")/SUMIFS('Raw Data'!$D:$D, 'Raw Data'!$B:$B, "Control", 'Raw Data'!$C:$C, "E. 40-99"),"") -> 1.8569356 | P9: =IFERROR(SUMIFS('Raw Data'!$F:$F, 'Raw Data'!$B:$B, "Variant", 'Raw Data'!$C:$C, "E. 40-99")/SUMIFS('Raw Data'!$D:$D, 'Raw Data'!$B:$B, "Variant", 'Raw Data'!$C:$C, "E. 40-99"),"") -> 1.9354387 | Q9: =IFERROR((P9-O9)/ABS(O9),"") -> 0.04227563 | R9: =IFERROR(SUMIFS('Raw Data'!$F:$F, 'Raw Data'!$B:$B, "Control", 'Raw Data'!$C:$C, "F. 100+")/SUMIFS('Raw Data'!$D:$D, 'Raw Data'!$B:$B, "Control", 'Raw Data'!$C:$C, "F. 100+"),"") -> 3.2921571 | S9: =IFERROR(SUMIFS('Raw Data'!$F:$F, 'Raw Data'!$B:$B, "Variant", 'Raw Data'!$C:$C, "F. 100+")/SUMIFS('Raw Data'!$D:$D, 'Raw Data'!$B:$B, "Variant", 'Raw Data'!$C:$C, "F. 100+"),"") -> 3.7746023 | T9: =IFERROR((S9-R9)/ABS(R9),"") -> 0.14654378
B10: AVG Payer day (%) | C10: =IFERROR(SUMPRODUCT(('Raw Data'!$B$2:$B$9999="Control")*('Raw Data'!$C$2:$C$9999="A. 0")*'Raw Data'!$D$2:$D$9999*'Raw Data'!$H$2:$H$9999/100)/SUMIFS('Raw Data'!$D:$D, 'Raw Data'!$B:$B, "Control", 'Raw Data'!$C:$C, "A. 0")*100,"") -> 0.11219302 | D10: =IFERROR(SUMPRODUCT(('Raw Data'!$B$2:$B$9999="Variant")*('Raw Data'!$C$2:$C$9999="A. 0")*'Raw Data'!$D$2:$D$9999*'Raw Data'!$H$2:$H$9999/100)/SUMIFS('Raw Data'!$D:$D, 'Raw Data'!$B:$B, "Variant", 'Raw Data'!$C:$C, "A. 0")*100,"") -> 0.11193099 | E10: =IFERROR((D10-C10)/ABS(C10),"") -> -0.0023354597 | F10: =IFERROR(SUMPRODUCT(('Raw Data'!$B$2:$B$9999="Control")*('Raw Data'!$C$2:$C$9999="B. 1-9")*'Raw Data'!$D$2:$D$9999*'Raw Data'!$H$2:$H$9999/100)/SUMIFS('Raw Data'!$D:$D, 'Raw Data'!$B:$B, "Control", 'Raw Data'!$C:$C, "B. 1-9")*100,"") -> 3.1001404 | G10: =IFERROR(SUMPRODUCT(('Raw Data'!$B$2:$B$9999="Variant")*('Raw Data'!$C$2:$C$9999="B. 1-9")*'Raw Data'!$D$2:$D$9999*'Raw Data'!$H$2:$H$9999/100)/SUMIFS('Raw Data'!$D:$D, 'Raw Data'!$B:$B, "Variant", 'Raw Data'!$C:$C, "B. 1-9")*100,"") -> 3.2123059 | H10: =IFERROR((G10-F10)/ABS(F10),"") -> 0.036180782 | I10: =IFERROR(SUMPRODUCT(('Raw Data'!$B$2:$B$9999="Control")*('Raw Data'!$C$2:$C$9999="C. 10-19")*'Raw Data'!$D$2:$D$9999*'Raw Data'!$H$2:$H$9999/100)/SUMIFS('Raw Data'!$D:$D, 'Raw Data'!$B:$B, "Control", 'Raw Data'!$C:$C, "C. 10-19")*100,"") -> 8.1126463 | J10: =IFERROR(SUMPRODUCT(('Raw Data'!$B$2:$B$9999="Variant")*('Raw Data'!$C$2:$C$9999="C. 10-19")*'Raw Data'!$D$2:$D$9999*'Raw Data'!$H$2:$H$9999/100)/SUMIFS('Raw Data'!$D:$D, 'Raw Data'!$B:$B, "Variant", 'Raw Data'!$C:$C, "C. 10-19")*100,"") -> 8.1286187 | K10: =IFERROR((J10-I10)/ABS(I10),"") -> 0.0019688259 | L10: =IFERROR(SUMPRODUCT(('Raw Data'!$B$2:$B$9999="Control")*('Raw Data'!$C$2:$C$9999="D. 20-39")*'Raw Data'!$D$2:$D$9999*'Raw Data'!$H$2:$H$9999/100)/SUMIFS('Raw Data'!$D:$D, 'Raw Data'!$B:$B, "Control", 'Raw Data'!$C:$C, "D. 20-39")*100,"") -> 11.95899 | M10: =IFERROR(SUMPRODUCT(('Raw Data'!$B$2:$B$9999="Variant")*('Raw Data'!$C$2:$C$9999="D. 20-39")*'Raw Data'!$D$2:$D$9999*'Raw Data'!$H$2:$H$9999/100)/SUMIFS('Raw Data'!$D:$D, 'Raw Data'!$B:$B, "Variant", 'Raw Data'!$C:$C, "D. 20-39")*100,"") -> 11.909557 | N10: =IFERROR((M10-L10)/ABS(L10),"") -> -0.0041335681 | O10: =IFERROR(SUMPRODUCT(('Raw Data'!$B$2:$B$9999="Control")*('Raw Data'!$C$2:$C$9999="E. 40-99")*'Raw Data'!$D$2:$D$9999*'Raw Data'!$H$2:$H$9999/100)/SUMIFS('Raw Data'!$D:$D, 'Raw Data'!$B:$B, "Control", 'Raw Data'!$C:$C, "E. 40-99")*100,"") -> 15.082809 | P10: =IFERROR(SUMPRODUCT(('Raw Data'!$B$2:$B$9999="Variant")*('Raw Data'!$C$2:$C$9999="E. 40-99")*'Raw Data'!$D$2:$D$9999*'Raw Data'!$H$2:$H$9999/100)/SUMIFS('Raw Data'!$D:$D, 'Raw Data'!$B:$B, "Variant", 'Raw Data'!$C:$C, "E. 40-99")*100,"") -> 15.042847 | Q10: =IFERROR((P10-O10)/ABS(O10),"") -> -0.0026495683 | R10: =IFERROR(SUMPRODUCT(('Raw Data'!$B$2:$B$9999="Control")*('Raw Data'!$C$2:$C$9999="F. 100+")*'Raw Data'!$D$2:$D$9999*'Raw Data'!$H$2:$H$9999/100)/SUMIFS('Raw Data'!$D:$D, 'Raw Data'!$B:$B, "Control", 'Raw Data'!$C:$C, "F. 100+")*100,"") -> 15.799055 | S10: =IFERROR(SUMPRODUCT(('Raw Data'!$B$2:$B$9999="Variant")*('Raw Data'!$C$2:$C$9999="F. 100+")*'Raw Data'!$D$2:$D$9999*'Raw Data'!$H$2:$H$9999/100)/SUMIFS('Raw Data'!$D:$D, 'Raw Data'!$B:$B, "Variant", 'Raw Data'!$C:$C, "F. 100+")*100,"") -> 16.984116 | T10: =IFERROR((S10-R10)/ABS(R10),"") -> 0.075008338
B11: ARPPU | C11: =IFERROR(SUMIFS('Raw Data'!$F:$F, 'Raw Data'!$B:$B, "Control", 'Raw Data'!$C:$C, "A. 0")/SUMPRODUCT(('Raw Data'!$B$2:$B$9999="Control")*('Raw Data'!$C$2:$C$9999="A. 0")*'Raw Data'!$D$2:$D$9999*'Raw Data'!$H$2:$H$9999/100),"") -> 4.5720472 | D11: =IFERROR(SUMIFS('Raw Data'!$F:$F, 'Raw Data'!$B:$B, "Variant", 'Raw Data'!$C:$C, "A. 0")/SUMPRODUCT(('Raw Data'!$B$2:$B$9999="Variant")*('Raw Data'!$C$2:$C$9999="A. 0")*'Raw Data'!$D$2:$D$9999*'Raw Data'!$H$2:$H$9999/100),"") -> 3.8806662 | E11: =IFERROR((D11-C11)/ABS(C11),"") -> -0.15121912 | F11: =IFERROR(SUMIFS('Raw Data'!$F:$F, 'Raw Data'!$B:$B, "Control", 'Raw Data'!$C:$C, "B. 1-9")/SUMPRODUCT(('Raw Data'!$B$2:$B$9999="Control")*('Raw Data'!$C$2:$C$9999="B. 1-9")*'Raw Data'!$D$2:$D$9999*'Raw Data'!$H$2:$H$9999/100),"") -> 3.379698 | G11: =IFERROR(SUMIFS('Raw Data'!$F:$F, 'Raw Data'!$B:$B, "Variant", 'Raw Data'!$C:$C, "B. 1-9")/SUMPRODUCT(('Raw Data'!$B$2:$B$9999="Variant")*('Raw Data'!$C$2:$C$9999="B. 1-9")*'Raw Data'!$D$2:$D$9999*'Raw Data'!$H$2:$H$9999/100),"") -> 3.3308415 | H11: =IFERROR((G11-F11)/ABS(F11),"") -> -0.014455878 | I11: =IFERROR(SUMIFS('Raw Data'!$F:$F, 'Raw Data'!$B:$B, "Control", 'Raw Data'!$C:$C, "C. 10-19")/SUMPRODUCT(('Raw Data'!$B$2:$B$9999="Control")*('Raw Data'!$C$2:$C$9999="C. 10-19")*'Raw Data'!$D$2:$D$9999*'Raw Data'!$H$2:$H$9999/100),"") -> 4.6612548 | J11: =IFERROR(SUMIFS('Raw Data'!$F:$F, 'Raw Data'!$B:$B, "Variant", 'Raw Data'!$C:$C, "C. 10-19")/SUMPRODUCT(('Raw Data'!$B$2:$B$9999="Variant")*('Raw Data'!$C$2:$C$9999="C. 10-19")*'Raw Data'!$D$2:$D$9999*'Raw Data'!$H$2:$H$9999/100),"") -> 4.6971266 | K11: =IFERROR((J11-I11)/ABS(I11),"") -> 0.0076957309 | L11: =IFERROR(SUMIFS('Raw Data'!$F:$F, 'Raw Data'!$B:$B, "Control", 'Raw Data'!$C:$C, "D. 20-39")/SUMPRODUCT(('Raw Data'!$B$2:$B$9999="Control")*('Raw Data'!$C$2:$C$9999="D. 20-39")*'Raw Data'!$D$2:$D$9999*'Raw Data'!$H$2:$H$9999/100),"") -> 7.3490113 | M11: =IFERROR(SUMIFS('Raw Data'!$F:$F, 'Raw Data'!$B:$B, "Variant", 'Raw Data'!$C:$C, "D. 20-39")/SUMPRODUCT(('Raw Data'!$B$2:$B$9999="Variant")*('Raw Data'!$C$2:$C$9999="D. 20-39")*'Raw Data'!$D$2:$D$9999*'Raw Data'!$H$2:$H$9999/100),"") -> 7.1967 | N11: =IFERROR((M11-L11)/ABS(L11),"") -> -0.020725411 | O11: =IFERROR(SUMIFS('Raw Data'!$F:$F, 'Raw Data'!$B:$B, "Control", 'Raw Data'!$C:$C, "E. 40-99")/SUMPRODUCT(('Raw Data'!$B$2:$B$9999="Control")*('Raw Data'!$C$2:$C$9999="E. 40-99")*'Raw Data'!$D$2:$D$9999*'Raw Data'!$H$2:$H$9999/100),"") -> 12.311603 | P11: =IFERROR(SUMIFS('Raw Data'!$F:$F, 'Raw Data'!$B:$B, "Variant", 'Raw Data'!$C:$C, "E. 40-99")/SUMPRODUCT(('Raw Data'!$B$2:$B$9999="Variant")*('Raw Data'!$C$2:$C$9999="E. 40-99")*'Raw Data'!$D$2:$D$9999*'Raw Data'!$H$2:$H$9999/100),"") -> 12.866173 | Q11: =IFERROR((P11-O11)/ABS(O11),"") -> 0.045044547 | R11: =IFERROR(SUMIFS('Raw Data'!$F:$F, 'Raw Data'!$B:$B, "Control", 'Raw Data'!$C:$C, "F. 100+")/SUMPRODUCT(('Raw Data'!$B$2:$B$9999="Control")*('Raw Data'!$C$2:$C$9999="F. 100+")*'Raw Data'!$D$2:$D$9999*'Raw Data'!$H$2:$H$9999/100),"") -> 20.837684 | S11: =IFERROR(SUMIFS('Raw Data'!$F:$F, 'Raw Data'!$B:$B, "Variant", 'Raw Data'!$C:$C, "F. 100+")/SUMPRODUCT(('Raw Data'!$B$2:$B$9999="Variant")*('Raw Data'!$C$2:$C$9999="F. 100+")*'Raw Data'!$D$2:$D$9999*'Raw Data'!$H$2:$H$9999/100),"") -> 22.224309 | T11: =IFERROR((S11-R11)/ABS(R11),"") -> 0.066544077
A12: Engagement
B13: Time spent (mins) | C13: =IFERROR(SUMPRODUCT(('Raw Data'!$B$2:$B$9999="Control")*('Raw Data'!$C$2:$C$9999="A. 0")*'Raw Data'!$D$2:$D$9999*'Raw Data'!$J$2:$J$9999)/SUMIFS('Raw Data'!$D:$D, 'Raw Data'!$B:$B, "Control", 'Raw Data'!$C:$C, "A. 0"),"") -> 6.4304274 | D13: =IFERROR(SUMPRODUCT(('Raw Data'!$B$2:$B$9999="Variant")*('Raw Data'!$C$2:$C$9999="A. 0")*'Raw Data'!$D$2:$D$9999*'Raw Data'!$J$2:$J$9999)/SUMIFS('Raw Data'!$D:$D, 'Raw Data'!$B:$B, "Variant", 'Raw Data'!$C:$C, "A. 0"),"") -> 6.5687264 | E13: =IFERROR((D13-C13)/ABS(C13),"") -> 0.021506967 | F13: =IFERROR(SUMPRODUCT(('Raw Data'!$B$2:$B$9999="Control")*('Raw Data'!$C$2:$C$9999="B. 1-9")*'Raw Data'!$D$2:$D$9999*'Raw Data'!$J$2:$J$9999)/SUMIFS('Raw Data'!$D:$D, 'Raw Data'!$B:$B, "Control", 'Raw Data'!$C:$C, "B. 1-9"),"") -> 31.745879 | G13: =IFERROR(SUMPRODUCT(('Raw Data'!$B$2:$B$9999="Variant")*('Raw Data'!$C$2:$C$9999="B. 1-9")*'Raw Data'!$D$2:$D$9999*'Raw Data'!$J$2:$J$9999)/SUMIFS('Raw Data'!$D:$D, 'Raw Data'!$B:$B, "Variant", 'Raw Data'!$C:$C, "B. 1-9"),"") -> 32.633704 | H13: =IFERROR((G13-F13)/ABS(F13),"") -> 0.02796664 | I13: =IFERROR(SUMPRODUCT(('Raw Data'!$B$2:$B$9999="Control")*('Raw Data'!$C$2:$C$9999="C. 10-19")*'Raw Data'!$D$2:$D$9999*'Raw Data'!$J$2:$J$9999)/SUMIFS('Raw Data'!$D:$D, 'Raw Data'!$B:$B, "Control", 'Raw Data'!$C:$C, "C. 10-19"),"") -> 57.822319 | J13: =IFERROR(SUMPRODUCT(('Raw Data'!$B$2:$B$9999="Variant")*('Raw Data'!$C$2:$C$9999="C. 10-19")*'Raw Data'!$D$2:$D$9999*'Raw Data'!$J$2:$J$9999)/SUMIFS('Raw Data'!$D:$D, 'Raw Data'!$B:$B, "Variant", 'Raw Data'!$C:$C, "C. 10-19"),"") -> 59.497589 | K13: =IFERROR((J13-I13)/ABS(I13),"") -> 0.028972733 | L13: =IFERROR(SUMPRODUCT(('Raw Data'!$B$2:$B$9999="Control")*('Raw Data'!$C$2:$C$9999="D. 20-39")*'Raw Data'!$D$2:$D$9999*'Raw Data'!$J$2:$J$9999)/SUMIFS('Raw Data'!$D:$D, 'Raw Data'!$B:$B, "Control", 'Raw Data'!$C:$C, "D. 20-39"),"") -> 83.011584 | M13: =IFERROR(SUMPRODUCT(('Raw Data'!$B$2:$B$9999="Variant")*('Raw Data'!$C$2:$C$9999="D. 20-39")*'Raw Data'!$D$2:$D$9999*'Raw Data'!$J$2:$J$9999)/SUMIFS('Raw Data'!$D:$D, 'Raw Data'!$B:$B, "Variant", 'Raw Data'!$C:$C, "D. 20-39"),"") -> 84.757425 | N13: =IFERROR((M13-L13)/ABS(L13),"") -> 0.021031297 | O13: =IFERROR(SUMPRODUCT(('Raw Data'!$B$2:$B$9999="Control")*('Raw Data'!$C$2:$C$9999="E. 40-99")*'Raw Data'!$D$2:$D$9999*'Raw Data'!$J$2:$J$9999)/SUMIFS('Raw Data'!$D:$D, 'Raw Data'!$B:$B, "Control", 'Raw Data'!$C:$C, "E. 40-99"),"") -> 130.83582 | P13: =IFERROR(SUMPRODUCT(('Raw Data'!$B$2:$B$9999="Variant")*('Raw Data'!$C$2:$C$9999="E. 40-99")*'Raw Data'!$D$2:$D$9999*'Raw Data'!$J$2:$J$9999)/SUMIFS('Raw Data'!$D:$D, 'Raw Data'!$B:$B, "Variant", 'Raw Data'!$C:$C, "E. 40-99"),"") -> 132.90854 | Q13: =IFERROR((P13-O13)/ABS(O13),"") -> 0.015842113 | R13: =IFERROR(SUMPRODUCT(('Raw Data'!$B$2:$B$9999="Control")*('Raw Data'!$C$2:$C$9999="F. 100+")*'Raw Data'!$D$2:$D$9999*'Raw Data'!$J$2:$J$9999)/SUMIFS('Raw Data'!$D:$D, 'Raw Data'!$B:$B, "Control", 'Raw Data'!$C:$C, "F. 100+"),"") -> 243.4056 | S13: =IFERROR(SUMPRODUCT(('Raw Data'!$B$2:$B$9999="Variant")*('Raw Data'!$C$2:$C$9999="F. 100+")*'Raw Data'!$D$2:$D$9999*'Raw Data'!$J$2:$J$9999)/SUMIFS('Raw Data'!$D:$D, 'Raw Data'!$B:$B, "Variant", 'Raw Data'!$C:$C, "F. 100+"),"") -> 248.62782 | T13: =IFERROR((S13-R13)/ABS(R13),"") -> 0.021454791
B14: Level attempts / player | C14: =IFERROR(SUMPRODUCT(('Raw Data'!$B$2:$B$9999="Control")*('Raw Data'!$C$2:$C$9999="A. 0")*'Raw Data'!$D$2:$D$9999*'Raw Data'!$K$2:$K$9999)/SUMIFS('Raw Data'!$D:$D, 'Raw Data'!$B:$B, "Control", 'Raw Data'!$C:$C, "A. 0"),"") -> 2.7258533 | D14: =IFERROR(SUMPRODUCT(('Raw Data'!$B$2:$B$9999="Variant")*('Raw Data'!$C$2:$C$9999="A. 0")*'Raw Data'!$D$2:$D$9999*'Raw Data'!$K$2:$K$9999)/SUMIFS('Raw Data'!$D:$D, 'Raw Data'!$B:$B, "Variant", 'Raw Data'!$C:$C, "A. 0"),"") -> 2.8131201 | E14: =IFERROR((D14-C14)/ABS(C14),"") -> 0.032014505 | F14: =IFERROR(SUMPRODUCT(('Raw Data'!$B$2:$B$9999="Control")*('Raw Data'!$C$2:$C$9999="B. 1-9")*'Raw Data'!$D$2:$D$9999*'Raw Data'!$K$2:$K$9999)/SUMIFS('Raw Data'!$D:$D, 'Raw Data'!$B:$B, "Control", 'Raw Data'!$C:$C, "B. 1-9"),"") -> 15.657149 | G14: =IFERROR(SUMPRODUCT(('Raw Data'!$B$2:$B$9999="Variant")*('Raw Data'!$C$2:$C$9999="B. 1-9")*'Raw Data'!$D$2:$D$9999*'Raw Data'!$K$2:$K$9999)/SUMIFS('Raw Data'!$D:$D, 'Raw Data'!$B:$B, "Variant", 'Raw Data'!$C:$C, "B. 1-9"),"") -> 16.042561 | H14: =IFERROR((G14-F14)/ABS(F14),"") -> 0.024615714 | I14: =IFERROR(SUMPRODUCT(('Raw Data'!$B$2:$B$9999="Control")*('Raw Data'!$C$2:$C$9999="C. 10-19")*'Raw Data'!$D$2:$D$9999*'Raw Data'!$K$2:$K$9999)/SUMIFS('Raw Data'!$D:$D, 'Raw Data'!$B:$B, "Control", 'Raw Data'!$C:$C, "C. 10-19"),"") -> 29.56553 | J14: =IFERROR(SUMPRODUCT(('Raw Data'!$B$2:$B$9999="Variant")*('Raw Data'!$C$2:$C$9999="C. 10-19")*'Raw Data'!$D$2:$D$9999*'Raw Data'!$K$2:$K$9999)/SUMIFS('Raw Data'!$D:$D, 'Raw Data'!$B:$B, "Variant", 'Raw Data'!$C:$C, "C. 10-19"),"") -> 30.442178 | K14: =IFERROR((J14-I14)/ABS(I14),"") -> 0.029651007 | L14: =IFERROR(SUMPRODUCT(('Raw Data'!$B$2:$B$9999="Control")*('Raw Data'!$C$2:$C$9999="D. 20-39")*'Raw Data'!$D$2:$D$9999*'Raw Data'!$K$2:$K$9999)/SUMIFS('Raw Data'!$D:$D, 'Raw Data'!$B:$B, "Control", 'Raw Data'!$C:$C, "D. 20-39"),"") -> 44.615331 | M14: =IFERROR(SUMPRODUCT(('Raw Data'!$B$2:$B$9999="Variant")*('Raw Data'!$C$2:$C$9999="D. 20-39")*'Raw Data'!$D$2:$D$9999*'Raw Data'!$K$2:$K$9999)/SUMIFS('Raw Data'!$D:$D, 'Raw Data'!$B:$B, "Variant", 'Raw Data'!$C:$C, "D. 20-39"),"") -> 45.510224 | N14: =IFERROR((M14-L14)/ABS(L14),"") -> 0.02005797 | O14: =IFERROR(SUMPRODUCT(('Raw Data'!$B$2:$B$9999="Control")*('Raw Data'!$C$2:$C$9999="E. 40-99")*'Raw Data'!$D$2:$D$9999*'Raw Data'!$K$2:$K$9999)/SUMIFS('Raw Data'!$D:$D, 'Raw Data'!$B:$B, "Control", 'Raw Data'!$C:$C, "E. 40-99"),"") -> 74.561666 | P14: =IFERROR(SUMPRODUCT(('Raw Data'!$B$2:$B$9999="Variant")*('Raw Data'!$C$2:$C$9999="E. 40-99")*'Raw Data'!$D$2:$D$9999*'Raw Data'!$K$2:$K$9999)/SUMIFS('Raw Data'!$D:$D, 'Raw Data'!$B:$B, "Variant", 'Raw Data'!$C:$C, "E. 40-99"),"") -> 75.536948 | Q14: =IFERROR((P14-O14)/ABS(O14),"") -> 0.013080207 | R14: =IFERROR(SUMPRODUCT(('Raw Data'!$B$2:$B$9999="Control")*('Raw Data'!$C$2:$C$9999="F. 100+")*'Raw Data'!$D$2:$D$9999*'Raw Data'!$K$2:$K$9999)/SUMIFS('Raw Data'!$D:$D, 'Raw Data'!$B:$B, "Control", 'Raw Data'!$C:$C, "F. 100+"),"") -> 149.75455 | S14: =IFERROR(SUMPRODUCT(('Raw Data'!$B$2:$B$9999="Variant")*('Raw Data'!$C$2:$C$9999="F. 100+")*'Raw Data'!$D$2:$D$9999*'Raw Data'!$K$2:$K$9999)/SUMIFS('Raw Data'!$D:$D, 'Raw Data'!$B:$B, "Variant", 'Raw Data'!$C:$C, "F. 100+"),"") -> 149.93435 | T14: =IFERROR((S14-R14)/ABS(R14),"") -> 0.0012006876
B15: Level completes / player | C15: =IFERROR(SUMPRODUCT(('Raw Data'!$B$2:$B$9999="Control")*('Raw Data'!$C$2:$C$9999="A. 0")*'Raw Data'!$D$2:$D$9999*'Raw Data'!$L$2:$L$9999)/SUMIFS('Raw Data'!$D:$D, 'Raw Data'!$B:$B, "Control", 'Raw Data'!$C:$C, "A. 0"),"") -> 0.058897839 | D15: =IFERROR(SUMPRODUCT(('Raw Data'!$B$2:$B$9999="Variant")*('Raw Data'!$C$2:$C$9999="A. 0")*'Raw Data'!$D$2:$D$9999*'Raw Data'!$L$2:$L$9999)/SUMIFS('Raw Data'!$D:$D, 'Raw Data'!$B:$B, "Variant", 'Raw Data'!$C:$C, "A. 0"),"") -> 0.063852341 | E15: =IFERROR((D15-C15)/ABS(C15),"") -> 0.08412027 | F15: =IFERROR(SUMPRODUCT(('Raw Data'!$B$2:$B$9999="Control")*('Raw Data'!$C$2:$C$9999="B. 1-9")*'Raw Data'!$D$2:$D$9999*'Raw Data'!$L$2:$L$9999)/SUMIFS('Raw Data'!$D:$D, 'Raw Data'!$B:$B, "Control", 'Raw Data'!$C:$C, "B. 1-9"),"") -> 5.5878982 | G15: =IFERROR(SUMPRODUCT(('Raw Data'!$B$2:$B$9999="Variant")*('Raw Data'!$C$2:$C$9999="B. 1-9")*'Raw Data'!$D$2:$D$9999*'Raw Data'!$L$2:$L$9999)/SUMIFS('Raw Data'!$D:$D, 'Raw Data'!$B:$B, "Variant", 'Raw Data'!$C:$C, "B. 1-9"),"") -> 5.6042368 | H15: =IFERROR((G15-F15)/ABS(F15),"") -> 0.0029239101 | I15: =IFERROR(SUMPRODUCT(('Raw Data'!$B$2:$B$9999="Control")*('Raw Data'!$C$2:$C$9999="C. 10-19")*'Raw Data'!$D$2:$D$9999*'Raw Data'!$L$2:$L$9999)/SUMIFS('Raw Data'!$D:$D, 'Raw Data'!$B:$B, "Control", 'Raw Data'!$C:$C, "C. 10-19"),"") -> 14.432736 | J15: =IFERROR(SUMPRODUCT(('Raw Data'!$B$2:$B$9999="Variant")*('Raw Data'!$C$2:$C$9999="C. 10-19")*'Raw Data'!$D$2:$D$9999*'Raw Data'!$L$2:$L$9999)/SUMIFS('Raw Data'!$D:$D, 'Raw Data'!$B:$B, "Variant", 'Raw Data'!$C:$C, "C. 10-19"),"") -> 14.515333 | K15: =IFERROR((J15-I15)/ABS(I15),"") -> 0.0057228689 | L15: =IFERROR(SUMPRODUCT(('Raw Data'!$B$2:$B$9999="Control")*('Raw Data'!$C$2:$C$9999="D. 20-39")*'Raw Data'!$D$2:$D$9999*'Raw Data'!$L$2:$L$9999)/SUMIFS('Raw Data'!$D:$D, 'Raw Data'!$B:$B, "Control", 'Raw Data'!$C:$C, "D. 20-39"),"") -> 27.734219 | M15: =IFERROR(SUMPRODUCT(('Raw Data'!$B$2:$B$9999="Variant")*('Raw Data'!$C$2:$C$9999="D. 20-39")*'Raw Data'!$D$2:$D$9999*'Raw Data'!$L$2:$L$9999)/SUMIFS('Raw Data'!$D:$D, 'Raw Data'!$B:$B, "Variant", 'Raw Data'!$C:$C, "D. 20-39"),"") -> 28.083718 | N15: =IFERROR((M15-L15)/ABS(L15),"") -> 0.012601738 | O15: =IFERROR(SUMPRODUCT(('Raw Data'!$B$2:$B$9999="Control")*('Raw Data'!$C$2:$C$9999="E. 40-99")*'Raw Data'!$D$2:$D$9999*'Raw Data'!$L$2:$L$9999)/SUMIFS('Raw Data'!$D:$D, 'Raw Data'!$B:$B, "Control", 'Raw Data'!$C:$C, "E. 40-99"),"") -> 56.089138 | P15: =IFERROR(SUMPRODUCT(('Raw Data'!$B$2:$B$9999="Variant")*('Raw Data'!$C$2:$C$9999="E. 40-99")*'Raw Data'!$D$2:$D$9999*'Raw Data'!$L$2:$L$9999)/SUMIFS('Raw Data'!$D:$D, 'Raw Data'!$B:$B, "Variant", 'Raw Data'!$C:$C, "E. 40-99"),"") -> 56.906657 | Q15: =IFERROR((P15-O15)/ABS(O15),"") -> 0.014575351 | R15: =IFERROR(SUMPRODUCT(('Raw Data'!$B$2:$B$9999="Control")*('Raw Data'!$C$2:$C$9999="F. 100+")*'Raw Data'!$D$2:$D$9999*'Raw Data'!$L$2:$L$9999)/SUMIFS('Raw Data'!$D:$D, 'Raw Data'!$B:$B, "Control", 'Raw Data'!$C:$C, "F. 100+"),"") -> 126.95442 | S15: =IFERROR(SUMPRODUCT(('Raw Data'!$B$2:$B$9999="Variant")*('Raw Data'!$C$2:$C$9999="F. 100+")*'Raw Data'!$D$2:$D$9999*'Raw Data'!$L$2:$L$9999)/SUMIFS('Raw Data'!$D:$D, 'Raw Data'!$B:$B, "Variant", 'Raw Data'!$C:$C, "F. 100+"),"") -> 126.36774 | T15: =IFERROR((S15-R15)/ABS(R15),"") -> -0.0046211366
A16: Daily Streak
B17: Avg daily streak | C17: =IFERROR(SUMPRODUCT(('Raw Data'!$B$2:$B$9999="Control")*('Raw Data'!$C$2:$C$9999="A. 0")*'Raw Data'!$D$2:$D$9999*'Raw Data'!$AD$2:$AD$9999)/SUMIFS('Raw Data'!$D:$D, 'Raw Data'!$B:$B, "Control", 'Raw Data'!$C:$C, "A. 0"),"") -> 0 | D17: =IFERROR(SUMPRODUCT(('Raw Data'!$B$2:$B$9999="Variant")*('Raw Data'!$C$2:$C$9999="A. 0")*'Raw Data'!$D$2:$D$9999*'Raw Data'!$AD$2:$AD$9999)/SUMIFS('Raw Data'!$D:$D, 'Raw Data'!$B:$B, "Variant", 'Raw Data'!$C:$C, "A. 0"),"") -> 0 | E17: =IFERROR((D17-C17)/ABS(C17),"") | F17: =IFERROR(SUMPRODUCT(('Raw Data'!$B$2:$B$9999="Control")*('Raw Data'!$C$2:$C$9999="B. 1-9")*'Raw Data'!$D$2:$D$9999*'Raw Data'!$AD$2:$AD$9999)/SUMIFS('Raw Data'!$D:$D, 'Raw Data'!$B:$B, "Control", 'Raw Data'!$C:$C, "B. 1-9"),"") -> 3.850426 | G17: =IFERROR(SUMPRODUCT(('Raw Data'!$B$2:$B$9999="Variant")*('Raw Data'!$C$2:$C$9999="B. 1-9")*'Raw Data'!$D$2:$D$9999*'Raw Data'!$AD$2:$AD$9999)/SUMIFS('Raw Data'!$D:$D, 'Raw Data'!$B:$B, "Variant", 'Raw Data'!$C:$C, "B. 1-9"),"") -> 3.8362349 | H17: =IFERROR((G17-F17)/ABS(F17),"") -> -0.0036855847 | I17: =IFERROR(SUMPRODUCT(('Raw Data'!$B$2:$B$9999="Control")*('Raw Data'!$C$2:$C$9999="C. 10-19")*'Raw Data'!$D$2:$D$9999*'Raw Data'!$AD$2:$AD$9999)/SUMIFS('Raw Data'!$D:$D, 'Raw Data'!$B:$B, "Control", 'Raw Data'!$C:$C, "C. 10-19"),"") -> 9.3562958 | J17: =IFERROR(SUMPRODUCT(('Raw Data'!$B$2:$B$9999="Variant")*('Raw Data'!$C$2:$C$9999="C. 10-19")*'Raw Data'!$D$2:$D$9999*'Raw Data'!$AD$2:$AD$9999)/SUMIFS('Raw Data'!$D:$D, 'Raw Data'!$B:$B, "Variant", 'Raw Data'!$C:$C, "C. 10-19"),"") -> 9.3730652 | K17: =IFERROR((J17-I17)/ABS(I17),"") -> 0.0017923214 | L17: =IFERROR(SUMPRODUCT(('Raw Data'!$B$2:$B$9999="Control")*('Raw Data'!$C$2:$C$9999="D. 20-39")*'Raw Data'!$D$2:$D$9999*'Raw Data'!$AD$2:$AD$9999)/SUMIFS('Raw Data'!$D:$D, 'Raw Data'!$B:$B, "Control", 'Raw Data'!$C:$C, "D. 20-39"),"") -> 18.113888 | M17: =IFERROR(SUMPRODUCT(('Raw Data'!$B$2:$B$9999="Variant")*('Raw Data'!$C$2:$C$9999="D. 20-39")*'Raw Data'!$D$2:$D$9999*'Raw Data'!$AD$2:$AD$9999)/SUMIFS('Raw Data'!$D:$D, 'Raw Data'!$B:$B, "Variant", 'Raw Data'!$C:$C, "D. 20-39"),"") -> 18.3893 | N17: =IFERROR((M17-L17)/ABS(L17),"") -> 0.015204459 | O17: =IFERROR(SUMPRODUCT(('Raw Data'!$B$2:$B$9999="Control")*('Raw Data'!$C$2:$C$9999="E. 40-99")*'Raw Data'!$D$2:$D$9999*'Raw Data'!$AD$2:$AD$9999)/SUMIFS('Raw Data'!$D:$D, 'Raw Data'!$B:$B, "Control", 'Raw Data'!$C:$C, "E. 40-99"),"") -> 37.804735 | P17: =IFERROR(SUMPRODUCT(('Raw Data'!$B$2:$B$9999="Variant")*('Raw Data'!$C$2:$C$9999="E. 40-99")*'Raw Data'!$D$2:$D$9999*'Raw Data'!$AD$2:$AD$9999)/SUMIFS('Raw Data'!$D:$D, 'Raw Data'!$B:$B, "Variant", 'Raw Data'!$C:$C, "E. 40-99"),"") -> 39.027694 | Q17: =IFERROR((P17-O17)/ABS(O17),"") -> 0.032349371 | R17: =IFERROR(SUMPRODUCT(('Raw Data'!$B$2:$B$9999="Control")*('Raw Data'!$C$2:$C$9999="F. 100+")*'Raw Data'!$D$2:$D$9999*'Raw Data'!$AD$2:$AD$9999)/SUMIFS('Raw Data'!$D:$D, 'Raw Data'!$B:$B, "Control", 'Raw Data'!$C:$C, "F. 100+"),"") -> 88.190885 | S17: =IFERROR(SUMPRODUCT(('Raw Data'!$B$2:$B$9999="Variant")*('Raw Data'!$C$2:$C$9999="F. 100+")*'Raw Data'!$D$2:$D$9999*'Raw Data'!$AD$2:$AD$9999)/SUMIFS('Raw Data'!$D:$D, 'Raw Data'!$B:$B, "Variant", 'Raw Data'!$C:$C, "F. 100+"),"") -> 88.697662 | T17: =IFERROR((S17-R17)/ABS(R17),"") -> 0.0057463601
B18: P25 daily streak | C18: =IFERROR(SUMPRODUCT(('Raw Data'!$B$2:$B$9999="Control")*('Raw Data'!$C$2:$C$9999="A. 0")*'Raw Data'!$D$2:$D$9999*'Raw Data'!$AE$2:$AE$9999)/SUMIFS('Raw Data'!$D:$D, 'Raw Data'!$B:$B, "Control", 'Raw Data'!$C:$C, "A. 0"),"") -> 0 | D18: =IFERROR(SUMPRODUCT(('Raw Data'!$B$2:$B$9999="Variant")*('Raw Data'!$C$2:$C$9999="A. 0")*'Raw Data'!$D$2:$D$9999*'Raw Data'!$AE$2:$AE$9999)/SUMIFS('Raw Data'!$D:$D, 'Raw Data'!$B:$B, "Variant", 'Raw Data'!$C:$C, "A. 0"),"") -> 0 | E18: =IFERROR((D18-C18)/ABS(C18),"") | F18: =IFERROR(SUMPRODUCT(('Raw Data'!$B$2:$B$9999="Control")*('Raw Data'!$C$2:$C$9999="B. 1-9")*'Raw Data'!$D$2:$D$9999*'Raw Data'!$AE$2:$AE$9999)/SUMIFS('Raw Data'!$D:$D, 'Raw Data'!$B:$B, "Control", 'Raw Data'!$C:$C, "B. 1-9"),"") -> 1 | G18: =IFERROR(SUMPRODUCT(('Raw Data'!$B$2:$B$9999="Variant")*('Raw Data'!$C$2:$C$9999="B. 1-9")*'Raw Data'!$D$2:$D$9999*'Raw Data'!$AE$2:$AE$9999)/SUMIFS('Raw Data'!$D:$D, 'Raw Data'!$B:$B, "Variant", 'Raw Data'!$C:$C, "B. 1-9"),"") -> 1 | H18: =IFERROR((G18-F18)/ABS(F18),"") -> 0 | I18: =IFERROR(SUMPRODUCT(('Raw Data'!$B$2:$B$9999="Control")*('Raw Data'!$C$2:$C$9999="C. 10-19")*'Raw Data'!$D$2:$D$9999*'Raw Data'!$AE$2:$AE$9999)/SUMIFS('Raw Data'!$D:$D, 'Raw Data'!$B:$B, "Control", 'Raw Data'!$C:$C, "C. 10-19"),"") -> 3.1056083 | J18: =IFERROR(SUMPRODUCT(('Raw Data'!$B$2:$B$9999="Variant")*('Raw Data'!$C$2:$C$9999="C. 10-19")*'Raw Data'!$D$2:$D$9999*'Raw Data'!$AE$2:$AE$9999)/SUMIFS('Raw Data'!$D:$D, 'Raw Data'!$B:$B, "Variant", 'Raw Data'!$C:$C, "C. 10-19"),"") -> 3.0707976 | K18: =IFERROR((J18-I18)/ABS(I18),"") -> -0.011208996 | L18: =IFERROR(SUMPRODUCT(('Raw Data'!$B$2:$B$9999="Control")*('Raw Data'!$C$2:$C$9999="D. 20-39")*'Raw Data'!$D$2:$D$9999*'Raw Data'!$AE$2:$AE$9999)/SUMIFS('Raw Data'!$D:$D, 'Raw Data'!$B:$B, "Control", 'Raw Data'!$C:$C, "D. 20-39"),"") -> 6.9494927 | M18: =IFERROR(SUMPRODUCT(('Raw Data'!$B$2:$B$9999="Variant")*('Raw Data'!$C$2:$C$9999="D. 20-39")*'Raw Data'!$D$2:$D$9999*'Raw Data'!$AE$2:$AE$9999)/SUMIFS('Raw Data'!$D:$D, 'Raw Data'!$B:$B, "Variant", 'Raw Data'!$C:$C, "D. 20-39"),"") -> 6.7502983 | N18: =IFERROR((M18-L18)/ABS(L18),"") -> -0.028663153 | O18: =IFERROR(SUMPRODUCT(('Raw Data'!$B$2:$B$9999="Control")*('Raw Data'!$C$2:$C$9999="E. 40-99")*'Raw Data'!$D$2:$D$9999*'Raw Data'!$AE$2:$AE$9999)/SUMIFS('Raw Data'!$D:$D, 'Raw Data'!$B:$B, "Control", 'Raw Data'!$C:$C, "E. 40-99"),"") -> 14.681538 | P18: =IFERROR(SUMPRODUCT(('Raw Data'!$B$2:$B$9999="Variant")*('Raw Data'!$C$2:$C$9999="E. 40-99")*'Raw Data'!$D$2:$D$9999*'Raw Data'!$AE$2:$AE$9999)/SUMIFS('Raw Data'!$D:$D, 'Raw Data'!$B:$B, "Variant", 'Raw Data'!$C:$C, "E. 40-99"),"") -> 15.012966 | Q18: =IFERROR((P18-O18)/ABS(O18),"") -> 0.02257448 | R18: =IFERROR(SUMPRODUCT(('Raw Data'!$B$2:$B$9999="Control")*('Raw Data'!$C$2:$C$9999="F. 100+")*'Raw Data'!$D$2:$D$9999*'Raw Data'!$AE$2:$AE$9999)/SUMIFS('Raw Data'!$D:$D, 'Raw Data'!$B:$B, "Control", 'Raw Data'!$C:$C, "F. 100+"),"") -> 35.22683 | S18: =IFERROR(SUMPRODUCT(('Raw Data'!$B$2:$B$9999="Variant")*('Raw Data'!$C$2:$C$9999="F. 100+")*'Raw Data'!$D$2:$D$9999*'Raw Data'!$AE$2:$AE$9999)/SUMIFS('Raw Data'!$D:$D, 'Raw Data'!$B:$B, "Variant", 'Raw Data'!$C:$C, "F. 100+"),"") -> 35.481734 | T18: =IFERROR((S18-R18)/ABS(R18),"") -> 0.0072360758
B19: P50 daily streak | C19: =IFERROR(SUMPRODUCT(('Raw Data'!$B$2:$B$9999="Control")*('Raw Data'!$C$2:$C$9999="A. 0")*'Raw Data'!$D$2:$D$9999*'Raw Data'!$AF$2:$AF$9999)/SUMIFS('Raw Data'!$D:$D, 'Raw Data'!$B:$B, "Control", 'Raw Data'!$C:$C, "A. 0"),"") -> 0 | D19: =IFERROR(SUMPRODUCT(('Raw Data'!$B$2:$B$9999="Variant")*('Raw Data'!$C$2:$C$9999="A. 0")*'Raw Data'!$D$2:$D$9999*'Raw Data'!$AF$2:$AF$9999)/SUMIFS('Raw Data'!$D:$D, 'Raw Data'!$B:$B, "Variant", 'Raw Data'!$C:$C, "A. 0"),"") -> 0 | E19: =IFERROR((D19-C19)/ABS(C19),"") | F19: =IFERROR(SUMPRODUCT(('Raw Data'!$B$2:$B$9999="Control")*('Raw Data'!$C$2:$C$9999="B. 1-9")*'Raw Data'!$D$2:$D$9999*'Raw Data'!$AF$2:$AF$9999)/SUMIFS('Raw Data'!$D:$D, 'Raw Data'!$B:$B, "Control", 'Raw Data'!$C:$C, "B. 1-9"),"") -> 2.1389519 | G19: =IFERROR(SUMPRODUCT(('Raw Data'!$B$2:$B$9999="Variant")*('Raw Data'!$C$2:$C$9999="B. 1-9")*'Raw Data'!$D$2:$D$9999*'Raw Data'!$AF$2:$AF$9999)/SUMIFS('Raw Data'!$D:$D, 'Raw Data'!$B:$B, "Variant", 'Raw Data'!$C:$C, "B. 1-9"),"") -> 2.1388837 | H19: =IFERROR((G19-F19)/ABS(F19),"") -> -3.189077e-05 | I19: =IFERROR(SUMPRODUCT(('Raw Data'!$B$2:$B$9999="Control")*('Raw Data'!$C$2:$C$9999="C. 10-19")*'Raw Data'!$D$2:$D$9999*'Raw Data'!$AF$2:$AF$9999)/SUMIFS('Raw Data'!$D:$D, 'Raw Data'!$B:$B, "Control", 'Raw Data'!$C:$C, "C. 10-19"),"") -> 7.1445742 | J19: =IFERROR(SUMPRODUCT(('Raw Data'!$B$2:$B$9999="Variant")*('Raw Data'!$C$2:$C$9999="C. 10-19")*'Raw Data'!$D$2:$D$9999*'Raw Data'!$AF$2:$AF$9999)/SUMIFS('Raw Data'!$D:$D, 'Raw Data'!$B:$B, "Variant", 'Raw Data'!$C:$C, "C. 10-19"),"") -> 6.9668431 | K19: =IFERROR((J19-I19)/ABS(I19),"") -> -0.024876376 | L19: =IFERROR(SUMPRODUCT(('Raw Data'!$B$2:$B$9999="Control")*('Raw Data'!$C$2:$C$9999="D. 20-39")*'Raw Data'!$D$2:$D$9999*'Raw Data'!$AF$2:$AF$9999)/SUMIFS('Raw Data'!$D:$D, 'Raw Data'!$B:$B, "Control", 'Raw Data'!$C:$C, "D. 20-39"),"") -> 14.13997 | M19: =IFERROR(SUMPRODUCT(('Raw Data'!$B$2:$B$9999="Variant")*('Raw Data'!$C$2:$C$9999="D. 20-39")*'Raw Data'!$D$2:$D$9999*'Raw Data'!$AF$2:$AF$9999)/SUMIFS('Raw Data'!$D:$D, 'Raw Data'!$B:$B, "Variant", 'Raw Data'!$C:$C, "D. 20-39"),"") -> 14.178614 | N19: =IFERROR((M19-L19)/ABS(L19),"") -> 0.0027329707 | O19: =IFERROR(SUMPRODUCT(('Raw Data'!$B$2:$B$9999="Control")*('Raw Data'!$C$2:$C$9999="E. 40-99")*'Raw Data'!$D$2:$D$9999*'Raw Data'!$AF$2:$AF$9999)/SUMIFS('Raw Data'!$D:$D, 'Raw Data'!$B:$B, "Control", 'Raw Data'!$C:$C, "E. 40-99"),"") -> 29.820848 | P19: =IFERROR(SUMPRODUCT(('Raw Data'!$B$2:$B$9999="Variant")*('Raw Data'!$C$2:$C$9999="E. 40-99")*'Raw Data'!$D$2:$D$9999*'Raw Data'!$AF$2:$AF$9999)/SUMIFS('Raw Data'!$D:$D, 'Raw Data'!$B:$B, "Variant", 'Raw Data'!$C:$C, "E. 40-99"),"") -> 30.915691 | Q19: =IFERROR((P19-O19)/ABS(O19),"") -> 0.036714023 | R19: =IFERROR(SUMPRODUCT(('Raw Data'!$B$2:$B$9999="Control")*('Raw Data'!$C$2:$C$9999="F. 100+")*'Raw Data'!$D$2:$D$9999*'Raw Data'!$AF$2:$AF$9999)/SUMIFS('Raw Data'!$D:$D, 'Raw Data'!$B:$B, "Control", 'Raw Data'!$C:$C, "F. 100+"),"") -> 74.421694 | S19: =IFERROR(SUMPRODUCT(('Raw Data'!$B$2:$B$9999="Variant")*('Raw Data'!$C$2:$C$9999="F. 100+")*'Raw Data'!$D$2:$D$9999*'Raw Data'!$AF$2:$AF$9999)/SUMIFS('Raw Data'!$D:$D, 'Raw Data'!$B:$B, "Variant", 'Raw Data'!$C:$C, "F. 100+"),"") -> 76.772195 | T19: =IFERROR((S19-R19)/ABS(R19),"") -> 0.031583539
B20: P75 daily streak | C20: =IFERROR(SUMPRODUCT(('Raw Data'!$B$2:$B$9999="Control")*('Raw Data'!$C$2:$C$9999="A. 0")*'Raw Data'!$D$2:$D$9999*'Raw Data'!$AG$2:$AG$9999)/SUMIFS('Raw Data'!$D:$D, 'Raw Data'!$B:$B, "Control", 'Raw Data'!$C:$C, "A. 0"),"") -> 0 | D20: =IFERROR(SUMPRODUCT(('Raw Data'!$B$2:$B$9999="Variant")*('Raw Data'!$C$2:$C$9999="A. 0")*'Raw Data'!$D$2:$D$9999*'Raw Data'!$AG$2:$AG$9999)/SUMIFS('Raw Data'!$D:$D, 'Raw Data'!$B:$B, "Variant", 'Raw Data'!$C:$C, "A. 0"),"") -> 0 | E20: =IFERROR((D20-C20)/ABS(C20),"") | F20: =IFERROR(SUMPRODUCT(('Raw Data'!$B$2:$B$9999="Control")*('Raw Data'!$C$2:$C$9999="B. 1-9")*'Raw Data'!$D$2:$D$9999*'Raw Data'!$AG$2:$AG$9999)/SUMIFS('Raw Data'!$D:$D, 'Raw Data'!$B:$B, "Control", 'Raw Data'!$C:$C, "B. 1-9"),"") -> 5.0348217 | G20: =IFERROR(SUMPRODUCT(('Raw Data'!$B$2:$B$9999="Variant")*('Raw Data'!$C$2:$C$9999="B. 1-9")*'Raw Data'!$D$2:$D$9999*'Raw Data'!$AG$2:$AG$9999)/SUMIFS('Raw Data'!$D:$D, 'Raw Data'!$B:$B, "Variant", 'Raw Data'!$C:$C, "B. 1-9"),"") -> 5 | H20: =IFERROR((G20-F20)/ABS(F20),"") -> -0.0069161719 | I20: =IFERROR(SUMPRODUCT(('Raw Data'!$B$2:$B$9999="Control")*('Raw Data'!$C$2:$C$9999="C. 10-19")*'Raw Data'!$D$2:$D$9999*'Raw Data'!$AG$2:$AG$9999)/SUMIFS('Raw Data'!$D:$D, 'Raw Data'!$B:$B, "Control", 'Raw Data'!$C:$C, "C. 10-19"),"") -> 12.871208 | J20: =IFERROR(SUMPRODUCT(('Raw Data'!$B$2:$B$9999="Variant")*('Raw Data'!$C$2:$C$9999="C. 10-19")*'Raw Data'!$D$2:$D$9999*'Raw Data'!$AG$2:$AG$9999)/SUMIFS('Raw Data'!$D:$D, 'Raw Data'!$B:$B, "Variant", 'Raw Data'!$C:$C, "C. 10-19"),"") -> 12.972468 | K20: =IFERROR((J20-I20)/ABS(I20),"") -> 0.0078671653 | L20: =IFERROR(SUMPRODUCT(('Raw Data'!$B$2:$B$9999="Control")*('Raw Data'!$C$2:$C$9999="D. 20-39")*'Raw Data'!$D$2:$D$9999*'Raw Data'!$AG$2:$AG$9999)/SUMIFS('Raw Data'!$D:$D, 'Raw Data'!$B:$B, "Control", 'Raw Data'!$C:$C, "D. 20-39"),"") -> 25.407476 | M20: =IFERROR(SUMPRODUCT(('Raw Data'!$B$2:$B$9999="Variant")*('Raw Data'!$C$2:$C$9999="D. 20-39")*'Raw Data'!$D$2:$D$9999*'Raw Data'!$AG$2:$AG$9999)/SUMIFS('Raw Data'!$D:$D, 'Raw Data'!$B:$B, "Variant", 'Raw Data'!$C:$C, "D. 20-39"),"") -> 25.625808 | N20: =IFERROR((M20-L20)/ABS(L20),"") -> 0.0085932346 | O20: =IFERROR(SUMPRODUCT(('Raw Data'!$B$2:$B$9999="Control")*('Raw Data'!$C$2:$C$9999="E. 40-99")*'Raw Data'!$D$2:$D$9999*'Raw Data'!$AG$2:$AG$9999)/SUMIFS('Raw Data'!$D:$D, 'Raw Data'!$B:$B, "Control", 'Raw Data'!$C:$C, "E. 40-99"),"") -> 51.936681 | P20: =IFERROR(SUMPRODUCT(('Raw Data'!$B$2:$B$9999="Variant")*('Raw Data'!$C$2:$C$9999="E. 40-99")*'Raw Data'!$D$2:$D$9999*'Raw Data'!$AG$2:$AG$9999)/SUMIFS('Raw Data'!$D:$D, 'Raw Data'!$B:$B, "Variant", 'Raw Data'!$C:$C, "E. 40-99"),"") -> 53.638368 | Q20: =IFERROR((P20-O20)/ABS(O20),"") -> 0.032764647 | R20: =IFERROR(SUMPRODUCT(('Raw Data'!$B$2:$B$9999="Control")*('Raw Data'!$C$2:$C$9999="F. 100+")*'Raw Data'!$D$2:$D$9999*'Raw Data'!$AG$2:$AG$9999)/SUMIFS('Raw Data'!$D:$D, 'Raw Data'!$B:$B, "Control", 'Raw Data'!$C:$C, "F. 100+"),"") -> 124.26968 | S20: =IFERROR(SUMPRODUCT(('Raw Data'!$B$2:$B$9999="Variant")*('Raw Data'!$C$2:$C$9999="F. 100+")*'Raw Data'!$D$2:$D$9999*'Raw Data'!$AG$2:$AG$9999)/SUMIFS('Raw Data'!$D:$D, 'Raw Data'!$B:$B, "Variant", 'Raw Data'!$C:$C, "F. 100+"),"") -> 124.66088 | T20: =IFERROR((S20-R20)/ABS(R20),"") -> 0.0031479511
B21: P90 daily streak | C21: =IFERROR(SUMPRODUCT(('Raw Data'!$B$2:$B$9999="Control")*('Raw Data'!$C$2:$C$9999="A. 0")*'Raw Data'!$D$2:$D$9999*'Raw Data'!$AH$2:$AH$9999)/SUMIFS('Raw Data'!$D:$D, 'Raw Data'!$B:$B, "Control", 'Raw Data'!$C:$C, "A. 0"),"") -> 0 | D21: =IFERROR(SUMPRODUCT(('Raw Data'!$B$2:$B$9999="Variant")*('Raw Data'!$C$2:$C$9999="A. 0")*'Raw Data'!$D$2:$D$9999*'Raw Data'!$AH$2:$AH$9999)/SUMIFS('Raw Data'!$D:$D, 'Raw Data'!$B:$B, "Variant", 'Raw Data'!$C:$C, "A. 0"),"") -> 0 | E21: =IFERROR((D21-C21)/ABS(C21),"") | F21: =IFERROR(SUMPRODUCT(('Raw Data'!$B$2:$B$9999="Control")*('Raw Data'!$C$2:$C$9999="B. 1-9")*'Raw Data'!$D$2:$D$9999*'Raw Data'!$AH$2:$AH$9999)/SUMIFS('Raw Data'!$D:$D, 'Raw Data'!$B:$B, "Control", 'Raw Data'!$C:$C, "B. 1-9"),"") -> 8.7879724 | G21: =IFERROR(SUMPRODUCT(('Raw Data'!$B$2:$B$9999="Variant")*('Raw Data'!$C$2:$C$9999="B. 1-9")*'Raw Data'!$D$2:$D$9999*'Raw Data'!$AH$2:$AH$9999)/SUMIFS('Raw Data'!$D:$D, 'Raw Data'!$B:$B, "Variant", 'Raw Data'!$C:$C, "B. 1-9"),"") -> 8.6823329 | H21: =IFERROR((G21-F21)/ABS(F21),"") -> -0.012020909 | I21: =IFERROR(SUMPRODUCT(('Raw Data'!$B$2:$B$9999="Control")*('Raw Data'!$C$2:$C$9999="C. 10-19")*'Raw Data'!$D$2:$D$9999*'Raw Data'!$AH$2:$AH$9999)/SUMIFS('Raw Data'!$D:$D, 'Raw Data'!$B:$B, "Control", 'Raw Data'!$C:$C, "C. 10-19"),"") -> 20.117468 | J21: =IFERROR(SUMPRODUCT(('Raw Data'!$B$2:$B$9999="Variant")*('Raw Data'!$C$2:$C$9999="C. 10-19")*'Raw Data'!$D$2:$D$9999*'Raw Data'!$AH$2:$AH$9999)/SUMIFS('Raw Data'!$D:$D, 'Raw Data'!$B:$B, "Variant", 'Raw Data'!$C:$C, "C. 10-19"),"") -> 20.220959 | K21: =IFERROR((J21-I21)/ABS(I21),"") -> 0.0051443116 | L21: =IFERROR(SUMPRODUCT(('Raw Data'!$B$2:$B$9999="Control")*('Raw Data'!$C$2:$C$9999="D. 20-39")*'Raw Data'!$D$2:$D$9999*'Raw Data'!$AH$2:$AH$9999)/SUMIFS('Raw Data'!$D:$D, 'Raw Data'!$B:$B, "Control", 'Raw Data'!$C:$C, "D. 20-39"),"") -> 37.932861 | M21: =IFERROR(SUMPRODUCT(('Raw Data'!$B$2:$B$9999="Variant")*('Raw Data'!$C$2:$C$9999="D. 20-39")*'Raw Data'!$D$2:$D$9999*'Raw Data'!$AH$2:$AH$9999)/SUMIFS('Raw Data'!$D:$D, 'Raw Data'!$B:$B, "Variant", 'Raw Data'!$C:$C, "D. 20-39"),"") -> 38.91431 | N21: =IFERROR((M21-L21)/ABS(L21),"") -> 0.025873316 | O21: =IFERROR(SUMPRODUCT(('Raw Data'!$B$2:$B$9999="Control")*('Raw Data'!$C$2:$C$9999="E. 40-99")*'Raw Data'!$D$2:$D$9999*'Raw Data'!$AH$2:$AH$9999)/SUMIFS('Raw Data'!$D:$D, 'Raw Data'!$B:$B, "Control", 'Raw Data'!$C:$C, "E. 40-99"),"") -> 79.400642 | P21: =IFERROR(SUMPRODUCT(('Raw Data'!$B$2:$B$9999="Variant")*('Raw Data'!$C$2:$C$9999="E. 40-99")*'Raw Data'!$D$2:$D$9999*'Raw Data'!$AH$2:$AH$9999)/SUMIFS('Raw Data'!$D:$D, 'Raw Data'!$B:$B, "Variant", 'Raw Data'!$C:$C, "E. 40-99"),"") -> 82.173653 | Q21: =IFERROR((P21-O21)/ABS(O21),"") -> 0.03492429 | R21: =IFERROR(SUMPRODUCT(('Raw Data'!$B$2:$B$9999="Control")*('Raw Data'!$C$2:$C$9999="F. 100+")*'Raw Data'!$D$2:$D$9999*'Raw Data'!$AH$2:$AH$9999)/SUMIFS('Raw Data'!$D:$D, 'Raw Data'!$B:$B, "Control", 'Raw Data'!$C:$C, "F. 100+"),"") -> 179.36788 | S21: =IFERROR(SUMPRODUCT(('Raw Data'!$B$2:$B$9999="Variant")*('Raw Data'!$C$2:$C$9999="F. 100+")*'Raw Data'!$D$2:$D$9999*'Raw Data'!$AH$2:$AH$9999)/SUMIFS('Raw Data'!$D:$D, 'Raw Data'!$B:$B, "Variant", 'Raw Data'!$C:$C, "F. 100+"),"") -> 177.7185 | T21: =IFERROR((S21-R21)/ABS(R21),"") -> -0.0091955163
A22: Difficulty
B23: Pass rate | C23: =IFERROR(SUMPRODUCT(('Raw Data'!$B$2:$B$9999="Control")*('Raw Data'!$C$2:$C$9999="A. 0")*'Raw Data'!$D$2:$D$9999*'Raw Data'!$M$2:$M$9999)/SUMIFS('Raw Data'!$D:$D, 'Raw Data'!$B:$B, "Control", 'Raw Data'!$C:$C, "A. 0"),"") -> 0.021860321 | D23: =IFERROR(SUMPRODUCT(('Raw Data'!$B$2:$B$9999="Variant")*('Raw Data'!$C$2:$C$9999="A. 0")*'Raw Data'!$D$2:$D$9999*'Raw Data'!$M$2:$M$9999)/SUMIFS('Raw Data'!$D:$D, 'Raw Data'!$B:$B, "Variant", 'Raw Data'!$C:$C, "A. 0"),"") -> 0.023070146 | E23: =IFERROR((D23-C23)/ABS(C23),"") -> 0.0553434 | F23: =IFERROR(SUMPRODUCT(('Raw Data'!$B$2:$B$9999="Control")*('Raw Data'!$C$2:$C$9999="B. 1-9")*'Raw Data'!$D$2:$D$9999*'Raw Data'!$M$2:$M$9999)/SUMIFS('Raw Data'!$D:$D, 'Raw Data'!$B:$B, "Control", 'Raw Data'!$C:$C, "B. 1-9"),"") -> 0.35788332 | G23: =IFERROR(SUMPRODUCT(('Raw Data'!$B$2:$B$9999="Variant")*('Raw Data'!$C$2:$C$9999="B. 1-9")*'Raw Data'!$D$2:$D$9999*'Raw Data'!$M$2:$M$9999)/SUMIFS('Raw Data'!$D:$D, 'Raw Data'!$B:$B, "Variant", 'Raw Data'!$C:$C, "B. 1-9"),"") -> 0.34991098 | H23: =IFERROR((G23-F23)/ABS(F23),"") -> -0.022276382 | I23: =IFERROR(SUMPRODUCT(('Raw Data'!$B$2:$B$9999="Control")*('Raw Data'!$C$2:$C$9999="C. 10-19")*'Raw Data'!$D$2:$D$9999*'Raw Data'!$M$2:$M$9999)/SUMIFS('Raw Data'!$D:$D, 'Raw Data'!$B:$B, "Control", 'Raw Data'!$C:$C, "C. 10-19"),"") -> 0.48910357 | J23: =IFERROR(SUMPRODUCT(('Raw Data'!$B$2:$B$9999="Variant")*('Raw Data'!$C$2:$C$9999="C. 10-19")*'Raw Data'!$D$2:$D$9999*'Raw Data'!$M$2:$M$9999)/SUMIFS('Raw Data'!$D:$D, 'Raw Data'!$B:$B, "Variant", 'Raw Data'!$C:$C, "C. 10-19"),"") -> 0.47754203 | K23: =IFERROR((J23-I23)/ABS(I23),"") -> -0.023638211 | L23: =IFERROR(SUMPRODUCT(('Raw Data'!$B$2:$B$9999="Control")*('Raw Data'!$C$2:$C$9999="D. 20-39")*'Raw Data'!$D$2:$D$9999*'Raw Data'!$M$2:$M$9999)/SUMIFS('Raw Data'!$D:$D, 'Raw Data'!$B:$B, "Control", 'Raw Data'!$C:$C, "D. 20-39"),"") -> 0.62169759 | M23: =IFERROR(SUMPRODUCT(('Raw Data'!$B$2:$B$9999="Variant")*('Raw Data'!$C$2:$C$9999="D. 20-39")*'Raw Data'!$D$2:$D$9999*'Raw Data'!$M$2:$M$9999)/SUMIFS('Raw Data'!$D:$D, 'Raw Data'!$B:$B, "Variant", 'Raw Data'!$C:$C, "D. 20-39"),"") -> 0.61679331 | N23: =IFERROR((M23-L23)/ABS(L23),"") -> -0.0078885351 | O23: =IFERROR(SUMPRODUCT(('Raw Data'!$B$2:$B$9999="Control")*('Raw Data'!$C$2:$C$9999="E. 40-99")*'Raw Data'!$D$2:$D$9999*'Raw Data'!$M$2:$M$9999)/SUMIFS('Raw Data'!$D:$D, 'Raw Data'!$B:$B, "Control", 'Raw Data'!$C:$C, "E. 40-99"),"") -> 0.75220446 | P23: =IFERROR(SUMPRODUCT(('Raw Data'!$B$2:$B$9999="Variant")*('Raw Data'!$C$2:$C$9999="E. 40-99")*'Raw Data'!$D$2:$D$9999*'Raw Data'!$M$2:$M$9999)/SUMIFS('Raw Data'!$D:$D, 'Raw Data'!$B:$B, "Variant", 'Raw Data'!$C:$C, "E. 40-99"),"") -> 0.75306844 | Q23: =IFERROR((P23-O23)/ABS(O23),"") -> 0.0011485924 | R23: =IFERROR(SUMPRODUCT(('Raw Data'!$B$2:$B$9999="Control")*('Raw Data'!$C$2:$C$9999="F. 100+")*'Raw Data'!$D$2:$D$9999*'Raw Data'!$M$2:$M$9999)/SUMIFS('Raw Data'!$D:$D, 'Raw Data'!$B:$B, "Control", 'Raw Data'!$C:$C, "F. 100+"),"") -> 0.84783844 | S23: =IFERROR(SUMPRODUCT(('Raw Data'!$B$2:$B$9999="Variant")*('Raw Data'!$C$2:$C$9999="F. 100+")*'Raw Data'!$D$2:$D$9999*'Raw Data'!$M$2:$M$9999)/SUMIFS('Raw Data'!$D:$D, 'Raw Data'!$B:$B, "Variant", 'Raw Data'!$C:$C, "F. 100+"),"") -> 0.84285308 | T23: =IFERROR((S23-R23)/ABS(R23),"") -> -0.0058800858
B24: OOM rate | C24: =IFERROR(SUMPRODUCT(('Raw Data'!$B$2:$B$9999="Control")*('Raw Data'!$C$2:$C$9999="A. 0")*'Raw Data'!$D$2:$D$9999*'Raw Data'!$N$2:$N$9999)/SUMIFS('Raw Data'!$D:$D, 'Raw Data'!$B:$B, "Control", 'Raw Data'!$C:$C, "A. 0"),"") -> 0.9815874 | D24: =IFERROR(SUMPRODUCT(('Raw Data'!$B$2:$B$9999="Variant")*('Raw Data'!$C$2:$C$9999="A. 0")*'Raw Data'!$D$2:$D$9999*'Raw Data'!$N$2:$N$9999)/SUMIFS('Raw Data'!$D:$D, 'Raw Data'!$B:$B, "Variant", 'Raw Data'!$C:$C, "A. 0"),"") -> 0.9799736 | E24: =IFERROR((D24-C24)/ABS(C24),"") -> -0.0016440757 | F24: =IFERROR(SUMPRODUCT(('Raw Data'!$B$2:$B$9999="Control")*('Raw Data'!$C$2:$C$9999="B. 1-9")*'Raw Data'!$D$2:$D$9999*'Raw Data'!$N$2:$N$9999)/SUMIFS('Raw Data'!$D:$D, 'Raw Data'!$B:$B, "Control", 'Raw Data'!$C:$C, "B. 1-9"),"") -> 0.75982597 | G24: =IFERROR(SUMPRODUCT(('Raw Data'!$B$2:$B$9999="Variant")*('Raw Data'!$C$2:$C$9999="B. 1-9")*'Raw Data'!$D$2:$D$9999*'Raw Data'!$N$2:$N$9999)/SUMIFS('Raw Data'!$D:$D, 'Raw Data'!$B:$B, "Variant", 'Raw Data'!$C:$C, "B. 1-9"),"") -> 0.76202177 | H24: =IFERROR((G24-F24)/ABS(F24),"") -> 0.0028898639 | I24: =IFERROR(SUMPRODUCT(('Raw Data'!$B$2:$B$9999="Control")*('Raw Data'!$C$2:$C$9999="C. 10-19")*'Raw Data'!$D$2:$D$9999*'Raw Data'!$N$2:$N$9999)/SUMIFS('Raw Data'!$D:$D, 'Raw Data'!$B:$B, "Control", 'Raw Data'!$C:$C, "C. 10-19"),"") -> 0.64785492 | J24: =IFERROR(SUMPRODUCT(('Raw Data'!$B$2:$B$9999="Variant")*('Raw Data'!$C$2:$C$9999="C. 10-19")*'Raw Data'!$D$2:$D$9999*'Raw Data'!$N$2:$N$9999)/SUMIFS('Raw Data'!$D:$D, 'Raw Data'!$B:$B, "Variant", 'Raw Data'!$C:$C, "C. 10-19"),"") -> 0.6539622 | K24: =IFERROR((J24-I24)/ABS(I24),"") -> 0.009426922 | L24: =IFERROR(SUMPRODUCT(('Raw Data'!$B$2:$B$9999="Control")*('Raw Data'!$C$2:$C$9999="D. 20-39")*'Raw Data'!$D$2:$D$9999*'Raw Data'!$N$2:$N$9999)/SUMIFS('Raw Data'!$D:$D, 'Raw Data'!$B:$B, "Control", 'Raw Data'!$C:$C, "D. 20-39"),"") -> 0.52288643 | M24: =IFERROR(SUMPRODUCT(('Raw Data'!$B$2:$B$9999="Variant")*('Raw Data'!$C$2:$C$9999="D. 20-39")*'Raw Data'!$D$2:$D$9999*'Raw Data'!$N$2:$N$9999)/SUMIFS('Raw Data'!$D:$D, 'Raw Data'!$B:$B, "Variant", 'Raw Data'!$C:$C, "D. 20-39"),"") -> 0.5243463 | N24: =IFERROR((M24-L24)/ABS(L24),"") -> 0.002791941 | O24: =IFERROR(SUMPRODUCT(('Raw Data'!$B$2:$B$9999="Control")*('Raw Data'!$C$2:$C$9999="E. 40-99")*'Raw Data'!$D$2:$D$9999*'Raw Data'!$N$2:$N$9999)/SUMIFS('Raw Data'!$D:$D, 'Raw Data'!$B:$B, "Control", 'Raw Data'!$C:$C, "E. 40-99"),"") -> 0.39317147 | P24: =IFERROR(SUMPRODUCT(('Raw Data'!$B$2:$B$9999="Variant")*('Raw Data'!$C$2:$C$9999="E. 40-99")*'Raw Data'!$D$2:$D$9999*'Raw Data'!$N$2:$N$9999)/SUMIFS('Raw Data'!$D:$D, 'Raw Data'!$B:$B, "Variant", 'Raw Data'!$C:$C, "E. 40-99"),"") -> 0.39105596 | Q24: =IFERROR((P24-O24)/ABS(O24),"") -> -0.0053806274 | R24: =IFERROR(SUMPRODUCT(('Raw Data'!$B$2:$B$9999="Control")*('Raw Data'!$C$2:$C$9999="F. 100+")*'Raw Data'!$D$2:$D$9999*'Raw Data'!$N$2:$N$9999)/SUMIFS('Raw Data'!$D:$D, 'Raw Data'!$B:$B, "Control", 'Raw Data'!$C:$C, "F. 100+"),"") -> 0.28313985 | S24: =IFERROR(SUMPRODUCT(('Raw Data'!$B$2:$B$9999="Variant")*('Raw Data'!$C$2:$C$9999="F. 100+")*'Raw Data'!$D$2:$D$9999*'Raw Data'!$N$2:$N$9999)/SUMIFS('Raw Data'!$D:$D, 'Raw Data'!$B:$B, "Variant", 'Raw Data'!$C:$C, "F. 100+"),"") -> 0.28980897 | T24: =IFERROR((S24-R24)/ABS(R24),"") -> 0.023554158
B25: First-try OOM rate | C25: =IFERROR(SUMPRODUCT(('Raw Data'!$B$2:$B$9999="Control")*('Raw Data'!$C$2:$C$9999="A. 0")*'Raw Data'!$D$2:$D$9999*'Raw Data'!$O$2:$O$9999)/SUMIFS('Raw Data'!$D:$D, 'Raw Data'!$B:$B, "Control", 'Raw Data'!$C:$C, "A. 0"),"") -> 0.7763233 | D25: =IFERROR(SUMPRODUCT(('Raw Data'!$B$2:$B$9999="Variant")*('Raw Data'!$C$2:$C$9999="A. 0")*'Raw Data'!$D$2:$D$9999*'Raw Data'!$O$2:$O$9999)/SUMIFS('Raw Data'!$D:$D, 'Raw Data'!$B:$B, "Variant", 'Raw Data'!$C:$C, "A. 0"),"") -> 0.74494993 | E25: =IFERROR((D25-C25)/ABS(C25),"") -> -0.040412765 | F25: =IFERROR(SUMPRODUCT(('Raw Data'!$B$2:$B$9999="Control")*('Raw Data'!$C$2:$C$9999="B. 1-9")*'Raw Data'!$D$2:$D$9999*'Raw Data'!$O$2:$O$9999)/SUMIFS('Raw Data'!$D:$D, 'Raw Data'!$B:$B, "Control", 'Raw Data'!$C:$C, "B. 1-9"),"") -> 0.53356215 | G25: =IFERROR(SUMPRODUCT(('Raw Data'!$B$2:$B$9999="Variant")*('Raw Data'!$C$2:$C$9999="B. 1-9")*'Raw Data'!$D$2:$D$9999*'Raw Data'!$O$2:$O$9999)/SUMIFS('Raw Data'!$D:$D, 'Raw Data'!$B:$B, "Variant", 'Raw Data'!$C:$C, "B. 1-9"),"") -> 0.53120168 | H25: =IFERROR((G25-F25)/ABS(F25),"") -> -0.0044239839 | I25: =IFERROR(SUMPRODUCT(('Raw Data'!$B$2:$B$9999="Control")*('Raw Data'!$C$2:$C$9999="C. 10-19")*'Raw Data'!$D$2:$D$9999*'Raw Data'!$O$2:$O$9999)/SUMIFS('Raw Data'!$D:$D, 'Raw Data'!$B:$B, "Control", 'Raw Data'!$C:$C, "C. 10-19"),"") -> 0.41605134 | J25: =IFERROR(SUMPRODUCT(('Raw Data'!$B$2:$B$9999="Variant")*('Raw Data'!$C$2:$C$9999="C. 10-19")*'Raw Data'!$D$2:$D$9999*'Raw Data'!$O$2:$O$9999)/SUMIFS('Raw Data'!$D:$D, 'Raw Data'!$B:$B, "Variant", 'Raw Data'!$C:$C, "C. 10-19"),"") -> 0.41562015 | K25: =IFERROR((J25-I25)/ABS(I25),"") -> -0.00103639 | L25: =IFERROR(SUMPRODUCT(('Raw Data'!$B$2:$B$9999="Control")*('Raw Data'!$C$2:$C$9999="D. 20-39")*'Raw Data'!$D$2:$D$9999*'Raw Data'!$O$2:$O$9999)/SUMIFS('Raw Data'!$D:$D, 'Raw Data'!$B:$B, "Control", 'Raw Data'!$C:$C, "D. 20-39"),"") -> 0.33006846 | M25: =IFERROR(SUMPRODUCT(('Raw Data'!$B$2:$B$9999="Variant")*('Raw Data'!$C$2:$C$9999="D. 20-39")*'Raw Data'!$D$2:$D$9999*'Raw Data'!$O$2:$O$9999)/SUMIFS('Raw Data'!$D:$D, 'Raw Data'!$B:$B, "Variant", 'Raw Data'!$C:$C, "D. 20-39"),"") -> 0.32689821 | N25: =IFERROR((M25-L25)/ABS(L25),"") -> -0.0096048211 | O25: =IFERROR(SUMPRODUCT(('Raw Data'!$B$2:$B$9999="Control")*('Raw Data'!$C$2:$C$9999="E. 40-99")*'Raw Data'!$D$2:$D$9999*'Raw Data'!$O$2:$O$9999)/SUMIFS('Raw Data'!$D:$D, 'Raw Data'!$B:$B, "Control", 'Raw Data'!$C:$C, "E. 40-99"),"") -> 0.25755219 | P25: =IFERROR(SUMPRODUCT(('Raw Data'!$B$2:$B$9999="Variant")*('Raw Data'!$C$2:$C$9999="E. 40-99")*'Raw Data'!$D$2:$D$9999*'Raw Data'!$O$2:$O$9999)/SUMIFS('Raw Data'!$D:$D, 'Raw Data'!$B:$B, "Variant", 'Raw Data'!$C:$C, "E. 40-99"),"") -> 0.2537171 | Q25: =IFERROR((P25-O25)/ABS(O25),"") -> -0.014890554 | R25: =IFERROR(SUMPRODUCT(('Raw Data'!$B$2:$B$9999="Control")*('Raw Data'!$C$2:$C$9999="F. 100+")*'Raw Data'!$D$2:$D$9999*'Raw Data'!$O$2:$O$9999)/SUMIFS('Raw Data'!$D:$D, 'Raw Data'!$B:$B, "Control", 'Raw Data'!$C:$C, "F. 100+"),"") -> 0.19643438 | S25: =IFERROR(SUMPRODUCT(('Raw Data'!$B$2:$B$9999="Variant")*('Raw Data'!$C$2:$C$9999="F. 100+")*'Raw Data'!$D$2:$D$9999*'Raw Data'!$O$2:$O$9999)/SUMIFS('Raw Data'!$D:$D, 'Raw Data'!$B:$B, "Variant", 'Raw Data'!$C:$C, "F. 100+"),"") -> 0.20023819 | T25: =IFERROR((S25-R25)/ABS(R25),"") -> 0.019364252
B26: Attempts per completion | C26: =IFERROR(SUMPRODUCT(('Raw Data'!$B$2:$B$9999="Control")*('Raw Data'!$C$2:$C$9999="A. 0")*'Raw Data'!$D$2:$D$9999*'Raw Data'!$P$2:$P$9999)/SUMIFS('Raw Data'!$D:$D, 'Raw Data'!$B:$B, "Control", 'Raw Data'!$C:$C, "A. 0"),"") -> 69.200155 | D26: =IFERROR(SUMPRODUCT(('Raw Data'!$B$2:$B$9999="Variant")*('Raw Data'!$C$2:$C$9999="A. 0")*'Raw Data'!$D$2:$D$9999*'Raw Data'!$P$2:$P$9999)/SUMIFS('Raw Data'!$D:$D, 'Raw Data'!$B:$B, "Variant", 'Raw Data'!$C:$C, "A. 0"),"") -> 48.636483 | E26: =IFERROR((D26-C26)/ABS(C26),"") -> -0.29716222 | F26: =IFERROR(SUMPRODUCT(('Raw Data'!$B$2:$B$9999="Control")*('Raw Data'!$C$2:$C$9999="B. 1-9")*'Raw Data'!$D$2:$D$9999*'Raw Data'!$P$2:$P$9999)/SUMIFS('Raw Data'!$D:$D, 'Raw Data'!$B:$B, "Control", 'Raw Data'!$C:$C, "B. 1-9"),"") -> 2.8011394 | G26: =IFERROR(SUMPRODUCT(('Raw Data'!$B$2:$B$9999="Variant")*('Raw Data'!$C$2:$C$9999="B. 1-9")*'Raw Data'!$D$2:$D$9999*'Raw Data'!$P$2:$P$9999)/SUMIFS('Raw Data'!$D:$D, 'Raw Data'!$B:$B, "Variant", 'Raw Data'!$C:$C, "B. 1-9"),"") -> 2.8624707 | H26: =IFERROR((G26-F26)/ABS(F26),"") -> 0.021895113 | I26: =IFERROR(SUMPRODUCT(('Raw Data'!$B$2:$B$9999="Control")*('Raw Data'!$C$2:$C$9999="C. 10-19")*'Raw Data'!$D$2:$D$9999*'Raw Data'!$P$2:$P$9999)/SUMIFS('Raw Data'!$D:$D, 'Raw Data'!$B:$B, "Control", 'Raw Data'!$C:$C, "C. 10-19"),"") -> 2.0480784 | J26: =IFERROR(SUMPRODUCT(('Raw Data'!$B$2:$B$9999="Variant")*('Raw Data'!$C$2:$C$9999="C. 10-19")*'Raw Data'!$D$2:$D$9999*'Raw Data'!$P$2:$P$9999)/SUMIFS('Raw Data'!$D:$D, 'Raw Data'!$B:$B, "Variant", 'Raw Data'!$C:$C, "C. 10-19"),"") -> 2.0972354 | K26: =IFERROR((J26-I26)/ABS(I26),"") -> 0.024001533 | L26: =IFERROR(SUMPRODUCT(('Raw Data'!$B$2:$B$9999="Control")*('Raw Data'!$C$2:$C$9999="D. 20-39")*'Raw Data'!$D$2:$D$9999*'Raw Data'!$P$2:$P$9999)/SUMIFS('Raw Data'!$D:$D, 'Raw Data'!$B:$B, "Control", 'Raw Data'!$C:$C, "D. 20-39"),"") -> 1.6102783 | M26: =IFERROR(SUMPRODUCT(('Raw Data'!$B$2:$B$9999="Variant")*('Raw Data'!$C$2:$C$9999="D. 20-39")*'Raw Data'!$D$2:$D$9999*'Raw Data'!$P$2:$P$9999)/SUMIFS('Raw Data'!$D:$D, 'Raw Data'!$B:$B, "Variant", 'Raw Data'!$C:$C, "D. 20-39"),"") -> 1.6235219 | N26: =IFERROR((M26-L26)/ABS(L26),"") -> 0.0082244262 | O26: =IFERROR(SUMPRODUCT(('Raw Data'!$B$2:$B$9999="Control")*('Raw Data'!$C$2:$C$9999="E. 40-99")*'Raw Data'!$D$2:$D$9999*'Raw Data'!$P$2:$P$9999)/SUMIFS('Raw Data'!$D:$D, 'Raw Data'!$B:$B, "Control", 'Raw Data'!$C:$C, "E. 40-99"),"") -> 1.3300902 | P26: =IFERROR(SUMPRODUCT(('Raw Data'!$B$2:$B$9999="Variant")*('Raw Data'!$C$2:$C$9999="E. 40-99")*'Raw Data'!$D$2:$D$9999*'Raw Data'!$P$2:$P$9999)/SUMIFS('Raw Data'!$D:$D, 'Raw Data'!$B:$B, "Variant", 'Raw Data'!$C:$C, "E. 40-99"),"") -> 1.3285932 | Q26: =IFERROR((P26-O26)/ABS(O26),"") -> -0.0011255309 | R26: =IFERROR(SUMPRODUCT(('Raw Data'!$B$2:$B$9999="Control")*('Raw Data'!$C$2:$C$9999="F. 100+")*'Raw Data'!$D$2:$D$9999*'Raw Data'!$P$2:$P$9999)/SUMIFS('Raw Data'!$D:$D, 'Raw Data'!$B:$B, "Control", 'Raw Data'!$C:$C, "F. 100+"),"") -> 1.1798282 | S26: =IFERROR(SUMPRODUCT(('Raw Data'!$B$2:$B$9999="Variant")*('Raw Data'!$C$2:$C$9999="F. 100+")*'Raw Data'!$D$2:$D$9999*'Raw Data'!$P$2:$P$9999)/SUMIFS('Raw Data'!$D:$D, 'Raw Data'!$B:$B, "Variant", 'Raw Data'!$C:$C, "F. 100+"),"") -> 1.186839 | T26: =IFERROR((S26-R26)/ABS(R26),"") -> 0.0059422562
A27: HC Economy
B28: HC gain total / player | C28: =IFERROR(SUMPRODUCT(('Raw Data'!$B$2:$B$9999="Control")*('Raw Data'!$C$2:$C$9999="A. 0")*'Raw Data'!$D$2:$D$9999*'Raw Data'!$Q$2:$Q$9999)/SUMIFS('Raw Data'!$D:$D, 'Raw Data'!$B:$B, "Control", 'Raw Data'!$C:$C, "A. 0"),"") -> 26.989699 | D28: =IFERROR(SUMPRODUCT(('Raw Data'!$B$2:$B$9999="Variant")*('Raw Data'!$C$2:$C$9999="A. 0")*'Raw Data'!$D$2:$D$9999*'Raw Data'!$Q$2:$Q$9999)/SUMIFS('Raw Data'!$D:$D, 'Raw Data'!$B:$B, "Variant", 'Raw Data'!$C:$C, "A. 0"),"") -> 23.576351 | E28: =IFERROR((D28-C28)/ABS(C28),"") -> -0.12646856 | F28: =IFERROR(SUMPRODUCT(('Raw Data'!$B$2:$B$9999="Control")*('Raw Data'!$C$2:$C$9999="B. 1-9")*'Raw Data'!$D$2:$D$9999*'Raw Data'!$Q$2:$Q$9999)/SUMIFS('Raw Data'!$D:$D, 'Raw Data'!$B:$B, "Control", 'Raw Data'!$C:$C, "B. 1-9"),"") -> 65.71083 | G28: =IFERROR(SUMPRODUCT(('Raw Data'!$B$2:$B$9999="Variant")*('Raw Data'!$C$2:$C$9999="B. 1-9")*'Raw Data'!$D$2:$D$9999*'Raw Data'!$Q$2:$Q$9999)/SUMIFS('Raw Data'!$D:$D, 'Raw Data'!$B:$B, "Variant", 'Raw Data'!$C:$C, "B. 1-9"),"") -> 58.796127 | H28: =IFERROR((G28-F28)/ABS(F28),"") -> -0.10522928 | I28: =IFERROR(SUMPRODUCT(('Raw Data'!$B$2:$B$9999="Control")*('Raw Data'!$C$2:$C$9999="C. 10-19")*'Raw Data'!$D$2:$D$9999*'Raw Data'!$Q$2:$Q$9999)/SUMIFS('Raw Data'!$D:$D, 'Raw Data'!$B:$B, "Control", 'Raw Data'!$C:$C, "C. 10-19"),"") -> 130.47514 | J28: =IFERROR(SUMPRODUCT(('Raw Data'!$B$2:$B$9999="Variant")*('Raw Data'!$C$2:$C$9999="C. 10-19")*'Raw Data'!$D$2:$D$9999*'Raw Data'!$Q$2:$Q$9999)/SUMIFS('Raw Data'!$D:$D, 'Raw Data'!$B:$B, "Variant", 'Raw Data'!$C:$C, "C. 10-19"),"") -> 123.21437 | K28: =IFERROR((J28-I28)/ABS(I28),"") -> -0.055648662 | L28: =IFERROR(SUMPRODUCT(('Raw Data'!$B$2:$B$9999="Control")*('Raw Data'!$C$2:$C$9999="D. 20-39")*'Raw Data'!$D$2:$D$9999*'Raw Data'!$Q$2:$Q$9999)/SUMIFS('Raw Data'!$D:$D, 'Raw Data'!$B:$B, "Control", 'Raw Data'!$C:$C, "D. 20-39"),"") -> 231.86417 | M28: =IFERROR(SUMPRODUCT(('Raw Data'!$B$2:$B$9999="Variant")*('Raw Data'!$C$2:$C$9999="D. 20-39")*'Raw Data'!$D$2:$D$9999*'Raw Data'!$Q$2:$Q$9999)/SUMIFS('Raw Data'!$D:$D, 'Raw Data'!$B:$B, "Variant", 'Raw Data'!$C:$C, "D. 20-39"),"") -> 226.3284 | N28: =IFERROR((M28-L28)/ABS(L28),"") -> -0.023875054 | O28: =IFERROR(SUMPRODUCT(('Raw Data'!$B$2:$B$9999="Control")*('Raw Data'!$C$2:$C$9999="E. 40-99")*'Raw Data'!$D$2:$D$9999*'Raw Data'!$Q$2:$Q$9999)/SUMIFS('Raw Data'!$D:$D, 'Raw Data'!$B:$B, "Control", 'Raw Data'!$C:$C, "E. 40-99"),"") -> 433.09226 | P28: =IFERROR(SUMPRODUCT(('Raw Data'!$B$2:$B$9999="Variant")*('Raw Data'!$C$2:$C$9999="E. 40-99")*'Raw Data'!$D$2:$D$9999*'Raw Data'!$Q$2:$Q$9999)/SUMIFS('Raw Data'!$D:$D, 'Raw Data'!$B:$B, "Variant", 'Raw Data'!$C:$C, "E. 40-99"),"") -> 438.42963 | Q28: =IFERROR((P28-O28)/ABS(O28),"") -> 0.012323882 | R28: =IFERROR(SUMPRODUCT(('Raw Data'!$B$2:$B$9999="Control")*('Raw Data'!$C$2:$C$9999="F. 100+")*'Raw Data'!$D$2:$D$9999*'Raw Data'!$Q$2:$Q$9999)/SUMIFS('Raw Data'!$D:$D, 'Raw Data'!$B:$B, "Control", 'Raw Data'!$C:$C, "F. 100+"),"") -> 834.68989 | S28: =IFERROR(SUMPRODUCT(('Raw Data'!$B$2:$B$9999="Variant")*('Raw Data'!$C$2:$C$9999="F. 100+")*'Raw Data'!$D$2:$D$9999*'Raw Data'!$Q$2:$Q$9999)/SUMIFS('Raw Data'!$D:$D, 'Raw Data'!$B:$B, "Variant", 'Raw Data'!$C:$C, "F. 100+"),"") -> 822.66151 | T28: =IFERROR((S28-R28)/ABS(R28),"") -> -0.014410597
B29: HC gain PAID / player | C29: =IFERROR(SUMPRODUCT(('Raw Data'!$B$2:$B$9999="Control")*('Raw Data'!$C$2:$C$9999="A. 0")*'Raw Data'!$D$2:$D$9999*'Raw Data'!$T$2:$T$9999)/SUMIFS('Raw Data'!$D:$D, 'Raw Data'!$B:$B, "Control", 'Raw Data'!$C:$C, "A. 0"),"") -> 0.31689585 | D29: =IFERROR(SUMPRODUCT(('Raw Data'!$B$2:$B$9999="Variant")*('Raw Data'!$C$2:$C$9999="A. 0")*'Raw Data'!$D$2:$D$9999*'Raw Data'!$T$2:$T$9999)/SUMIFS('Raw Data'!$D:$D, 'Raw Data'!$B:$B, "Variant", 'Raw Data'!$C:$C, "A. 0"),"") -> 0.27573416 | E29: =IFERROR((D29-C29)/ABS(C29),"") -> -0.12989027 | F29: =IFERROR(SUMPRODUCT(('Raw Data'!$B$2:$B$9999="Control")*('Raw Data'!$C$2:$C$9999="B. 1-9")*'Raw Data'!$D$2:$D$9999*'Raw Data'!$T$2:$T$9999)/SUMIFS('Raw Data'!$D:$D, 'Raw Data'!$B:$B, "Control", 'Raw Data'!$C:$C, "B. 1-9"),"") -> 6.6490282 | G29: =IFERROR(SUMPRODUCT(('Raw Data'!$B$2:$B$9999="Variant")*('Raw Data'!$C$2:$C$9999="B. 1-9")*'Raw Data'!$D$2:$D$9999*'Raw Data'!$T$2:$T$9999)/SUMIFS('Raw Data'!$D:$D, 'Raw Data'!$B:$B, "Variant", 'Raw Data'!$C:$C, "B. 1-9"),"") -> 6.7789735 | H29: =IFERROR((G29-F29)/ABS(F29),"") -> 0.019543503 | I29: =IFERROR(SUMPRODUCT(('Raw Data'!$B$2:$B$9999="Control")*('Raw Data'!$C$2:$C$9999="C. 10-19")*'Raw Data'!$D$2:$D$9999*'Raw Data'!$T$2:$T$9999)/SUMIFS('Raw Data'!$D:$D, 'Raw Data'!$B:$B, "Control", 'Raw Data'!$C:$C, "C. 10-19"),"") -> 23.338872 | J29: =IFERROR(SUMPRODUCT(('Raw Data'!$B$2:$B$9999="Variant")*('Raw Data'!$C$2:$C$9999="C. 10-19")*'Raw Data'!$D$2:$D$9999*'Raw Data'!$T$2:$T$9999)/SUMIFS('Raw Data'!$D:$D, 'Raw Data'!$B:$B, "Variant", 'Raw Data'!$C:$C, "C. 10-19"),"") -> 23.501215 | K29: =IFERROR((J29-I29)/ABS(I29),"") -> 0.0069558981 | L29: =IFERROR(SUMPRODUCT(('Raw Data'!$B$2:$B$9999="Control")*('Raw Data'!$C$2:$C$9999="D. 20-39")*'Raw Data'!$D$2:$D$9999*'Raw Data'!$T$2:$T$9999)/SUMIFS('Raw Data'!$D:$D, 'Raw Data'!$B:$B, "Control", 'Raw Data'!$C:$C, "D. 20-39"),"") -> 53.78642 | M29: =IFERROR(SUMPRODUCT(('Raw Data'!$B$2:$B$9999="Variant")*('Raw Data'!$C$2:$C$9999="D. 20-39")*'Raw Data'!$D$2:$D$9999*'Raw Data'!$T$2:$T$9999)/SUMIFS('Raw Data'!$D:$D, 'Raw Data'!$B:$B, "Variant", 'Raw Data'!$C:$C, "D. 20-39"),"") -> 52.805842 | N29: =IFERROR((M29-L29)/ABS(L29),"") -> -0.018230951 | O29: =IFERROR(SUMPRODUCT(('Raw Data'!$B$2:$B$9999="Control")*('Raw Data'!$C$2:$C$9999="E. 40-99")*'Raw Data'!$D$2:$D$9999*'Raw Data'!$T$2:$T$9999)/SUMIFS('Raw Data'!$D:$D, 'Raw Data'!$B:$B, "Control", 'Raw Data'!$C:$C, "E. 40-99"),"") -> 114.24422 | P29: =IFERROR(SUMPRODUCT(('Raw Data'!$B$2:$B$9999="Variant")*('Raw Data'!$C$2:$C$9999="E. 40-99")*'Raw Data'!$D$2:$D$9999*'Raw Data'!$T$2:$T$9999)/SUMIFS('Raw Data'!$D:$D, 'Raw Data'!$B:$B, "Variant", 'Raw Data'!$C:$C, "E. 40-99"),"") -> 119.7299 | Q29: =IFERROR((P29-O29)/ABS(O29),"") -> 0.048017146 | R29: =IFERROR(SUMPRODUCT(('Raw Data'!$B$2:$B$9999="Control")*('Raw Data'!$C$2:$C$9999="F. 100+")*'Raw Data'!$D$2:$D$9999*'Raw Data'!$T$2:$T$9999)/SUMIFS('Raw Data'!$D:$D, 'Raw Data'!$B:$B, "Control", 'Raw Data'!$C:$C, "F. 100+"),"") -> 211.82531 | S29: =IFERROR(SUMPRODUCT(('Raw Data'!$B$2:$B$9999="Variant")*('Raw Data'!$C$2:$C$9999="F. 100+")*'Raw Data'!$D$2:$D$9999*'Raw Data'!$T$2:$T$9999)/SUMIFS('Raw Data'!$D:$D, 'Raw Data'!$B:$B, "Variant", 'Raw Data'!$C:$C, "F. 100+"),"") -> 235.79767 | T29: =IFERROR((S29-R29)/ABS(R29),"") -> 0.11317044
