Workbook

Sheet By Bucket
A1: A/B Test Summary By 7d Completion Bucket
A3: Category | B3: Metric | C3: 0 | F3: 1-9 | I3: 10-19 | L3: 20-39 | O3: 40-99 | R3: 100+
C4: Control | D4: Variant | E4: Δ % | F4: Control | G4: Variant | H4: Δ % | I4: Control | J4: Variant | K4: Δ % | L4: Control | M4: Variant | N4: Δ % | O4: Control | P4: Variant | Q4: Δ % | R4: Control | S4: Variant | T4: Δ %
A5: Players
B6: Players (sum) | C6: =SUMIFS(Raw_Data_Daily!$D:$D, Raw_Data_Daily!$B:$B, "Control", Raw_Data_Daily!$C:$C, "A. 0") -> 0 | D6: =SUMIFS(Raw_Data_Daily!$D:$D, Raw_Data_Daily!$B:$B, "Variant", Raw_Data_Daily!$C:$C, "A. 0") -> 0 | E6: =IFERROR((D6-C6)/ABS(C6),"") | F6: =SUMIFS(Raw_Data_Daily!$D:$D, Raw_Data_Daily!$B:$B, "Control", Raw_Data_Daily!$C:$C, "B. 1-9") -> 61400 | G6: =SUMIFS(Raw_Data_Daily!$D:$D, Raw_Data_Daily!$B:$B, "Variant", Raw_Data_Daily!$C:$C, "B. 1-9") -> 61508 | H6: =IFERROR((G6-F6)/ABS(F6),"") -> 0.0017589577 | I6: =SUMIFS(Raw_Data_Daily!$D:$D, Raw_Data_Daily!$B:$B, "Control", Raw_Data_Daily!$C:$C, "C. 10-19") -> 43234 | J6: =SUMIFS(Raw_Data_Daily!$D:$D, Raw_Data_Daily!$B:$B, "Variant", Raw_Data_Daily!$C:$C, "C. 10-19") -> 44265 | K6: =IFERROR((J6-I6)/ABS(I6),"") -> 0.023846972 | L6: =SUMIFS(Raw_Data_Daily!$D:$D, Raw_Data_Daily!$B:$B, "Control", Raw_Data_Daily!$C:$C, "D. 20-39") -> 37201 | M6: =SUMIFS(Raw_Data_Daily!$D:$D, Raw_Data_Daily!$B:$B, "Variant", Raw_Data_Daily!$C:$C, "D. 20-39") -> 37039 | N6: =IFERROR((M6-L6)/ABS(L6),"") -> -0.0043547216 | O6: =SUMIFS(Raw_Data_Daily!$D:$D, Raw_Data_Daily!$B:$B, "Control", Raw_Data_Daily!$C:$C, "E. 40-99") -> 23787 | P6: =SUMIFS(Raw_Data_Daily!$D:$D, Raw_Data_Daily!$B:$B, "Variant", Raw_Data_Daily!$C:$C, "E. 40-99") -> 22845 | Q6: =IFERROR((P6-O6)/ABS(O6),"") -> -0.039601463 | R6: =SUMIFS(Raw_Data_Daily!$D:$D, Raw_Data_Daily!$B:$B, "Control", Raw_Data_Daily!$C:$C, "F. 100+") -> 3548 | S6: =SUMIFS(Raw_Data_Daily!$D:$D, Raw_Data_Daily!$B:$B, "Variant", Raw_Data_Daily!$C:$C, "F. 100+") -> 3283 | T6: =IFERROR((S6-R6)/ABS(R6),"") -> -0.074689966
A7: Revenue
B8: Total revenue | C8: =SUMIFS(Raw_Data_Daily!$F:$F, Raw_Data_Daily!$B:$B, "Control", Raw_Data_Daily!$C:$C, "A. 0") -> 0 | D8: =SUMIFS(Raw_Data_Daily!$F:$F, Raw_Data_Daily!$B:$B, "Variant", Raw_Data_Daily!$C:$C, "A. 0") -> 0 | E8: =IFERROR((D8-C8)/ABS(C8),"") | F8: =SUMIFS(Raw_Data_Daily!$F:$F, Raw_Data_Daily!$B:$B, "Control", Raw_Data_Daily!$C:$C, "B. 1-9") -> 2317.41 | G8: =SUMIFS(Raw_Data_Daily!$F:$F, Raw_Data_Daily!$B:$B, "Variant", Raw_Data_Daily!$C:$C, "B. 1-9") -> 2128.97 | H8: =IFERROR((G8-F8)/ABS(F8),"") -> -0.081314916 | I8: =SUMIFS(Raw_Data_Daily!$F:$F, Raw_Data_Daily!$B:$B, "Control", Raw_Data_Daily!$C:$C, "C. 10-19") -> 3818.71 | J8: =SUMIFS(Raw_Data_Daily!$F:$F, Raw_Data_Daily!$B:$B, "Variant", Raw_Data_Daily!$C:$C, "C. 10-19") -> 4047.88 | K8: =IFERROR((J8-I8)/ABS(I8),"") -> 0.060012413 | L8: =SUMIFS(Raw_Data_Daily!$F:$F, Raw_Data_Daily!$B:$B, "Control", Raw_Data_Daily!$C:$C, "D. 20-39") -> 6700.02 | M8: =SUMIFS(Raw_Data_Daily!$F:$F, Raw_Data_Daily!$B:$B, "Variant", Raw_Data_Daily!$C:$C, "D. 20-39") -> 5209.65 | N8: =IFERROR((M8-L8)/ABS(L8),"") -> -0.22244262 | O8: =SUMIFS(Raw_Data_Daily!$F:$F, Raw_Data_Daily!$B:$B, "Control", Raw_Data_Daily!$C:$C, "E. 40-99") -> 9072.24 | P8: =SUMIFS(Raw_Data_Daily!$F:$F, Raw_Data_Daily!$B:$B, "Variant", Raw_Data_Daily!$C:$C, "E. 40-99") -> 8063.71 | Q8: =IFERROR((P8-O8)/ABS(O8),"") -> -0.11116659 | R8: =SUMIFS(Raw_Data_Daily!$F:$F, Raw_Data_Daily!$B:$B, "Control", Raw_Data_Daily!$C:$C, "F. 100+") -> 3100.98 | S8: =SUMIFS(Raw_Data_Daily!$F:$F, Raw_Data_Daily!$B:$B, "Variant", Raw_Data_Daily!$C:$C, "F. 100+") -> 2891.01 | T8: =IFERROR((S8-R8)/ABS(R8),"") -> -0.067710853
B9: ARPDAU | C9: =IFERROR(SUMIFS(Raw_Data_Daily!$F:$F, Raw_Data_Daily!$B:$B, "Control", Raw_Data_Daily!$C:$C, "A. 0")/SUMIFS(Raw_Data_Daily!$D:$D, Raw_Data_Daily!$B:$B, "Control", Raw_Data_Daily!$C:$C, "A. 0"),"") | D9: =IFERROR(SUMIFS(Raw_Data_Daily!$F:$F, Raw_Data_Daily!$B:$B, "Variant", Raw_Data_Daily!$C:$C, "A. 0")/SUMIFS(Raw_Data_Daily!$D:$D, Raw_Data_Daily!$B:$B, "Variant", Raw_Data_Daily!$C:$C, "A. 0"),"") | E9: =IFERROR((D9-C9)/ABS(C9),"") | F9: =IFERROR(SUMIFS(Raw_Data_Daily!$F:$F, Raw_Data_Daily!$B:$B, "Control", Raw_Data_Daily!$C:$C, "B. 1-9")/SUMIFS(Raw_Data_Daily!$D:$D, Raw_Data_Daily!$B:$B, "Control", Raw_Data_Daily!$C:$C, "B. 1-9"),"") -> 0.037742834 | G9: =IFERROR(SUMIFS(Raw_Data_Daily!$F:$F, Raw_Data_Daily!$B:$B, "Variant", Raw_Data_Daily!$C:$C, "B. 1-9")/SUMIFS(Raw_Data_Daily!$D:$D, Raw_Data_Daily!$B:$B, "Variant", Raw_Data_Daily!$C:$C, "B. 1-9"),"") -> 0.034612896 | H9: =IFERROR((G9-F9)/ABS(F9),"") -> -0.082928007 | I9: =IFERROR(SUMIFS(Raw_Data_Daily!$F:$F, Raw_Data_Daily!$B:$B, "Control", Raw_Data_Daily!$C:$C, "C. 10-19")/SUMIFS(Raw_Data_Daily!$D:$D, Raw_Data_Daily!$B:$B, "Control", Raw_Data_Daily!$C:$C, "C. 10-19"),"") -> 0.088326549 | J9: =IFERROR(SUMIFS(Raw_Data_Daily!$F:$F, Raw_Data_Daily!$B:$B, "Variant", Raw_Data_Daily!$C:$C, "C. 10-19")/SUMIFS(Raw_Data_Daily!$D:$D, Raw_Data_Daily!$B:$B, "Variant", Raw_Data_Daily!$C:$C, "C. 10-19"),"") -> 0.091446515 | K9: =IFERROR((J9-I9)/ABS(I9),"") -> 0.035323091 | L9: =IFERROR(SUMIFS(Raw_Data_Daily!$F:$F, Raw_Data_Daily!$B:$B, "Control", Raw_Data_Daily!$C:$C, "D. 20-39")/SUMIFS(Raw_Data_Daily!$D:$D, Raw_Data_Daily!$B:$B, "Control", Raw_Data_Daily!$C:$C, "D. 20-39"),"") -> 0.18010322 | M9: =IFERROR(SUMIFS(Raw_Data_Daily!$F:$F, Raw_Data_Daily!$B:$B, "Variant", Raw_Data_Daily!$C:$C, "D. 20-39")/SUMIFS(Raw_Data_Daily!$D:$D, Raw_Data_Daily!$B:$B, "Variant", Raw_Data_Daily!$C:$C, "D. 20-39"),"") -> 0.1406531 | N9: =IFERROR((M9-L9)/ABS(L9),"") -> -0.21904176 | O9: =IFERROR(SUMIFS(Raw_Data_Daily!$F:$F, Raw_Data_Daily!$B:$B, "Control", Raw_Data_Daily!$C:$C, "E. 40-99")/SUMIFS(Raw_Data_Daily!$D:$D, Raw_Data_Daily!$B:$B, "Control", Raw_Data_Daily!$C:$C, "E. 40-99"),"") -> 0.38139488 | P9: =IFERROR(SUMIFS(Raw_Data_Daily!$F:$F, Raw_Data_Daily!$B:$B, "Variant", Raw_Data_Daily!$C:$C, "E. 40-99")/SUMIFS(Raw_Data_Daily!$D:$D, Raw_Data_Daily!$B:$B, "Variant", Raw_Data_Daily!$C:$C, "E. 40-99"),"") -> 0.35297483 | Q9: =IFERROR((P9-O9)/ABS(O9),"") -> -0.074516074 | R9: =IFERROR(SUMIFS(Raw_Data_Daily!$F:$F, Raw_Data_Daily!$B:$B, "Control", Raw_Data_Daily!$C:$C, "F. 100+")/SUMIFS(Raw_Data_Daily!$D:$D, Raw_Data_Daily!$B:$B, "Control", Raw_Data_Daily!$C:$C, "F. 100+"),"") -> 0.87400789 | S9: =IFERROR(SUMIFS(Raw_Data_Daily!$F:$F, Raw_Data_Daily!$B:$B, "Variant", Raw_Data_Daily!$C:$C, "F. 100+")/SUMIFS(Raw_Data_Daily!$D:$D, Raw_Data_Daily!$B:$B, "Variant", Raw_Data_Daily!$C:$C, "F. 100+"),"") -> 0.88060006 | T9: =IFERROR((S9-R9)/ABS(R9),"") -> 0.0075424595
B10: AVG Payer day (%) | C10: =IFERROR(SUMPRODUCT((Raw_Data_Daily!$B$2:$B$9999="Control")*(Raw_Data_Daily!$C$2:$C$9999="A. 0")*Raw_Data_Daily!$D$2:$D$9999*Raw_Data_Daily!$H$2:$H$9999/100)/SUMIFS(Raw_Data_Daily!$D:$D, Raw_Data_Daily!$B:$B, "Control", Raw_Data_Daily!$C:$C, "A. 0")*100,"") | D10: =IFERROR(SUMPRODUCT((Raw_Data_Daily!$B$2:$B$9999="Variant")*(Raw_Data_Daily!$C$2:$C$9999="A. 0")*Raw_Data_Daily!$D$2:$D$9999*Raw_Data_Daily!$H$2:$H$9999/100)/SUMIFS(Raw_Data_Daily!$D:$D, Raw_Data_Daily!$B:$B, "Variant", Raw_Data_Daily!$C:$C, "A. 0")*100,"") | E10: =IFERROR((D10-C10)/ABS(C10),"") | F10: =IFERROR(SUMPRODUCT((Raw_Data_Daily!$B$2:$B$9999="Control")*(Raw_Data_Daily!$C$2:$C$9999="B. 1-9")*Raw_Data_Daily!$D$2:$D$9999*Raw_Data_Daily!$H$2:$H$9999/100)/SUMIFS(Raw_Data_Daily!$D:$D, Raw_Data_Daily!$B:$B, "Control", Raw_Data_Daily!$C:$C, "B. 1-9")*100,"") -> 1.4614308 | G10: =IFERROR(SUMPRODUCT((Raw_Data_Daily!$B$2:$B$9999="Variant")*(Raw_Data_Daily!$C$2:$C$9999="B. 1-9")*Raw_Data_Daily!$D$2:$D$9999*Raw_Data_Daily!$H$2:$H$9999/100)/SUMIFS(Raw_Data_Daily!$D:$D, Raw_Data_Daily!$B:$B, "Variant", Raw_Data_Daily!$C:$C, "B. 1-9")*100,"") -> 1.2815624 | H10: =IFERROR((G10-F10)/ABS(F10),"") -> -0.12307691 | I10: =IFERROR(SUMPRODUCT((Raw_Data_Daily!$B$2:$B$9999="Control")*(Raw_Data_Daily!$C$2:$C$9999="C. 10-19")*Raw_Data_Daily!$D$2:$D$9999*Raw_Data_Daily!$H$2:$H$9999/100)/SUMIFS(Raw_Data_Daily!$D:$D, Raw_Data_Daily!$B:$B, "Control", Raw_Data_Daily!$C:$C, "C. 10-19")*100,"") -> 2.4646459 | J10: =IFERROR(SUMPRODUCT((Raw_Data_Daily!$B$2:$B$9999="Variant")*(Raw_Data_Daily!$C$2:$C$9999="C. 10-19")*Raw_Data_Daily!$D$2:$D$9999*Raw_Data_Daily!$H$2:$H$9999/100)/SUMIFS(Raw_Data_Daily!$D:$D, Raw_Data_Daily!$B:$B, "Variant", Raw_Data_Daily!$C:$C, "C. 10-19")*100,"") -> 2.5198118 | K10: =IFERROR((J10-I10)/ABS(I10),"") -> 0.022382905 | L10: =IFERROR(SUMPRODUCT((Raw_Data_Daily!$B$2:$B$9999="Control")*(Raw_Data_Daily!$C$2:$C$9999="D. 20-39")*Raw_Data_Daily!$D$2:$D$9999*Raw_Data_Daily!$H$2:$H$9999/100)/SUMIFS(Raw_Data_Daily!$D:$D, Raw_Data_Daily!$B:$B, "Control", Raw_Data_Daily!$C:$C, "D. 20-39")*100,"") -> 3.585867 | M10: =IFERROR(SUMPRODUCT((Raw_Data_Daily!$B$2:$B$9999="Variant")*(Raw_Data_Daily!$C$2:$C$9999="D. 20-39")*Raw_Data_Daily!$D$2:$D$9999*Raw_Data_Daily!$H$2:$H$9999/100)/SUMIFS(Raw_Data_Daily!$D:$D, Raw_Data_Daily!$B:$B, "Variant", Raw_Data_Daily!$C:$C, "D. 20-39")*100,"") -> 3.3228106 | N10: =IFERROR((M10-L10)/ABS(L10),"") -> -0.073359244 | O10: =IFERROR(SUMPRODUCT((Raw_Data_Daily!$B$2:$B$9999="Control")*(Raw_Data_Daily!$C$2:$C$9999="E. 40-99")*Raw_Data_Daily!$D$2:$D$9999*Raw_Data_Daily!$H$2:$H$9999/100)/SUMIFS(Raw_Data_Daily!$D:$D, Raw_Data_Daily!$B:$B, "Control", Raw_Data_Daily!$C:$C, "E. 40-99")*100,"") -> 5.796026 | P10: =IFERROR(SUMPRODUCT((Raw_Data_Daily!$B$2:$B$9999="Variant")*(Raw_Data_Daily!$C$2:$C$9999="E. 40-99")*Raw_Data_Daily!$D$2:$D$9999*Raw_Data_Daily!$H$2:$H$9999/100)/SUMIFS(Raw_Data_Daily!$D:$D, Raw_Data_Daily!$B:$B, "Variant", Raw_Data_Daily!$C:$C, "E. 40-99")*100,"") -> 5.3695798 | Q10: =IFERROR((P10-O10)/ABS(O10),"") -> -0.07357562 | R10: =IFERROR(SUMPRODUCT((Raw_Data_Daily!$B$2:$B$9999="Control")*(Raw_Data_Daily!$C$2:$C$9999="F. 100+")*Raw_Data_Daily!$D$2:$D$9999*Raw_Data_Daily!$H$2:$H$9999/100)/SUMIFS(Raw_Data_Daily!$D:$D, Raw_Data_Daily!$B:$B, "Control", Raw_Data_Daily!$C:$C, "F. 100+")*100,"") -> 8.2295237 | S10: =IFERROR(SUMPRODUCT((Raw_Data_Daily!$B$2:$B$9999="Variant")*(Raw_Data_Daily!$C$2:$C$9999="F. 100+")*Raw_Data_Daily!$D$2:$D$9999*Raw_Data_Daily!$H$2:$H$9999/100)/SUMIFS(Raw_Data_Daily!$D:$D, Raw_Data_Daily!$B:$B, "Variant", Raw_Data_Daily!$C:$C, "F. 100+")*100,"") -> 7.674633 | T10: =IFERROR((S10-R10)/ABS(R10),"") -> -0.067426833
B11: ARPPU | C11: =IFERROR(SUMIFS(Raw_Data_Daily!$F:$F, Raw_Data_Daily!$B:$B, "Control", Raw_Data_Daily!$C:$C, "A. 0")/SUMPRODUCT((Raw_Data_Daily!$B$2:$B$9999="Control")*(Raw_Data_Daily!$C$2:$C$9999="A. 0")*Raw_Data_Daily!$D$2:$D$9999*Raw_Data_Daily!$H$2:$H$9999/100),"") | D11: =IFERROR(SUMIFS(Raw_Data_Daily!$F:$F, Raw_Data_Daily!$B:$B, "Variant", Raw_Data_Daily!$C:$C, "A. 0")/SUMPRODUCT((Raw_Data_Daily!$B$2:$B$9999="Variant")*(Raw_Data_Daily!$C$2:$C$9999="A. 0")*Raw_Data_Daily!$D$2:$D$9999*Raw_Data_Daily!$H$2:$H$9999/100),"") | E11: =IFERROR((D11-C11)/ABS(C11),"") | F11: =IFERROR(SUMIFS(Raw_Data_Daily!$F:$F, Raw_Data_Daily!$B:$B, "Control", Raw_Data_Daily!$C:$C, "B. 1-9")/SUMPRODUCT((Raw_Data_Daily!$B$2:$B$9999="Control")*(Raw_Data_Daily!$C$2:$C$9999="B. 1-9")*Raw_Data_Daily!$D$2:$D$9999*Raw_Data_Daily!$H$2:$H$9999/100),"") -> 2.5825947 | G11: =IFERROR(SUMIFS(Raw_Data_Daily!$F:$F, Raw_Data_Daily!$B:$B, "Variant", Raw_Data_Daily!$C:$C, "B. 1-9")/SUMPRODUCT((Raw_Data_Daily!$B$2:$B$9999="Variant")*(Raw_Data_Daily!$C$2:$C$9999="B. 1-9")*Raw_Data_Daily!$D$2:$D$9999*Raw_Data_Daily!$H$2:$H$9999/100),"") -> 2.7008358 | H11: =IFERROR((G11-F11)/ABS(F11),"") -> 0.045783835 | I11: =IFERROR(SUMIFS(Raw_Data_Daily!$F:$F, Raw_Data_Daily!$B:$B, "Control", Raw_Data_Daily!$C:$C, "C. 10-19")/SUMPRODUCT((Raw_Data_Daily!$B$2:$B$9999="Control")*(Raw_Data_Daily!$C$2:$C$9999="C. 10-19")*Raw_Data_Daily!$D$2:$D$9999*Raw_Data_Daily!$H$2:$H$9999/100),"") -> 3.583742 | J11: =IFERROR(SUMIFS(Raw_Data_Daily!$F:$F, Raw_Data_Daily!$B:$B, "Variant", Raw_Data_Daily!$C:$C, "C. 10-19")/SUMPRODUCT((Raw_Data_Daily!$B$2:$B$9999="Variant")*(Raw_Data_Daily!$C$2:$C$9999="C. 10-19")*Raw_Data_Daily!$D$2:$D$9999*Raw_Data_Daily!$H$2:$H$9999/100),"") -> 3.629101 | K11: =IFERROR((J11-I11)/ABS(I11),"") -> 0.012656889 | L11: =IFERROR(SUMIFS(Raw_Data_Daily!$F:$F, Raw_Data_Daily!$B:$B, "Control", Raw_Data_Daily!$C:$C, "D. 20-39")/SUMPRODUCT((Raw_Data_Daily!$B$2:$B$9999="Control")*(Raw_Data_Daily!$C$2:$C$9999="D. 20-39")*Raw_Data_Daily!$D$2:$D$9999*Raw_Data_Daily!$H$2:$H$9999/100),"") -> 5.0225851 | M11: =IFERROR(SUMIFS(Raw_Data_Daily!$F:$F, Raw_Data_Daily!$B:$B, "Variant", Raw_Data_Daily!$C:$C, "D. 20-39")/SUMPRODUCT((Raw_Data_Daily!$B$2:$B$9999="Variant")*(Raw_Data_Daily!$C$2:$C$9999="D. 20-39")*Raw_Data_Daily!$D$2:$D$9999*Raw_Data_Daily!$H$2:$H$9999/100),"") -> 4.2329556 | N11: =IFERROR((M11-L11)/ABS(L11),"") -> -0.15721575 | O11: =IFERROR(SUMIFS(Raw_Data_Daily!$F:$F, Raw_Data_Daily!$B:$B, "Control", Raw_Data_Daily!$C:$C, "E. 40-99")/SUMPRODUCT((Raw_Data_Daily!$B$2:$B$9999="Control")*(Raw_Data_Daily!$C$2:$C$9999="E. 40-99")*Raw_Data_Daily!$D$2:$D$9999*Raw_Data_Daily!$H$2:$H$9999/100),"") -> 6.5802824 | P11: =IFERROR(SUMIFS(Raw_Data_Daily!$F:$F, Raw_Data_Daily!$B:$B, "Variant", Raw_Data_Daily!$C:$C, "E. 40-99")/SUMPRODUCT((Raw_Data_Daily!$B$2:$B$9999="Variant")*(Raw_Data_Daily!$C$2:$C$9999="E. 40-99")*Raw_Data_Daily!$D$2:$D$9999*Raw_Data_Daily!$H$2:$H$9999/100),"") -> 6.5736025 | Q11: =IFERROR((P11-O11)/ABS(O11),"") -> -0.0010151444 | R11: =IFERROR(SUMIFS(Raw_Data_Daily!$F:$F, Raw_Data_Daily!$B:$B, "Control", Raw_Data_Daily!$C:$C, "F. 100+")/SUMPRODUCT((Raw_Data_Daily!$B$2:$B$9999="Control")*(Raw_Data_Daily!$C$2:$C$9999="F. 100+")*Raw_Data_Daily!$D$2:$D$9999*Raw_Data_Daily!$H$2:$H$9999/100),"") -> 10.620395 | S11: =IFERROR(SUMIFS(Raw_Data_Daily!$F:$F, Raw_Data_Daily!$B:$B, "Variant", Raw_Data_Daily!$C:$C, "F. 100+")/SUMPRODUCT((Raw_Data_Daily!$B$2:$B$9999="Variant")*(Raw_Data_Daily!$C$2:$C$9999="F. 100+")*Raw_Data_Daily!$D$2:$D$9999*Raw_Data_Daily!$H$2:$H$9999/100),"") -> 11.474165 | T11: =IFERROR((S11-R11)/ABS(R11),"") -> 0.080389716
A12: Engagement
B13: Time spent (mins) | C13: =IFERROR(SUMPRODUCT((Raw_Data_Daily!$B$2:$B$9999="Control")*(Raw_Data_Daily!$C$2:$C$9999="A. 0")*Raw_Data_Daily!$D$2:$D$9999*Raw_Data_Daily!$J$2:$J$9999)/SUMIFS(Raw_Data_Daily!$D:$D, Raw_Data_Daily!$B:$B, "Control", Raw_Data_Daily!$C:$C, "A. 0"),"") | D13: =IFERROR(SUMPRODUCT((Raw_Data_Daily!$B$2:$B$9999="Variant")*(Raw_Data_Daily!$C$2:$C$9999="A. 0")*Raw_Data_Daily!$D$2:$D$9999*Raw_Data_Daily!$J$2:$J$9999)/SUMIFS(Raw_Data_Daily!$D:$D, Raw_Data_Daily!$B:$B, "Variant", Raw_Data_Daily!$C:$C, "A. 0"),"") | E13: =IFERROR((D13-C13)/ABS(C13),"") | F13: =IFERROR(SUMPRODUCT((Raw_Data_Daily!$B$2:$B$9999="Control")*(Raw_Data_Daily!$C$2:$C$9999="B. 1-9")*Raw_Data_Daily!$D$2:$D$9999*Raw_Data_Daily!$J$2:$J$9999)/SUMIFS(Raw_Data_Daily!$D:$D, Raw_Data_Daily!$B:$B, "Control", Raw_Data_Daily!$C:$C, "B. 1-9"),"") -> 30.071323 | G13: =IFERROR(SUMPRODUCT((Raw_Data_Daily!$B$2:$B$9999="Variant")*(Raw_Data_Daily!$C$2:$C$9999="B. 1-9")*Raw_Data_Daily!$D$2:$D$9999*Raw_Data_Daily!$J$2:$J$9999)/SUMIFS(Raw_Data_Daily!$D:$D, Raw_Data_Daily!$B:$B, "Variant", Raw_Data_Daily!$C:$C, "B. 1-9"),"") -> 29.186232 | H13: =IFERROR((G13-F13)/ABS(F13),"") -> -0.029433072 | I13: =IFERROR(SUMPRODUCT((Raw_Data_Daily!$B$2:$B$9999="Control")*(Raw_Data_Daily!$C$2:$C$9999="C. 10-19")*Raw_Data_Daily!$D$2:$D$9999*Raw_Data_Daily!$J$2:$J$9999)/SUMIFS(Raw_Data_Daily!$D:$D, Raw_Data_Daily!$B:$B, "Control", Raw_Data_Daily!$C:$C, "C. 10-19"),"") -> 47.621869 | J13: =IFERROR(SUMPRODUCT((Raw_Data_Daily!$B$2:$B$9999="Variant")*(Raw_Data_Daily!$C$2:$C$9999="C. 10-19")*Raw_Data_Daily!$D$2:$D$9999*Raw_Data_Daily!$J$2:$J$9999)/SUMIFS(Raw_Data_Daily!$D:$D, Raw_Data_Daily!$B:$B, "Variant", Raw_Data_Daily!$C:$C, "C. 10-19"),"") -> 49.201179 | K13: =IFERROR((J13-I13)/ABS(I13),"") -> 0.033163543 | L13: =IFERROR(SUMPRODUCT((Raw_Data_Daily!$B$2:$B$9999="Control")*(Raw_Data_Daily!$C$2:$C$9999="D. 20-39")*Raw_Data_Daily!$D$2:$D$9999*Raw_Data_Daily!$J$2:$J$9999)/SUMIFS(Raw_Data_Daily!$D:$D, Raw_Data_Daily!$B:$B, "Control", Raw_Data_Daily!$C:$C, "D. 20-39"),"") -> 69.43421 | M13: =IFERROR(SUMPRODUCT((Raw_Data_Daily!$B$2:$B$9999="Variant")*(Raw_Data_Daily!$C$2:$C$9999="D. 20-39")*Raw_Data_Daily!$D$2:$D$9999*Raw_Data_Daily!$J$2:$J$9999)/SUMIFS(Raw_Data_Daily!$D:$D, Raw_Data_Daily!$B:$B, "Variant", Raw_Data_Daily!$C:$C, "D. 20-39"),"") -> 72.482553 | N13: =IFERROR((M13-L13)/ABS(L13),"") -> 0.043902616 | O13: =IFERROR(SUMPRODUCT((Raw_Data_Daily!$B$2:$B$9999="Control")*(Raw_Data_Daily!$C$2:$C$9999="E. 40-99")*Raw_Data_Daily!$D$2:$D$9999*Raw_Data_Daily!$J$2:$J$9999)/SUMIFS(Raw_Data_Daily!$D:$D, Raw_Data_Daily!$B:$B, "Control", Raw_Data_Daily!$C:$C, "E. 40-99"),"") -> 112.438 | P13: =IFERROR(SUMPRODUCT((Raw_Data_Daily!$B$2:$B$9999="Variant")*(Raw_Data_Daily!$C$2:$C$9999="E. 40-99")*Raw_Data_Daily!$D$2:$D$9999*Raw_Data_Daily!$J$2:$J$9999)/SUMIFS(Raw_Data_Daily!$D:$D, Raw_Data_Daily!$B:$B, "Variant", Raw_Data_Daily!$C:$C, "E. 40-99"),"") -> 116.07129 | Q13: =IFERROR((P13-O13)/ABS(O13),"") -> 0.032313796 | R13: =IFERROR(SUMPRODUCT((Raw_Data_Daily!$B$2:$B$9999="Control")*(Raw_Data_Daily!$C$2:$C$9999="F. 100+")*Raw_Data_Daily!$D$2:$D$9999*Raw_Data_Daily!$J$2:$J$9999)/SUMIFS(Raw_Data_Daily!$D:$D, Raw_Data_Daily!$B:$B, "Control", Raw_Data_Daily!$C:$C, "F. 100+"),"") -> 203.28532 | S13: =IFERROR(SUMPRODUCT((Raw_Data_Daily!$B$2:$B$9999="Variant")*(Raw_Data_Daily!$C$2:$C$9999="F. 100+")*Raw_Data_Daily!$D$2:$D$9999*Raw_Data_Daily!$J$2:$J$9999)/SUMIFS(Raw_Data_Daily!$D:$D, Raw_Data_Daily!$B:$B, "Variant", Raw_Data_Daily!$C:$C, "F. 100+"),"") -> 207.22478 | T13: =IFERROR((S13-R13)/ABS(R13),"") -> 0.019378945
B14: Level attempts / player | C14: =IFERROR(SUMPRODUCT((Raw_Data_Daily!$B$2:$B$9999="Control")*(Raw_Data_Daily!$C$2:$C$9999="A. 0")*Raw_Data_Daily!$D$2:$D$9999*Raw_Data_Daily!$K$2:$K$9999)/SUMIFS(Raw_Data_Daily!$D:$D, Raw_Data_Daily!$B:$B, "Control", Raw_Data_Daily!$C:$C, "A. 0"),"") | D14: =IFERROR(SUMPRODUCT((Raw_Data_Daily!$B$2:$B$9999="Variant")*(Raw_Data_Daily!$C$2:$C$9999="A. 0")*Raw_Data_Daily!$D$2:$D$9999*Raw_Data_Daily!$K$2:$K$9999)/SUMIFS(Raw_Data_Daily!$D:$D, Raw_Data_Daily!$B:$B, "Variant", Raw_Data_Daily!$C:$C, "A. 0"),"") | E14: =IFERROR((D14-C14)/ABS(C14),"") | F14: =IFERROR(SUMPRODUCT((Raw_Data_Daily!$B$2:$B$9999="Control")*(Raw_Data_Daily!$C$2:$C$9999="B. 1-9")*Raw_Data_Daily!$D$2:$D$9999*Raw_Data_Daily!$K$2:$K$9999)/SUMIFS(Raw_Data_Daily!$D:$D, Raw_Data_Daily!$B:$B, "Control", Raw_Data_Daily!$C:$C, "B. 1-9"),"") -> 15.095945 | G14: =IFERROR(SUMPRODUCT((Raw_Data_Daily!$B$2:$B$9999="Variant")*(Raw_Data_Daily!$C$2:$C$9999="B. 1-9")*Raw_Data_Daily!$D$2:$D$9999*Raw_Data_Daily!$K$2:$K$9999)/SUMIFS(Raw_Data_Daily!$D:$D, Raw_Data_Daily!$B:$B, "Variant", Raw_Data_Daily!$C:$C, "B. 1-9"),"") -> 14.415164 | H14: =IFERROR((G14-F14)/ABS(F14),"") -> -0.045096939 | I14: =IFERROR(SUMPRODUCT((Raw_Data_Daily!$B$2:$B$9999="Control")*(Raw_Data_Daily!$C$2:$C$9999="C. 10-19")*Raw_Data_Daily!$D$2:$D$9999*Raw_Data_Daily!$K$2:$K$9999)/SUMIFS(Raw_Data_Daily!$D:$D, Raw_Data_Daily!$B:$B, "Control", Raw_Data_Daily!$C:$C, "C. 10-19"),"") -> 24.721275 | J14: =IFERROR(SUMPRODUCT((Raw_Data_Daily!$B$2:$B$9999="Variant")*(Raw_Data_Daily!$C$2:$C$9999="C. 10-19")*Raw_Data_Daily!$D$2:$D$9999*Raw_Data_Daily!$K$2:$K$9999)/SUMIFS(Raw_Data_Daily!$D:$D, Raw_Data_Daily!$B:$B, "Variant", Raw_Data_Daily!$C:$C, "C. 10-19"),"") -> 25.366312 | K14: =IFERROR((J14-I14)/ABS(I14),"") -> 0.026092387 | L14: =IFERROR(SUMPRODUCT((Raw_Data_Daily!$B$2:$B$9999="Control")*(Raw_Data_Daily!$C$2:$C$9999="D. 20-39")*Raw_Data_Daily!$D$2:$D$9999*Raw_Data_Daily!$K$2:$K$9999)/SUMIFS(Raw_Data_Daily!$D:$D, Raw_Data_Daily!$B:$B, "Control", Raw_Data_Daily!$C:$C, "D. 20-39"),"") -> 37.863267 | M14: =IFERROR(SUMPRODUCT((Raw_Data_Daily!$B$2:$B$9999="Variant")*(Raw_Data_Daily!$C$2:$C$9999="D. 20-39")*Raw_Data_Daily!$D$2:$D$9999*Raw_Data_Daily!$K$2:$K$9999)/SUMIFS(Raw_Data_Daily!$D:$D, Raw_Data_Daily!$B:$B, "Variant", Raw_Data_Daily!$C:$C, "D. 20-39"),"") -> 39.406311 | N14: =IFERROR((M14-L14)/ABS(L14),"") -> 0.04075307 | O14: =IFERROR(SUMPRODUCT((Raw_Data_Daily!$B$2:$B$9999="Control")*(Raw_Data_Daily!$C$2:$C$9999="E. 40-99")*Raw_Data_Daily!$D$2:$D$9999*Raw_Data_Daily!$K$2:$K$9999)/SUMIFS(Raw_Data_Daily!$D:$D, Raw_Data_Daily!$B:$B, "Control", Raw_Data_Daily!$C:$C, "E. 40-99"),"") -> 65.470065 | P14: =IFERROR(SUMPRODUCT((Raw_Data_Daily!$B$2:$B$9999="Variant")*(Raw_Data_Daily!$C$2:$C$9999="E. 40-99")*Raw_Data_Daily!$D$2:$D$9999*Raw_Data_Daily!$K$2:$K$9999)/SUMIFS(Raw_Data_Daily!$D:$D, Raw_Data_Daily!$B:$B, "Variant", Raw_Data_Daily!$C:$C, "E. 40-99"),"") -> 67.576095 | Q14: =IFERROR((P14-O14)/ABS(O14),"") -> 0.032167828 | R14: =IFERROR(SUMPRODUCT((Raw_Data_Daily!$B$2:$B$9999="Control")*(Raw_Data_Daily!$C$2:$C$9999="F. 100+")*Raw_Data_Daily!$D$2:$D$9999*Raw_Data_Daily!$K$2:$K$9999)/SUMIFS(Raw_Data_Daily!$D:$D, Raw_Data_Daily!$B:$B, "Control", Raw_Data_Daily!$C:$C, "F. 100+"),"") -> 127.15287 | S14: =IFERROR(SUMPRODUCT((Raw_Data_Daily!$B$2:$B$9999="Variant")*(Raw_Data_Daily!$C$2:$C$9999="F. 100+")*Raw_Data_Daily!$D$2:$D$9999*Raw_Data_Daily!$K$2:$K$9999)/SUMIFS(Raw_Data_Daily!$D:$D, Raw_Data_Daily!$B:$B, "Variant", Raw_Data_Daily!$C:$C, "F. 100+"),"") -> 127.10057 | T14: =IFERROR((S14-R14)/ABS(R14),"") -> -0.00041128899
B15: Level completes / player | C15: =IFERROR(SUMPRODUCT((Raw_Data_Daily!$B$2:$B$9999="Control")*(Raw_Data_Daily!$C$2:$C$9999="A. 0")*Raw_Data_Daily!$D$2:$D$9999*Raw_Data_Daily!$L$2:$L$9999)/SUMIFS(Raw_Data_Daily!$D:$D, Raw_Data_Daily!$B:$B, "Control", Raw_Data_Daily!$C:$C, "A. 0"),"") | D15: =IFERROR(SUMPRODUCT((Raw_Data_Daily!$B$2:$B$9999="Variant")*(Raw_Data_Daily!$C$2:$C$9999="A. 0")*Raw_Data_Daily!$D$2:$D$9999*Raw_Data_Daily!$L$2:$L$9999)/SUMIFS(Raw_Data_Daily!$D:$D, Raw_Data_Daily!$B:$B, "Variant", Raw_Data_Daily!$C:$C, "A. 0"),"") | E15: =IFERROR((D15-C15)/ABS(C15),"") | F15: =IFERROR(SUMPRODUCT((Raw_Data_Daily!$B$2:$B$9999="Control")*(Raw_Data_Daily!$C$2:$C$9999="B. 1-9")*Raw_Data_Daily!$D$2:$D$9999*Raw_Data_Daily!$L$2:$L$9999)/SUMIFS(Raw_Data_Daily!$D:$D, Raw_Data_Daily!$B:$B, "Control", Raw_Data_Daily!$C:$C, "B. 1-9"),"") -> 6.722395 | G15: =IFERROR(SUMPRODUCT((Raw_Data_Daily!$B$2:$B$9999="Variant")*(Raw_Data_Daily!$C$2:$C$9999="B. 1-9")*Raw_Data_Daily!$D$2:$D$9999*Raw_Data_Daily!$L$2:$L$9999)/SUMIFS(Raw_Data_Daily!$D:$D, Raw_Data_Daily!$B:$B, "Variant", Raw_Data_Daily!$C:$C, "B. 1-9"),"") -> 6.6148438 | H15: =IFERROR((G15-F15)/ABS(F15),"") -> -0.01599894 | I15: =IFERROR(SUMPRODUCT((Raw_Data_Daily!$B$2:$B$9999="Control")*(Raw_Data_Daily!$C$2:$C$9999="C. 10-19")*Raw_Data_Daily!$D$2:$D$9999*Raw_Data_Daily!$L$2:$L$9999)/SUMIFS(Raw_Data_Daily!$D:$D, Raw_Data_Daily!$B:$B, "Control", Raw_Data_Daily!$C:$C, "C. 10-19"),"") -> 13.855513 | J15: =IFERROR(SUMPRODUCT((Raw_Data_Daily!$B$2:$B$9999="Variant")*(Raw_Data_Daily!$C$2:$C$9999="C. 10-19")*Raw_Data_Daily!$D$2:$D$9999*Raw_Data_Daily!$L$2:$L$9999)/SUMIFS(Raw_Data_Daily!$D:$D, Raw_Data_Daily!$B:$B, "Variant", Raw_Data_Daily!$C:$C, "C. 10-19"),"") -> 13.907123 | K15: =IFERROR((J15-I15)/ABS(I15),"") -> 0.0037248865 | L15: =IFERROR(SUMPRODUCT((Raw_Data_Daily!$B$2:$B$9999="Control")*(Raw_Data_Daily!$C$2:$C$9999="D. 20-39")*Raw_Data_Daily!$D$2:$D$9999*Raw_Data_Daily!$L$2:$L$9999)/SUMIFS(Raw_Data_Daily!$D:$D, Raw_Data_Daily!$B:$B, "Control", Raw_Data_Daily!$C:$C, "D. 20-39"),"") -> 24.538213 | M15: =IFERROR(SUMPRODUCT((Raw_Data_Daily!$B$2:$B$9999="Variant")*(Raw_Data_Daily!$C$2:$C$9999="D. 20-39")*Raw_Data_Daily!$D$2:$D$9999*Raw_Data_Daily!$L$2:$L$9999)/SUMIFS(Raw_Data_Daily!$D:$D, Raw_Data_Daily!$B:$B, "Variant", Raw_Data_Daily!$C:$C, "D. 20-39"),"") -> 25.306149 | N15: =IFERROR((M15-L15)/ABS(L15),"") -> 0.031295491 | O15: =IFERROR(SUMPRODUCT((Raw_Data_Daily!$B$2:$B$9999="Control")*(Raw_Data_Daily!$C$2:$C$9999="E. 40-99")*Raw_Data_Daily!$D$2:$D$9999*Raw_Data_Daily!$L$2:$L$9999)/SUMIFS(Raw_Data_Daily!$D:$D, Raw_Data_Daily!$B:$B, "Control", Raw_Data_Daily!$C:$C, "E. 40-99"),"") -> 47.338767 | P15: =IFERROR(SUMPRODUCT((Raw_Data_Daily!$B$2:$B$9999="Variant")*(Raw_Data_Daily!$C$2:$C$9999="E. 40-99")*Raw_Data_Daily!$D$2:$D$9999*Raw_Data_Daily!$L$2:$L$9999)/SUMIFS(Raw_Data_Daily!$D:$D, Raw_Data_Daily!$B:$B, "Variant", Raw_Data_Daily!$C:$C, "E. 40-99"),"") -> 48.998214 | Q15: =IFERROR((P15-O15)/ABS(O15),"") -> 0.035054726 | R15: =IFERROR(SUMPRODUCT((Raw_Data_Daily!$B$2:$B$9999="Control")*(Raw_Data_Daily!$C$2:$C$9999="F. 100+")*Raw_Data_Daily!$D$2:$D$9999*Raw_Data_Daily!$L$2:$L$9999)/SUMIFS(Raw_Data_Daily!$D:$D, Raw_Data_Daily!$B:$B, "Control", Raw_Data_Daily!$C:$C, "F. 100+"),"") -> 99.081435 | S15: =IFERROR(SUMPRODUCT((Raw_Data_Daily!$B$2:$B$9999="Variant")*(Raw_Data_Daily!$C$2:$C$9999="F. 100+")*Raw_Data_Daily!$D$2:$D$9999*Raw_Data_Daily!$L$2:$L$9999)/SUMIFS(Raw_Data_Daily!$D:$D, Raw_Data_Daily!$B:$B, "Variant", Raw_Data_Daily!$C:$C, "F. 100+"),"") -> 99.243143 | T15: =IFERROR((S15-R15)/ABS(R15),"") -> 0.0016320803
A16: Daily Streak
B17: Avg daily streak | C17: =IFERROR(SUMPRODUCT((Raw_Data_Daily!$B$2:$B$9999="Control")*(Raw_Data_Daily!$C$2:$C$9999="A. 0")*Raw_Data_Daily!$D$2:$D$9999*Raw_Data_Daily!$AD$2:$AD$9999)/SUMIFS(Raw_Data_Daily!$D:$D, Raw_Data_Daily!$B:$B, "Control", Raw_Data_Daily!$C:$C, "A. 0"),"") | D17: =IFERROR(SUMPRODUCT((Raw_Data_Daily!$B$2:$B$9999="Variant")*(Raw_Data_Daily!$C$2:$C$9999="A. 0")*Raw_Data_Daily!$D$2:$D$9999*Raw_Data_Daily!$AD$2:$AD$9999)/SUMIFS(Raw_Data_Daily!$D:$D, Raw_Data_Daily!$B:$B, "Variant", Raw_Data_Daily!$C:$C, "A. 0"),"") | E17: =IFERROR((D17-C17)/ABS(C17),"") | F17: =IFERROR(SUMPRODUCT((Raw_Data_Daily!$B$2:$B$9999="Control")*(Raw_Data_Daily!$C$2:$C$9999="B. 1-9")*Raw_Data_Daily!$D$2:$D$9999*Raw_Data_Daily!$AD$2:$AD$9999)/SUMIFS(Raw_Data_Daily!$D:$D, Raw_Data_Daily!$B:$B, "Control", Raw_Data_Daily!$C:$C, "B. 1-9"),"") -> 6.0474638 | G17: =IFERROR(SUMPRODUCT((Raw_Data_Daily!$B$2:$B$9999="Variant")*(Raw_Data_Daily!$C$2:$C$9999="B. 1-9")*Raw_Data_Daily!$D$2:$D$9999*Raw_Data_Daily!$AD$2:$AD$9999)/SUMIFS(Raw_Data_Daily!$D:$D, Raw_Data_Daily!$B:$B, "Variant", Raw_Data_Daily!$C:$C, "B. 1-9"),"") -> 6.1260475 | H17: =IFERROR((G17-F17)/ABS(F17),"") -> 0.012994482 | I17: =IFERROR(SUMPRODUCT((Raw_Data_Daily!$B$2:$B$9999="Control")*(Raw_Data_Daily!$C$2:$C$9999="C. 10-19")*Raw_Data_Daily!$D$2:$D$9999*Raw_Data_Daily!$AD$2:$AD$9999)/SUMIFS(Raw_Data_Daily!$D:$D, Raw_Data_Daily!$B:$B, "Control", Raw_Data_Daily!$C:$C, "C. 10-19"),"") -> 10.037978 | J17: =IFERROR(SUMPRODUCT((Raw_Data_Daily!$B$2:$B$9999="Variant")*(Raw_Data_Daily!$C$2:$C$9999="C. 10-19")*Raw_Data_Daily!$D$2:$D$9999*Raw_Data_Daily!$AD$2:$AD$9999)/SUMIFS(Raw_Data_Daily!$D:$D, Raw_Data_Daily!$B:$B, "Variant", Raw_Data_Daily!$C:$C, "C. 10-19"),"") -> 10.043603 | K17: =IFERROR((J17-I17)/ABS(I17),"") -> 0.00056040405 | L17: =IFERROR(SUMPRODUCT((Raw_Data_Daily!$B$2:$B$9999="Control")*(Raw_Data_Daily!$C$2:$C$9999="D. 20-39")*Raw_Data_Daily!$D$2:$D$9999*Raw_Data_Daily!$AD$2:$AD$9999)/SUMIFS(Raw_Data_Daily!$D:$D, Raw_Data_Daily!$B:$B, "Control", Raw_Data_Daily!$C:$C, "D. 20-39"),"") -> 15.52879 | M17: =IFERROR(SUMPRODUCT((Raw_Data_Daily!$B$2:$B$9999="Variant")*(Raw_Data_Daily!$C$2:$C$9999="D. 20-39")*Raw_Data_Daily!$D$2:$D$9999*Raw_Data_Daily!$AD$2:$AD$9999)/SUMIFS(Raw_Data_Daily!$D:$D, Raw_Data_Daily!$B:$B, "Variant", Raw_Data_Daily!$C:$C, "D. 20-39"),"") -> 15.80986 | N17: =IFERROR((M17-L17)/ABS(L17),"") -> 0.018099968 | O17: =IFERROR(SUMPRODUCT((Raw_Data_Daily!$B$2:$B$9999="Control")*(Raw_Data_Daily!$C$2:$C$9999="E. 40-99")*Raw_Data_Daily!$D$2:$D$9999*Raw_Data_Daily!$AD$2:$AD$9999)/SUMIFS(Raw_Data_Daily!$D:$D, Raw_Data_Daily!$B:$B, "Control", Raw_Data_Daily!$C:$C, "E. 40-99"),"") -> 26.049572 | P17: =IFERROR(SUMPRODUCT((Raw_Data_Daily!$B$2:$B$9999="Variant")*(Raw_Data_Daily!$C$2:$C$9999="E. 40-99")*Raw_Data_Daily!$D$2:$D$9999*Raw_Data_Daily!$AD$2:$AD$9999)/SUMIFS(Raw_Data_Daily!$D:$D, Raw_Data_Daily!$B:$B, "Variant", Raw_Data_Daily!$C:$C, "E. 40-99"),"") -> 26.183379 | Q17: =IFERROR((P17-O17)/ABS(O17),"") -> 0.0051366233 | R17: =IFERROR(SUMPRODUCT((Raw_Data_Daily!$B$2:$B$9999="Control")*(Raw_Data_Daily!$C$2:$C$9999="F. 100+")*Raw_Data_Daily!$D$2:$D$9999*Raw_Data_Daily!$AD$2:$AD$9999)/SUMIFS(Raw_Data_Daily!$D:$D, Raw_Data_Daily!$B:$B, "Control", Raw_Data_Daily!$C:$C, "F. 100+"),"") -> 43.599098 | S17: =IFERROR(SUMPRODUCT((Raw_Data_Daily!$B$2:$B$9999="Variant")*(Raw_Data_Daily!$C$2:$C$9999="F. 100+")*Raw_Data_Daily!$D$2:$D$9999*Raw_Data_Daily!$AD$2:$AD$9999)/SUMIFS(Raw_Data_Daily!$D:$D, Raw_Data_Daily!$B:$B, "Variant", Raw_Data_Daily!$C:$C, "F. 100+"),"") -> 44.377173 | T17: =IFERROR((S17-R17)/ABS(R17),"") -> 0.017846131
B18: P25 daily streak | C18: =IFERROR(SUMPRODUCT((Raw_Data_Daily!$B$2:$B$9999="Control")*(Raw_Data_Daily!$C$2:$C$9999="A. 0")*Raw_Data_Daily!$D$2:$D$9999*Raw_Data_Daily!$AE$2:$AE$9999)/SUMIFS(Raw_Data_Daily!$D:$D, Raw_Data_Daily!$B:$B, "Control", Raw_Data_Daily!$C:$C, "A. 0"),"") | D18: =IFERROR(SUMPRODUCT((Raw_Data_Daily!$B$2:$B$9999="Variant")*(Raw_Data_Daily!$C$2:$C$9999="A. 0")*Raw_Data_Daily!$D$2:$D$9999*Raw_Data_Daily!$AE$2:$AE$9999)/SUMIFS(Raw_Data_Daily!$D:$D, Raw_Data_Daily!$B:$B, "Variant", Raw_Data_Daily!$C:$C, "A. 0"),"") | E18: =IFERROR((D18-C18)/ABS(C18),"") | F18: =IFERROR(SUMPRODUCT((Raw_Data_Daily!$B$2:$B$9999="Control")*(Raw_Data_Daily!$C$2:$C$9999="B. 1-9")*Raw_Data_Daily!$D$2:$D$9999*Raw_Data_Daily!$AE$2:$AE$9999)/SUMIFS(Raw_Data_Daily!$D:$D, Raw_Data_Daily!$B:$B, "Control", Raw_Data_Daily!$C:$C, "B. 1-9"),"") -> 2 | G18: =IFERROR(SUMPRODUCT((Raw_Data_Daily!$B$2:$B$9999="Variant")*(Raw_Data_Daily!$C$2:$C$9999="B. 1-9")*Raw_Data_Daily!$D$2:$D$9999*Raw_Data_Daily!$AE$2:$AE$9999)/SUMIFS(Raw_Data_Daily!$D:$D, Raw_Data_Daily!$B:$B, "Variant", Raw_Data_Daily!$C:$C, "B. 1-9"),"") -> 2 | H18: =IFERROR((G18-F18)/ABS(F18),"") -> 0 | I18: =IFERROR(SUMPRODUCT((Raw_Data_Daily!$B$2:$B$9999="Control")*(Raw_Data_Daily!$C$2:$C$9999="C. 10-19")*Raw_Data_Daily!$D$2:$D$9999*Raw_Data_Daily!$AE$2:$AE$9999)/SUMIFS(Raw_Data_Daily!$D:$D, Raw_Data_Daily!$B:$B, "Control", Raw_Data_Daily!$C:$C, "C. 10-19"),"") -> 3.332678 | J18: =IFERROR(SUMPRODUCT((Raw_Data_Daily!$B$2:$B$9999="Variant")*(Raw_Data_Daily!$C$2:$C$9999="C. 10-19")*Raw_Data_Daily!$D$2:$D$9999*Raw_Data_Daily!$AE$2:$AE$9999)/SUMIFS(Raw_Data_Daily!$D:$D, Raw_Data_Daily!$B:$B, "Variant", Raw_Data_Daily!$C:$C, "C. 10-19"),"") -> 3.3329267 | K18: =IFERROR((J18-I18)/ABS(I18),"") -> 7.4626651e-05 | L18: =IFERROR(SUMPRODUCT((Raw_Data_Daily!$B$2:$B$9999="Control")*(Raw_Data_Daily!$C$2:$C$9999="D. 20-39")*Raw_Data_Daily!$D$2:$D$9999*Raw_Data_Daily!$AE$2:$AE$9999)/SUMIFS(Raw_Data_Daily!$D:$D, Raw_Data_Daily!$B:$B, "Control", Raw_Data_Daily!$C:$C, "D. 20-39"),"") -> 5.6675358 | M18: =IFERROR(SUMPRODUCT((Raw_Data_Daily!$B$2:$B$9999="Variant")*(Raw_Data_Daily!$C$2:$C$9999="D. 20-39")*Raw_Data_Daily!$D$2:$D$9999*Raw_Data_Daily!$AE$2:$AE$9999)/SUMIFS(Raw_Data_Daily!$D:$D, Raw_Data_Daily!$B:$B, "Variant", Raw_Data_Daily!$C:$C, "D. 20-39"),"") -> 5.3359972 | N18: =IFERROR((M18-L18)/ABS(L18),"") -> -0.058497844 | O18: =IFERROR(SUMPRODUCT((Raw_Data_Daily!$B$2:$B$9999="Control")*(Raw_Data_Daily!$C$2:$C$9999="E. 40-99")*Raw_Data_Daily!$D$2:$D$9999*Raw_Data_Daily!$AE$2:$AE$9999)/SUMIFS(Raw_Data_Daily!$D:$D, Raw_Data_Daily!$B:$B, "Control", Raw_Data_Daily!$C:$C, "E. 40-99"),"") -> 9.8386514 | P18: =IFERROR(SUMPRODUCT((Raw_Data_Daily!$B$2:$B$9999="Variant")*(Raw_Data_Daily!$C$2:$C$9999="E. 40-99")*Raw_Data_Daily!$D$2:$D$9999*Raw_Data_Daily!$AE$2:$AE$9999)/SUMIFS(Raw_Data_Daily!$D:$D, Raw_Data_Daily!$B:$B, "Variant", Raw_Data_Daily!$C:$C, "E. 40-99"),"") -> 9.4959947 | Q18: =IFERROR((P18-O18)/ABS(O18),"") -> -0.0348276 | R18: =IFERROR(SUMPRODUCT((Raw_Data_Daily!$B$2:$B$9999="Control")*(Raw_Data_Daily!$C$2:$C$9999="F. 100+")*Raw_Data_Daily!$D$2:$D$9999*Raw_Data_Daily!$AE$2:$AE$9999)/SUMIFS(Raw_Data_Daily!$D:$D, Raw_Data_Daily!$B:$B, "Control", Raw_Data_Daily!$C:$C, "F. 100+"),"") -> 16.343856 | S18: =IFERROR(SUMPRODUCT((Raw_Data_Daily!$B$2:$B$9999="Variant")*(Raw_Data_Daily!$C$2:$C$9999="F. 100+")*Raw_Data_Daily!$D$2:$D$9999*Raw_Data_Daily!$AE$2:$AE$9999)/SUMIFS(Raw_Data_Daily!$D:$D, Raw_Data_Daily!$B:$B, "Variant", Raw_Data_Daily!$C:$C, "F. 100+"),"") -> 16.307341 | T18: =IFERROR((S18-R18)/ABS(R18),"") -> -0.0022341635
B19: P50 daily streak | C19: =IFERROR(SUMPRODUCT((Raw_Data_Daily!$B$2:$B$9999="Control")*(Raw_Data_Daily!$C$2:$C$9999="A. 0")*Raw_Data_Daily!$D$2:$D$9999*Raw_Data_Daily!$AF$2:$AF$9999)/SUMIFS(Raw_Data_Daily!$D:$D, Raw_Data_Daily!$B:$B, "Control", Raw_Data_Daily!$C:$C, "A. 0"),"") | D19: =IFERROR(SUMPRODUCT((Raw_Data_Daily!$B$2:$B$9999="Variant")*(Raw_Data_Daily!$C$2:$C$9999="A. 0")*Raw_Data_Daily!$D$2:$D$9999*Raw_Data_Daily!$AF$2:$AF$9999)/SUMIFS(Raw_Data_Daily!$D:$D, Raw_Data_Daily!$B:$B, "Variant", Raw_Data_Daily!$C:$C, "A. 0"),"") | E19: =IFERROR((D19-C19)/ABS(C19),"") | F19: =IFERROR(SUMPRODUCT((Raw_Data_Daily!$B$2:$B$9999="Control")*(Raw_Data_Daily!$C$2:$C$9999="B. 1-9")*Raw_Data_Daily!$D$2:$D$9999*Raw_Data_Daily!$AF$2:$AF$9999)/SUMIFS(Raw_Data_Daily!$D:$D, Raw_Data_Daily!$B:$B, "Control", Raw_Data_Daily!$C:$C, "B. 1-9"),"") -> 3.8317915 | G19: =IFERROR(SUMPRODUCT((Raw_Data_Daily!$B$2:$B$9999="Variant")*(Raw_Data_Daily!$C$2:$C$9999="B. 1-9")*Raw_Data_Daily!$D$2:$D$9999*Raw_Data_Daily!$AF$2:$AF$9999)/SUMIFS(Raw_Data_Daily!$D:$D, Raw_Data_Daily!$B:$B, "Variant", Raw_Data_Daily!$C:$C, "B. 1-9"),"") -> 4 | H19: =IFERROR((G19-F19)/ABS(F19),"") -> 0.043898126 | I19: =IFERROR(SUMPRODUCT((Raw_Data_Daily!$B$2:$B$9999="Control")*(Raw_Data_Daily!$C$2:$C$9999="C. 10-19")*Raw_Data_Daily!$D$2:$D$9999*Raw_Data_Daily!$AF$2:$AF$9999)/SUMIFS(Raw_Data_Daily!$D:$D, Raw_Data_Daily!$B:$B, "Control", Raw_Data_Daily!$C:$C, "C. 10-19"),"") -> 7.0012721 | J19: =IFERROR(SUMPRODUCT((Raw_Data_Daily!$B$2:$B$9999="Variant")*(Raw_Data_Daily!$C$2:$C$9999="C. 10-19")*Raw_Data_Daily!$D$2:$D$9999*Raw_Data_Daily!$AF$2:$AF$9999)/SUMIFS(Raw_Data_Daily!$D:$D, Raw_Data_Daily!$B:$B, "Variant", Raw_Data_Daily!$C:$C, "C. 10-19"),"") -> 7 | K19: =IFERROR((J19-I19)/ABS(I19),"") -> -0.00018170225 | L19: =IFERROR(SUMPRODUCT((Raw_Data_Daily!$B$2:$B$9999="Control")*(Raw_Data_Daily!$C$2:$C$9999="D. 20-39")*Raw_Data_Daily!$D$2:$D$9999*Raw_Data_Daily!$AF$2:$AF$9999)/SUMIFS(Raw_Data_Daily!$D:$D, Raw_Data_Daily!$B:$B, "Control", Raw_Data_Daily!$C:$C, "D. 20-39"),"") -> 10.835569 | M19: =IFERROR(SUMPRODUCT((Raw_Data_Daily!$B$2:$B$9999="Variant")*(Raw_Data_Daily!$C$2:$C$9999="D. 20-39")*Raw_Data_Daily!$D$2:$D$9999*Raw_Data_Daily!$AF$2:$AF$9999)/SUMIFS(Raw_Data_Daily!$D:$D, Raw_Data_Daily!$B:$B, "Variant", Raw_Data_Daily!$C:$C, "D. 20-39"),"") -> 11.00567 | N19: =IFERROR((M19-L19)/ABS(L19),"") -> 0.015698369 | O19: =IFERROR(SUMPRODUCT((Raw_Data_Daily!$B$2:$B$9999="Control")*(Raw_Data_Daily!$C$2:$C$9999="E. 40-99")*Raw_Data_Daily!$D$2:$D$9999*Raw_Data_Daily!$AF$2:$AF$9999)/SUMIFS(Raw_Data_Daily!$D:$D, Raw_Data_Daily!$B:$B, "Control", Raw_Data_Daily!$C:$C, "E. 40-99"),"") -> 18.342876 | P19: =IFERROR(SUMPRODUCT((Raw_Data_Daily!$B$2:$B$9999="Variant")*(Raw_Data_Daily!$C$2:$C$9999="E. 40-99")*Raw_Data_Daily!$D$2:$D$9999*Raw_Data_Daily!$AF$2:$AF$9999)/SUMIFS(Raw_Data_Daily!$D:$D, Raw_Data_Daily!$B:$B, "Variant", Raw_Data_Daily!$C:$C, "E. 40-99"),"") -> 18.324841 | Q19: =IFERROR((P19-O19)/ABS(O19),"") -> -0.00098321761 | R19: =IFERROR(SUMPRODUCT((Raw_Data_Daily!$B$2:$B$9999="Control")*(Raw_Data_Daily!$C$2:$C$9999="F. 100+")*Raw_Data_Daily!$D$2:$D$9999*Raw_Data_Daily!$AF$2:$AF$9999)/SUMIFS(Raw_Data_Daily!$D:$D, Raw_Data_Daily!$B:$B, "Control", Raw_Data_Daily!$C:$C, "F. 100+"),"") -> 30.222942 | S19: =IFERROR(SUMPRODUCT((Raw_Data_Daily!$B$2:$B$9999="Variant")*(Raw_Data_Daily!$C$2:$C$9999="F. 100+")*Raw_Data_Daily!$D$2:$D$9999*Raw_Data_Daily!$AF$2:$AF$9999)/SUMIFS(Raw_Data_Daily!$D:$D, Raw_Data_Daily!$B:$B, "Variant", Raw_Data_Daily!$C:$C, "F. 100+"),"") -> 31.268048 | T19: =IFERROR((S19-R19)/ABS(R19),"") -> 0.034579856
B20: P75 daily streak | C20: =IFERROR(SUMPRODUCT((Raw_Data_Daily!$B$2:$B$9999="Control")*(Raw_Data_Daily!$C$2:$C$9999="A. 0")*Raw_Data_Daily!$D$2:$D$9999*Raw_Data_Daily!$AG$2:$AG$9999)/SUMIFS(Raw_Data_Daily!$D:$D, Raw_Data_Daily!$B:$B, "Control", Raw_Data_Daily!$C:$C, "A. 0"),"") | D20: =IFERROR(SUMPRODUCT((Raw_Data_Daily!$B$2:$B$9999="Variant")*(Raw_Data_Daily!$C$2:$C$9999="A. 0")*Raw_Data_Daily!$D$2:$D$9999*Raw_Data_Daily!$AG$2:$AG$9999)/SUMIFS(Raw_Data_Daily!$D:$D, Raw_Data_Daily!$B:$B, "Variant", Raw_Data_Daily!$C:$C, "A. 0"),"") | E20: =IFERROR((D20-C20)/ABS(C20),"") | F20: =IFERROR(SUMPRODUCT((Raw_Data_Daily!$B$2:$B$9999="Control")*(Raw_Data_Daily!$C$2:$C$9999="B. 1-9")*Raw_Data_Daily!$D$2:$D$9999*Raw_Data_Daily!$AG$2:$AG$9999)/SUMIFS(Raw_Data_Daily!$D:$D, Raw_Data_Daily!$B:$B, "Control", Raw_Data_Daily!$C:$C, "B. 1-9"),"") -> 7.6758469 | G20: =IFERROR(SUMPRODUCT((Raw_Data_Daily!$B$2:$B$9999="Variant")*(Raw_Data_Daily!$C$2:$C$9999="B. 1-9")*Raw_Data_Daily!$D$2:$D$9999*Raw_Data_Daily!$AG$2:$AG$9999)/SUMIFS(Raw_Data_Daily!$D:$D, Raw_Data_Daily!$B:$B, "Variant", Raw_Data_Daily!$C:$C, "B. 1-9"),"") -> 7.834428 | H20: =IFERROR((G20-F20)/ABS(F20),"") -> 0.020659758 | I20: =IFERROR(SUMPRODUCT((Raw_Data_Daily!$B$2:$B$9999="Control")*(Raw_Data_Daily!$C$2:$C$9999="C. 10-19")*Raw_Data_Daily!$D$2:$D$9999*Raw_Data_Daily!$AG$2:$AG$9999)/SUMIFS(Raw_Data_Daily!$D:$D, Raw_Data_Daily!$B:$B, "Control", Raw_Data_Daily!$C:$C, "C. 10-19"),"") -> 12.832308 | J20: =IFERROR(SUMPRODUCT((Raw_Data_Daily!$B$2:$B$9999="Variant")*(Raw_Data_Daily!$C$2:$C$9999="C. 10-19")*Raw_Data_Daily!$D$2:$D$9999*Raw_Data_Daily!$AG$2:$AG$9999)/SUMIFS(Raw_Data_Daily!$D:$D, Raw_Data_Daily!$B:$B, "Variant", Raw_Data_Daily!$C:$C, "C. 10-19"),"") -> 13 | K20: =IFERROR((J20-I20)/ABS(I20),"") -> 0.013067961 | L20: =IFERROR(SUMPRODUCT((Raw_Data_Daily!$B$2:$B$9999="Control")*(Raw_Data_Daily!$C$2:$C$9999="D. 20-39")*Raw_Data_Daily!$D$2:$D$9999*Raw_Data_Daily!$AG$2:$AG$9999)/SUMIFS(Raw_Data_Daily!$D:$D, Raw_Data_Daily!$B:$B, "Control", Raw_Data_Daily!$C:$C, "D. 20-39"),"") -> 20.004435 | M20: =IFERROR(SUMPRODUCT((Raw_Data_Daily!$B$2:$B$9999="Variant")*(Raw_Data_Daily!$C$2:$C$9999="D. 20-39")*Raw_Data_Daily!$D$2:$D$9999*Raw_Data_Daily!$AG$2:$AG$9999)/SUMIFS(Raw_Data_Daily!$D:$D, Raw_Data_Daily!$B:$B, "Variant", Raw_Data_Daily!$C:$C, "D. 20-39"),"") -> 20.671994 | N20: =IFERROR((M20-L20)/ABS(L20),"") -> 0.03337055 | O20: =IFERROR(SUMPRODUCT((Raw_Data_Daily!$B$2:$B$9999="Control")*(Raw_Data_Daily!$C$2:$C$9999="E. 40-99")*Raw_Data_Daily!$D$2:$D$9999*Raw_Data_Daily!$AG$2:$AG$9999)/SUMIFS(Raw_Data_Daily!$D:$D, Raw_Data_Daily!$B:$B, "Control", Raw_Data_Daily!$C:$C, "E. 40-99"),"") -> 34.343087 | P20: =IFERROR(SUMPRODUCT((Raw_Data_Daily!$B$2:$B$9999="Variant")*(Raw_Data_Daily!$C$2:$C$9999="E. 40-99")*Raw_Data_Daily!$D$2:$D$9999*Raw_Data_Daily!$AG$2:$AG$9999)/SUMIFS(Raw_Data_Daily!$D:$D, Raw_Data_Daily!$B:$B, "Variant", Raw_Data_Daily!$C:$C, "E. 40-99"),"") -> 34.636638 | Q20: =IFERROR((P20-O20)/ABS(O20),"") -> 0.00854762 | R20: =IFERROR(SUMPRODUCT((Raw_Data_Daily!$B$2:$B$9999="Control")*(Raw_Data_Daily!$C$2:$C$9999="F. 100+")*Raw_Data_Daily!$D$2:$D$9999*Raw_Data_Daily!$AG$2:$AG$9999)/SUMIFS(Raw_Data_Daily!$D:$D, Raw_Data_Daily!$B:$B, "Control", Raw_Data_Daily!$C:$C, "F. 100+"),"") -> 55.248591 | S20: =IFERROR(SUMPRODUCT((Raw_Data_Daily!$B$2:$B$9999="Variant")*(Raw_Data_Daily!$C$2:$C$9999="F. 100+")*Raw_Data_Daily!$D$2:$D$9999*Raw_Data_Daily!$AG$2:$AG$9999)/SUMIFS(Raw_Data_Daily!$D:$D, Raw_Data_Daily!$B:$B, "Variant", Raw_Data_Daily!$C:$C, "F. 100+"),"") -> 55.469997 | T20: =IFERROR((S20-R20)/ABS(R20),"") -> 0.0040074542
B21: P90 daily streak | C21: =IFERROR(SUMPRODUCT((Raw_Data_Daily!$B$2:$B$9999="Control")*(Raw_Data_Daily!$C$2:$C$9999="A. 0")*Raw_Data_Daily!$D$2:$D$9999*Raw_Data_Daily!$AH$2:$AH$9999)/SUMIFS(Raw_Data_Daily!$D:$D, Raw_Data_Daily!$B:$B, "Control", Raw_Data_Daily!$C:$C, "A. 0"),"") | D21: =IFERROR(SUMPRODUCT((Raw_Data_Daily!$B$2:$B$9999="Variant")*(Raw_Data_Daily!$C$2:$C$9999="A. 0")*Raw_Data_Daily!$D$2:$D$9999*Raw_Data_Daily!$AH$2:$AH$9999)/SUMIFS(Raw_Data_Daily!$D:$D, Raw_Data_Daily!$B:$B, "Variant", Raw_Data_Daily!$C:$C, "A. 0"),"") | E21: =IFERROR((D21-C21)/ABS(C21),"") | F21: =IFERROR(SUMPRODUCT((Raw_Data_Daily!$B$2:$B$9999="Control")*(Raw_Data_Daily!$C$2:$C$9999="B. 1-9")*Raw_Data_Daily!$D$2:$D$9999*Raw_Data_Daily!$AH$2:$AH$9999)/SUMIFS(Raw_Data_Daily!$D:$D, Raw_Data_Daily!$B:$B, "Control", Raw_Data_Daily!$C:$C, "B. 1-9"),"") -> 13.671596 | G21: =IFERROR(SUMPRODUCT((Raw_Data_Daily!$B$2:$B$9999="Variant")*(Raw_Data_Daily!$C$2:$C$9999="B. 1-9")*Raw_Data_Daily!$D$2:$D$9999*Raw_Data_Daily!$AH$2:$AH$9999)/SUMIFS(Raw_Data_Daily!$D:$D, Raw_Data_Daily!$B:$B, "Variant", Raw_Data_Daily!$C:$C, "B. 1-9"),"") -> 14.170254 | H21: =IFERROR((G21-F21)/ABS(F21),"") -> 0.036474028 | I21: =IFERROR(SUMPRODUCT((Raw_Data_Daily!$B$2:$B$9999="Control")*(Raw_Data_Daily!$C$2:$C$9999="C. 10-19")*Raw_Data_Daily!$D$2:$D$9999*Raw_Data_Daily!$AH$2:$AH$9999)/SUMIFS(Raw_Data_Daily!$D:$D, Raw_Data_Daily!$B:$B, "Control", Raw_Data_Daily!$C:$C, "C. 10-19"),"") -> 21.99845 | J21: =IFERROR(SUMPRODUCT((Raw_Data_Daily!$B$2:$B$9999="Variant")*(Raw_Data_Daily!$C$2:$C$9999="C. 10-19")*Raw_Data_Daily!$D$2:$D$9999*Raw_Data_Daily!$AH$2:$AH$9999)/SUMIFS(Raw_Data_Daily!$D:$D, Raw_Data_Daily!$B:$B, "Variant", Raw_Data_Daily!$C:$C, "C. 10-19"),"") -> 22.158387 | K21: =IFERROR((J21-I21)/ABS(I21),"") -> 0.0072703618 | L21: =IFERROR(SUMPRODUCT((Raw_Data_Daily!$B$2:$B$9999="Control")*(Raw_Data_Daily!$C$2:$C$9999="D. 20-39")*Raw_Data_Daily!$D$2:$D$9999*Raw_Data_Daily!$AH$2:$AH$9999)/SUMIFS(Raw_Data_Daily!$D:$D, Raw_Data_Daily!$B:$B, "Control", Raw_Data_Daily!$C:$C, "D. 20-39"),"") -> 34.003521 | M21: =IFERROR(SUMPRODUCT((Raw_Data_Daily!$B$2:$B$9999="Variant")*(Raw_Data_Daily!$C$2:$C$9999="D. 20-39")*Raw_Data_Daily!$D$2:$D$9999*Raw_Data_Daily!$AH$2:$AH$9999)/SUMIFS(Raw_Data_Daily!$D:$D, Raw_Data_Daily!$B:$B, "Variant", Raw_Data_Daily!$C:$C, "D. 20-39"),"") -> 35.501174 | N21: =IFERROR((M21-L21)/ABS(L21),"") -> 0.044044057 | O21: =IFERROR(SUMPRODUCT((Raw_Data_Daily!$B$2:$B$9999="Control")*(Raw_Data_Daily!$C$2:$C$9999="E. 40-99")*Raw_Data_Daily!$D$2:$D$9999*Raw_Data_Daily!$AH$2:$AH$9999)/SUMIFS(Raw_Data_Daily!$D:$D, Raw_Data_Daily!$B:$B, "Control", Raw_Data_Daily!$C:$C, "E. 40-99"),"") -> 55.998907 | P21: =IFERROR(SUMPRODUCT((Raw_Data_Daily!$B$2:$B$9999="Variant")*(Raw_Data_Daily!$C$2:$C$9999="E. 40-99")*Raw_Data_Daily!$D$2:$D$9999*Raw_Data_Daily!$AH$2:$AH$9999)/SUMIFS(Raw_Data_Daily!$D:$D, Raw_Data_Daily!$B:$B, "Variant", Raw_Data_Daily!$C:$C, "E. 40-99"),"") -> 58.103874 | Q21: =IFERROR((P21-O21)/ABS(O21),"") -> 0.03758943 | R21: =IFERROR(SUMPRODUCT((Raw_Data_Daily!$B$2:$B$9999="Control")*(Raw_Data_Daily!$C$2:$C$9999="F. 100+")*Raw_Data_Daily!$D$2:$D$9999*Raw_Data_Daily!$AH$2:$AH$9999)/SUMIFS(Raw_Data_Daily!$D:$D, Raw_Data_Daily!$B:$B, "Control", Raw_Data_Daily!$C:$C, "F. 100+"),"") -> 96.537486 | S21: =IFERROR(SUMPRODUCT((Raw_Data_Daily!$B$2:$B$9999="Variant")*(Raw_Data_Daily!$C$2:$C$9999="F. 100+")*Raw_Data_Daily!$D$2:$D$9999*Raw_Data_Daily!$AH$2:$AH$9999)/SUMIFS(Raw_Data_Daily!$D:$D, Raw_Data_Daily!$B:$B, "Variant", Raw_Data_Daily!$C:$C, "F. 100+"),"") -> 99.834603 | T21: =IFERROR((S21-R21)/ABS(R21),"") -> 0.034153744
B22: P99 daily streak | C22: =IFERROR(SUMPRODUCT((Raw_Data_Daily!$B$2:$B$9999="Control")*(Raw_Data_Daily!$C$2:$C$9999="A. 0")*Raw_Data_Daily!$D$2:$D$9999*Raw_Data_Daily!$BC$2:$BC$9999)/SUMIFS(Raw_Data_Daily!$D:$D, Raw_Data_Daily!$B:$B, "Control", Raw_Data_Daily!$C:$C, "A. 0"),"") | D22: =IFERROR(SUMPRODUCT((Raw_Data_Daily!$B$2:$B$9999="Variant")*(Raw_Data_Daily!$C$2:$C$9999="A. 0")*Raw_Data_Daily!$D$2:$D$9999*Raw_Data_Daily!$BC$2:$BC$9999)/SUMIFS(Raw_Data_Daily!$D:$D, Raw_Data_Daily!$B:$B, "Variant", Raw_Data_Daily!$C:$C, "A. 0"),"") | E22: =IFERROR((D22-C22)/ABS(C22),"") | F22: =IFERROR(SUMPRODUCT((Raw_Data_Daily!$B$2:$B$9999="Control")*(Raw_Data_Daily!$C$2:$C$9999="B. 1-9")*Raw_Data_Daily!$D$2:$D$9999*Raw_Data_Daily!$BC$2:$BC$9999)/SUMIFS(Raw_Data_Daily!$D:$D, Raw_Data_Daily!$B:$B, "Control", Raw_Data_Daily!$C:$C, "B. 1-9"),"") -> 33.173485 | G22: =IFERROR(SUMPRODUCT((Raw_Data_Daily!$B$2:$B$9999="Variant")*(Raw_Data_Daily!$C$2:$C$9999="B. 1-9")*Raw_Data_Daily!$D$2:$D$9999*Raw_Data_Daily!$BC$2:$BC$9999)/SUMIFS(Raw_Data_Daily!$D:$D, Raw_Data_Daily!$B:$B, "Variant", Raw_Data_Daily!$C:$C, "B. 1-9"),"") -> 33.006341 | H22: =IFERROR((G22-F22)/ABS(F22),"") -> -0.0050385029 | I22: =IFERROR(SUMPRODUCT((Raw_Data_Daily!$B$2:$B$9999="Control")*(Raw_Data_Daily!$C$2:$C$9999="C. 10-19")*Raw_Data_Daily!$D$2:$D$9999*Raw_Data_Daily!$BC$2:$BC$9999)/SUMIFS(Raw_Data_Daily!$D:$D, Raw_Data_Daily!$B:$B, "Control", Raw_Data_Daily!$C:$C, "C. 10-19"),"") -> 49.492853 | J22: =IFERROR(SUMPRODUCT((Raw_Data_Daily!$B$2:$B$9999="Variant")*(Raw_Data_Daily!$C$2:$C$9999="C. 10-19")*Raw_Data_Daily!$D$2:$D$9999*Raw_Data_Daily!$BC$2:$BC$9999)/SUMIFS(Raw_Data_Daily!$D:$D, Raw_Data_Daily!$B:$B, "Variant", Raw_Data_Daily!$C:$C, "C. 10-19"),"") -> 49.144267 | K22: =IFERROR((J22-I22)/ABS(I22),"") -> -0.0070431456 | L22: =IFERROR(SUMPRODUCT((Raw_Data_Daily!$B$2:$B$9999="Control")*(Raw_Data_Daily!$C$2:$C$9999="D. 20-39")*Raw_Data_Daily!$D$2:$D$9999*Raw_Data_Daily!$BC$2:$BC$9999)/SUMIFS(Raw_Data_Daily!$D:$D, Raw_Data_Daily!$B:$B, "Control", Raw_Data_Daily!$C:$C, "D. 20-39"),"") -> 74.803419 | M22: =IFERROR(SUMPRODUCT((Raw_Data_Daily!$B$2:$B$9999="Variant")*(Raw_Data_Daily!$C$2:$C$9999="D. 20-39")*Raw_Data_Daily!$D$2:$D$9999*Raw_Data_Daily!$BC$2:$BC$9999)/SUMIFS(Raw_Data_Daily!$D:$D, Raw_Data_Daily!$B:$B, "Variant", Raw_Data_Daily!$C:$C, "D. 20-39"),"") -> 74.16758 | N22: =IFERROR((M22-L22)/ABS(L22),"") -> -0.0085001348 | O22: =IFERROR(SUMPRODUCT((Raw_Data_Daily!$B$2:$B$9999="Control")*(Raw_Data_Daily!$C$2:$C$9999="E. 40-99")*Raw_Data_Daily!$D$2:$D$9999*Raw_Data_Daily!$BC$2:$BC$9999)/SUMIFS(Raw_Data_Daily!$D:$D, Raw_Data_Daily!$B:$B, "Control", Raw_Data_Daily!$C:$C, "E. 40-99"),"") -> 124.08912 | P22: =IFERROR(SUMPRODUCT((Raw_Data_Daily!$B$2:$B$9999="Variant")*(Raw_Data_Daily!$C$2:$C$9999="E. 40-99")*Raw_Data_Daily!$D$2:$D$9999*Raw_Data_Daily!$BC$2:$BC$9999)/SUMIFS(Raw_Data_Daily!$D:$D, Raw_Data_Daily!$B:$B, "Variant", Raw_Data_Daily!$C:$C, "E. 40-99"),"") -> 121.24741 | Q22: =IFERROR((P22-O22)/ABS(O22),"") -> -0.02290062 | R22: =IFERROR(SUMPRODUCT((Raw_Data_Daily!$B$2:$B$9999="Control")*(Raw_Data_Daily!$C$2:$C$9999="F. 100+")*Raw_Data_Daily!$D$2:$D$9999*Raw_Data_Daily!$BC$2:$BC$9999)/SUMIFS(Raw_Data_Daily!$D:$D, Raw_Data_Daily!$B:$B, "Control", Raw_Data_Daily!$C:$C, "F. 100+"),"") -> 211.24464 | S22: =IFERROR(SUMPRODUCT((Raw_Data_Daily!$B$2:$B$9999="Variant")*(Raw_Data_Daily!$C$2:$C$9999="F. 100+")*Raw_Data_Daily!$D$2:$D$9999*Raw_Data_Daily!$BC$2:$BC$9999)/SUMIFS(Raw_Data_Daily!$D:$D, Raw_Data_Daily!$B:$B, "Variant", Raw_Data_Daily!$C:$C, "F. 100+"),"") -> 212.58209 | T22: =IFERROR((S22-R22)/ABS(R22),"") -> 0.0063312596
A23: Difficulty
B24: Pass rate | C24: =IFERROR(SUMPRODUCT((Raw_Data_Daily!$B$2:$B$9999="Control")*(Raw_Data_Daily!$C$2:$C$9999="A. 0")*Raw_Data_Daily!$D$2:$D$9999*Raw_Data_Daily!$M$2:$M$9999)/SUMIFS(Raw_Data_Daily!$D:$D, Raw_Data_Daily!$B:$B, "Control", Raw_Data_Daily!$C:$C, "A. 0"),"") | D24: =IFERROR(SUMPRODUCT((Raw_Data_Daily!$B$2:$B$9999="Variant")*(Raw_Data_Daily!$C$2:$C$9999="A. 0")*Raw_Data_Daily!$D$2:$D$9999*Raw_Data_Daily!$M$2:$M$9999)/SUMIFS(Raw_Data_Daily!$D:$D, Raw_Data_Daily!$B:$B, "Variant", Raw_Data_Daily!$C:$C, "A. 0"),"") | E24: =IFERROR((D24-C24)/ABS(C24),"") | F24: =IFERROR(SUMPRODUCT((Raw_Data_Daily!$B$2:$B$9999="Control")*(Raw_Data_Daily!$C$2:$C$9999="B. 1-9")*Raw_Data_Daily!$D$2:$D$9999*Raw_Data_Daily!$M$2:$M$9999)/SUMIFS(Raw_Data_Daily!$D:$D, Raw_Data_Daily!$B:$B, "Control", Raw_Data_Daily!$C:$C, "B. 1-9"),"") -> 0.44532772 | G24: =IFERROR(SUMPRODUCT((Raw_Data_Daily!$B$2:$B$9999="Variant")*(Raw_Data_Daily!$C$2:$C$9999="B. 1-9")*Raw_Data_Daily!$D$2:$D$9999*Raw_Data_Daily!$M$2:$M$9999)/SUMIFS(Raw_Data_Daily!$D:$D, Raw_Data_Daily!$B:$B, "Variant", Raw_Data_Daily!$C:$C, "B. 1-9"),"") -> 0.45878449 | H24: =IFERROR((G24-F24)/ABS(F24),"") -> 0.03021769 | I24: =IFERROR(SUMPRODUCT((Raw_Data_Daily!$B$2:$B$9999="Control")*(Raw_Data_Daily!$C$2:$C$9999="C. 10-19")*Raw_Data_Daily!$D$2:$D$9999*Raw_Data_Daily!$M$2:$M$9999)/SUMIFS(Raw_Data_Daily!$D:$D, Raw_Data_Daily!$B:$B, "Control", Raw_Data_Daily!$C:$C, "C. 10-19"),"") -> 0.56022343 | J24: =IFERROR(SUMPRODUCT((Raw_Data_Daily!$B$2:$B$9999="Variant")*(Raw_Data_Daily!$C$2:$C$9999="C. 10-19")*Raw_Data_Daily!$D$2:$D$9999*Raw_Data_Daily!$M$2:$M$9999)/SUMIFS(Raw_Data_Daily!$D:$D, Raw_Data_Daily!$B:$B, "Variant", Raw_Data_Daily!$C:$C, "C. 10-19"),"") -> 0.54840763 | K24: =IFERROR((J24-I24)/ABS(I24),"") -> -0.021091235 | L24: =IFERROR(SUMPRODUCT((Raw_Data_Daily!$B$2:$B$9999="Control")*(Raw_Data_Daily!$C$2:$C$9999="D. 20-39")*Raw_Data_Daily!$D$2:$D$9999*Raw_Data_Daily!$M$2:$M$9999)/SUMIFS(Raw_Data_Daily!$D:$D, Raw_Data_Daily!$B:$B, "Control", Raw_Data_Daily!$C:$C, "D. 20-39"),"") -> 0.64800585 | M24: =IFERROR(SUMPRODUCT((Raw_Data_Daily!$B$2:$B$9999="Variant")*(Raw_Data_Daily!$C$2:$C$9999="D. 20-39")*Raw_Data_Daily!$D$2:$D$9999*Raw_Data_Daily!$M$2:$M$9999)/SUMIFS(Raw_Data_Daily!$D:$D, Raw_Data_Daily!$B:$B, "Variant", Raw_Data_Daily!$C:$C, "D. 20-39"),"") -> 0.64221963 | N24: =IFERROR((M24-L24)/ABS(L24),"") -> -0.0089292733 | O24: =IFERROR(SUMPRODUCT((Raw_Data_Daily!$B$2:$B$9999="Control")*(Raw_Data_Daily!$C$2:$C$9999="E. 40-99")*Raw_Data_Daily!$D$2:$D$9999*Raw_Data_Daily!$M$2:$M$9999)/SUMIFS(Raw_Data_Daily!$D:$D, Raw_Data_Daily!$B:$B, "Control", Raw_Data_Daily!$C:$C, "E. 40-99"),"") -> 0.72309962 | P24: =IFERROR(SUMPRODUCT((Raw_Data_Daily!$B$2:$B$9999="Variant")*(Raw_Data_Daily!$C$2:$C$9999="E. 40-99")*Raw_Data_Daily!$D$2:$D$9999*Raw_Data_Daily!$M$2:$M$9999)/SUMIFS(Raw_Data_Daily!$D:$D, Raw_Data_Daily!$B:$B, "Variant", Raw_Data_Daily!$C:$C, "E. 40-99"),"") -> 0.7250168 | Q24: =IFERROR((P24-O24)/ABS(O24),"") -> 0.0026513339 | R24: =IFERROR(SUMPRODUCT((Raw_Data_Daily!$B$2:$B$9999="Control")*(Raw_Data_Daily!$C$2:$C$9999="F. 100+")*Raw_Data_Daily!$D$2:$D$9999*Raw_Data_Daily!$M$2:$M$9999)/SUMIFS(Raw_Data_Daily!$D:$D, Raw_Data_Daily!$B:$B, "Control", Raw_Data_Daily!$C:$C, "F. 100+"),"") -> 0.77929352 | S24: =IFERROR(SUMPRODUCT((Raw_Data_Daily!$B$2:$B$9999="Variant")*(Raw_Data_Daily!$C$2:$C$9999="F. 100+")*Raw_Data_Daily!$D$2:$D$9999*Raw_Data_Daily!$M$2:$M$9999)/SUMIFS(Raw_Data_Daily!$D:$D, Raw_Data_Daily!$B:$B, "Variant", Raw_Data_Daily!$C:$C, "F. 100+"),"") -> 0.78058599 | T24: =IFERROR((S24-R24)/ABS(R24),"") -> 0.0016585162
B25: OOM rate | C25: =IFERROR(SUMPRODUCT((Raw_Data_Daily!$B$2:$B$9999="Control")*(Raw_Data_Daily!$C$2:$C$9999="A. 0")*Raw_Data_Daily!$D$2:$D$9999*Raw_Data_Daily!$N$2:$N$9999)/SUMIFS(Raw_Data_Daily!$D:$D, Raw_Data_Daily!$B:$B, "Control", Raw_Data_Daily!$C:$C, "A. 0"),"") | D25: =IFERROR(SUMPRODUCT((Raw_Data_Daily!$B$2:$B$9999="Variant")*(Raw_Data_Daily!$C$2:$C$9999="A. 0")*Raw_Data_Daily!$D$2:$D$9999*Raw_Data_Daily!$N$2:$N$9999)/SUMIFS(Raw_Data_Daily!$D:$D, Raw_Data_Daily!$B:$B, "Variant", Raw_Data_Daily!$C:$C, "A. 0"),"") | E25: =IFERROR((D25-C25)/ABS(C25),"") | F25: =IFERROR(SUMPRODUCT((Raw_Data_Daily!$B$2:$B$9999="Control")*(Raw_Data_Daily!$C$2:$C$9999="B. 1-9")*Raw_Data_Daily!$D$2:$D$9999*Raw_Data_Daily!$N$2:$N$9999)/SUMIFS(Raw_Data_Daily!$D:$D, Raw_Data_Daily!$B:$B, "Control", Raw_Data_Daily!$C:$C, "B. 1-9"),"") -> 0.6743408 | G25: =IFERROR(SUMPRODUCT((Raw_Data_Daily!$B$2:$B$9999="Variant")*(Raw_Data_Daily!$C$2:$C$9999="B. 1-9")*Raw_Data_Daily!$D$2:$D$9999*Raw_Data_Daily!$N$2:$N$9999)/SUMIFS(Raw_Data_Daily!$D:$D, Raw_Data_Daily!$B:$B, "Variant", Raw_Data_Daily!$C:$C, "B. 1-9"),"") -> 0.66415141 | H25: =IFERROR((G25-F25)/ABS(F25),"") -> -0.015110161 | I25: =IFERROR(SUMPRODUCT((Raw_Data_Daily!$B$2:$B$9999="Control")*(Raw_Data_Daily!$C$2:$C$9999="C. 10-19")*Raw_Data_Daily!$D$2:$D$9999*Raw_Data_Daily!$N$2:$N$9999)/SUMIFS(Raw_Data_Daily!$D:$D, Raw_Data_Daily!$B:$B, "Control", Raw_Data_Daily!$C:$C, "C. 10-19"),"") -> 0.58059682 | J25: =IFERROR(SUMPRODUCT((Raw_Data_Daily!$B$2:$B$9999="Variant")*(Raw_Data_Daily!$C$2:$C$9999="C. 10-19")*Raw_Data_Daily!$D$2:$D$9999*Raw_Data_Daily!$N$2:$N$9999)/SUMIFS(Raw_Data_Daily!$D:$D, Raw_Data_Daily!$B:$B, "Variant", Raw_Data_Daily!$C:$C, "C. 10-19"),"") -> 0.58859418 | K25: =IFERROR((J25-I25)/ABS(I25),"") -> 0.01377438 | L25: =IFERROR(SUMPRODUCT((Raw_Data_Daily!$B$2:$B$9999="Control")*(Raw_Data_Daily!$C$2:$C$9999="D. 20-39")*Raw_Data_Daily!$D$2:$D$9999*Raw_Data_Daily!$N$2:$N$9999)/SUMIFS(Raw_Data_Daily!$D:$D, Raw_Data_Daily!$B:$B, "Control", Raw_Data_Daily!$C:$C, "D. 20-39"),"") -> 0.50111409 | M25: =IFERROR(SUMPRODUCT((Raw_Data_Daily!$B$2:$B$9999="Variant")*(Raw_Data_Daily!$C$2:$C$9999="D. 20-39")*Raw_Data_Daily!$D$2:$D$9999*Raw_Data_Daily!$N$2:$N$9999)/SUMIFS(Raw_Data_Daily!$D:$D, Raw_Data_Daily!$B:$B, "Variant", Raw_Data_Daily!$C:$C, "D. 20-39"),"") -> 0.50524016 | N25: =IFERROR((M25-L25)/ABS(L25),"") -> 0.0082337977 | O25: =IFERROR(SUMPRODUCT((Raw_Data_Daily!$B$2:$B$9999="Control")*(Raw_Data_Daily!$C$2:$C$9999="E. 40-99")*Raw_Data_Daily!$D$2:$D$9999*Raw_Data_Daily!$N$2:$N$9999)/SUMIFS(Raw_Data_Daily!$D:$D, Raw_Data_Daily!$B:$B, "Control", Raw_Data_Daily!$C:$C, "E. 40-99"),"") -> 0.42715033 | P25: =IFERROR(SUMPRODUCT((Raw_Data_Daily!$B$2:$B$9999="Variant")*(Raw_Data_Daily!$C$2:$C$9999="E. 40-99")*Raw_Data_Daily!$D$2:$D$9999*Raw_Data_Daily!$N$2:$N$9999)/SUMIFS(Raw_Data_Daily!$D:$D, Raw_Data_Daily!$B:$B, "Variant", Raw_Data_Daily!$C:$C, "E. 40-99"),"") -> 0.42581691 | Q25: =IFERROR((P25-O25)/ABS(O25),"") -> -0.0031216556 | R25: =IFERROR(SUMPRODUCT((Raw_Data_Daily!$B$2:$B$9999="Control")*(Raw_Data_Daily!$C$2:$C$9999="F. 100+")*Raw_Data_Daily!$D$2:$D$9999*Raw_Data_Daily!$N$2:$N$9999)/SUMIFS(Raw_Data_Daily!$D:$D, Raw_Data_Daily!$B:$B, "Control", Raw_Data_Daily!$C:$C, "F. 100+"),"") -> 0.35663596 | S25: =IFERROR(SUMPRODUCT((Raw_Data_Daily!$B$2:$B$9999="Variant")*(Raw_Data_Daily!$C$2:$C$9999="F. 100+")*Raw_Data_Daily!$D$2:$D$9999*Raw_Data_Daily!$N$2:$N$9999)/SUMIFS(Raw_Data_Daily!$D:$D, Raw_Data_Daily!$B:$B, "Variant", Raw_Data_Daily!$C:$C, "F. 100+"),"") -> 0.3604435 | T25: =IFERROR((S25-R25)/ABS(R25),"") -> 0.010676245
B26: First-try OOM rate | C26: =IFERROR(SUMPRODUCT((Raw_Data_Daily!$B$2:$B$9999="Control")*(Raw_Data_Daily!$C$2:$C$9999="A. 0")*Raw_Data_Daily!$D$2:$D$9999*Raw_Data_Daily!$O$2:$O$9999)/SUMIFS(Raw_Data_Daily!$D:$D, Raw_Data_Daily!$B:$B, "Control", Raw_Data_Daily!$C:$C, "A. 0"),"") | D26: =IFERROR(SUMPRODUCT((Raw_Data_Daily!$B$2:$B$9999="Variant")*(Raw_Data_Daily!$C$2:$C$9999="A. 0")*Raw_Data_Daily!$D$2:$D$9999*Raw_Data_Daily!$O$2:$O$9999)/SUMIFS(Raw_Data_Daily!$D:$D, Raw_Data_Daily!$B:$B, "Variant", Raw_Data_Daily!$C:$C, "A. 0"),"") | E26: =IFERROR((D26-C26)/ABS(C26),"") | F26: =IFERROR(SUMPRODUCT((Raw_Data_Daily!$B$2:$B$9999="Control")*(Raw_Data_Daily!$C$2:$C$9999="B. 1-9")*Raw_Data_Daily!$D$2:$D$9999*Raw_Data_Daily!$O$2:$O$9999)/SUMIFS(Raw_Data_Daily!$D:$D, Raw_Data_Daily!$B:$B, "Control", Raw_Data_Daily!$C:$C, "B. 1-9"),"") -> 0.41309363 | G26: =IFERROR(SUMPRODUCT((Raw_Data_Daily!$B$2:$B$9999="Variant")*(Raw_Data_Daily!$C$2:$C$9999="B. 1-9")*Raw_Data_Daily!$D$2:$D$9999*Raw_Data_Daily!$O$2:$O$9999)/SUMIFS(Raw_Data_Daily!$D:$D, Raw_Data_Daily!$B:$B, "Variant", Raw_Data_Daily!$C:$C, "B. 1-9"),"") -> 0.40293327 | H26: =IFERROR((G26-F26)/ABS(F26),"") -> -0.024595779 | I26: =IFERROR(SUMPRODUCT((Raw_Data_Daily!$B$2:$B$9999="Control")*(Raw_Data_Daily!$C$2:$C$9999="C. 10-19")*Raw_Data_Daily!$D$2:$D$9999*Raw_Data_Daily!$O$2:$O$9999)/SUMIFS(Raw_Data_Daily!$D:$D, Raw_Data_Daily!$B:$B, "Control", Raw_Data_Daily!$C:$C, "C. 10-19"),"") -> 0.35889053 | J26: =IFERROR(SUMPRODUCT((Raw_Data_Daily!$B$2:$B$9999="Variant")*(Raw_Data_Daily!$C$2:$C$9999="C. 10-19")*Raw_Data_Daily!$D$2:$D$9999*Raw_Data_Daily!$O$2:$O$9999)/SUMIFS(Raw_Data_Daily!$D:$D, Raw_Data_Daily!$B:$B, "Variant", Raw_Data_Daily!$C:$C, "C. 10-19"),"") -> 0.35813715 | K26: =IFERROR((J26-I26)/ABS(I26),"") -> -0.0020991771 | L26: =IFERROR(SUMPRODUCT((Raw_Data_Daily!$B$2:$B$9999="Control")*(Raw_Data_Daily!$C$2:$C$9999="D. 20-39")*Raw_Data_Daily!$D$2:$D$9999*Raw_Data_Daily!$O$2:$O$9999)/SUMIFS(Raw_Data_Daily!$D:$D, Raw_Data_Daily!$B:$B, "Control", Raw_Data_Daily!$C:$C, "D. 20-39"),"") -> 0.31294681 | M26: =IFERROR(SUMPRODUCT((Raw_Data_Daily!$B$2:$B$9999="Variant")*(Raw_Data_Daily!$C$2:$C$9999="D. 20-39")*Raw_Data_Daily!$D$2:$D$9999*Raw_Data_Daily!$O$2:$O$9999)/SUMIFS(Raw_Data_Daily!$D:$D, Raw_Data_Daily!$B:$B, "Variant", Raw_Data_Daily!$C:$C, "D. 20-39"),"") -> 0.31134425 | N26: =IFERROR((M26-L26)/ABS(L26),"") -> -0.0051208613 | O26: =IFERROR(SUMPRODUCT((Raw_Data_Daily!$B$2:$B$9999="Control")*(Raw_Data_Daily!$C$2:$C$9999="E. 40-99")*Raw_Data_Daily!$D$2:$D$9999*Raw_Data_Daily!$O$2:$O$9999)/SUMIFS(Raw_Data_Daily!$D:$D, Raw_Data_Daily!$B:$B, "Control", Raw_Data_Daily!$C:$C, "E. 40-99"),"") -> 0.27061768 | P26: =IFERROR(SUMPRODUCT((Raw_Data_Daily!$B$2:$B$9999="Variant")*(Raw_Data_Daily!$C$2:$C$9999="E. 40-99")*Raw_Data_Daily!$D$2:$D$9999*Raw_Data_Daily!$O$2:$O$9999)/SUMIFS(Raw_Data_Daily!$D:$D, Raw_Data_Daily!$B:$B, "Variant", Raw_Data_Daily!$C:$C, "E. 40-99"),"") -> 0.26870594 | Q26: =IFERROR((P26-O26)/ABS(O26),"") -> -0.0070643651 | R26: =IFERROR(SUMPRODUCT((Raw_Data_Daily!$B$2:$B$9999="Control")*(Raw_Data_Daily!$C$2:$C$9999="F. 100+")*Raw_Data_Daily!$D$2:$D$9999*Raw_Data_Daily!$O$2:$O$9999)/SUMIFS(Raw_Data_Daily!$D:$D, Raw_Data_Daily!$B:$B, "Control", Raw_Data_Daily!$C:$C, "F. 100+"),"") -> 0.22994673 | S26: =IFERROR(SUMPRODUCT((Raw_Data_Daily!$B$2:$B$9999="Variant")*(Raw_Data_Daily!$C$2:$C$9999="F. 100+")*Raw_Data_Daily!$D$2:$D$9999*Raw_Data_Daily!$O$2:$O$9999)/SUMIFS(Raw_Data_Daily!$D:$D, Raw_Data_Daily!$B:$B, "Variant", Raw_Data_Daily!$C:$C, "F. 100+"),"") -> 0.23099235 | T26: =IFERROR((S26-R26)/ABS(R26),"") -> 0.0045472445 | V26: todo
